[2025-04-07 08:30:24.163] [multi_sink] [info] Processing received message: {"jsonrpc":"2.0","method":"subscription","params":{"channel":"book.ETH-PERPETUAL.100ms","data":{"timestamp":1743994825751,"type":"change","change_id":23707145890,"instrument_name":"ETH-PERPETUAL","bids":[],"asks":[["delete",1578.9,0.0],["change",1579.45,6162903.0]],"prev_change_id":23707145553}}}
[2025-04-07 08:30:24.364] [multi_sink] [info] 📩 Received: {"jsonrpc":"2.0","method":"subscription","params":{"channel":"book.BTC-PERPETUAL.100ms","data":{"timestamp":1743994825987,"type":"change","change_id":41151893825,"instrument_name":"BTC-PERPETUAL","bids":[["new",78430.5,15460.0],["new",78430.0,2.21e4],["new",78428.5,6810.0],["new",78428.0,65720.0],["new",78427.5,55770.0],["new",78425.5,10.0],["new",78424.0,35220.0],["new",78418.0,32180.0],["new",78417.5,4.0e4],["delete",78388.0,0.0],["delete",78387.5,0.0],["delete",78386.5,0.0],["delete",78385.0,0.0],["delete",78384.5,0.0],["delete",78384.0,0.0],["delete",78383.5,0.0],["delete",78382.5,0.0],["delete",78380.5,0.0]],"asks":[["delete",78608.5,0.0],["new",78621.5,78620.0],["delete",78658.5,0.0],["new",78671.5,1.18e5]],"prev_change_id":41151893218}}}
[2025-04-07 08:30:24.365] [multi_sink] [info] Processing received message: {"jsonrpc":"2.0","method":"subscription","params":{"channel":"book.BTC-PERPETUAL.100ms","data":{"timestamp":1743994825987,"type":"change","change_id":41151893825,"instrument_name":"BTC-PERPETUAL","bids":[["new",78430.5,15460.0],["new",78430.0,2.21e4],["new",78428.5,6810.0],["new",78428.0,65720.0],["new",78427.5,55770.0],["new",78425.5,10.0],["new",78424.0,35220.0],["new",78418.0,32180.0],["new",78417.5,4.0e4],["delete",78388.0,0.0],["delete",78387.5,0.0],["delete",78386.5,0.0],["delete",78385.0,0.0],["delete",78384.5,0.0],["delete",78384.0,0.0],["delete",78383.5,0.0],["delete",78382.5,0.0],["delete",78380.5,0.0]],"asks":[["delete",78608.5,0.0],["new",78621.5,78620.0],["delete",78658.5,0.0],["new",78671.5,1.18e5]],"prev_change_id":41151893218}}}
[2025-04-07 08:30:24.689] [multi_sink] [info] 📩 Received: {"jsonrpc":"2.0","method":"subscription","params":{"channel":"book.BTC-PERPETUAL.100ms","data":{"timestamp":1743994826063,"type":"change","change_id":41151893860,"instrument_name":"BTC-PERPETUAL","bids":[["new",78432.5,61260.0],["new",78431.5,500.0],["delete",78380.0,0.0],["delete",78379.5,0.0]],"asks":[],"prev_change_id":41151893825}}}
[2025-04-07 08:30:24.691] [multi_sink] [info] Processing received message: {"jsonrpc":"2.0","method":"subscription","params":{"channel":"book.BTC-PERPETUAL.100ms","data":{"timestamp":1743994826063,"type":"change","change_id":41151893860,"instrument_name":"BTC-PERPETUAL","bids":[["new",78432.5,61260.0],["new",78431.5,500.0],["delete",78380.0,0.0],["delete",78379.5,0.0]],"asks":[],"prev_change_id":41151893825}}}
[2025-04-07 08:30:26.093] [multi_sink] [info] 📩 Received: {"jsonrpc":"2.0","method":"subscription","params":{"channel":"book.BTC-PERPETUAL.100ms","data":{"timestamp":1743994827445,"type":"change","change_id":41151896336,"instrument_name":"BTC-PERPETUAL","bids":[["new",78288.5,78280.0],["delete",78277.0,0.0],["new",78238.5,117350.0],["delete",78227.0,0.0]],"asks":[],"prev_change_id":41151893860}}}
[2025-04-07 08:30:26.097] [multi_sink] [info] Processing received message: {"jsonrpc":"2.0","method":"subscription","params":{"channel":"book.BTC-PERPETUAL.100ms","data":{"timestamp":1743994827445,"type":"change","change_id":41151896336,"instrument_name":"BTC-PERPETUAL","bids":[["new",78288.5,78280.0],["delete",78277.0,0.0],["new",78238.5,117350.0],["delete",78227.0,0.0]],"asks":[],"prev_change_id":41151893860}}}
[2025-04-07 08:30:27.181] [multi_sink] [info] 📩 Received: {"jsonrpc":"2.0","method":"subscription","params":{"channel":"book.ETH-PERPETUAL.100ms","data":{"timestamp":1743994828801,"type":"change","change_id":23707149566,"instrument_name":"ETH-PERPETUAL","bids":[["delete",1578.7,0.0],["new",1578.55,3829.0]],"asks":[["delete",1578.75,0.0],["new",1580.9,29506.0]],"prev_change_id":23707145890}}}
[2025-04-07 08:30:27.181] [multi_sink] [info] Processing received message: {"jsonrpc":"2.0","method":"subscription","params":{"channel":"book.ETH-PERPETUAL.100ms","data":{"timestamp":1743994828801,"type":"change","change_id":23707149566,"instrument_name":"ETH-PERPETUAL","bids":[["delete",1578.7,0.0],["new",1578.55,3829.0]],"asks":[["delete",1578.75,0.0],["new",1580.9,29506.0]],"prev_change_id":23707145890}}}
[2025-04-07 08:30:27.511] [multi_sink] [info] 📩 Received: {"jsonrpc":"2.0","method":"subscription","params":{"channel":"book.ETH-PERPETUAL.100ms","data":{"timestamp":1743994829142,"type":"change","change_id":23707150018,"instrument_name":"ETH-PERPETUAL","bids":[["new",1579.0,8633.0],["new",1578.95,50805.0],["new",1578.9,1028.0],["new",1578.85,43728.0],["new",1578.8,8533.0],["new",1578.75,8054.0],["new",1578.7,1539.0],["change",1578.65,10928.0],["new",1578.6,1028.0],["delete",1578.5,0.0],["delete",1578.45,0.0],["delete",1578.4,0.0],["delete",1578.3,0.0],["delete",1578.25,0.0],["delete",1578.2,0.0],["delete",1578.15,0.0],["delete",1578.1,0.0]],"asks":[["delete",1578.95,0.0],["delete",1579.0,0.0],["delete",1579.1,0.0],["delete",1579.15,0.0],["delete",1579.2,0.0],["delete",1579.25,0.0],["delete",1579.3,0.0],["delete",1579.35,0.0],["delete",1579.4,0.0],["new",1580.45,20703.0],["new",1580.5,31187.0],["new",1580.55,25930.0],["new",1580.6,1720.0],["new",1580.65,22729.0],["new",1580.7,74534.0],["new",1580.75,3212.0],["new",1580.8,9844.0],["new",1580.85,1028.0],["delete",1584.7,0.0],["new",1587.1,500.0]],"prev_change_id":23707149566}}}
[2025-04-07 08:30:27.514] [multi_sink] [info] Processing received message: {"jsonrpc":"2.0","method":"subscription","params":{"channel":"book.ETH-PERPETUAL.100ms","data":{"timestamp":1743994829142,"type":"change","change_id":23707150018,"instrument_name":"ETH-PERPETUAL","bids":[["new",1579.0,8633.0],["new",1578.95,50805.0],["new",1578.9,1028.0],["new",1578.85,43728.0],["new",1578.8,8533.0],["new",1578.75,8054.0],["new",1578.7,1539.0],["change",1578.65,10928.0],["new",1578.6,1028.0],["delete",1578.5,0.0],["delete",1578.45,0.0],["delete",1578.4,0.0],["delete",1578.3,0.0],["delete",1578.25,0.0],["delete",1578.2,0.0],["delete",1578.15,0.0],["delete",1578.1,0.0]],"asks":[["delete",1578.95,0.0],["delete",1579.0,0.0],["delete",1579.1,0.0],["delete",1579.15,0.0],["delete",1579.2,0.0],["delete",1579.25,0.0],["delete",1579.3,0.0],["delete",1579.35,0.0],["delete",1579.4,0.0],["new",1580.45,20703.0],["new",1580.5,31187.0],["new",1580.55,25930.0],["new",1580.6,1720.0],["new",1580.65,22729.0],["new",1580.7,74534.0],["new",1580.75,3212.0],["new",1580.8,9844.0],["new",1580.85,1028.0],["delete",1584.7,0.0],["new",1587.1,500.0]],"prev_change_id":23707149566}}}
[2025-04-07 08:30:27.841] [multi_sink] [info] 📩 Received: {"jsonrpc":"2.0","method":"subscription","params":{"channel":"book.ETH-PERPETUAL.100ms","data":{"timestamp":1743994829441,"type":"change","change_id":23707150304,"instrument_name":"ETH-PERPETUAL","bids":[["new",1579.4,9430.0],["new",1579.3,14882.0],["new",1579.25,37674.0],["new",1579.2,72328.0],["new",1579.15,5695.0],["new",1579.1,16819.0],["new",1579.05,14118.0],["delete",1578.05,0.0],["delete",1578.0,0.0],["change",1577.95,7744554.0],["delete",1577.9,0.0],["delete",1577.85,0.0],["delete",1577.8,0.0],["delete",1577.75,0.0],["delete",1577.7,0.0]],"asks":[["change",1579.45,6129268.0],["delete",1579.5,0.0],["delete",1579.55,0.0],["delete",1579.6,0.0],["delete",1579.65,0.0],["delete",1579.7,0.0],["delete",1579.75,0.0],["delete",1579.8,0.0],["new",1580.05,5.0e3],["new",1580.1,11870.0],["new",1580.15,2.51e4],["new",1580.2,23702.0],["new",1580.25,10013.0],["new",1580.3,14323.0],["new",1580.35,928.0],["new",1580.4,5944.0]],"prev_change_id":23707150018}}}
[2025-04-07 08:30:27.842] [multi_sink] [info] Processing received message: {"jsonrpc":"2.0","method":"subscription","params":{"channel":"book.ETH-PERPETUAL.100ms","data":{"timestamp":1743994829441,"type":"change","change_id":23707150304,"instrument_name":"ETH-PERPETUAL","bids":[["new",1579.4,9430.0],["new",1579.3,14882.0],["new",1579.25,37674.0],["new",1579.2,72328.0],["new",1579.15,5695.0],["new",1579.1,16819.0],["new",1579.05,14118.0],["delete",1578.05,0.0],["delete",1578.0,0.0],["change",1577.95,7744554.0],["delete",1577.9,0.0],["delete",1577.85,0.0],["delete",1577.8,0.0],["delete",1577.75,0.0],["delete",1577.7,0.0]],"asks":[["change",1579.45,6129268.0],["delete",1579.5,0.0],["delete",1579.55,0.0],["delete",1579.6,0.0],["delete",1579.65,0.0],["delete",1579.7,0.0],["delete",1579.75,0.0],["delete",1579.8,0.0],["new",1580.05,5.0e3],["new",1580.1,11870.0],["new",1580.15,2.51e4],["new",1580.2,23702.0],["new",1580.25,10013.0],["new",1580.3,14323.0],["new",1580.35,928.0],["new",1580.4,5944.0]],"prev_change_id":23707150018}}}
[2025-04-07 08:30:28.174] [multi_sink] [info] 📩 Received: {"jsonrpc":"2.0","method":"subscription","params":{"channel":"book.ETH-PERPETUAL.100ms","data":{"timestamp":1743994829553,"type":"change","change_id":23707150404,"instrument_name":"ETH-PERPETUAL","bids":[["delete",1577.65,0.0],["delete",1577.6,0.0],["new",1574.65,500.0],["delete",1573.05,0.0],["new",1571.5,500.0],["delete",1569.1,0.0]],"asks":[["change",1579.45,6111993.0],["new",1579.75,1916.0],["delete",1579.85,0.0],["delete",1579.9,0.0],["new",1580.0,1.6e3]],"prev_change_id":23707150304}}}
[2025-04-07 08:30:28.185] [multi_sink] [info] Processing received message: {"jsonrpc":"2.0","method":"subscription","params":{"channel":"book.ETH-PERPETUAL.100ms","data":{"timestamp":1743994829553,"type":"change","change_id":23707150404,"instrument_name":"ETH-PERPETUAL","bids":[["delete",1577.65,0.0],["delete",1577.6,0.0],["new",1574.65,500.0],["delete",1573.05,0.0],["new",1571.5,500.0],["delete",1569.1,0.0]],"asks":[["change",1579.45,6111993.0],["new",1579.75,1916.0],["delete",1579.85,0.0],["delete",1579.9,0.0],["new",1580.0,1.6e3]],"prev_change_id":23707150304}}}
[2025-04-07 08:30:28.336] [multi_sink] [info] 📩 Received: {"jsonrpc":"2.0","method":"subscription","params":{"channel":"book.BTC-PERPETUAL.100ms","data":{"timestamp":1743994829966,"type":"change","change_id":41151899796,"instrument_name":"BTC-PERPETUAL","bids":[["new",78261.0,8000580.0],["delete",78205.0,0.0]],"asks":[],"prev_change_id":41151896336}}}
[2025-04-07 08:30:28.341] [multi_sink] [info] Processing received message: {"jsonrpc":"2.0","method":"subscription","params":{"channel":"book.BTC-PERPETUAL.100ms","data":{"timestamp":1743994829966,"type":"change","change_id":41151899796,"instrument_name":"BTC-PERPETUAL","bids":[["new",78261.0,8000580.0],["delete",78205.0,0.0]],"asks":[],"prev_change_id":41151896336}}}
[2025-04-07 08:30:28.665] [multi_sink] [info] 📩 Received: {"jsonrpc":"2.0","method":"subscription","params":{"channel":"book.BTC-PERPETUAL.100ms","data":{"timestamp":1743994829982,"type":"change","change_id":41151899797,"instrument_name":"BTC-PERPETUAL","bids":[["change",78414.0,7871390.0],["delete",78358.0,0.0]],"asks":[],"prev_change_id":41151899796}}}
[2025-04-07 08:30:28.666] [multi_sink] [info] Processing received message: {"jsonrpc":"2.0","method":"subscription","params":{"channel":"book.BTC-PERPETUAL.100ms","data":{"timestamp":1743994829982,"type":"change","change_id":41151899797,"instrument_name":"BTC-PERPETUAL","bids":[["change",78414.0,7871390.0],["delete",78358.0,0.0]],"asks":[],"prev_change_id":41151899796}}}
[2025-04-07 08:30:28.998] [multi_sink] [info] 📩 Received: {"jsonrpc":"2.0","method":"subscription","params":{"channel":"book.BTC-PERPETUAL.100ms","data":{"timestamp":1743994830608,"type":"change","change_id":41151900619,"instrument_name":"BTC-PERPETUAL","bids":[["new",78435.5,1560.0],["new",78433.0,5210.0],["delete",78432.5,0.0],["delete",78431.5,0.0],["delete",78430.5,0.0],["change",78430.0,5220.0],["new",78429.5,1.0e4],["new",78429.0,14890.0],["change",78428.5,40180.0],["delete",78428.0,0.0],["delete",78427.5,0.0],["new",78426.5,15790.0],["delete",78425.5,0.0],["change",78424.0,70440.0]],"asks":[["delete",78435.5,0.0],["delete",78446.5,0.0],["new",78459.0,490.0],["new",78460.0,8690.0],["new",78461.0,1.09e4],["new",78461.5,490.0],["new",78462.5,4330.0],["new",78463.0,490.0],["new",78463.5,510.0],["new",78464.0,10490.0],["new",78491.5,6640830.0],["delete",78588.5,0.0],["new",78644.5,7777770.0]],"prev_change_id":41151899797}}}
[2025-04-07 08:30:28.999] [multi_sink] [info] Processing received message: {"jsonrpc":"2.0","method":"subscription","params":{"channel":"book.BTC-PERPETUAL.100ms","data":{"timestamp":1743994830608,"type":"change","change_id":41151900619,"instrument_name":"BTC-PERPETUAL","bids":[["new",78435.5,1560.0],["new",78433.0,5210.0],["delete",78432.5,0.0],["delete",78431.5,0.0],["delete",78430.5,0.0],["change",78430.0,5220.0],["new",78429.5,1.0e4],["new",78429.0,14890.0],["change",78428.5,40180.0],["delete",78428.0,0.0],["delete",78427.5,0.0],["new",78426.5,15790.0],["delete",78425.5,0.0],["change",78424.0,70440.0]],"asks":[["delete",78435.5,0.0],["delete",78446.5,0.0],["new",78459.0,490.0],["new",78460.0,8690.0],["new",78461.0,1.09e4],["new",78461.5,490.0],["new",78462.5,4330.0],["new",78463.0,490.0],["new",78463.5,510.0],["new",78464.0,10490.0],["new",78491.5,6640830.0],["delete",78588.5,0.0],["new",78644.5,7777770.0]],"prev_change_id":41151899797}}}
[2025-04-07 08:30:29.338] [multi_sink] [info] 📩 Received: {"jsonrpc":"2.0","method":"subscription","params":{"channel":"book.BTC-PERPETUAL.100ms","data":{"timestamp":1743994830950,"type":"change","change_id":41151901233,"instrument_name":"BTC-PERPETUAL","bids":[["new",78443.5,650.0],["new",78440.5,49960.0],["new",78440.0,19410.0],["new",78438.5,200.0],["new",78437.5,3840.0],["new",78437.0,1.0e4],["new",78436.5,40430.0],["new",78436.0,220.0],["change",78424.0,35220.0],["delete",78418.0,0.0],["delete",78417.5,0.0],["delete",78417.0,0.0],["delete",78416.5,0.0],["delete",78415.0,0.0],["delete",78414.5,0.0],["change",78414.0,7825720.0]],"asks":[["new",78454.5,490.0],["new",78455.0,6490.0],["new",78455.5,980.0],["new",78456.0,880.0],["new",78456.5,4.3e3],["new",78457.0,490.0],["new",78457.5,490.0],["new",78458.0,1960.0],["new",78458.5,10920.0]],"prev_change_id":41151900619}}}
[2025-04-07 08:30:29.340] [multi_sink] [info] Processing received message: {"jsonrpc":"2.0","method":"subscription","params":{"channel":"book.BTC-PERPETUAL.100ms","data":{"timestamp":1743994830950,"type":"change","change_id":41151901233,"instrument_name":"BTC-PERPETUAL","bids":[["new",78443.5,650.0],["new",78440.5,49960.0],["new",78440.0,19410.0],["new",78438.5,200.0],["new",78437.5,3840.0],["new",78437.0,1.0e4],["new",78436.5,40430.0],["new",78436.0,220.0],["change",78424.0,35220.0],["delete",78418.0,0.0],["delete",78417.5,0.0],["delete",78417.0,0.0],["delete",78416.5,0.0],["delete",78415.0,0.0],["delete",78414.5,0.0],["change",78414.0,7825720.0]],"asks":[["new",78454.5,490.0],["new",78455.0,6490.0],["new",78455.5,980.0],["new",78456.0,880.0],["new",78456.5,4.3e3],["new",78457.0,490.0],["new",78457.5,490.0],["new",78458.0,1960.0],["new",78458.5,10920.0]],"prev_change_id":41151900619}}}
[2025-04-07 08:30:29.654] [multi_sink] [info] 📩 Received: {"jsonrpc":"2.0","method":"subscription","params":{"channel":"book.BTC-PERPETUAL.100ms","data":{"timestamp":1743994831063,"type":"change","change_id":41151901285,"instrument_name":"BTC-PERPETUAL","bids":[["new",78452.5,28350.0],["new",78446.5,2880.0],["new",78446.0,9610.0]],"asks":[["new",78453.0,95870.0],["new",78453.5,5810.0],["new",78454.0,1.0e4]],"prev_change_id":41151901233}}}
[2025-04-07 08:30:29.655] [multi_sink] [info] Processing received message: {"jsonrpc":"2.0","method":"subscription","params":{"channel":"book.BTC-PERPETUAL.100ms","data":{"timestamp":1743994831063,"type":"change","change_id":41151901285,"instrument_name":"BTC-PERPETUAL","bids":[["new",78452.5,28350.0],["new",78446.5,2880.0],["new",78446.0,9610.0]],"asks":[["new",78453.0,95870.0],["new",78453.5,5810.0],["new",78454.0,1.0e4]],"prev_change_id":41151901233}}}
[2025-04-07 08:30:30.258] [multi_sink] [info] 📩 Received: {"jsonrpc":"2.0","method":"subscription","params":{"channel":"book.BTC-PERPETUAL.100ms","data":{"timestamp":1743994831890,"type":"change","change_id":41151902725,"instrument_name":"BTC-PERPETUAL","bids":[],"asks":[["new",78609.5,78610.0],["delete",78621.5,0.0]],"prev_change_id":41151901285}}}
[2025-04-07 08:30:30.261] [multi_sink] [info] Processing received message: {"jsonrpc":"2.0","method":"subscription","params":{"channel":"book.BTC-PERPETUAL.100ms","data":{"timestamp":1743994831890,"type":"change","change_id":41151902725,"instrument_name":"BTC-PERPETUAL","bids":[],"asks":[["new",78609.5,78610.0],["delete",78621.5,0.0]],"prev_change_id":41151901285}}}
[2025-04-07 08:30:30.588] [multi_sink] [info] 📩 Received: {"jsonrpc":"2.0","method":"subscription","params":{"channel":"book.BTC-PERPETUAL.100ms","data":{"timestamp":1743994831926,"type":"change","change_id":41151902887,"instrument_name":"BTC-PERPETUAL","bids":[["delete",78288.5,0.0],["new",78275.5,78270.0],["delete",78238.5,0.0],["new",78225.5,117330.0]],"asks":[["new",78659.5,117990.0],["delete",78671.5,0.0]],"prev_change_id":41151902725}}}
[2025-04-07 08:30:30.591] [multi_sink] [info] Processing received message: {"jsonrpc":"2.0","method":"subscription","params":{"channel":"book.BTC-PERPETUAL.100ms","data":{"timestamp":1743994831926,"type":"change","change_id":41151902887,"instrument_name":"BTC-PERPETUAL","bids":[["delete",78288.5,0.0],["new",78275.5,78270.0],["delete",78238.5,0.0],["new",78225.5,117330.0]],"asks":[["new",78659.5,117990.0],["delete",78671.5,0.0]],"prev_change_id":41151902725}}}
[2025-04-07 08:30:31.218] [multi_sink] [info] 📩 Received: {"jsonrpc":"2.0","method":"subscription","params":{"channel":"book.ETH-PERPETUAL.100ms","data":{"timestamp":1743994832621,"type":"change","change_id":23707153686,"instrument_name":"ETH-PERPETUAL","bids":[["change",1579.05,7758672.0],["delete",1577.95,0.0]],"asks":[],"prev_change_id":23707150404}}}
[2025-04-07 08:30:31.221] [multi_sink] [info] Processing received message: {"jsonrpc":"2.0","method":"subscription","params":{"channel":"book.ETH-PERPETUAL.100ms","data":{"timestamp":1743994832621,"type":"change","change_id":23707153686,"instrument_name":"ETH-PERPETUAL","bids":[["change",1579.05,7758672.0],["delete",1577.95,0.0]],"asks":[],"prev_change_id":23707150404}}}
[2025-04-07 08:30:31.224] [multi_sink] [info] 📩 Received: {"jsonrpc":"2.0","method":"subscription","params":{"channel":"book.BTC-PERPETUAL.100ms","data":{"timestamp":1743994832854,"type":"change","change_id":41151903950,"instrument_name":"BTC-PERPETUAL","bids":[],"asks":[["new",78599.5,7.86e4],["delete",78609.5,0.0]],"prev_change_id":41151902887}}}
[2025-04-07 08:30:31.227] [multi_sink] [info] Processing received message: {"jsonrpc":"2.0","method":"subscription","params":{"channel":"book.BTC-PERPETUAL.100ms","data":{"timestamp":1743994832854,"type":"change","change_id":41151903950,"instrument_name":"BTC-PERPETUAL","bids":[],"asks":[["new",78599.5,7.86e4],["delete",78609.5,0.0]],"prev_change_id":41151902887}}}
[2025-04-07 08:30:31.539] [multi_sink] [info] 📩 Received: {"jsonrpc":"2.0","method":"subscription","params":{"channel":"book.ETH-PERPETUAL.100ms","data":{"timestamp":1743994832951,"type":"change","change_id":23707154186,"instrument_name":"ETH-PERPETUAL","bids":[],"asks":[["delete",1579.45,0.0],["change",1580.55,6137923.0]],"prev_change_id":23707153686}}}
[2025-04-07 08:30:31.544] [multi_sink] [info] Processing received message: {"jsonrpc":"2.0","method":"subscription","params":{"channel":"book.ETH-PERPETUAL.100ms","data":{"timestamp":1743994832951,"type":"change","change_id":23707154186,"instrument_name":"ETH-PERPETUAL","bids":[],"asks":[["delete",1579.45,0.0],["change",1580.55,6137923.0]],"prev_change_id":23707153686}}}
[2025-04-07 08:30:31.553] [multi_sink] [info] 📩 Received: {"jsonrpc":"2.0","method":"subscription","params":{"channel":"book.BTC-PERPETUAL.100ms","data":{"timestamp":1743994832855,"type":"change","change_id":41151903951,"instrument_name":"BTC-PERPETUAL","bids":[],"asks":[["new",78649.5,117970.0],["delete",78659.5,0.0]],"prev_change_id":41151903950}}}
[2025-04-07 08:30:31.555] [multi_sink] [info] Processing received message: {"jsonrpc":"2.0","method":"subscription","params":{"channel":"book.BTC-PERPETUAL.100ms","data":{"timestamp":1743994832855,"type":"change","change_id":41151903951,"instrument_name":"BTC-PERPETUAL","bids":[],"asks":[["new",78649.5,117970.0],["delete",78659.5,0.0]],"prev_change_id":41151903950}}}
[2025-04-07 08:30:31.884] [multi_sink] [info] 📩 Received: {"jsonrpc":"2.0","method":"subscription","params":{"channel":"book.BTC-PERPETUAL.100ms","data":{"timestamp":1743994833468,"type":"change","change_id":41151905031,"instrument_name":"BTC-PERPETUAL","bids":[["delete",78275.5,0.0],["delete",78225.5,0.0]],"asks":[["delete",78599.5,0.0],["delete",78649.5,0.0]],"prev_change_id":41151903951}}}
[2025-04-07 08:30:31.885] [multi_sink] [info] Processing received message: {"jsonrpc":"2.0","method":"subscription","params":{"channel":"book.BTC-PERPETUAL.100ms","data":{"timestamp":1743994833468,"type":"change","change_id":41151905031,"instrument_name":"BTC-PERPETUAL","bids":[["delete",78275.5,0.0],["delete",78225.5,0.0]],"asks":[["delete",78599.5,0.0],["delete",78649.5,0.0]],"prev_change_id":41151903951}}}
[2025-04-07 08:30:32.205] [multi_sink] [info] 📩 Received: {"jsonrpc":"2.0","method":"subscription","params":{"channel":"book.ETH-PERPETUAL.100ms","data":{"timestamp":1743994833804,"type":"change","change_id":23707154705,"instrument_name":"ETH-PERPETUAL","bids":[["delete",1579.4,0.0],["new",1577.9,930.0]],"asks":[["delete",1579.75,0.0],["change",1580.35,26955.0]],"prev_change_id":23707154186}}}
[2025-04-07 08:30:32.205] [multi_sink] [info] Processing received message: {"jsonrpc":"2.0","method":"subscription","params":{"channel":"book.ETH-PERPETUAL.100ms","data":{"timestamp":1743994833804,"type":"change","change_id":23707154705,"instrument_name":"ETH-PERPETUAL","bids":[["delete",1579.4,0.0],["new",1577.9,930.0]],"asks":[["delete",1579.75,0.0],["change",1580.35,26955.0]],"prev_change_id":23707154186}}}
[2025-04-07 08:30:32.532] [multi_sink] [info] 📩 Received: {"jsonrpc":"2.0","method":"subscription","params":{"channel":"book.ETH-PERPETUAL.100ms","data":{"timestamp":1743994834136,"type":"change","change_id":23707155163,"instrument_name":"ETH-PERPETUAL","bids":[["delete",1579.3,0.0],["delete",1579.25,0.0],["delete",1579.2,0.0],["delete",1579.15,0.0],["delete",1579.1,0.0],["change",1579.05,7744554.0],["delete",1579.0,0.0],["delete",1578.95,0.0],["delete",1578.9,0.0],["new",1578.35,4087.0],["new",1578.3,8693.0],["new",1578.25,8944.0],["new",1578.2,26910.0],["new",1578.15,4103.0],["new",1578.1,10313.0],["new",1578.05,8507.0],["new",1578.0,1030.0],["new",1577.95,61048.0]],"asks":[["new",1579.9,8422.0],["new",1579.95,1412.0],["change",1580.0,13078.0],["change",1580.05,7705.0],["change",1580.1,56993.0],["change",1580.15,100.0],["change",1580.2,83259.0],["change",1580.25,927.0],["change",1580.3,26919.0],["change",1580.35,26027.0],["delete",1580.4,0.0]],"prev_change_id":23707154705}}}
[2025-04-07 08:30:32.535] [multi_sink] [info] Processing received message: {"jsonrpc":"2.0","method":"subscription","params":{"channel":"book.ETH-PERPETUAL.100ms","data":{"timestamp":1743994834136,"type":"change","change_id":23707155163,"instrument_name":"ETH-PERPETUAL","bids":[["delete",1579.3,0.0],["delete",1579.25,0.0],["delete",1579.2,0.0],["delete",1579.15,0.0],["delete",1579.1,0.0],["change",1579.05,7744554.0],["delete",1579.0,0.0],["delete",1578.95,0.0],["delete",1578.9,0.0],["new",1578.35,4087.0],["new",1578.3,8693.0],["new",1578.25,8944.0],["new",1578.2,26910.0],["new",1578.15,4103.0],["new",1578.1,10313.0],["new",1578.05,8507.0],["new",1578.0,1030.0],["new",1577.95,61048.0]],"asks":[["new",1579.9,8422.0],["new",1579.95,1412.0],["change",1580.0,13078.0],["change",1580.05,7705.0],["change",1580.1,56993.0],["change",1580.15,100.0],["change",1580.2,83259.0],["change",1580.25,927.0],["change",1580.3,26919.0],["change",1580.35,26027.0],["delete",1580.4,0.0]],"prev_change_id":23707154705}}}
[2025-04-07 08:30:32.865] [multi_sink] [info] 📩 Received: {"jsonrpc":"2.0","method":"subscription","params":{"channel":"book.ETH-PERPETUAL.100ms","data":{"timestamp":1743994834482,"type":"change","change_id":23707155636,"instrument_name":"ETH-PERPETUAL","bids":[["delete",1578.85,0.0],["change",1578.8,13494.0],["change",1578.75,5160.0],["change",1578.7,923.0],["change",1578.65,7622.0],["change",1578.6,15021.0],["change",1578.55,41877.0],["new",1578.5,40988.0],["new",1578.45,2275.0],["new",1578.4,1030.0]],"asks":[["new",1579.35,12705.0],["new",1579.4,5163.0],["new",1579.55,2382.0],["new",1579.6,28582.0],["new",1579.65,3.01e4],["new",1579.7,12089.0],["new",1579.75,5.0e3],["new",1579.8,33573.0],["new",1579.85,29052.0],["delete",1580.45,0.0],["delete",1580.5,0.0],["change",1580.55,6111993.0],["delete",1580.6,0.0],["delete",1580.65,0.0],["delete",1580.7,0.0],["delete",1580.75,0.0],["delete",1580.8,0.0],["delete",1580.85,0.0]],"prev_change_id":23707155163}}}
[2025-04-07 08:30:32.870] [multi_sink] [info] Processing received message: {"jsonrpc":"2.0","method":"subscription","params":{"channel":"book.ETH-PERPETUAL.100ms","data":{"timestamp":1743994834482,"type":"change","change_id":23707155636,"instrument_name":"ETH-PERPETUAL","bids":[["delete",1578.85,0.0],["change",1578.8,13494.0],["change",1578.75,5160.0],["change",1578.7,923.0],["change",1578.65,7622.0],["change",1578.6,15021.0],["change",1578.55,41877.0],["new",1578.5,40988.0],["new",1578.45,2275.0],["new",1578.4,1030.0]],"asks":[["new",1579.35,12705.0],["new",1579.4,5163.0],["new",1579.55,2382.0],["new",1579.6,28582.0],["new",1579.65,3.01e4],["new",1579.7,12089.0],["new",1579.75,5.0e3],["new",1579.8,33573.0],["new",1579.85,29052.0],["delete",1580.45,0.0],["delete",1580.5,0.0],["change",1580.55,6111993.0],["delete",1580.6,0.0],["delete",1580.65,0.0],["delete",1580.7,0.0],["delete",1580.75,0.0],["delete",1580.8,0.0],["delete",1580.85,0.0]],"prev_change_id":23707155163}}}
[2025-04-07 08:30:33.192] [multi_sink] [info] 📩 Received: {"jsonrpc":"2.0","method":"subscription","params":{"channel":"book.ETH-PERPETUAL.100ms","data":{"timestamp":1743994834519,"type":"change","change_id":23707155671,"instrument_name":"ETH-PERPETUAL","bids":[["new",1578.9,5671.0]],"asks":[["new",1579.3,53457.0],["delete",1580.9,0.0]],"prev_change_id":23707155636}}}
[2025-04-07 08:30:33.196] [multi_sink] [info] Processing received message: {"jsonrpc":"2.0","method":"subscription","params":{"channel":"book.ETH-PERPETUAL.100ms","data":{"timestamp":1743994834519,"type":"change","change_id":23707155671,"instrument_name":"ETH-PERPETUAL","bids":[["new",1578.9,5671.0]],"asks":[["new",1579.3,53457.0],["delete",1580.9,0.0]],"prev_change_id":23707155636}}}
[2025-04-07 08:30:33.230] [multi_sink] [info] 📩 Received: {"jsonrpc":"2.0","method":"subscription","params":{"channel":"book.BTC-PERPETUAL.100ms","data":{"timestamp":1743994834859,"type":"change","change_id":41151906728,"instrument_name":"BTC-PERPETUAL","bids":[],"asks":[["new",78565.0,78560.0]],"prev_change_id":41151905031}}}
[2025-04-07 08:30:33.233] [multi_sink] [info] Processing received message: {"jsonrpc":"2.0","method":"subscription","params":{"channel":"book.BTC-PERPETUAL.100ms","data":{"timestamp":1743994834859,"type":"change","change_id":41151906728,"instrument_name":"BTC-PERPETUAL","bids":[],"asks":[["new",78565.0,78560.0]],"prev_change_id":41151905031}}}
[2025-04-07 08:30:33.564] [multi_sink] [info] 📩 Received: {"jsonrpc":"2.0","method":"subscription","params":{"channel":"book.BTC-PERPETUAL.100ms","data":{"timestamp":1743994834862,"type":"change","change_id":41151906729,"instrument_name":"BTC-PERPETUAL","bids":[],"asks":[["new",78615.0,117920.0]],"prev_change_id":41151906728}}}
[2025-04-07 08:30:33.565] [multi_sink] [info] Processing received message: {"jsonrpc":"2.0","method":"subscription","params":{"channel":"book.BTC-PERPETUAL.100ms","data":{"timestamp":1743994834862,"type":"change","change_id":41151906729,"instrument_name":"BTC-PERPETUAL","bids":[],"asks":[["new",78615.0,117920.0]],"prev_change_id":41151906728}}}
[2025-04-07 08:30:33.888] [multi_sink] [info] 📩 Received: {"jsonrpc":"2.0","method":"subscription","params":{"channel":"book.BTC-PERPETUAL.100ms","data":{"timestamp":1743994835503,"type":"change","change_id":41151907901,"instrument_name":"BTC-PERPETUAL","bids":[["delete",78452.5,0.0],["delete",78446.5,0.0],["delete",78446.0,0.0],["delete",78443.5,0.0],["delete",78440.5,0.0],["change",78440.0,6620.0],["new",78235.5,78230.0],["new",78185.5,117270.0]],"asks":[["delete",78453.0,0.0],["delete",78453.5,0.0],["delete",78454.0,0.0],["delete",78454.5,0.0],["delete",78455.0,0.0]],"prev_change_id":41151906729}}}
[2025-04-07 08:30:33.893] [multi_sink] [info] Processing received message: {"jsonrpc":"2.0","method":"subscription","params":{"channel":"book.BTC-PERPETUAL.100ms","data":{"timestamp":1743994835503,"type":"change","change_id":41151907901,"instrument_name":"BTC-PERPETUAL","bids":[["delete",78452.5,0.0],["delete",78446.5,0.0],["delete",78446.0,0.0],["delete",78443.5,0.0],["delete",78440.5,0.0],["change",78440.0,6620.0],["new",78235.5,78230.0],["new",78185.5,117270.0]],"asks":[["delete",78453.0,0.0],["delete",78453.5,0.0],["delete",78454.0,0.0],["delete",78454.5,0.0],["delete",78455.0,0.0]],"prev_change_id":41151906729}}}
[2025-04-07 08:30:34.218] [multi_sink] [info] 📩 Received: {"jsonrpc":"2.0","method":"subscription","params":{"channel":"book.BTC-PERPETUAL.100ms","data":{"timestamp":1743994835838,"type":"change","change_id":41151908217,"instrument_name":"BTC-PERPETUAL","bids":[["delete",78440.0,0.0],["delete",78438.5,0.0],["delete",78437.5,0.0],["delete",78437.0,0.0],["delete",78436.5,0.0],["delete",78436.0,0.0],["delete",78435.5,0.0],["delete",78433.0,0.0],["delete",78430.0,0.0],["delete",78429.5,0.0],["delete",78429.0,0.0],["delete",78428.5,0.0],["delete",78426.5,0.0],["change",78424.0,380.0]],"asks":[["new",78426.0,3.73e4],["new",78429.5,24940.0],["new",78430.0,16250.0],["delete",78455.5,0.0],["delete",78456.0,0.0],["delete",78456.5,0.0],["delete",78457.0,0.0],["delete",78457.5,0.0],["delete",78458.0,0.0],["delete",78458.5,0.0],["delete",78459.0,0.0],["delete",78460.0,0.0]],"prev_change_id":41151907901}}}
[2025-04-07 08:30:34.220] [multi_sink] [info] Processing received message: {"jsonrpc":"2.0","method":"subscription","params":{"channel":"book.BTC-PERPETUAL.100ms","data":{"timestamp":1743994835838,"type":"change","change_id":41151908217,"instrument_name":"BTC-PERPETUAL","bids":[["delete",78440.0,0.0],["delete",78438.5,0.0],["delete",78437.5,0.0],["delete",78437.0,0.0],["delete",78436.5,0.0],["delete",78436.0,0.0],["delete",78435.5,0.0],["delete",78433.0,0.0],["delete",78430.0,0.0],["delete",78429.5,0.0],["delete",78429.0,0.0],["delete",78428.5,0.0],["delete",78426.5,0.0],["change",78424.0,380.0]],"asks":[["new",78426.0,3.73e4],["new",78429.5,24940.0],["new",78430.0,16250.0],["delete",78455.5,0.0],["delete",78456.0,0.0],["delete",78456.5,0.0],["delete",78457.0,0.0],["delete",78457.5,0.0],["delete",78458.0,0.0],["delete",78458.5,0.0],["delete",78459.0,0.0],["delete",78460.0,0.0]],"prev_change_id":41151907901}}}
[2025-04-07 08:30:34.550] [multi_sink] [info] 📩 Received: {"jsonrpc":"2.0","method":"subscription","params":{"channel":"book.BTC-PERPETUAL.100ms","data":{"timestamp":1743994836067,"type":"change","change_id":41151908618,"instrument_name":"BTC-PERPETUAL","bids":[["delete",78424.0,0.0],["new",78415.0,310.0]],"asks":[["new",78415.5,186660.0],["new",78417.0,3.3e4],["new",78417.5,88110.0],["new",78418.0,54270.0],["new",78421.0,5.5e3],["new",78422.0,10070.0],["delete",78461.0,0.0],["delete",78461.5,0.0],["delete",78462.5,0.0],["delete",78463.0,0.0],["delete",78463.5,0.0],["delete",78464.0,0.0]],"prev_change_id":41151908217}}}
[2025-04-07 08:30:34.552] [multi_sink] [info] Processing received message: {"jsonrpc":"2.0","method":"subscription","params":{"channel":"book.BTC-PERPETUAL.100ms","data":{"timestamp":1743994836067,"type":"change","change_id":41151908618,"instrument_name":"BTC-PERPETUAL","bids":[["delete",78424.0,0.0],["new",78415.0,310.0]],"asks":[["new",78415.5,186660.0],["new",78417.0,3.3e4],["new",78417.5,88110.0],["new",78418.0,54270.0],["new",78421.0,5.5e3],["new",78422.0,10070.0],["delete",78461.0,0.0],["delete",78461.5,0.0],["delete",78462.5,0.0],["delete",78463.0,0.0],["delete",78463.5,0.0],["delete",78464.0,0.0]],"prev_change_id":41151908217}}}
[2025-04-07 08:30:35.832] [multi_sink] [info] 📩 Received: {"jsonrpc":"2.0","method":"subscription","params":{"channel":"book.BTC-PERPETUAL.100ms","data":{"timestamp":1743994837197,"type":"change","change_id":41151910831,"instrument_name":"BTC-PERPETUAL","bids":[["delete",78414.0,0.0],["new",78376.5,7825720.0],["delete",78261.0,0.0],["new",78223.5,8000580.0]],"asks":[],"prev_change_id":41151908618}}}
[2025-04-07 08:30:35.835] [multi_sink] [info] Processing received message: {"jsonrpc":"2.0","method":"subscription","params":{"channel":"book.BTC-PERPETUAL.100ms","data":{"timestamp":1743994837197,"type":"change","change_id":41151910831,"instrument_name":"BTC-PERPETUAL","bids":[["delete",78414.0,0.0],["new",78376.5,7825720.0],["delete",78261.0,0.0],["new",78223.5,8000580.0]],"asks":[],"prev_change_id":41151908618}}}
[2025-04-07 08:30:36.162] [multi_sink] [info] 📩 Received: {"jsonrpc":"2.0","method":"subscription","params":{"channel":"book.BTC-PERPETUAL.100ms","data":{"timestamp":1743994837529,"type":"change","change_id":41151911124,"instrument_name":"BTC-PERPETUAL","bids":[],"asks":[["new",78454.0,6640830.0],["delete",78491.5,0.0],["new",78607.0,7777770.0],["delete",78644.5,0.0]],"prev_change_id":41151910831}}}
[2025-04-07 08:30:36.163] [multi_sink] [info] Processing received message: {"jsonrpc":"2.0","method":"subscription","params":{"channel":"book.BTC-PERPETUAL.100ms","data":{"timestamp":1743994837529,"type":"change","change_id":41151911124,"instrument_name":"BTC-PERPETUAL","bids":[],"asks":[["new",78454.0,6640830.0],["delete",78491.5,0.0],["new",78607.0,7777770.0],["delete",78644.5,0.0]],"prev_change_id":41151910831}}}
[2025-04-07 08:30:36.838] [multi_sink] [info] 📩 Received: {"jsonrpc":"2.0","method":"subscription","params":{"channel":"book.BTC-PERPETUAL.100ms","data":{"timestamp":1743994838219,"type":"change","change_id":41151912310,"instrument_name":"BTC-PERPETUAL","bids":[["new",78245.5,78240.0],["delete",78235.5,0.0],["new",78195.5,117290.0],["delete",78185.5,0.0]],"asks":[["delete",78565.0,0.0],["new",78577.0,78570.0],["delete",78615.0,0.0],["new",78627.0,117940.0]],"prev_change_id":41151911124}}}
[2025-04-07 08:30:36.839] [multi_sink] [info] Processing received message: {"jsonrpc":"2.0","method":"subscription","params":{"channel":"book.BTC-PERPETUAL.100ms","data":{"timestamp":1743994838219,"type":"change","change_id":41151912310,"instrument_name":"BTC-PERPETUAL","bids":[["new",78245.5,78240.0],["delete",78235.5,0.0],["new",78195.5,117290.0],["delete",78185.5,0.0]],"asks":[["delete",78565.0,0.0],["new",78577.0,78570.0],["delete",78615.0,0.0],["new",78627.0,117940.0]],"prev_change_id":41151911124}}}
[2025-04-07 08:30:37.173] [multi_sink] [info] 📩 Received: {"jsonrpc":"2.0","method":"subscription","params":{"channel":"book.ETH-PERPETUAL.100ms","data":{"timestamp":1743994838802,"type":"change","change_id":23707160099,"instrument_name":"ETH-PERPETUAL","bids":[],"asks":[["delete",1579.3,0.0],["change",1580.25,1854.0]],"prev_change_id":23707155671}}}
[2025-04-07 08:30:37.176] [multi_sink] [info] Processing received message: {"jsonrpc":"2.0","method":"subscription","params":{"channel":"book.ETH-PERPETUAL.100ms","data":{"timestamp":1743994838802,"type":"change","change_id":23707160099,"instrument_name":"ETH-PERPETUAL","bids":[],"asks":[["delete",1579.3,0.0],["change",1580.25,1854.0]],"prev_change_id":23707155671}}}
[2025-04-07 08:30:37.316] [multi_sink] [info] 📩 Received: {"jsonrpc":"2.0","method":"subscription","params":{"channel":"book.BTC-PERPETUAL.100ms","data":{"timestamp":1743994838949,"type":"change","change_id":41151913166,"instrument_name":"BTC-PERPETUAL","bids":[],"asks":[["delete",78577.0,0.0],["new",78587.5,78580.0]],"prev_change_id":41151912310}}}
[2025-04-07 08:30:37.317] [multi_sink] [info] Processing received message: {"jsonrpc":"2.0","method":"subscription","params":{"channel":"book.BTC-PERPETUAL.100ms","data":{"timestamp":1743994838949,"type":"change","change_id":41151913166,"instrument_name":"BTC-PERPETUAL","bids":[],"asks":[["delete",78577.0,0.0],["new",78587.5,78580.0]],"prev_change_id":41151912310}}}
[2025-04-07 08:30:37.505] [multi_sink] [info] 📩 Received: {"jsonrpc":"2.0","method":"subscription","params":{"channel":"book.ETH-PERPETUAL.100ms","data":{"timestamp":1743994839104,"type":"change","change_id":23707160573,"instrument_name":"ETH-PERPETUAL","bids":[["delete",1578.9,0.0],["delete",1578.8,0.0],["delete",1578.75,0.0],["delete",1578.7,0.0],["delete",1578.65,0.0],["delete",1578.6,0.0],["delete",1578.55,0.0],["delete",1578.5,0.0],["delete",1578.45,0.0],["change",1578.25,21145.0],["change",1578.2,28468.0],["change",1578.15,8497.0],["change",1578.1,18267.0],["change",1578.05,12917.0],["change",1578.0,4846.0],["change",1577.95,83101.0],["change",1577.9,3513.0],["new",1577.85,41616.0]],"asks":[["delete",1579.35,0.0],["delete",1579.4,0.0],["delete",1579.55,0.0],["delete",1579.6,0.0],["delete",1579.65,0.0],["delete",1579.7,0.0],["delete",1579.75,0.0],["delete",1579.8,0.0],["change",1579.85,38099.0],["change",1579.9,37354.0],["change",1579.95,4852.0],["change",1580.0,30511.0],["change",1580.05,16166.0],["change",1580.1,98557.0],["change",1580.15,200.0],["change",1580.2,123562.0]],"prev_change_id":23707160099}}}
[2025-04-07 08:30:37.508] [multi_sink] [info] Processing received message: {"jsonrpc":"2.0","method":"subscription","params":{"channel":"book.ETH-PERPETUAL.100ms","data":{"timestamp":1743994839104,"type":"change","change_id":23707160573,"instrument_name":"ETH-PERPETUAL","bids":[["delete",1578.9,0.0],["delete",1578.8,0.0],["delete",1578.75,0.0],["delete",1578.7,0.0],["delete",1578.65,0.0],["delete",1578.6,0.0],["delete",1578.55,0.0],["delete",1578.5,0.0],["delete",1578.45,0.0],["change",1578.25,21145.0],["change",1578.2,28468.0],["change",1578.15,8497.0],["change",1578.1,18267.0],["change",1578.05,12917.0],["change",1578.0,4846.0],["change",1577.95,83101.0],["change",1577.9,3513.0],["new",1577.85,41616.0]],"asks":[["delete",1579.35,0.0],["delete",1579.4,0.0],["delete",1579.55,0.0],["delete",1579.6,0.0],["delete",1579.65,0.0],["delete",1579.7,0.0],["delete",1579.75,0.0],["delete",1579.8,0.0],["change",1579.85,38099.0],["change",1579.9,37354.0],["change",1579.95,4852.0],["change",1580.0,30511.0],["change",1580.05,16166.0],["change",1580.1,98557.0],["change",1580.15,200.0],["change",1580.2,123562.0]],"prev_change_id":23707160099}}}
[2025-04-07 08:30:37.649] [multi_sink] [info] 📩 Received: {"jsonrpc":"2.0","method":"subscription","params":{"channel":"book.BTC-PERPETUAL.100ms","data":{"timestamp":1743994838951,"type":"change","change_id":41151913167,"instrument_name":"BTC-PERPETUAL","bids":[],"asks":[["delete",78627.0,0.0],["new",78637.5,117940.0]],"prev_change_id":41151913166}}}
[2025-04-07 08:30:37.650] [multi_sink] [info] Processing received message: {"jsonrpc":"2.0","method":"subscription","params":{"channel":"book.BTC-PERPETUAL.100ms","data":{"timestamp":1743994838951,"type":"change","change_id":41151913167,"instrument_name":"BTC-PERPETUAL","bids":[],"asks":[["delete",78627.0,0.0],["new",78637.5,117940.0]],"prev_change_id":41151913166}}}
[2025-04-07 08:30:37.830] [multi_sink] [info] 📩 Received: {"jsonrpc":"2.0","method":"subscription","params":{"channel":"book.ETH-PERPETUAL.100ms","data":{"timestamp":1743994839450,"type":"change","change_id":23707160929,"instrument_name":"ETH-PERPETUAL","bids":[["new",1578.7,19748.0],["new",1578.65,23426.0],["new",1578.6,28085.0],["new",1578.55,13101.0],["new",1578.5,7551.0],["new",1578.45,66264.0],["change",1578.4,7.14e4],["change",1578.35,9695.0],["change",1578.3,1.9e4],["change",1578.25,12201.0],["change",1578.2,1558.0],["change",1578.15,4394.0],["change",1578.1,7954.0],["change",1578.05,4410.0],["change",1578.0,3816.0]],"asks":[["new",1579.3,9910.0],["new",1579.45,100.0],["new",1579.5,2295.0],["new",1579.55,100.0],["new",1579.6,45142.0],["new",1579.65,38027.0],["new",1579.7,83314.0],["new",1579.75,1027.0],["new",1579.8,15847.0],["change",1579.85,9047.0],["change",1579.9,28932.0],["change",1579.95,3440.0],["change",1580.0,17433.0],["change",1580.05,8461.0],["change",1580.1,41564.0],["change",1580.15,100.0],["change",1580.2,40303.0],["change",1580.25,927.0]],"prev_change_id":23707160573}}}
[2025-04-07 08:30:37.832] [multi_sink] [info] Processing received message: {"jsonrpc":"2.0","method":"subscription","params":{"channel":"book.ETH-PERPETUAL.100ms","data":{"timestamp":1743994839450,"type":"change","change_id":23707160929,"instrument_name":"ETH-PERPETUAL","bids":[["new",1578.7,19748.0],["new",1578.65,23426.0],["new",1578.6,28085.0],["new",1578.55,13101.0],["new",1578.5,7551.0],["new",1578.45,66264.0],["change",1578.4,7.14e4],["change",1578.35,9695.0],["change",1578.3,1.9e4],["change",1578.25,12201.0],["change",1578.2,1558.0],["change",1578.15,4394.0],["change",1578.1,7954.0],["change",1578.05,4410.0],["change",1578.0,3816.0]],"asks":[["new",1579.3,9910.0],["new",1579.45,100.0],["new",1579.5,2295.0],["new",1579.55,100.0],["new",1579.6,45142.0],["new",1579.65,38027.0],["new",1579.7,83314.0],["new",1579.75,1027.0],["new",1579.8,15847.0],["change",1579.85,9047.0],["change",1579.9,28932.0],["change",1579.95,3440.0],["change",1580.0,17433.0],["change",1580.05,8461.0],["change",1580.1,41564.0],["change",1580.15,100.0],["change",1580.2,40303.0],["change",1580.25,927.0]],"prev_change_id":23707160573}}}
[2025-04-07 08:30:38.113] [multi_sink] [info] 📩 Received: {"jsonrpc":"2.0","method":"subscription","params":{"channel":"book.BTC-PERPETUAL.100ms","data":{"timestamp":1743994839745,"type":"change","change_id":41151914135,"instrument_name":"BTC-PERPETUAL","bids":[["delete",78245.5,0.0]],"asks":[],"prev_change_id":41151913167}}}
[2025-04-07 08:30:38.116] [multi_sink] [info] Processing received message: {"jsonrpc":"2.0","method":"subscription","params":{"channel":"book.BTC-PERPETUAL.100ms","data":{"timestamp":1743994839745,"type":"change","change_id":41151914135,"instrument_name":"BTC-PERPETUAL","bids":[["delete",78245.5,0.0]],"asks":[],"prev_change_id":41151913167}}}
[2025-04-07 08:30:38.165] [multi_sink] [info] 📩 Received: {"jsonrpc":"2.0","method":"subscription","params":{"channel":"book.ETH-PERPETUAL.100ms","data":{"timestamp":1743994839523,"type":"change","change_id":23707161066,"instrument_name":"ETH-PERPETUAL","bids":[["change",1579.05,7744514.0],["new",1578.8,44644.0],["new",1578.75,51835.0],["change",1577.95,22053.0],["change",1577.9,2583.0]],"asks":[["new",1579.25,2973.0],["delete",1580.3,0.0],["delete",1580.35,0.0]],"prev_change_id":23707160929}}}
[2025-04-07 08:30:38.169] [multi_sink] [info] Processing received message: {"jsonrpc":"2.0","method":"subscription","params":{"channel":"book.ETH-PERPETUAL.100ms","data":{"timestamp":1743994839523,"type":"change","change_id":23707161066,"instrument_name":"ETH-PERPETUAL","bids":[["change",1579.05,7744514.0],["new",1578.8,44644.0],["new",1578.75,51835.0],["change",1577.95,22053.0],["change",1577.9,2583.0]],"asks":[["new",1579.25,2973.0],["delete",1580.3,0.0],["delete",1580.35,0.0]],"prev_change_id":23707160929}}}
[2025-04-07 08:30:38.445] [multi_sink] [info] 📩 Received: {"jsonrpc":"2.0","method":"subscription","params":{"channel":"book.BTC-PERPETUAL.100ms","data":{"timestamp":1743994839750,"type":"change","change_id":41151914136,"instrument_name":"BTC-PERPETUAL","bids":[["delete",78195.5,0.0]],"asks":[],"prev_change_id":41151914135}}}
[2025-04-07 08:30:38.448] [multi_sink] [info] Processing received message: {"jsonrpc":"2.0","method":"subscription","params":{"channel":"book.BTC-PERPETUAL.100ms","data":{"timestamp":1743994839750,"type":"change","change_id":41151914136,"instrument_name":"BTC-PERPETUAL","bids":[["delete",78195.5,0.0]],"asks":[],"prev_change_id":41151914135}}}
[2025-04-07 08:30:38.495] [multi_sink] [info] 📩 Received: {"jsonrpc":"2.0","method":"subscription","params":{"channel":"book.ETH-PERPETUAL.100ms","data":{"timestamp":1743994839838,"type":"change","change_id":23707161403,"instrument_name":"ETH-PERPETUAL","bids":[["delete",1579.05,0.0],["change",1578.1,7752468.0]],"asks":[],"prev_change_id":23707161066}}}
[2025-04-07 08:30:38.496] [multi_sink] [info] Processing received message: {"jsonrpc":"2.0","method":"subscription","params":{"channel":"book.ETH-PERPETUAL.100ms","data":{"timestamp":1743994839838,"type":"change","change_id":23707161403,"instrument_name":"ETH-PERPETUAL","bids":[["delete",1579.05,0.0],["change",1578.1,7752468.0]],"asks":[],"prev_change_id":23707161066}}}
[2025-04-07 08:30:38.783] [multi_sink] [info] 📩 Received: {"jsonrpc":"2.0","method":"subscription","params":{"channel":"book.BTC-PERPETUAL.100ms","data":{"timestamp":1743994840397,"type":"change","change_id":41151915328,"instrument_name":"BTC-PERPETUAL","bids":[["delete",78415.0,0.0],["new",78395.5,8.31e4],["new",78395.0,1010.0],["new",78265.0,78260.0],["new",78215.0,117320.0]],"asks":[["delete",78415.5,0.0],["delete",78417.0,0.0],["new",78448.0,4940.0],["new",78448.5,8560.0]],"prev_change_id":41151914136}}}
[2025-04-07 08:30:38.785] [multi_sink] [info] Processing received message: {"jsonrpc":"2.0","method":"subscription","params":{"channel":"book.BTC-PERPETUAL.100ms","data":{"timestamp":1743994840397,"type":"change","change_id":41151915328,"instrument_name":"BTC-PERPETUAL","bids":[["delete",78415.0,0.0],["new",78395.5,8.31e4],["new",78395.0,1010.0],["new",78265.0,78260.0],["new",78215.0,117320.0]],"asks":[["delete",78415.5,0.0],["delete",78417.0,0.0],["new",78448.0,4940.0],["new",78448.5,8560.0]],"prev_change_id":41151914136}}}
[2025-04-07 08:30:38.835] [multi_sink] [info] 📩 Received: {"jsonrpc":"2.0","method":"subscription","params":{"channel":"book.ETH-PERPETUAL.100ms","data":{"timestamp":1743994840179,"type":"change","change_id":23707161836,"instrument_name":"ETH-PERPETUAL","bids":[],"asks":[["change",1579.6,6157135.0],["delete",1580.55,0.0]],"prev_change_id":23707161403}}}
[2025-04-07 08:30:38.838] [multi_sink] [info] Processing received message: {"jsonrpc":"2.0","method":"subscription","params":{"channel":"book.ETH-PERPETUAL.100ms","data":{"timestamp":1743994840179,"type":"change","change_id":23707161836,"instrument_name":"ETH-PERPETUAL","bids":[],"asks":[["change",1579.6,6157135.0],["delete",1580.55,0.0]],"prev_change_id":23707161403}}}
[2025-04-07 08:30:39.105] [multi_sink] [info] 📩 Received: {"jsonrpc":"2.0","method":"subscription","params":{"channel":"book.BTC-PERPETUAL.100ms","data":{"timestamp":1743994840737,"type":"change","change_id":41151915580,"instrument_name":"BTC-PERPETUAL","bids":[["new",78409.5,10.0],["new",78405.0,430.0],["new",78404.0,6.96e4],["new",78403.5,3.5e4],["new",78402.5,2490.0],["new",78402.0,184840.0],["new",7.84e4,30720.0],["new",78398.0,1750.0],["new",78397.5,5830.0]],"asks":[["delete",78417.5,0.0],["delete",78418.0,0.0],["delete",78421.0,0.0],["delete",78422.0,0.0],["delete",78426.0,0.0],["delete",78429.5,0.0],["delete",78430.0,0.0],["new",78438.0,5740.0],["new",78439.5,490.0],["new",78440.0,110.0],["new",78444.5,35930.0],["new",78446.5,16750.0],["new",78447.0,27990.0],["new",78447.5,7.08e4]],"prev_change_id":41151915328}}}
[2025-04-07 08:30:39.107] [multi_sink] [info] Processing received message: {"jsonrpc":"2.0","method":"subscription","params":{"channel":"book.BTC-PERPETUAL.100ms","data":{"timestamp":1743994840737,"type":"change","change_id":41151915580,"instrument_name":"BTC-PERPETUAL","bids":[["new",78409.5,10.0],["new",78405.0,430.0],["new",78404.0,6.96e4],["new",78403.5,3.5e4],["new",78402.5,2490.0],["new",78402.0,184840.0],["new",7.84e4,30720.0],["new",78398.0,1750.0],["new",78397.5,5830.0]],"asks":[["delete",78417.5,0.0],["delete",78418.0,0.0],["delete",78421.0,0.0],["delete",78422.0,0.0],["delete",78426.0,0.0],["delete",78429.5,0.0],["delete",78430.0,0.0],["new",78438.0,5740.0],["new",78439.5,490.0],["new",78440.0,110.0],["new",78444.5,35930.0],["new",78446.5,16750.0],["new",78447.0,27990.0],["new",78447.5,7.08e4]],"prev_change_id":41151915328}}}
[2025-04-07 08:30:39.434] [multi_sink] [info] 📩 Received: {"jsonrpc":"2.0","method":"subscription","params":{"channel":"book.BTC-PERPETUAL.100ms","data":{"timestamp":1743994841059,"type":"change","change_id":41151916072,"instrument_name":"BTC-PERPETUAL","bids":[["new",78414.5,16490.0],["new",78414.0,26420.0],["new",78413.5,62620.0],["new",78412.5,9440.0],["new",78411.5,65060.0],["new",78411.0,60470.0],["new",78410.5,2.19e4],["new",78410.0,60920.0],["delete",78265.0,0.0],["new",78254.0,78250.0],["delete",78215.0,0.0],["new",78204.0,1.173e5]],"asks":[["new",78416.5,190.0],["new",78419.0,200.0],["new",78421.5,220.0],["new",78428.0,6.0e3],["new",78434.5,2830.0],["new",78435.0,9440.0],["new",78436.5,4.8e3],["new",78437.0,250.0],["new",78437.5,1.0e4]],"prev_change_id":41151915580}}}
[2025-04-07 08:30:39.436] [multi_sink] [info] Processing received message: {"jsonrpc":"2.0","method":"subscription","params":{"channel":"book.BTC-PERPETUAL.100ms","data":{"timestamp":1743994841059,"type":"change","change_id":41151916072,"instrument_name":"BTC-PERPETUAL","bids":[["new",78414.5,16490.0],["new",78414.0,26420.0],["new",78413.5,62620.0],["new",78412.5,9440.0],["new",78411.5,65060.0],["new",78411.0,60470.0],["new",78410.5,2.19e4],["new",78410.0,60920.0],["delete",78265.0,0.0],["new",78254.0,78250.0],["delete",78215.0,0.0],["new",78204.0,1.173e5]],"asks":[["new",78416.5,190.0],["new",78419.0,200.0],["new",78421.5,220.0],["new",78428.0,6.0e3],["new",78434.5,2830.0],["new",78435.0,9440.0],["new",78436.5,4.8e3],["new",78437.0,250.0],["new",78437.5,1.0e4]],"prev_change_id":41151915580}}}
[2025-04-07 08:30:39.764] [multi_sink] [info] 📩 Received: {"jsonrpc":"2.0","method":"subscription","params":{"channel":"book.BTC-PERPETUAL.100ms","data":{"timestamp":1743994841079,"type":"change","change_id":41151916079,"instrument_name":"BTC-PERPETUAL","bids":[["new",78416.0,137250.0]],"asks":[],"prev_change_id":41151916072}}}
[2025-04-07 08:30:39.767] [multi_sink] [info] Processing received message: {"jsonrpc":"2.0","method":"subscription","params":{"channel":"book.BTC-PERPETUAL.100ms","data":{"timestamp":1743994841079,"type":"change","change_id":41151916079,"instrument_name":"BTC-PERPETUAL","bids":[["new",78416.0,137250.0]],"asks":[],"prev_change_id":41151916072}}}
[2025-04-07 08:30:40.866] [multi_sink] [info] 📩 Received: {"jsonrpc":"2.0","method":"subscription","params":{"channel":"book.BTC-PERPETUAL.100ms","data":{"timestamp":1743994842424,"type":"change","change_id":41151918453,"instrument_name":"BTC-PERPETUAL","bids":[["delete",78254.0,0.0],["new",78242.0,78240.0],["delete",78204.0,0.0],["new",78192.0,117280.0]],"asks":[["new",78577.0,78570.0],["delete",78587.5,0.0],["new",78627.0,117940.0],["delete",78637.5,0.0]],"prev_change_id":41151916079}}}
[2025-04-07 08:30:40.870] [multi_sink] [info] Processing received message: {"jsonrpc":"2.0","method":"subscription","params":{"channel":"book.BTC-PERPETUAL.100ms","data":{"timestamp":1743994842424,"type":"change","change_id":41151918453,"instrument_name":"BTC-PERPETUAL","bids":[["delete",78254.0,0.0],["new",78242.0,78240.0],["delete",78204.0,0.0],["new",78192.0,117280.0]],"asks":[["new",78577.0,78570.0],["delete",78587.5,0.0],["new",78627.0,117940.0],["delete",78637.5,0.0]],"prev_change_id":41151916079}}}
[2025-04-07 08:30:42.219] [multi_sink] [info] 📩 Received: {"jsonrpc":"2.0","method":"subscription","params":{"channel":"book.BTC-PERPETUAL.100ms","data":{"timestamp":1743994843756,"type":"change","change_id":41151920076,"instrument_name":"BTC-PERPETUAL","bids":[],"asks":[["new",78567.0,78560.0],["delete",78577.0,0.0],["new",78617.0,117920.0],["delete",78627.0,0.0]],"prev_change_id":41151918453}}}
[2025-04-07 08:30:42.220] [multi_sink] [info] Processing received message: {"jsonrpc":"2.0","method":"subscription","params":{"channel":"book.BTC-PERPETUAL.100ms","data":{"timestamp":1743994843756,"type":"change","change_id":41151920076,"instrument_name":"BTC-PERPETUAL","bids":[],"asks":[["new",78567.0,78560.0],["delete",78577.0,0.0],["new",78617.0,117920.0],["delete",78627.0,0.0]],"prev_change_id":41151918453}}}
[2025-04-07 08:30:42.286] [multi_sink] [info] 📩 Received: {"jsonrpc":"2.0","method":"subscription","params":{"channel":"book.ETH-PERPETUAL.100ms","data":{"timestamp":1743994843881,"type":"change","change_id":23707165476,"instrument_name":"ETH-PERPETUAL","bids":[["delete",1578.8,0.0],["delete",1578.75,0.0],["delete",1578.7,0.0],["change",1578.05,5338.0],["change",1578.0,4846.0],["change",1577.95,36945.0]],"asks":[["delete",1579.25,0.0],["delete",1579.3,0.0],["delete",1579.45,0.0],["change",1579.95,40581.0],["change",1580.0,80379.0],["change",1580.05,26397.0]],"prev_change_id":23707161836}}}
[2025-04-07 08:30:42.288] [multi_sink] [info] Processing received message: {"jsonrpc":"2.0","method":"subscription","params":{"channel":"book.ETH-PERPETUAL.100ms","data":{"timestamp":1743994843881,"type":"change","change_id":23707165476,"instrument_name":"ETH-PERPETUAL","bids":[["delete",1578.8,0.0],["delete",1578.75,0.0],["delete",1578.7,0.0],["change",1578.05,5338.0],["change",1578.0,4846.0],["change",1577.95,36945.0]],"asks":[["delete",1579.25,0.0],["delete",1579.3,0.0],["delete",1579.45,0.0],["change",1579.95,40581.0],["change",1580.0,80379.0],["change",1580.05,26397.0]],"prev_change_id":23707161836}}}
[2025-04-07 08:30:42.622] [multi_sink] [info] 📩 Received: {"jsonrpc":"2.0","method":"subscription","params":{"channel":"book.ETH-PERPETUAL.100ms","data":{"timestamp":1743994844221,"type":"change","change_id":23707165866,"instrument_name":"ETH-PERPETUAL","bids":[["delete",1578.65,0.0],["delete",1578.6,0.0],["delete",1578.55,0.0],["change",1578.5,100.0],["change",1578.45,63701.0],["change",1578.4,15167.0],["change",1578.35,42598.0],["change",1578.3,8577.0],["change",1578.25,1026.0],["change",1578.2,2839.0],["change",1578.15,7.7e3],["change",1578.1,7754745.0]],"asks":[["new",1579.45,10925.0],["change",1579.5,10614.0],["delete",1579.55,0.0],["change",1579.6,6125995.0],["change",1579.65,39892.0],["change",1579.7,9933.0],["change",1579.75,91.0],["change",1579.8,1512.0],["change",1579.85,927.0],["change",1579.9,927.0]],"prev_change_id":23707165476}}}
[2025-04-07 08:30:42.625] [multi_sink] [info] Processing received message: {"jsonrpc":"2.0","method":"subscription","params":{"channel":"book.ETH-PERPETUAL.100ms","data":{"timestamp":1743994844221,"type":"change","change_id":23707165866,"instrument_name":"ETH-PERPETUAL","bids":[["delete",1578.65,0.0],["delete",1578.6,0.0],["delete",1578.55,0.0],["change",1578.5,100.0],["change",1578.45,63701.0],["change",1578.4,15167.0],["change",1578.35,42598.0],["change",1578.3,8577.0],["change",1578.25,1026.0],["change",1578.2,2839.0],["change",1578.15,7.7e3],["change",1578.1,7754745.0]],"asks":[["new",1579.45,10925.0],["change",1579.5,10614.0],["delete",1579.55,0.0],["change",1579.6,6125995.0],["change",1579.65,39892.0],["change",1579.7,9933.0],["change",1579.75,91.0],["change",1579.8,1512.0],["change",1579.85,927.0],["change",1579.9,927.0]],"prev_change_id":23707165476}}}
[2025-04-07 08:30:42.865] [multi_sink] [info] 📩 Received: {"jsonrpc":"2.0","method":"subscription","params":{"channel":"book.BTC-PERPETUAL.100ms","data":{"timestamp":1743994844426,"type":"change","change_id":41151921198,"instrument_name":"BTC-PERPETUAL","bids":[["delete",78376.5,0.0],["new",78371.5,7825720.0],["delete",78223.5,0.0],["new",78218.5,8000580.0]],"asks":[],"prev_change_id":41151920076}}}
[2025-04-07 08:30:42.869] [multi_sink] [info] Processing received message: {"jsonrpc":"2.0","method":"subscription","params":{"channel":"book.BTC-PERPETUAL.100ms","data":{"timestamp":1743994844426,"type":"change","change_id":41151921198,"instrument_name":"BTC-PERPETUAL","bids":[["delete",78376.5,0.0],["new",78371.5,7825720.0],["delete",78223.5,0.0],["new",78218.5,8000580.0]],"asks":[],"prev_change_id":41151920076}}}
[2025-04-07 08:30:42.949] [multi_sink] [info] 📩 Received: {"jsonrpc":"2.0","method":"subscription","params":{"channel":"book.ETH-PERPETUAL.100ms","data":{"timestamp":1743994844525,"type":"change","change_id":23707166220,"instrument_name":"ETH-PERPETUAL","bids":[["new",1579.0,2442.0],["new",1578.95,79738.0],["new",1578.9,12999.0],["new",1578.8,6051.0],["new",1578.75,5.0e3],["new",1578.7,1796.0],["new",1578.65,3378.0],["new",1578.55,10926.0],["change",1578.2,1281.0],["change",1578.15,3306.0],["change",1578.1,7746791.0],["change",1578.05,928.0],["change",1578.0,1030.0],["change",1577.95,14892.0],["delete",1577.9,0.0],["delete",1577.85,0.0]],"asks":[["new",1579.05,7576.0],["new",1579.1,12737.0],["new",1579.15,11757.0],["new",1579.2,5.1e3],["new",1579.25,12997.0],["new",1579.3,27268.0],["new",1579.35,100.0],["new",1579.4,5122.0],["change",1579.95,37141.0],["change",1580.0,62946.0],["change",1580.05,17936.0],["delete",1580.1,0.0],["delete",1580.15,0.0],["delete",1580.2,0.0],["delete",1580.25,0.0]],"prev_change_id":23707165866}}}
[2025-04-07 08:30:42.952] [multi_sink] [info] Processing received message: {"jsonrpc":"2.0","method":"subscription","params":{"channel":"book.ETH-PERPETUAL.100ms","data":{"timestamp":1743994844525,"type":"change","change_id":23707166220,"instrument_name":"ETH-PERPETUAL","bids":[["new",1579.0,2442.0],["new",1578.95,79738.0],["new",1578.9,12999.0],["new",1578.8,6051.0],["new",1578.75,5.0e3],["new",1578.7,1796.0],["new",1578.65,3378.0],["new",1578.55,10926.0],["change",1578.2,1281.0],["change",1578.15,3306.0],["change",1578.1,7746791.0],["change",1578.05,928.0],["change",1578.0,1030.0],["change",1577.95,14892.0],["delete",1577.9,0.0],["delete",1577.85,0.0]],"asks":[["new",1579.05,7576.0],["new",1579.1,12737.0],["new",1579.15,11757.0],["new",1579.2,5.1e3],["new",1579.25,12997.0],["new",1579.3,27268.0],["new",1579.35,100.0],["new",1579.4,5122.0],["change",1579.95,37141.0],["change",1580.0,62946.0],["change",1580.05,17936.0],["delete",1580.1,0.0],["delete",1580.15,0.0],["delete",1580.2,0.0],["delete",1580.25,0.0]],"prev_change_id":23707165866}}}
[2025-04-07 08:30:43.195] [multi_sink] [info] 📩 Received: {"jsonrpc":"2.0","method":"subscription","params":{"channel":"book.BTC-PERPETUAL.100ms","data":{"timestamp":1743994844755,"type":"change","change_id":41151921420,"instrument_name":"BTC-PERPETUAL","bids":[],"asks":[["new",78449.0,6640830.0],["delete",78454.0,0.0],["new",78602.0,7777770.0],["delete",78607.0,0.0]],"prev_change_id":41151921198}}}
[2025-04-07 08:30:43.196] [multi_sink] [info] Processing received message: {"jsonrpc":"2.0","method":"subscription","params":{"channel":"book.BTC-PERPETUAL.100ms","data":{"timestamp":1743994844755,"type":"change","change_id":41151921420,"instrument_name":"BTC-PERPETUAL","bids":[],"asks":[["new",78449.0,6640830.0],["delete",78454.0,0.0],["new",78602.0,7777770.0],["delete",78607.0,0.0]],"prev_change_id":41151921198}}}
[2025-04-07 08:30:43.863] [multi_sink] [info] 📩 Received: {"jsonrpc":"2.0","method":"subscription","params":{"channel":"book.BTC-PERPETUAL.100ms","data":{"timestamp":1743994845473,"type":"change","change_id":41151922596,"instrument_name":"BTC-PERPETUAL","bids":[["delete",78416.0,0.0],["delete",78414.5,0.0],["delete",78414.0,0.0],["delete",78413.5,0.0],["new",78388.0,15710.0],["new",78387.5,17510.0],["new",78386.0,34840.0],["new",78384.0,3430.0]],"asks":[["delete",78416.5,0.0],["delete",78419.0,0.0],["delete",78421.5,0.0],["new",78424.5,34840.0],["new",78425.0,480.0],["new",78427.0,13760.0],["new",78427.5,81640.0],["delete",78428.0,0.0]],"prev_change_id":41151921420}}}
[2025-04-07 08:30:43.866] [multi_sink] [info] Processing received message: {"jsonrpc":"2.0","method":"subscription","params":{"channel":"book.BTC-PERPETUAL.100ms","data":{"timestamp":1743994845473,"type":"change","change_id":41151922596,"instrument_name":"BTC-PERPETUAL","bids":[["delete",78416.0,0.0],["delete",78414.5,0.0],["delete",78414.0,0.0],["delete",78413.5,0.0],["new",78388.0,15710.0],["new",78387.5,17510.0],["new",78386.0,34840.0],["new",78384.0,3430.0]],"asks":[["delete",78416.5,0.0],["delete",78419.0,0.0],["delete",78421.5,0.0],["new",78424.5,34840.0],["new",78425.0,480.0],["new",78427.0,13760.0],["new",78427.5,81640.0],["delete",78428.0,0.0]],"prev_change_id":41151921420}}}
[2025-04-07 08:30:44.187] [multi_sink] [info] 📩 Received: {"jsonrpc":"2.0","method":"subscription","params":{"channel":"book.BTC-PERPETUAL.100ms","data":{"timestamp":1743994845811,"type":"change","change_id":41151922916,"instrument_name":"BTC-PERPETUAL","bids":[["delete",78412.5,0.0],["delete",78411.5,0.0],["delete",78411.0,0.0],["delete",78410.5,0.0],["delete",78410.0,0.0],["delete",78409.5,0.0],["delete",78405.0,0.0],["delete",78404.0,0.0],["delete",78403.5,0.0],["new",78396.0,9440.0],["change",78395.0,2020.0],["new",78394.5,510.0],["new",78393.0,480.0],["new",78392.0,12770.0],["new",78390.5,16490.0],["new",78390.0,16490.0],["new",78389.5,490.0],["new",78389.0,5740.0]],"asks":[["new",78416.5,27830.0],["new",78419.0,6270.0],["new",78419.5,1.0e4],["new",78420.0,83160.0],["new",78420.5,4590.0],["new",78421.0,14640.0],["new",78421.5,220.0],["new",78424.0,37440.0],["delete",78434.5,0.0],["delete",78435.0,0.0],["delete",78436.5,0.0],["delete",78437.0,0.0],["delete",78437.5,0.0],["delete",78438.0,0.0],["delete",78439.5,0.0],["delete",78440.0,0.0],["delete",78444.5,0.0]],"prev_change_id":41151922596}}}
[2025-04-07 08:30:44.191] [multi_sink] [info] Processing received message: {"jsonrpc":"2.0","method":"subscription","params":{"channel":"book.BTC-PERPETUAL.100ms","data":{"timestamp":1743994845811,"type":"change","change_id":41151922916,"instrument_name":"BTC-PERPETUAL","bids":[["delete",78412.5,0.0],["delete",78411.5,0.0],["delete",78411.0,0.0],["delete",78410.5,0.0],["delete",78410.0,0.0],["delete",78409.5,0.0],["delete",78405.0,0.0],["delete",78404.0,0.0],["delete",78403.5,0.0],["new",78396.0,9440.0],["change",78395.0,2020.0],["new",78394.5,510.0],["new",78393.0,480.0],["new",78392.0,12770.0],["new",78390.5,16490.0],["new",78390.0,16490.0],["new",78389.5,490.0],["new",78389.0,5740.0]],"asks":[["new",78416.5,27830.0],["new",78419.0,6270.0],["new",78419.5,1.0e4],["new",78420.0,83160.0],["new",78420.5,4590.0],["new",78421.0,14640.0],["new",78421.5,220.0],["new",78424.0,37440.0],["delete",78434.5,0.0],["delete",78435.0,0.0],["delete",78436.5,0.0],["delete",78437.0,0.0],["delete",78437.5,0.0],["delete",78438.0,0.0],["delete",78439.5,0.0],["delete",78440.0,0.0],["delete",78444.5,0.0]],"prev_change_id":41151922596}}}
[2025-04-07 08:30:44.517] [multi_sink] [info] 📩 Received: {"jsonrpc":"2.0","method":"subscription","params":{"channel":"book.BTC-PERPETUAL.100ms","data":{"timestamp":1743994846074,"type":"change","change_id":41151923329,"instrument_name":"BTC-PERPETUAL","bids":[["new",78410.0,1150.0],["change",78402.5,2020.0],["change",78402.0,390.0],["delete",7.84e4,0.0],["new",78399.5,430.0],["delete",78398.0,0.0],["change",78397.5,70.0],["new",78397.0,470.0],["new",78396.5,2830.0],["delete",78395.5,0.0],["change",78395.0,1010.0]],"asks":[["new",78410.5,103870.0],["new",78411.0,2.19e4],["new",78411.5,10160.0],["new",78412.0,9440.0],["new",78414.0,170.0],["new",78415.5,3.3e4],["new",78416.0,46540.0],["delete",78446.5,0.0],["delete",78447.0,0.0],["delete",78447.5,0.0],["delete",78448.0,0.0],["delete",78448.5,0.0]],"prev_change_id":41151922916}}}
[2025-04-07 08:30:44.518] [multi_sink] [info] Processing received message: {"jsonrpc":"2.0","method":"subscription","params":{"channel":"book.BTC-PERPETUAL.100ms","data":{"timestamp":1743994846074,"type":"change","change_id":41151923329,"instrument_name":"BTC-PERPETUAL","bids":[["new",78410.0,1150.0],["change",78402.5,2020.0],["change",78402.0,390.0],["delete",7.84e4,0.0],["new",78399.5,430.0],["delete",78398.0,0.0],["change",78397.5,70.0],["new",78397.0,470.0],["new",78396.5,2830.0],["delete",78395.5,0.0],["change",78395.0,1010.0]],"asks":[["new",78410.5,103870.0],["new",78411.0,2.19e4],["new",78411.5,10160.0],["new",78412.0,9440.0],["new",78414.0,170.0],["new",78415.5,3.3e4],["new",78416.0,46540.0],["delete",78446.5,0.0],["delete",78447.0,0.0],["delete",78447.5,0.0],["delete",78448.0,0.0],["delete",78448.5,0.0]],"prev_change_id":41151922916}}}
[2025-04-07 08:30:44.855] [multi_sink] [info] 📩 Received: {"jsonrpc":"2.0","method":"subscription","params":{"channel":"book.BTC-PERPETUAL.100ms","data":{"timestamp":1743994846168,"type":"change","change_id":41151923360,"instrument_name":"BTC-PERPETUAL","bids":[["delete",78242.0,0.0],["new",78230.0,78230.0],["delete",78192.0,0.0],["new",78180.0,117270.0]],"asks":[],"prev_change_id":41151923329}}}
[2025-04-07 08:30:44.858] [multi_sink] [info] Processing received message: {"jsonrpc":"2.0","method":"subscription","params":{"channel":"book.BTC-PERPETUAL.100ms","data":{"timestamp":1743994846168,"type":"change","change_id":41151923360,"instrument_name":"BTC-PERPETUAL","bids":[["delete",78242.0,0.0],["new",78230.0,78230.0],["delete",78192.0,0.0],["new",78180.0,117270.0]],"asks":[],"prev_change_id":41151923329}}}
[2025-04-07 08:30:47.326] [multi_sink] [info] 📩 Received: {"jsonrpc":"2.0","method":"subscription","params":{"channel":"book.ETH-PERPETUAL.100ms","data":{"timestamp":1743994848949,"type":"change","change_id":23707170788,"instrument_name":"ETH-PERPETUAL","bids":[["delete",1579.0,0.0],["delete",1578.95,0.0],["delete",1578.9,0.0],["delete",1578.8,0.0],["delete",1578.75,0.0],["new",1577.9,9501.0],["new",1577.85,38345.0],["new",1577.8,928.0],["new",1577.75,3936.0],["new",1577.7,9099.0]],"asks":[["delete",1579.05,0.0],["delete",1579.1,0.0],["delete",1579.15,0.0],["delete",1579.2,0.0],["delete",1579.25,0.0],["change",1579.65,162394.0],["change",1579.7,68809.0],["change",1579.75,365.0],["change",1579.8,2639.0],["change",1579.85,1854.0]],"prev_change_id":23707166220}}}
[2025-04-07 08:30:47.329] [multi_sink] [info] Processing received message: {"jsonrpc":"2.0","method":"subscription","params":{"channel":"book.ETH-PERPETUAL.100ms","data":{"timestamp":1743994848949,"type":"change","change_id":23707170788,"instrument_name":"ETH-PERPETUAL","bids":[["delete",1579.0,0.0],["delete",1578.95,0.0],["delete",1578.9,0.0],["delete",1578.8,0.0],["delete",1578.75,0.0],["new",1577.9,9501.0],["new",1577.85,38345.0],["new",1577.8,928.0],["new",1577.75,3936.0],["new",1577.7,9099.0]],"asks":[["delete",1579.05,0.0],["delete",1579.1,0.0],["delete",1579.15,0.0],["delete",1579.2,0.0],["delete",1579.25,0.0],["change",1579.65,162394.0],["change",1579.7,68809.0],["change",1579.75,365.0],["change",1579.8,2639.0],["change",1579.85,1854.0]],"prev_change_id":23707166220}}}
[2025-04-07 08:30:47.622] [multi_sink] [info] 📩 Received: {"jsonrpc":"2.0","method":"subscription","params":{"channel":"book.BTC-PERPETUAL.100ms","data":{"timestamp":1743994849255,"type":"change","change_id":41151928180,"instrument_name":"BTC-PERPETUAL","bids":[["new",78241.0,78240.0],["delete",78230.0,0.0]],"asks":[],"prev_change_id":41151923360}}}
[2025-04-07 08:30:47.623] [multi_sink] [info] Processing received message: {"jsonrpc":"2.0","method":"subscription","params":{"channel":"book.BTC-PERPETUAL.100ms","data":{"timestamp":1743994849255,"type":"change","change_id":41151928180,"instrument_name":"BTC-PERPETUAL","bids":[["new",78241.0,78240.0],["delete",78230.0,0.0]],"asks":[],"prev_change_id":41151923360}}}
[2025-04-07 08:30:47.653] [multi_sink] [info] 📩 Received: {"jsonrpc":"2.0","method":"subscription","params":{"channel":"book.ETH-PERPETUAL.100ms","data":{"timestamp":1743994849274,"type":"change","change_id":23707170934,"instrument_name":"ETH-PERPETUAL","bids":[["delete",1578.7,0.0],["delete",1578.65,0.0],["delete",1578.55,0.0],["delete",1578.5,0.0],["delete",1578.45,0.0],["change",1578.4,85392.0],["delete",1578.35,0.0],["change",1578.3,7438.0],["change",1578.25,1026.0],["change",1578.2,2562.0],["change",1578.15,4232.0],["change",1578.1,7748894.0],["change",1578.05,1856.0],["change",1578.0,15506.0],["change",1577.95,76248.0]],"asks":[["new",1579.2,6558.0],["new",1579.25,5567.0],["change",1579.3,1285.0],["change",1579.35,100.0],["change",1579.4,19195.0],["change",1579.45,2.5e4],["change",1579.5,62329.0],["new",1579.55,8243.0],["change",1579.6,6156666.0],["change",1579.65,122502.0],["change",1579.7,58876.0],["change",1579.75,274.0]],"prev_change_id":23707170788}}}
[2025-04-07 08:30:47.655] [multi_sink] [info] Processing received message: {"jsonrpc":"2.0","method":"subscription","params":{"channel":"book.ETH-PERPETUAL.100ms","data":{"timestamp":1743994849274,"type":"change","change_id":23707170934,"instrument_name":"ETH-PERPETUAL","bids":[["delete",1578.7,0.0],["delete",1578.65,0.0],["delete",1578.55,0.0],["delete",1578.5,0.0],["delete",1578.45,0.0],["change",1578.4,85392.0],["delete",1578.35,0.0],["change",1578.3,7438.0],["change",1578.25,1026.0],["change",1578.2,2562.0],["change",1578.15,4232.0],["change",1578.1,7748894.0],["change",1578.05,1856.0],["change",1578.0,15506.0],["change",1577.95,76248.0]],"asks":[["new",1579.2,6558.0],["new",1579.25,5567.0],["change",1579.3,1285.0],["change",1579.35,100.0],["change",1579.4,19195.0],["change",1579.45,2.5e4],["change",1579.5,62329.0],["new",1579.55,8243.0],["change",1579.6,6156666.0],["change",1579.65,122502.0],["change",1579.7,58876.0],["change",1579.75,274.0]],"prev_change_id":23707170788}}}
[2025-04-07 08:30:47.952] [multi_sink] [info] 📩 Received: {"jsonrpc":"2.0","method":"subscription","params":{"channel":"book.BTC-PERPETUAL.100ms","data":{"timestamp":1743994849439,"type":"change","change_id":41151928388,"instrument_name":"BTC-PERPETUAL","bids":[["new",78191.0,117280.0],["delete",78180.0,0.0]],"asks":[["delete",78567.0,0.0],["new",78578.5,78570.0],["delete",78617.0,0.0],["new",78628.5,117930.0]],"prev_change_id":41151928180}}}
[2025-04-07 08:30:47.956] [multi_sink] [info] Processing received message: {"jsonrpc":"2.0","method":"subscription","params":{"channel":"book.BTC-PERPETUAL.100ms","data":{"timestamp":1743994849439,"type":"change","change_id":41151928388,"instrument_name":"BTC-PERPETUAL","bids":[["new",78191.0,117280.0],["delete",78180.0,0.0]],"asks":[["delete",78567.0,0.0],["new",78578.5,78570.0],["delete",78617.0,0.0],["new",78628.5,117930.0]],"prev_change_id":41151928180}}}
[2025-04-07 08:30:47.983] [multi_sink] [info] 📩 Received: {"jsonrpc":"2.0","method":"subscription","params":{"channel":"book.ETH-PERPETUAL.100ms","data":{"timestamp":1743994849497,"type":"change","change_id":23707171342,"instrument_name":"ETH-PERPETUAL","bids":[["new",1578.75,40218.0],["new",1578.7,3.5e4],["new",1578.65,100.0],["new",1578.55,8019.0],["new",1578.5,13009.0],["new",1578.45,36376.0],["change",1578.2,1281.0],["change",1578.15,926.0],["change",1578.1,7746617.0],["change",1578.05,928.0],["change",1578.0,14476.0],["change",1577.95,61356.0]],"asks":[["new",1578.8,675.0],["new",1578.9,363.0],["new",1579.0,182.0],["new",1579.05,632.0],["new",1579.1,180.0],["new",1579.15,9908.0],["change",1579.8,1127.0],["change",1579.85,927.0],["delete",1579.9,0.0],["delete",1579.95,0.0],["delete",1580.0,0.0],["delete",1580.05,0.0]],"prev_change_id":23707170934}}}
[2025-04-07 08:30:47.987] [multi_sink] [info] Processing received message: {"jsonrpc":"2.0","method":"subscription","params":{"channel":"book.ETH-PERPETUAL.100ms","data":{"timestamp":1743994849497,"type":"change","change_id":23707171342,"instrument_name":"ETH-PERPETUAL","bids":[["new",1578.75,40218.0],["new",1578.7,3.5e4],["new",1578.65,100.0],["new",1578.55,8019.0],["new",1578.5,13009.0],["new",1578.45,36376.0],["change",1578.2,1281.0],["change",1578.15,926.0],["change",1578.1,7746617.0],["change",1578.05,928.0],["change",1578.0,14476.0],["change",1577.95,61356.0]],"asks":[["new",1578.8,675.0],["new",1578.9,363.0],["new",1579.0,182.0],["new",1579.05,632.0],["new",1579.1,180.0],["new",1579.15,9908.0],["change",1579.8,1127.0],["change",1579.85,927.0],["delete",1579.9,0.0],["delete",1579.95,0.0],["delete",1580.0,0.0],["delete",1580.05,0.0]],"prev_change_id":23707170934}}}
[2025-04-07 08:30:48.397] [multi_sink] [info] 📩 Received: {"jsonrpc":"2.0","method":"subscription","params":{"channel":"book.BTC-PERPETUAL.100ms","data":{"timestamp":1743994850023,"type":"change","change_id":41151929008,"instrument_name":"BTC-PERPETUAL","bids":[["new",78253.0,78250.0],["delete",78241.0,0.0]],"asks":[],"prev_change_id":41151928388}}}
[2025-04-07 08:30:48.400] [multi_sink] [info] Processing received message: {"jsonrpc":"2.0","method":"subscription","params":{"channel":"book.BTC-PERPETUAL.100ms","data":{"timestamp":1743994850023,"type":"change","change_id":41151929008,"instrument_name":"BTC-PERPETUAL","bids":[["new",78253.0,78250.0],["delete",78241.0,0.0]],"asks":[],"prev_change_id":41151928388}}}
[2025-04-07 08:30:48.720] [multi_sink] [info] 📩 Received: {"jsonrpc":"2.0","method":"subscription","params":{"channel":"book.BTC-PERPETUAL.100ms","data":{"timestamp":1743994850133,"type":"change","change_id":41151929015,"instrument_name":"BTC-PERPETUAL","bids":[["delete",78253.0,0.0],["delete",78191.0,0.0]],"asks":[["delete",78578.5,0.0],["delete",78628.5,0.0]],"prev_change_id":41151929008}}}
[2025-04-07 08:30:48.723] [multi_sink] [info] Processing received message: {"jsonrpc":"2.0","method":"subscription","params":{"channel":"book.BTC-PERPETUAL.100ms","data":{"timestamp":1743994850133,"type":"change","change_id":41151929015,"instrument_name":"BTC-PERPETUAL","bids":[["delete",78253.0,0.0],["delete",78191.0,0.0]],"asks":[["delete",78578.5,0.0],["delete",78628.5,0.0]],"prev_change_id":41151929008}}}
[2025-04-07 08:30:49.062] [multi_sink] [info] 📩 Received: {"jsonrpc":"2.0","method":"subscription","params":{"channel":"book.BTC-PERPETUAL.100ms","data":{"timestamp":1743994850682,"type":"change","change_id":41151929878,"instrument_name":"BTC-PERPETUAL","bids":[["delete",78410.0,0.0],["new",78404.0,12670.0],["change",78402.5,2190.0],["change",78402.0,3.41e4],["new",78400.5,5740.0],["new",7.84e4,190.0],["delete",78399.5,0.0],["new",78398.5,1640.0],["new",78398.0,5210.0],["change",78397.5,270.0],["delete",78397.0,0.0],["delete",78396.5,0.0],["delete",78396.0,0.0],["change",78395.0,1230.0],["change",78394.5,14630.0]],"asks":[["delete",78410.5,0.0],["delete",78411.0,0.0],["delete",78411.5,0.0],["delete",78412.0,0.0],["delete",78414.0,0.0],["delete",78415.5,0.0],["delete",78416.0,0.0],["delete",78416.5,0.0],["delete",78419.0,0.0],["delete",78419.5,0.0],["new",78451.0,116650.0],["new",78451.5,6080.0],["new",78452.0,4830.0],["new",78452.5,27540.0],["new",78453.0,8.17e4],["new",78453.5,1490.0],["new",78454.5,490.0],["new",78455.0,490.0],["new",78455.5,6190.0],["new",78456.0,490.0]],"prev_change_id":41151929015}}}
[2025-04-07 08:30:49.064] [multi_sink] [info] Processing received message: {"jsonrpc":"2.0","method":"subscription","params":{"channel":"book.BTC-PERPETUAL.100ms","data":{"timestamp":1743994850682,"type":"change","change_id":41151929878,"instrument_name":"BTC-PERPETUAL","bids":[["delete",78410.0,0.0],["new",78404.0,12670.0],["change",78402.5,2190.0],["change",78402.0,3.41e4],["new",78400.5,5740.0],["new",7.84e4,190.0],["delete",78399.5,0.0],["new",78398.5,1640.0],["new",78398.0,5210.0],["change",78397.5,270.0],["delete",78397.0,0.0],["delete",78396.5,0.0],["delete",78396.0,0.0],["change",78395.0,1230.0],["change",78394.5,14630.0]],"asks":[["delete",78410.5,0.0],["delete",78411.0,0.0],["delete",78411.5,0.0],["delete",78412.0,0.0],["delete",78414.0,0.0],["delete",78415.5,0.0],["delete",78416.0,0.0],["delete",78416.5,0.0],["delete",78419.0,0.0],["delete",78419.5,0.0],["new",78451.0,116650.0],["new",78451.5,6080.0],["new",78452.0,4830.0],["new",78452.5,27540.0],["new",78453.0,8.17e4],["new",78453.5,1490.0],["new",78454.5,490.0],["new",78455.0,490.0],["new",78455.5,6190.0],["new",78456.0,490.0]],"prev_change_id":41151929015}}}
[2025-04-07 08:30:49.390] [multi_sink] [info] 📩 Received: {"jsonrpc":"2.0","method":"subscription","params":{"channel":"book.BTC-PERPETUAL.100ms","data":{"timestamp":1743994851009,"type":"change","change_id":41151930489,"instrument_name":"BTC-PERPETUAL","bids":[["new",78416.5,9.92e4],["new",78414.0,5.64e4],["new",78413.5,9440.0],["new",78412.0,10.0],["new",78410.5,940.0],["new",78410.0,85170.0],["new",78409.5,3.5e4],["new",78405.0,160.0],["delete",78393.0,0.0],["delete",78392.0,0.0],["delete",78390.5,0.0],["delete",78390.0,0.0],["delete",78389.5,0.0],["delete",78389.0,0.0],["delete",78388.0,0.0],["delete",78387.5,0.0]],"asks":[["delete",78420.0,0.0],["delete",78420.5,0.0],["delete",78421.0,0.0],["delete",78421.5,0.0],["delete",78424.0,0.0],["delete",78424.5,0.0],["delete",78425.0,0.0],["delete",78427.0,0.0],["delete",78427.5,0.0],["new",78436.5,13260.0],["new",78437.0,1.0e4],["new",78440.0,2810.0],["new",78442.0,1.65e4],["new",78442.5,3020.0],["new",78446.5,250.0],["new",78447.0,44290.0],["new",78450.0,2.3e3],["new",78450.5,3390.0]],"prev_change_id":41151929878}}}
[2025-04-07 08:30:49.395] [multi_sink] [info] Processing received message: {"jsonrpc":"2.0","method":"subscription","params":{"channel":"book.BTC-PERPETUAL.100ms","data":{"timestamp":1743994851009,"type":"change","change_id":41151930489,"instrument_name":"BTC-PERPETUAL","bids":[["new",78416.5,9.92e4],["new",78414.0,5.64e4],["new",78413.5,9440.0],["new",78412.0,10.0],["new",78410.5,940.0],["new",78410.0,85170.0],["new",78409.5,3.5e4],["new",78405.0,160.0],["delete",78393.0,0.0],["delete",78392.0,0.0],["delete",78390.5,0.0],["delete",78390.0,0.0],["delete",78389.5,0.0],["delete",78389.0,0.0],["delete",78388.0,0.0],["delete",78387.5,0.0]],"asks":[["delete",78420.0,0.0],["delete",78420.5,0.0],["delete",78421.0,0.0],["delete",78421.5,0.0],["delete",78424.0,0.0],["delete",78424.5,0.0],["delete",78425.0,0.0],["delete",78427.0,0.0],["delete",78427.5,0.0],["new",78436.5,13260.0],["new",78437.0,1.0e4],["new",78440.0,2810.0],["new",78442.0,1.65e4],["new",78442.5,3020.0],["new",78446.5,250.0],["new",78447.0,44290.0],["new",78450.0,2.3e3],["new",78450.5,3390.0]],"prev_change_id":41151929878}}}
[2025-04-07 08:30:49.716] [multi_sink] [info] 📩 Received: {"jsonrpc":"2.0","method":"subscription","params":{"channel":"book.BTC-PERPETUAL.100ms","data":{"timestamp":1743994851055,"type":"change","change_id":41151930503,"instrument_name":"BTC-PERPETUAL","bids":[["new",78418.0,35670.0],["new",78417.0,650.0],["delete",78386.0,0.0],["delete",78384.0,0.0]],"asks":[["new",78418.5,220.0]],"prev_change_id":41151930489}}}
[2025-04-07 08:30:49.720] [multi_sink] [info] Processing received message: {"jsonrpc":"2.0","method":"subscription","params":{"channel":"book.BTC-PERPETUAL.100ms","data":{"timestamp":1743994851055,"type":"change","change_id":41151930503,"instrument_name":"BTC-PERPETUAL","bids":[["new",78418.0,35670.0],["new",78417.0,650.0],["delete",78386.0,0.0],["delete",78384.0,0.0]],"asks":[["new",78418.5,220.0]],"prev_change_id":41151930489}}}
[2025-04-07 08:30:50.041] [multi_sink] [info] 📩 Received: {"jsonrpc":"2.0","method":"subscription","params":{"channel":"book.BTC-PERPETUAL.100ms","data":{"timestamp":1743994851630,"type":"change","change_id":41151931472,"instrument_name":"BTC-PERPETUAL","bids":[["new",78375.5,7825720.0],["delete",78371.5,0.0],["new",78222.5,8000580.0],["delete",78218.5,0.0]],"asks":[],"prev_change_id":41151930503}}}
[2025-04-07 08:30:50.044] [multi_sink] [info] Processing received message: {"jsonrpc":"2.0","method":"subscription","params":{"channel":"book.BTC-PERPETUAL.100ms","data":{"timestamp":1743994851630,"type":"change","change_id":41151931472,"instrument_name":"BTC-PERPETUAL","bids":[["new",78375.5,7825720.0],["delete",78371.5,0.0],["new",78222.5,8000580.0],["delete",78218.5,0.0]],"asks":[],"prev_change_id":41151930503}}}
[2025-04-07 08:30:50.370] [multi_sink] [info] 📩 Received: {"jsonrpc":"2.0","method":"subscription","params":{"channel":"book.BTC-PERPETUAL.100ms","data":{"timestamp":1743994851960,"type":"change","change_id":41151932082,"instrument_name":"BTC-PERPETUAL","bids":[],"asks":[["delete",78449.0,0.0],["change",78453.0,6722530.0],["delete",78602.0,0.0],["new",78606.0,7777770.0]],"prev_change_id":41151931472}}}
[2025-04-07 08:30:50.373] [multi_sink] [info] Processing received message: {"jsonrpc":"2.0","method":"subscription","params":{"channel":"book.BTC-PERPETUAL.100ms","data":{"timestamp":1743994851960,"type":"change","change_id":41151932082,"instrument_name":"BTC-PERPETUAL","bids":[],"asks":[["delete",78449.0,0.0],["change",78453.0,6722530.0],["delete",78602.0,0.0],["new",78606.0,7777770.0]],"prev_change_id":41151931472}}}
[2025-04-07 08:30:50.701] [multi_sink] [info] 📩 Received: {"jsonrpc":"2.0","method":"subscription","params":{"channel":"book.BTC-PERPETUAL.100ms","data":{"timestamp":1743994852238,"type":"change","change_id":41151932633,"instrument_name":"BTC-PERPETUAL","bids":[["new",78270.0,78270.0],["new",78220.0,117330.0]],"asks":[["new",78594.5,78590.0],["new",78644.5,117960.0]],"prev_change_id":41151932082}}}
[2025-04-07 08:30:50.706] [multi_sink] [info] Processing received message: {"jsonrpc":"2.0","method":"subscription","params":{"channel":"book.BTC-PERPETUAL.100ms","data":{"timestamp":1743994852238,"type":"change","change_id":41151932633,"instrument_name":"BTC-PERPETUAL","bids":[["new",78270.0,78270.0],["new",78220.0,117330.0]],"asks":[["new",78594.5,78590.0],["new",78644.5,117960.0]],"prev_change_id":41151932082}}}
[2025-04-07 08:30:51.032] [multi_sink] [info] 📩 Received: {"jsonrpc":"2.0","method":"subscription","params":{"channel":"book.BTC-PERPETUAL.100ms","data":{"timestamp":1743994852351,"type":"change","change_id":41151932862,"instrument_name":"BTC-PERPETUAL","bids":[["delete",78270.0,0.0],["delete",78220.0,0.0]],"asks":[],"prev_change_id":41151932633}}}
[2025-04-07 08:30:51.036] [multi_sink] [info] Processing received message: {"jsonrpc":"2.0","method":"subscription","params":{"channel":"book.BTC-PERPETUAL.100ms","data":{"timestamp":1743994852351,"type":"change","change_id":41151932862,"instrument_name":"BTC-PERPETUAL","bids":[["delete",78270.0,0.0],["delete",78220.0,0.0]],"asks":[],"prev_change_id":41151932633}}}
[2025-04-07 08:30:51.362] [multi_sink] [info] 📩 Received: {"jsonrpc":"2.0","method":"subscription","params":{"channel":"book.BTC-PERPETUAL.100ms","data":{"timestamp":1743994852910,"type":"change","change_id":41151933482,"instrument_name":"BTC-PERPETUAL","bids":[],"asks":[["delete",78594.5,0.0],["delete",78644.5,0.0]],"prev_change_id":41151932862}}}
[2025-04-07 08:30:51.367] [multi_sink] [info] Processing received message: {"jsonrpc":"2.0","method":"subscription","params":{"channel":"book.BTC-PERPETUAL.100ms","data":{"timestamp":1743994852910,"type":"change","change_id":41151933482,"instrument_name":"BTC-PERPETUAL","bids":[],"asks":[["delete",78594.5,0.0],["delete",78644.5,0.0]],"prev_change_id":41151932862}}}
[2025-04-07 08:30:52.030] [multi_sink] [info] 📩 Received: {"jsonrpc":"2.0","method":"subscription","params":{"channel":"book.ETH-PERPETUAL.100ms","data":{"timestamp":1743994853613,"type":"change","change_id":23707175726,"instrument_name":"ETH-PERPETUAL","bids":[["change",1578.7,7779514.0],["change",1578.1,2103.0]],"asks":[],"prev_change_id":23707171342}}}
[2025-04-07 08:30:52.032] [multi_sink] [info] Processing received message: {"jsonrpc":"2.0","method":"subscription","params":{"channel":"book.ETH-PERPETUAL.100ms","data":{"timestamp":1743994853613,"type":"change","change_id":23707175726,"instrument_name":"ETH-PERPETUAL","bids":[["change",1578.7,7779514.0],["change",1578.1,2103.0]],"asks":[],"prev_change_id":23707171342}}}
[2025-04-07 08:30:52.355] [multi_sink] [info] 📩 Received: {"jsonrpc":"2.0","method":"subscription","params":{"channel":"book.ETH-PERPETUAL.100ms","data":{"timestamp":1743994853986,"type":"change","change_id":23707176449,"instrument_name":"ETH-PERPETUAL","bids":[["delete",1578.75,0.0],["change",1578.7,7744514.0],["delete",1578.65,0.0],["delete",1578.55,0.0],["delete",1578.5,0.0],["delete",1578.45,0.0],["change",1578.15,1852.0],["change",1578.1,3131.0],["change",1578.05,13110.0],["change",1578.0,15506.0],["change",1577.95,106075.0],["change",1577.9,13967.0]],"asks":[["delete",1578.8,0.0],["delete",1578.9,0.0],["delete",1579.0,0.0],["delete",1579.05,0.0],["delete",1579.1,0.0],["delete",1579.15,0.0],["change",1579.6,44673.0],["new",1579.9,14035.0],["new",1579.95,100.0],["new",1580.0,545.0],["new",1580.05,100.0],["new",1580.1,78838.0],["new",1580.15,1206.0],["new",1580.2,6111993.0]],"prev_change_id":23707175726}}}
[2025-04-07 08:30:52.357] [multi_sink] [info] Processing received message: {"jsonrpc":"2.0","method":"subscription","params":{"channel":"book.ETH-PERPETUAL.100ms","data":{"timestamp":1743994853986,"type":"change","change_id":23707176449,"instrument_name":"ETH-PERPETUAL","bids":[["delete",1578.75,0.0],["change",1578.7,7744514.0],["delete",1578.65,0.0],["delete",1578.55,0.0],["delete",1578.5,0.0],["delete",1578.45,0.0],["change",1578.15,1852.0],["change",1578.1,3131.0],["change",1578.05,13110.0],["change",1578.0,15506.0],["change",1577.95,106075.0],["change",1577.9,13967.0]],"asks":[["delete",1578.8,0.0],["delete",1578.9,0.0],["delete",1579.0,0.0],["delete",1579.05,0.0],["delete",1579.1,0.0],["delete",1579.15,0.0],["change",1579.6,44673.0],["new",1579.9,14035.0],["new",1579.95,100.0],["new",1580.0,545.0],["new",1580.05,100.0],["new",1580.1,78838.0],["new",1580.15,1206.0],["new",1580.2,6111993.0]],"prev_change_id":23707175726}}}
[2025-04-07 08:30:52.611] [multi_sink] [info] 📩 Received: {"jsonrpc":"2.0","method":"subscription","params":{"channel":"book.BTC-PERPETUAL.100ms","data":{"timestamp":1743994854243,"type":"change","change_id":41151935580,"instrument_name":"BTC-PERPETUAL","bids":[],"asks":[["new",78561.5,78560.0]],"prev_change_id":41151933482}}}
[2025-04-07 08:30:52.614] [multi_sink] [info] Processing received message: {"jsonrpc":"2.0","method":"subscription","params":{"channel":"book.BTC-PERPETUAL.100ms","data":{"timestamp":1743994854243,"type":"change","change_id":41151935580,"instrument_name":"BTC-PERPETUAL","bids":[],"asks":[["new",78561.5,78560.0]],"prev_change_id":41151933482}}}
[2025-04-07 08:30:52.686] [multi_sink] [info] 📩 Received: {"jsonrpc":"2.0","method":"subscription","params":{"channel":"book.ETH-PERPETUAL.100ms","data":{"timestamp":1743994854317,"type":"change","change_id":23707176590,"instrument_name":"ETH-PERPETUAL","bids":[["new",1578.65,4575.0],["new",1578.55,17332.0],["new",1578.5,14919.0],["new",1578.45,610.0],["change",1578.4,3.0e3],["new",1578.35,926.0],["change",1578.3,7438.0],["change",1578.25,26648.0],["change",1578.2,39315.0],["change",1578.15,926.0],["change",1578.1,1028.0],["change",1578.05,12182.0],["change",1578.0,1030.0],["change",1577.95,44719.0]],"asks":[["delete",1579.2,0.0],["delete",1579.25,0.0],["delete",1579.3,0.0],["delete",1579.35,0.0],["delete",1579.4,0.0],["change",1579.45,5770.0],["change",1579.5,15401.0],["change",1579.55,100.0],["change",1579.6,3856.0],["change",1579.65,128527.0],["change",1579.7,66314.0],["change",1579.75,21405.0],["change",1579.8,30165.0],["change",1579.85,4316.0]],"prev_change_id":23707176449}}}
[2025-04-07 08:30:52.687] [multi_sink] [info] Processing received message: {"jsonrpc":"2.0","method":"subscription","params":{"channel":"book.ETH-PERPETUAL.100ms","data":{"timestamp":1743994854317,"type":"change","change_id":23707176590,"instrument_name":"ETH-PERPETUAL","bids":[["new",1578.65,4575.0],["new",1578.55,17332.0],["new",1578.5,14919.0],["new",1578.45,610.0],["change",1578.4,3.0e3],["new",1578.35,926.0],["change",1578.3,7438.0],["change",1578.25,26648.0],["change",1578.2,39315.0],["change",1578.15,926.0],["change",1578.1,1028.0],["change",1578.05,12182.0],["change",1578.0,1030.0],["change",1577.95,44719.0]],"asks":[["delete",1579.2,0.0],["delete",1579.25,0.0],["delete",1579.3,0.0],["delete",1579.35,0.0],["delete",1579.4,0.0],["change",1579.45,5770.0],["change",1579.5,15401.0],["change",1579.55,100.0],["change",1579.6,3856.0],["change",1579.65,128527.0],["change",1579.7,66314.0],["change",1579.75,21405.0],["change",1579.8,30165.0],["change",1579.85,4316.0]],"prev_change_id":23707176449}}}
[2025-04-07 08:30:52.946] [multi_sink] [info] 📩 Received: {"jsonrpc":"2.0","method":"subscription","params":{"channel":"book.BTC-PERPETUAL.100ms","data":{"timestamp":1743994854351,"type":"change","change_id":41151935787,"instrument_name":"BTC-PERPETUAL","bids":[["new",78231.5,78230.0],["new",78181.5,117270.0]],"asks":[["new",78611.5,117910.0]],"prev_change_id":41151935580}}}
[2025-04-07 08:30:52.947] [multi_sink] [info] Processing received message: {"jsonrpc":"2.0","method":"subscription","params":{"channel":"book.BTC-PERPETUAL.100ms","data":{"timestamp":1743994854351,"type":"change","change_id":41151935787,"instrument_name":"BTC-PERPETUAL","bids":[["new",78231.5,78230.0],["new",78181.5,117270.0]],"asks":[["new",78611.5,117910.0]],"prev_change_id":41151935580}}}
[2025-04-07 08:30:53.018] [multi_sink] [info] 📩 Received: {"jsonrpc":"2.0","method":"subscription","params":{"channel":"book.ETH-PERPETUAL.100ms","data":{"timestamp":1743994854511,"type":"change","change_id":23707176969,"instrument_name":"ETH-PERPETUAL","bids":[["new",1579.05,9907.0],["new",1578.95,7.14e4],["new",1578.9,5671.0],["new",1578.8,1171.0],["new",1578.75,1796.0],["change",1577.9,4466.0],["delete",1577.85,0.0],["delete",1577.8,0.0],["delete",1577.75,0.0],["delete",1577.7,0.0]],"asks":[["new",1579.15,17931.0],["new",1579.25,2250.0],["new",1579.3,17723.0],["new",1579.35,26271.0],["new",1579.4,5737.0],["change",1579.65,6025.0],["change",1579.7,7438.0],["change",1579.75,21131.0],["change",1579.8,29038.0],["change",1579.85,3389.0]],"prev_change_id":23707176590}}}
[2025-04-07 08:30:53.019] [multi_sink] [info] Processing received message: {"jsonrpc":"2.0","method":"subscription","params":{"channel":"book.ETH-PERPETUAL.100ms","data":{"timestamp":1743994854511,"type":"change","change_id":23707176969,"instrument_name":"ETH-PERPETUAL","bids":[["new",1579.05,9907.0],["new",1578.95,7.14e4],["new",1578.9,5671.0],["new",1578.8,1171.0],["new",1578.75,1796.0],["change",1577.9,4466.0],["delete",1577.85,0.0],["delete",1577.8,0.0],["delete",1577.75,0.0],["delete",1577.7,0.0]],"asks":[["new",1579.15,17931.0],["new",1579.25,2250.0],["new",1579.3,17723.0],["new",1579.35,26271.0],["new",1579.4,5737.0],["change",1579.65,6025.0],["change",1579.7,7438.0],["change",1579.75,21131.0],["change",1579.8,29038.0],["change",1579.85,3389.0]],"prev_change_id":23707176590}}}
[2025-04-07 08:30:53.958] [multi_sink] [info] 📩 Received: {"jsonrpc":"2.0","method":"subscription","params":{"channel":"book.BTC-PERPETUAL.100ms","data":{"timestamp":1743994855577,"type":"change","change_id":41151937467,"instrument_name":"BTC-PERPETUAL","bids":[["delete",78418.0,0.0],["delete",78417.0,0.0],["delete",78416.5,0.0],["delete",78414.0,0.0],["delete",78413.5,0.0],["delete",78412.0,0.0],["delete",78410.5,0.0],["new",78381.5,9440.0],["new",78381.0,16490.0],["new",78380.0,62550.0],["new",78379.5,5740.0],["new",78378.0,1.59e5],["new",78377.5,6210.0],["new",78376.5,16490.0]],"asks":[["delete",78418.5,0.0],["new",78422.5,6.0e3],["new",78423.0,1.0e4],["new",78423.5,1.0e4],["new",78424.5,4.89e4],["new",78425.0,91640.0],["new",78425.5,2.0e4],["new",78427.0,49070.0],["delete",78436.5,0.0],["delete",78437.0,0.0],["delete",78440.0,0.0],["delete",78442.0,0.0],["delete",78442.5,0.0],["delete",78446.5,0.0]],"prev_change_id":41151935787}}}
[2025-04-07 08:30:53.962] [multi_sink] [info] Processing received message: {"jsonrpc":"2.0","method":"subscription","params":{"channel":"book.BTC-PERPETUAL.100ms","data":{"timestamp":1743994855577,"type":"change","change_id":41151937467,"instrument_name":"BTC-PERPETUAL","bids":[["delete",78418.0,0.0],["delete",78417.0,0.0],["delete",78416.5,0.0],["delete",78414.0,0.0],["delete",78413.5,0.0],["delete",78412.0,0.0],["delete",78410.5,0.0],["new",78381.5,9440.0],["new",78381.0,16490.0],["new",78380.0,62550.0],["new",78379.5,5740.0],["new",78378.0,1.59e5],["new",78377.5,6210.0],["new",78376.5,16490.0]],"asks":[["delete",78418.5,0.0],["new",78422.5,6.0e3],["new",78423.0,1.0e4],["new",78423.5,1.0e4],["new",78424.5,4.89e4],["new",78425.0,91640.0],["new",78425.5,2.0e4],["new",78427.0,49070.0],["delete",78436.5,0.0],["delete",78437.0,0.0],["delete",78440.0,0.0],["delete",78442.0,0.0],["delete",78442.5,0.0],["delete",78446.5,0.0]],"prev_change_id":41151935787}}}
[2025-04-07 08:30:54.297] [multi_sink] [info] 📩 Received: {"jsonrpc":"2.0","method":"subscription","params":{"channel":"book.BTC-PERPETUAL.100ms","data":{"timestamp":1743994855911,"type":"change","change_id":41151937906,"instrument_name":"BTC-PERPETUAL","bids":[["delete",78410.0,0.0],["delete",78409.5,0.0],["delete",78405.0,0.0],["delete",78404.0,0.0],["delete",78402.5,0.0],["delete",78402.0,0.0],["delete",78400.5,0.0],["delete",7.84e4,0.0],["new",78399.5,3.3e3],["delete",78398.5,0.0],["change",78397.5,540.0],["new",78397.0,480.0],["change",78395.0,2460.0],["new",78387.5,4.29e4],["new",78386.0,3.41e4],["new",78384.5,490.0],["new",78384.0,93440.0],["new",78382.0,26490.0]],"asks":[["new",78413.0,7.55e4],["new",78413.5,5740.0],["new",78414.0,9910.0],["new",78416.0,21890.0],["new",78416.5,510.0],["new",78417.0,3120.0],["new",78418.0,2.06e4],["new",78418.5,35320.0],["new",78419.0,550.0],["delete",78447.0,0.0],["delete",78450.0,0.0],["delete",78450.5,0.0],["delete",78451.0,0.0],["delete",78451.5,0.0],["delete",78452.0,0.0],["delete",78452.5,0.0],["change",78453.0,6640830.0],["delete",78453.5,0.0]],"prev_change_id":41151937467}}}
[2025-04-07 08:30:54.298] [multi_sink] [info] Processing received message: {"jsonrpc":"2.0","method":"subscription","params":{"channel":"book.BTC-PERPETUAL.100ms","data":{"timestamp":1743994855911,"type":"change","change_id":41151937906,"instrument_name":"BTC-PERPETUAL","bids":[["delete",78410.0,0.0],["delete",78409.5,0.0],["delete",78405.0,0.0],["delete",78404.0,0.0],["delete",78402.5,0.0],["delete",78402.0,0.0],["delete",78400.5,0.0],["delete",7.84e4,0.0],["new",78399.5,3.3e3],["delete",78398.5,0.0],["change",78397.5,540.0],["new",78397.0,480.0],["change",78395.0,2460.0],["new",78387.5,4.29e4],["new",78386.0,3.41e4],["new",78384.5,490.0],["new",78384.0,93440.0],["new",78382.0,26490.0]],"asks":[["new",78413.0,7.55e4],["new",78413.5,5740.0],["new",78414.0,9910.0],["new",78416.0,21890.0],["new",78416.5,510.0],["new",78417.0,3120.0],["new",78418.0,2.06e4],["new",78418.5,35320.0],["new",78419.0,550.0],["delete",78447.0,0.0],["delete",78450.0,0.0],["delete",78450.5,0.0],["delete",78451.0,0.0],["delete",78451.5,0.0],["delete",78452.0,0.0],["delete",78452.5,0.0],["change",78453.0,6640830.0],["delete",78453.5,0.0]],"prev_change_id":41151937467}}}
[2025-04-07 08:30:54.618] [multi_sink] [info] 📩 Received: {"jsonrpc":"2.0","method":"subscription","params":{"channel":"book.BTC-PERPETUAL.100ms","data":{"timestamp":1743994856054,"type":"change","change_id":41151938105,"instrument_name":"BTC-PERPETUAL","bids":[["new",78410.0,1120.0],["new",78405.0,160.0],["new",78402.5,2190.0],["new",7.84e4,190.0],["delete",78398.0,0.0],["change",78397.5,270.0],["change",78395.0,1230.0],["delete",78394.5,0.0]],"asks":[["new",78410.5,224180.0],["new",78411.5,16930.0],["new",78412.0,7.89e4],["new",78412.5,83160.0],["delete",78454.5,0.0],["delete",78455.0,0.0],["delete",78455.5,0.0],["delete",78456.0,0.0]],"prev_change_id":41151937906}}}
[2025-04-07 08:30:54.623] [multi_sink] [info] Processing received message: {"jsonrpc":"2.0","method":"subscription","params":{"channel":"book.BTC-PERPETUAL.100ms","data":{"timestamp":1743994856054,"type":"change","change_id":41151938105,"instrument_name":"BTC-PERPETUAL","bids":[["new",78410.0,1120.0],["new",78405.0,160.0],["new",78402.5,2190.0],["new",7.84e4,190.0],["delete",78398.0,0.0],["change",78397.5,270.0],["change",78395.0,1230.0],["delete",78394.5,0.0]],"asks":[["new",78410.5,224180.0],["new",78411.5,16930.0],["new",78412.0,7.89e4],["new",78412.5,83160.0],["delete",78454.5,0.0],["delete",78455.0,0.0],["delete",78455.5,0.0],["delete",78456.0,0.0]],"prev_change_id":41151937906}}}
[2025-04-07 08:30:56.978] [multi_sink] [info] 📩 Received: {"jsonrpc":"2.0","method":"subscription","params":{"channel":"book.BTC-PERPETUAL.100ms","data":{"timestamp":1743994858611,"type":"change","change_id":41151942020,"instrument_name":"BTC-PERPETUAL","bids":[["delete",78231.5,0.0],["new",78221.0,78220.0]],"asks":[],"prev_change_id":41151938105}}}
[2025-04-07 08:30:56.980] [multi_sink] [info] Processing received message: {"jsonrpc":"2.0","method":"subscription","params":{"channel":"book.BTC-PERPETUAL.100ms","data":{"timestamp":1743994858611,"type":"change","change_id":41151942020,"instrument_name":"BTC-PERPETUAL","bids":[["delete",78231.5,0.0],["new",78221.0,78220.0]],"asks":[],"prev_change_id":41151938105}}}
[2025-04-07 08:30:57.310] [multi_sink] [info] 📩 Received: {"jsonrpc":"2.0","method":"subscription","params":{"channel":"book.BTC-PERPETUAL.100ms","data":{"timestamp":1743994858848,"type":"change","change_id":41151942240,"instrument_name":"BTC-PERPETUAL","bids":[["delete",78375.5,0.0],["new",78366.5,7825720.0],["delete",78222.5,0.0],["delete",78221.0,0.0],["new",78213.5,8000580.0],["delete",78181.5,0.0]],"asks":[["delete",78561.5,0.0],["delete",78611.5,0.0]],"prev_change_id":41151942020}}}
[2025-04-07 08:30:57.311] [multi_sink] [info] Processing received message: {"jsonrpc":"2.0","method":"subscription","params":{"channel":"book.BTC-PERPETUAL.100ms","data":{"timestamp":1743994858848,"type":"change","change_id":41151942240,"instrument_name":"BTC-PERPETUAL","bids":[["delete",78375.5,0.0],["new",78366.5,7825720.0],["delete",78222.5,0.0],["delete",78221.0,0.0],["new",78213.5,8000580.0],["delete",78181.5,0.0]],"asks":[["delete",78561.5,0.0],["delete",78611.5,0.0]],"prev_change_id":41151942020}}}
[2025-04-07 08:30:57.390] [multi_sink] [info] 📩 Received: {"jsonrpc":"2.0","method":"subscription","params":{"channel":"book.ETH-PERPETUAL.100ms","data":{"timestamp":1743994859023,"type":"change","change_id":23707182255,"instrument_name":"ETH-PERPETUAL","bids":[["delete",1579.05,0.0],["delete",1578.95,0.0],["delete",1578.9,0.0],["delete",1578.8,0.0],["delete",1578.75,0.0],["delete",1578.65,0.0],["new",1577.45,39177.0],["new",1577.4,12899.0],["new",1577.35,42320.0],["new",1577.3,6948.0],["new",1577.25,4210.0],["new",1577.2,2793.0]],"asks":[["change",1579.15,3923.0],["new",1579.2,10003.0],["change",1579.25,1026.0],["change",1579.3,15018.0],["change",1579.35,46404.0],["change",1579.4,26210.0],["change",1579.45,3.51e4],["delete",1579.5,0.0]],"prev_change_id":23707176969}}}
[2025-04-07 08:30:57.394] [multi_sink] [info] Processing received message: {"jsonrpc":"2.0","method":"subscription","params":{"channel":"book.ETH-PERPETUAL.100ms","data":{"timestamp":1743994859023,"type":"change","change_id":23707182255,"instrument_name":"ETH-PERPETUAL","bids":[["delete",1579.05,0.0],["delete",1578.95,0.0],["delete",1578.9,0.0],["delete",1578.8,0.0],["delete",1578.75,0.0],["delete",1578.65,0.0],["new",1577.45,39177.0],["new",1577.4,12899.0],["new",1577.35,42320.0],["new",1577.3,6948.0],["new",1577.25,4210.0],["new",1577.2,2793.0]],"asks":[["change",1579.15,3923.0],["new",1579.2,10003.0],["change",1579.25,1026.0],["change",1579.3,15018.0],["change",1579.35,46404.0],["change",1579.4,26210.0],["change",1579.45,3.51e4],["delete",1579.5,0.0]],"prev_change_id":23707176969}}}
[2025-04-07 08:30:57.642] [multi_sink] [info] 📩 Received: {"jsonrpc":"2.0","method":"subscription","params":{"channel":"book.BTC-PERPETUAL.100ms","data":{"timestamp":1743994859181,"type":"change","change_id":41151942591,"instrument_name":"BTC-PERPETUAL","bids":[],"asks":[["new",78444.0,6640830.0],["delete",78453.0,0.0],["new",78597.0,7777770.0],["delete",78606.0,0.0]],"prev_change_id":41151942240}}}
[2025-04-07 08:30:57.647] [multi_sink] [info] Processing received message: {"jsonrpc":"2.0","method":"subscription","params":{"channel":"book.BTC-PERPETUAL.100ms","data":{"timestamp":1743994859181,"type":"change","change_id":41151942591,"instrument_name":"BTC-PERPETUAL","bids":[],"asks":[["new",78444.0,6640830.0],["delete",78453.0,0.0],["new",78597.0,7777770.0],["delete",78606.0,0.0]],"prev_change_id":41151942240}}}
[2025-04-07 08:30:57.731] [multi_sink] [info] 📩 Received: {"jsonrpc":"2.0","method":"subscription","params":{"channel":"book.ETH-PERPETUAL.100ms","data":{"timestamp":1743994859331,"type":"change","change_id":23707182398,"instrument_name":"ETH-PERPETUAL","bids":[["delete",1578.55,0.0],["delete",1578.5,0.0],["delete",1578.45,0.0],["delete",1578.4,0.0],["delete",1578.35,0.0],["delete",1578.3,0.0],["delete",1578.25,0.0],["delete",1578.2,0.0],["delete",1578.15,0.0],["change",1577.9,4566.0],["new",1577.85,15017.0],["new",1577.8,16353.0],["new",1577.75,5231.0],["new",1577.7,4216.0],["new",1577.65,1950.0],["new",1577.6,2477.0],["new",1577.55,15599.0],["new",1577.5,11590.0]],"asks":[["new",1578.75,12918.0],["new",1578.8,8216.0],["new",1578.85,11025.0],["new",1578.9,14122.0],["new",1578.95,889.0],["new",1579.0,73080.0],["new",1579.05,72424.0],["new",1579.1,14927.0],["delete",1579.55,0.0],["delete",1579.6,0.0],["delete",1579.65,0.0],["delete",1579.7,0.0],["delete",1579.75,0.0],["delete",1579.8,0.0],["delete",1579.85,0.0],["delete",1579.9,0.0]],"prev_change_id":23707182255}}}
[2025-04-07 08:30:57.735] [multi_sink] [info] Processing received message: {"jsonrpc":"2.0","method":"subscription","params":{"channel":"book.ETH-PERPETUAL.100ms","data":{"timestamp":1743994859331,"type":"change","change_id":23707182398,"instrument_name":"ETH-PERPETUAL","bids":[["delete",1578.55,0.0],["delete",1578.5,0.0],["delete",1578.45,0.0],["delete",1578.4,0.0],["delete",1578.35,0.0],["delete",1578.3,0.0],["delete",1578.25,0.0],["delete",1578.2,0.0],["delete",1578.15,0.0],["change",1577.9,4566.0],["new",1577.85,15017.0],["new",1577.8,16353.0],["new",1577.75,5231.0],["new",1577.7,4216.0],["new",1577.65,1950.0],["new",1577.6,2477.0],["new",1577.55,15599.0],["new",1577.5,11590.0]],"asks":[["new",1578.75,12918.0],["new",1578.8,8216.0],["new",1578.85,11025.0],["new",1578.9,14122.0],["new",1578.95,889.0],["new",1579.0,73080.0],["new",1579.05,72424.0],["new",1579.1,14927.0],["delete",1579.55,0.0],["delete",1579.6,0.0],["delete",1579.65,0.0],["delete",1579.7,0.0],["delete",1579.75,0.0],["delete",1579.8,0.0],["delete",1579.85,0.0],["delete",1579.9,0.0]],"prev_change_id":23707182255}}}
[2025-04-07 08:30:58.055] [multi_sink] [info] 📩 Received: {"jsonrpc":"2.0","method":"subscription","params":{"channel":"book.ETH-PERPETUAL.100ms","data":{"timestamp":1743994859525,"type":"change","change_id":23707182711,"instrument_name":"ETH-PERPETUAL","bids":[["change",1578.7,7643377.0],["new",1578.25,5255.0],["new",1578.15,15577.0],["delete",1578.1,0.0],["change",1578.05,100.0],["change",1578.0,7.14e4],["change",1577.95,10617.0],["change",1577.9,100.0]],"asks":[["delete",1579.95,0.0],["delete",1580.0,0.0],["delete",1580.05,0.0],["delete",1580.1,0.0],["delete",1580.15,0.0]],"prev_change_id":23707182398}}}
[2025-04-07 08:30:58.060] [multi_sink] [info] Processing received message: {"jsonrpc":"2.0","method":"subscription","params":{"channel":"book.ETH-PERPETUAL.100ms","data":{"timestamp":1743994859525,"type":"change","change_id":23707182711,"instrument_name":"ETH-PERPETUAL","bids":[["change",1578.7,7643377.0],["new",1578.25,5255.0],["new",1578.15,15577.0],["delete",1578.1,0.0],["change",1578.05,100.0],["change",1578.0,7.14e4],["change",1577.95,10617.0],["change",1577.9,100.0]],"asks":[["delete",1579.95,0.0],["delete",1580.0,0.0],["delete",1580.05,0.0],["delete",1580.1,0.0],["delete",1580.15,0.0]],"prev_change_id":23707182398}}}
[2025-04-07 08:30:58.993] [multi_sink] [info] 📩 Received: {"jsonrpc":"2.0","method":"subscription","params":{"channel":"book.BTC-PERPETUAL.100ms","data":{"timestamp":1743994860622,"type":"change","change_id":41151944865,"instrument_name":"BTC-PERPETUAL","bids":[["delete",78410.0,0.0],["delete",78405.0,0.0],["delete",78402.5,0.0],["delete",7.84e4,0.0],["delete",78399.5,0.0],["delete",78397.5,0.0],["delete",78397.0,0.0],["delete",78395.0,0.0]],"asks":[["new",78391.5,6.06e4],["new",78392.0,60470.0],["new",78393.0,23680.0],["new",78394.0,2.2e4],["new",78395.0,81930.0],["new",78395.5,5210.0],["new",78396.0,29170.0],["delete",78410.5,0.0],["delete",78411.5,0.0],["delete",78412.0,0.0],["delete",78412.5,0.0],["delete",78413.0,0.0],["delete",78413.5,0.0],["delete",78414.0,0.0],["delete",78416.0,0.0]],"prev_change_id":41151942591}}}
[2025-04-07 08:30:58.997] [multi_sink] [info] Processing received message: {"jsonrpc":"2.0","method":"subscription","params":{"channel":"book.BTC-PERPETUAL.100ms","data":{"timestamp":1743994860622,"type":"change","change_id":41151944865,"instrument_name":"BTC-PERPETUAL","bids":[["delete",78410.0,0.0],["delete",78405.0,0.0],["delete",78402.5,0.0],["delete",7.84e4,0.0],["delete",78399.5,0.0],["delete",78397.5,0.0],["delete",78397.0,0.0],["delete",78395.0,0.0]],"asks":[["new",78391.5,6.06e4],["new",78392.0,60470.0],["new",78393.0,23680.0],["new",78394.0,2.2e4],["new",78395.0,81930.0],["new",78395.5,5210.0],["new",78396.0,29170.0],["delete",78410.5,0.0],["delete",78411.5,0.0],["delete",78412.0,0.0],["delete",78412.5,0.0],["delete",78413.0,0.0],["delete",78413.5,0.0],["delete",78414.0,0.0],["delete",78416.0,0.0]],"prev_change_id":41151942591}}}
[2025-04-07 08:30:59.328] [multi_sink] [info] 📩 Received: {"jsonrpc":"2.0","method":"subscription","params":{"channel":"book.BTC-PERPETUAL.100ms","data":{"timestamp":1743994860936,"type":"change","change_id":41151945469,"instrument_name":"BTC-PERPETUAL","bids":[["delete",78387.5,0.0],["delete",78386.0,0.0],["delete",78384.5,0.0],["delete",78384.0,0.0],["delete",78382.0,0.0],["delete",78381.5,0.0],["delete",78381.0,0.0],["delete",78380.0,0.0],["delete",78379.5,0.0],["new",78372.5,490.0],["new",78372.0,490.0],["new",78371.0,1680.0],["new",78370.5,490.0],["new",78370.0,2010.0],["new",78369.5,490.0],["new",78368.5,490.0],["new",78368.0,490.0],["new",78367.5,150.0],["new",78215.0,78210.0],["new",78165.0,117240.0]],"asks":[["new",78384.0,500.0],["new",78384.5,1.2e4],["new",78386.5,3.45e4],["new",78389.0,15740.0],["new",78389.5,42890.0],["new",78390.0,81640.0],["new",78390.5,3090.0],["new",78391.0,1.0e4],["delete",78416.5,0.0],["delete",78417.0,0.0],["delete",78418.0,0.0],["delete",78418.5,0.0],["delete",78419.0,0.0],["delete",78422.5,0.0],["delete",78423.0,0.0],["delete",78423.5,0.0],["new",78546.0,78540.0],["new",78596.0,117890.0]],"prev_change_id":41151944865}}}
[2025-04-07 08:30:59.330] [multi_sink] [info] Processing received message: {"jsonrpc":"2.0","method":"subscription","params":{"channel":"book.BTC-PERPETUAL.100ms","data":{"timestamp":1743994860936,"type":"change","change_id":41151945469,"instrument_name":"BTC-PERPETUAL","bids":[["delete",78387.5,0.0],["delete",78386.0,0.0],["delete",78384.5,0.0],["delete",78384.0,0.0],["delete",78382.0,0.0],["delete",78381.5,0.0],["delete",78381.0,0.0],["delete",78380.0,0.0],["delete",78379.5,0.0],["new",78372.5,490.0],["new",78372.0,490.0],["new",78371.0,1680.0],["new",78370.5,490.0],["new",78370.0,2010.0],["new",78369.5,490.0],["new",78368.5,490.0],["new",78368.0,490.0],["new",78367.5,150.0],["new",78215.0,78210.0],["new",78165.0,117240.0]],"asks":[["new",78384.0,500.0],["new",78384.5,1.2e4],["new",78386.5,3.45e4],["new",78389.0,15740.0],["new",78389.5,42890.0],["new",78390.0,81640.0],["new",78390.5,3090.0],["new",78391.0,1.0e4],["delete",78416.5,0.0],["delete",78417.0,0.0],["delete",78418.0,0.0],["delete",78418.5,0.0],["delete",78419.0,0.0],["delete",78422.5,0.0],["delete",78423.0,0.0],["delete",78423.5,0.0],["new",78546.0,78540.0],["new",78596.0,117890.0]],"prev_change_id":41151944865}}}
[2025-04-07 08:30:59.405] [multi_sink] [info] 📩 Received: {"jsonrpc":"2.0","method":"subscription","params":{"channel":"book.ETH-PERPETUAL.100ms","data":{"timestamp":1743994860839,"type":"change","change_id":23707184297,"instrument_name":"ETH-PERPETUAL","bids":[["delete",1578.7,0.0],["new",1577.0,7643377.0]],"asks":[],"prev_change_id":23707182711}}}
[2025-04-07 08:30:59.408] [multi_sink] [info] Processing received message: {"jsonrpc":"2.0","method":"subscription","params":{"channel":"book.ETH-PERPETUAL.100ms","data":{"timestamp":1743994860839,"type":"change","change_id":23707184297,"instrument_name":"ETH-PERPETUAL","bids":[["delete",1578.7,0.0],["new",1577.0,7643377.0]],"asks":[],"prev_change_id":23707182711}}}
[2025-04-07 08:30:59.654] [multi_sink] [info] 📩 Received: {"jsonrpc":"2.0","method":"subscription","params":{"channel":"book.BTC-PERPETUAL.100ms","data":{"timestamp":1743994861075,"type":"change","change_id":41151945532,"instrument_name":"BTC-PERPETUAL","bids":[["delete",78378.0,0.0],["delete",78377.5,0.0],["delete",78376.5,0.0],["new",78374.5,490.0],["new",78373.5,490.0]],"asks":[["new",78375.5,21120.0],["new",78383.0,1.06e4],["new",78383.5,35320.0],["delete",78424.5,0.0],["delete",78425.0,0.0],["delete",78425.5,0.0],["delete",78427.0,0.0]],"prev_change_id":41151945469}}}
[2025-04-07 08:30:59.657] [multi_sink] [info] Processing received message: {"jsonrpc":"2.0","method":"subscription","params":{"channel":"book.BTC-PERPETUAL.100ms","data":{"timestamp":1743994861075,"type":"change","change_id":41151945532,"instrument_name":"BTC-PERPETUAL","bids":[["delete",78378.0,0.0],["delete",78377.5,0.0],["delete",78376.5,0.0],["new",78374.5,490.0],["new",78373.5,490.0]],"asks":[["new",78375.5,21120.0],["new",78383.0,1.06e4],["new",78383.5,35320.0],["delete",78424.5,0.0],["delete",78425.0,0.0],["delete",78425.5,0.0],["delete",78427.0,0.0]],"prev_change_id":41151945469}}}
[2025-04-07 08:30:59.737] [multi_sink] [info] 📩 Received: {"jsonrpc":"2.0","method":"subscription","params":{"channel":"book.ETH-PERPETUAL.100ms","data":{"timestamp":1743994861168,"type":"change","change_id":23707184656,"instrument_name":"ETH-PERPETUAL","bids":[],"asks":[["new",1578.5,6111993.0],["delete",1580.2,0.0]],"prev_change_id":23707184297}}}
[2025-04-07 08:30:59.742] [multi_sink] [info] Processing received message: {"jsonrpc":"2.0","method":"subscription","params":{"channel":"book.ETH-PERPETUAL.100ms","data":{"timestamp":1743994861168,"type":"change","change_id":23707184656,"instrument_name":"ETH-PERPETUAL","bids":[],"asks":[["new",1578.5,6111993.0],["delete",1580.2,0.0]],"prev_change_id":23707184297}}}
[2025-04-07 08:31:01.595] [multi_sink] [info] 📩 Received: {"jsonrpc":"2.0","method":"subscription","params":{"channel":"book.BTC-PERPETUAL.100ms","data":{"timestamp":1743994863222,"type":"change","change_id":41151948751,"instrument_name":"BTC-PERPETUAL","bids":[],"asks":[["new",78536.0,78530.0],["delete",78546.0,0.0]],"prev_change_id":41151945532}}}
[2025-04-07 08:31:01.595] [multi_sink] [info] Processing received message: {"jsonrpc":"2.0","method":"subscription","params":{"channel":"book.BTC-PERPETUAL.100ms","data":{"timestamp":1743994863222,"type":"change","change_id":41151948751,"instrument_name":"BTC-PERPETUAL","bids":[],"asks":[["new",78536.0,78530.0],["delete",78546.0,0.0]],"prev_change_id":41151945532}}}
[2025-04-07 08:31:01.920] [multi_sink] [info] 📩 Received: {"jsonrpc":"2.0","method":"subscription","params":{"channel":"book.BTC-PERPETUAL.100ms","data":{"timestamp":1743994863303,"type":"change","change_id":41151949262,"instrument_name":"BTC-PERPETUAL","bids":[["delete",78215.0,0.0],["new",78202.0,7.82e4],["delete",78165.0,0.0],["new",78152.0,117220.0]],"asks":[["new",78586.0,117870.0],["delete",78596.0,0.0]],"prev_change_id":41151948751}}}
[2025-04-07 08:31:01.921] [multi_sink] [info] Processing received message: {"jsonrpc":"2.0","method":"subscription","params":{"channel":"book.BTC-PERPETUAL.100ms","data":{"timestamp":1743994863303,"type":"change","change_id":41151949262,"instrument_name":"BTC-PERPETUAL","bids":[["delete",78215.0,0.0],["new",78202.0,7.82e4],["delete",78165.0,0.0],["new",78152.0,117220.0]],"asks":[["new",78586.0,117870.0],["delete",78596.0,0.0]],"prev_change_id":41151948751}}}
[2025-04-07 08:31:02.181] [multi_sink] [info] 📩 Received: {"jsonrpc":"2.0","method":"subscription","params":{"channel":"book.ETH-PERPETUAL.100ms","data":{"timestamp":1743994863811,"type":"change","change_id":23707187234,"instrument_name":"ETH-PERPETUAL","bids":[],"asks":[["delete",1578.75,0.0],["change",1578.85,16796.0]],"prev_change_id":23707184656}}}
[2025-04-07 08:31:02.181] [multi_sink] [info] Processing received message: {"jsonrpc":"2.0","method":"subscription","params":{"channel":"book.ETH-PERPETUAL.100ms","data":{"timestamp":1743994863811,"type":"change","change_id":23707187234,"instrument_name":"ETH-PERPETUAL","bids":[],"asks":[["delete",1578.75,0.0],["change",1578.85,16796.0]],"prev_change_id":23707184656}}}
[2025-04-07 08:31:02.507] [multi_sink] [info] 📩 Received: {"jsonrpc":"2.0","method":"subscription","params":{"channel":"book.ETH-PERPETUAL.100ms","data":{"timestamp":1743994864132,"type":"change","change_id":23707187746,"instrument_name":"ETH-PERPETUAL","bids":[["delete",1578.25,0.0],["delete",1578.15,0.0],["delete",1578.05,0.0],["delete",1578.0,0.0],["delete",1577.95,0.0],["delete",1577.9,0.0],["delete",1577.85,0.0],["delete",1577.8,0.0],["delete",1577.75,0.0],["new",1577.1,3127.0],["new",1577.05,14343.0],["change",1577.0,7651837.0],["new",1576.95,36774.0],["new",1576.9,13773.0],["new",1576.85,43475.0],["new",1576.8,4790.0],["new",1576.75,15669.0],["new",1576.7,2276.0]],"asks":[["new",1578.4,27167.0],["new",1578.45,14102.0],["change",1578.5,6208156.0],["new",1578.55,10773.0],["new",1578.6,15885.0],["new",1578.65,925.0],["new",1578.7,4007.0],["new",1578.75,8458.0],["change",1578.8,13791.0],["change",1578.85,5771.0],["delete",1578.9,0.0],["delete",1578.95,0.0],["delete",1579.0,0.0],["delete",1579.05,0.0],["delete",1579.1,0.0],["delete",1579.15,0.0],["delete",1579.2,0.0]],"prev_change_id":23707187234}}}
[2025-04-07 08:31:02.511] [multi_sink] [info] Processing received message: {"jsonrpc":"2.0","method":"subscription","params":{"channel":"book.ETH-PERPETUAL.100ms","data":{"timestamp":1743994864132,"type":"change","change_id":23707187746,"instrument_name":"ETH-PERPETUAL","bids":[["delete",1578.25,0.0],["delete",1578.15,0.0],["delete",1578.05,0.0],["delete",1578.0,0.0],["delete",1577.95,0.0],["delete",1577.9,0.0],["delete",1577.85,0.0],["delete",1577.8,0.0],["delete",1577.75,0.0],["new",1577.1,3127.0],["new",1577.05,14343.0],["change",1577.0,7651837.0],["new",1576.95,36774.0],["new",1576.9,13773.0],["new",1576.85,43475.0],["new",1576.8,4790.0],["new",1576.75,15669.0],["new",1576.7,2276.0]],"asks":[["new",1578.4,27167.0],["new",1578.45,14102.0],["change",1578.5,6208156.0],["new",1578.55,10773.0],["new",1578.6,15885.0],["new",1578.65,925.0],["new",1578.7,4007.0],["new",1578.75,8458.0],["change",1578.8,13791.0],["change",1578.85,5771.0],["delete",1578.9,0.0],["delete",1578.95,0.0],["delete",1579.0,0.0],["delete",1579.05,0.0],["delete",1579.1,0.0],["delete",1579.15,0.0],["delete",1579.2,0.0]],"prev_change_id":23707187234}}}
[2025-04-07 08:31:02.839] [multi_sink] [info] 📩 Received: {"jsonrpc":"2.0","method":"subscription","params":{"channel":"book.ETH-PERPETUAL.100ms","data":{"timestamp":1743994864461,"type":"change","change_id":23707188010,"instrument_name":"ETH-PERPETUAL","bids":[["delete",1577.7,0.0],["delete",1577.65,0.0],["delete",1577.6,0.0],["change",1577.55,1160.0],["change",1577.5,1958.0],["change",1577.45,9545.0],["change",1577.4,10005.0],["change",1577.35,8140.0],["change",1577.3,100.0],["change",1577.25,54595.0],["change",1577.2,79755.0],["new",1577.15,2301.0],["delete",1574.65,0.0],["new",1573.05,500.0]],"asks":[["new",1577.9,2972.0],["new",1577.95,9905.0],["new",1578.0,5.8e3],["new",1578.05,5.0e3],["new",1578.1,17036.0],["new",1578.15,6282.0],["new",1578.2,7260.0],["new",1578.3,9341.0],["new",1578.35,6025.0],["delete",1579.25,0.0],["delete",1579.3,0.0],["delete",1579.35,0.0],["delete",1579.4,0.0],["delete",1579.45,0.0]],"prev_change_id":23707187746}}}
[2025-04-07 08:31:02.843] [multi_sink] [info] Processing received message: {"jsonrpc":"2.0","method":"subscription","params":{"channel":"book.ETH-PERPETUAL.100ms","data":{"timestamp":1743994864461,"type":"change","change_id":23707188010,"instrument_name":"ETH-PERPETUAL","bids":[["delete",1577.7,0.0],["delete",1577.65,0.0],["delete",1577.6,0.0],["change",1577.55,1160.0],["change",1577.5,1958.0],["change",1577.45,9545.0],["change",1577.4,10005.0],["change",1577.35,8140.0],["change",1577.3,100.0],["change",1577.25,54595.0],["change",1577.2,79755.0],["new",1577.15,2301.0],["delete",1574.65,0.0],["new",1573.05,500.0]],"asks":[["new",1577.9,2972.0],["new",1577.95,9905.0],["new",1578.0,5.8e3],["new",1578.05,5.0e3],["new",1578.1,17036.0],["new",1578.15,6282.0],["new",1578.2,7260.0],["new",1578.3,9341.0],["new",1578.35,6025.0],["delete",1579.25,0.0],["delete",1579.3,0.0],["delete",1579.35,0.0],["delete",1579.4,0.0],["delete",1579.45,0.0]],"prev_change_id":23707187746}}}
[2025-04-07 08:31:03.170] [multi_sink] [info] 📩 Received: {"jsonrpc":"2.0","method":"subscription","params":{"channel":"book.ETH-PERPETUAL.100ms","data":{"timestamp":1743994864516,"type":"change","change_id":23707188112,"instrument_name":"ETH-PERPETUAL","bids":[["new",1577.75,1709.0],["new",1577.7,543.0],["change",1577.25,50385.0],["change",1577.2,76962.0]],"asks":[["new",1577.85,6157.0]],"prev_change_id":23707188010}}}
[2025-04-07 08:31:03.173] [multi_sink] [info] Processing received message: {"jsonrpc":"2.0","method":"subscription","params":{"channel":"book.ETH-PERPETUAL.100ms","data":{"timestamp":1743994864516,"type":"change","change_id":23707188112,"instrument_name":"ETH-PERPETUAL","bids":[["new",1577.75,1709.0],["new",1577.7,543.0],["change",1577.25,50385.0],["change",1577.2,76962.0]],"asks":[["new",1577.85,6157.0]],"prev_change_id":23707188010}}}
[2025-04-07 08:31:03.619] [multi_sink] [info] 📩 Received: {"jsonrpc":"2.0","method":"subscription","params":{"channel":"book.BTC-PERPETUAL.100ms","data":{"timestamp":1743994865248,"type":"change","change_id":41151952110,"instrument_name":"BTC-PERPETUAL","bids":[],"asks":[["new",78525.5,78520.0],["delete",78536.0,0.0]],"prev_change_id":41151949262}}}
[2025-04-07 08:31:03.620] [multi_sink] [info] Processing received message: {"jsonrpc":"2.0","method":"subscription","params":{"channel":"book.BTC-PERPETUAL.100ms","data":{"timestamp":1743994865248,"type":"change","change_id":41151952110,"instrument_name":"BTC-PERPETUAL","bids":[],"asks":[["new",78525.5,78520.0],["delete",78536.0,0.0]],"prev_change_id":41151949262}}}
[2025-04-07 08:31:03.945] [multi_sink] [info] 📩 Received: {"jsonrpc":"2.0","method":"subscription","params":{"channel":"book.BTC-PERPETUAL.100ms","data":{"timestamp":1743994865557,"type":"change","change_id":41151952364,"instrument_name":"BTC-PERPETUAL","bids":[["delete",78374.5,0.0],["delete",78373.5,0.0],["delete",78372.5,0.0],["delete",78372.0,0.0],["delete",78371.0,0.0],["delete",78370.5,0.0],["new",78364.5,490.0],["new",78364.0,490.0],["new",78363.5,4040.0],["new",78363.0,490.0],["new",78362.5,9930.0],["new",78361.5,490.0]],"asks":[["delete",78375.5,0.0],["delete",78383.0,0.0],["delete",78383.5,0.0],["delete",78384.0,0.0],["delete",78384.5,0.0],["delete",78386.5,0.0],["new",78387.0,3.5e4],["new",78387.5,390.0],["new",78388.0,7.05e4],["new",78388.5,20.0],["change",78390.0,163710.0],["change",78391.5,74330.0],["delete",78525.5,0.0],["new",78537.5,78530.0],["delete",78586.0,0.0],["new",78587.5,117870.0]],"prev_change_id":41151952110}}}
[2025-04-07 08:31:03.949] [multi_sink] [info] Processing received message: {"jsonrpc":"2.0","method":"subscription","params":{"channel":"book.BTC-PERPETUAL.100ms","data":{"timestamp":1743994865557,"type":"change","change_id":41151952364,"instrument_name":"BTC-PERPETUAL","bids":[["delete",78374.5,0.0],["delete",78373.5,0.0],["delete",78372.5,0.0],["delete",78372.0,0.0],["delete",78371.0,0.0],["delete",78370.5,0.0],["new",78364.5,490.0],["new",78364.0,490.0],["new",78363.5,4040.0],["new",78363.0,490.0],["new",78362.5,9930.0],["new",78361.5,490.0]],"asks":[["delete",78375.5,0.0],["delete",78383.0,0.0],["delete",78383.5,0.0],["delete",78384.0,0.0],["delete",78384.5,0.0],["delete",78386.5,0.0],["new",78387.0,3.5e4],["new",78387.5,390.0],["new",78388.0,7.05e4],["new",78388.5,20.0],["change",78390.0,163710.0],["change",78391.5,74330.0],["delete",78525.5,0.0],["new",78537.5,78530.0],["delete",78586.0,0.0],["new",78587.5,117870.0]],"prev_change_id":41151952110}}}
[2025-04-07 08:31:04.277] [multi_sink] [info] 📩 Received: {"jsonrpc":"2.0","method":"subscription","params":{"channel":"book.BTC-PERPETUAL.100ms","data":{"timestamp":1743994865903,"type":"change","change_id":41151952882,"instrument_name":"BTC-PERPETUAL","bids":[["new",78370.5,490.0],["change",78370.0,2010.0],["change",78369.5,490.0],["change",78368.5,680.0],["change",78368.0,960.0],["delete",78367.5,0.0],["new",78367.0,490.0],["change",78366.5,7826210.0],["new",78366.0,200.0],["new",78365.5,490.0]],"asks":[["new",78378.5,4770.0],["new",78380.0,95480.0],["new",78381.5,1.65e4],["new",78382.0,33490.0],["new",78382.5,9620.0],["new",78383.0,5740.0],["new",78383.5,85380.0],["new",78384.5,1.65e4],["new",78385.5,1.0e4],["new",78386.5,20920.0],["delete",78389.0,0.0],["delete",78389.5,0.0],["change",78390.0,82070.0],["delete",78390.5,0.0],["delete",78391.0,0.0],["change",78391.5,13730.0],["delete",78392.0,0.0],["delete",78393.0,0.0],["delete",78394.0,0.0],["delete",78395.0,0.0]],"prev_change_id":41151952364}}}
[2025-04-07 08:31:04.279] [multi_sink] [info] Processing received message: {"jsonrpc":"2.0","method":"subscription","params":{"channel":"book.BTC-PERPETUAL.100ms","data":{"timestamp":1743994865903,"type":"change","change_id":41151952882,"instrument_name":"BTC-PERPETUAL","bids":[["new",78370.5,490.0],["change",78370.0,2010.0],["change",78369.5,490.0],["change",78368.5,680.0],["change",78368.0,960.0],["delete",78367.5,0.0],["new",78367.0,490.0],["change",78366.5,7826210.0],["new",78366.0,200.0],["new",78365.5,490.0]],"asks":[["new",78378.5,4770.0],["new",78380.0,95480.0],["new",78381.5,1.65e4],["new",78382.0,33490.0],["new",78382.5,9620.0],["new",78383.0,5740.0],["new",78383.5,85380.0],["new",78384.5,1.65e4],["new",78385.5,1.0e4],["new",78386.5,20920.0],["delete",78389.0,0.0],["delete",78389.5,0.0],["change",78390.0,82070.0],["delete",78390.5,0.0],["delete",78391.0,0.0],["change",78391.5,13730.0],["delete",78392.0,0.0],["delete",78393.0,0.0],["delete",78394.0,0.0],["delete",78395.0,0.0]],"prev_change_id":41151952364}}}
[2025-04-07 08:31:04.607] [multi_sink] [info] 📩 Received: {"jsonrpc":"2.0","method":"subscription","params":{"channel":"book.BTC-PERPETUAL.100ms","data":{"timestamp":1743994866073,"type":"change","change_id":41151953097,"instrument_name":"BTC-PERPETUAL","bids":[["new",78374.5,18230.0],["new",78373.5,650.0],["new",78372.5,490.0],["new",78372.0,490.0],["new",78371.0,660.0],["change",78366.5,490.0],["new",78341.0,7825720.0],["delete",78213.5,0.0],["new",78188.0,8000580.0]],"asks":[["new",78375.0,80830.0],["new",78375.5,61110.0],["new",78376.0,15550.0],["new",78378.0,490.0],["delete",78395.5,0.0],["delete",78396.0,0.0]],"prev_change_id":41151952882}}}
[2025-04-07 08:31:04.609] [multi_sink] [info] Processing received message: {"jsonrpc":"2.0","method":"subscription","params":{"channel":"book.BTC-PERPETUAL.100ms","data":{"timestamp":1743994866073,"type":"change","change_id":41151953097,"instrument_name":"BTC-PERPETUAL","bids":[["new",78374.5,18230.0],["new",78373.5,650.0],["new",78372.5,490.0],["new",78372.0,490.0],["new",78371.0,660.0],["change",78366.5,490.0],["new",78341.0,7825720.0],["delete",78213.5,0.0],["new",78188.0,8000580.0]],"asks":[["new",78375.0,80830.0],["new",78375.5,61110.0],["new",78376.0,15550.0],["new",78378.0,490.0],["delete",78395.5,0.0],["delete",78396.0,0.0]],"prev_change_id":41151952882}}}
[2025-04-07 08:31:04.938] [multi_sink] [info] 📩 Received: {"jsonrpc":"2.0","method":"subscription","params":{"channel":"book.BTC-PERPETUAL.100ms","data":{"timestamp":1743994866404,"type":"change","change_id":41151953931,"instrument_name":"BTC-PERPETUAL","bids":[],"asks":[["new",78418.5,6640830.0],["delete",78444.0,0.0],["new",78571.5,7777770.0],["delete",78597.0,0.0]],"prev_change_id":41151953097}}}
[2025-04-07 08:31:04.939] [multi_sink] [info] Processing received message: {"jsonrpc":"2.0","method":"subscription","params":{"channel":"book.BTC-PERPETUAL.100ms","data":{"timestamp":1743994866404,"type":"change","change_id":41151953931,"instrument_name":"BTC-PERPETUAL","bids":[],"asks":[["new",78418.5,6640830.0],["delete",78444.0,0.0],["new",78571.5,7777770.0],["delete",78597.0,0.0]],"prev_change_id":41151953097}}}
[2025-04-07 08:31:06.020] [multi_sink] [info] 📩 Received: {"jsonrpc":"2.0","method":"subscription","params":{"channel":"book.BTC-PERPETUAL.100ms","data":{"timestamp":1743994867648,"type":"change","change_id":41151955490,"instrument_name":"BTC-PERPETUAL","bids":[],"asks":[["new",78526.0,78520.0],["delete",78537.5,0.0]],"prev_change_id":41151953931}}}
[2025-04-07 08:31:06.024] [multi_sink] [info] Processing received message: {"jsonrpc":"2.0","method":"subscription","params":{"channel":"book.BTC-PERPETUAL.100ms","data":{"timestamp":1743994867648,"type":"change","change_id":41151955490,"instrument_name":"BTC-PERPETUAL","bids":[],"asks":[["new",78526.0,78520.0],["delete",78537.5,0.0]],"prev_change_id":41151953931}}}
[2025-04-07 08:31:06.346] [multi_sink] [info] 📩 Received: {"jsonrpc":"2.0","method":"subscription","params":{"channel":"book.BTC-PERPETUAL.100ms","data":{"timestamp":1743994867653,"type":"change","change_id":41151955492,"instrument_name":"BTC-PERPETUAL","bids":[],"asks":[["new",78576.0,117860.0],["delete",78587.5,0.0]],"prev_change_id":41151955490}}}
[2025-04-07 08:31:06.349] [multi_sink] [info] Processing received message: {"jsonrpc":"2.0","method":"subscription","params":{"channel":"book.BTC-PERPETUAL.100ms","data":{"timestamp":1743994867653,"type":"change","change_id":41151955492,"instrument_name":"BTC-PERPETUAL","bids":[],"asks":[["new",78576.0,117860.0],["delete",78587.5,0.0]],"prev_change_id":41151955490}}}
[2025-04-07 08:31:06.408] [multi_sink] [info] 📩 Received: {"jsonrpc":"2.0","method":"subscription","params":{"channel":"book.ETH-PERPETUAL.100ms","data":{"timestamp":1743994868039,"type":"change","change_id":23707191763,"instrument_name":"ETH-PERPETUAL","bids":[["change",1577.05,7657720.0],["change",1577.0,8460.0]],"asks":[],"prev_change_id":23707188112}}}
[2025-04-07 08:31:06.411] [multi_sink] [info] Processing received message: {"jsonrpc":"2.0","method":"subscription","params":{"channel":"book.ETH-PERPETUAL.100ms","data":{"timestamp":1743994868039,"type":"change","change_id":23707191763,"instrument_name":"ETH-PERPETUAL","bids":[["change",1577.05,7657720.0],["change",1577.0,8460.0]],"asks":[],"prev_change_id":23707188112}}}
[2025-04-07 08:31:06.681] [multi_sink] [info] 📩 Received: {"jsonrpc":"2.0","method":"subscription","params":{"channel":"book.BTC-PERPETUAL.100ms","data":{"timestamp":1743994868192,"type":"change","change_id":41151956035,"instrument_name":"BTC-PERPETUAL","bids":[["delete",78202.0,0.0],["new",78191.0,78190.0],["delete",78152.0,0.0],["new",78141.0,117210.0]],"asks":[],"prev_change_id":41151955492}}}
[2025-04-07 08:31:06.681] [multi_sink] [info] Processing received message: {"jsonrpc":"2.0","method":"subscription","params":{"channel":"book.BTC-PERPETUAL.100ms","data":{"timestamp":1743994868192,"type":"change","change_id":41151956035,"instrument_name":"BTC-PERPETUAL","bids":[["delete",78202.0,0.0],["new",78191.0,78190.0],["delete",78152.0,0.0],["new",78141.0,117210.0]],"asks":[],"prev_change_id":41151955492}}}
[2025-04-07 08:31:06.776] [multi_sink] [info] 📩 Received: {"jsonrpc":"2.0","method":"subscription","params":{"channel":"book.ETH-PERPETUAL.100ms","data":{"timestamp":1743994868409,"type":"change","change_id":23707192010,"instrument_name":"ETH-PERPETUAL","bids":[],"asks":[["change",1578.5,96163.0],["change",1578.55,6122766.0]],"prev_change_id":23707191763}}}
[2025-04-07 08:31:06.780] [multi_sink] [info] Processing received message: {"jsonrpc":"2.0","method":"subscription","params":{"channel":"book.ETH-PERPETUAL.100ms","data":{"timestamp":1743994868409,"type":"change","change_id":23707192010,"instrument_name":"ETH-PERPETUAL","bids":[],"asks":[["change",1578.5,96163.0],["change",1578.55,6122766.0]],"prev_change_id":23707191763}}}
[2025-04-07 08:31:07.437] [multi_sink] [info] 📩 Received: {"jsonrpc":"2.0","method":"subscription","params":{"channel":"book.ETH-PERPETUAL.100ms","data":{"timestamp":1743994869063,"type":"change","change_id":23707192733,"instrument_name":"ETH-PERPETUAL","bids":[["delete",1577.75,0.0],["delete",1577.7,0.0],["delete",1577.55,0.0],["delete",1577.5,0.0],["delete",1577.45,0.0],["delete",1577.4,0.0],["delete",1577.35,0.0],["delete",1577.3,0.0],["new",1576.45,2312.0],["new",1576.4,1023.0],["new",1576.35,5279.0],["new",1576.3,4023.0],["new",1576.25,14679.0],["new",1576.2,38866.0],["new",1576.15,923.0],["new",1576.1,1023.0]],"asks":[["delete",1577.85,0.0],["delete",1577.9,0.0],["delete",1577.95,0.0],["change",1578.0,143447.0],["change",1578.05,8360.0],["change",1578.1,889.0],["change",1578.15,100.0],["change",1578.2,1598.0],["new",1578.25,2031.0],["change",1578.3,23384.0],["change",1578.35,40813.0]],"prev_change_id":23707192010}}}
[2025-04-07 08:31:07.439] [multi_sink] [info] Processing received message: {"jsonrpc":"2.0","method":"subscription","params":{"channel":"book.ETH-PERPETUAL.100ms","data":{"timestamp":1743994869063,"type":"change","change_id":23707192733,"instrument_name":"ETH-PERPETUAL","bids":[["delete",1577.75,0.0],["delete",1577.7,0.0],["delete",1577.55,0.0],["delete",1577.5,0.0],["delete",1577.45,0.0],["delete",1577.4,0.0],["delete",1577.35,0.0],["delete",1577.3,0.0],["new",1576.45,2312.0],["new",1576.4,1023.0],["new",1576.35,5279.0],["new",1576.3,4023.0],["new",1576.25,14679.0],["new",1576.2,38866.0],["new",1576.15,923.0],["new",1576.1,1023.0]],"asks":[["delete",1577.85,0.0],["delete",1577.9,0.0],["delete",1577.95,0.0],["change",1578.0,143447.0],["change",1578.05,8360.0],["change",1578.1,889.0],["change",1578.15,100.0],["change",1578.2,1598.0],["new",1578.25,2031.0],["change",1578.3,23384.0],["change",1578.35,40813.0]],"prev_change_id":23707192010}}}
[2025-04-07 08:31:07.582] [multi_sink] [info] 📩 Received: {"jsonrpc":"2.0","method":"subscription","params":{"channel":"book.BTC-PERPETUAL.100ms","data":{"timestamp":1743994869215,"type":"change","change_id":41151957447,"instrument_name":"BTC-PERPETUAL","bids":[],"asks":[["new",78515.5,78510.0],["delete",78526.0,0.0]],"prev_change_id":41151956035}}}
[2025-04-07 08:31:07.584] [multi_sink] [info] Processing received message: {"jsonrpc":"2.0","method":"subscription","params":{"channel":"book.BTC-PERPETUAL.100ms","data":{"timestamp":1743994869215,"type":"change","change_id":41151957447,"instrument_name":"BTC-PERPETUAL","bids":[],"asks":[["new",78515.5,78510.0],["delete",78526.0,0.0]],"prev_change_id":41151956035}}}
[2025-04-07 08:31:07.773] [multi_sink] [info] 📩 Received: {"jsonrpc":"2.0","method":"subscription","params":{"channel":"book.ETH-PERPETUAL.100ms","data":{"timestamp":1743994869373,"type":"change","change_id":23707192849,"instrument_name":"ETH-PERPETUAL","bids":[["delete",1577.25,0.0],["delete",1577.2,0.0],["delete",1577.15,0.0],["delete",1577.1,0.0],["change",1577.05,7643377.0],["delete",1577.0,0.0],["delete",1576.95,0.0],["change",1576.9,27084.0],["change",1576.8,6339.0],["change",1576.75,96706.0],["change",1576.7,32537.0],["new",1576.65,926.0],["new",1576.6,1814.0],["new",1576.55,3838.0],["new",1576.5,8454.0]],"asks":[["new",1577.55,21539.0],["new",1577.65,100.0],["new",1577.7,9155.0],["new",1577.75,18260.0],["new",1577.8,19269.0],["new",1577.85,460.0],["new",1577.9,57440.0],["new",1577.95,14003.0],["change",1578.3,14043.0],["change",1578.35,34788.0],["delete",1578.4,0.0],["delete",1578.45,0.0],["delete",1578.5,0.0],["change",1578.55,6111993.0],["delete",1578.6,0.0],["delete",1578.65,0.0]],"prev_change_id":23707192733}}}
[2025-04-07 08:31:07.776] [multi_sink] [info] Processing received message: {"jsonrpc":"2.0","method":"subscription","params":{"channel":"book.ETH-PERPETUAL.100ms","data":{"timestamp":1743994869373,"type":"change","change_id":23707192849,"instrument_name":"ETH-PERPETUAL","bids":[["delete",1577.25,0.0],["delete",1577.2,0.0],["delete",1577.15,0.0],["delete",1577.1,0.0],["change",1577.05,7643377.0],["delete",1577.0,0.0],["delete",1576.95,0.0],["change",1576.9,27084.0],["change",1576.8,6339.0],["change",1576.75,96706.0],["change",1576.7,32537.0],["new",1576.65,926.0],["new",1576.6,1814.0],["new",1576.55,3838.0],["new",1576.5,8454.0]],"asks":[["new",1577.55,21539.0],["new",1577.65,100.0],["new",1577.7,9155.0],["new",1577.75,18260.0],["new",1577.8,19269.0],["new",1577.85,460.0],["new",1577.9,57440.0],["new",1577.95,14003.0],["change",1578.3,14043.0],["change",1578.35,34788.0],["delete",1578.4,0.0],["delete",1578.45,0.0],["delete",1578.5,0.0],["change",1578.55,6111993.0],["delete",1578.6,0.0],["delete",1578.65,0.0]],"prev_change_id":23707192733}}}
[2025-04-07 08:31:07.913] [multi_sink] [info] 📩 Received: {"jsonrpc":"2.0","method":"subscription","params":{"channel":"book.BTC-PERPETUAL.100ms","data":{"timestamp":1743994869218,"type":"change","change_id":41151957448,"instrument_name":"BTC-PERPETUAL","bids":[],"asks":[["new",78565.5,117840.0],["delete",78576.0,0.0]],"prev_change_id":41151957447}}}
[2025-04-07 08:31:07.916] [multi_sink] [info] Processing received message: {"jsonrpc":"2.0","method":"subscription","params":{"channel":"book.BTC-PERPETUAL.100ms","data":{"timestamp":1743994869218,"type":"change","change_id":41151957448,"instrument_name":"BTC-PERPETUAL","bids":[],"asks":[["new",78565.5,117840.0],["delete",78576.0,0.0]],"prev_change_id":41151957447}}}
[2025-04-07 08:31:08.099] [multi_sink] [info] 📩 Received: {"jsonrpc":"2.0","method":"subscription","params":{"channel":"book.ETH-PERPETUAL.100ms","data":{"timestamp":1743994869523,"type":"change","change_id":23707193096,"instrument_name":"ETH-PERPETUAL","bids":[["new",1577.25,1687.0],["change",1577.05,7643762.0],["new",1577.0,2971.0],["new",1576.95,12372.0],["delete",1576.85,0.0],["change",1576.8,1549.0],["change",1576.75,81037.0],["change",1576.7,30261.0]],"asks":[["new",1577.3,39989.0],["new",1577.35,6751.0],["new",1577.4,9904.0],["new",1577.5,18582.0],["delete",1578.7,0.0],["delete",1578.75,0.0],["delete",1578.8,0.0],["delete",1578.85,0.0]],"prev_change_id":23707192849}}}
[2025-04-07 08:31:08.101] [multi_sink] [info] Processing received message: {"jsonrpc":"2.0","method":"subscription","params":{"channel":"book.ETH-PERPETUAL.100ms","data":{"timestamp":1743994869523,"type":"change","change_id":23707193096,"instrument_name":"ETH-PERPETUAL","bids":[["new",1577.25,1687.0],["change",1577.05,7643762.0],["new",1577.0,2971.0],["new",1576.95,12372.0],["delete",1576.85,0.0],["change",1576.8,1549.0],["change",1576.75,81037.0],["change",1576.7,30261.0]],"asks":[["new",1577.3,39989.0],["new",1577.35,6751.0],["new",1577.4,9904.0],["new",1577.5,18582.0],["delete",1578.7,0.0],["delete",1578.75,0.0],["delete",1578.8,0.0],["delete",1578.85,0.0]],"prev_change_id":23707192849}}}
[2025-04-07 08:31:08.244] [multi_sink] [info] 📩 Received: {"jsonrpc":"2.0","method":"subscription","params":{"channel":"book.BTC-PERPETUAL.100ms","data":{"timestamp":1743994869851,"type":"change","change_id":41151958445,"instrument_name":"BTC-PERPETUAL","bids":[["delete",78191.0,0.0],["new",78179.0,78170.0],["delete",78141.0,0.0],["new",78129.0,117180.0]],"asks":[],"prev_change_id":41151957448}}}
[2025-04-07 08:31:08.246] [multi_sink] [info] Processing received message: {"jsonrpc":"2.0","method":"subscription","params":{"channel":"book.BTC-PERPETUAL.100ms","data":{"timestamp":1743994869851,"type":"change","change_id":41151958445,"instrument_name":"BTC-PERPETUAL","bids":[["delete",78191.0,0.0],["new",78179.0,78170.0],["delete",78141.0,0.0],["new",78129.0,117180.0]],"asks":[],"prev_change_id":41151957448}}}
[2025-04-07 08:31:08.573] [multi_sink] [info] 📩 Received: {"jsonrpc":"2.0","method":"subscription","params":{"channel":"book.BTC-PERPETUAL.100ms","data":{"timestamp":1743994870008,"type":"change","change_id":41151958788,"instrument_name":"BTC-PERPETUAL","bids":[],"asks":[["delete",78515.5,0.0],["delete",78565.5,0.0]],"prev_change_id":41151958445}}}
[2025-04-07 08:31:08.575] [multi_sink] [info] Processing received message: {"jsonrpc":"2.0","method":"subscription","params":{"channel":"book.BTC-PERPETUAL.100ms","data":{"timestamp":1743994870008,"type":"change","change_id":41151958788,"instrument_name":"BTC-PERPETUAL","bids":[],"asks":[["delete",78515.5,0.0],["delete",78565.5,0.0]],"prev_change_id":41151958445}}}
[2025-04-07 08:31:08.904] [multi_sink] [info] 📩 Received: {"jsonrpc":"2.0","method":"subscription","params":{"channel":"book.BTC-PERPETUAL.100ms","data":{"timestamp":1743994870507,"type":"change","change_id":41151959589,"instrument_name":"BTC-PERPETUAL","bids":[["delete",78374.5,0.0],["delete",78373.5,0.0],["delete",78372.5,0.0],["delete",78372.0,0.0],["delete",78371.0,0.0],["new",78324.0,4990.0],["new",78320.0,1.7e4],["new",78319.5,5.73e4],["new",78319.0,9440.0],["new",78318.5,16490.0]],"asks":[["new",78373.5,30190.0],["new",78374.0,37340.0],["change",78375.0,15370.0],["change",78375.5,160.0],["change",78376.0,6.98e4],["delete",78378.0,0.0],["delete",78378.5,0.0]],"prev_change_id":41151958788}}}
[2025-04-07 08:31:08.906] [multi_sink] [info] Processing received message: {"jsonrpc":"2.0","method":"subscription","params":{"channel":"book.BTC-PERPETUAL.100ms","data":{"timestamp":1743994870507,"type":"change","change_id":41151959589,"instrument_name":"BTC-PERPETUAL","bids":[["delete",78374.5,0.0],["delete",78373.5,0.0],["delete",78372.5,0.0],["delete",78372.0,0.0],["delete",78371.0,0.0],["new",78324.0,4990.0],["new",78320.0,1.7e4],["new",78319.5,5.73e4],["new",78319.0,9440.0],["new",78318.5,16490.0]],"asks":[["new",78373.5,30190.0],["new",78374.0,37340.0],["change",78375.0,15370.0],["change",78375.5,160.0],["change",78376.0,6.98e4],["delete",78378.0,0.0],["delete",78378.5,0.0]],"prev_change_id":41151958788}}}
[2025-04-07 08:31:09.239] [multi_sink] [info] 📩 Received: {"jsonrpc":"2.0","method":"subscription","params":{"channel":"book.BTC-PERPETUAL.100ms","data":{"timestamp":1743994870866,"type":"change","change_id":41151959983,"instrument_name":"BTC-PERPETUAL","bids":[["delete",78370.5,0.0],["delete",78370.0,0.0],["delete",78369.5,0.0],["delete",78368.5,0.0],["delete",78368.0,0.0],["delete",78367.0,0.0],["delete",78366.5,0.0],["delete",78366.0,0.0],["delete",78365.5,0.0],["delete",78364.5,0.0],["delete",78364.0,0.0],["delete",78363.5,0.0],["delete",78363.0,0.0],["change",78362.5,980.0]],"asks":[["new",78363.5,37560.0],["new",78364.0,19510.0],["new",78364.5,102410.0],["new",78365.0,149340.0],["new",78366.0,8820.0],["new",78367.5,3620.0],["new",78368.0,45860.0],["new",78369.0,1.7e3],["new",78370.0,1.91e4],["delete",78380.0,0.0],["delete",78381.5,0.0],["delete",78382.0,0.0],["delete",78382.5,0.0],["delete",78383.0,0.0],["delete",78383.5,0.0],["delete",78384.5,0.0],["delete",78385.5,0.0],["delete",78386.5,0.0],["delete",78387.0,0.0]],"prev_change_id":41151959589}}}
[2025-04-07 08:31:09.242] [multi_sink] [info] Processing received message: {"jsonrpc":"2.0","method":"subscription","params":{"channel":"book.BTC-PERPETUAL.100ms","data":{"timestamp":1743994870866,"type":"change","change_id":41151959983,"instrument_name":"BTC-PERPETUAL","bids":[["delete",78370.5,0.0],["delete",78370.0,0.0],["delete",78369.5,0.0],["delete",78368.5,0.0],["delete",78368.0,0.0],["delete",78367.0,0.0],["delete",78366.5,0.0],["delete",78366.0,0.0],["delete",78365.5,0.0],["delete",78364.5,0.0],["delete",78364.0,0.0],["delete",78363.5,0.0],["delete",78363.0,0.0],["change",78362.5,980.0]],"asks":[["new",78363.5,37560.0],["new",78364.0,19510.0],["new",78364.5,102410.0],["new",78365.0,149340.0],["new",78366.0,8820.0],["new",78367.5,3620.0],["new",78368.0,45860.0],["new",78369.0,1.7e3],["new",78370.0,1.91e4],["delete",78380.0,0.0],["delete",78381.5,0.0],["delete",78382.0,0.0],["delete",78382.5,0.0],["delete",78383.0,0.0],["delete",78383.5,0.0],["delete",78384.5,0.0],["delete",78385.5,0.0],["delete",78386.5,0.0],["delete",78387.0,0.0]],"prev_change_id":41151959589}}}
[2025-04-07 08:31:09.567] [multi_sink] [info] 📩 Received: {"jsonrpc":"2.0","method":"subscription","params":{"channel":"book.BTC-PERPETUAL.100ms","data":{"timestamp":1743994871054,"type":"change","change_id":41151960370,"instrument_name":"BTC-PERPETUAL","bids":[["delete",78362.5,0.0],["delete",78361.5,0.0]],"asks":[["new",78357.0,2.183e5],["new",78359.0,1.34e4],["new",78359.5,3.45e4],["new",78360.0,55860.0],["new",78360.5,200140.0],["delete",78387.5,0.0],["delete",78388.0,0.0],["delete",78388.5,0.0],["delete",78390.0,0.0],["delete",78391.5,0.0]],"prev_change_id":41151959983}}}
[2025-04-07 08:31:09.571] [multi_sink] [info] Processing received message: {"jsonrpc":"2.0","method":"subscription","params":{"channel":"book.BTC-PERPETUAL.100ms","data":{"timestamp":1743994871054,"type":"change","change_id":41151960370,"instrument_name":"BTC-PERPETUAL","bids":[["delete",78362.5,0.0],["delete",78361.5,0.0]],"asks":[["new",78357.0,2.183e5],["new",78359.0,1.34e4],["new",78359.5,3.45e4],["new",78360.0,55860.0],["new",78360.5,200140.0],["delete",78387.5,0.0],["delete",78388.0,0.0],["delete",78388.5,0.0],["delete",78390.0,0.0],["delete",78391.5,0.0]],"prev_change_id":41151959983}}}
[2025-04-07 08:31:09.896] [multi_sink] [info] 📩 Received: {"jsonrpc":"2.0","method":"subscription","params":{"channel":"book.BTC-PERPETUAL.100ms","data":{"timestamp":1743994871254,"type":"change","change_id":41151960960,"instrument_name":"BTC-PERPETUAL","bids":[],"asks":[["new",78503.5,7.85e4],["new",78553.5,117830.0]],"prev_change_id":41151960370}}}
[2025-04-07 08:31:09.898] [multi_sink] [info] Processing received message: {"jsonrpc":"2.0","method":"subscription","params":{"channel":"book.BTC-PERPETUAL.100ms","data":{"timestamp":1743994871254,"type":"change","change_id":41151960960,"instrument_name":"BTC-PERPETUAL","bids":[],"asks":[["new",78503.5,7.85e4],["new",78553.5,117830.0]],"prev_change_id":41151960370}}}
[2025-04-07 08:31:10.439] [multi_sink] [info] 📩 Received: {"jsonrpc":"2.0","method":"subscription","params":{"channel":"book.BTC-PERPETUAL.100ms","data":{"timestamp":1743994872070,"type":"change","change_id":41151962035,"instrument_name":"BTC-PERPETUAL","bids":[],"asks":[["delete",78503.5,0.0],["new",78517.5,78510.0]],"prev_change_id":41151960960}}}
[2025-04-07 08:31:10.439] [multi_sink] [info] Processing received message: {"jsonrpc":"2.0","method":"subscription","params":{"channel":"book.BTC-PERPETUAL.100ms","data":{"timestamp":1743994872070,"type":"change","change_id":41151962035,"instrument_name":"BTC-PERPETUAL","bids":[],"asks":[["delete",78503.5,0.0],["new",78517.5,78510.0]],"prev_change_id":41151960960}}}
[2025-04-07 08:31:10.780] [multi_sink] [info] 📩 Received: {"jsonrpc":"2.0","method":"subscription","params":{"channel":"book.BTC-PERPETUAL.100ms","data":{"timestamp":1743994872077,"type":"change","change_id":41151962036,"instrument_name":"BTC-PERPETUAL","bids":[],"asks":[["delete",78553.5,0.0],["new",78567.5,117840.0]],"prev_change_id":41151962035}}}
[2025-04-07 08:31:10.783] [multi_sink] [info] Processing received message: {"jsonrpc":"2.0","method":"subscription","params":{"channel":"book.BTC-PERPETUAL.100ms","data":{"timestamp":1743994872077,"type":"change","change_id":41151962036,"instrument_name":"BTC-PERPETUAL","bids":[],"asks":[["delete",78553.5,0.0],["new",78567.5,117840.0]],"prev_change_id":41151962035}}}
[2025-04-07 08:31:11.105] [multi_sink] [info] 📩 Received: {"jsonrpc":"2.0","method":"subscription","params":{"channel":"book.BTC-PERPETUAL.100ms","data":{"timestamp":1743994872426,"type":"change","change_id":41151962838,"instrument_name":"BTC-PERPETUAL","bids":[["new",78190.0,78190.0],["delete",78179.0,0.0],["new",78140.0,117210.0],["delete",78129.0,0.0]],"asks":[],"prev_change_id":41151962036}}}
[2025-04-07 08:31:11.108] [multi_sink] [info] Processing received message: {"jsonrpc":"2.0","method":"subscription","params":{"channel":"book.BTC-PERPETUAL.100ms","data":{"timestamp":1743994872426,"type":"change","change_id":41151962838,"instrument_name":"BTC-PERPETUAL","bids":[["new",78190.0,78190.0],["delete",78179.0,0.0],["new",78140.0,117210.0],["delete",78129.0,0.0]],"asks":[],"prev_change_id":41151962036}}}
[2025-04-07 08:31:11.635] [multi_sink] [info] 📩 Received: {"jsonrpc":"2.0","method":"subscription","params":{"channel":"book.BTC-PERPETUAL.100ms","data":{"timestamp":1743994873268,"type":"change","change_id":41151964044,"instrument_name":"BTC-PERPETUAL","bids":[],"asks":[["delete",78517.5,0.0],["new",78529.0,78520.0]],"prev_change_id":41151962838}}}
[2025-04-07 08:31:11.638] [multi_sink] [info] Processing received message: {"jsonrpc":"2.0","method":"subscription","params":{"channel":"book.BTC-PERPETUAL.100ms","data":{"timestamp":1743994873268,"type":"change","change_id":41151964044,"instrument_name":"BTC-PERPETUAL","bids":[],"asks":[["delete",78517.5,0.0],["new",78529.0,78520.0]],"prev_change_id":41151962838}}}
[2025-04-07 08:31:11.967] [multi_sink] [info] 📩 Received: {"jsonrpc":"2.0","method":"subscription","params":{"channel":"book.BTC-PERPETUAL.100ms","data":{"timestamp":1743994873284,"type":"change","change_id":41151964047,"instrument_name":"BTC-PERPETUAL","bids":[["delete",78341.0,0.0],["new",78318.0,7825720.0],["delete",78188.0,0.0],["new",78165.0,8000580.0]],"asks":[["delete",78567.5,0.0],["new",78579.0,117860.0]],"prev_change_id":41151964044}}}
[2025-04-07 08:31:11.969] [multi_sink] [info] Processing received message: {"jsonrpc":"2.0","method":"subscription","params":{"channel":"book.BTC-PERPETUAL.100ms","data":{"timestamp":1743994873284,"type":"change","change_id":41151964047,"instrument_name":"BTC-PERPETUAL","bids":[["delete",78341.0,0.0],["new",78318.0,7825720.0],["delete",78188.0,0.0],["new",78165.0,8000580.0]],"asks":[["delete",78567.5,0.0],["new",78579.0,117860.0]],"prev_change_id":41151964044}}}
[2025-04-07 08:31:12.297] [multi_sink] [info] 📩 Received: {"jsonrpc":"2.0","method":"subscription","params":{"channel":"book.BTC-PERPETUAL.100ms","data":{"timestamp":1743994873615,"type":"change","change_id":41151964394,"instrument_name":"BTC-PERPETUAL","bids":[],"asks":[["new",78395.5,6640830.0],["delete",78418.5,0.0],["new",78548.5,7777770.0],["delete",78571.5,0.0]],"prev_change_id":41151964047}}}
[2025-04-07 08:31:12.300] [multi_sink] [info] Processing received message: {"jsonrpc":"2.0","method":"subscription","params":{"channel":"book.BTC-PERPETUAL.100ms","data":{"timestamp":1743994873615,"type":"change","change_id":41151964394,"instrument_name":"BTC-PERPETUAL","bids":[],"asks":[["new",78395.5,6640830.0],["delete",78418.5,0.0],["new",78548.5,7777770.0],["delete",78571.5,0.0]],"prev_change_id":41151964047}}}
[2025-04-07 08:31:12.495] [multi_sink] [info] 📩 Received: {"jsonrpc":"2.0","method":"subscription","params":{"channel":"book.ETH-PERPETUAL.100ms","data":{"timestamp":1743994874104,"type":"change","change_id":23707198346,"instrument_name":"ETH-PERPETUAL","bids":[["delete",1577.25,0.0],["change",1577.05,7643377.0],["delete",1577.0,0.0],["delete",1576.95,0.0],["delete",1576.9,0.0],["change",1576.8,100.0],["change",1576.75,4925.0],["change",1576.7,17335.0],["change",1576.65,2371.0],["change",1576.5,15055.0],["change",1576.45,16673.0],["change",1576.4,2106.0],["change",1576.35,6202.0],["change",1576.3,5046.0]],"asks":[["delete",1577.3,0.0],["delete",1577.35,0.0],["delete",1577.4,0.0],["delete",1577.5,0.0],["delete",1577.55,0.0],["delete",1577.65,0.0],["delete",1577.7,0.0],["delete",1577.75,0.0],["delete",1577.8,0.0],["change",1578.1,10105.0],["change",1578.15,22506.0],["change",1578.2,16523.0],["change",1578.25,3056.0],["change",1578.3,25113.0],["change",1578.35,68148.0],["new",1578.4,925.0],["new",1578.45,15486.0],["new",1578.5,57534.0]],"prev_change_id":23707193096}}}
[2025-04-07 08:31:12.496] [multi_sink] [info] Processing received message: {"jsonrpc":"2.0","method":"subscription","params":{"channel":"book.ETH-PERPETUAL.100ms","data":{"timestamp":1743994874104,"type":"change","change_id":23707198346,"instrument_name":"ETH-PERPETUAL","bids":[["delete",1577.25,0.0],["change",1577.05,7643377.0],["delete",1577.0,0.0],["delete",1576.95,0.0],["delete",1576.9,0.0],["change",1576.8,100.0],["change",1576.75,4925.0],["change",1576.7,17335.0],["change",1576.65,2371.0],["change",1576.5,15055.0],["change",1576.45,16673.0],["change",1576.4,2106.0],["change",1576.35,6202.0],["change",1576.3,5046.0]],"asks":[["delete",1577.3,0.0],["delete",1577.35,0.0],["delete",1577.4,0.0],["delete",1577.5,0.0],["delete",1577.55,0.0],["delete",1577.65,0.0],["delete",1577.7,0.0],["delete",1577.75,0.0],["delete",1577.8,0.0],["change",1578.1,10105.0],["change",1578.15,22506.0],["change",1578.2,16523.0],["change",1578.25,3056.0],["change",1578.3,25113.0],["change",1578.35,68148.0],["new",1578.4,925.0],["new",1578.45,15486.0],["new",1578.5,57534.0]],"prev_change_id":23707193096}}}
[2025-04-07 08:31:12.626] [multi_sink] [info] 📩 Received: {"jsonrpc":"2.0","method":"subscription","params":{"channel":"book.BTC-PERPETUAL.100ms","data":{"timestamp":1743994874053,"type":"change","change_id":41151964934,"instrument_name":"BTC-PERPETUAL","bids":[["delete",78190.0,0.0],["delete",78140.0,0.0]],"asks":[],"prev_change_id":41151964394}}}
[2025-04-07 08:31:12.627] [multi_sink] [info] Processing received message: {"jsonrpc":"2.0","method":"subscription","params":{"channel":"book.BTC-PERPETUAL.100ms","data":{"timestamp":1743994874053,"type":"change","change_id":41151964934,"instrument_name":"BTC-PERPETUAL","bids":[["delete",78190.0,0.0],["delete",78140.0,0.0]],"asks":[],"prev_change_id":41151964394}}}
[2025-04-07 08:31:12.826] [multi_sink] [info] 📩 Received: {"jsonrpc":"2.0","method":"subscription","params":{"channel":"book.ETH-PERPETUAL.100ms","data":{"timestamp":1743994874446,"type":"change","change_id":23707198624,"instrument_name":"ETH-PERPETUAL","bids":[["new",1577.25,39903.0],["new",1577.2,6745.0],["new",1577.15,2.25e4],["new",1577.1,856.0],["change",1577.05,7661548.0],["new",1577.0,7109.0],["new",1576.95,79694.0],["new",1576.9,93750.0],["new",1576.85,1023.0],["delete",1576.6,0.0],["delete",1576.55,0.0],["change",1576.5,6601.0],["change",1576.45,14361.0],["change",1576.4,1083.0],["change",1576.35,923.0],["change",1576.3,1023.0],["delete",1576.25,0.0],["delete",1576.2,0.0]],"asks":[["new",1577.65,5.0e3],["new",1577.7,12386.0],["new",1577.75,9903.0],["new",1577.8,20791.0],["change",1577.85,60.0],["change",1577.9,75183.0],["change",1577.95,3998.0],["change",1578.0,13078.0],["change",1578.05,8360.0],["change",1578.1,9216.0],["change",1578.15,22406.0],["change",1578.2,14925.0],["change",1578.25,1025.0]],"prev_change_id":23707198346}}}
[2025-04-07 08:31:12.830] [multi_sink] [info] Processing received message: {"jsonrpc":"2.0","method":"subscription","params":{"channel":"book.ETH-PERPETUAL.100ms","data":{"timestamp":1743994874446,"type":"change","change_id":23707198624,"instrument_name":"ETH-PERPETUAL","bids":[["new",1577.25,39903.0],["new",1577.2,6745.0],["new",1577.15,2.25e4],["new",1577.1,856.0],["change",1577.05,7661548.0],["new",1577.0,7109.0],["new",1576.95,79694.0],["new",1576.9,93750.0],["new",1576.85,1023.0],["delete",1576.6,0.0],["delete",1576.55,0.0],["change",1576.5,6601.0],["change",1576.45,14361.0],["change",1576.4,1083.0],["change",1576.35,923.0],["change",1576.3,1023.0],["delete",1576.25,0.0],["delete",1576.2,0.0]],"asks":[["new",1577.65,5.0e3],["new",1577.7,12386.0],["new",1577.75,9903.0],["new",1577.8,20791.0],["change",1577.85,60.0],["change",1577.9,75183.0],["change",1577.95,3998.0],["change",1578.0,13078.0],["change",1578.05,8360.0],["change",1578.1,9216.0],["change",1578.15,22406.0],["change",1578.2,14925.0],["change",1578.25,1025.0]],"prev_change_id":23707198346}}}
[2025-04-07 08:31:12.957] [multi_sink] [info] 📩 Received: {"jsonrpc":"2.0","method":"subscription","params":{"channel":"book.BTC-PERPETUAL.100ms","data":{"timestamp":1743994874430,"type":"change","change_id":41151965677,"instrument_name":"BTC-PERPETUAL","bids":[["new",78203.0,7.82e4],["new",78153.0,117220.0]],"asks":[],"prev_change_id":41151964934}}}
[2025-04-07 08:31:12.962] [multi_sink] [info] Processing received message: {"jsonrpc":"2.0","method":"subscription","params":{"channel":"book.BTC-PERPETUAL.100ms","data":{"timestamp":1743994874430,"type":"change","change_id":41151965677,"instrument_name":"BTC-PERPETUAL","bids":[["new",78203.0,7.82e4],["new",78153.0,117220.0]],"asks":[],"prev_change_id":41151964934}}}
[2025-04-07 08:31:13.156] [multi_sink] [info] 📩 Received: {"jsonrpc":"2.0","method":"subscription","params":{"channel":"book.ETH-PERPETUAL.100ms","data":{"timestamp":1743994874522,"type":"change","change_id":23707198777,"instrument_name":"ETH-PERPETUAL","bids":[["new",1577.4,9146.0],["new",1577.3,1.16e4],["delete",1576.15,0.0],["delete",1576.1,0.0]],"asks":[["new",1577.45,40.0],["new",1577.6,3974.0],["change",1578.3,11070.0],["change",1578.35,33360.0]],"prev_change_id":23707198624}}}
[2025-04-07 08:31:13.157] [multi_sink] [info] Processing received message: {"jsonrpc":"2.0","method":"subscription","params":{"channel":"book.ETH-PERPETUAL.100ms","data":{"timestamp":1743994874522,"type":"change","change_id":23707198777,"instrument_name":"ETH-PERPETUAL","bids":[["new",1577.4,9146.0],["new",1577.3,1.16e4],["delete",1576.15,0.0],["delete",1576.1,0.0]],"asks":[["new",1577.45,40.0],["new",1577.6,3974.0],["change",1578.3,11070.0],["change",1578.35,33360.0]],"prev_change_id":23707198624}}}
[2025-04-07 08:31:13.568] [multi_sink] [info] 📩 Received: {"jsonrpc":"2.0","method":"subscription","params":{"channel":"book.BTC-PERPETUAL.100ms","data":{"timestamp":1743994875202,"type":"change","change_id":41151966301,"instrument_name":"BTC-PERPETUAL","bids":[["delete",78203.0,0.0]],"asks":[],"prev_change_id":41151965677}}}
[2025-04-07 08:31:13.572] [multi_sink] [info] Processing received message: {"jsonrpc":"2.0","method":"subscription","params":{"channel":"book.BTC-PERPETUAL.100ms","data":{"timestamp":1743994875202,"type":"change","change_id":41151966301,"instrument_name":"BTC-PERPETUAL","bids":[["delete",78203.0,0.0]],"asks":[],"prev_change_id":41151965677}}}
[2025-04-07 08:31:13.661] [multi_sink] [info] 📩 Received: {"jsonrpc":"2.0","method":"subscription","params":{"channel":"book.ETH-PERPETUAL.100ms","data":{"timestamp":1743994875292,"type":"change","change_id":23707199889,"instrument_name":"ETH-PERPETUAL","bids":[["change",1577.05,18171.0],["change",1576.8,6280017.0]],"asks":[],"prev_change_id":23707198777}}}
[2025-04-07 08:31:13.661] [multi_sink] [info] Processing received message: {"jsonrpc":"2.0","method":"subscription","params":{"channel":"book.ETH-PERPETUAL.100ms","data":{"timestamp":1743994875292,"type":"change","change_id":23707199889,"instrument_name":"ETH-PERPETUAL","bids":[["change",1577.05,18171.0],["change",1576.8,6280017.0]],"asks":[],"prev_change_id":23707198777}}}
[2025-04-07 08:31:13.899] [multi_sink] [info] 📩 Received: {"jsonrpc":"2.0","method":"subscription","params":{"channel":"book.BTC-PERPETUAL.100ms","data":{"timestamp":1743994875518,"type":"change","change_id":41151967097,"instrument_name":"BTC-PERPETUAL","bids":[["new",78352.0,19770.0],["new",78351.5,220.0],["new",78351.0,490.0],["new",78350.5,490.0],["new",78349.5,490.0],["delete",78324.0,0.0],["delete",78320.0,0.0],["delete",78319.5,0.0],["delete",78319.0,0.0],["delete",78318.5,0.0],["delete",78153.0,0.0]],"asks":[["delete",78357.0,0.0],["delete",78359.0,0.0],["delete",78359.5,0.0],["delete",78360.0,0.0],["delete",78360.5,0.0],["new",78382.0,48510.0],["new",78382.5,1990.0],["new",78383.5,13720.0],["new",78384.5,36810.0],["new",78385.0,83160.0],["delete",78529.0,0.0],["delete",78579.0,0.0]],"prev_change_id":41151966301}}}
[2025-04-07 08:31:13.903] [multi_sink] [info] Processing received message: {"jsonrpc":"2.0","method":"subscription","params":{"channel":"book.BTC-PERPETUAL.100ms","data":{"timestamp":1743994875518,"type":"change","change_id":41151967097,"instrument_name":"BTC-PERPETUAL","bids":[["new",78352.0,19770.0],["new",78351.5,220.0],["new",78351.0,490.0],["new",78350.5,490.0],["new",78349.5,490.0],["delete",78324.0,0.0],["delete",78320.0,0.0],["delete",78319.5,0.0],["delete",78319.0,0.0],["delete",78318.5,0.0],["delete",78153.0,0.0]],"asks":[["delete",78357.0,0.0],["delete",78359.0,0.0],["delete",78359.5,0.0],["delete",78360.0,0.0],["delete",78360.5,0.0],["new",78382.0,48510.0],["new",78382.5,1990.0],["new",78383.5,13720.0],["new",78384.5,36810.0],["new",78385.0,83160.0],["delete",78529.0,0.0],["delete",78579.0,0.0]],"prev_change_id":41151966301}}}
[2025-04-07 08:31:13.989] [multi_sink] [info] 📩 Received: {"jsonrpc":"2.0","method":"subscription","params":{"channel":"book.ETH-PERPETUAL.100ms","data":{"timestamp":1743994875621,"type":"change","change_id":23707200216,"instrument_name":"ETH-PERPETUAL","bids":[],"asks":[["change",1578.3,6123063.0],["delete",1578.55,0.0]],"prev_change_id":23707199889}}}
[2025-04-07 08:31:13.991] [multi_sink] [info] Processing received message: {"jsonrpc":"2.0","method":"subscription","params":{"channel":"book.ETH-PERPETUAL.100ms","data":{"timestamp":1743994875621,"type":"change","change_id":23707200216,"instrument_name":"ETH-PERPETUAL","bids":[],"asks":[["change",1578.3,6123063.0],["delete",1578.55,0.0]],"prev_change_id":23707199889}}}
[2025-04-07 08:31:14.229] [multi_sink] [info] 📩 Received: {"jsonrpc":"2.0","method":"subscription","params":{"channel":"book.BTC-PERPETUAL.100ms","data":{"timestamp":1743994875855,"type":"change","change_id":41151967476,"instrument_name":"BTC-PERPETUAL","bids":[["new",78359.0,710.0],["new",78357.0,10.0],["new",78356.5,32380.0],["new",78356.0,10960.0],["new",78355.0,10490.0],["new",78354.5,490.0],["new",78354.0,200.0],["new",78353.5,490.0],["new",78352.5,22720.0]],"asks":[["delete",78363.5,0.0],["delete",78364.0,0.0],["delete",78364.5,0.0],["delete",78365.0,0.0],["delete",78366.0,0.0],["delete",78367.5,0.0],["delete",78368.0,0.0],["delete",78369.0,0.0],["delete",78370.0,0.0],["new",78372.5,79140.0],["change",78373.5,30250.0],["new",78376.5,6060.0],["new",78377.0,9060.0],["new",78378.5,8820.0],["new",78379.0,5250.0],["new",78380.5,24310.0],["new",78381.0,1.65e4],["new",78381.5,12460.0]],"prev_change_id":41151967097}}}
[2025-04-07 08:31:14.233] [multi_sink] [info] Processing received message: {"jsonrpc":"2.0","method":"subscription","params":{"channel":"book.BTC-PERPETUAL.100ms","data":{"timestamp":1743994875855,"type":"change","change_id":41151967476,"instrument_name":"BTC-PERPETUAL","bids":[["new",78359.0,710.0],["new",78357.0,10.0],["new",78356.5,32380.0],["new",78356.0,10960.0],["new",78355.0,10490.0],["new",78354.5,490.0],["new",78354.0,200.0],["new",78353.5,490.0],["new",78352.5,22720.0]],"asks":[["delete",78363.5,0.0],["delete",78364.0,0.0],["delete",78364.5,0.0],["delete",78365.0,0.0],["delete",78366.0,0.0],["delete",78367.5,0.0],["delete",78368.0,0.0],["delete",78369.0,0.0],["delete",78370.0,0.0],["new",78372.5,79140.0],["change",78373.5,30250.0],["new",78376.5,6060.0],["new",78377.0,9060.0],["new",78378.5,8820.0],["new",78379.0,5250.0],["new",78380.5,24310.0],["new",78381.0,1.65e4],["new",78381.5,12460.0]],"prev_change_id":41151967097}}}
[2025-04-07 08:31:14.559] [multi_sink] [info] 📩 Received: {"jsonrpc":"2.0","method":"subscription","params":{"channel":"book.BTC-PERPETUAL.100ms","data":{"timestamp":1743994876088,"type":"change","change_id":41151967881,"instrument_name":"BTC-PERPETUAL","bids":[["new",78363.0,83920.0],["new",78362.5,16950.0],["new",78362.0,2.15e4],["new",78361.5,35170.0],["new",78360.0,16530.0],["new",78359.5,21990.0]],"asks":[["new",78363.5,390.0],["new",78366.0,430.0],["new",78368.5,470.0],["new",78371.5,3.0e3],["new",78372.0,33260.0],["change",78373.5,60.0],["delete",78374.0,0.0],["delete",78375.0,0.0],["delete",78375.5,0.0],["delete",78376.0,0.0]],"prev_change_id":41151967476}}}
[2025-04-07 08:31:14.564] [multi_sink] [info] Processing received message: {"jsonrpc":"2.0","method":"subscription","params":{"channel":"book.BTC-PERPETUAL.100ms","data":{"timestamp":1743994876088,"type":"change","change_id":41151967881,"instrument_name":"BTC-PERPETUAL","bids":[["new",78363.0,83920.0],["new",78362.5,16950.0],["new",78362.0,2.15e4],["new",78361.5,35170.0],["new",78360.0,16530.0],["new",78359.5,21990.0]],"asks":[["new",78363.5,390.0],["new",78366.0,430.0],["new",78368.5,470.0],["new",78371.5,3.0e3],["new",78372.0,33260.0],["change",78373.5,60.0],["delete",78374.0,0.0],["delete",78375.0,0.0],["delete",78375.5,0.0],["delete",78376.0,0.0]],"prev_change_id":41151967476}}}
[2025-04-07 08:31:14.891] [multi_sink] [info] 📩 Received: {"jsonrpc":"2.0","method":"subscription","params":{"channel":"book.BTC-PERPETUAL.100ms","data":{"timestamp":1743994876437,"type":"change","change_id":41151968733,"instrument_name":"BTC-PERPETUAL","bids":[],"asks":[["new",78511.0,78510.0],["new",78561.0,117840.0]],"prev_change_id":41151967881}}}
[2025-04-07 08:31:14.892] [multi_sink] [info] Processing received message: {"jsonrpc":"2.0","method":"subscription","params":{"channel":"book.BTC-PERPETUAL.100ms","data":{"timestamp":1743994876437,"type":"change","change_id":41151968733,"instrument_name":"BTC-PERPETUAL","bids":[],"asks":[["new",78511.0,78510.0],["new",78561.0,117840.0]],"prev_change_id":41151967881}}}
[2025-04-07 08:31:15.579] [multi_sink] [info] 📩 Received: {"jsonrpc":"2.0","method":"subscription","params":{"channel":"book.BTC-PERPETUAL.100ms","data":{"timestamp":1743994877207,"type":"change","change_id":41151969463,"instrument_name":"BTC-PERPETUAL","bids":[["new",78183.0,78180.0]],"asks":[],"prev_change_id":41151968733}}}
[2025-04-07 08:31:15.582] [multi_sink] [info] Processing received message: {"jsonrpc":"2.0","method":"subscription","params":{"channel":"book.BTC-PERPETUAL.100ms","data":{"timestamp":1743994877207,"type":"change","change_id":41151969463,"instrument_name":"BTC-PERPETUAL","bids":[["new",78183.0,78180.0]],"asks":[],"prev_change_id":41151968733}}}
[2025-04-07 08:31:15.905] [multi_sink] [info] 📩 Received: {"jsonrpc":"2.0","method":"subscription","params":{"channel":"book.BTC-PERPETUAL.100ms","data":{"timestamp":1743994877212,"type":"change","change_id":41151969466,"instrument_name":"BTC-PERPETUAL","bids":[["new",78133.0,117190.0]],"asks":[],"prev_change_id":41151969463}}}
[2025-04-07 08:31:15.906] [multi_sink] [info] Processing received message: {"jsonrpc":"2.0","method":"subscription","params":{"channel":"book.BTC-PERPETUAL.100ms","data":{"timestamp":1743994877212,"type":"change","change_id":41151969466,"instrument_name":"BTC-PERPETUAL","bids":[["new",78133.0,117190.0]],"asks":[],"prev_change_id":41151969463}}}
[2025-04-07 08:31:17.202] [multi_sink] [info] 📩 Received: {"jsonrpc":"2.0","method":"subscription","params":{"channel":"book.ETH-PERPETUAL.100ms","data":{"timestamp":1743994878813,"type":"change","change_id":23707203328,"instrument_name":"ETH-PERPETUAL","bids":[["delete",1577.4,0.0],["new",1575.9,8352.0]],"asks":[["delete",1577.45,0.0],["change",1578.1,11659.0]],"prev_change_id":23707200216}}}
[2025-04-07 08:31:17.204] [multi_sink] [info] Processing received message: {"jsonrpc":"2.0","method":"subscription","params":{"channel":"book.ETH-PERPETUAL.100ms","data":{"timestamp":1743994878813,"type":"change","change_id":23707203328,"instrument_name":"ETH-PERPETUAL","bids":[["delete",1577.4,0.0],["new",1575.9,8352.0]],"asks":[["delete",1577.45,0.0],["change",1578.1,11659.0]],"prev_change_id":23707200216}}}
[2025-04-07 08:31:17.531] [multi_sink] [info] 📩 Received: {"jsonrpc":"2.0","method":"subscription","params":{"channel":"book.ETH-PERPETUAL.100ms","data":{"timestamp":1743994879145,"type":"change","change_id":23707203870,"instrument_name":"ETH-PERPETUAL","bids":[["delete",1577.3,0.0],["delete",1577.25,0.0],["delete",1577.2,0.0],["delete",1577.15,0.0],["delete",1577.1,0.0],["delete",1577.05,0.0],["delete",1577.0,0.0],["delete",1576.95,0.0],["delete",1576.9,0.0],["change",1576.35,1846.0],["change",1576.3,2046.0],["new",1576.25,3.5e3],["new",1576.2,8258.0],["new",1576.15,923.0],["new",1576.1,10779.0],["new",1576.05,24430.0],["new",1576.0,17454.0],["new",1575.95,40923.0]],"asks":[["change",1577.6,11187.0],["change",1577.65,14925.0],["change",1577.7,43797.0],["change",1577.75,8497.0],["change",1577.8,7.14e4],["change",1577.85,1023.0],["change",1577.9,18898.0],["change",1577.95,7609.0],["change",1578.0,52981.0]],"prev_change_id":23707203328}}}
[2025-04-07 08:31:17.536] [multi_sink] [info] Processing received message: {"jsonrpc":"2.0","method":"subscription","params":{"channel":"book.ETH-PERPETUAL.100ms","data":{"timestamp":1743994879145,"type":"change","change_id":23707203870,"instrument_name":"ETH-PERPETUAL","bids":[["delete",1577.3,0.0],["delete",1577.25,0.0],["delete",1577.2,0.0],["delete",1577.15,0.0],["delete",1577.1,0.0],["delete",1577.05,0.0],["delete",1577.0,0.0],["delete",1576.95,0.0],["delete",1576.9,0.0],["change",1576.35,1846.0],["change",1576.3,2046.0],["new",1576.25,3.5e3],["new",1576.2,8258.0],["new",1576.15,923.0],["new",1576.1,10779.0],["new",1576.05,24430.0],["new",1576.0,17454.0],["new",1575.95,40923.0]],"asks":[["change",1577.6,11187.0],["change",1577.65,14925.0],["change",1577.7,43797.0],["change",1577.75,8497.0],["change",1577.8,7.14e4],["change",1577.85,1023.0],["change",1577.9,18898.0],["change",1577.95,7609.0],["change",1578.0,52981.0]],"prev_change_id":23707203328}}}
[2025-04-07 08:31:17.860] [multi_sink] [info] 📩 Received: {"jsonrpc":"2.0","method":"subscription","params":{"channel":"book.ETH-PERPETUAL.100ms","data":{"timestamp":1743994879487,"type":"change","change_id":23707204110,"instrument_name":"ETH-PERPETUAL","bids":[["new",1576.9,3086.0],["delete",1576.85,0.0],["change",1576.8,6289819.0],["change",1576.75,384.0],["change",1576.7,2289.0],["change",1576.65,6374.0],["new",1576.55,38108.0],["change",1576.5,14916.0],["change",1576.45,97913.0],["change",1576.4,1023.0],["change",1576.35,923.0],["delete",1571.5,0.0],["new",1569.1,500.0]],"asks":[["new",1577.15,8055.0],["new",1577.2,3.29e4],["new",1577.25,1.25e4],["new",1577.3,371.0],["new",1577.35,100.0],["new",1577.4,9188.0],["new",1577.45,21721.0],["new",1577.5,12877.0],["new",1577.55,5.0e3],["delete",1578.05,0.0],["change",1578.1,2443.0],["delete",1578.15,0.0],["delete",1578.2,0.0],["delete",1578.25,0.0],["change",1578.3,6111993.0],["delete",1578.35,0.0],["delete",1578.4,0.0],["delete",1578.45,0.0]],"prev_change_id":23707203870}}}
[2025-04-07 08:31:17.864] [multi_sink] [info] Processing received message: {"jsonrpc":"2.0","method":"subscription","params":{"channel":"book.ETH-PERPETUAL.100ms","data":{"timestamp":1743994879487,"type":"change","change_id":23707204110,"instrument_name":"ETH-PERPETUAL","bids":[["new",1576.9,3086.0],["delete",1576.85,0.0],["change",1576.8,6289819.0],["change",1576.75,384.0],["change",1576.7,2289.0],["change",1576.65,6374.0],["new",1576.55,38108.0],["change",1576.5,14916.0],["change",1576.45,97913.0],["change",1576.4,1023.0],["change",1576.35,923.0],["delete",1571.5,0.0],["new",1569.1,500.0]],"asks":[["new",1577.15,8055.0],["new",1577.2,3.29e4],["new",1577.25,1.25e4],["new",1577.3,371.0],["new",1577.35,100.0],["new",1577.4,9188.0],["new",1577.45,21721.0],["new",1577.5,12877.0],["new",1577.55,5.0e3],["delete",1578.05,0.0],["change",1578.1,2443.0],["delete",1578.15,0.0],["delete",1578.2,0.0],["delete",1578.25,0.0],["change",1578.3,6111993.0],["delete",1578.35,0.0],["delete",1578.4,0.0],["delete",1578.45,0.0]],"prev_change_id":23707203870}}}
[2025-04-07 08:31:18.190] [multi_sink] [info] 📩 Received: {"jsonrpc":"2.0","method":"subscription","params":{"channel":"book.ETH-PERPETUAL.100ms","data":{"timestamp":1743994879589,"type":"change","change_id":23707204249,"instrument_name":"ETH-PERPETUAL","bids":[["new",1577.0,8230.0],["change",1576.3,1023.0]],"asks":[["new",1577.05,9241.0],["delete",1578.5,0.0],["new",1581.95,500.0],["delete",1583.55,0.0]],"prev_change_id":23707204110}}}
[2025-04-07 08:31:18.190] [multi_sink] [info] Processing received message: {"jsonrpc":"2.0","method":"subscription","params":{"channel":"book.ETH-PERPETUAL.100ms","data":{"timestamp":1743994879589,"type":"change","change_id":23707204249,"instrument_name":"ETH-PERPETUAL","bids":[["new",1577.0,8230.0],["change",1576.3,1023.0]],"asks":[["new",1577.05,9241.0],["delete",1578.5,0.0],["new",1581.95,500.0],["delete",1583.55,0.0]],"prev_change_id":23707204110}}}
[2025-04-07 08:31:18.733] [multi_sink] [info] 📩 Received: {"jsonrpc":"2.0","method":"subscription","params":{"channel":"book.BTC-PERPETUAL.100ms","data":{"timestamp":1743994880365,"type":"change","change_id":41151974294,"instrument_name":"BTC-PERPETUAL","bids":[],"asks":[["delete",78363.5,0.0],["new",78377.5,5.2e3]],"prev_change_id":41151969466}}}
[2025-04-07 08:31:18.734] [multi_sink] [info] Processing received message: {"jsonrpc":"2.0","method":"subscription","params":{"channel":"book.BTC-PERPETUAL.100ms","data":{"timestamp":1743994880365,"type":"change","change_id":41151974294,"instrument_name":"BTC-PERPETUAL","bids":[],"asks":[["delete",78363.5,0.0],["new",78377.5,5.2e3]],"prev_change_id":41151969466}}}
[2025-04-07 08:31:19.061] [multi_sink] [info] 📩 Received: {"jsonrpc":"2.0","method":"subscription","params":{"channel":"book.BTC-PERPETUAL.100ms","data":{"timestamp":1743994880664,"type":"change","change_id":41151974468,"instrument_name":"BTC-PERPETUAL","bids":[["delete",78363.0,0.0],["delete",78362.5,0.0],["delete",78362.0,0.0],["delete",78361.5,0.0],["delete",78360.0,0.0],["delete",78359.5,0.0],["delete",78359.0,0.0],["delete",78357.0,0.0],["delete",78356.5,0.0],["new",78347.5,760.0],["new",78347.0,510.0],["new",78344.5,550.0],["new",78342.5,3010.0],["new",78336.0,490.0],["new",78335.5,12890.0],["new",78333.0,3360.0],["new",78332.5,40080.0],["new",78331.0,10.0],["new",78318.5,7825720.0],["delete",78318.0,0.0],["new",78165.5,8000580.0],["delete",78165.0,0.0]],"asks":[["delete",78366.0,0.0],["delete",78368.5,0.0],["new",78369.5,9620.0],["change",78371.5,42690.0],["change",78372.0,34940.0],["new",78373.0,8770.0],["delete",78373.5,0.0],["new",78374.0,13710.0],["new",78376.0,22760.0],["change",78376.5,2.8e3],["delete",78377.0,0.0]],"prev_change_id":41151974294}}}
[2025-04-07 08:31:19.065] [multi_sink] [info] Processing received message: {"jsonrpc":"2.0","method":"subscription","params":{"channel":"book.BTC-PERPETUAL.100ms","data":{"timestamp":1743994880664,"type":"change","change_id":41151974468,"instrument_name":"BTC-PERPETUAL","bids":[["delete",78363.0,0.0],["delete",78362.5,0.0],["delete",78362.0,0.0],["delete",78361.5,0.0],["delete",78360.0,0.0],["delete",78359.5,0.0],["delete",78359.0,0.0],["delete",78357.0,0.0],["delete",78356.5,0.0],["new",78347.5,760.0],["new",78347.0,510.0],["new",78344.5,550.0],["new",78342.5,3010.0],["new",78336.0,490.0],["new",78335.5,12890.0],["new",78333.0,3360.0],["new",78332.5,40080.0],["new",78331.0,10.0],["new",78318.5,7825720.0],["delete",78318.0,0.0],["new",78165.5,8000580.0],["delete",78165.0,0.0]],"asks":[["delete",78366.0,0.0],["delete",78368.5,0.0],["new",78369.5,9620.0],["change",78371.5,42690.0],["change",78372.0,34940.0],["new",78373.0,8770.0],["delete",78373.5,0.0],["new",78374.0,13710.0],["new",78376.0,22760.0],["change",78376.5,2.8e3],["delete",78377.0,0.0]],"prev_change_id":41151974294}}}
[2025-04-07 08:31:19.392] [multi_sink] [info] 📩 Received: {"jsonrpc":"2.0","method":"subscription","params":{"channel":"book.BTC-PERPETUAL.100ms","data":{"timestamp":1743994881008,"type":"change","change_id":41151975082,"instrument_name":"BTC-PERPETUAL","bids":[["change",78356.0,500.0],["change",78355.0,640.0],["change",78354.5,490.0],["delete",78354.0,0.0],["change",78353.5,490.0],["change",78352.5,490.0],["change",78352.0,920.0],["delete",78351.5,0.0],["change",78351.0,490.0],["change",78350.5,980.0],["change",78349.5,1450.0]],"asks":[["new",78358.5,2.15e4],["new",78359.0,43580.0],["new",78360.0,3.3e4],["new",78360.5,3.37e4],["new",78361.5,17460.0],["new",78362.0,82670.0],["new",78363.0,3.42e4],["new",78368.0,1.6e4],["delete",78378.5,0.0],["delete",78379.0,0.0],["delete",78380.5,0.0],["delete",78381.0,0.0],["delete",78381.5,0.0],["delete",78382.0,0.0],["delete",78382.5,0.0],["delete",78383.5,0.0],["delete",78384.5,0.0],["delete",78395.5,0.0],["new",78396.0,6640830.0],["delete",78548.5,0.0],["new",78549.0,7777770.0]],"prev_change_id":41151974468}}}
[2025-04-07 08:31:19.394] [multi_sink] [info] Processing received message: {"jsonrpc":"2.0","method":"subscription","params":{"channel":"book.BTC-PERPETUAL.100ms","data":{"timestamp":1743994881008,"type":"change","change_id":41151975082,"instrument_name":"BTC-PERPETUAL","bids":[["change",78356.0,500.0],["change",78355.0,640.0],["change",78354.5,490.0],["delete",78354.0,0.0],["change",78353.5,490.0],["change",78352.5,490.0],["change",78352.0,920.0],["delete",78351.5,0.0],["change",78351.0,490.0],["change",78350.5,980.0],["change",78349.5,1450.0]],"asks":[["new",78358.5,2.15e4],["new",78359.0,43580.0],["new",78360.0,3.3e4],["new",78360.5,3.37e4],["new",78361.5,17460.0],["new",78362.0,82670.0],["new",78363.0,3.42e4],["new",78368.0,1.6e4],["delete",78378.5,0.0],["delete",78379.0,0.0],["delete",78380.5,0.0],["delete",78381.0,0.0],["delete",78381.5,0.0],["delete",78382.0,0.0],["delete",78382.5,0.0],["delete",78383.5,0.0],["delete",78384.5,0.0],["delete",78395.5,0.0],["new",78396.0,6640830.0],["delete",78548.5,0.0],["new",78549.0,7777770.0]],"prev_change_id":41151974468}}}
[2025-04-07 08:31:19.736] [multi_sink] [info] 📩 Received: {"jsonrpc":"2.0","method":"subscription","params":{"channel":"book.BTC-PERPETUAL.100ms","data":{"timestamp":1743994881206,"type":"change","change_id":41151975154,"instrument_name":"BTC-PERPETUAL","bids":[["new",78357.0,570.0],["new",78356.5,1250.0],["change",78350.5,490.0],["change",78349.5,960.0],["delete",78183.0,0.0],["new",78170.0,78170.0],["delete",78133.0,0.0],["new",78120.0,117180.0]],"asks":[["new",78357.5,216710.0],["new",78358.0,160.0],["delete",78385.0,0.0]],"prev_change_id":41151975082}}}
[2025-04-07 08:31:19.737] [multi_sink] [info] Processing received message: {"jsonrpc":"2.0","method":"subscription","params":{"channel":"book.BTC-PERPETUAL.100ms","data":{"timestamp":1743994881206,"type":"change","change_id":41151975154,"instrument_name":"BTC-PERPETUAL","bids":[["new",78357.0,570.0],["new",78356.5,1250.0],["change",78350.5,490.0],["change",78349.5,960.0],["delete",78183.0,0.0],["new",78170.0,78170.0],["delete",78133.0,0.0],["new",78120.0,117180.0]],"asks":[["new",78357.5,216710.0],["new",78358.0,160.0],["delete",78385.0,0.0]],"prev_change_id":41151975082}}}
[2025-04-07 08:31:20.879] [multi_sink] [info] 📩 Received: {"jsonrpc":"2.0","method":"subscription","params":{"channel":"book.ETH-PERPETUAL.100ms","data":{"timestamp":1743994882510,"type":"change","change_id":23707207351,"instrument_name":"ETH-PERPETUAL","bids":[["change",1576.8,9902.0],["change",1575.95,7.6843e6]],"asks":[],"prev_change_id":23707204249}}}
[2025-04-07 08:31:20.880] [multi_sink] [info] Processing received message: {"jsonrpc":"2.0","method":"subscription","params":{"channel":"book.ETH-PERPETUAL.100ms","data":{"timestamp":1743994882510,"type":"change","change_id":23707207351,"instrument_name":"ETH-PERPETUAL","bids":[["change",1576.8,9902.0],["change",1575.95,7.6843e6]],"asks":[],"prev_change_id":23707204249}}}
[2025-04-07 08:31:21.211] [multi_sink] [info] 📩 Received: {"jsonrpc":"2.0","method":"subscription","params":{"channel":"book.ETH-PERPETUAL.100ms","data":{"timestamp":1743994882844,"type":"change","change_id":23707207558,"instrument_name":"ETH-PERPETUAL","bids":[],"asks":[["change",1577.45,6133714.0],["delete",1578.3,0.0]],"prev_change_id":23707207351}}}
[2025-04-07 08:31:21.215] [multi_sink] [info] Processing received message: {"jsonrpc":"2.0","method":"subscription","params":{"channel":"book.ETH-PERPETUAL.100ms","data":{"timestamp":1743994882844,"type":"change","change_id":23707207558,"instrument_name":"ETH-PERPETUAL","bids":[],"asks":[["change",1577.45,6133714.0],["delete",1578.3,0.0]],"prev_change_id":23707207351}}}
[2025-04-07 08:31:22.237] [multi_sink] [info] 📩 Received: {"jsonrpc":"2.0","method":"subscription","params":{"channel":"book.ETH-PERPETUAL.100ms","data":{"timestamp":1743994883849,"type":"change","change_id":23707208573,"instrument_name":"ETH-PERPETUAL","bids":[["delete",1577.0,0.0],["delete",1576.9,0.0],["new",1575.7,11933.0],["new",1575.65,10578.0]],"asks":[["delete",1577.05,0.0],["delete",1577.15,0.0],["change",1577.8,115609.0],["change",1577.85,5444.0]],"prev_change_id":23707207558}}}
[2025-04-07 08:31:22.239] [multi_sink] [info] Processing received message: {"jsonrpc":"2.0","method":"subscription","params":{"channel":"book.ETH-PERPETUAL.100ms","data":{"timestamp":1743994883849,"type":"change","change_id":23707208573,"instrument_name":"ETH-PERPETUAL","bids":[["delete",1577.0,0.0],["delete",1576.9,0.0],["new",1575.7,11933.0],["new",1575.65,10578.0]],"asks":[["delete",1577.05,0.0],["delete",1577.15,0.0],["change",1577.8,115609.0],["change",1577.85,5444.0]],"prev_change_id":23707207558}}}
[2025-04-07 08:31:22.484] [multi_sink] [info] 📩 Received: {"jsonrpc":"2.0","method":"subscription","params":{"channel":"book.BTC-PERPETUAL.100ms","data":{"timestamp":1743994883889,"type":"change","change_id":41151979110,"instrument_name":"BTC-PERPETUAL","bids":[],"asks":[["new",78500.5,7.85e4],["delete",78511.0,0.0],["new",78550.5,117820.0],["delete",78561.0,0.0]],"prev_change_id":41151975154}}}
[2025-04-07 08:31:22.487] [multi_sink] [info] Processing received message: {"jsonrpc":"2.0","method":"subscription","params":{"channel":"book.BTC-PERPETUAL.100ms","data":{"timestamp":1743994883889,"type":"change","change_id":41151979110,"instrument_name":"BTC-PERPETUAL","bids":[],"asks":[["new",78500.5,7.85e4],["delete",78511.0,0.0],["new",78550.5,117820.0],["delete",78561.0,0.0]],"prev_change_id":41151975154}}}
[2025-04-07 08:31:22.566] [multi_sink] [info] 📩 Received: {"jsonrpc":"2.0","method":"subscription","params":{"channel":"book.ETH-PERPETUAL.100ms","data":{"timestamp":1743994884190,"type":"change","change_id":23707209209,"instrument_name":"ETH-PERPETUAL","bids":[["delete",1576.8,0.0],["delete",1576.75,0.0],["delete",1576.7,0.0],["delete",1576.65,0.0],["delete",1576.55,0.0],["delete",1576.5,0.0],["delete",1576.45,0.0],["delete",1576.4,0.0],["delete",1576.35,0.0],["change",1576.15,22949.0],["change",1576.1,34750.0],["change",1576.05,60879.0],["change",1576.0,89877.0],["change",1575.95,7739009.0],["change",1575.9,54830.0],["new",1575.85,2330.0],["new",1575.8,917.0],["new",1575.75,7681.0]],"asks":[["delete",1577.2,0.0],["change",1577.25,72323.0],["change",1577.3,14002.0],["change",1577.35,7709.0],["delete",1577.4,0.0],["change",1577.45,6111993.0],["change",1577.5,6125.0],["change",1577.55,15026.0],["change",1577.6,10991.0],["change",1577.65,51906.0],["change",1577.7,44720.0],["change",1577.75,20675.0]],"prev_change_id":23707208573}}}
[2025-04-07 08:31:22.570] [multi_sink] [info] Processing received message: {"jsonrpc":"2.0","method":"subscription","params":{"channel":"book.ETH-PERPETUAL.100ms","data":{"timestamp":1743994884190,"type":"change","change_id":23707209209,"instrument_name":"ETH-PERPETUAL","bids":[["delete",1576.8,0.0],["delete",1576.75,0.0],["delete",1576.7,0.0],["delete",1576.65,0.0],["delete",1576.55,0.0],["delete",1576.5,0.0],["delete",1576.45,0.0],["delete",1576.4,0.0],["delete",1576.35,0.0],["change",1576.15,22949.0],["change",1576.1,34750.0],["change",1576.05,60879.0],["change",1576.0,89877.0],["change",1575.95,7739009.0],["change",1575.9,54830.0],["new",1575.85,2330.0],["new",1575.8,917.0],["new",1575.75,7681.0]],"asks":[["delete",1577.2,0.0],["change",1577.25,72323.0],["change",1577.3,14002.0],["change",1577.35,7709.0],["delete",1577.4,0.0],["change",1577.45,6111993.0],["change",1577.5,6125.0],["change",1577.55,15026.0],["change",1577.6,10991.0],["change",1577.65,51906.0],["change",1577.7,44720.0],["change",1577.75,20675.0]],"prev_change_id":23707208573}}}
[2025-04-07 08:31:22.896] [multi_sink] [info] 📩 Received: {"jsonrpc":"2.0","method":"subscription","params":{"channel":"book.ETH-PERPETUAL.100ms","data":{"timestamp":1743994884501,"type":"change","change_id":23707209452,"instrument_name":"ETH-PERPETUAL","bids":[["new",1576.65,7853.0],["new",1576.55,21062.0],["new",1576.5,9897.0],["new",1576.45,33030.0],["new",1576.4,1.01e4],["change",1576.3,1892.0],["change",1576.25,13207.0],["change",1576.2,8085.0],["change",1576.15,22026.0],["change",1576.1,23971.0],["change",1576.05,36449.0],["change",1576.0,72423.0],["change",1575.95,7698086.0]],"asks":[["new",1576.8,2971.0],["new",1576.85,9902.0],["new",1576.95,1.5e3],["new",1577.0,6927.0],["new",1577.05,1423.0],["new",1577.1,5.0e3],["new",1577.15,16224.0],["new",1577.2,31471.0],["change",1577.65,36981.0],["change",1577.7,923.0],["change",1577.75,12178.0],["change",1577.8,44209.0],["change",1577.85,4421.0],["delete",1577.9,0.0],["delete",1577.95,0.0],["delete",1578.0,0.0]],"prev_change_id":23707209209}}}
[2025-04-07 08:31:22.900] [multi_sink] [info] Processing received message: {"jsonrpc":"2.0","method":"subscription","params":{"channel":"book.ETH-PERPETUAL.100ms","data":{"timestamp":1743994884501,"type":"change","change_id":23707209452,"instrument_name":"ETH-PERPETUAL","bids":[["new",1576.65,7853.0],["new",1576.55,21062.0],["new",1576.5,9897.0],["new",1576.45,33030.0],["new",1576.4,1.01e4],["change",1576.3,1892.0],["change",1576.25,13207.0],["change",1576.2,8085.0],["change",1576.15,22026.0],["change",1576.1,23971.0],["change",1576.05,36449.0],["change",1576.0,72423.0],["change",1575.95,7698086.0]],"asks":[["new",1576.8,2971.0],["new",1576.85,9902.0],["new",1576.95,1.5e3],["new",1577.0,6927.0],["new",1577.05,1423.0],["new",1577.1,5.0e3],["new",1577.15,16224.0],["new",1577.2,31471.0],["change",1577.65,36981.0],["change",1577.7,923.0],["change",1577.75,12178.0],["change",1577.8,44209.0],["change",1577.85,4421.0],["delete",1577.9,0.0],["delete",1577.95,0.0],["delete",1578.0,0.0]],"prev_change_id":23707209209}}}
[2025-04-07 08:31:23.240] [multi_sink] [info] 📩 Received: {"jsonrpc":"2.0","method":"subscription","params":{"channel":"book.ETH-PERPETUAL.100ms","data":{"timestamp":1743994884643,"type":"change","change_id":23707209592,"instrument_name":"ETH-PERPETUAL","bids":[["new",1576.7,6299.0],["change",1575.9,46478.0]],"asks":[["new",1576.75,11748.0],["delete",1578.1,0.0],["new",1584.7,500.0],["delete",1587.1,0.0]],"prev_change_id":23707209452}}}
[2025-04-07 08:31:23.241] [multi_sink] [info] Processing received message: {"jsonrpc":"2.0","method":"subscription","params":{"channel":"book.ETH-PERPETUAL.100ms","data":{"timestamp":1743994884643,"type":"change","change_id":23707209592,"instrument_name":"ETH-PERPETUAL","bids":[["new",1576.7,6299.0],["change",1575.9,46478.0]],"asks":[["new",1576.75,11748.0],["delete",1578.1,0.0],["new",1584.7,500.0],["delete",1587.1,0.0]],"prev_change_id":23707209452}}}
[2025-04-07 08:31:23.658] [multi_sink] [info] 📩 Received: {"jsonrpc":"2.0","method":"subscription","params":{"channel":"book.BTC-PERPETUAL.100ms","data":{"timestamp":1743994885291,"type":"change","change_id":41151981328,"instrument_name":"BTC-PERPETUAL","bids":[["delete",78170.0,0.0],["new",78151.0,78150.0]],"asks":[],"prev_change_id":41151979110}}}
[2025-04-07 08:31:23.658] [multi_sink] [info] Processing received message: {"jsonrpc":"2.0","method":"subscription","params":{"channel":"book.BTC-PERPETUAL.100ms","data":{"timestamp":1743994885291,"type":"change","change_id":41151981328,"instrument_name":"BTC-PERPETUAL","bids":[["delete",78170.0,0.0],["new",78151.0,78150.0]],"asks":[],"prev_change_id":41151979110}}}
[2025-04-07 08:31:23.990] [multi_sink] [info] 📩 Received: {"jsonrpc":"2.0","method":"subscription","params":{"channel":"book.BTC-PERPETUAL.100ms","data":{"timestamp":1743994885593,"type":"change","change_id":41151981667,"instrument_name":"BTC-PERPETUAL","bids":[["delete",78357.0,0.0],["delete",78356.5,0.0],["delete",78356.0,0.0],["delete",78355.0,0.0],["delete",78354.5,0.0],["delete",78353.5,0.0],["delete",78352.5,0.0],["new",78307.5,37840.0],["new",78306.5,35860.0],["new",78306.0,34530.0],["new",78305.5,81640.0],["new",78303.5,8840.0],["new",78303.0,5380.0],["new",78302.5,16490.0],["delete",78120.0,0.0],["new",78101.0,117150.0]],"asks":[["new",78353.0,1.467e5],["new",78356.0,34530.0],["new",78357.0,160.0],["change",78357.5,5740.0],["change",78358.0,22780.0],["change",78358.5,1.0e4],["change",78359.0,103450.0],["delete",78360.0,0.0],["delete",78360.5,0.0],["delete",78361.5,0.0],["new",78488.5,78480.0],["delete",78500.5,0.0],["new",78538.5,1.178e5],["delete",78550.5,0.0]],"prev_change_id":41151981328}}}
[2025-04-07 08:31:23.994] [multi_sink] [info] Processing received message: {"jsonrpc":"2.0","method":"subscription","params":{"channel":"book.BTC-PERPETUAL.100ms","data":{"timestamp":1743994885593,"type":"change","change_id":41151981667,"instrument_name":"BTC-PERPETUAL","bids":[["delete",78357.0,0.0],["delete",78356.5,0.0],["delete",78356.0,0.0],["delete",78355.0,0.0],["delete",78354.5,0.0],["delete",78353.5,0.0],["delete",78352.5,0.0],["new",78307.5,37840.0],["new",78306.5,35860.0],["new",78306.0,34530.0],["new",78305.5,81640.0],["new",78303.5,8840.0],["new",78303.0,5380.0],["new",78302.5,16490.0],["delete",78120.0,0.0],["new",78101.0,117150.0]],"asks":[["new",78353.0,1.467e5],["new",78356.0,34530.0],["new",78357.0,160.0],["change",78357.5,5740.0],["change",78358.0,22780.0],["change",78358.5,1.0e4],["change",78359.0,103450.0],["delete",78360.0,0.0],["delete",78360.5,0.0],["delete",78361.5,0.0],["new",78488.5,78480.0],["delete",78500.5,0.0],["new",78538.5,1.178e5],["delete",78550.5,0.0]],"prev_change_id":41151981328}}}
[2025-04-07 08:31:24.321] [multi_sink] [info] 📩 Received: {"jsonrpc":"2.0","method":"subscription","params":{"channel":"book.BTC-PERPETUAL.100ms","data":{"timestamp":1743994885932,"type":"change","change_id":41151982112,"instrument_name":"BTC-PERPETUAL","bids":[["delete",78352.0,0.0],["delete",78351.0,0.0],["delete",78350.5,0.0],["delete",78349.5,0.0],["delete",78347.5,0.0],["delete",78347.0,0.0],["delete",78344.5,0.0],["delete",78342.5,0.0],["delete",78336.0,0.0],["new",78330.0,1080.0],["new",78320.0,10020.0],["change",78318.5,7826740.0],["new",78315.0,310.0],["new",78313.5,9440.0],["new",78312.5,4020.0],["new",78312.0,300.0],["new",78310.0,20.0],["new",78308.0,490.0]],"asks":[["new",78347.5,268350.0],["new",78348.0,7.3e4],["new",78349.5,14480.0],["new",78350.0,25590.0],["new",78350.5,19750.0],["new",78351.0,45130.0],["new",78351.5,20220.0],["new",78352.0,9510.0],["new",78352.5,93040.0],["delete",78362.0,0.0],["delete",78363.0,0.0],["delete",78368.0,0.0],["delete",78369.5,0.0],["delete",78371.5,0.0],["delete",78372.0,0.0],["delete",78372.5,0.0],["delete",78373.0,0.0],["delete",78374.0,0.0],["delete",78488.5,0.0],["delete",78538.5,0.0]],"prev_change_id":41151981667}}}
[2025-04-07 08:31:24.324] [multi_sink] [info] Processing received message: {"jsonrpc":"2.0","method":"subscription","params":{"channel":"book.BTC-PERPETUAL.100ms","data":{"timestamp":1743994885932,"type":"change","change_id":41151982112,"instrument_name":"BTC-PERPETUAL","bids":[["delete",78352.0,0.0],["delete",78351.0,0.0],["delete",78350.5,0.0],["delete",78349.5,0.0],["delete",78347.5,0.0],["delete",78347.0,0.0],["delete",78344.5,0.0],["delete",78342.5,0.0],["delete",78336.0,0.0],["new",78330.0,1080.0],["new",78320.0,10020.0],["change",78318.5,7826740.0],["new",78315.0,310.0],["new",78313.5,9440.0],["new",78312.5,4020.0],["new",78312.0,300.0],["new",78310.0,20.0],["new",78308.0,490.0]],"asks":[["new",78347.5,268350.0],["new",78348.0,7.3e4],["new",78349.5,14480.0],["new",78350.0,25590.0],["new",78350.5,19750.0],["new",78351.0,45130.0],["new",78351.5,20220.0],["new",78352.0,9510.0],["new",78352.5,93040.0],["delete",78362.0,0.0],["delete",78363.0,0.0],["delete",78368.0,0.0],["delete",78369.5,0.0],["delete",78371.5,0.0],["delete",78372.0,0.0],["delete",78372.5,0.0],["delete",78373.0,0.0],["delete",78374.0,0.0],["delete",78488.5,0.0],["delete",78538.5,0.0]],"prev_change_id":41151981667}}}
[2025-04-07 08:31:24.650] [multi_sink] [info] 📩 Received: {"jsonrpc":"2.0","method":"subscription","params":{"channel":"book.BTC-PERPETUAL.100ms","data":{"timestamp":1743994886098,"type":"change","change_id":41151982316,"instrument_name":"BTC-PERPETUAL","bids":[["new",78344.5,510.0],["new",78342.5,3010.0],["new",78342.0,550.0],["delete",78335.5,0.0],["delete",78333.0,0.0],["delete",78332.5,0.0],["change",78331.0,10.0],["delete",78151.0,0.0],["delete",78101.0,0.0]],"asks":[["new",78345.0,2.06e4],["new",78345.5,13370.0],["new",78346.5,19350.0],["new",78347.0,19310.0],["delete",78376.0,0.0],["delete",78376.5,0.0],["delete",78377.5,0.0]],"prev_change_id":41151982112}}}
[2025-04-07 08:31:24.652] [multi_sink] [info] Processing received message: {"jsonrpc":"2.0","method":"subscription","params":{"channel":"book.BTC-PERPETUAL.100ms","data":{"timestamp":1743994886098,"type":"change","change_id":41151982316,"instrument_name":"BTC-PERPETUAL","bids":[["new",78344.5,510.0],["new",78342.5,3010.0],["new",78342.0,550.0],["delete",78335.5,0.0],["delete",78333.0,0.0],["delete",78332.5,0.0],["change",78331.0,10.0],["delete",78151.0,0.0],["delete",78101.0,0.0]],"asks":[["new",78345.0,2.06e4],["new",78345.5,13370.0],["new",78346.5,19350.0],["new",78347.0,19310.0],["delete",78376.0,0.0],["delete",78376.5,0.0],["delete",78377.5,0.0]],"prev_change_id":41151982112}}}
[2025-04-07 08:31:25.767] [multi_sink] [info] 📩 Received: {"jsonrpc":"2.0","method":"subscription","params":{"channel":"book.BTC-PERPETUAL.100ms","data":{"timestamp":1743994887401,"type":"change","change_id":41151984569,"instrument_name":"BTC-PERPETUAL","bids":[],"asks":[["new",78467.0,78460.0]],"prev_change_id":41151982316}}}
[2025-04-07 08:31:25.769] [multi_sink] [info] Processing received message: {"jsonrpc":"2.0","method":"subscription","params":{"channel":"book.BTC-PERPETUAL.100ms","data":{"timestamp":1743994887401,"type":"change","change_id":41151984569,"instrument_name":"BTC-PERPETUAL","bids":[],"asks":[["new",78467.0,78460.0]],"prev_change_id":41151982316}}}
[2025-04-07 08:31:26.097] [multi_sink] [info] 📩 Received: {"jsonrpc":"2.0","method":"subscription","params":{"channel":"book.BTC-PERPETUAL.100ms","data":{"timestamp":1743994887730,"type":"change","change_id":41151984874,"instrument_name":"BTC-PERPETUAL","bids":[["change",78318.5,1020.0],["new",78281.5,7825720.0],["delete",78165.5,0.0],["new",78136.5,78130.0],["new",78128.5,8000580.0],["new",78086.5,117130.0]],"asks":[["new",78517.0,117770.0]],"prev_change_id":41151984569}}}
[2025-04-07 08:31:26.098] [multi_sink] [info] Processing received message: {"jsonrpc":"2.0","method":"subscription","params":{"channel":"book.BTC-PERPETUAL.100ms","data":{"timestamp":1743994887730,"type":"change","change_id":41151984874,"instrument_name":"BTC-PERPETUAL","bids":[["change",78318.5,1020.0],["new",78281.5,7825720.0],["delete",78165.5,0.0],["new",78136.5,78130.0],["new",78128.5,8000580.0],["new",78086.5,117130.0]],"asks":[["new",78517.0,117770.0]],"prev_change_id":41151984569}}}
[2025-04-07 08:31:26.427] [multi_sink] [info] 📩 Received: {"jsonrpc":"2.0","method":"subscription","params":{"channel":"book.BTC-PERPETUAL.100ms","data":{"timestamp":1743994888060,"type":"change","change_id":41151985437,"instrument_name":"BTC-PERPETUAL","bids":[["delete",78136.5,0.0],["new",78122.5,78120.0],["delete",78086.5,0.0],["new",78072.5,1.171e5]],"asks":[["change",78359.0,6744280.0],["delete",78396.0,0.0],["new",78512.0,7777770.0],["delete",78549.0,0.0]],"prev_change_id":41151984874}}}
[2025-04-07 08:31:26.429] [multi_sink] [info] Processing received message: {"jsonrpc":"2.0","method":"subscription","params":{"channel":"book.BTC-PERPETUAL.100ms","data":{"timestamp":1743994888060,"type":"change","change_id":41151985437,"instrument_name":"BTC-PERPETUAL","bids":[["delete",78136.5,0.0],["new",78122.5,78120.0],["delete",78086.5,0.0],["new",78072.5,1.171e5]],"asks":[["change",78359.0,6744280.0],["delete",78396.0,0.0],["new",78512.0,7777770.0],["delete",78549.0,0.0]],"prev_change_id":41151984874}}}
[2025-04-07 08:31:27.269] [multi_sink] [info] 📩 Received: {"jsonrpc":"2.0","method":"subscription","params":{"channel":"book.ETH-PERPETUAL.100ms","data":{"timestamp":1743994888888,"type":"change","change_id":23707214538,"instrument_name":"ETH-PERPETUAL","bids":[["delete",1576.7,0.0],["delete",1576.65,0.0],["delete",1576.55,0.0]],"asks":[["delete",1576.75,0.0],["delete",1576.8,0.0],["delete",1576.85,0.0]],"prev_change_id":23707209592}}}
[2025-04-07 08:31:27.272] [multi_sink] [info] Processing received message: {"jsonrpc":"2.0","method":"subscription","params":{"channel":"book.ETH-PERPETUAL.100ms","data":{"timestamp":1743994888888,"type":"change","change_id":23707214538,"instrument_name":"ETH-PERPETUAL","bids":[["delete",1576.7,0.0],["delete",1576.65,0.0],["delete",1576.55,0.0]],"asks":[["delete",1576.75,0.0],["delete",1576.8,0.0],["delete",1576.85,0.0]],"prev_change_id":23707209592}}}
[2025-04-07 08:31:27.519] [multi_sink] [info] 📩 Received: {"jsonrpc":"2.0","method":"subscription","params":{"channel":"book.BTC-PERPETUAL.100ms","data":{"timestamp":1743994889114,"type":"change","change_id":41151986812,"instrument_name":"BTC-PERPETUAL","bids":[],"asks":[["delete",78467.0,0.0],["delete",78517.0,0.0]],"prev_change_id":41151985437}}}
[2025-04-07 08:31:27.520] [multi_sink] [info] Processing received message: {"jsonrpc":"2.0","method":"subscription","params":{"channel":"book.BTC-PERPETUAL.100ms","data":{"timestamp":1743994889114,"type":"change","change_id":41151986812,"instrument_name":"BTC-PERPETUAL","bids":[],"asks":[["delete",78467.0,0.0],["delete",78517.0,0.0]],"prev_change_id":41151985437}}}
[2025-04-07 08:31:27.608] [multi_sink] [info] 📩 Received: {"jsonrpc":"2.0","method":"subscription","params":{"channel":"book.ETH-PERPETUAL.100ms","data":{"timestamp":1743994889228,"type":"change","change_id":23707214919,"instrument_name":"ETH-PERPETUAL","bids":[["delete",1576.5,0.0],["delete",1576.45,0.0],["delete",1576.4,0.0],["delete",1576.3,0.0],["delete",1576.25,0.0],["delete",1576.2,0.0],["delete",1576.15,0.0],["delete",1576.1,0.0],["delete",1576.05,0.0],["change",1576.0,51350.0],["new",1574.2,5471.0],["delete",1573.05,0.0],["new",1571.4,500.0]],"asks":[["delete",1576.95,0.0],["delete",1577.0,0.0],["delete",1577.05,0.0],["delete",1577.1,0.0],["delete",1577.15,0.0],["delete",1577.2,0.0],["delete",1577.25,0.0],["delete",1577.3,0.0],["delete",1577.35,0.0]],"prev_change_id":23707214538}}}
[2025-04-07 08:31:27.610] [multi_sink] [info] Processing received message: {"jsonrpc":"2.0","method":"subscription","params":{"channel":"book.ETH-PERPETUAL.100ms","data":{"timestamp":1743994889228,"type":"change","change_id":23707214919,"instrument_name":"ETH-PERPETUAL","bids":[["delete",1576.5,0.0],["delete",1576.45,0.0],["delete",1576.4,0.0],["delete",1576.3,0.0],["delete",1576.25,0.0],["delete",1576.2,0.0],["delete",1576.15,0.0],["delete",1576.1,0.0],["delete",1576.05,0.0],["change",1576.0,51350.0],["new",1574.2,5471.0],["delete",1573.05,0.0],["new",1571.4,500.0]],"asks":[["delete",1576.95,0.0],["delete",1577.0,0.0],["delete",1577.05,0.0],["delete",1577.1,0.0],["delete",1577.15,0.0],["delete",1577.2,0.0],["delete",1577.25,0.0],["delete",1577.3,0.0],["delete",1577.35,0.0]],"prev_change_id":23707214538}}}
[2025-04-07 08:31:27.930] [multi_sink] [info] 📩 Received: {"jsonrpc":"2.0","method":"subscription","params":{"channel":"book.ETH-PERPETUAL.100ms","data":{"timestamp":1743994889537,"type":"change","change_id":23707215286,"instrument_name":"ETH-PERPETUAL","bids":[["delete",1576.0,0.0],["change",1575.95,7545952.0],["delete",1575.9,0.0],["delete",1575.85,0.0],["delete",1575.8,0.0],["delete",1575.75,0.0],["delete",1575.7,0.0],["delete",1575.65,0.0],["new",1575.0,74910.0],["new",1574.95,33256.0],["new",1574.9,484.0],["new",1574.85,3308.0],["new",1574.8,1.01e4],["new",1574.75,925.0],["new",1574.7,2271.0]],"asks":[["delete",1577.5,0.0],["delete",1577.55,0.0],["delete",1577.6,0.0],["delete",1577.65,0.0],["delete",1577.7,0.0],["delete",1577.75,0.0],["delete",1577.8,0.0],["delete",1577.85,0.0]],"prev_change_id":23707214919}}}
[2025-04-07 08:31:27.931] [multi_sink] [info] Processing received message: {"jsonrpc":"2.0","method":"subscription","params":{"channel":"book.ETH-PERPETUAL.100ms","data":{"timestamp":1743994889537,"type":"change","change_id":23707215286,"instrument_name":"ETH-PERPETUAL","bids":[["delete",1576.0,0.0],["change",1575.95,7545952.0],["delete",1575.9,0.0],["delete",1575.85,0.0],["delete",1575.8,0.0],["delete",1575.75,0.0],["delete",1575.7,0.0],["delete",1575.65,0.0],["new",1575.0,74910.0],["new",1574.95,33256.0],["new",1574.9,484.0],["new",1574.85,3308.0],["new",1574.8,1.01e4],["new",1574.75,925.0],["new",1574.7,2271.0]],"asks":[["delete",1577.5,0.0],["delete",1577.55,0.0],["delete",1577.6,0.0],["delete",1577.65,0.0],["delete",1577.7,0.0],["delete",1577.75,0.0],["delete",1577.8,0.0],["delete",1577.85,0.0]],"prev_change_id":23707214919}}}
[2025-04-07 08:31:28.184] [multi_sink] [info] 📩 Received: {"jsonrpc":"2.0","method":"subscription","params":{"channel":"book.BTC-PERPETUAL.100ms","data":{"timestamp":1743994889669,"type":"change","change_id":41151987719,"instrument_name":"BTC-PERPETUAL","bids":[],"asks":[["new",78457.0,78450.0],["new",78507.0,117760.0]],"prev_change_id":41151986812}}}
[2025-04-07 08:31:28.186] [multi_sink] [info] Processing received message: {"jsonrpc":"2.0","method":"subscription","params":{"channel":"book.BTC-PERPETUAL.100ms","data":{"timestamp":1743994889669,"type":"change","change_id":41151987719,"instrument_name":"BTC-PERPETUAL","bids":[],"asks":[["new",78457.0,78450.0],["new",78507.0,117760.0]],"prev_change_id":41151986812}}}
[2025-04-07 08:31:28.264] [multi_sink] [info] 📩 Received: {"jsonrpc":"2.0","method":"subscription","params":{"channel":"book.ETH-PERPETUAL.100ms","data":{"timestamp":1743994889724,"type":"change","change_id":23707215472,"instrument_name":"ETH-PERPETUAL","bids":[["delete",1575.95,0.0],["change",1574.7,7548223.0]],"asks":[],"prev_change_id":23707215286}}}
[2025-04-07 08:31:28.264] [multi_sink] [info] Processing received message: {"jsonrpc":"2.0","method":"subscription","params":{"channel":"book.ETH-PERPETUAL.100ms","data":{"timestamp":1743994889724,"type":"change","change_id":23707215472,"instrument_name":"ETH-PERPETUAL","bids":[["delete",1575.95,0.0],["change",1574.7,7548223.0]],"asks":[],"prev_change_id":23707215286}}}
[2025-04-07 08:31:28.510] [multi_sink] [info] 📩 Received: {"jsonrpc":"2.0","method":"subscription","params":{"channel":"book.BTC-PERPETUAL.100ms","data":{"timestamp":1743994890064,"type":"change","change_id":41151988437,"instrument_name":"BTC-PERPETUAL","bids":[],"asks":[["change",78345.0,20710.0]],"prev_change_id":41151987719}}}
[2025-04-07 08:31:28.512] [multi_sink] [info] Processing received message: {"jsonrpc":"2.0","method":"subscription","params":{"channel":"book.BTC-PERPETUAL.100ms","data":{"timestamp":1743994890064,"type":"change","change_id":41151988437,"instrument_name":"BTC-PERPETUAL","bids":[],"asks":[["change",78345.0,20710.0]],"prev_change_id":41151987719}}}
[2025-04-07 08:31:28.592] [multi_sink] [info] 📩 Received: {"jsonrpc":"2.0","method":"subscription","params":{"channel":"book.ETH-PERPETUAL.100ms","data":{"timestamp":1743994890054,"type":"change","change_id":23707216029,"instrument_name":"ETH-PERPETUAL","bids":[],"asks":[["new",1576.2,6111993.0],["delete",1577.45,0.0]],"prev_change_id":23707215472}}}
