[2025-04-06 21:48:19.806] [multi_sink] [info]  Logger initialized successfully.
[2025-04-06 21:48:19.819] [multi_sink] [info]  DeribitClient created for test.deribit.com:443/ws/api/v2
[2025-04-06 21:48:20.744] [multi_sink] [info] Starting receive_thread...
[2025-04-06 21:48:20.744] [multi_sink] [info]  Starting process_thread...
[2025-04-06 21:48:20.744] [multi_sink] [info]  Starting send_thread...
[2025-04-06 21:53:28.871] [multi_sink] [error]  [Receive Loop] Error: Connection reset by peer
[2025-04-06 22:07:13.269] [multi_sink] [info]  Logger initialized successfully.
[2025-04-06 22:07:13.276] [multi_sink] [info]  DeribitClient created for test.deribit.com:443/ws/api/v2
[2025-04-06 22:07:13.985] [multi_sink] [info] Starting receive_thread...
[2025-04-06 22:07:13.986] [multi_sink] [info]  Starting process_thread...
[2025-04-06 22:07:13.986] [multi_sink] [info]  Starting send_thread...
[2025-04-06 22:07:20.641] [multi_sink] [info] ➡️ Added to send queue: {"id":"auth#2","jsonrpc":"2.0","method":"public/auth","params":{"client_id":"d","client_secret":"s","grant_type":"client_credentials"}}
[2025-04-06 22:07:20.643] [multi_sink] [info]  Sent authentication request
[2025-04-06 22:07:20.644] [multi_sink] [info] ➡️ Sent: {"id":"auth#2","jsonrpc":"2.0","method":"public/auth","params":{"client_id":"d","client_secret":"s","grant_type":"client_credentials"}}
[2025-04-06 22:07:20.813] [multi_sink] [info] 📩 Received: {"jsonrpc":"2.0","id":"auth#2","error":{"code":13004,"message":"invalid_credentia[2025-04-06 23:04:40.800] [multi_sink] [info]  Logger initialized successfully.
[2025-04-06 23:04:40.814] [multi_sink] [info]  DeribitClient created for test.deribit.com:443/ws/api/v2
[2025-04-06 23:04:41.686] [multi_sink] [info] Starting receive_thread...
[2025-04-06 23:04:41.686] [multi_sink] [info]  Starting process_thread...
[2025-04-06 23:04:41.686] [multi_sink] [info]  Starting send_thread...
[2025-04-06 23:04:41.688] [multi_sink] [info] Starting WebSocket server on port 8080
[2025-04-06 23:04:41.688] [multi_sink] [info] Local WebSocket server running on port 8080
[2025-04-06 23:05:56.759] [multi_sink] [info] ➡️ Added to send queue: {"id":"auth#2","jsonrpc":"2.0","method":"public/auth","params":{"client_id":"KrYGD58Z","client_secret":"gI4vZ-kp10WPIwcRjdbNexOPOfppHpQWqHp6_fzEc3k","grant_type":"client_credentials"}}
[2025-04-06 23:05:56.759] [multi_sink] [info]  Sent authentication request
[2025-04-06 23:05:56.759] [multi_sink] [info] ➡️ Sent: {"id":"auth#2","jsonrpc":"2.0","method":"public/auth","params":{"client_id":"KrYGD58Z","client_secret":"gI4vZ-kp10WPIwcRjdbNexOPOfppHpQWqHp6_fzEc3k","grant_type":"client_credentials"}}
[2025-04-06 23:05:56.924] [multi_sink] [info] 📩 Received: {"jsonrpc":"2.0","id":"auth#2","result":{"enabled_features":["block_trade_approval","restricted_block_trades"],"access_token":"1775496957789.1Uk2LaH9.F3aPIt-KjzhZxS9E2haqd_jABXFhASTt9yjNd177R1KZQoc4zrTZncQMhmxGrmXD8KiwBqvsolHF0Tg6_Ac8wMDa6k-qsbdC1XgBjBGORzkydRfqJnNp6pQBtP0BkPgBGhr-3RK5OYkfdu-KwgGAF0ETWMVmkVCCb-EQxsEg0LC7UxF3oC4RiOhXX0r71UdOHLNYRjqnlLzX22of3Wddx1MQlkKlVYPMBOhvRiJcYWly_EKlWg4eTmvpku7pzjvlrVOnGSt3l-RF5iGVnG7RtYVVk2s6HTiN_qCXAgcS2wnNZK2wAji52tB_IGc8vacXjrpUvY8ObktWo-rFFx-XWAs5xHLDUnCzVzzLAPbvtR_wPnp0yhjYhVOoSp74","expires_in":31536000,"refresh_token":"1775496957789.1RkAvJAi.5T4-QLGcr8raWidg-DeNTEMewzrCtveS5fKTRBd1thPAM_S2sBHwzy-8zdBPnO-Bgk9UN-9RmBmwfaRznKEEdIOF5kviwu4kICPl9auFFqqexOQmO7fcaVvCQFuITi_YL0Nz519HHHu9lKXTBLu9hYo54dpK5gzo1mX3itV0Ow2W0Ok8lLue25YYpa8B-nQrzm77TUpPfV3q6hwUjZTC83YPOHytQJ3Hd-j1tp7GesDemvJ72Pmcz6KFKOQZ5sRpjeKFX3mowZ9uRRnE4V04CCkjj-4YncS6lXfJECoWkb-IaSlvpJ3mWHHxcEUbFcZDp6pvko746T4gCs6oCoXlJa8U2XQjQeQUN7ftCign-kROa9okTKBcLXRjzus","scope":"name:test block_rfq:read_write block_trade:read_write connection trade:read_write custody:read_write account:read_write wallet:read_write mainaccount","token_type":"bearer"},"usIn":1743960957789429,"usOut":1743960957789642,"usDiff":213,"testnet":true}
[2025-04-06 23:05:56.926] [multi_sink] [info] Processing received message: {"jsonrpc":"2.0","id":"auth#2","result":{"enabled_features":["block_trade_approval","restricted_block_trades"],"access_token":"1775496957789.1Uk2LaH9.F3aPIt-KjzhZxS9E2haqd_jABXFhASTt9yjNd177R1KZQoc4zrTZncQMhmxGrmXD8KiwBqvsolHF0Tg6_Ac8wMDa6k-qsbdC1XgBjBGORzkydRfqJnNp6pQBtP0BkPgBGhr-3RK5OYkfdu-KwgGAF0ETWMVmkVCCb-EQxsEg0LC7UxF3oC4RiOhXX0r71UdOHLNYRjqnlLzX22of3Wddx1MQlkKlVYPMBOhvRiJcYWly_EKlWg4eTmvpku7pzjvlrVOnGSt3l-RF5iGVnG7RtYVVk2s6HTiN_qCXAgcS2wnNZK2wAji52tB_IGc8vacXjrpUvY8ObktWo-rFFx-XWAs5xHLDUnCzVzzLAPbvtR_wPnp0yhjYhVOoSp74","expires_in":31536000,"refresh_token":"1775496957789.1RkAvJAi.5T4-QLGcr8raWidg-DeNTEMewzrCtveS5fKTRBd1thPAM_S2sBHwzy-8zdBPnO-Bgk9UN-9RmBmwfaRznKEEdIOF5kviwu4kICPl9auFFqqexOQmO7fcaVvCQFuITi_YL0Nz519HHHu9lKXTBLu9hYo54dpK5gzo1mX3itV0Ow2W0Ok8lLue25YYpa8B-nQrzm77TUpPfV3q6hwUjZTC83YPOHytQJ3Hd-j1tp7GesDemvJ72Pmcz6KFKOQZ5sRpjeKFX3mowZ9uRRnE4V04CCkjj-4YncS6lXfJECoWkb-IaSlvpJ3mWHHxcEUbFcZDp6pvko746T4gCs6oCoXlJa8U2XQjQeQUN7ftCign-kROa9okTKBcLXRjzus","scope":"name:test block_rfq:read_write block_trade:read_write connection trade:read_write custody:read_write account:read_write wallet:read_write mainaccount","token_type":"bearer"},"usIn":1743960957789429,"usOut":1743960957789642,"usDiff":213,"testnet":true}
[2025-04-06 23:06:27.296] [multi_sink] [info] ➡️ Added to send queue: {"id":"order#3","jsonrpc":"2.0","method":"private/buy","params":{"amount":100.0,"instrument_name":"BTC-PERPETUAL","post_only":false,"price":2300.0,"reduce_only":false,"type":"limiy"}}
[2025-04-06 23:06:27.296] [multi_sink] [info] Sent  order request for BTC-PERPETUAL
[2025-04-06 23:06:27.296] [multi_sink] [info] ➡️ Sent: {"id":"order#3","jsonrpc":"2.0","method":"private/buy","params":{"amount":100.0,"instrument_name":"BTC-PERPETUAL","post_only":false,"price":2300.0,"reduce_only":false,"type":"limiy"}}
[2025-04-06 23:06:27.467] [multi_sink] [info] 📩 Received: {"jsonrpc":"2.0","id":"order#3","error":{"code":-32602,"data":{"reason":"illegal value for type","param":"type"},"message":"Invalid params"},"usIn":1743960988326940,"usOut":1743960988328493,"usDiff":1553,"testnet":true}
[2025-04-06 23:06:27.469] [multi_sink] [info] Processing received message: {"jsonrpc":"2.0","id":"order#3","error":{"code":-32602,"data":{"reason":"illegal value for type","param":"type"},"message":"Invalid params"},"usIn":1743960988326940,"usOut":1743960988328493,"usDiff":1553,"testnet":true}
[2025-04-06 23:07:16.887] [multi_sink] [info] ➡️ Added to send queue: {"id":"cancel_all#4","jsonrpc":"2.0","method":"private/cancel_all","params":{}}
[2025-04-06 23:07:16.887] [multi_sink] [info] ➡️ Sent: {"id":"cancel_all#4","jsonrpc":"2.0","method":"private/cancel_all","params":{}}
[2025-04-06 23:07:17.103] [multi_sink] [info] 📩 Received: {"jsonrpc":"2.0","id":"cancel_all#4","result":0,"usIn":1743961037915761,"usOut":1743961037923427,"usDiff":7666,"testnet":true}
[2025-04-06 23:07:17.107] [multi_sink] [info] Processing received message: {"jsonrpc":"2.0","id":"cancel_all#4","result":0,"usIn":1743961037915761,"usOut":1743961037923427,"usDiff":7666,"testnet":true}
[2025-04-06 23:08:03.167] [multi_sink] [info] ➡️ Added to send queue: {"id":"order#5","jsonrpc":"2.0","method":"private/buy","params":{"amount":200.0,"instrument_name":"BTC-PERPETUAL","post_only":false,"price":3000.0,"reduce_only":false,"type":"limit"}}
[2025-04-06 23:08:03.167] [multi_sink] [info] Sent  order request for BTC-PERPETUAL
[2025-04-06 23:08:03.167] [multi_sink] [info] ➡️ Sent: {"id":"order#5","jsonrpc":"2.0","method":"private/buy","params":{"amount":200.0,"instrument_name":"BTC-PERPETUAL","post_only":false,"price":3000.0,"reduce_only":false,"type":"limit"}}
[2025-04-06 23:08:03.331] [multi_sink] [info] 📩 Received: {"jsonrpc":"2.0","id":"order#5","result":{"order":{"label":"","price":3.0e3,"amount":200.0,"direction":"buy","time_in_force":"good_til_cancelled","instrument_name":"BTC-PERPETUAL","api":true,"web":false,"order_id":"41102846955","creation_timestamp":1743961084198,"mmp":false,"replaced":false,"filled_amount":0.0,"post_only":false,"last_update_timestamp":1743961084198,"reduce_only":false,"average_price":0.0,"contracts":20.0,"order_state":"open","order_type":"limit","is_liquidation":false,"risk_reducing":false},"trades":[]},"usIn":1743961084196477,"usOut":1743961084199329,"usDiff":2852,"testnet":true}
[2025-04-06 23:08:03.335] [multi_sink] [info] Processing received message: {"jsonrpc":"2.0","id":"order#5","result":{"order":{"label":"","price":3.0e3,"amount":200.0,"direction":"buy","time_in_force":"good_til_cancelled","instrument_name":"BTC-PERPETUAL","api":true,"web":false,"order_id":"41102846955","creation_timestamp":1743961084198,"mmp":false,"replaced":false,"filled_amount":0.0,"post_only":false,"last_update_timestamp":1743961084198,"reduce_only":false,"average_price":0.0,"contracts":20.0,"order_state":"open","order_type":"limit","is_liquidation":false,"risk_reducing":false},"trades":[]},"usIn":1743961084196477,"usOut":1743961084199329,"usDiff":2852,"testnet":true}
[2025-04-06 23:12:07.808] [multi_sink] [info] Received message from client: {"subscribe": "book.BTC-PERPETUAL.raw"}
[2025-04-06 23:13:05.488] [multi_sink] [error]  [Receive Loop] Error: Connection reset by peer
[2025-04-06 23:18:27.264] [multi_sink] [info]  Logger initialized successfully.
[2025-04-06 23:18:27.274] [multi_sink] [info]  DeribitClient created for test.deribit.com:443/ws/api/v2
[2025-04-06 23:18:27.979] [multi_sink] [info] Starting receive_thread...
[2025-04-06 23:18:27.980] [multi_sink] [info]  Starting process_thread...
[2025-04-06 23:18:27.980] [multi_sink] [info]  Starting send_thread...
[2025-04-06 23:18:27.980] [multi_sink] [info] Starting WebSocket server on port 8080
[2025-04-06 23:18:27.981] [multi_sink] [info] Local WebSocket server running on port 8080
[2025-04-06 23:18:47.350] [multi_sink] [info] ➡️ Added to send queue: {"id":"auth#2","jsonrpc":"2.0","method":"public/auth","params":{"client_id":"KrYGD58Z","client_secret":"gI4vZ-kp10WPIwcRjdbNexOPOfppHpQWqHp6_fzEc3k","grant_type":"client_credentials"}}
[2025-04-06 23:18:47.350] [multi_sink] [info]  Sent authentication request
[2025-04-06 23:18:47.350] [multi_sink] [info] ➡️ Sent: {"id":"auth#2","jsonrpc":"2.0","method":"public/auth","params":{"client_id":"KrYGD58Z","client_secret":"gI4vZ-kp10WPIwcRjdbNexOPOfppHpQWqHp6_fzEc3k","grant_type":"client_credentials"}}
[2025-04-06 23:18:47.508] [multi_sink] [info] 📩 Received: {"jsonrpc":"2.0","id":"auth#2","result":{"enabled_features":["block_trade_approval","restricted_block_trades"],"access_token":"1775497728375.1Z_SD3BS.desoTgZQR8Lh1jD6cxqRBhzntARyD9FEP4TSq7zJDvu5irw9W-9x10H87f8yIpF3SXtLldWGkvdddQqpdDJ5u9vTCda2rOoxHmINrC5QfsMDYKPs7dau9J0Y6DNzpIdJClDpEShicGB1DKu_vDFufNbJelt5DMBcJDWznrOocboOR7TPyJmQhz4BaZMYLG1PGjozjvVp91wTL0tcVxxmvVc87lySir739Cd014arwDKqO3RqpaJUuKXvzo6a8h-gEBwmbBOBpJ1v8K_-zecCJJ-mPr7D3BtndQ9ZwHd8HcwwjzY36AEhQMeBUlLJ27prvqBqTDM0AVItomn8kqJA7PwMVLtvh-Srj40odG6JhisLvC7Zwi5dvKR2XzhK","expires_in":31536000,"refresh_token":"1775497728375.1QB5Fg1A.K9JU-ZrfEhYIgXInQQ6HlD3eTWyYo_2RzPmdSGczd1NRCfT42wVhZJYEHiNtx45M32fbevMv04n5gt7PUY5bpH_wut0ErtiGN9iOeKdHoAX4CiqWAiQS6ZOnz-qU94D58XBlSNSoi6KQX4GLty5NoFSl3rC0o8PlMpvmg0xQGUV6-hzITa_JKK5HNz9cqPtzl_qTsaXbs4GdCoKwRnovJlQro6ZxfBoKsaAYku2DWA3aeuXXG31Z5Ymc_gAZAiW1XCUgD6IvvedSuoBXq9P85GE8iDNxvkkIAEnwg3DRoX1UYIPty95Lw36JYmMCQbeu8vSvXQ-13wSbSX037MvWMvTBgi-4P93cAYtkxWWRkYwdrTEv73qnHxpD0ZA","scope":"name:test block_rfq:read_write block_trade:read_write connection trade:read_write custody:read_write account:read_write wallet:read_write mainaccount","token_type":"bearer"},"usIn":1743961728375654,"usOut":1743961728375873,"usDiff":219,"testnet":true}
[2025-04-06 23:18:47.509] [multi_sink] [info] Processing received message: {"jsonrpc":"2.0","id":"auth#2","result":{"enabled_features":["block_trade_approval","restricted_block_trades"],"access_token":"1775497728375.1Z_SD3BS.desoTgZQR8Lh1jD6cxqRBhzntARyD9FEP4TSq7zJDvu5irw9W-9x10H87f8yIpF3SXtLldWGkvdddQqpdDJ5u9vTCda2rOoxHmINrC5QfsMDYKPs7dau9J0Y6DNzpIdJClDpEShicGB1DKu_vDFufNbJelt5DMBcJDWznrOocboOR7TPyJmQhz4BaZMYLG1PGjozjvVp91wTL0tcVxxmvVc87lySir739Cd014arwDKqO3RqpaJUuKXvzo6a8h-gEBwmbBOBpJ1v8K_-zecCJJ-mPr7D3BtndQ9ZwHd8HcwwjzY36AEhQMeBUlLJ27prvqBqTDM0AVItomn8kqJA7PwMVLtvh-Srj40odG6JhisLvC7Zwi5dvKR2XzhK","expires_in":31536000,"refresh_token":"1775497728375.1QB5Fg1A.K9JU-ZrfEhYIgXInQQ6HlD3eTWyYo_2RzPmdSGczd1NRCfT42wVhZJYEHiNtx45M32fbevMv04n5gt7PUY5bpH_wut0ErtiGN9iOeKdHoAX4CiqWAiQS6ZOnz-qU94D58XBlSNSoi6KQX4GLty5NoFSl3rC0o8PlMpvmg0xQGUV6-hzITa_JKK5HNz9cqPtzl_qTsaXbs4GdCoKwRnovJlQro6ZxfBoKsaAYku2DWA3aeuXXG31Z5Ymc_gAZAiW1XCUgD6IvvedSuoBXq9P85GE8iDNxvkkIAEnwg3DRoX1UYIPty95Lw36JYmMCQbeu8vSvXQ-13wSbSX037MvWMvTBgi-4P93cAYtkxWWRkYwdrTEv73qnHxpD0ZA","scope":"name:test block_rfq:read_write block_trade:read_write connection trade:read_write custody:read_write account:read_write wallet:read_write mainaccount","token_type":"bearer"},"usIn":1743961728375654,"usOut":1743961728375873,"usDiff":219,"testnet":true}
[2025-04-06 23:19:02.590] [multi_sink] [info] Received message from client: {"subscribe": "book.BTC-PERPETUAL.100ms"}
[2025-04-06 23:23:51.073] [multi_sink] [error]  [Receive Loop] Error: Connection reset by peer
[2025-04-06 23:44:53.340] [multi_sink] [info]  Logger initialized successfully.
[2025-04-06 23:44:53.353] [multi_sink] [info]  DeribitClient created for test.deribit.com:443/ws/api/v2
[2025-04-06 23:44:54.072] [multi_sink] [info] Starting receive_thread...
[2025-04-06 23:44:54.072] [multi_sink] [info]  Starting process_thread...
[2025-04-06 23:44:54.072] [multi_sink] [info]  Starting send_thread...
[2025-04-06 23:44:54.072] [multi_sink] [info] Starting WebSocket server on port 8080
[2025-04-06 23:44:54.072] [multi_sink] [info] Local WebSocket server running on port 8080
[2025-04-06 23:45:24.767] [multi_sink] [info] ➡️ Added to send queue: {"id":"auth#2","jsonrpc":"2.0","method":"public/auth","params":{"client_id":"KrYGD58Z","client_secret":"gI4vZ-kp10WPIwcRjdbNexOPOfppHpQWqHp6_fzEc3k","grant_type":"client_credentials"}}
[2025-04-06 23:45:24.767] [multi_sink] [info]  Sent authentication request
[2025-04-06 23:45:24.767] [multi_sink] [info] ➡️ Sent: {"id":"auth#2","jsonrpc":"2.0","method":"public/auth","params":{"client_id":"KrYGD58Z","client_secret":"gI4vZ-kp10WPIwcRjdbNexOPOfppHpQWqHp6_fzEc3k","grant_type":"client_credentials"}}
[2025-04-06 23:45:24.928] [multi_sink] [info] 📩 Received: {"jsonrpc":"2.0","id":"auth#2","result":{"enabled_features":["block_trade_approval","restricted_block_trades"],"access_token":"1775499325819.1Q1beq6w.VLB1BeD-nIMe1C4S4RQyLo-0o0mH-lTfCNpKFk6VKxqT-CJWWnaYBMjEwp96mHdxw5THBFXvGD4_PnxWBW_LSOFjRrS_COFzzFBNmUT0J0GEif6rpxKI7D64_T0Gm2IVcBvO7EyAzQAWKLjCUeQv30t1o7rgifxETbcWrV_QPWgIOG8zT063bjHBdoLPhvCGWFHgfHfSFmICcayCrncPquthJ3g04osaWK_TDCS_GBgBrUrUnpxYv1Y3paVChadKsckl5e_X8gek2flY3CxtBOVvtRQwB62G9obMiSQ6xCBNWyGm2dTINMsvX0dDGhunn4h5Wex8znPRqqSsIc-HQ6XaKqGqLKAovZNL86MEzz_QSGNjqlHQNQn3QXOS","expires_in":31536000,"refresh_token":"1775499325819.1eMo_zB6.V6Xeu1DXuT-EhsiODWj4r0Ygp64lz8eX6HuKefp8-EgxX7Hl7bB83Ne8-L4GLraLdPiTZJgdma31lY2mhfMbEfFwNP33oD4qg6w0K28UMVAK9TQlTILv-HzKPHqg8jAevqjy22l5i9vIrw3ze_I-ahDBVvqqEwc5woI4ea63vyip9e5nLMGSenkrqIysRueOwwQJSZ9jLj8qO5iidbaZBt2SD8IxAQN6GPwzfHQPgTFCEUmYzMq1ZDqHFX-nlQP9UVn0GTP13upEdCbi0l_J0d_PaNvTxWLIcZhKkjL50zn5AqOhm8aQmllSTArdpMg4fbn2hSzcL7yfOtak02f88DNg11BsRJS2ZcrZ9ggNBW2XjERe1w6QH51SW0A","scope":"name:test block_rfq:read_write block_trade:read_write connection trade:read_write custody:read_write account:read_write wallet:read_write mainaccount","token_type":"bearer"},"usIn":1743963325819441,"usOut":1743963325819650,"usDiff":209,"testnet":true}
[2025-04-06 23:45:24.929] [multi_sink] [info] Processing received message: {"jsonrpc":"2.0","id":"auth#2","result":{"enabled_features":["block_trade_approval","restricted_block_trades"],"access_token":"1775499325819.1Q1beq6w.VLB1BeD-nIMe1C4S4RQyLo-0o0mH-lTfCNpKFk6VKxqT-CJWWnaYBMjEwp96mHdxw5THBFXvGD4_PnxWBW_LSOFjRrS_COFzzFBNmUT0J0GEif6rpxKI7D64_T0Gm2IVcBvO7EyAzQAWKLjCUeQv30t1o7rgifxETbcWrV_QPWgIOG8zT063bjHBdoLPhvCGWFHgfHfSFmICcayCrncPquthJ3g04osaWK_TDCS_GBgBrUrUnpxYv1Y3paVChadKsckl5e_X8gek2flY3CxtBOVvtRQwB62G9obMiSQ6xCBNWyGm2dTINMsvX0dDGhunn4h5Wex8znPRqqSsIc-HQ6XaKqGqLKAovZNL86MEzz_QSGNjqlHQNQn3QXOS","expires_in":31536000,"refresh_token":"1775499325819.1eMo_zB6.V6Xeu1DXuT-EhsiODWj4r0Ygp64lz8eX6HuKefp8-EgxX7Hl7bB83Ne8-L4GLraLdPiTZJgdma31lY2mhfMbEfFwNP33oD4qg6w0K28UMVAK9TQlTILv-HzKPHqg8jAevqjy22l5i9vIrw3ze_I-ahDBVvqqEwc5woI4ea63vyip9e5nLMGSenkrqIysRueOwwQJSZ9jLj8qO5iidbaZBt2SD8IxAQN6GPwzfHQPgTFCEUmYzMq1ZDqHFX-nlQP9UVn0GTP13upEdCbi0l_J0d_PaNvTxWLIcZhKkjL50zn5AqOhm8aQmllSTArdpMg4fbn2hSzcL7yfOtak02f88DNg11BsRJS2ZcrZ9ggNBW2XjERe1w6QH51SW0A","scope":"name:test block_rfq:read_write block_trade:read_write connection trade:read_write custody:read_write account:read_write wallet:read_write mainaccount","token_type":"bearer"},"usIn":1743963325819441,"usOut":1743963325819650,"usDiff":209,"testnet":true}
[2025-04-06 23:45:39.485] [multi_sink] [info] Received message from client 140545758334000: {"subscribe": "book.BTC-PERPETUAL.100ms"}
[2025-04-06 23:45:39.485] [multi_sink] [info] Added subscription for client 140545758334000 to channel book.BTC-PERPETUAL.100ms
[2025-04-06 23:45:39.485] [multi_sink] [info] ➡️ Added to send queue: {"id":"subscribe#3","jsonrpc":"2.0","method":"private/subscribe","params":{"channels":["book.book.BTC-PERPETUAL.100ms"]}}
[2025-04-06 23:45:39.485] [multi_sink] [info]  Subscribed to book.BTC-PERPETUAL.100ms order book
[2025-04-06 23:45:39.485] [multi_sink] [debug] Updated activity for client: 140545758334000
[2025-04-06 23:45:39.486] [multi_sink] [info] ➡️ Sent: {"id":"subscribe#3","jsonrpc":"2.0","method":"private/subscribe","params":{"channels":["book.book.BTC-PERPETUAL.100ms"]}}
[2025-04-06 23:45:39.647] [multi_sink] [info] 📩 Received: {"jsonrpc":"2.0","id":"subscribe#3","result":[],"usIn":1743963340537728,"usOut":1743963340538329,"usDiff":601,"testnet":true}
[2025-04-06 23:45:39.650] [multi_sink] [info] Processing received message: {"jsonrpc":"2.0","id":"subscribe#3","result":[],"usIn":1743963340537728,"usOut":1743963340538329,"usDiff":601,"testnet":true}
[2025-04-06 23:46:56.522] [multi_sink] [info] Removed client session: 140545758334000
[2025-04-06 23:46:57.954] [multi_sink] [info] Received message from client 140545758343024: {"subscribe": "BTC-PERPETUAL.100ms"}
[2025-04-06 23:46:57.954] [multi_sink] [info] Added subscription for client 140545758343024 to channel BTC-PERPETUAL.100ms
[2025-04-06 23:46:57.954] [multi_sink] [info] ➡️ Added to send queue: {"id":"subscribe#4","jsonrpc":"2.0","method":"private/subscribe","params":{"channels":["book.BTC-PERPETUAL.100ms"]}}
[2025-04-06 23:46:57.954] [multi_sink] [info]  Subscribed to BTC-PERPETUAL.100ms order book
[2025-04-06 23:46:57.954] [multi_sink] [debug] Updated activity for client: 140545758343024
[2025-04-06 23:46:57.954] [multi_sink] [info] ➡️ Sent: {"id":"subscribe#4","jsonrpc":"2.0","method":"private/subscribe","params":{"channels":["book.BTC-PERPETUAL.100ms"]}}
[2025-04-06 23:46:58.115] [multi_sink] [info] 📩 Received: {"jsonrpc":"2.0","id":"subscribe#4","result":["book.BTC-PERPETUAL.100ms"],"usIn":1743963419007787,"usOut":1743963419007943,"usDiff":156,"testnet":true}
[2025-04-06 23:46:58.119] [multi_sink] [info] Processing received message: {"jsonrpc":"2.0","id":"subscribe#4","result":["book.BTC-PERPETUAL.100ms"],"usIn":1743963419007787,"usOut":1743963419007943,"usDiff":156,"testnet":true}
[2025-04-06 23:46:58.119] [multi_sink] [error] Broadcast error: Operation canceled
[2025-04-06 23:46:58.167] [multi_sink] [info] 📩 Received: {"jsonrpc":"2.0","method":"subscription","params":{"channel":"book.BTC-PERPETUAL.100ms","data":{"timestamp":1743963418822,"type":"snapshot","change_id":41106161750,"instrument_name":"BTC-PERPETUAL","bids":[["new",80054.5,277620.0],["new",80054.0,24110.0],["new",80053.5,42090.0],["new",80052.5,38280.0],["new",80052.0,9480.0],["new",80050.0,2120.0],["new",80049.0,16490.0],["new",80048.5,12990.0],["new",80047.5,9640.0],["new",80047.0,81150.0],["new",80046.0,1.852e5],["new",80045.0,50.0],["new",80044.5,79990.0],["new",80044.0,27740.0],["new",80042.5,8.31e4],["new",80042.0,1.1e3],["new",80040.0,300.0],["new",80037.5,17580.0],["new",80037.0,21520.0],["new",80017.5,12650.0],["new",80015.0,5821010.0],["new",79872.0,8.0085e6],["new",79331.0,10.0],["new",7.8e4,9621290.0],["new",77963.0,520.0],["new",7.5e4,89170.0],["new",74979.0,10.0],["new",7.4e4,50.0],["new",73273.5,10.0],["new",73246.5,10.0],["new",7.0e4,100310.0],["new",69557.0,10.0],["new",6.8e4,200.0],["new",6.55e4,40.0],["new",6.5e4,70.0],["new",64483.5,90.0],["new",6.4e4,64080.0],["new",6.39e4,150.0],["new",63755.5,160.0],["new",63027.5,290.0],["new",62503.0,5.0e5],["new",62299.5,500.0],["new",6.21e4,6.0e4],["new",61279.5,5.0e5],["new",60686.0,50.0],["new",6.05e4,20.0],["new",6.0e4,513410.0],["new",5.9e4,5.0e5],["new",5.8e4,5.0e5],["new",5.7e4,1.425e5],["new",5.6e4,1.4e5],["new",5.5e4,280.0],["new",54224.5,5420.0],["new",52718.5,10.0],["new",52683.0,10.0],["new",52635.0,10.0],["new",52629.5,10.0],["new",52620.5,10.0],["new",52610.0,10.0],["new",52547.0,10.0],["new",52130.5,10.0],["new",5.2e4,10.0],["new",51567.5,20.0],["new",5.1e4,730.0],["new",50023.0,10.0],["new",50022.0,10.0],["new",50021.0,10.0],["new",50020.0,10.0],["new",50019.0,10.0],["new",50018.0,10.0],["new",50017.0,10.0],["new",50016.0,10.0],["new",50015.0,10.0],["new",50014.0,10.0],["new",50013.0,10.0],["new",50012.0,10.0],["new",50011.0,10.0],["new",50010.0,10.0],["new",50009.0,20.0],["new",50008.0,20.0],["new",50007.0,20.0],["new",50006.0,20.0],["new",50005.0,20.0],["new",50004.0,20.0],["new",50003.0,20.0],["new",50002.0,20.0],["new",50001.0,20.0],["new",5.0e4,11790.0],["new",49133.5,2.5e4],["new",4.9e4,200.0],["new",48978.0,100.0],["new",4.8e4,20.0],["new",47983.0,50.0],["new",47981.0,50.0],["new",46605.0,10.0],["new",46580.0,10.0],["new",45000.5,30.0],["new",4.5e4,290.0],["new",4.49e4,30.0],["new",40575.0,40.0],["new",4.05e4,20.0],["new",4.0e4,3.0e3],["new",3.8e4,6.0e5],["new",3.7e4,4.0e4],["new",3.5e4,401860.0],["new",3.3e4,20.0],["new",3.2e4,20.0],["new",31313.0,10.0],["new",3.1e4,1020.0],["new",3.0e4,2120.0],["new",2.5e4,480.0],["new",2.4e4,10.0],["new",22706.0,13850.0],["new",2.25e4,1.08e5],["new",22392.5,8.0e4],["new",22310.5,10.0],["new",22284.5,300.0],["new",22250.0,1.08e5],["new",22209.0,5.0e5],["new",2.2e4,10.0],["new",21795.0,300.0],["new",21375.0,5.0e5],["new",21305.5,300.0],["new",2.1e4,2.01e4],["new",20949.5,40.0],["new",20816.0,300.0],["new",20326.5,300.0],["new",2.02e4,1.0e3],["new",2.01e4,1.0e3],["new",2.0e4,2320.0],["new",19940.0,10.0],["new",19582.0,120.0],["new",1.95e4,40.0],["new",1.94e4,10.0],["new",19373.0,300.0],["new",19347.5,600.0],["new",19288.5,5.0e5],["new",19129.0,180.0],["new",1.9e4,10.0],["new",18368.5,600.0],["new",18328.0,5.0e5],["new",18274.5,40.0],["new",1.8e4,80.0],["new",17612.5,5.0e5],["new",17503.0,10.0],["new",17389.5,600.0],["new",1.7e4,150.0],["new",16926.0,5.0e5],["new",1.69e4,20.0],["new",16625.0,92610.0],["new",1.66e4,1.0e5],["new",16575.0,1.0e5],["new",16550.0,1.0e5],["new",16525.0,1.0e5],["new",16515.0,10.0],["new",16410.5,600.0],["new",16328.0,5.0e5],["new",16141.5,2890.0],["new",16134.0,1080.0],["new",16088.0,2890.0],["new",16080.5,1080.0],["new",16034.5,2890.0],["new",16026.5,1080.0],["new",1.6e4,230.0],["new",15973.0,1080.0],["new",15919.5,1080.0],["new",15866.0,1110.0],["new",15704.5,5.0e5],["new",15620.0,1.0e3],["new",1.55e4,3.1e5],["new",15444.0,100.0],["new",15431.5,600.0],["new",1.54e4,10050.0],["new",15285.0,270.0],["new",15263.0,110.0],["new",15165.0,1.0e4],["new",15162.5,1.0e4],["new",1.51e4,10.0],["new",15063.0,270.0],["new",15045.0,810.0],["new",1.5e4,1100910.0],["new",14899.0,200.0],["new",14888.0,148880.0],["new",14864.5,2430.0],["new",14823.5,270.0],["new",14823.0,810.0],["new",14681.0,4.8e3],["new",14565.0,2430.0],["new",1.45e4,10.0],["new",14343.0,2430.0],["new",1.42e4,14210.0],["new",14090.0,400.0],["new",1.4e4,330.0],["new",13964.0,1.5e5],["new",13835.0,13840.0],["new",1.37e4,100.0],["new",13360.0,100.0],["new",13078.5,9.8e4],["new",1.3e4,530.0],["new",12839.0,23040.0],["new",1.28e4,111360.0],["new",12510.5,1.5e5],["new",1.25e4,1.25e4],["new",12345.0,550.0],["new",12334.0,500.0],["new",12304.5,7290.0],["new",1.23e4,125880.0],["new",12232.5,30.0],["new",1.22e4,5.0e5],["new",12189.5,1220.0],["new",12104.0,2.0e3],["new",1.2e4,5580.0],["new",11937.5,2.0e3],["new",11867.5,2.0e3],["new",11797.5,2.0e3],["new",11728.0,2.0e3],["new",1.17e4,4120.0],["new",11659.0,2.0e3],["new",11522.0,2.0e3],["new",11454.0,2.0e3],["new",11450.5,20.0],["new",11420.5,30.0],["new",11360.5,90.0],["new",11240.5,270.0],["new",11230.0,200.0],["new",1.12e4,10.0],["new",11187.0,2.0e3],["new",11121.0,2.0e3],["new",1.11e4,10.0],["new",11055.5,2.0e3],["new",11000.5,810.0],["new",1.1e4,5.003e5],["new",10990.5,2.0e3],["new",10926.0,2.0e3],["new",10861.5,2.0e3],["new",10797.5,2.0e3],["new",10734.0,2.0e3],["new",10682.5,2430.0],["new",10682.0,2430.0],["new",10520.5,2430.0],["new",10399.0,10.0],["new",1.02e4,130.0],["new",10179.0,50.0],["new",10172.5,810.0],["new",10164.5,2430.0],["new",10142.0,1.0e5],["new",10027.5,90.0],["new",10026.0,810.0],["new",10022.0,26730.0],["new",10009.5,150.0],["new",1.0e4,2108110.0],["new",9951.5,2.2e3],["new",9876.0,2430.0],["new",9874.0,2430.0],["new",9866.0,1.0e5],["new",9811.5,2430.0],["new",9785.5,7290.0],["new",9775.5,2430.0],["new",9743.5,2430.0],["new",9693.5,2430.0],["new",9692.5,2430.0],["new",9687.5,2430.0],["new",9687.0,2.43e4],["new",9674.0,3660.0],["new",9657.5,100.0],["new",9650.0,2430.0],["new",9640.5,7290.0],["new",9632.5,1.0e3],["new",9607.5,1.0e4],["new",9.6e3,100.0],["new",9597.0,2430.0],["new",9595.5,2430.0],["new",9582.5,9.7e4],["new",9546.0,2430.0],["new",9524.5,7290.0],["new",9.5e3,9.5e4],["new",9411.0,8560.0],["new",9362.0,43740.0],["new",9326.5,1.5e5],["new",9317.5,890.0],["new",9274.0,1.0e5],["new",9250.5,7290.0],["new",9250.0,167450.0],["new",9234.0,7290.0],["new",9210.0,7.368e5],["new",9155.5,5.5e5],["new",9142.5,40.0],["new",9127.0,330.0],["new",9103.5,7290.0],["new",9102.5,160.0],["new",9.1e3,2.73e5],["new",9053.5,7290.0],["new",9047.5,7290.0],["new",9022.5,640.0],["new",9010.0,7290.0],["new",9.0e3,1220.0],["new",8957.0,7290.0],["new",8.9e3,100.0],["new",8878.0,2560.0],["new",8862.5,2560.0],["new",8854.0,1.5e5],["new",8839.0,600.0],["new",8802.0,2560.0],["new",8.8e3,100.0],["new",8785.0,9740.0],["new",8761.5,1040.0],["new",8760.0,1.0e5],["new",8735.0,9.0e3],["new",8.7e3,100.0],["new",8685.0,9.0e3],["new",8651.5,1560.0],["new",8638.5,10.0],["new",8635.0,9.0e3],["new",8.6e3,100.0],["new",8599.0,720.0],["new",8585.0,9.0e3],["new",8571.0,1250.0],["new",8546.0,2430.0],["new",8535.0,9.0e3],["new",8.5e3,8.93e4],["new",8485.0,9.0e3],["new",8450.0,2110.0],["new",8435.0,9.0e3],["new",8.4e3,100.0],["new",8393.0,14630.0],["new",8385.0,9.0e3],["new",8350.0,2090.0],["new",8338.5,320.0],["new",8335.0,9.0e3],["new",8.3e3,100.0],["new",8290.0,1.6e3],["new",8285.0,9.0e3],["new",8241.5,4120.0],["new",8235.0,9.0e3],["new",8218.0,8.1e3],["new",8.2e3,100.0],["new",8185.0,9.0e3],["new",8135.0,9.0e3],["new",8.1e3,100.0],["new",8085.0,9.0e3],["new",8066.5,17120.0],["new",8035.0,9.0e3],["new",8.0e3,1220.0],["new",7987.5,900.0],["new",7985.0,9.0e3],["new",7973.0,29260.0],["new",7.9e3,100.0],["new",7892.0,7.0e5],["new",7890.5,640.0],["new",7876.0,58520.0],["new",7809.0,5.0e5],["new",7.8e3,1.01e4],["new",7777.0,10.0],["new",7.7e3,100.0],["new",7672.0,150.0],["new",7659.5,150.0],["new",7.6e3,100.0],["new",7555.5,10.0],["new",7523.5,40.0],["new",7.5e3,2250.0],["new",7472.0,160.0],["new",7447.0,450.0],["new",7434.5,450.0],["new",7420.5,10.0],["new",7.4e3,100.0],["new",7390.0,640.0],["new",7353.0,1280.0],["new",7.3e3,100.0],["new",7.2e3,1.1e3],["new",7190.0,450.0],["new",7170.5,500.0],["new",7160.0,7160.0],["new",7.1e3,1.001e5],["new",7048.5,10240.0],["new",7005.5,3.2e4],["new",7.0e3,1110.0],["new",6931.0,5.0e3],["new",6.9e3,100.0],["new",6.8e3,100.0],["new",6735.5,1.28e5],["new",6708.0,2560.0],["new",6.7e3,100.0],["new",6.6e3,100.0],["new",6590.0,8620.0],["new",6589.0,6470.0],["new",6588.0,28390.0],["new",6587.0,24480.0],["new",6551.0,20.0],["new",6550.0,20.0],["new",6512.0,35850.0],["new",6511.0,69260.0],["new",6510.0,221750.0],["new",6509.0,35860.0],["new",6.5e3,1.6e3],["new",6418.5,10.0],["new",6.4e3,100.0],["new",6395.0,64660.0],["new",6394.0,92760.0],["new",6393.0,217970.0],["new",6392.0,66110.0],["new",6390.5,10.0],["new",6.3e3,100.0],["new",6295.0,100.0],["new",6286.5,1.383e5],["new",6285.5,286720.0],["new",6284.5,211380.0],["new",6283.5,246610.0],["new",6259.5,750.0],["new",6.2e3,100.0],["new",6186.5,73690.0],["new",6185.5,340510.0],["new",6184.5,21880.0],["new",6183.5,186350.0],["new",6169.5,450.0],["new",6.1e3,100.0],["new",6050.0,40.0],["new",6.0e3,4140.0],["new",5999.0,5.0e3],["new",5934.0,5120.0],["new",5925.5,5.12e5],["new",5.9e3,210.0],["new",5.8e3,100.0],["new",5.7e3,100.0],["new",5.6e3,100.0],["new",5.5e3,2.1e3],["new",5.4e3,100.0],["new",5359.5,2250.0],["new",5346.0,7290.0],["new",5309.0,50.0],["new",5.3e3,100.0],["new",5.2e3,100.0],["new",5118.0,2560.0],["new",5.1e3,100.0],["new",5050.5,450.0],["new",5044.5,150.0],["new",5005.0,10240.0],["new",5.0e3,10110.0],["new",4999.0,20520.0],["new",4964.0,10.0],["new",4922.0,450.0],["new",4757.5,200.0],["new",4690.0,1.0e3],["new",4610.0,1.0e4],["new",4.6e3,2.0e3],["new",4597.0,1.6e3],["new",4594.5,450.0],["new",4514.5,1.0e6],["new",4.5e3,800.0],["new",4414.0,46280.0],["new",4003.0,40.0],["new",4001.0,20.0],["new",4.0e3,640.0],["new",3921.0,23040.0],["new",3845.0,40.0],["new",3.8e3,10050.0],["new",3777.5,6.4e3],["new",3774.0,3.0e3],["new",3773.0,1.0e3],["new",3754.5,1.0e3],["new",3708.0,2.7e4],["new",3.7e3,30.0],["new",3680.0,10.0],["new",3655.0,20.0],["new",3650.0,10.0],["new",3.6e3,3.6e4],["new",3590.0,1.0e4],["new",3567.0,500.0],["new",3.5e3,230.0],["new",3.4e3,80.0],["new",3230.0,10.0],["new",3228.0,10.0],["new",3.2e3,20.0],["new",3001.0,20.0],["new",3.0e3,7.2e3],["new",2999.0,40.0],["new",2879.0,300.0],["new",2601.0,20.0],["new",2544.0,10.0],["new",2.5e3,20.0],["new",2467.0,2.56e4],["new",2.4e3,1.0e3],["new",2309.0,250.0],["new",2.3e3,20.0],["new",2222.0,680.0],["new",2211.0,40.0],["new",2005.0,140.0],["new",2.0e3,21250.0],["new",1999.0,10.0],["new",1994.5,5.0e3],["new",1979.0,60.0],["new",1.9e3,30.0],["new",1.7e3,300.0],["new",1.4e3,40.0],["new",1234.0,10.0],["new",1205.0,40.0],["new",1.1e3,20.0],["new",1099.0,10.0],["new",1002.5,70.0],["new",1001.5,60.0],["new",1000.5,80.0],["new",1.0e3,12450.0],["new",900.0,10.0],["new",800.0,10.0],["new",648.0,40.0],["new",600.0,760.0],["new",541.5,1.0e4],["new",502.0,1350.0],["new",500.0,3580.0],["new",400.0,150.0],["new",300.0,540.0],["new",288.0,10.0],["new",287.0,10.0],["new",281.0,100.0],["new",234.0,20.0],["new",222.0,300.0],["new",200.0,1220.0],["new",123.0,1.0e3],["new",120.0,110.0],["new",110.0,80.0],["new",101.0,110.0],["new",100.0,123510.0],["new",60.0,270.0],["new",58.0,10.0],["new",50.0,1350.0],["new",40.0,120.0],["new",35.5,20.0],["new",30.0,10350.0],["new",25.0,30.0],["new",23.0,20.0],["new",20.0,2210.0],["new",16.5,10.0],["new",15.0,20.0],["new",13.0,30.0],["new",12.0,2160.0],["new",11.0,10.0],["new",10.0,4010.0],["new",9.0,20.0],["new",6.5,10.0],["new",6.0,40.0],["new",5.0,300.0],["new",4.0,40.0],["new",3.0,20.0],["new",1.0,390.0],["new",0.5,61150.0]],"asks":[["new",80055.0,790.0],["new",80073.5,13130.0],["new",80074.5,490.0],["new",80075.5,34870.0],["new",80076.0,34640.0],["new",80076.5,81640.0],["new",80080.0,8890.0],["new",80080.5,13290.0],["new",80081.0,540.0],["new",80084.0,34870.0],["new",80089.0,16490.0],["new",80089.5,16490.0],["new",80090.0,4.0e4],["new",80092.5,1.67e4],["new",80093.0,18540.0],["new",80095.5,26520.0],["new",80097.0,9.5e3],["new",80098.5,83150.0],["new",80099.0,1110.0],["new",80099.5,33490.0],["new",80105.0,3680.0],["new",80140.5,3680.0],["new",80158.5,7360.0],["new",80239.0,80230.0],["new",80263.5,7777770.0],["new",80289.0,120420.0],["new",80469.0,7450.0],["new",80642.0,690.0],["new",80816.0,10.0],["new",81962.0,81590.0],["new",82168.0,81830.0],["new",82848.0,83220.0],["new",83749.0,1.0e4],["new",8.45e4,1.0e6],["new",8.5e4,1.0e6],["new",8.55e4,1.0e6],["new",8.6e4,1.0e6],["new",8.7e4,1.0e6],["new",8.75e4,1.0e6],["new",8.8e4,1.0e6],["new",9.0e4,20.0],["new",91442.0,10.0],["new",91747.0,300.0],["new",92036.5,100.0],["new",92823.0,6810.0],["new",92838.5,520.0],["new",95042.0,4190.0],["new",9.52e4,5950.0],["new",9.8e4,10.0],["new",9.9e4,20.0],["new",99670.0,5630.0],["new",1.0e5,10010.0],["new",100094.5,170.0],["new",100128.0,100.0],["new",100141.5,30.0],["new",100166.5,190.0],["new",1.008e5,5570.0],["new",100894.0,20.0],["new",101144.5,190.0],["new",102106.5,20.0],["new",103085.5,30.0],["new",103097.5,70.0],["new",103102.0,200.0],["new",103114.0,90.0],["new",104059.0,180.0],["new",104115.5,40.0],["new",104160.5,70.0],["new",104228.0,50.0],["new",105206.5,80.0],["new",107232.0,230.0],["new",107667.0,290.0],["new",109004.5,500.0],["new",110298.0,210.0],["new",110763.0,260.0],["new",111228.0,310.0],["new",111693.0,370.0],["new",112158.0,440.0],["new",112285.0,450.0],["new",112623.0,530.0],["new",113088.0,640.0],["new",113553.0,770.0],["new",114018.0,920.0],["new",114483.5,1.1e3],["new",114948.5,1320.0],["new",115164.0,550.0],["new",115413.5,1590.0],["new",118043.5,680.0],["new",119094.5,120.0],["new",1.2e5,100020.0],["new",120922.5,820.0],["new",123801.5,1010.0],["new",126680.5,1230.0],["new",129559.5,1.5e3],["new",130318.5,130.0],["new",145037.0,150.0],["new",145090.5,150.0],["new",145306.5,300.0],["new",1.5e5,38100030.0]]}}}
[2025-04-06 23:46:58.170] [multi_sink] [info] Processing received message: {"jsonrpc":"2.0","method":"subscription","params":{"channel":"book.BTC-PERPETUAL.100ms","data":{"timestamp":1743963418822,"type":"snapshot","change_id":41106161750,"instrument_name":"BTC-PERPETUAL","bids":[["new",80054.5,277620.0],["new",80054.0,24110.0],["new",80053.5,42090.0],["new",80052.5,38280.0],["new",80052.0,9480.0],["new",80050.0,2120.0],["new",80049.0,16490.0],["new",80048.5,12990.0],["new",80047.5,9640.0],["new",80047.0,81150.0],["new",80046.0,1.852e5],["new",80045.0,50.0],["new",80044.5,79990.0],["new",80044.0,27740.0],["new",80042.5,8.31e4],["new",80042.0,1.1e3],["new",80040.0,300.0],["new",80037.5,17580.0],["new",80037.0,21520.0],["new",80017.5,12650.0],["new",80015.0,5821010.0],["new",79872.0,8.0085e6],["new",79331.0,10.0],["new",7.8e4,9621290.0],["new",77963.0,520.0],["new",7.5e4,89170.0],["new",74979.0,10.0],["new",7.4e4,50.0],["new",73273.5,10.0],["new",73246.5,10.0],["new",7.0e4,100310.0],["new",69557.0,10.0],["new",6.8e4,200.0],["new",6.55e4,40.0],["new",6.5e4,70.0],["new",64483.5,90.0],["new",6.4e4,64080.0],["new",6.39e4,150.0],["new",63755.5,160.0],["new",63027.5,290.0],["new",62503.0,5.0e5],["new",62299.5,500.0],["new",6.21e4,6.0e4],["new",61279.5,5.0e5],["new",60686.0,50.0],["new",6.05e4,20.0],["new",6.0e4,513410.0],["new",5.9e4,5.0e5],["new",5.8e4,5.0e5],["new",5.7e4,1.425e5],["new",5.6e4,1.4e5],["new",5.5e4,280.0],["new",54224.5,5420.0],["new",52718.5,10.0],["new",52683.0,10.0],["new",52635.0,10.0],["new",52629.5,10.0],["new",52620.5,10.0],["new",52610.0,10.0],["new",52547.0,10.0],["new",52130.5,10.0],["new",5.2e4,10.0],["new",51567.5,20.0],["new",5.1e4,730.0],["new",50023.0,10.0],["new",50022.0,10.0],["new",50021.0,10.0],["new",50020.0,10.0],["new",50019.0,10.0],["new",50018.0,10.0],["new",50017.0,10.0],["new",50016.0,10.0],["new",50015.0,10.0],["new",50014.0,10.0],["new",50013.0,10.0],["new",50012.0,10.0],["new",50011.0,10.0],["new",50010.0,10.0],["new",50009.0,20.0],["new",50008.0,20.0],["new",50007.0,20.0],["new",50006.0,20.0],["new",50005.0,20.0],["new",50004.0,20.0],["new",50003.0,20.0],["new",50002.0,20.0],["new",50001.0,20.0],["new",5.0e4,11790.0],["new",49133.5,2.5e4],["new",4.9e4,200.0],["new",48978.0,100.0],["new",4.8e4,20.0],["new",47983.0,50.0],["new",47981.0,50.0],["new",46605.0,10.0],["new",46580.0,10.0],["new",45000.5,30.0],["new",4.5e4,290.0],["new",4.49e4,30.0],["new",40575.0,40.0],["new",4.05e4,20.0],["new",4.0e4,3.0e3],["new",3.8e4,6.0e5],["new",3.7e4,4.0e4],["new",3.5e4,401860.0],["new",3.3e4,20.0],["new",3.2e4,20.0],["new",31313.0,10.0],["new",3.1e4,1020.0],["new",3.0e4,2120.0],["new",2.5e4,480.0],["new",2.4e4,10.0],["new",22706.0,13850.0],["new",2.25e4,1.08e5],["new",22392.5,8.0e4],["new",22310.5,10.0],["new",22284.5,300.0],["new",22250.0,1.08e5],["new",22209.0,5.0e5],["new",2.2e4,10.0],["new",21795.0,300.0],["new",21375.0,5.0e5],["new",21305.5,300.0],["new",2.1e4,2.01e4],["new",20949.5,40.0],["new",20816.0,300.0],["new",20326.5,300.0],["new",2.02e4,1.0e3],["new",2.01e4,1.0e3],["new",2.0e4,2320.0],["new",19940.0,10.0],["new",19582.0,120.0],["new",1.95e4,40.0],["new",1.94e4,10.0],["new",19373.0,300.0],["new",19347.5,600.0],["new",19288.5,5.0e5],["new",19129.0,180.0],["new",1.9e4,10.0],["new",18368.5,600.0],["new",18328.0,5.0e5],["new",18274.5,40.0],["new",1.8e4,80.0],["new",17612.5,5.0e5],["new",17503.0,10.0],["new",17389.5,600.0],["new",1.7e4,150.0],["new",16926.0,5.0e5],["new",1.69e4,20.0],["new",16625.0,92610.0],["new",1.66e4,1.0e5],["new",16575.0,1.0e5],["new",16550.0,1.0e5],["new",16525.0,1.0e5],["new",16515.0,10.0],["new",16410.5,600.0],["new",16328.0,5.0e5],["new",16141.5,2890.0],["new",16134.0,1080.0],["new",16088.0,2890.0],["new",16080.5,1080.0],["new",16034.5,2890.0],["new",16026.5,1080.0],["new",1.6e4,230.0],["new",15973.0,1080.0],["new",15919.5,1080.0],["new",15866.0,1110.0],["new",15704.5,5.0e5],["new",15620.0,1.0e3],["new",1.55e4,3.1e5],["new",15444.0,100.0],["new",15431.5,600.0],["new",1.54e4,10050.0],["new",15285.0,270.0],["new",15263.0,110.0],["new",15165.0,1.0e4],["new",15162.5,1.0e4],["new",1.51e4,10.0],["new",15063.0,270.0],["new",15045.0,810.0],["new",1.5e4,1100910.0],["new",14899.0,200.0],["new",14888.0,148880.0],["new",14864.5,2430.0],["new",14823.5,270.0],["new",14823.0,810.0],["new",14681.0,4.8e3],["new",14565.0,2430.0],["new",1.45e4,10.0],["new",14343.0,2430.0],["new",1.42e4,14210.0],["new",14090.0,400.0],["new",1.4e4,330.0],["new",13964.0,1.5e5],["new",13835.0,13840.0],["new",1.37e4,100.0],["new",13360.0,100.0],["new",13078.5,9.8e4],["new",1.3e4,530.0],["new",12839.0,23040.0],["new",1.28e4,111360.0],["new",12510.5,1.5e5],["new",1.25e4,1.25e4],["new",12345.0,550.0],["new",12334.0,500.0],["new",12304.5,7290.0],["new",1.23e4,125880.0],["new",12232.5,30.0],["new",1.22e4,5.0e5],["new",12189.5,1220.0],["new",12104.0,2.0e3],["new",1.2e4,5580.0],["new",11937.5,2.0e3],["new",11867.5,2.0e3],["new",11797.5,2.0e3],["new",11728.0,2.0e3],["new",1.17e4,4120.0],["new",11659.0,2.0e3],["new",11522.0,2.0e3],["new",11454.0,2.0e3],["new",11450.5,20.0],["new",11420.5,30.0],["new",11360.5,90.0],["new",11240.5,270.0],["new",11230.0,200.0],["new",1.12e4,10.0],["new",11187.0,2.0e3],["new",11121.0,2.0e3],["new",1.11e4,10.0],["new",11055.5,2.0e3],["new",11000.5,810.0],["new",1.1e4,5.003e5],["new",10990.5,2.0e3],["new",10926.0,2.0e3],["new",10861.5,2.0e3],["new",10797.5,2.0e3],["new",10734.0,2.0e3],["new",10682.5,2430.0],["new",10682.0,2430.0],["new",10520.5,2430.0],["new",10399.0,10.0],["new",1.02e4,130.0],["new",10179.0,50.0],["new",10172.5,810.0],["new",10164.5,2430.0],["new",10142.0,1.0e5],["new",10027.5,90.0],["new",10026.0,810.0],["new",10022.0,26730.0],["new",10009.5,150.0],["new",1.0e4,2108110.0],["new",9951.5,2.2e3],["new",9876.0,2430.0],["new",9874.0,2430.0],["new",9866.0,1.0e5],["new",9811.5,2430.0],["new",9785.5,7290.0],["new",9775.5,2430.0],["new",9743.5,2430.0],["new",9693.5,2430.0],["new",9692.5,2430.0],["new",9687.5,2430.0],["new",9687.0,2.43e4],["new",9674.0,3660.0],["new",9657.5,100.0],["new",9650.0,2430.0],["new",9640.5,7290.0],["new",9632.5,1.0e3],["new",9607.5,1.0e4],["new",9.6e3,100.0],["new",9597.0,2430.0],["new",9595.5,2430.0],["new",9582.5,9.7e4],["new",9546.0,2430.0],["new",9524.5,7290.0],["new",9.5e3,9.5e4],["new",9411.0,8560.0],["new",9362.0,43740.0],["new",9326.5,1.5e5],["new",9317.5,890.0],["new",9274.0,1.0e5],["new",9250.5,7290.0],["new",9250.0,167450.0],["new",9234.0,7290.0],["new",9210.0,7.368e5],["new",9155.5,5.5e5],["new",9142.5,40.0],["new",9127.0,330.0],["new",9103.5,7290.0],["new",9102.5,160.0],["new",9.1e3,2.73e5],["new",9053.5,7290.0],["new",9047.5,7290.0],["new",9022.5,640.0],["new",9010.0,7290.0],["new",9.0e3,1220.0],["new",8957.0,7290.0],["new",8.9e3,100.0],["new",8878.0,2560.0],["new",8862.5,2560.0],["new",8854.0,1.5e5],["new",8839.0,600.0],["new",8802.0,2560.0],["new",8.8e3,100.0],["new",8785.0,9740.0],["new",8761.5,1040.0],["new",8760.0,1.0e5],["new",8735.0,9.0e3],["new",8.7e3,100.0],["new",8685.0,9.0e3],["new",8651.5,1560.0],["new",8638.5,10.0],["new",8635.0,9.0e3],["new",8.6e3,100.0],["new",8599.0,720.0],["new",8585.0,9.0e3],["new",8571.0,1250.0],["new",8546.0,2430.0],["new",8535.0,9.0e3],["new",8.5e3,8.93e4],["new",8485.0,9.0e3],["new",8450.0,2110.0],["new",8435.0,9.0e3],["new",8.4e3,100.0],["new",8393.0,14630.0],["new",8385.0,9.0e3],["new",8350.0,2090.0],["new",8338.5,320.0],["new",8335.0,9.0e3],["new",8.3e3,100.0],["new",8290.0,1.6e3],["new",8285.0,9.0e3],["new",8241.5,4120.0],["new",8235.0,9.0e3],["new",8218.0,8.1e3],["new",8.2e3,100.0],["new",8185.0,9.0e3],["new",8135.0,9.0e3],["new",8.1e3,100.0],["new",8085.0,9.0e3],["new",8066.5,17120.0],["new",8035.0,9.0e3],["new",8.0e3,1220.0],["new",7987.5,900.0],["new",7985.0,9.0e3],["new",7973.0,29260.0],["new",7.9e3,100.0],["new",7892.0,7.0e5],["new",7890.5,640.0],["new",7876.0,58520.0],["new",7809.0,5.0e5],["new",7.8e3,1.01e4],["new",7777.0,10.0],["new",7.7e3,100.0],["new",7672.0,150.0],["new",7659.5,150.0],["new",7.6e3,100.0],["new",7555.5,10.0],["new",7523.5,40.0],["new",7.5e3,2250.0],["new",7472.0,160.0],["new",7447.0,450.0],["new",7434.5,450.0],["new",7420.5,10.0],["new",7.4e3,100.0],["new",7390.0,640.0],["new",7353.0,1280.0],["new",7.3e3,100.0],["new",7.2e3,1.1e3],["new",7190.0,450.0],["new",7170.5,500.0],["new",7160.0,7160.0],["new",7.1e3,1.001e5],["new",7048.5,10240.0],["new",7005.5,3.2e4],["new",7.0e3,1110.0],["new",6931.0,5.0e3],["new",6.9e3,100.0],["new",6.8e3,100.0],["new",6735.5,1.28e5],["new",6708.0,2560.0],["new",6.7e3,100.0],["new",6.6e3,100.0],["new",6590.0,8620.0],["new",6589.0,6470.0],["new",6588.0,28390.0],["new",6587.0,24480.0],["new",6551.0,20.0],["new",6550.0,20.0],["new",6512.0,35850.0],["new",6511.0,69260.0],["new",6510.0,221750.0],["new",6509.0,35860.0],["new",6.5e3,1.6e3],["new",6418.5,10.0],["new",6.4e3,100.0],["new",6395.0,64660.0],["new",6394.0,92760.0],["new",6393.0,217970.0],["new",6392.0,66110.0],["new",6390.5,10.0],["new",6.3e3,100.0],["new",6295.0,100.0],["new",6286.5,1.383e5],["new",6285.5,286720.0],["new",6284.5,211380.0],["new",6283.5,246610.0],["new",6259.5,750.0],["new",6.2e3,100.0],["new",6186.5,73690.0],["new",6185.5,340510.0],["new",6184.5,21880.0],["new",6183.5,186350.0],["new",6169.5,450.0],["new",6.1e3,100.0],["new",6050.0,40.0],["new",6.0e3,4140.0],["new",5999.0,5.0e3],["new",5934.0,5120.0],["new",5925.5,5.12e5],["new",5.9e3,210.0],["new",5.8e3,100.0],["new",5.7e3,100.0],["new",5.6e3,100.0],["new",5.5e3,2.1e3],["new",5.4e3,100.0],["new",5359.5,2250.0],["new",5346.0,7290.0],["new",5309.0,50.0],["new",5.3e3,100.0],["new",5.2e3,100.0],["new",5118.0,2560.0],["new",5.1e3,100.0],["new",5050.5,450.0],["new",5044.5,150.0],["new",5005.0,10240.0],["new",5.0e3,10110.0],["new",4999.0,20520.0],["new",4964.0,10.0],["new",4922.0,450.0],["new",4757.5,200.0],["new",4690.0,1.0e3],["new",4610.0,1.0e4],["new",4.6e3,2.0e3],["new",4597.0,1.6e3],["new",4594.5,450.0],["new",4514.5,1.0e6],["new",4.5e3,800.0],["new",4414.0,46280.0],["new",4003.0,40.0],["new",4001.0,20.0],["new",4.0e3,640.0],["new",3921.0,23040.0],["new",3845.0,40.0],["new",3.8e3,10050.0],["new",3777.5,6.4e3],["new",3774.0,3.0e3],["new",3773.0,1.0e3],["new",3754.5,1.0e3],["new",3708.0,2.7e4],["new",3.7e3,30.0],["new",3680.0,10.0],["new",3655.0,20.0],["new",3650.0,10.0],["new",3.6e3,3.6e4],["new",3590.0,1.0e4],["new",3567.0,500.0],["new",3.5e3,230.0],["new",3.4e3,80.0],["new",3230.0,10.0],["new",3228.0,10.0],["new",3.2e3,20.0],["new",3001.0,20.0],["new",3.0e3,7.2e3],["new",2999.0,40.0],["new",2879.0,300.0],["new",2601.0,20.0],["new",2544.0,10.0],["new",2.5e3,20.0],["new",2467.0,2.56e4],["new",2.4e3,1.0e3],["new",2309.0,250.0],["new",2.3e3,20.0],["new",2222.0,680.0],["new",2211.0,40.0],["new",2005.0,140.0],["new",2.0e3,21250.0],["new",1999.0,10.0],["new",1994.5,5.0e3],["new",1979.0,60.0],["new",1.9e3,30.0],["new",1.7e3,300.0],["new",1.4e3,40.0],["new",1234.0,10.0],["new",1205.0,40.0],["new",1.1e3,20.0],["new",1099.0,10.0],["new",1002.5,70.0],["new",1001.5,60.0],["new",1000.5,80.0],["new",1.0e3,12450.0],["new",900.0,10.0],["new",800.0,10.0],["new",648.0,40.0],["new",600.0,760.0],["new",541.5,1.0e4],["new",502.0,1350.0],["new",500.0,3580.0],["new",400.0,150.0],["new",300.0,540.0],["new",288.0,10.0],["new",287.0,10.0],["new",281.0,100.0],["new",234.0,20.0],["new",222.0,300.0],["new",200.0,1220.0],["new",123.0,1.0e3],["new",120.0,110.0],["new",110.0,80.0],["new",101.0,110.0],["new",100.0,123510.0],["new",60.0,270.0],["new",58.0,10.0],["new",50.0,1350.0],["new",40.0,120.0],["new",35.5,20.0],["new",30.0,10350.0],["new",25.0,30.0],["new",23.0,20.0],["new",20.0,2210.0],["new",16.5,10.0],["new",15.0,20.0],["new",13.0,30.0],["new",12.0,2160.0],["new",11.0,10.0],["new",10.0,4010.0],["new",9.0,20.0],["new",6.5,10.0],["new",6.0,40.0],["new",5.0,300.0],["new",4.0,40.0],["new",3.0,20.0],["new",1.0,390.0],["new",0.5,61150.0]],"asks":[["new",80055.0,790.0],["new",80073.5,13130.0],["new",80074.5,490.0],["new",80075.5,34870.0],["new",80076.0,34640.0],["new",80076.5,81640.0],["new",80080.0,8890.0],["new",80080.5,13290.0],["new",80081.0,540.0],["new",80084.0,34870.0],["new",80089.0,16490.0],["new",80089.5,16490.0],["new",80090.0,4.0e4],["new",80092.5,1.67e4],["new",80093.0,18540.0],["new",80095.5,26520.0],["new",80097.0,9.5e3],["new",80098.5,83150.0],["new",80099.0,1110.0],["new",80099.5,33490.0],["new",80105.0,3680.0],["new",80140.5,3680.0],["new",80158.5,7360.0],["new",80239.0,80230.0],["new",80263.5,7777770.0],["new",80289.0,120420.0],["new",80469.0,7450.0],["new",80642.0,690.0],["new",80816.0,10.0],["new",81962.0,81590.0],["new",82168.0,81830.0],["new",82848.0,83220.0],["new",83749.0,1.0e4],["new",8.45e4,1.0e6],["new",8.5e4,1.0e6],["new",8.55e4,1.0e6],["new",8.6e4,1.0e6],["new",8.7e4,1.0e6],["new",8.75e4,1.0e6],["new",8.8e4,1.0e6],["new",9.0e4,20.0],["new",91442.0,10.0],["new",91747.0,300.0],["new",92036.5,100.0],["new",92823.0,6810.0],["new",92838.5,520.0],["new",95042.0,4190.0],["new",9.52e4,5950.0],["new",9.8e4,10.0],["new",9.9e4,20.0],["new",99670.0,5630.0],["new",1.0e5,10010.0],["new",100094.5,170.0],["new",100128.0,100.0],["new",100141.5,30.0],["new",100166.5,190.0],["new",1.008e5,5570.0],["new",100894.0,20.0],["new",101144.5,190.0],["new",102106.5,20.0],["new",103085.5,30.0],["new",103097.5,70.0],["new",103102.0,200.0],["new",103114.0,90.0],["new",104059.0,180.0],["new",104115.5,40.0],["new",104160.5,70.0],["new",104228.0,50.0],["new",105206.5,80.0],["new",107232.0,230.0],["new",107667.0,290.0],["new",109004.5,500.0],["new",110298.0,210.0],["new",110763.0,260.0],["new",111228.0,310.0],["new",111693.0,370.0],["new",112158.0,440.0],["new",112285.0,450.0],["new",112623.0,530.0],["new",113088.0,640.0],["new",113553.0,770.0],["new",114018.0,920.0],["new",114483.5,1.1e3],["new",114948.5,1320.0],["new",115164.0,550.0],["new",115413.5,1590.0],["new",118043.5,680.0],["new",119094.5,120.0],["new",1.2e5,100020.0],["new",120922.5,820.0],["new",123801.5,1010.0],["new",126680.5,1230.0],["new",129559.5,1.5e3],["new",130318.5,130.0],["new",145037.0,150.0],["new",145090.5,150.0],["new",145306.5,300.0],["new",1.5e5,38100030.0]]}}}
[2025-04-06 23:46:58.176] [multi_sink] [error] Broadcast error: Operation canceled
[2025-04-06 23:46:58.344] [multi_sink] [info] 📩 Received: {"jsonrpc":"2.0","method":"subscription","params":{"channel":"book.BTC-PERPETUAL.100ms","data":{"timestamp":1743963419206,"type":"change","change_id":41106161863,"instrument_name":"BTC-PERPETUAL","bids":[["new",79917.0,79910.0],["new",79867.0,1.198e5]],"asks":[],"prev_change_id":41106161750}}}
[2025-04-06 23:46:58.346] [multi_sink] [info] Processing received message: {"jsonrpc":"2.0","method":"subscription","params":{"channel":"book.BTC-PERPETUAL.100ms","data":{"timestamp":1743963419206,"type":"change","change_id":41106161863,"instrument_name":"BTC-PERPETUAL","bids":[["new",79917.0,79910.0],["new",79867.0,1.198e5]],"asks":[],"prev_change_id":41106161750}}}
[2025-04-06 23:46:58.346] [multi_sink] [error] Broadcast error: Operation canceled
[2025-04-06 23:46:59.335] [multi_sink] [info] 📩 Received: {"jsonrpc":"2.0","method":"subscription","params":{"channel":"book.BTC-PERPETUAL.100ms","data":{"timestamp":1743963419966,"type":"change","change_id":41106163123,"instrument_name":"BTC-PERPETUAL","bids":[["delete",79917.0,0.0],["new",79904.5,7.99e4],["delete",79867.0,0.0],["new",79854.5,119780.0]],"asks":[],"prev_change_id":41106161863}}}
[2025-04-06 23:46:59.337] [multi_sink] [info] Processing received message: {"jsonrpc":"2.0","method":"subscription","params":{"channel":"book.BTC-PERPETUAL.100ms","data":{"timestamp":1743963419966,"type":"change","change_id":41106163123,"instrument_name":"BTC-PERPETUAL","bids":[["delete",79917.0,0.0],["new",79904.5,7.99e4],["delete",79867.0,0.0],["new",79854.5,119780.0]],"asks":[],"prev_change_id":41106161863}}}
[2025-04-06 23:46:59.337] [multi_sink] [error] Broadcast error: Operation canceled
[2025-04-06 23:47:00.595] [multi_sink] [info] 📩 Received: {"jsonrpc":"2.0","method":"subscription","params":{"channel":"book.BTC-PERPETUAL.100ms","data":{"timestamp":1743963421487,"type":"change","change_id":41106164987,"instrument_name":"BTC-PERPETUAL","bids":[["new",79879.0,8.0085e6],["delete",79872.0,0.0]],"asks":[],"prev_change_id":41106163123}}}
[2025-04-06 23:47:00.597] [multi_sink] [info] Processing received message: {"jsonrpc":"2.0","method":"subscription","params":{"channel":"book.BTC-PERPETUAL.100ms","data":{"timestamp":1743963421487,"type":"change","change_id":41106164987,"instrument_name":"BTC-PERPETUAL","bids":[["new",79879.0,8.0085e6],["delete",79872.0,0.0]],"asks":[],"prev_change_id":41106163123}}}
[2025-04-06 23:47:00.598] [multi_sink] [error] Broadcast error: Operation canceled
[2025-04-06 23:47:00.927] [multi_sink] [info] 📩 Received: {"jsonrpc":"2.0","method":"subscription","params":{"channel":"book.BTC-PERPETUAL.100ms","data":{"timestamp":1743963421727,"type":"change","change_id":41106165671,"instrument_name":"BTC-PERPETUAL","bids":[["new",79915.5,79910.0],["delete",79904.5,0.0],["new",79865.5,119790.0],["delete",79854.5,0.0]],"asks":[],"prev_change_id":41106164987}}}
[2025-04-06 23:47:00.932] [multi_sink] [info] Processing received message: {"jsonrpc":"2.0","method":"subscription","params":{"channel":"book.BTC-PERPETUAL.100ms","data":{"timestamp":1743963421727,"type":"change","change_id":41106165671,"instrument_name":"BTC-PERPETUAL","bids":[["new",79915.5,79910.0],["delete",79904.5,0.0],["new",79865.5,119790.0],["delete",79854.5,0.0]],"asks":[],"prev_change_id":41106164987}}}
[2025-04-06 23:47:00.932] [multi_sink] [error] Broadcast error: Operation canceled
[2025-04-06 23:47:01.259] [multi_sink] [info] 📩 Received: {"jsonrpc":"2.0","method":"subscription","params":{"channel":"book.BTC-PERPETUAL.100ms","data":{"timestamp":1743963422118,"type":"change","change_id":41106165758,"instrument_name":"BTC-PERPETUAL","bids":[["delete",80054.5,0.0],["delete",80054.0,0.0],["delete",80053.5,0.0],["delete",80052.5,0.0],["delete",80052.0,0.0],["new",80050.5,2490.0],["change",80050.0,4240.0],["change",80048.5,19150.0],["change",80047.5,47680.0],["change",80047.0,8.13e4]],"asks":[["change",80055.0,10.0],["delete",80073.5,0.0],["delete",80074.5,0.0],["delete",80075.5,0.0],["delete",80076.0,0.0],["change",80099.5,43020.0],["new",8.01e4,16490.0],["new",80100.5,57950.0],["new",80101.0,76090.0],["new",80101.5,81640.0],["delete",80263.5,0.0],["new",80270.5,7777770.0]],"prev_change_id":41106165671}}}
[2025-04-06 23:47:01.263] [multi_sink] [info] Processing received message: {"jsonrpc":"2.0","method":"subscription","params":{"channel":"book.BTC-PERPETUAL.100ms","data":{"timestamp":1743963422118,"type":"change","change_id":41106165758,"instrument_name":"BTC-PERPETUAL","bids":[["delete",80054.5,0.0],["delete",80054.0,0.0],["delete",80053.5,0.0],["delete",80052.5,0.0],["delete",80052.0,0.0],["new",80050.5,2490.0],["change",80050.0,4240.0],["change",80048.5,19150.0],["change",80047.5,47680.0],["change",80047.0,8.13e4]],"asks":[["change",80055.0,10.0],["delete",80073.5,0.0],["delete",80074.5,0.0],["delete",80075.5,0.0],["delete",80076.0,0.0],["change",80099.5,43020.0],["new",8.01e4,16490.0],["new",80100.5,57950.0],["new",80101.0,76090.0],["new",80101.5,81640.0],["delete",80263.5,0.0],["new",80270.5,7777770.0]],"prev_change_id":41106165671}}}
[2025-04-06 23:47:01.274] [multi_sink] [error] Broadcast error: Operation canceled
[2025-04-06 23:47:01.588] [multi_sink] [info] 📩 Received: {"jsonrpc":"2.0","method":"subscription","params":{"channel":"book.BTC-PERPETUAL.100ms","data":{"timestamp":1743963422471,"type":"change","change_id":41106166358,"instrument_name":"BTC-PERPETUAL","bids":[["new",80063.0,4.19e4],["new",80062.5,16480.0],["new",80062.0,12980.0],["new",80061.0,2.0e4],["new",80060.0,56070.0],["new",80056.0,204260.0],["new",80054.5,94510.0],["new",80053.0,8.31e4],["new",80052.5,3280.0],["change",80050.0,2120.0],["delete",80049.0,0.0],["change",80048.5,6160.0],["change",80047.5,38040.0],["change",80047.0,150.0],["delete",80046.0,0.0],["delete",80045.0,0.0],["delete",80044.5,0.0],["delete",80044.0,0.0],["delete",79915.5,0.0],["new",79905.0,7.99e4],["delete",79865.5,0.0],["new",79855.0,119780.0]],"asks":[["delete",80055.0,0.0],["delete",80076.5,0.0],["delete",80080.0,0.0],["delete",80080.5,0.0],["delete",80081.0,0.0],["delete",80084.0,0.0],["new",80088.5,490.0],["change",80089.0,4510.0],["change",80089.5,5750.0],["delete",80090.0,0.0],["new",80091.5,9530.0],["new",80092.0,7850.0],["delete",80092.5,0.0],["change",80093.0,18540.0],["change",80095.5,45580.0],["new",80096.0,10780.0],["new",80097.5,16860.0],["new",80098.0,9530.0]],"prev_change_id":41106165758}}}
[2025-04-06 23:47:01.606] [multi_sink] [info] Processing received message: {"jsonrpc":"2.0","method":"subscription","params":{"channel":"book.BTC-PERPETUAL.100ms","data":{"timestamp":1743963422471,"type":"change","change_id":41106166358,"instrument_name":"BTC-PERPETUAL","bids":[["new",80063.0,4.19e4],["new",80062.5,16480.0],["new",80062.0,12980.0],["new",80061.0,2.0e4],["new",80060.0,56070.0],["new",80056.0,204260.0],["new",80054.5,94510.0],["new",80053.0,8.31e4],["new",80052.5,3280.0],["change",80050.0,2120.0],["delete",80049.0,0.0],["change",80048.5,6160.0],["change",80047.5,38040.0],["change",80047.0,150.0],["delete",80046.0,0.0],["delete",80045.0,0.0],["delete",80044.5,0.0],["delete",80044.0,0.0],["delete",79915.5,0.0],["new",79905.0,7.99e4],["delete",79865.5,0.0],["new",79855.0,119780.0]],"asks":[["delete",80055.0,0.0],["delete",80076.5,0.0],["delete",80080.0,0.0],["delete",80080.5,0.0],["delete",80081.0,0.0],["delete",80084.0,0.0],["new",80088.5,490.0],["change",80089.0,4510.0],["change",80089.5,5750.0],["delete",80090.0,0.0],["new",80091.5,9530.0],["new",80092.0,7850.0],["delete",80092.5,0.0],["change",80093.0,18540.0],["change",80095.5,45580.0],["new",80096.0,10780.0],["new",80097.5,16860.0],["new",80098.0,9530.0]],"prev_change_id":41106165758}}}
[2025-04-06 23:47:01.607] [multi_sink] [error] Broadcast error: Operation canceled
[2025-04-06 23:47:01.919] [multi_sink] [info] 📩 Received: {"jsonrpc":"2.0","method":"subscription","params":{"channel":"book.BTC-PERPETUAL.100ms","data":{"timestamp":1743963422758,"type":"change","change_id":41106167149,"instrument_name":"BTC-PERPETUAL","bids":[["new",80067.5,254460.0],["new",80067.0,8.0e3],["new",80065.5,6650.0],["new",80065.0,5740.0],["new",80064.0,16490.0],["new",80063.5,25350.0],["delete",80042.5,0.0],["delete",80042.0,0.0],["delete",80040.0,0.0],["delete",80037.5,0.0],["delete",80037.0,0.0]],"asks":[["new",80068.0,12310.0],["new",80075.0,90.0],["new",80080.0,370.0],["new",80087.0,3890.0],["new",80087.5,12980.0],["change",80095.5,19060.0],["delete",80097.0,0.0],["delete",80098.5,0.0],["delete",80099.0,0.0],["change",80099.5,9530.0],["delete",80239.0,0.0],["delete",80289.0,0.0]],"prev_change_id":41106166358}}}
[2025-04-06 23:47:01.924] [multi_sink] [info] Processing received message: {"jsonrpc":"2.0","method":"subscription","params":{"channel":"book.BTC-PERPETUAL.100ms","data":{"timestamp":1743963422758,"type":"change","change_id":41106167149,"instrument_name":"BTC-PERPETUAL","bids":[["new",80067.5,254460.0],["new",80067.0,8.0e3],["new",80065.5,6650.0],["new",80065.0,5740.0],["new",80064.0,16490.0],["new",80063.5,25350.0],["delete",80042.5,0.0],["delete",80042.0,0.0],["delete",80040.0,0.0],["delete",80037.5,0.0],["delete",80037.0,0.0]],"asks":[["new",80068.0,12310.0],["new",80075.0,90.0],["new",80080.0,370.0],["new",80087.0,3890.0],["new",80087.5,12980.0],["change",80095.5,19060.0],["delete",80097.0,0.0],["delete",80098.5,0.0],["delete",80099.0,0.0],["change",80099.5,9530.0],["delete",80239.0,0.0],["delete",80289.0,0.0]],"prev_change_id":41106166358}}}
[2025-04-06 23:47:01.926] [multi_sink] [error] Broadcast error: Operation canceled
[2025-04-06 23:47:02.250] [multi_sink] [info] 📩 Received: {"jsonrpc":"2.0","method":"subscription","params":{"channel":"book.BTC-PERPETUAL.100ms","data":{"timestamp":1743963422931,"type":"change","change_id":41106167278,"instrument_name":"BTC-PERPETUAL","bids":[],"asks":[["change",80068.0,12320.0]],"prev_change_id":41106167149}}}
[2025-04-06 23:47:02.252] [multi_sink] [info] Processing received message: {"jsonrpc":"2.0","method":"subscription","params":{"channel":"book.BTC-PERPETUAL.100ms","data":{"timestamp":1743963422931,"type":"change","change_id":41106167278,"instrument_name":"BTC-PERPETUAL","bids":[],"asks":[["change",80068.0,12320.0]],"prev_change_id":41106167149}}}
[2025-04-06 23:47:02.252] [multi_sink] [error] Broadcast error: Operation canceled
[2025-04-06 23:47:03.410] [multi_sink] [info] 📩 Received: {"jsonrpc":"2.0","method":"subscription","params":{"channel":"book.BTC-PERPETUAL.100ms","data":{"timestamp":1743963424059,"type":"change","change_id":41106168781,"instrument_name":"BTC-PERPETUAL","bids":[["delete",79905.0,0.0],["delete",79855.0,0.0]],"asks":[],"prev_change_id":41106167278}}}
[2025-04-06 23:47:03.410] [multi_sink] [info] Processing received message: {"jsonrpc":"2.0","method":"subscription","params":{"channel":"book.BTC-PERPETUAL.100ms","data":{"timestamp":1743963424059,"type":"change","change_id":41106168781,"instrument_name":"BTC-PERPETUAL","bids":[["delete",79905.0,0.0],["delete",79855.0,0.0]],"asks":[],"prev_change_id":41106167278}}}
[2025-04-06 23:47:03.411] [multi_sink] [error] Broadcast error: Operation canceled
[2025-04-06 23:47:03.738] [multi_sink] [info] 📩 Received: {"jsonrpc":"2.0","method":"subscription","params":{"channel":"book.BTC-PERPETUAL.100ms","data":{"timestamp":1743963424595,"type":"change","change_id":41106169341,"instrument_name":"BTC-PERPETUAL","bids":[],"asks":[["new",80217.5,80210.0],["new",80267.5,1.204e5]],"prev_change_id":41106168781}}}
[2025-04-06 23:47:03.741] [multi_sink] [info] Processing received message: {"jsonrpc":"2.0","method":"subscription","params":{"channel":"book.BTC-PERPETUAL.100ms","data":{"timestamp":1743963424595,"type":"change","change_id":41106169341,"instrument_name":"BTC-PERPETUAL","bids":[],"asks":[["new",80217.5,80210.0],["new",80267.5,1.204e5]],"prev_change_id":41106168781}}}
[2025-04-06 23:47:03.742] [multi_sink] [error] Broadcast error: Operation canceled
[2025-04-06 23:47:04.070] [multi_sink] [info] 📩 Received: {"jsonrpc":"2.0","method":"subscription","params":{"channel":"book.BTC-PERPETUAL.100ms","data":{"timestamp":1743963424756,"type":"change","change_id":41106170081,"instrument_name":"BTC-PERPETUAL","bids":[["new",79889.0,79880.0],["new",79839.0,119750.0]],"asks":[],"prev_change_id":41106169341}}}
[2025-04-06 23:47:04.072] [multi_sink] [info] Processing received message: {"jsonrpc":"2.0","method":"subscription","params":{"channel":"book.BTC-PERPETUAL.100ms","data":{"timestamp":1743963424756,"type":"change","change_id":41106170081,"instrument_name":"BTC-PERPETUAL","bids":[["new",79889.0,79880.0],["new",79839.0,119750.0]],"asks":[],"prev_change_id":41106169341}}}
[2025-04-06 23:47:04.072] [multi_sink] [error] Broadcast error: Operation canceled
[2025-04-06 23:47:06.099] [multi_sink] [info] 📩 Received: {"jsonrpc":"2.0","method":"subscription","params":{"channel":"book.BTC-PERPETUAL.100ms","data":{"timestamp":1743963426974,"type":"change","change_id":41106172834,"instrument_name":"BTC-PERPETUAL","bids":[["delete",80067.5,0.0],["new",80025.5,1.576e5]],"asks":[["change",80068.0,10.0],["new",80077.0,28820.0],["new",80094.5,7777770.0]],"prev_change_id":41106170081}}}
[2025-04-06 23:47:06.102] [multi_sink] [info] Processing received message: {"jsonrpc":"2.0","method":"subscription","params":{"channel":"book.BTC-PERPETUAL.100ms","data":{"timestamp":1743963426974,"type":"change","change_id":41106172834,"instrument_name":"BTC-PERPETUAL","bids":[["delete",80067.5,0.0],["new",80025.5,1.576e5]],"asks":[["change",80068.0,10.0],["new",80077.0,28820.0],["new",80094.5,7777770.0]],"prev_change_id":41106170081}}}
[2025-04-06 23:47:06.103] [multi_sink] [error] Broadcast error: Operation canceled
[2025-04-06 23:47:06.430] [multi_sink] [info] 📩 Received: {"jsonrpc":"2.0","method":"subscription","params":{"channel":"book.BTC-PERPETUAL.100ms","data":{"timestamp":1743963427311,"type":"change","change_id":41106173095,"instrument_name":"BTC-PERPETUAL","bids":[["delete",80067.0,0.0],["delete",80065.5,0.0],["delete",80065.0,0.0],["delete",80064.0,0.0],["delete",80063.5,0.0],["delete",80063.0,0.0],["delete",80062.5,0.0],["delete",80062.0,0.0],["delete",80061.0,0.0],["new",80036.5,24270.0],["new",80036.0,40190.0],["new",80034.5,79990.0],["new",80033.5,33230.0],["new",80033.0,34630.0],["new",80032.5,13720.0],["new",80030.0,10.0],["new",80027.0,520.0],["new",80026.0,212750.0]],"asks":[["new",80069.5,16490.0],["new",80070.0,1.91e4],["new",80072.0,16490.0],["new",80072.5,370.0],["new",80073.0,42220.0],["new",80073.5,4.0e4],["new",80074.5,100720.0],["delete",80075.0,0.0],["new",80076.0,39380.0],["new",80076.5,3.52e4],["delete",80080.0,0.0],["delete",80087.0,0.0],["delete",80087.5,0.0],["delete",80088.5,0.0],["delete",80089.0,0.0],["delete",80089.5,0.0],["delete",80091.5,0.0],["delete",80092.0,0.0]],"prev_change_id":41106172834}}}
[2025-04-06 23:47:06.432] [multi_sink] [info] Processing received message: {"jsonrpc":"2.0","method":"subscription","params":{"channel":"book.BTC-PERPETUAL.100ms","data":{"timestamp":1743963427311,"type":"change","change_id":41106173095,"instrument_name":"BTC-PERPETUAL","bids":[["delete",80067.0,0.0],["delete",80065.5,0.0],["delete",80065.0,0.0],["delete",80064.0,0.0],["delete",80063.5,0.0],["delete",80063.0,0.0],["delete",80062.5,0.0],["delete",80062.0,0.0],["delete",80061.0,0.0],["new",80036.5,24270.0],["new",80036.0,40190.0],["new",80034.5,79990.0],["new",80033.5,33230.0],["new",80033.0,34630.0],["new",80032.5,13720.0],["new",80030.0,10.0],["new",80027.0,520.0],["new",80026.0,212750.0]],"asks":[["new",80069.5,16490.0],["new",80070.0,1.91e4],["new",80072.0,16490.0],["new",80072.5,370.0],["new",80073.0,42220.0],["new",80073.5,4.0e4],["new",80074.5,100720.0],["delete",80075.0,0.0],["new",80076.0,39380.0],["new",80076.5,3.52e4],["delete",80080.0,0.0],["delete",80087.0,0.0],["delete",80087.5,0.0],["delete",80088.5,0.0],["delete",80089.0,0.0],["delete",80089.5,0.0],["delete",80091.5,0.0],["delete",80092.0,0.0]],"prev_change_id":41106172834}}}
[2025-04-06 23:47:06.433] [multi_sink] [error] Broadcast error: Operation canceled
[2025-04-06 23:47:06.759] [multi_sink] [info] 📩 Received: {"jsonrpc":"2.0","method":"subscription","params":{"channel":"book.BTC-PERPETUAL.100ms","data":{"timestamp":1743963427627,"type":"change","change_id":41106173469,"instrument_name":"BTC-PERPETUAL","bids":[["delete",80060.0,0.0],["delete",80056.0,0.0],["delete",80054.5,0.0],["delete",80053.0,0.0],["delete",80052.5,0.0],["delete",80050.5,0.0],["delete",80050.0,0.0],["delete",80048.5,0.0],["new",80045.0,24040.0],["new",80044.5,8.0e4],["new",80042.0,1.1e3],["new",80041.5,16490.0],["new",80040.5,5.43e4],["new",80040.0,310.0],["new",80038.0,480.0],["new",80037.5,8060.0]],"asks":[["new",80054.0,1.0e4],["new",80054.5,10650.0],["new",80055.0,35490.0],["new",80060.5,490.0],["new",80065.0,20560.0],["new",80066.0,34630.0],["new",80066.5,540.0],["new",80067.5,1.91e4],["change",80068.0,10720.0],["delete",80093.0,0.0],["delete",80095.5,0.0],["delete",80096.0,0.0],["delete",80097.5,0.0],["delete",80098.0,0.0],["delete",80099.5,0.0],["delete",8.01e4,0.0],["delete",80100.5,0.0],["delete",80101.0,0.0]],"prev_change_id":41106173095}}}
[2025-04-06 23:47:06.761] [multi_sink] [info] Processing received message: {"jsonrpc":"2.0","method":"subscription","params":{"channel":"book.BTC-PERPETUAL.100ms","data":{"timestamp":1743963427627,"type":"change","change_id":41106173469,"instrument_name":"BTC-PERPETUAL","bids":[["delete",80060.0,0.0],["delete",80056.0,0.0],["delete",80054.5,0.0],["delete",80053.0,0.0],["delete",80052.5,0.0],["delete",80050.5,0.0],["delete",80050.0,0.0],["delete",80048.5,0.0],["new",80045.0,24040.0],["new",80044.5,8.0e4],["new",80042.0,1.1e3],["new",80041.5,16490.0],["new",80040.5,5.43e4],["new",80040.0,310.0],["new",80038.0,480.0],["new",80037.5,8060.0]],"asks":[["new",80054.0,1.0e4],["new",80054.5,10650.0],["new",80055.0,35490.0],["new",80060.5,490.0],["new",80065.0,20560.0],["new",80066.0,34630.0],["new",80066.5,540.0],["new",80067.5,1.91e4],["change",80068.0,10720.0],["delete",80093.0,0.0],["delete",80095.5,0.0],["delete",80096.0,0.0],["delete",80097.5,0.0],["delete",80098.0,0.0],["delete",80099.5,0.0],["delete",8.01e4,0.0],["delete",80100.5,0.0],["delete",80101.0,0.0]],"prev_change_id":41106173095}}}
[2025-04-06 23:47:06.780] [multi_sink] [error] Broadcast error: Operation canceled
[2025-04-06 23:47:07.089] [multi_sink] [info] 📩 Received: {"jsonrpc":"2.0","method":"subscription","params":{"channel":"book.BTC-PERPETUAL.100ms","data":{"timestamp":1743963427694,"type":"change","change_id":41106174051,"instrument_name":"BTC-PERPETUAL","bids":[["change",80047.5,740.0],["change",80047.0,150.0]],"asks":[["new",80048.0,71540.0],["delete",80101.5,0.0]],"prev_change_id":41106173469}}}
[2025-04-06 23:47:07.090] [multi_sink] [info] Processing received message: {"jsonrpc":"2.0","method":"subscription","params":{"channel":"book.BTC-PERPETUAL.100ms","data":{"timestamp":1743963427694,"type":"change","change_id":41106174051,"instrument_name":"BTC-PERPETUAL","bids":[["change",80047.5,740.0],["change",80047.0,150.0]],"asks":[["new",80048.0,71540.0],["delete",80101.5,0.0]],"prev_change_id":41106173469}}}
[2025-04-06 23:47:07.091] [multi_sink] [error] Broadcast error: Operation canceled
[2025-04-06 23:47:07.422] [multi_sink] [info] 📩 Received: {"jsonrpc":"2.0","method":"subscription","params":{"channel":"book.BTC-PERPETUAL.100ms","data":{"timestamp":1743963428221,"type":"change","change_id":41106174507,"instrument_name":"BTC-PERPETUAL","bids":[],"asks":[["change",80068.0,10710.0]],"prev_change_id":41106174051}}}
[2025-04-06 23:47:07.425] [multi_sink] [info] Processing received message: {"jsonrpc":"2.0","method":"subscription","params":{"channel":"book.BTC-PERPETUAL.100ms","data":{"timestamp":1743963428221,"type":"change","change_id":41106174507,"instrument_name":"BTC-PERPETUAL","bids":[],"asks":[["change",80068.0,10710.0]],"prev_change_id":41106174051}}}
[2025-04-06 23:47:07.426] [multi_sink] [error] Broadcast error: Operation canceled
[2025-04-06 23:47:07.751] [multi_sink] [info] 📩 Received: {"jsonrpc":"2.0","method":"subscription","params":{"channel":"book.BTC-PERPETUAL.100ms","data":{"timestamp":1743963428521,"type":"change","change_id":41106174992,"instrument_name":"BTC-PERPETUAL","bids":[],"asks":[["change",80048.0,71550.0]],"prev_change_id":41106174507}}}
[2025-04-06 23:47:07.754] [multi_sink] [info] Processing received message: {"jsonrpc":"2.0","method":"subscription","params":{"channel":"book.BTC-PERPETUAL.100ms","data":{"timestamp":1743963428521,"type":"change","change_id":41106174992,"instrument_name":"BTC-PERPETUAL","bids":[],"asks":[["change",80048.0,71550.0]],"prev_change_id":41106174507}}}
[2025-04-06 23:47:07.755] [multi_sink] [error] Broadcast error: Operation canceled
[2025-04-06 23:47:08.442] [multi_sink] [info] 📩 Received: {"jsonrpc":"2.0","method":"subscription","params":{"channel":"book.BTC-PERPETUAL.100ms","data":{"timestamp":1743963429334,"type":"change","change_id":41106176053,"instrument_name":"BTC-PERPETUAL","bids":[["delete",79879.0,0.0],["new",79852.0,8.0085e6]],"asks":[],"prev_change_id":41106174992}}}
[2025-04-06 23:47:08.442] [multi_sink] [info] Processing received message: {"jsonrpc":"2.0","method":"subscription","params":{"channel":"book.BTC-PERPETUAL.100ms","data":{"timestamp":1743963429334,"type":"change","change_id":41106176053,"instrument_name":"BTC-PERPETUAL","bids":[["delete",79879.0,0.0],["new",79852.0,8.0085e6]],"asks":[],"prev_change_id":41106174992}}}
[2025-04-06 23:47:08.443] [multi_sink] [error] Broadcast error: Operation canceled
[2025-04-06 23:47:09.103] [multi_sink] [info] 📩 Received: {"jsonrpc":"2.0","method":"subscription","params":{"channel":"book.BTC-PERPETUAL.100ms","data":{"timestamp":1743963429786,"type":"change","change_id":41106177064,"instrument_name":"BTC-PERPETUAL","bids":[],"asks":[["new",80243.5,7777770.0],["delete",80270.5,0.0]],"prev_change_id":41106176053}}}
[2025-04-06 23:47:09.108] [multi_sink] [info] Processing received message: {"jsonrpc":"2.0","method":"subscription","params":{"channel":"book.BTC-PERPETUAL.100ms","data":{"timestamp":1743963429786,"type":"change","change_id":41106177064,"instrument_name":"BTC-PERPETUAL","bids":[],"asks":[["new",80243.5,7777770.0],["delete",80270.5,0.0]],"prev_change_id":41106176053}}}
[2025-04-06 23:47:09.108] [multi_sink] [error] Broadcast error: Operation canceled
[2025-04-06 23:47:09.433] [multi_sink] [info] 📩 Received: {"jsonrpc":"2.0","method":"subscription","params":{"channel":"book.BTC-PERPETUAL.100ms","data":{"timestamp":1743963430249,"type":"change","change_id":41106177239,"instrument_name":"BTC-PERPETUAL","bids":[["new",79899.0,79890.0],["delete",79889.0,0.0],["new",79849.0,119760.0],["delete",79839.0,0.0]],"asks":[["delete",80217.5,0.0],["new",80229.5,80230.0],["delete",80267.5,0.0],["new",80279.5,120420.0]],"prev_change_id":41106177064}}}
[2025-04-06 23:47:09.433] [multi_sink] [info] Processing received message: {"jsonrpc":"2.0","method":"subscription","params":{"channel":"book.BTC-PERPETUAL.100ms","data":{"timestamp":1743963430249,"type":"change","change_id":41106177239,"instrument_name":"BTC-PERPETUAL","bids":[["new",79899.0,79890.0],["delete",79889.0,0.0],["new",79849.0,119760.0],["delete",79839.0,0.0]],"asks":[["delete",80217.5,0.0],["new",80229.5,80230.0],["delete",80267.5,0.0],["new",80279.5,120420.0]],"prev_change_id":41106177064}}}
[2025-04-06 23:47:09.434] [multi_sink] [error] Broadcast error: Operation canceled
[2025-04-06 23:47:11.132] [multi_sink] [info] 📩 Received: {"jsonrpc":"2.0","method":"subscription","params":{"channel":"book.BTC-PERPETUAL.100ms","data":{"timestamp":1743963432009,"type":"change","change_id":41106179768,"instrument_name":"BTC-PERPETUAL","bids":[["delete",80047.5,0.0],["delete",80047.0,0.0],["change",80032.5,14460.0],["new",80031.0,27970.0]],"asks":[["change",80048.0,10.0],["delete",80054.0,0.0],["new",80092.0,30470.0],["new",80092.5,59290.0]],"prev_change_id":41106177239}}}
[2025-04-06 23:47:11.137] [multi_sink] [info] Processing received message: {"jsonrpc":"2.0","method":"subscription","params":{"channel":"book.BTC-PERPETUAL.100ms","data":{"timestamp":1743963432009,"type":"change","change_id":41106179768,"instrument_name":"BTC-PERPETUAL","bids":[["delete",80047.5,0.0],["delete",80047.0,0.0],["change",80032.5,14460.0],["new",80031.0,27970.0]],"asks":[["change",80048.0,10.0],["delete",80054.0,0.0],["new",80092.0,30470.0],["new",80092.5,59290.0]],"prev_change_id":41106177239}}}
[2025-04-06 23:47:11.137] [multi_sink] [error] Broadcast error: Operation canceled
[2025-04-06 23:47:11.464] [multi_sink] [info] 📩 Received: {"jsonrpc":"2.0","method":"subscription","params":{"channel":"book.BTC-PERPETUAL.100ms","data":{"timestamp":1743963432334,"type":"change","change_id":41106180030,"instrument_name":"BTC-PERPETUAL","bids":[["delete",80045.0,0.0],["delete",80044.5,0.0],["delete",80042.0,0.0],["delete",80041.5,0.0],["change",80040.5,9.3e3],["change",80040.0,290.0],["new",80039.0,7270.0],["new",80038.5,5750.0],["delete",80038.0,0.0],["delete",80037.5,0.0],["change",80036.5,24010.0],["change",80036.0,83730.0],["change",80034.5,159990.0],["change",80033.5,33480.0],["change",80033.0,69250.0]],"asks":[["delete",80054.5,0.0],["delete",80055.0,0.0],["delete",80060.5,0.0],["delete",80065.0,0.0],["delete",80066.0,0.0],["delete",80066.5,0.0],["delete",80067.5,0.0],["delete",80068.0,0.0],["delete",80069.5,0.0],["change",80076.0,50210.0],["change",80076.5,7.04e4],["new",80080.0,8360.0],["new",80080.5,26630.0],["new",80084.0,7740.0],["new",80084.5,9530.0],["new",80087.5,1.0e4],["new",80090.5,16490.0],["new",80091.5,9930.0]],"prev_change_id":41106179768}}}
[2025-04-06 23:47:11.468] [multi_sink] [info] Processing received message: {"jsonrpc":"2.0","method":"subscription","params":{"channel":"book.BTC-PERPETUAL.100ms","data":{"timestamp":1743963432334,"type":"change","change_id":41106180030,"instrument_name":"BTC-PERPETUAL","bids":[["delete",80045.0,0.0],["delete",80044.5,0.0],["delete",80042.0,0.0],["delete",80041.5,0.0],["change",80040.5,9.3e3],["change",80040.0,290.0],["new",80039.0,7270.0],["new",80038.5,5750.0],["delete",80038.0,0.0],["delete",80037.5,0.0],["change",80036.5,24010.0],["change",80036.0,83730.0],["change",80034.5,159990.0],["change",80033.5,33480.0],["change",80033.0,69250.0]],"asks":[["delete",80054.5,0.0],["delete",80055.0,0.0],["delete",80060.5,0.0],["delete",80065.0,0.0],["delete",80066.0,0.0],["delete",80066.5,0.0],["delete",80067.5,0.0],["delete",80068.0,0.0],["delete",80069.5,0.0],["change",80076.0,50210.0],["change",80076.5,7.04e4],["new",80080.0,8360.0],["new",80080.5,26630.0],["new",80084.0,7740.0],["new",80084.5,9530.0],["new",80087.5,1.0e4],["new",80090.5,16490.0],["new",80091.5,9930.0]],"prev_change_id":41106179768}}}
[2025-04-06 23:47:11.470] [multi_sink] [error] Broadcast error: Operation canceled
[2025-04-06 23:47:11.795] [multi_sink] [info] 📩 Received: {"jsonrpc":"2.0","method":"subscription","params":{"channel":"book.BTC-PERPETUAL.100ms","data":{"timestamp":1743963432664,"type":"change","change_id":41106180498,"instrument_name":"BTC-PERPETUAL","bids":[["new",80050.5,290280.0],["new",80048.0,39540.0],["new",80047.5,5.16e4],["new",80047.0,140.0],["new",80045.0,50.0],["new",80044.5,8.0e4],["new",80044.0,36460.0],["new",80042.0,35720.0],["new",80041.0,9.31e4],["change",80036.0,43540.0],["change",80034.5,8.0e4],["change",80033.5,250.0],["change",80033.0,34620.0],["change",80032.5,740.0],["delete",80030.0,0.0],["delete",80027.0,0.0],["delete",80026.0,0.0],["delete",80025.5,0.0],["new",79910.5,79910.0],["delete",79899.0,0.0],["new",79860.5,119790.0],["delete",79849.0,0.0]],"asks":[["delete",80048.0,0.0],["new",80051.0,1380.0],["new",80068.0,30.0],["new",80069.0,6160.0],["change",80070.0,5750.0],["change",80072.0,12980.0],["change",80072.5,370.0],["change",80073.0,30240.0],["delete",80073.5,0.0],["new",80074.0,10490.0],["change",80074.5,81640.0],["change",80076.0,10830.0],["change",80076.5,3.52e4],["delete",80077.0,0.0],["delete",80229.5,0.0],["new",80242.0,80240.0],["delete",80279.5,0.0],["new",80292.0,120430.0]],"prev_change_id":41106180030}}}
[2025-04-06 23:47:11.798] [multi_sink] [info] Processing received message: {"jsonrpc":"2.0","method":"subscription","params":{"channel":"book.BTC-PERPETUAL.100ms","data":{"timestamp":1743963432664,"type":"change","change_id":41106180498,"instrument_name":"BTC-PERPETUAL","bids":[["new",80050.5,290280.0],["new",80048.0,39540.0],["new",80047.5,5.16e4],["new",80047.0,140.0],["new",80045.0,50.0],["new",80044.5,8.0e4],["new",80044.0,36460.0],["new",80042.0,35720.0],["new",80041.0,9.31e4],["change",80036.0,43540.0],["change",80034.5,8.0e4],["change",80033.5,250.0],["change",80033.0,34620.0],["change",80032.5,740.0],["delete",80030.0,0.0],["delete",80027.0,0.0],["delete",80026.0,0.0],["delete",80025.5,0.0],["new",79910.5,79910.0],["delete",79899.0,0.0],["new",79860.5,119790.0],["delete",79849.0,0.0]],"asks":[["delete",80048.0,0.0],["new",80051.0,1380.0],["new",80068.0,30.0],["new",80069.0,6160.0],["change",80070.0,5750.0],["change",80072.0,12980.0],["change",80072.5,370.0],["change",80073.0,30240.0],["delete",80073.5,0.0],["new",80074.0,10490.0],["change",80074.5,81640.0],["change",80076.0,10830.0],["change",80076.5,3.52e4],["delete",80077.0,0.0],["delete",80229.5,0.0],["new",80242.0,80240.0],["delete",80279.5,0.0],["new",80292.0,120430.0]],"prev_change_id":41106180030}}}
[2025-04-06 23:47:11.801] [multi_sink] [error] Broadcast error: Operation canceled
[2025-04-06 23:47:12.123] [multi_sink] [info] 📩 Received: {"jsonrpc":"2.0","method":"subscription","params":{"channel":"book.BTC-PERPETUAL.100ms","data":{"timestamp":1743963432901,"type":"change","change_id":41106181251,"instrument_name":"BTC-PERPETUAL","bids":[],"asks":[["change",80051.0,1390.0]],"prev_change_id":41106180498}}}
[2025-04-06 23:47:12.128] [multi_sink] [info] Processing received message: {"jsonrpc":"2.0","method":"subscription","params":{"channel":"book.BTC-PERPETUAL.100ms","data":{"timestamp":1743963432901,"type":"change","change_id":41106181251,"instrument_name":"BTC-PERPETUAL","bids":[],"asks":[["change",80051.0,1390.0]],"prev_change_id":41106180498}}}
[2025-04-06 23:47:12.128] [multi_sink] [error] Broadcast error: Operation canceled
[2025-04-06 23:47:12.453] [multi_sink] [info] 📩 Received: {"jsonrpc":"2.0","method":"subscription","params":{"channel":"book.BTC-PERPETUAL.100ms","data":{"timestamp":1743963433155,"type":"change","change_id":41106181372,"instrument_name":"BTC-PERPETUAL","bids":[["delete",79910.5,0.0],["new",79899.0,79890.0],["delete",79860.5,0.0],["new",79849.0,119760.0]],"asks":[],"prev_change_id":41106181251}}}
[2025-04-06 23:47:12.453] [multi_sink] [info] Processing received message: {"jsonrpc":"2.0","method":"subscription","params":{"channel":"book.BTC-PERPETUAL.100ms","data":{"timestamp":1743963433155,"type":"change","change_id":41106181372,"instrument_name":"BTC-PERPETUAL","bids":[["delete",79910.5,0.0],["new",79899.0,79890.0],["delete",79860.5,0.0],["new",79849.0,119760.0]],"asks":[],"prev_change_id":41106181251}}}
[2025-04-06 23:47:12.465] [multi_sink] [error] Broadcast error: Operation canceled
[2025-04-06 23:47:12.784] [multi_sink] [info] 📩 Received: {"jsonrpc":"2.0","method":"subscription","params":{"channel":"book.BTC-PERPETUAL.100ms","data":{"timestamp":1743963433523,"type":"change","change_id":41106181921,"instrument_name":"BTC-PERPETUAL","bids":[],"asks":[["delete",80242.0,0.0],["delete",80292.0,0.0]],"prev_change_id":41106181372}}}
[2025-04-06 23:47:12.784] [multi_sink] [info] Processing received message: {"jsonrpc":"2.0","method":"subscription","params":{"channel":"book.BTC-PERPETUAL.100ms","data":{"timestamp":1743963433523,"type":"change","change_id":41106181921,"instrument_name":"BTC-PERPETUAL","bids":[],"asks":[["delete",80242.0,0.0],["delete",80292.0,0.0]],"prev_change_id":41106181372}}}
[2025-04-06 23:47:12.786] [multi_sink] [error] Broadcast error: Operation canceled
[2025-04-06 23:47:13.531] [multi_sink] [info] 📩 Received: {"jsonrpc":"2.0","method":"subscription","params":{"channel":"book.BTC-PERPETUAL.100ms","data":{"timestamp":1743963434419,"type":"change","change_id":41106182979,"instrument_name":"BTC-PERPETUAL","bids":[["new",80028.0,5821010.0],["delete",80015.0,0.0]],"asks":[],"prev_change_id":41106181921}}}
[2025-04-06 23:47:13.536] [multi_sink] [info] Processing received message: {"jsonrpc":"2.0","method":"subscription","params":{"channel":"book.BTC-PERPETUAL.100ms","data":{"timestamp":1743963434419,"type":"change","change_id":41106182979,"instrument_name":"BTC-PERPETUAL","bids":[["new",80028.0,5821010.0],["delete",80015.0,0.0]],"asks":[],"prev_change_id":41106181921}}}
[2025-04-06 23:47:13.537] [multi_sink] [error] Broadcast error: Operation canceled
[2025-04-06 23:47:13.860] [multi_sink] [info] 📩 Received: {"jsonrpc":"2.0","method":"subscription","params":{"channel":"book.BTC-PERPETUAL.100ms","data":{"timestamp":1743963434526,"type":"change","change_id":41106183286,"instrument_name":"BTC-PERPETUAL","bids":[],"asks":[["new",80228.0,80220.0],["new",80278.0,120410.0]],"prev_change_id":41106182979}}}
[2025-04-06 23:47:13.862] [multi_sink] [info] Processing received message: {"jsonrpc":"2.0","method":"subscription","params":{"channel":"book.BTC-PERPETUAL.100ms","data":{"timestamp":1743963434526,"type":"change","change_id":41106183286,"instrument_name":"BTC-PERPETUAL","bids":[],"asks":[["new",80228.0,80220.0],["new",80278.0,120410.0]],"prev_change_id":41106182979}}}
[2025-04-06 23:47:13.863] [multi_sink] [error] Broadcast error: Operation canceled
[2025-04-06 23:47:14.189] [multi_sink] [info] 📩 Received: {"jsonrpc":"2.0","method":"subscription","params":{"channel":"book.BTC-PERPETUAL.100ms","data":{"timestamp":1743963434827,"type":"change","change_id":41106184046,"instrument_name":"BTC-PERPETUAL","bids":[],"asks":[["delete",80094.5,0.0]],"prev_change_id":41106183286}}}
[2025-04-06 23:47:14.191] [multi_sink] [info] Processing received message: {"jsonrpc":"2.0","method":"subscription","params":{"channel":"book.BTC-PERPETUAL.100ms","data":{"timestamp":1743963434827,"type":"change","change_id":41106184046,"instrument_name":"BTC-PERPETUAL","bids":[],"asks":[["delete",80094.5,0.0]],"prev_change_id":41106183286}}}
[2025-04-06 23:47:14.192] [multi_sink] [error] Broadcast error: Operation canceled
[2025-04-06 23:47:14.520] [multi_sink] [info] 📩 Received: {"jsonrpc":"2.0","method":"subscription","params":{"channel":"book.BTC-PERPETUAL.100ms","data":{"timestamp":1743963435296,"type":"change","change_id":41106184283,"instrument_name":"BTC-PERPETUAL","bids":[["delete",79899.0,0.0],["new",79887.0,79880.0],["delete",79849.0,0.0],["new",79837.0,119750.0]],"asks":[["delete",80228.0,0.0],["delete",80278.0,0.0]],"prev_change_id":41106184046}}}
[2025-04-06 23:47:14.524] [multi_sink] [info] Processing received message: {"jsonrpc":"2.0","method":"subscription","params":{"channel":"book.BTC-PERPETUAL.100ms","data":{"timestamp":1743963435296,"type":"change","change_id":41106184283,"instrument_name":"BTC-PERPETUAL","bids":[["delete",79899.0,0.0],["new",79887.0,79880.0],["delete",79849.0,0.0],["new",79837.0,119750.0]],"asks":[["delete",80228.0,0.0],["delete",80278.0,0.0]],"prev_change_id":41106184046}}}
[2025-04-06 23:47:14.525] [multi_sink] [error] Broadcast error: Operation canceled
[2025-04-06 23:47:15.200] [multi_sink] [info] 📩 Received: {"jsonrpc":"2.0","method":"subscription","params":{"channel":"book.BTC-PERPETUAL.100ms","data":{"timestamp":1743963436093,"type":"change","change_id":41106185388,"instrument_name":"BTC-PERPETUAL","bids":[["delete",79887.0,0.0]],"asks":[],"prev_change_id":41106184283}}}
[2025-04-06 23:47:15.204] [multi_sink] [info] Processing received message: {"jsonrpc":"2.0","method":"subscription","params":{"channel":"book.BTC-PERPETUAL.100ms","data":{"timestamp":1743963436093,"type":"change","change_id":41106185388,"instrument_name":"BTC-PERPETUAL","bids":[["delete",79887.0,0.0]],"asks":[],"prev_change_id":41106184283}}}
[2025-04-06 23:47:15.206] [multi_sink] [error] Broadcast error: Operation canceled
[2025-04-06 23:47:15.532] [multi_sink] [info] 📩 Received: {"jsonrpc":"2.0","method":"subscription","params":{"channel":"book.BTC-PERPETUAL.100ms","data":{"timestamp":1743963436101,"type":"change","change_id":41106185389,"instrument_name":"BTC-PERPETUAL","bids":[["delete",79837.0,0.0]],"asks":[],"prev_change_id":41106185388}}}
[2025-04-06 23:47:15.537] [multi_sink] [info] Processing received message: {"jsonrpc":"2.0","method":"subscription","params":{"channel":"book.BTC-PERPETUAL.100ms","data":{"timestamp":1743963436101,"type":"change","change_id":41106185389,"instrument_name":"BTC-PERPETUAL","bids":[["delete",79837.0,0.0]],"asks":[],"prev_change_id":41106185388}}}
[2025-04-06 23:47:15.540] [multi_sink] [error] Broadcast error: Operation canceled
[2025-04-06 23:47:16.191] [multi_sink] [info] 📩 Received: {"jsonrpc":"2.0","method":"subscription","params":{"channel":"book.BTC-PERPETUAL.100ms","data":{"timestamp":1743963437082,"type":"change","change_id":41106186719,"instrument_name":"BTC-PERPETUAL","bids":[["delete",80050.5,0.0],["delete",80048.0,0.0],["delete",80047.5,0.0],["change",80040.0,7.9e3],["change",80038.5,8740.0],["change",80036.0,152270.0]],"asks":[["change",80051.0,10.0],["delete",80068.0,0.0],["delete",80069.0,0.0],["delete",80070.0,0.0],["new",80089.0,32980.0],["new",80089.5,16510.0],["change",80091.5,19460.0],["change",80092.0,79150.0]],"prev_change_id":41106185389}}}
[2025-04-06 23:47:16.192] [multi_sink] [info] Processing received message: {"jsonrpc":"2.0","method":"subscription","params":{"channel":"book.BTC-PERPETUAL.100ms","data":{"timestamp":1743963437082,"type":"change","change_id":41106186719,"instrument_name":"BTC-PERPETUAL","bids":[["delete",80050.5,0.0],["delete",80048.0,0.0],["delete",80047.5,0.0],["change",80040.0,7.9e3],["change",80038.5,8740.0],["change",80036.0,152270.0]],"asks":[["change",80051.0,10.0],["delete",80068.0,0.0],["delete",80069.0,0.0],["delete",80070.0,0.0],["new",80089.0,32980.0],["new",80089.5,16510.0],["change",80091.5,19460.0],["change",80092.0,79150.0]],"prev_change_id":41106185389}}}
[2025-04-06 23:47:16.193] [multi_sink] [error] Broadcast error: Operation canceled
[2025-04-06 23:47:16.521] [multi_sink] [info] 📩 Received: {"jsonrpc":"2.0","method":"subscription","params":{"channel":"book.BTC-PERPETUAL.100ms","data":{"timestamp":1743963437388,"type":"change","change_id":41106186997,"instrument_name":"BTC-PERPETUAL","bids":[["delete",80047.0,0.0],["new",80046.5,19990.0],["new",80046.0,35540.0],["new",80045.5,1.0e4],["change",80045.0,870.0],["change",80044.5,79990.0],["change",80044.0,27740.0],["new",80042.5,8.31e4],["change",80042.0,1.1e3],["delete",80041.0,0.0],["change",80040.5,9290.0],["change",80040.0,7610.0],["delete",80039.0,0.0],["new",79894.0,79890.0],["new",79860.5,8.0085e6],["delete",79852.0,0.0],["new",79844.0,119760.0]],"asks":[["delete",80072.0,0.0],["delete",80072.5,0.0],["delete",80073.0,0.0],["delete",80074.0,0.0],["delete",80074.5,0.0],["delete",80076.0,0.0],["delete",80076.5,0.0],["delete",80080.0,0.0],["change",80080.5,32380.0],["new",80082.5,1.0e4],["new",80083.0,9640.0],["new",80083.5,12980.0],["change",80084.0,13280.0],["change",80084.5,19150.0],["new",80085.0,540.0],["change",80087.5,1.99e4],["new",80223.0,80220.0],["new",80273.0,1.204e5]],"prev_change_id":41106186719}}}
[2025-04-06 23:47:16.523] [multi_sink] [info] Processing received message: {"jsonrpc":"2.0","method":"subscription","params":{"channel":"book.BTC-PERPETUAL.100ms","data":{"timestamp":1743963437388,"type":"change","change_id":41106186997,"instrument_name":"BTC-PERPETUAL","bids":[["delete",80047.0,0.0],["new",80046.5,19990.0],["new",80046.0,35540.0],["new",80045.5,1.0e4],["change",80045.0,870.0],["change",80044.5,79990.0],["change",80044.0,27740.0],["new",80042.5,8.31e4],["change",80042.0,1.1e3],["delete",80041.0,0.0],["change",80040.5,9290.0],["change",80040.0,7610.0],["delete",80039.0,0.0],["new",79894.0,79890.0],["new",79860.5,8.0085e6],["delete",79852.0,0.0],["new",79844.0,119760.0]],"asks":[["delete",80072.0,0.0],["delete",80072.5,0.0],["delete",80073.0,0.0],["delete",80074.0,0.0],["delete",80074.5,0.0],["delete",80076.0,0.0],["delete",80076.5,0.0],["delete",80080.0,0.0],["change",80080.5,32380.0],["new",80082.5,1.0e4],["new",80083.0,9640.0],["new",80083.5,12980.0],["change",80084.0,13280.0],["change",80084.5,19150.0],["new",80085.0,540.0],["change",80087.5,1.99e4],["new",80223.0,80220.0],["new",80273.0,1.204e5]],"prev_change_id":41106186719}}}
[2025-04-06 23:47:16.524] [multi_sink] [error] Broadcast error: Operation canceled
[2025-04-06 23:47:16.852] [multi_sink] [info] 📩 Received: {"jsonrpc":"2.0","method":"subscription","params":{"channel":"book.BTC-PERPETUAL.100ms","data":{"timestamp":1743963437692,"type":"change","change_id":41106187576,"instrument_name":"BTC-PERPETUAL","bids":[["new",80055.0,272910.0],["new",80054.5,4.95e4],["new",80054.0,4930.0],["new",80052.5,16490.0],["new",80052.0,64680.0],["new",80051.5,41490.0],["new",80050.0,155750.0],["new",80047.5,5.43e4],["change",80038.5,2990.0],["delete",80036.5,0.0],["change",80036.0,108730.0],["delete",80034.5,0.0],["delete",80033.5,0.0],["delete",80033.0,0.0],["delete",80032.5,0.0],["delete",80031.0,0.0]],"asks":[["delete",80051.0,0.0],["new",80055.5,21630.0],["new",80056.5,140.0],["new",80065.0,680.0],["new",80068.0,100.0],["new",80076.0,13030.0],["new",80076.5,35560.0],["new",80077.5,4.0e3],["new",80080.0,7840.0],["change",80080.5,5750.0],["change",80084.0,5540.0],["change",80084.5,9620.0],["change",80087.5,9.9e3],["delete",80090.5,0.0],["change",80091.5,9530.0],["change",80092.0,48680.0],["delete",80092.5,0.0],["delete",80243.5,0.0],["new",80252.0,7777770.0]],"prev_change_id":41106186997}}}
[2025-04-06 23:47:16.853] [multi_sink] [info] Processing received message: {"jsonrpc":"2.0","method":"subscription","params":{"channel":"book.BTC-PERPETUAL.100ms","data":{"timestamp":1743963437692,"type":"change","change_id":41106187576,"instrument_name":"BTC-PERPETUAL","bids":[["new",80055.0,272910.0],["new",80054.5,4.95e4],["new",80054.0,4930.0],["new",80052.5,16490.0],["new",80052.0,64680.0],["new",80051.5,41490.0],["new",80050.0,155750.0],["new",80047.5,5.43e4],["change",80038.5,2990.0],["delete",80036.5,0.0],["change",80036.0,108730.0],["delete",80034.5,0.0],["delete",80033.5,0.0],["delete",80033.0,0.0],["delete",80032.5,0.0],["delete",80031.0,0.0]],"asks":[["delete",80051.0,0.0],["new",80055.5,21630.0],["new",80056.5,140.0],["new",80065.0,680.0],["new",80068.0,100.0],["new",80076.0,13030.0],["new",80076.5,35560.0],["new",80077.5,4.0e3],["new",80080.0,7840.0],["change",80080.5,5750.0],["change",80084.0,5540.0],["change",80084.5,9620.0],["change",80087.5,9.9e3],["delete",80090.5,0.0],["change",80091.5,9530.0],["change",80092.0,48680.0],["delete",80092.5,0.0],["delete",80243.5,0.0],["new",80252.0,7777770.0]],"prev_change_id":41106186997}}}
[2025-04-06 23:47:16.855] [multi_sink] [error] Broadcast error: Operation canceled
[2025-04-06 23:47:17.183] [multi_sink] [info] 📩 Received: {"jsonrpc":"2.0","method":"subscription","params":{"channel":"book.BTC-PERPETUAL.100ms","data":{"timestamp":1743963437926,"type":"change","change_id":41106188253,"instrument_name":"BTC-PERPETUAL","bids":[],"asks":[["change",80055.5,21640.0]],"prev_change_id":41106187576}}}
[2025-04-06 23:47:17.185] [multi_sink] [info] Processing received message: {"jsonrpc":"2.0","method":"subscription","params":{"channel":"book.BTC-PERPETUAL.100ms","data":{"timestamp":1743963437926,"type":"change","change_id":41106188253,"instrument_name":"BTC-PERPETUAL","bids":[],"asks":[["change",80055.5,21640.0]],"prev_change_id":41106187576}}}
[2025-04-06 23:47:17.185] [multi_sink] [error] Broadcast error: Operation canceled
[2025-04-06 23:47:17.513] [multi_sink] [info] 📩 Received: {"jsonrpc":"2.0","method":"subscription","params":{"channel":"book.BTC-PERPETUAL.100ms","data":{"timestamp":1743963438216,"type":"change","change_id":41106188424,"instrument_name":"BTC-PERPETUAL","bids":[["delete",79894.0,0.0],["delete",79844.0,0.0]],"asks":[["new",80211.5,80210.0],["delete",80223.0,0.0],["new",80261.5,120390.0],["delete",80273.0,0.0]],"prev_change_id":41106188253}}}
[2025-04-06 23:47:17.518] [multi_sink] [info] Processing received message: {"jsonrpc":"2.0","method":"subscription","params":{"channel":"book.BTC-PERPETUAL.100ms","data":{"timestamp":1743963438216,"type":"change","change_id":41106188424,"instrument_name":"BTC-PERPETUAL","bids":[["delete",79894.0,0.0],["delete",79844.0,0.0]],"asks":[["new",80211.5,80210.0],["delete",80223.0,0.0],["new",80261.5,120390.0],["delete",80273.0,0.0]],"prev_change_id":41106188253}}}
[2025-04-06 23:47:17.519] [multi_sink] [error] Broadcast error: Operation canceled
[2025-04-06 23:47:18.513] [multi_sink] [info] 📩 Received: {"jsonrpc":"2.0","method":"subscription","params":{"channel":"book.BTC-PERPETUAL.100ms","data":{"timestamp":1743963439306,"type":"change","change_id":41106189991,"instrument_name":"BTC-PERPETUAL","bids":[["new",79891.0,79890.0],["new",79841.0,119760.0]],"asks":[],"prev_change_id":41106188424}}}
[2025-04-06 23:47:18.517] [multi_sink] [info] Processing received message: {"jsonrpc":"2.0","method":"subscription","params":{"channel":"book.BTC-PERPETUAL.100ms","data":{"timestamp":1743963439306,"type":"change","change_id":41106189991,"instrument_name":"BTC-PERPETUAL","bids":[["new",79891.0,79890.0],["new",79841.0,119760.0]],"asks":[],"prev_change_id":41106188424}}}
[2025-04-06 23:47:18.518] [multi_sink] [error] Broadcast error: Operation canceled
[2025-04-06 23:47:21.186] [multi_sink] [info] 📩 Received: {"jsonrpc":"2.0","method":"subscription","params":{"channel":"book.BTC-PERPETUAL.100ms","data":{"timestamp":1743963442050,"type":"change","change_id":41106193703,"instrument_name":"BTC-PERPETUAL","bids":[["delete",80055.0,0.0],["delete",80054.5,0.0],["delete",80054.0,0.0],["new",80030.0,10820.0],["new",80027.5,540.0],["new",80026.0,212750.0]],"asks":[["change",80055.5,10.0],["delete",80056.5,0.0],["delete",80065.0,0.0],["change",80076.5,71120.0],["new",80077.0,5.5e3],["change",80077.5,8.0e3]],"prev_change_id":41106189991}}}
[2025-04-06 23:47:21.187] [multi_sink] [info] Processing received message: {"jsonrpc":"2.0","method":"subscription","params":{"channel":"book.BTC-PERPETUAL.100ms","data":{"timestamp":1743963442050,"type":"change","change_id":41106193703,"instrument_name":"BTC-PERPETUAL","bids":[["delete",80055.0,0.0],["delete",80054.5,0.0],["delete",80054.0,0.0],["new",80030.0,10820.0],["new",80027.5,540.0],["new",80026.0,212750.0]],"asks":[["change",80055.5,10.0],["delete",80056.5,0.0],["delete",80065.0,0.0],["change",80076.5,71120.0],["new",80077.0,5.5e3],["change",80077.5,8.0e3]],"prev_change_id":41106189991}}}
[2025-04-06 23:47:21.188] [multi_sink] [error] Broadcast error: Operation canceled
[2025-04-06 23:47:21.518] [multi_sink] [info] 📩 Received: {"jsonrpc":"2.0","method":"subscription","params":{"channel":"book.BTC-PERPETUAL.100ms","data":{"timestamp":1743963442379,"type":"change","change_id":41106193970,"instrument_name":"BTC-PERPETUAL","bids":[["delete",80052.5,0.0],["delete",80052.0,0.0],["delete",80051.5,0.0],["delete",80050.0,0.0],["delete",80047.5,0.0],["delete",80046.5,0.0],["delete",80046.0,0.0],["delete",80045.5,0.0],["delete",80045.0,0.0],["new",80034.5,8.0e4],["new",80034.0,16490.0],["new",80033.5,5980.0],["new",80033.0,34620.0],["new",80032.5,740.0],["new",80032.0,1.0e4],["new",80031.5,13410.0],["new",80031.0,2.0e4],["new",80030.5,16490.0],["delete",80028.0,0.0],["new",80005.5,5821010.0]],"asks":[["new",80064.5,16490.0],["new",80065.0,20020.0],["change",80068.0,16490.0],["new",80068.5,2.9e3],["new",80069.0,9670.0],["new",80072.5,370.0],["new",80073.0,19340.0],["new",80075.0,4.0e4],["change",80076.0,29820.0],["change",80076.5,35560.0],["change",80077.5,4.0e3],["delete",80080.0,0.0],["delete",80080.5,0.0],["delete",80082.5,0.0],["delete",80083.0,0.0],["delete",80083.5,0.0]],"prev_change_id":41106193703}}}
[2025-04-06 23:47:21.521] [multi_sink] [info] Processing received message: {"jsonrpc":"2.0","method":"subscription","params":{"channel":"book.BTC-PERPETUAL.100ms","data":{"timestamp":1743963442379,"type":"change","change_id":41106193970,"instrument_name":"BTC-PERPETUAL","bids":[["delete",80052.5,0.0],["delete",80052.0,0.0],["delete",80051.5,0.0],["delete",80050.0,0.0],["delete",80047.5,0.0],["delete",80046.5,0.0],["delete",80046.0,0.0],["delete",80045.5,0.0],["delete",80045.0,0.0],["new",80034.5,8.0e4],["new",80034.0,16490.0],["new",80033.5,5980.0],["new",80033.0,34620.0],["new",80032.5,740.0],["new",80032.0,1.0e4],["new",80031.5,13410.0],["new",80031.0,2.0e4],["new",80030.5,16490.0],["delete",80028.0,0.0],["new",80005.5,5821010.0]],"asks":[["new",80064.5,16490.0],["new",80065.0,20020.0],["change",80068.0,16490.0],["new",80068.5,2.9e3],["new",80069.0,9670.0],["new",80072.5,370.0],["new",80073.0,19340.0],["new",80075.0,4.0e4],["change",80076.0,29820.0],["change",80076.5,35560.0],["change",80077.5,4.0e3],["delete",80080.0,0.0],["delete",80080.5,0.0],["delete",80082.5,0.0],["delete",80083.0,0.0],["delete",80083.5,0.0]],"prev_change_id":41106193703}}}
[2025-04-06 23:47:21.523] [multi_sink] [error] Broadcast error: Operation canceled
[2025-04-06 23:47:21.848] [multi_sink] [info] 📩 Received: {"jsonrpc":"2.0","method":"subscription","params":{"channel":"book.BTC-PERPETUAL.100ms","data":{"timestamp":1743963442676,"type":"change","change_id":41106194431,"instrument_name":"BTC-PERPETUAL","bids":[["new",80045.0,60580.0],["change",80044.5,8.32e4],["delete",80044.0,0.0],["delete",80042.5,0.0],["change",80042.0,1080.0],["delete",80040.5,0.0],["change",80040.0,9.6e3],["new",80039.5,15490.0],["change",80038.5,3.5e4],["new",80036.5,490.0],["change",80036.0,62050.0]],"asks":[["new",80045.5,25410.0],["new",80047.5,3.0e3],["new",80048.0,1.0e4],["new",80061.0,490.0],["new",80061.5,5750.0],["new",80062.0,23670.0],["new",80062.5,35560.0],["new",80064.0,3820.0],["delete",80084.0,0.0],["delete",80084.5,0.0],["delete",80085.0,0.0],["delete",80087.5,0.0],["delete",80089.0,0.0],["delete",80089.5,0.0],["delete",80091.5,0.0],["delete",80092.0,0.0]],"prev_change_id":41106193970}}}
[2025-04-06 23:47:21.849] [multi_sink] [info] Processing received message: {"jsonrpc":"2.0","method":"subscription","params":{"channel":"book.BTC-PERPETUAL.100ms","data":{"timestamp":1743963442676,"type":"change","change_id":41106194431,"instrument_name":"BTC-PERPETUAL","bids":[["new",80045.0,60580.0],["change",80044.5,8.32e4],["delete",80044.0,0.0],["delete",80042.5,0.0],["change",80042.0,1080.0],["delete",80040.5,0.0],["change",80040.0,9.6e3],["new",80039.5,15490.0],["change",80038.5,3.5e4],["new",80036.5,490.0],["change",80036.0,62050.0]],"asks":[["new",80045.5,25410.0],["new",80047.5,3.0e3],["new",80048.0,1.0e4],["new",80061.0,490.0],["new",80061.5,5750.0],["new",80062.0,23670.0],["new",80062.5,35560.0],["new",80064.0,3820.0],["delete",80084.0,0.0],["delete",80084.5,0.0],["delete",80085.0,0.0],["delete",80087.5,0.0],["delete",80089.0,0.0],["delete",80089.5,0.0],["delete",80091.5,0.0],["delete",80092.0,0.0]],"prev_change_id":41106193970}}}
[2025-04-06 23:47:21.850] [multi_sink] [error] Broadcast error: Operation canceled
[2025-04-06 23:47:22.178] [multi_sink] [info] 📩 Received: {"jsonrpc":"2.0","method":"subscription","params":{"channel":"book.BTC-PERPETUAL.100ms","data":{"timestamp":1743963442961,"type":"change","change_id":41106195208,"instrument_name":"BTC-PERPETUAL","bids":[],"asks":[["delete",80055.5,0.0]],"prev_change_id":41106194431}}}
[2025-04-06 23:47:22.179] [multi_sink] [info] Processing received message: {"jsonrpc":"2.0","method":"subscription","params":{"channel":"book.BTC-PERPETUAL.100ms","data":{"timestamp":1743963442961,"type":"change","change_id":41106195208,"instrument_name":"BTC-PERPETUAL","bids":[],"asks":[["delete",80055.5,0.0]],"prev_change_id":41106194431}}}
[2025-04-06 23:47:22.180] [multi_sink] [error] Broadcast error: Operation canceled
[2025-04-06 23:47:22.509] [multi_sink] [info] 📩 Received: {"jsonrpc":"2.0","method":"subscription","params":{"channel":"book.BTC-PERPETUAL.100ms","data":{"timestamp":1743963443281,"type":"change","change_id":41106195522,"instrument_name":"BTC-PERPETUAL","bids":[],"asks":[["change",80045.5,25420.0]],"prev_change_id":41106195208}}}
[2025-04-06 23:47:22.512] [multi_sink] [info] Processing received message: {"jsonrpc":"2.0","method":"subscription","params":{"channel":"book.BTC-PERPETUAL.100ms","data":{"timestamp":1743963443281,"type":"change","change_id":41106195522,"instrument_name":"BTC-PERPETUAL","bids":[],"asks":[["change",80045.5,25420.0]],"prev_change_id":41106195208}}}
[2025-04-06 23:47:22.514] [multi_sink] [error] Broadcast error: Operation canceled
[2025-04-06 23:47:24.556] [multi_sink] [info] 📩 Received: {"jsonrpc":"2.0","method":"subscription","params":{"channel":"book.BTC-PERPETUAL.100ms","data":{"timestamp":1743963445361,"type":"change","change_id":41106198261,"instrument_name":"BTC-PERPETUAL","bids":[["delete",79891.0,0.0],["new",79880.0,79880.0],["delete",79860.5,0.0],["new",79849.0,8.0085e6],["delete",79841.0,0.0],["new",79830.0,119740.0]],"asks":[],"prev_change_id":41106195522}}}
[2025-04-06 23:47:24.557] [multi_sink] [info] Processing received message: {"jsonrpc":"2.0","method":"subscription","params":{"channel":"book.BTC-PERPETUAL.100ms","data":{"timestamp":1743963445361,"type":"change","change_id":41106198261,"instrument_name":"BTC-PERPETUAL","bids":[["delete",79891.0,0.0],["new",79880.0,79880.0],["delete",79860.5,0.0],["new",79849.0,8.0085e6],["delete",79841.0,0.0],["new",79830.0,119740.0]],"asks":[],"prev_change_id":41106195522}}}
[2025-04-06 23:47:24.558] [multi_sink] [error] Broadcast error: Operation canceled
[2025-04-06 23:47:24.886] [multi_sink] [info] 📩 Received: {"jsonrpc":"2.0","method":"subscription","params":{"channel":"book.BTC-PERPETUAL.100ms","data":{"timestamp":1743963445776,"type":"change","change_id":41106198880,"instrument_name":"BTC-PERPETUAL","bids":[],"asks":[["new",80240.5,7777770.0],["delete",80252.0,0.0]],"prev_change_id":41106198261}}}
[2025-04-06 23:47:24.887] [multi_sink] [info] Processing received message: {"jsonrpc":"2.0","method":"subscription","params":{"channel":"book.BTC-PERPETUAL.100ms","data":{"timestamp":1743963445776,"type":"change","change_id":41106198880,"instrument_name":"BTC-PERPETUAL","bids":[],"asks":[["new",80240.5,7777770.0],["delete",80252.0,0.0]],"prev_change_id":41106198261}}}
[2025-04-06 23:47:24.890] [multi_sink] [error] Broadcast error: Operation canceled
[2025-04-06 23:47:25.832] [multi_sink] [info] 📩 Received: {"jsonrpc":"2.0","method":"subscription","params":{"channel":"book.BTC-PERPETUAL.100ms","data":{"timestamp":1743963446725,"type":"change","change_id":41106200178,"instrument_name":"BTC-PERPETUAL","bids":[],"asks":[["new",80201.5,8.02e4],["delete",80211.5,0.0]],"prev_change_id":41106198880}}}
[2025-04-06 23:47:25.836] [multi_sink] [info] Processing received message: {"jsonrpc":"2.0","method":"subscription","params":{"channel":"book.BTC-PERPETUAL.100ms","data":{"timestamp":1743963446725,"type":"change","change_id":41106200178,"instrument_name":"BTC-PERPETUAL","bids":[],"asks":[["new",80201.5,8.02e4],["delete",80211.5,0.0]],"prev_change_id":41106198880}}}
[2025-04-06 23:47:25.837] [multi_sink] [error] Broadcast error: Operation canceled
[2025-04-06 23:47:26.163] [multi_sink] [info] 📩 Received: {"jsonrpc":"2.0","method":"subscription","params":{"channel":"book.BTC-PERPETUAL.100ms","data":{"timestamp":1743963447056,"type":"change","change_id":41106200705,"instrument_name":"BTC-PERPETUAL","bids":[["delete",80045.0,0.0],["delete",80044.5,0.0],["delete",80042.0,0.0],["change",80017.5,14640.0],["new",80016.0,90.0]],"asks":[["change",80045.5,10.0],["delete",80047.5,0.0],["delete",80048.0,0.0],["new",80060.0,20630.0],["change",80061.5,22240.0],["change",80062.0,43590.0],["delete",80201.5,0.0],["new",80212.5,80210.0],["delete",80261.5,0.0],["new",80262.5,120390.0]],"prev_change_id":41106200178}}}
[2025-04-06 23:47:26.165] [multi_sink] [info] Processing received message: {"jsonrpc":"2.0","method":"subscription","params":{"channel":"book.BTC-PERPETUAL.100ms","data":{"timestamp":1743963447056,"type":"change","change_id":41106200705,"instrument_name":"BTC-PERPETUAL","bids":[["delete",80045.0,0.0],["delete",80044.5,0.0],["delete",80042.0,0.0],["change",80017.5,14640.0],["new",80016.0,90.0]],"asks":[["change",80045.5,10.0],["delete",80047.5,0.0],["delete",80048.0,0.0],["new",80060.0,20630.0],["change",80061.5,22240.0],["change",80062.0,43590.0],["delete",80201.5,0.0],["new",80212.5,80210.0],["delete",80261.5,0.0],["new",80262.5,120390.0]],"prev_change_id":41106200178}}}
[2025-04-06 23:47:26.166] [multi_sink] [error] Broadcast error: Operation canceled
[2025-04-06 23:47:26.493] [multi_sink] [info] 📩 Received: {"jsonrpc":"2.0","method":"subscription","params":{"channel":"book.BTC-PERPETUAL.100ms","data":{"timestamp":1743963447384,"type":"change","change_id":41106200973,"instrument_name":"BTC-PERPETUAL","bids":[["delete",80040.0,0.0],["delete",80039.5,0.0],["delete",80038.5,0.0],["delete",80036.5,0.0],["delete",80036.0,0.0],["delete",80034.5,0.0],["delete",80034.0,0.0],["delete",80033.5,0.0],["delete",80033.0,0.0],["new",80026.5,480.0],["change",80026.0,275480.0],["new",80025.5,144980.0],["new",80025.0,403270.0],["new",80024.5,79990.0],["new",80023.5,12670.0],["new",80023.0,52180.0],["new",80022.5,5050.0],["new",80021.0,4170.0]],"asks":[["change",80045.5,500.0],["new",80046.0,1.0e4],["new",80050.0,12970.0],["new",80052.5,10670.0],["new",80054.0,35560.0],["new",80056.0,9690.0],["new",80056.5,3150.0],["new",80057.0,9690.0],["new",80059.0,16490.0],["delete",80061.0,0.0],["change",80061.5,16490.0],["change",80062.0,19920.0],["delete",80062.5,0.0],["delete",80064.0,0.0],["delete",80064.5,0.0],["delete",80065.0,0.0],["delete",80068.0,0.0],["delete",80068.5,0.0]],"prev_change_id":41106200705}}}
[2025-04-06 23:47:26.494] [multi_sink] [info] Processing received message: {"jsonrpc":"2.0","method":"subscription","params":{"channel":"book.BTC-PERPETUAL.100ms","data":{"timestamp":1743963447384,"type":"change","change_id":41106200973,"instrument_name":"BTC-PERPETUAL","bids":[["delete",80040.0,0.0],["delete",80039.5,0.0],["delete",80038.5,0.0],["delete",80036.5,0.0],["delete",80036.0,0.0],["delete",80034.5,0.0],["delete",80034.0,0.0],["delete",80033.5,0.0],["delete",80033.0,0.0],["new",80026.5,480.0],["change",80026.0,275480.0],["new",80025.5,144980.0],["new",80025.0,403270.0],["new",80024.5,79990.0],["new",80023.5,12670.0],["new",80023.0,52180.0],["new",80022.5,5050.0],["new",80021.0,4170.0]],"asks":[["change",80045.5,500.0],["new",80046.0,1.0e4],["new",80050.0,12970.0],["new",80052.5,10670.0],["new",80054.0,35560.0],["new",80056.0,9690.0],["new",80056.5,3150.0],["new",80057.0,9690.0],["new",80059.0,16490.0],["delete",80061.0,0.0],["change",80061.5,16490.0],["change",80062.0,19920.0],["delete",80062.5,0.0],["delete",80064.0,0.0],["delete",80064.5,0.0],["delete",80065.0,0.0],["delete",80068.0,0.0],["delete",80068.5,0.0]],"prev_change_id":41106200705}}}
[2025-04-06 23:47:26.504] [multi_sink] [error] Broadcast error: Operation canceled
[2025-04-06 23:47:26.825] [multi_sink] [info] 📩 Received: {"jsonrpc":"2.0","method":"subscription","params":{"channel":"book.BTC-PERPETUAL.100ms","data":{"timestamp":1743963447682,"type":"change","change_id":41106201431,"instrument_name":"BTC-PERPETUAL","bids":[["new",80036.0,7.25e4],["new",80034.5,8.0e4],["new",80034.0,9980.0],["new",80033.5,250.0],["change",80032.5,740.0],["delete",80032.0,0.0],["delete",80031.5,0.0],["delete",80031.0,0.0],["delete",80030.5,0.0],["change",80030.0,830.0],["new",80029.5,26990.0],["new",80029.0,3.5e4],["delete",80027.5,0.0],["change",80026.0,62730.0]],"asks":[["new",80036.5,35760.0],["new",80040.0,43440.0],["new",80040.5,43040.0],["new",80041.5,9260.0],["new",80042.0,4.14e4],["new",80042.5,650.0],["new",80044.0,24370.0],["new",80045.0,470.0],["delete",80069.0,0.0],["delete",80072.5,0.0],["delete",80073.0,0.0],["delete",80075.0,0.0],["delete",80076.0,0.0],["delete",80076.5,0.0],["delete",80077.0,0.0],["delete",80077.5,0.0]],"prev_change_id":41106200973}}}
[2025-04-06 23:47:26.829] [multi_sink] [info] Processing received message: {"jsonrpc":"2.0","method":"subscription","params":{"channel":"book.BTC-PERPETUAL.100ms","data":{"timestamp":1743963447682,"type":"change","change_id":41106201431,"instrument_name":"BTC-PERPETUAL","bids":[["new",80036.0,7.25e4],["new",80034.5,8.0e4],["new",80034.0,9980.0],["new",80033.5,250.0],["change",80032.5,740.0],["delete",80032.0,0.0],["delete",80031.5,0.0],["delete",80031.0,0.0],["delete",80030.5,0.0],["change",80030.0,830.0],["new",80029.5,26990.0],["new",80029.0,3.5e4],["delete",80027.5,0.0],["change",80026.0,62730.0]],"asks":[["new",80036.5,35760.0],["new",80040.0,43440.0],["new",80040.5,43040.0],["new",80041.5,9260.0],["new",80042.0,4.14e4],["new",80042.5,650.0],["new",80044.0,24370.0],["new",80045.0,470.0],["delete",80069.0,0.0],["delete",80072.5,0.0],["delete",80073.0,0.0],["delete",80075.0,0.0],["delete",80076.0,0.0],["delete",80076.5,0.0],["delete",80077.0,0.0],["delete",80077.5,0.0]],"prev_change_id":41106200973}}}
[2025-04-06 23:47:26.830] [multi_sink] [error] Broadcast error: Operation canceled
[2025-04-06 23:47:27.708] [multi_sink] [info] 📩 Received: {"jsonrpc":"2.0","method":"subscription","params":{"channel":"book.BTC-PERPETUAL.100ms","data":{"timestamp":1743963448601,"type":"change","change_id":41106202875,"instrument_name":"BTC-PERPETUAL","bids":[],"asks":[["change",80045.5,490.0]],"prev_change_id":41106201431}}}
[2025-04-06 23:47:27.710] [multi_sink] [info] Processing received message: {"jsonrpc":"2.0","method":"subscription","params":{"channel":"book.BTC-PERPETUAL.100ms","data":{"timestamp":1743963448601,"type":"change","change_id":41106202875,"instrument_name":"BTC-PERPETUAL","bids":[],"asks":[["change",80045.5,490.0]],"prev_change_id":41106201431}}}
[2025-04-06 23:47:27.710] [multi_sink] [error] Broadcast error: Operation canceled
[2025-04-06 23:47:28.042] [multi_sink] [info] 📩 Received: {"jsonrpc":"2.0","method":"subscription","params":{"channel":"book.BTC-PERPETUAL.100ms","data":{"timestamp":1743963448921,"type":"change","change_id":41106203670,"instrument_name":"BTC-PERPETUAL","bids":[],"asks":[["change",80036.5,35770.0]],"prev_change_id":41106202875}}}
[2025-04-06 23:47:28.045] [multi_sink] [info] Processing received message: {"jsonrpc":"2.0","method":"subscription","params":{"channel":"book.BTC-PERPETUAL.100ms","data":{"timestamp":1743963448921,"type":"change","change_id":41106203670,"instrument_name":"BTC-PERPETUAL","bids":[],"asks":[["change",80036.5,35770.0]],"prev_change_id":41106202875}}}
[2025-04-06 23:47:28.045] [multi_sink] [error] Broadcast error: Operation canceled
[2025-04-06 23:47:28.369] [multi_sink] [info] 📩 Received: {"jsonrpc":"2.0","method":"subscription","params":{"channel":"book.BTC-PERPETUAL.100ms","data":{"timestamp":1743963448966,"type":"change","change_id":41106203674,"instrument_name":"BTC-PERPETUAL","bids":[],"asks":[["new",80201.0,8.02e4],["delete",80212.5,0.0],["new",80251.0,120370.0],["delete",80262.5,0.0]],"prev_change_id":41106203670}}}
[2025-04-06 23:47:28.369] [multi_sink] [info] Processing received message: {"jsonrpc":"2.0","method":"subscription","params":{"channel":"book.BTC-PERPETUAL.100ms","data":{"timestamp":1743963448966,"type":"change","change_id":41106203674,"instrument_name":"BTC-PERPETUAL","bids":[],"asks":[["new",80201.0,8.02e4],["delete",80212.5,0.0],["new",80251.0,120370.0],["delete",80262.5,0.0]],"prev_change_id":41106203670}}}
[2025-04-06 23:47:28.370] [multi_sink] [error] Broadcast error: Operation canceled
[2025-04-06 23:47:29.261] [multi_sink] [info] 📩 Received: {"jsonrpc":"2.0","method":"subscription","params":{"channel":"book.BTC-PERPETUAL.100ms","data":{"timestamp":1743963449847,"type":"change","change_id":41106204997,"instrument_name":"BTC-PERPETUAL","bids":[["delete",80005.5,0.0],["new",79996.5,5821010.0]],"asks":[],"prev_change_id":41106203674}}}
[2025-04-06 23:47:29.266] [multi_sink] [info] Processing received message: {"jsonrpc":"2.0","method":"subscription","params":{"channel":"book.BTC-PERPETUAL.100ms","data":{"timestamp":1743963449847,"type":"change","change_id":41106204997,"instrument_name":"BTC-PERPETUAL","bids":[["delete",80005.5,0.0],["new",79996.5,5821010.0]],"asks":[],"prev_change_id":41106203674}}}
[2025-04-06 23:47:29.267] [multi_sink] [error] Broadcast error: Operation canceled
[2025-04-06 23:47:31.272] [multi_sink] [info] 📩 Received: {"jsonrpc":"2.0","method":"subscription","params":{"channel":"book.BTC-PERPETUAL.100ms","data":{"timestamp":1743963452157,"type":"change","change_id":41106207693,"instrument_name":"BTC-PERPETUAL","bids":[["delete",80036.0,0.0],["delete",80034.5,0.0],["delete",80034.0,0.0],["delete",80033.5,0.0],["delete",80032.5,0.0],["new",80018.0,166490.0],["change",80017.5,16640.0],["change",80016.0,160.0],["new",80014.5,27220.0],["new",80014.0,30.0]],"asks":[["change",80036.5,10.0],["delete",80040.0,0.0],["delete",80040.5,0.0],["delete",80041.5,0.0],["delete",80042.0,0.0],["delete",80042.5,0.0],["change",80056.0,29070.0],["change",80056.5,6.3e3],["change",80060.0,31140.0],["new",80061.0,38520.0],["change",80061.5,99650.0],["change",80062.0,25410.0]],"prev_change_id":41106204997}}}
[2025-04-06 23:47:31.274] [multi_sink] [info] Processing received message: {"jsonrpc":"2.0","method":"subscription","params":{"channel":"book.BTC-PERPETUAL.100ms","data":{"timestamp":1743963452157,"type":"change","change_id":41106207693,"instrument_name":"BTC-PERPETUAL","bids":[["delete",80036.0,0.0],["delete",80034.5,0.0],["delete",80034.0,0.0],["delete",80033.5,0.0],["delete",80032.5,0.0],["new",80018.0,166490.0],["change",80017.5,16640.0],["change",80016.0,160.0],["new",80014.5,27220.0],["new",80014.0,30.0]],"asks":[["change",80036.5,10.0],["delete",80040.0,0.0],["delete",80040.5,0.0],["delete",80041.5,0.0],["delete",80042.0,0.0],["delete",80042.5,0.0],["change",80056.0,29070.0],["change",80056.5,6.3e3],["change",80060.0,31140.0],["new",80061.0,38520.0],["change",80061.5,99650.0],["change",80062.0,25410.0]],"prev_change_id":41106204997}}}
[2025-04-06 23:47:31.276] [multi_sink] [error] Broadcast error: Operation canceled
[2025-04-06 23:47:31.603] [multi_sink] [info] 📩 Received: {"jsonrpc":"2.0","method":"subscription","params":{"channel":"book.BTC-PERPETUAL.100ms","data":{"timestamp":1743963452476,"type":"change","change_id":41106208201,"instrument_name":"BTC-PERPETUAL","bids":[["delete",80030.0,0.0],["delete",80029.5,0.0],["delete",80029.0,0.0],["delete",80026.5,0.0],["delete",80026.0,0.0],["delete",80025.5,0.0],["change",80025.0,403270.0],["delete",80023.5,0.0],["change",80023.0,59070.0],["change",80022.5,1.01e4],["new",80021.5,470.0],["change",80021.0,8340.0],["new",80020.5,13210.0],["new",80020.0,20.0],["new",80018.5,5710.0]],"asks":[["new",80042.0,1.0e4],["delete",80044.0,0.0],["new",80044.5,10710.0],["change",80045.0,35690.0],["delete",80045.5,0.0],["delete",80046.0,0.0],["new",80048.0,4050.0],["delete",80050.0,0.0],["new",80052.0,13510.0],["change",80052.5,47750.0],["new",80053.0,96540.0],["new",80053.5,35690.0],["delete",80054.0,0.0],["new",80055.5,16490.0],["change",80056.0,19380.0],["change",80056.5,3150.0]],"prev_change_id":41106207693}}}
[2025-04-06 23:47:31.605] [multi_sink] [info] Processing received message: {"jsonrpc":"2.0","method":"subscription","params":{"channel":"book.BTC-PERPETUAL.100ms","data":{"timestamp":1743963452476,"type":"change","change_id":41106208201,"instrument_name":"BTC-PERPETUAL","bids":[["delete",80030.0,0.0],["delete",80029.5,0.0],["delete",80029.0,0.0],["delete",80026.5,0.0],["delete",80026.0,0.0],["delete",80025.5,0.0],["change",80025.0,403270.0],["delete",80023.5,0.0],["change",80023.0,59070.0],["change",80022.5,1.01e4],["new",80021.5,470.0],["change",80021.0,8340.0],["new",80020.5,13210.0],["new",80020.0,20.0],["new",80018.5,5710.0]],"asks":[["new",80042.0,1.0e4],["delete",80044.0,0.0],["new",80044.5,10710.0],["change",80045.0,35690.0],["delete",80045.5,0.0],["delete",80046.0,0.0],["new",80048.0,4050.0],["delete",80050.0,0.0],["new",80052.0,13510.0],["change",80052.5,47750.0],["new",80053.0,96540.0],["new",80053.5,35690.0],["delete",80054.0,0.0],["new",80055.5,16490.0],["change",80056.0,19380.0],["change",80056.5,3150.0]],"prev_change_id":41106207693}}}
[2025-04-06 23:47:31.607] [multi_sink] [error] Broadcast error: Operation canceled
[2025-04-06 23:47:31.935] [multi_sink] [info] 📩 Received: {"jsonrpc":"2.0","method":"subscription","params":{"channel":"book.BTC-PERPETUAL.100ms","data":{"timestamp":1743963452692,"type":"change","change_id":41106208416,"instrument_name":"BTC-PERPETUAL","bids":[["new",80034.5,34110.0],["new",80033.5,250.0],["new",80031.0,9990.0],["new",80030.0,1150.0],["new",80026.0,62750.0],["new",80025.5,16490.0],["change",80023.0,6890.0],["change",80022.5,5050.0],["change",80021.0,4170.0],["change",80017.5,14650.0],["change",80016.0,70.0]],"asks":[["new",80035.0,1.379e5],["new",80036.0,11610.0],["change",80036.5,3.87e4],["new",80041.0,490.0],["new",80041.5,3150.0],["delete",80057.0,0.0],["delete",80059.0,0.0],["change",80060.0,10510.0],["change",80061.5,83160.0],["change",80062.0,5490.0]],"prev_change_id":41106208201}}}
[2025-04-06 23:47:31.935] [multi_sink] [info] Processing received message: {"jsonrpc":"2.0","method":"subscription","params":{"channel":"book.BTC-PERPETUAL.100ms","data":{"timestamp":1743963452692,"type":"change","change_id":41106208416,"instrument_name":"BTC-PERPETUAL","bids":[["new",80034.5,34110.0],["new",80033.5,250.0],["new",80031.0,9990.0],["new",80030.0,1150.0],["new",80026.0,62750.0],["new",80025.5,16490.0],["change",80023.0,6890.0],["change",80022.5,5050.0],["change",80021.0,4170.0],["change",80017.5,14650.0],["change",80016.0,70.0]],"asks":[["new",80035.0,1.379e5],["new",80036.0,11610.0],["change",80036.5,3.87e4],["new",80041.0,490.0],["new",80041.5,3150.0],["delete",80057.0,0.0],["delete",80059.0,0.0],["change",80060.0,10510.0],["change",80061.5,83160.0],["change",80062.0,5490.0]],"prev_change_id":41106208201}}}
[2025-04-06 23:47:31.937] [multi_sink] [error] Broadcast error: Operation canceled
[2025-04-06 23:47:32.594] [multi_sink] [info] 📩 Received: {"jsonrpc":"2.0","method":"subscription","params":{"channel":"book.BTC-PERPETUAL.100ms","data":{"timestamp":1743963453467,"type":"change","change_id":41106209531,"instrument_name":"BTC-PERPETUAL","bids":[["delete",79849.0,0.0],["new",79839.0,8.0085e6]],"asks":[["change",80035.0,135380.0]],"prev_change_id":41106208416}}}
[2025-04-06 23:47:32.595] [multi_sink] [info] Processing received message: {"jsonrpc":"2.0","method":"subscription","params":{"channel":"book.BTC-PERPETUAL.100ms","data":{"timestamp":1743963453467,"type":"change","change_id":41106209531,"instrument_name":"BTC-PERPETUAL","bids":[["delete",79849.0,0.0],["new",79839.0,8.0085e6]],"asks":[["change",80035.0,135380.0]],"prev_change_id":41106208416}}}
[2025-04-06 23:47:32.596] [multi_sink] [error] Broadcast error: Operation canceled
[2025-04-06 23:47:33.255] [multi_sink] [info] 📩 Received: {"jsonrpc":"2.0","method":"subscription","params":{"channel":"book.BTC-PERPETUAL.100ms","data":{"timestamp":1743963453960,"type":"change","change_id":41106210661,"instrument_name":"BTC-PERPETUAL","bids":[],"asks":[["new",80230.5,7777770.0],["delete",80240.5,0.0]],"prev_change_id":41106209531}}}
[2025-04-06 23:47:33.256] [multi_sink] [info] Processing received message: {"jsonrpc":"2.0","method":"subscription","params":{"channel":"book.BTC-PERPETUAL.100ms","data":{"timestamp":1743963453960,"type":"change","change_id":41106210661,"instrument_name":"BTC-PERPETUAL","bids":[],"asks":[["new",80230.5,7777770.0],["delete",80240.5,0.0]],"prev_change_id":41106209531}}}
[2025-04-06 23:47:33.257] [multi_sink] [error] Broadcast error: Operation canceled
[2025-04-06 23:47:33.588] [multi_sink] [info] 📩 Received: {"jsonrpc":"2.0","method":"subscription","params":{"channel":"book.BTC-PERPETUAL.100ms","data":{"timestamp":1743963454222,"type":"change","change_id":41106210728,"instrument_name":"BTC-PERPETUAL","bids":[],"asks":[["change",80036.5,38690.0]],"prev_change_id":41106210661}}}
[2025-04-06 23:47:33.590] [multi_sink] [info] Processing received message: {"jsonrpc":"2.0","method":"subscription","params":{"channel":"book.BTC-PERPETUAL.100ms","data":{"timestamp":1743963454222,"type":"change","change_id":41106210728,"instrument_name":"BTC-PERPETUAL","bids":[],"asks":[["change",80036.5,38690.0]],"prev_change_id":41106210661}}}
[2025-04-06 23:47:33.591] [multi_sink] [error] Broadcast error: Operation canceled
[2025-04-06 23:47:33.917] [multi_sink] [info] 📩 Received: {"jsonrpc":"2.0","method":"subscription","params":{"channel":"book.BTC-PERPETUAL.100ms","data":{"timestamp":1743963454542,"type":"change","change_id":41106211231,"instrument_name":"BTC-PERPETUAL","bids":[],"asks":[["change",80035.0,135390.0]],"prev_change_id":41106210728}}}
[2025-04-06 23:47:33.921] [multi_sink] [info] Processing received message: {"jsonrpc":"2.0","method":"subscription","params":{"channel":"book.BTC-PERPETUAL.100ms","data":{"timestamp":1743963454542,"type":"change","change_id":41106211231,"instrument_name":"BTC-PERPETUAL","bids":[],"asks":[["change",80035.0,135390.0]],"prev_change_id":41106210728}}}
[2025-04-06 23:47:33.922] [multi_sink] [error] Broadcast error: Operation canceled
[2025-04-06 23:47:34.247] [multi_sink] [info] 📩 Received: {"jsonrpc":"2.0","method":"subscription","params":{"channel":"book.BTC-PERPETUAL.100ms","data":{"timestamp":1743963455078,"type":"change","change_id":41106211999,"instrument_name":"BTC-PERPETUAL","bids":[],"asks":[["delete",80201.0,0.0],["new",80213.0,80210.0],["delete",80251.0,0.0],["new",80263.0,120390.0]],"prev_change_id":41106211231}}}
[2025-04-06 23:47:34.251] [multi_sink] [info] Processing received message: {"jsonrpc":"2.0","method":"subscription","params":{"channel":"book.BTC-PERPETUAL.100ms","data":{"timestamp":1743963455078,"type":"change","change_id":41106211999,"instrument_name":"BTC-PERPETUAL","bids":[],"asks":[["delete",80201.0,0.0],["new",80213.0,80210.0],["delete",80251.0,0.0],["new",80263.0,120390.0]],"prev_change_id":41106211231}}}
[2025-04-06 23:47:34.252] [multi_sink] [error] Broadcast error: Operation canceled
[2025-04-06 23:47:34.579] [multi_sink] [info] 📩 Received: {"jsonrpc":"2.0","method":"subscription","params":{"channel":"book.BTC-PERPETUAL.100ms","data":{"timestamp":1743963455467,"type":"change","change_id":41106212239,"instrument_name":"BTC-PERPETUAL","bids":[["new",79890.0,79890.0],["delete",79880.0,0.0],["new",79840.0,119760.0],["delete",79830.0,0.0]],"asks":[["delete",80213.0,0.0],["new",80223.5,80220.0],["delete",80263.0,0.0],["new",80273.5,120410.0]],"prev_change_id":41106211999}}}
[2025-04-06 23:47:34.583] [multi_sink] [info] Processing received message: {"jsonrpc":"2.0","method":"subscription","params":{"channel":"book.BTC-PERPETUAL.100ms","data":{"timestamp":1743963455467,"type":"change","change_id":41106212239,"instrument_name":"BTC-PERPETUAL","bids":[["new",79890.0,79890.0],["delete",79880.0,0.0],["new",79840.0,119760.0],["delete",79830.0,0.0]],"asks":[["delete",80213.0,0.0],["new",80223.5,80220.0],["delete",80263.0,0.0],["new",80273.5,120410.0]],"prev_change_id":41106211999}}}
[2025-04-06 23:47:34.587] [multi_sink] [error] Broadcast error: Operation canceled
[2025-04-06 23:47:35.632] [multi_sink] [info] 📩 Received: {"jsonrpc":"2.0","method":"subscription","params":{"channel":"book.BTC-PERPETUAL.100ms","data":{"timestamp":1743963456281,"type":"change","change_id":41106213450,"instrument_name":"BTC-PERPETUAL","bids":[["delete",79890.0,0.0],["delete",79840.0,0.0]],"asks":[["delete",80223.5,0.0],["delete",80273.5,0.0]],"prev_change_id":41106212239}}}
[2025-04-06 23:47:35.635] [multi_sink] [info] Processing received message: {"jsonrpc":"2.0","method":"subscription","params":{"channel":"book.BTC-PERPETUAL.100ms","data":{"timestamp":1743963456281,"type":"change","change_id":41106213450,"instrument_name":"BTC-PERPETUAL","bids":[["delete",79890.0,0.0],["delete",79840.0,0.0]],"asks":[["delete",80223.5,0.0],["delete",80273.5,0.0]],"prev_change_id":41106212239}}}
[2025-04-06 23:47:35.636] [multi_sink] [error] Broadcast error: Operation canceled
[2025-04-06 23:47:36.307] [multi_sink] [info] 📩 Received: {"jsonrpc":"2.0","method":"subscription","params":{"channel":"book.BTC-PERPETUAL.100ms","data":{"timestamp":1743963457168,"type":"change","change_id":41106214737,"instrument_name":"BTC-PERPETUAL","bids":[["new",80035.0,43260.0],["change",80034.5,81640.0],["delete",80033.5,0.0],["new",80033.0,35210.0],["change",80031.0,22250.0],["change",80030.0,64850.0],["new",80027.5,2.72e4],["delete",80026.0,0.0],["delete",80025.5,0.0]],"asks":[["delete",80035.0,0.0],["delete",80036.0,0.0],["delete",80036.5,0.0],["delete",80041.0,0.0],["delete",80041.5,0.0],["delete",80042.0,0.0],["new",80088.5,36410.0],["new",80089.0,26560.0],["new",80089.5,16490.0],["new",80090.0,2530.0],["new",80091.0,81640.0],["new",80091.5,7010.0]],"prev_change_id":41106213450}}}
[2025-04-06 23:47:36.311] [multi_sink] [info] Processing received message: {"jsonrpc":"2.0","method":"subscription","params":{"channel":"book.BTC-PERPETUAL.100ms","data":{"timestamp":1743963457168,"type":"change","change_id":41106214737,"instrument_name":"BTC-PERPETUAL","bids":[["new",80035.0,43260.0],["change",80034.5,81640.0],["delete",80033.5,0.0],["new",80033.0,35210.0],["change",80031.0,22250.0],["change",80030.0,64850.0],["new",80027.5,2.72e4],["delete",80026.0,0.0],["delete",80025.5,0.0]],"asks":[["delete",80035.0,0.0],["delete",80036.0,0.0],["delete",80036.5,0.0],["delete",80041.0,0.0],["delete",80041.5,0.0],["delete",80042.0,0.0],["new",80088.5,36410.0],["new",80089.0,26560.0],["new",80089.5,16490.0],["new",80090.0,2530.0],["new",80091.0,81640.0],["new",80091.5,7010.0]],"prev_change_id":41106213450}}}
[2025-04-06 23:47:36.312] [multi_sink] [error] Broadcast error: Operation canceled
[2025-04-06 23:47:36.638] [multi_sink] [info] 📩 Received: {"jsonrpc":"2.0","method":"subscription","params":{"channel":"book.BTC-PERPETUAL.100ms","data":{"timestamp":1743963457524,"type":"change","change_id":41106215334,"instrument_name":"BTC-PERPETUAL","bids":[["new",80050.0,155740.0],["new",80048.5,3.5e4],["new",80048.0,48580.0],["new",80047.0,14020.0],["new",80044.0,24910.0],["new",80040.5,8.31e4],["new",80040.0,10460.0],["new",80039.5,34840.0],["new",80035.5,33460.0],["delete",80025.0,0.0],["delete",80024.5,0.0],["delete",80023.0,0.0],["delete",80022.5,0.0],["delete",80021.5,0.0],["delete",80021.0,0.0],["delete",80020.5,0.0],["delete",80020.0,0.0],["delete",80018.5,0.0],["change",80017.5,5835660.0],["delete",79996.5,0.0]],"asks":[["delete",80044.5,0.0],["delete",80045.0,0.0],["delete",80048.0,0.0],["delete",80052.0,0.0],["delete",80052.5,0.0],["delete",80053.0,0.0],["delete",80053.5,0.0],["delete",80055.5,0.0],["delete",80056.0,0.0],["delete",80056.5,0.0],["new",80075.0,1270.0],["new",80075.5,4250.0],["new",80076.0,26390.0],["new",80076.5,35560.0],["new",80081.5,490.0],["new",80082.0,1730.0],["new",80082.5,5750.0],["new",80085.0,3490.0],["new",80085.5,9690.0],["new",80086.5,1.0e3],["new",80233.5,80230.0],["new",80283.5,120420.0]],"prev_change_id":41106214737}}}
[2025-04-06 23:47:36.642] [multi_sink] [info] Processing received message: {"jsonrpc":"2.0","method":"subscription","params":{"channel":"book.BTC-PERPETUAL.100ms","data":{"timestamp":1743963457524,"type":"change","change_id":41106215334,"instrument_name":"BTC-PERPETUAL","bids":[["new",80050.0,155740.0],["new",80048.5,3.5e4],["new",80048.0,48580.0],["new",80047.0,14020.0],["new",80044.0,24910.0],["new",80040.5,8.31e4],["new",80040.0,10460.0],["new",80039.5,34840.0],["new",80035.5,33460.0],["delete",80025.0,0.0],["delete",80024.5,0.0],["delete",80023.0,0.0],["delete",80022.5,0.0],["delete",80021.5,0.0],["delete",80021.0,0.0],["delete",80020.5,0.0],["delete",80020.0,0.0],["delete",80018.5,0.0],["change",80017.5,5835660.0],["delete",79996.5,0.0]],"asks":[["delete",80044.5,0.0],["delete",80045.0,0.0],["delete",80048.0,0.0],["delete",80052.0,0.0],["delete",80052.5,0.0],["delete",80053.0,0.0],["delete",80053.5,0.0],["delete",80055.5,0.0],["delete",80056.0,0.0],["delete",80056.5,0.0],["new",80075.0,1270.0],["new",80075.5,4250.0],["new",80076.0,26390.0],["new",80076.5,35560.0],["new",80081.5,490.0],["new",80082.0,1730.0],["new",80082.5,5750.0],["new",80085.0,3490.0],["new",80085.5,9690.0],["new",80086.5,1.0e3],["new",80233.5,80230.0],["new",80283.5,120420.0]],"prev_change_id":41106214737}}}
[2025-04-06 23:47:36.643] [multi_sink] [error] Broadcast error: Operation canceled
[2025-04-06 23:47:36.968] [multi_sink] [info] 📩 Received: {"jsonrpc":"2.0","method":"subscription","params":{"channel":"book.BTC-PERPETUAL.100ms","data":{"timestamp":1743963457706,"type":"change","change_id":41106215570,"instrument_name":"BTC-PERPETUAL","bids":[["new",80057.0,283780.0],["new",80055.0,17820.0],["new",80054.5,41380.0],["new",80052.5,2.0e4],["new",80051.0,90160.0],["delete",80018.0,0.0],["change",80017.5,5833660.0],["delete",80016.0,0.0],["delete",80014.5,0.0],["delete",80014.0,0.0]],"asks":[["new",80057.5,820.0],["new",80058.0,10.0],["delete",80060.0,0.0],["delete",80061.0,0.0],["delete",80061.5,0.0],["delete",80062.0,0.0],["new",80065.0,1260.0],["new",80071.0,1.0e4]],"prev_change_id":41106215334}}}
[2025-04-06 23:47:36.971] [multi_sink] [info] Processing received message: {"jsonrpc":"2.0","method":"subscription","params":{"channel":"book.BTC-PERPETUAL.100ms","data":{"timestamp":1743963457706,"type":"change","change_id":41106215570,"instrument_name":"BTC-PERPETUAL","bids":[["new",80057.0,283780.0],["new",80055.0,17820.0],["new",80054.5,41380.0],["new",80052.5,2.0e4],["new",80051.0,90160.0],["delete",80018.0,0.0],["change",80017.5,5833660.0],["delete",80016.0,0.0],["delete",80014.5,0.0],["delete",80014.0,0.0]],"asks":[["new",80057.5,820.0],["new",80058.0,10.0],["delete",80060.0,0.0],["delete",80061.0,0.0],["delete",80061.5,0.0],["delete",80062.0,0.0],["new",80065.0,1260.0],["new",80071.0,1.0e4]],"prev_change_id":41106215334}}}
[2025-04-06 23:47:36.972] [multi_sink] [error] Broadcast error: Operation canceled
[2025-04-06 23:47:37.299] [multi_sink] [info] 📩 Received: {"jsonrpc":"2.0","method":"subscription","params":{"channel":"book.BTC-PERPETUAL.100ms","data":{"timestamp":1743963457924,"type":"change","change_id":41106216237,"instrument_name":"BTC-PERPETUAL","bids":[],"asks":[["change",80057.5,830.0]],"prev_change_id":41106215570}}}
[2025-04-06 23:47:37.301] [multi_sink] [info] Processing received message: {"jsonrpc":"2.0","method":"subscription","params":{"channel":"book.BTC-PERPETUAL.100ms","data":{"timestamp":1743963457924,"type":"change","change_id":41106216237,"instrument_name":"BTC-PERPETUAL","bids":[],"asks":[["change",80057.5,830.0]],"prev_change_id":41106215570}}}
[2025-04-06 23:47:37.302] [multi_sink] [error] Broadcast error: Operation canceled
[2025-04-06 23:47:37.641] [multi_sink] [info] 📩 Received: {"jsonrpc":"2.0","method":"subscription","params":{"channel":"book.BTC-PERPETUAL.100ms","data":{"timestamp":1743963458238,"type":"change","change_id":41106216449,"instrument_name":"BTC-PERPETUAL","bids":[["new",79908.5,7.99e4],["new",79858.5,119780.0]],"asks":[],"prev_change_id":41106216237}}}
[2025-04-06 23:47:37.642] [multi_sink] [info] Processing received message: {"jsonrpc":"2.0","method":"subscription","params":{"channel":"book.BTC-PERPETUAL.100ms","data":{"timestamp":1743963458238,"type":"change","change_id":41106216449,"instrument_name":"BTC-PERPETUAL","bids":[["new",79908.5,7.99e4],["new",79858.5,119780.0]],"asks":[],"prev_change_id":41106216237}}}
[2025-04-06 23:47:37.643] [multi_sink] [error] Broadcast error: Operation canceled
[2025-04-06 23:47:38.652] [multi_sink] [info] 📩 Received: {"jsonrpc":"2.0","method":"subscription","params":{"channel":"book.BTC-PERPETUAL.100ms","data":{"timestamp":1743963459264,"type":"change","change_id":41106217942,"instrument_name":"BTC-PERPETUAL","bids":[["delete",79908.5,0.0],["delete",79858.5,0.0]],"asks":[["delete",80233.5,0.0],["new",80252.5,80250.0],["delete",80283.5,0.0],["new",80302.5,120450.0]],"prev_change_id":41106216449}}}
[2025-04-06 23:47:38.656] [multi_sink] [info] Processing received message: {"jsonrpc":"2.0","method":"subscription","params":{"channel":"book.BTC-PERPETUAL.100ms","data":{"timestamp":1743963459264,"type":"change","change_id":41106217942,"instrument_name":"BTC-PERPETUAL","bids":[["delete",79908.5,0.0],["delete",79858.5,0.0]],"asks":[["delete",80233.5,0.0],["new",80252.5,80250.0],["delete",80283.5,0.0],["new",80302.5,120450.0]],"prev_change_id":41106216449}}}
[2025-04-06 23:47:38.656] [multi_sink] [error] Broadcast error: Operation canceled
[2025-04-06 23:47:38.983] [multi_sink] [info] 📩 Received: {"jsonrpc":"2.0","method":"subscription","params":{"channel":"book.BTC-PERPETUAL.100ms","data":{"timestamp":1743963459824,"type":"change","change_id":41106218716,"instrument_name":"BTC-PERPETUAL","bids":[],"asks":[["delete",80252.5,0.0],["delete",80302.5,0.0]],"prev_change_id":41106217942}}}
[2025-04-06 23:47:38.987] [multi_sink] [info] Processing received message: {"jsonrpc":"2.0","method":"subscription","params":{"channel":"book.BTC-PERPETUAL.100ms","data":{"timestamp":1743963459824,"type":"change","change_id":41106218716,"instrument_name":"BTC-PERPETUAL","bids":[],"asks":[["delete",80252.5,0.0],["delete",80302.5,0.0]],"prev_change_id":41106217942}}}
[2025-04-06 23:47:38.988] [multi_sink] [error] Broadcast error: Operation canceled
[2025-04-06 23:47:40.666] [multi_sink] [info] 📩 Received: {"jsonrpc":"2.0","method":"subscription","params":{"channel":"book.BTC-PERPETUAL.100ms","data":{"timestamp":1743963461274,"type":"change","change_id":41106220642,"instrument_name":"BTC-PERPETUAL","bids":[["new",79897.0,79890.0],["new",79847.0,119770.0]],"asks":[["new",80221.0,80220.0],["new",80271.0,1.204e5]],"prev_change_id":41106218716}}}
[2025-04-06 23:47:40.668] [multi_sink] [info] Processing received message: {"jsonrpc":"2.0","method":"subscription","params":{"channel":"book.BTC-PERPETUAL.100ms","data":{"timestamp":1743963461274,"type":"change","change_id":41106220642,"instrument_name":"BTC-PERPETUAL","bids":[["new",79897.0,79890.0],["new",79847.0,119770.0]],"asks":[["new",80221.0,80220.0],["new",80271.0,1.204e5]],"prev_change_id":41106218716}}}
[2025-04-06 23:47:40.669] [multi_sink] [error] Broadcast error: Operation canceled
[2025-04-06 23:47:41.345] [multi_sink] [info] 📩 Received: {"jsonrpc":"2.0","method":"subscription","params":{"channel":"book.BTC-PERPETUAL.100ms","data":{"timestamp":1743963462233,"type":"change","change_id":41106221936,"instrument_name":"BTC-PERPETUAL","bids":[["delete",80057.0,0.0],["delete",80055.0,0.0],["delete",80054.5,0.0],["delete",80052.5,0.0],["delete",80051.0,0.0],["delete",80050.0,0.0],["delete",80048.5,0.0],["change",80048.0,83430.0],["new",80047.5,1720.0],["new",80044.5,5750.0],["new",80043.5,70810.0],["new",80042.5,2310.0],["change",80040.5,1.662e5],["change",80040.0,171520.0]],"asks":[["change",80057.5,10.0],["delete",80058.0,0.0],["delete",80065.0,0.0],["delete",80071.0,0.0],["delete",80075.0,0.0],["delete",80075.5,0.0],["delete",80076.0,0.0],["delete",80076.5,0.0],["new",80083.0,4.0e4],["new",80083.5,9710.0],["new",80084.0,23390.0],["new",80084.5,34850.0],["change",80085.0,3.9e3],["new",80086.0,33420.0],["change",80086.5,17490.0],["new",80087.0,540.0]],"prev_change_id":41106220642}}}
[2025-04-06 23:47:41.346] [multi_sink] [info] Processing received message: {"jsonrpc":"2.0","method":"subscription","params":{"channel":"book.BTC-PERPETUAL.100ms","data":{"timestamp":1743963462233,"type":"change","change_id":41106221936,"instrument_name":"BTC-PERPETUAL","bids":[["delete",80057.0,0.0],["delete",80055.0,0.0],["delete",80054.5,0.0],["delete",80052.5,0.0],["delete",80051.0,0.0],["delete",80050.0,0.0],["delete",80048.5,0.0],["change",80048.0,83430.0],["new",80047.5,1720.0],["new",80044.5,5750.0],["new",80043.5,70810.0],["new",80042.5,2310.0],["change",80040.5,1.662e5],["change",80040.0,171520.0]],"asks":[["change",80057.5,10.0],["delete",80058.0,0.0],["delete",80065.0,0.0],["delete",80071.0,0.0],["delete",80075.0,0.0],["delete",80075.5,0.0],["delete",80076.0,0.0],["delete",80076.5,0.0],["new",80083.0,4.0e4],["new",80083.5,9710.0],["new",80084.0,23390.0],["new",80084.5,34850.0],["change",80085.0,3.9e3],["new",80086.0,33420.0],["change",80086.5,17490.0],["new",80087.0,540.0]],"prev_change_id":41106220642}}}
[2025-04-06 23:47:41.347] [multi_sink] [error] Broadcast error: Operation canceled
[2025-04-06 23:47:41.674] [multi_sink] [info] 📩 Received: {"jsonrpc":"2.0","method":"subscription","params":{"channel":"book.BTC-PERPETUAL.100ms","data":{"timestamp":1743963462553,"type":"change","change_id":41106222480,"instrument_name":"BTC-PERPETUAL","bids":[["new",80055.0,490.0],["new",80053.5,32970.0],["new",80053.0,540.0],["new",80052.0,18480.0],["new",80051.5,200.0],["new",80051.0,2.0e4],["new",80050.5,9980.0],["new",80049.0,9990.0],["new",80048.5,1.4e4],["change",80048.0,34850.0],["delete",80047.0,0.0],["delete",80044.0,0.0],["change",80040.5,8.31e4],["change",80040.0,161060.0],["delete",80039.5,0.0],["delete",80035.5,0.0],["delete",80035.0,0.0],["delete",80034.5,0.0],["new",79881.5,8.0085e6],["delete",79839.0,0.0]],"asks":[["new",80066.5,1450.0],["new",80074.5,10490.0],["new",80075.0,35520.0],["new",80075.5,4.13e4],["new",80076.0,35630.0],["new",80077.5,6660.0],["new",80079.0,5460.0],["new",80079.5,19420.0],["new",80081.0,18360.0],["delete",80081.5,0.0],["delete",80082.0,0.0],["delete",80082.5,0.0],["change",80085.0,410.0],["delete",80085.5,0.0],["change",80086.5,16490.0],["delete",80088.5,0.0],["delete",80089.0,0.0],["delete",80089.5,0.0]],"prev_change_id":41106221936}}}
[2025-04-06 23:47:41.676] [multi_sink] [info] Processing received message: {"jsonrpc":"2.0","method":"subscription","params":{"channel":"book.BTC-PERPETUAL.100ms","data":{"timestamp":1743963462553,"type":"change","change_id":41106222480,"instrument_name":"BTC-PERPETUAL","bids":[["new",80055.0,490.0],["new",80053.5,32970.0],["new",80053.0,540.0],["new",80052.0,18480.0],["new",80051.5,200.0],["new",80051.0,2.0e4],["new",80050.5,9980.0],["new",80049.0,9990.0],["new",80048.5,1.4e4],["change",80048.0,34850.0],["delete",80047.0,0.0],["delete",80044.0,0.0],["change",80040.5,8.31e4],["change",80040.0,161060.0],["delete",80039.5,0.0],["delete",80035.5,0.0],["delete",80035.0,0.0],["delete",80034.5,0.0],["new",79881.5,8.0085e6],["delete",79839.0,0.0]],"asks":[["new",80066.5,1450.0],["new",80074.5,10490.0],["new",80075.0,35520.0],["new",80075.5,4.13e4],["new",80076.0,35630.0],["new",80077.5,6660.0],["new",80079.0,5460.0],["new",80079.5,19420.0],["new",80081.0,18360.0],["delete",80081.5,0.0],["delete",80082.0,0.0],["delete",80082.5,0.0],["change",80085.0,410.0],["delete",80085.5,0.0],["change",80086.5,16490.0],["delete",80088.5,0.0],["delete",80089.0,0.0],["delete",80089.5,0.0]],"prev_change_id":41106221936}}}
[2025-04-06 23:47:41.678] [multi_sink] [error] Broadcast error: Operation canceled
[2025-04-06 23:47:42.005] [multi_sink] [info] 📩 Received: {"jsonrpc":"2.0","method":"subscription","params":{"channel":"book.BTC-PERPETUAL.100ms","data":{"timestamp":1743963462681,"type":"change","change_id":41106222598,"instrument_name":"BTC-PERPETUAL","bids":[["new",80059.5,9.01e4],["new",80058.5,10490.0],["new",80058.0,34980.0],["new",80056.0,10190.0],["delete",80033.0,0.0],["delete",80031.0,0.0],["delete",80030.0,0.0],["delete",80027.5,0.0]],"asks":[["delete",80057.5,0.0],["new",80060.0,46570.0],["new",80061.5,6980.0],["new",80062.0,23250.0],["delete",80090.0,0.0],["delete",80091.0,0.0],["delete",80091.5,0.0],["delete",80230.5,0.0],["new",80271.5,7777770.0]],"prev_change_id":41106222480}}}
[2025-04-06 23:47:42.007] [multi_sink] [info] Processing received message: {"jsonrpc":"2.0","method":"subscription","params":{"channel":"book.BTC-PERPETUAL.100ms","data":{"timestamp":1743963462681,"type":"change","change_id":41106222598,"instrument_name":"BTC-PERPETUAL","bids":[["new",80059.5,9.01e4],["new",80058.5,10490.0],["new",80058.0,34980.0],["new",80056.0,10190.0],["delete",80033.0,0.0],["delete",80031.0,0.0],["delete",80030.0,0.0],["delete",80027.5,0.0]],"asks":[["delete",80057.5,0.0],["new",80060.0,46570.0],["new",80061.5,6980.0],["new",80062.0,23250.0],["delete",80090.0,0.0],["delete",80091.0,0.0],["delete",80091.5,0.0],["delete",80230.5,0.0],["new",80271.5,7777770.0]],"prev_change_id":41106222480}}}
[2025-04-06 23:47:42.008] [multi_sink] [error] Broadcast error: Operation canceled
[2025-04-06 23:47:42.670] [multi_sink] [info] 📩 Received: {"jsonrpc":"2.0","method":"subscription","params":{"channel":"book.BTC-PERPETUAL.100ms","data":{"timestamp":1743963463542,"type":"change","change_id":41106224064,"instrument_name":"BTC-PERPETUAL","bids":[["new",79907.0,7.99e4],["delete",79897.0,0.0],["new",79857.0,119780.0],["delete",79847.0,0.0]],"asks":[["change",80060.0,46580.0],["delete",80221.0,0.0],["new",80232.5,80230.0],["delete",80271.0,0.0],["new",80282.5,120420.0]],"prev_change_id":41106222598}}}
[2025-04-06 23:47:42.670] [multi_sink] [info] Processing received message: {"jsonrpc":"2.0","method":"subscription","params":{"channel":"book.BTC-PERPETUAL.100ms","data":{"timestamp":1743963463542,"type":"change","change_id":41106224064,"instrument_name":"BTC-PERPETUAL","bids":[["new",79907.0,7.99e4],["delete",79897.0,0.0],["new",79857.0,119780.0],["delete",79847.0,0.0]],"asks":[["change",80060.0,46580.0],["delete",80221.0,0.0],["new",80232.5,80230.0],["delete",80271.0,0.0],["new",80282.5,120420.0]],"prev_change_id":41106222598}}}
[2025-04-06 23:47:42.671] [multi_sink] [error] Broadcast error: Operation canceled
[2025-04-06 23:47:42.996] [multi_sink] [info] 📩 Received: {"jsonrpc":"2.0","method":"subscription","params":{"channel":"book.BTC-PERPETUAL.100ms","data":{"timestamp":1743963463631,"type":"change","change_id":41106224073,"instrument_name":"BTC-PERPETUAL","bids":[["delete",79907.0,0.0],["delete",79857.0,0.0]],"asks":[["delete",80232.5,0.0],["new",80250.5,80250.0],["delete",80282.5,0.0],["new",80300.5,120450.0]],"prev_change_id":41106224064}}}
[2025-04-06 23:47:42.999] [multi_sink] [info] Processing received message: {"jsonrpc":"2.0","method":"subscription","params":{"channel":"book.BTC-PERPETUAL.100ms","data":{"timestamp":1743963463631,"type":"change","change_id":41106224073,"instrument_name":"BTC-PERPETUAL","bids":[["delete",79907.0,0.0],["delete",79857.0,0.0]],"asks":[["delete",80232.5,0.0],["new",80250.5,80250.0],["delete",80282.5,0.0],["new",80300.5,120450.0]],"prev_change_id":41106224064}}}
[2025-04-06 23:47:42.999] [multi_sink] [error] Broadcast error: Operation canceled
[2025-04-06 23:47:43.813] [multi_sink] [info] 📩 Received: {"jsonrpc":"2.0","method":"subscription","params":{"channel":"book.BTC-PERPETUAL.100ms","data":{"timestamp":1743963464706,"type":"change","change_id":41106225524,"instrument_name":"BTC-PERPETUAL","bids":[],"asks":[["delete",80250.5,0.0]],"prev_change_id":41106224073}}}
[2025-04-06 23:47:43.817] [multi_sink] [info] Processing received message: {"jsonrpc":"2.0","method":"subscription","params":{"channel":"book.BTC-PERPETUAL.100ms","data":{"timestamp":1743963464706,"type":"change","change_id":41106225524,"instrument_name":"BTC-PERPETUAL","bids":[],"asks":[["delete",80250.5,0.0]],"prev_change_id":41106224073}}}
[2025-04-06 23:47:43.818] [multi_sink] [error] Broadcast error: Operation canceled
[2025-04-06 23:47:44.147] [multi_sink] [info] 📩 Received: {"jsonrpc":"2.0","method":"subscription","params":{"channel":"book.BTC-PERPETUAL.100ms","data":{"timestamp":1743963464714,"type":"change","change_id":41106225627,"instrument_name":"BTC-PERPETUAL","bids":[],"asks":[["delete",80300.5,0.0]],"prev_change_id":41106225524}}}
[2025-04-06 23:47:44.147] [multi_sink] [info] Processing received message: {"jsonrpc":"2.0","method":"subscription","params":{"channel":"book.BTC-PERPETUAL.100ms","data":{"timestamp":1743963464714,"type":"change","change_id":41106225627,"instrument_name":"BTC-PERPETUAL","bids":[],"asks":[["delete",80300.5,0.0]],"prev_change_id":41106225524}}}
[2025-04-06 23:47:44.148] [multi_sink] [error] Broadcast error: Operation canceled
[2025-04-06 23:47:44.476] [multi_sink] [info] 📩 Received: {"jsonrpc":"2.0","method":"subscription","params":{"channel":"book.BTC-PERPETUAL.100ms","data":{"timestamp":1743963465226,"type":"change","change_id":41106226268,"instrument_name":"BTC-PERPETUAL","bids":[["new",80020.0,5821010.0],["change",80017.5,12650.0]],"asks":[],"prev_change_id":41106225627}}}
[2025-04-06 23:47:44.476] [multi_sink] [info] Processing received message: {"jsonrpc":"2.0","method":"subscription","params":{"channel":"book.BTC-PERPETUAL.100ms","data":{"timestamp":1743963465226,"type":"change","change_id":41106226268,"instrument_name":"BTC-PERPETUAL","bids":[["new",80020.0,5821010.0],["change",80017.5,12650.0]],"asks":[],"prev_change_id":41106225627}}}
[2025-04-06 23:47:44.477] [multi_sink] [error] Broadcast error: Operation canceled
[2025-04-06 23:47:44.808] [multi_sink] [info] 📩 Received: {"jsonrpc":"2.0","method":"subscription","params":{"channel":"book.BTC-PERPETUAL.100ms","data":{"timestamp":1743963465639,"type":"change","change_id":41106226778,"instrument_name":"BTC-PERPETUAL","bids":[["new",79940.5,79940.0],["new",79890.5,119830.0]],"asks":[["new",80270.0,80270.0],["new",80320.0,120480.0]],"prev_change_id":41106226268}}}
[2025-04-06 23:47:44.810] [multi_sink] [info] Processing received message: {"jsonrpc":"2.0","method":"subscription","params":{"channel":"book.BTC-PERPETUAL.100ms","data":{"timestamp":1743963465639,"type":"change","change_id":41106226778,"instrument_name":"BTC-PERPETUAL","bids":[["new",79940.5,79940.0],["new",79890.5,119830.0]],"asks":[["new",80270.0,80270.0],["new",80320.0,120480.0]],"prev_change_id":41106226268}}}
[2025-04-06 23:47:44.811] [multi_sink] [error] Broadcast error: Operation canceled
[2025-04-06 23:47:45.595] [multi_sink] [info] 📩 Received: {"jsonrpc":"2.0","method":"subscription","params":{"channel":"book.BTC-PERPETUAL.100ms","data":{"timestamp":1743963466486,"type":"change","change_id":41106228058,"instrument_name":"BTC-PERPETUAL","bids":[],"asks":[["delete",80270.0,0.0]],"prev_change_id":41106226778}}}
[2025-04-06 23:47:45.599] [multi_sink] [info] Processing received message: {"jsonrpc":"2.0","method":"subscription","params":{"channel":"book.BTC-PERPETUAL.100ms","data":{"timestamp":1743963466486,"type":"change","change_id":41106228058,"instrument_name":"BTC-PERPETUAL","bids":[],"asks":[["delete",80270.0,0.0]],"prev_change_id":41106226778}}}
[2025-04-06 23:47:45.600] [multi_sink] [error] Broadcast error: Operation canceled
[2025-04-06 23:47:45.923] [multi_sink] [info] 📩 Received: {"jsonrpc":"2.0","method":"subscription","params":{"channel":"book.BTC-PERPETUAL.100ms","data":{"timestamp":1743963466493,"type":"change","change_id":41106228215,"instrument_name":"BTC-PERPETUAL","bids":[],"asks":[["delete",80320.0,0.0]],"prev_change_id":41106228058}}}
[2025-04-06 23:47:45.925] [multi_sink] [info] Processing received message: {"jsonrpc":"2.0","method":"subscription","params":{"channel":"book.BTC-PERPETUAL.100ms","data":{"timestamp":1743963466493,"type":"change","change_id":41106228215,"instrument_name":"BTC-PERPETUAL","bids":[],"asks":[["delete",80320.0,0.0]],"prev_change_id":41106228058}}}
[2025-04-06 23:47:45.926] [multi_sink] [error] Broadcast error: Operation canceled
[2025-04-06 23:47:46.254] [multi_sink] [info] 📩 Received: {"jsonrpc":"2.0","method":"subscription","params":{"channel":"book.BTC-PERPETUAL.100ms","data":{"timestamp":1743963467136,"type":"change","change_id":41106229022,"instrument_name":"BTC-PERPETUAL","bids":[["delete",80059.5,0.0],["delete",80058.5,0.0],["delete",80058.0,0.0],["delete",80056.0,0.0],["delete",80055.0,0.0]],"asks":[["delete",80060.0,0.0],["delete",80061.5,0.0],["delete",80062.0,0.0],["delete",80066.5,0.0],["delete",80074.5,0.0],["delete",80075.0,0.0],["delete",80075.5,0.0],["delete",80076.0,0.0],["delete",80077.5,0.0],["change",80079.0,1280.0],["new",80135.0,6980.0]],"prev_change_id":41106228215}}}
[2025-04-06 23:47:46.258] [multi_sink] [info] Processing received message: {"jsonrpc":"2.0","method":"subscription","params":{"channel":"book.BTC-PERPETUAL.100ms","data":{"timestamp":1743963467136,"type":"change","change_id":41106229022,"instrument_name":"BTC-PERPETUAL","bids":[["delete",80059.5,0.0],["delete",80058.5,0.0],["delete",80058.0,0.0],["delete",80056.0,0.0],["delete",80055.0,0.0]],"asks":[["delete",80060.0,0.0],["delete",80061.5,0.0],["delete",80062.0,0.0],["delete",80066.5,0.0],["delete",80074.5,0.0],["delete",80075.0,0.0],["delete",80075.5,0.0],["delete",80076.0,0.0],["delete",80077.5,0.0],["change",80079.0,1280.0],["new",80135.0,6980.0]],"prev_change_id":41106228215}}}
[2025-04-06 23:47:46.258] [multi_sink] [error] Broadcast error: Operation canceled
[2025-04-06 23:47:46.585] [multi_sink] [info] 📩 Received: {"jsonrpc":"2.0","method":"subscription","params":{"channel":"book.BTC-PERPETUAL.100ms","data":{"timestamp":1743963467474,"type":"change","change_id":41106229307,"instrument_name":"BTC-PERPETUAL","bids":[["new",80095.5,16490.0],["new",80095.0,128160.0],["new",80094.5,102190.0],["delete",80053.5,0.0],["delete",80053.0,0.0],["delete",80052.0,0.0],["delete",80051.5,0.0],["delete",80051.0,0.0],["delete",80050.5,0.0],["delete",80049.0,0.0],["delete",80048.5,0.0],["delete",80048.0,0.0]],"asks":[["delete",80079.0,0.0],["delete",80079.5,0.0],["delete",80081.0,0.0],["delete",80083.0,0.0],["delete",80083.5,0.0],["delete",80084.0,0.0],["delete",80084.5,0.0],["delete",80085.0,0.0],["delete",80086.0,0.0],["delete",80086.5,0.0],["delete",80087.0,0.0]],"prev_change_id":41106229022}}}
[2025-04-06 23:47:46.589] [multi_sink] [info] Processing received message: {"jsonrpc":"2.0","method":"subscription","params":{"channel":"book.BTC-PERPETUAL.100ms","data":{"timestamp":1743963467474,"type":"change","change_id":41106229307,"instrument_name":"BTC-PERPETUAL","bids":[["new",80095.5,16490.0],["new",80095.0,128160.0],["new",80094.5,102190.0],["delete",80053.5,0.0],["delete",80053.0,0.0],["delete",80052.0,0.0],["delete",80051.5,0.0],["delete",80051.0,0.0],["delete",80050.5,0.0],["delete",80049.0,0.0],["delete",80048.5,0.0],["delete",80048.0,0.0]],"asks":[["delete",80079.0,0.0],["delete",80079.5,0.0],["delete",80081.0,0.0],["delete",80083.0,0.0],["delete",80083.5,0.0],["delete",80084.0,0.0],["delete",80084.5,0.0],["delete",80085.0,0.0],["delete",80086.0,0.0],["delete",80086.5,0.0],["delete",80087.0,0.0]],"prev_change_id":41106229022}}}
[2025-04-06 23:47:46.590] [multi_sink] [error] Broadcast error: Operation canceled
[2025-04-06 23:47:46.917] [multi_sink] [info] 📩 Received: {"jsonrpc":"2.0","method":"subscription","params":{"channel":"book.BTC-PERPETUAL.100ms","data":{"timestamp":1743963467705,"type":"change","change_id":41106229789,"instrument_name":"BTC-PERPETUAL","bids":[["new",80108.5,39760.0],["new",80103.5,4950.0],["new",80103.0,16470.0],["new",80098.5,4.12e4],["new",80098.0,4.12e4],["new",80097.5,41190.0],["delete",80047.5,0.0],["delete",80044.5,0.0],["delete",80043.5,0.0],["delete",80042.5,0.0],["delete",80040.5,0.0],["delete",80040.0,0.0]],"asks":[["delete",80105.0,0.0],["new",80278.0,80270.0],["new",80328.0,120490.0]],"prev_change_id":41106229307}}}
[2025-04-06 23:47:46.917] [multi_sink] [info] Processing received message: {"jsonrpc":"2.0","method":"subscription","params":{"channel":"book.BTC-PERPETUAL.100ms","data":{"timestamp":1743963467705,"type":"change","change_id":41106229789,"instrument_name":"BTC-PERPETUAL","bids":[["new",80108.5,39760.0],["new",80103.5,4950.0],["new",80103.0,16470.0],["new",80098.5,4.12e4],["new",80098.0,4.12e4],["new",80097.5,41190.0],["delete",80047.5,0.0],["delete",80044.5,0.0],["delete",80043.5,0.0],["delete",80042.5,0.0],["delete",80040.5,0.0],["delete",80040.0,0.0]],"asks":[["delete",80105.0,0.0],["new",80278.0,80270.0],["new",80328.0,120490.0]],"prev_change_id":41106229307}}}
[2025-04-06 23:47:46.918] [multi_sink] [error] Broadcast error: Operation canceled
[2025-04-06 23:47:47.246] [multi_sink] [info] 📩 Received: {"jsonrpc":"2.0","method":"subscription","params":{"channel":"book.BTC-PERPETUAL.100ms","data":{"timestamp":1743963467906,"type":"change","change_id":41106230175,"instrument_name":"BTC-PERPETUAL","bids":[],"asks":[["new",80109.0,10.0]],"prev_change_id":41106229789}}}
[2025-04-06 23:47:47.250] [multi_sink] [info] Processing received message: {"jsonrpc":"2.0","method":"subscription","params":{"channel":"book.BTC-PERPETUAL.100ms","data":{"timestamp":1743963467906,"type":"change","change_id":41106230175,"instrument_name":"BTC-PERPETUAL","bids":[],"asks":[["new",80109.0,10.0]],"prev_change_id":41106229789}}}
[2025-04-06 23:47:47.250] [multi_sink] [error] Broadcast error: Operation canceled
[2025-04-06 23:47:47.906] [multi_sink] [info] 📩 Received: {"jsonrpc":"2.0","method":"subscription","params":{"channel":"book.BTC-PERPETUAL.100ms","data":{"timestamp":1743963468716,"type":"change","change_id":41106231476,"instrument_name":"BTC-PERPETUAL","bids":[["new",80068.5,8440.0]],"asks":[],"prev_change_id":41106230175}}}
[2025-04-06 23:47:47.908] [multi_sink] [info] Processing received message: {"jsonrpc":"2.0","method":"subscription","params":{"channel":"book.BTC-PERPETUAL.100ms","data":{"timestamp":1743963468716,"type":"change","change_id":41106231476,"instrument_name":"BTC-PERPETUAL","bids":[["new",80068.5,8440.0]],"asks":[],"prev_change_id":41106230175}}}
[2025-04-06 23:47:47.909] [multi_sink] [error] Broadcast error: Operation canceled
[2025-04-06 23:47:48.163] [multi_sink] [info] 📩 Received: {"jsonrpc":"2.0","method":"subscription","params":{"channel":"book.BTC-PERPETUAL.100ms","data":{"timestamp":1743963468762,"type":"change","change_id":41106231566,"instrument_name":"BTC-PERPETUAL","bids":[["new",79950.5,79950.0],["delete",79940.5,0.0],["new",79900.5,119850.0],["delete",79890.5,0.0]],"asks":[],"prev_change_id":41106231476}}}
[2025-04-06 23:47:48.167] [multi_sink] [info] Processing received message: {"jsonrpc":"2.0","method":"subscription","params":{"channel":"book.BTC-PERPETUAL.100ms","data":{"timestamp":1743963468762,"type":"change","change_id":41106231566,"instrument_name":"BTC-PERPETUAL","bids":[["new",79950.5,79950.0],["delete",79940.5,0.0],["new",79900.5,119850.0],["delete",79890.5,0.0]],"asks":[],"prev_change_id":41106231476}}}
[2025-04-06 23:47:48.167] [multi_sink] [error] Broadcast error: Operation canceled
[2025-04-06 23:47:48.522] [multi_sink] [info] 📩 Received: {"jsonrpc":"2.0","method":"subscription","params":{"channel":"book.BTC-PERPETUAL.100ms","data":{"timestamp":1743963469316,"type":"change","change_id":41106232354,"instrument_name":"BTC-PERPETUAL","bids":[["change",80068.5,16880.0]],"asks":[],"prev_change_id":41106231566}}}
[2025-04-06 23:47:48.527] [multi_sink] [info] Processing received message: {"jsonrpc":"2.0","method":"subscription","params":{"channel":"book.BTC-PERPETUAL.100ms","data":{"timestamp":1743963469316,"type":"change","change_id":41106232354,"instrument_name":"BTC-PERPETUAL","bids":[["change",80068.5,16880.0]],"asks":[],"prev_change_id":41106231566}}}
[2025-04-06 23:47:48.528] [multi_sink] [error] Broadcast error: Operation canceled
[2025-04-06 23:47:49.151] [multi_sink] [info] 📩 Received: {"jsonrpc":"2.0","method":"subscription","params":{"channel":"book.BTC-PERPETUAL.100ms","data":{"timestamp":1743963469982,"type":"change","change_id":41106233424,"instrument_name":"BTC-PERPETUAL","bids":[["new",79912.5,8.0085e6],["delete",79881.5,0.0]],"asks":[],"prev_change_id":41106232354}}}
[2025-04-06 23:47:49.153] [multi_sink] [info] Processing received message: {"jsonrpc":"2.0","method":"subscription","params":{"channel":"book.BTC-PERPETUAL.100ms","data":{"timestamp":1743963469982,"type":"change","change_id":41106233424,"instrument_name":"BTC-PERPETUAL","bids":[["new",79912.5,8.0085e6],["delete",79881.5,0.0]],"asks":[],"prev_change_id":41106232354}}}
[2025-04-06 23:47:49.154] [multi_sink] [error] Broadcast error: Operation canceled
[2025-04-06 23:47:49.544] [multi_sink] [info] 📩 Received: {"jsonrpc":"2.0","method":"subscription","params":{"channel":"book.BTC-PERPETUAL.100ms","data":{"timestamp":1743963470409,"type":"change","change_id":41106233687,"instrument_name":"BTC-PERPETUAL","bids":[],"asks":[["delete",80271.5,0.0],["new",80305.0,7777770.0]],"prev_change_id":41106233424}}}
[2025-04-06 23:47:49.546] [multi_sink] [info] Processing received message: {"jsonrpc":"2.0","method":"subscription","params":{"channel":"book.BTC-PERPETUAL.100ms","data":{"timestamp":1743963470409,"type":"change","change_id":41106233687,"instrument_name":"BTC-PERPETUAL","bids":[],"asks":[["delete",80271.5,0.0],["new",80305.0,7777770.0]],"prev_change_id":41106233424}}}
[2025-04-06 23:47:49.547] [multi_sink] [error] Broadcast error: Operation canceled
[2025-04-06 23:47:49.955] [multi_sink] [info] 📩 Received: {"jsonrpc":"2.0","method":"subscription","params":{"channel":"book.BTC-PERPETUAL.100ms","data":{"timestamp":1743963470656,"type":"change","change_id":41106233994,"instrument_name":"BTC-PERPETUAL","bids":[],"asks":[["delete",80278.0,0.0],["new",80290.5,80290.0],["delete",80328.0,0.0],["new",80340.5,120510.0]],"prev_change_id":41106233687}}}
[2025-04-06 23:47:49.957] [multi_sink] [info] Processing received message: {"jsonrpc":"2.0","method":"subscription","params":{"channel":"book.BTC-PERPETUAL.100ms","data":{"timestamp":1743963470656,"type":"change","change_id":41106233994,"instrument_name":"BTC-PERPETUAL","bids":[],"asks":[["delete",80278.0,0.0],["new",80290.5,80290.0],["delete",80328.0,0.0],["new",80340.5,120510.0]],"prev_change_id":41106233687}}}
[2025-04-06 23:47:49.958] [multi_sink] [error] Broadcast error: Operation canceled
[2025-04-06 23:47:50.177] [multi_sink] [info] 📩 Received: {"jsonrpc":"2.0","method":"subscription","params":{"channel":"book.BTC-PERPETUAL.100ms","data":{"timestamp":1743963470817,"type":"change","change_id":41106234311,"instrument_name":"BTC-PERPETUAL","bids":[["change",80068.5,25320.0],["new",79962.0,79960.0],["delete",79950.5,0.0],["new",79912.0,119860.0],["delete",79900.5,0.0]],"asks":[],"prev_change_id":41106233994}}}
[2025-04-06 23:47:50.178] [multi_sink] [info] Processing received message: {"jsonrpc":"2.0","method":"subscription","params":{"channel":"book.BTC-PERPETUAL.100ms","data":{"timestamp":1743963470817,"type":"change","change_id":41106234311,"instrument_name":"BTC-PERPETUAL","bids":[["change",80068.5,25320.0],["new",79962.0,79960.0],["delete",79950.5,0.0],["new",79912.0,119860.0],["delete",79900.5,0.0]],"asks":[],"prev_change_id":41106233994}}}
[2025-04-06 23:47:50.179] [multi_sink] [error] Broadcast error: Operation canceled
[2025-04-06 23:47:51.415] [multi_sink] [info] 📩 Received: {"jsonrpc":"2.0","method":"subscription","params":{"channel":"book.BTC-PERPETUAL.100ms","data":{"timestamp":1743963472279,"type":"change","change_id":41106236323,"instrument_name":"BTC-PERPETUAL","bids":[["new",80109.0,13890.0],["change",80108.5,36020.0],["new",80107.5,24930.0],["new",80107.0,83090.0],["change",80103.5,11470.0],["change",80103.0,2990.0],["new",8.01e4,91010.0],["new",80099.0,27970.0],["change",80098.5,197070.0],["delete",80098.0,0.0],["delete",80097.5,0.0],["delete",80095.5,0.0],["delete",80095.0,0.0],["delete",80094.5,0.0]],"asks":[["delete",80109.0,0.0],["delete",80135.0,0.0],["new",80148.5,150.0],["new",80149.0,38610.0],["new",80150.0,35170.0],["new",80151.0,200.0],["new",80152.0,89530.0],["new",80152.5,30620.0],["new",80153.0,13810.0],["new",80154.0,16490.0],["new",80154.5,79120.0]],"prev_change_id":41106234311}}}
[2025-04-06 23:47:51.418] [multi_sink] [info] Processing received message: {"jsonrpc":"2.0","method":"subscription","params":{"channel":"book.BTC-PERPETUAL.100ms","data":{"timestamp":1743963472279,"type":"change","change_id":41106236323,"instrument_name":"BTC-PERPETUAL","bids":[["new",80109.0,13890.0],["change",80108.5,36020.0],["new",80107.5,24930.0],["new",80107.0,83090.0],["change",80103.5,11470.0],["change",80103.0,2990.0],["new",8.01e4,91010.0],["new",80099.0,27970.0],["change",80098.5,197070.0],["delete",80098.0,0.0],["delete",80097.5,0.0],["delete",80095.5,0.0],["delete",80095.0,0.0],["delete",80094.5,0.0]],"asks":[["delete",80109.0,0.0],["delete",80135.0,0.0],["new",80148.5,150.0],["new",80149.0,38610.0],["new",80150.0,35170.0],["new",80151.0,200.0],["new",80152.0,89530.0],["new",80152.5,30620.0],["new",80153.0,13810.0],["new",80154.0,16490.0],["new",80154.5,79120.0]],"prev_change_id":41106234311}}}
[2025-04-06 23:47:51.419] [multi_sink] [error] Broadcast error: Operation canceled
[2025-04-06 23:47:51.743] [multi_sink] [info] 📩 Received: {"jsonrpc":"2.0","method":"subscription","params":{"channel":"book.BTC-PERPETUAL.100ms","data":{"timestamp":1743963472621,"type":"change","change_id":41106236848,"instrument_name":"BTC-PERPETUAL","bids":[["new",80120.5,16490.0],["new",80117.0,45230.0],["new",80116.0,25750.0],["new",80115.5,35380.0],["new",80115.0,4.11e4],["new",80114.5,3.5e4],["new",80110.5,80480.0],["new",80110.0,150030.0],["new",80109.5,4.11e4]],"asks":[["new",80121.0,10.0],["new",80136.5,10410.0],["new",80137.0,34690.0],["new",80141.0,490.0],["new",80141.5,5450.0],["new",80142.0,19360.0],["new",80145.5,20870.0],["new",80146.0,19360.0],["new",80146.5,5750.0],["new",80147.5,5090.0]],"prev_change_id":41106236323}}}
[2025-04-06 23:47:51.748] [multi_sink] [info] Processing received message: {"jsonrpc":"2.0","method":"subscription","params":{"channel":"book.BTC-PERPETUAL.100ms","data":{"timestamp":1743963472621,"type":"change","change_id":41106236848,"instrument_name":"BTC-PERPETUAL","bids":[["new",80120.5,16490.0],["new",80117.0,45230.0],["new",80116.0,25750.0],["new",80115.5,35380.0],["new",80115.0,4.11e4],["new",80114.5,3.5e4],["new",80110.5,80480.0],["new",80110.0,150030.0],["new",80109.5,4.11e4]],"asks":[["new",80121.0,10.0],["new",80136.5,10410.0],["new",80137.0,34690.0],["new",80141.0,490.0],["new",80141.5,5450.0],["new",80142.0,19360.0],["new",80145.5,20870.0],["new",80146.0,19360.0],["new",80146.5,5750.0],["new",80147.5,5090.0]],"prev_change_id":41106236323}}}
[2025-04-06 23:47:51.749] [multi_sink] [error] Broadcast error: Operation canceled
[2025-04-06 23:47:52.074] [multi_sink] [info] 📩 Received: {"jsonrpc":"2.0","method":"subscription","params":{"channel":"book.BTC-PERPETUAL.100ms","data":{"timestamp":1743963472941,"type":"change","change_id":41106237341,"instrument_name":"BTC-PERPETUAL","bids":[["new",80122.0,237460.0],["new",80121.0,21280.0],["new",80070.0,5821010.0],["delete",80020.0,0.0]],"asks":[["delete",80121.0,0.0],["new",80122.5,19840.0],["new",80125.0,320.0]],"prev_change_id":41106236848}}}
[2025-04-06 23:47:52.079] [multi_sink] [info] Processing received message: {"jsonrpc":"2.0","method":"subscription","params":{"channel":"book.BTC-PERPETUAL.100ms","data":{"timestamp":1743963472941,"type":"change","change_id":41106237341,"instrument_name":"BTC-PERPETUAL","bids":[["new",80122.0,237460.0],["new",80121.0,21280.0],["new",80070.0,5821010.0],["delete",80020.0,0.0]],"asks":[["delete",80121.0,0.0],["new",80122.5,19840.0],["new",80125.0,320.0]],"prev_change_id":41106236848}}}
[2025-04-06 23:47:52.079] [multi_sink] [error] Broadcast error: Operation canceled
[2025-04-06 23:47:53.825] [multi_sink] [info] 📩 Received: {"jsonrpc":"2.0","method":"subscription","params":{"channel":"book.BTC-PERPETUAL.100ms","data":{"timestamp":1743963474719,"type":"change","change_id":41106239916,"instrument_name":"BTC-PERPETUAL","bids":[["delete",79962.0,0.0],["new",79951.0,79950.0]],"asks":[],"prev_change_id":41106237341}}}
[2025-04-06 23:47:53.826] [multi_sink] [info] Processing received message: {"jsonrpc":"2.0","method":"subscription","params":{"channel":"book.BTC-PERPETUAL.100ms","data":{"timestamp":1743963474719,"type":"change","change_id":41106239916,"instrument_name":"BTC-PERPETUAL","bids":[["delete",79962.0,0.0],["new",79951.0,79950.0]],"asks":[],"prev_change_id":41106237341}}}
[2025-04-06 23:47:53.827] [multi_sink] [error] Broadcast error: Operation canceled
[2025-04-06 23:47:54.156] [multi_sink] [info] 📩 Received: {"jsonrpc":"2.0","method":"subscription","params":{"channel":"book.BTC-PERPETUAL.100ms","data":{"timestamp":1743963474730,"type":"change","change_id":41106239988,"instrument_name":"BTC-PERPETUAL","bids":[["delete",79912.0,0.0],["new",79901.0,119850.0]],"asks":[["new",80280.0,80280.0],["delete",80290.5,0.0],["new",80330.0,120490.0],["delete",80340.5,0.0]],"prev_change_id":41106239916}}}
[2025-04-06 23:47:54.161] [multi_sink] [info] Processing received message: {"jsonrpc":"2.0","method":"subscription","params":{"channel":"book.BTC-PERPETUAL.100ms","data":{"timestamp":1743963474730,"type":"change","change_id":41106239988,"instrument_name":"BTC-PERPETUAL","bids":[["delete",79912.0,0.0],["new",79901.0,119850.0]],"asks":[["new",80280.0,80280.0],["delete",80290.5,0.0],["new",80330.0,120490.0],["delete",80340.5,0.0]],"prev_change_id":41106239916}}}
[2025-04-06 23:47:54.162] [multi_sink] [error] Broadcast error: Operation canceled
[2025-04-06 23:47:54.488] [multi_sink] [info] 📩 Received: {"jsonrpc":"2.0","method":"subscription","params":{"channel":"book.BTC-PERPETUAL.100ms","data":{"timestamp":1743963475223,"type":"change","change_id":41106240644,"instrument_name":"BTC-PERPETUAL","bids":[["delete",79951.0,0.0],["delete",79901.0,0.0]],"asks":[["new",80269.5,80270.0],["delete",80280.0,0.0],["new",80319.5,120480.0],["delete",80330.0,0.0]],"prev_change_id":41106239988}}}
[2025-04-06 23:47:54.491] [multi_sink] [info] Processing received message: {"jsonrpc":"2.0","method":"subscription","params":{"channel":"book.BTC-PERPETUAL.100ms","data":{"timestamp":1743963475223,"type":"change","change_id":41106240644,"instrument_name":"BTC-PERPETUAL","bids":[["delete",79951.0,0.0],["delete",79901.0,0.0]],"asks":[["new",80269.5,80270.0],["delete",80280.0,0.0],["new",80319.5,120480.0],["delete",80330.0,0.0]],"prev_change_id":41106239988}}}
[2025-04-06 23:47:54.492] [multi_sink] [error] Broadcast error: Operation canceled
[2025-04-06 23:47:54.819] [multi_sink] [info] 📩 Received: {"jsonrpc":"2.0","method":"subscription","params":{"channel":"book.BTC-PERPETUAL.100ms","data":{"timestamp":1743963475683,"type":"change","change_id":41106241139,"instrument_name":"BTC-PERPETUAL","bids":[],"asks":[["delete",80269.5,0.0],["delete",80319.5,0.0]],"prev_change_id":41106240644}}}
[2025-04-06 23:47:54.821] [multi_sink] [info] Processing received message: {"jsonrpc":"2.0","method":"subscription","params":{"channel":"book.BTC-PERPETUAL.100ms","data":{"timestamp":1743963475683,"type":"change","change_id":41106241139,"instrument_name":"BTC-PERPETUAL","bids":[],"asks":[["delete",80269.5,0.0],["delete",80319.5,0.0]],"prev_change_id":41106240644}}}
[2025-04-06 23:47:54.822] [multi_sink] [error] Broadcast error: Operation canceled
[2025-04-06 23:47:56.098] [multi_sink] [info] 📩 Received: {"jsonrpc":"2.0","method":"subscription","params":{"channel":"book.BTC-PERPETUAL.100ms","data":{"timestamp":1743963476990,"type":"change","change_id":41106242831,"instrument_name":"BTC-PERPETUAL","bids":[["change",80122.0,218140.0]],"asks":[["change",80122.5,10.0]],"prev_change_id":41106241139}}}
[2025-04-06 23:47:56.103] [multi_sink] [info] Processing received message: {"jsonrpc":"2.0","method":"subscription","params":{"channel":"book.BTC-PERPETUAL.100ms","data":{"timestamp":1743963476990,"type":"change","change_id":41106242831,"instrument_name":"BTC-PERPETUAL","bids":[["change",80122.0,218140.0]],"asks":[["change",80122.5,10.0]],"prev_change_id":41106241139}}}
[2025-04-06 23:47:56.104] [multi_sink] [error] Broadcast error: Operation canceled
[2025-04-06 23:47:56.427] [multi_sink] [info] 📩 Received: {"jsonrpc":"2.0","method":"subscription","params":{"channel":"book.BTC-PERPETUAL.100ms","data":{"timestamp":1743963477317,"type":"change","change_id":41106243599,"instrument_name":"BTC-PERPETUAL","bids":[["delete",80122.0,0.0],["delete",80121.0,0.0],["delete",80120.5,0.0],["delete",80117.0,0.0],["delete",80116.0,0.0],["delete",80115.5,0.0],["delete",80115.0,0.0],["delete",80114.5,0.0],["delete",80110.5,0.0],["delete",80110.0,0.0],["new",79911.5,79910.0],["new",79861.5,119790.0]],"asks":[["delete",80125.0,0.0],["delete",80136.5,0.0],["delete",80137.0,0.0],["delete",80141.0,0.0],["delete",80141.5,0.0],["delete",80142.0,0.0],["delete",80145.5,0.0],["delete",80146.0,0.0],["new",80242.5,80240.0],["new",80292.5,120430.0]],"prev_change_id":41106242831}}}
[2025-04-06 23:47:56.428] [multi_sink] [info] Processing received message: {"jsonrpc":"2.0","method":"subscription","params":{"channel":"book.BTC-PERPETUAL.100ms","data":{"timestamp":1743963477317,"type":"change","change_id":41106243599,"instrument_name":"BTC-PERPETUAL","bids":[["delete",80122.0,0.0],["delete",80121.0,0.0],["delete",80120.5,0.0],["delete",80117.0,0.0],["delete",80116.0,0.0],["delete",80115.5,0.0],["delete",80115.0,0.0],["delete",80114.5,0.0],["delete",80110.5,0.0],["delete",80110.0,0.0],["new",79911.5,79910.0],["new",79861.5,119790.0]],"asks":[["delete",80125.0,0.0],["delete",80136.5,0.0],["delete",80137.0,0.0],["delete",80141.0,0.0],["delete",80141.5,0.0],["delete",80142.0,0.0],["delete",80145.5,0.0],["delete",80146.0,0.0],["new",80242.5,80240.0],["new",80292.5,120430.0]],"prev_change_id":41106242831}}}
[2025-04-06 23:47:56.429] [multi_sink] [error] Broadcast error: Operation canceled
[2025-04-06 23:47:56.761] [multi_sink] [info] 📩 Received: {"jsonrpc":"2.0","method":"subscription","params":{"channel":"book.BTC-PERPETUAL.100ms","data":{"timestamp":1743963477637,"type":"change","change_id":41106243980,"instrument_name":"BTC-PERPETUAL","bids":[["delete",80109.5,0.0],["delete",80109.0,0.0],["delete",80108.5,0.0],["delete",80107.5,0.0],["delete",80107.0,0.0],["delete",80103.5,0.0],["delete",80103.0,0.0],["delete",8.01e4,0.0],["delete",80099.0,0.0],["change",80098.5,196250.0],["new",80072.5,10870.0],["new",80067.0,4670.0],["delete",79911.5,0.0],["delete",79861.5,0.0]],"asks":[["delete",80146.5,0.0],["delete",80147.5,0.0],["delete",80148.5,0.0],["delete",80149.0,0.0],["delete",80150.0,0.0],["delete",80151.0,0.0],["delete",80152.0,0.0],["delete",80152.5,0.0],["delete",80153.0,0.0],["delete",80242.5,0.0],["delete",80292.5,0.0]],"prev_change_id":41106243599}}}
[2025-04-06 23:47:56.763] [multi_sink] [info] Processing received message: {"jsonrpc":"2.0","method":"subscription","params":{"channel":"book.BTC-PERPETUAL.100ms","data":{"timestamp":1743963477637,"type":"change","change_id":41106243980,"instrument_name":"BTC-PERPETUAL","bids":[["delete",80109.5,0.0],["delete",80109.0,0.0],["delete",80108.5,0.0],["delete",80107.5,0.0],["delete",80107.0,0.0],["delete",80103.5,0.0],["delete",80103.0,0.0],["delete",8.01e4,0.0],["delete",80099.0,0.0],["change",80098.5,196250.0],["new",80072.5,10870.0],["new",80067.0,4670.0],["delete",79911.5,0.0],["delete",79861.5,0.0]],"asks":[["delete",80146.5,0.0],["delete",80147.5,0.0],["delete",80148.5,0.0],["delete",80149.0,0.0],["delete",80150.0,0.0],["delete",80151.0,0.0],["delete",80152.0,0.0],["delete",80152.5,0.0],["delete",80153.0,0.0],["delete",80242.5,0.0],["delete",80292.5,0.0]],"prev_change_id":41106243599}}}
[2025-04-06 23:47:56.764] [multi_sink] [error] Broadcast error: Operation canceled
[2025-04-06 23:47:57.087] [multi_sink] [info] 📩 Received: {"jsonrpc":"2.0","method":"subscription","params":{"channel":"book.BTC-PERPETUAL.100ms","data":{"timestamp":1743963477875,"type":"change","change_id":41106244444,"instrument_name":"BTC-PERPETUAL","bids":[["delete",80098.5,0.0],["new",80077.5,30420.0],["delete",79912.5,0.0],["new",79897.0,8.0085e6]],"asks":[["new",80078.0,3.99e4],["delete",80154.0,0.0],["delete",80154.5,0.0]],"prev_change_id":41106243980}}}
[2025-04-06 23:47:57.090] [multi_sink] [info] Processing received message: {"jsonrpc":"2.0","method":"subscription","params":{"channel":"book.BTC-PERPETUAL.100ms","data":{"timestamp":1743963477875,"type":"change","change_id":41106244444,"instrument_name":"BTC-PERPETUAL","bids":[["delete",80098.5,0.0],["new",80077.5,30420.0],["delete",79912.5,0.0],["new",79897.0,8.0085e6]],"asks":[["new",80078.0,3.99e4],["delete",80154.0,0.0],["delete",80154.5,0.0]],"prev_change_id":41106243980}}}
[2025-04-06 23:47:57.091] [multi_sink] [error] Broadcast error: Operation canceled
[2025-04-06 23:47:57.427] [multi_sink] [info] 📩 Received: {"jsonrpc":"2.0","method":"subscription","params":{"channel":"book.BTC-PERPETUAL.100ms","data":{"timestamp":1743963478263,"type":"change","change_id":41106245082,"instrument_name":"BTC-PERPETUAL","bids":[],"asks":[["delete",80122.5,0.0]],"prev_change_id":41106244444}}}
[2025-04-06 23:47:57.431] [multi_sink] [info] Processing received message: {"jsonrpc":"2.0","method":"subscription","params":{"channel":"book.BTC-PERPETUAL.100ms","data":{"timestamp":1743963478263,"type":"change","change_id":41106245082,"instrument_name":"BTC-PERPETUAL","bids":[],"asks":[["delete",80122.5,0.0]],"prev_change_id":41106244444}}}
[2025-04-06 23:47:57.431] [multi_sink] [error] Broadcast error: Operation canceled
[2025-04-06 23:47:57.747] [multi_sink] [info] 📩 Received: {"jsonrpc":"2.0","method":"subscription","params":{"channel":"book.BTC-PERPETUAL.100ms","data":{"timestamp":1743963478565,"type":"change","change_id":41106245569,"instrument_name":"BTC-PERPETUAL","bids":[],"asks":[["change",80078.0,39910.0]],"prev_change_id":41106245082}}}
[2025-04-06 23:47:57.751] [multi_sink] [info] Processing received message: {"jsonrpc":"2.0","method":"subscription","params":{"channel":"book.BTC-PERPETUAL.100ms","data":{"timestamp":1743963478565,"type":"change","change_id":41106245569,"instrument_name":"BTC-PERPETUAL","bids":[],"asks":[["change",80078.0,39910.0]],"prev_change_id":41106245082}}}
[2025-04-06 23:47:57.752] [multi_sink] [error] Broadcast error: Operation canceled
[2025-04-06 23:47:58.078] [multi_sink] [info] 📩 Received: {"jsonrpc":"2.0","method":"subscription","params":{"channel":"book.BTC-PERPETUAL.100ms","data":{"timestamp":1743963478705,"type":"change","change_id":41106245661,"instrument_name":"BTC-PERPETUAL","bids":[],"asks":[["new",80288.5,7777770.0],["delete",80305.0,0.0]],"prev_change_id":41106245569}}}
[2025-04-06 23:47:58.081] [multi_sink] [info] Processing received message: {"jsonrpc":"2.0","method":"subscription","params":{"channel":"book.BTC-PERPETUAL.100ms","data":{"timestamp":1743963478705,"type":"change","change_id":41106245661,"instrument_name":"BTC-PERPETUAL","bids":[],"asks":[["new",80288.5,7777770.0],["delete",80305.0,0.0]],"prev_change_id":41106245569}}}
[2025-04-06 23:47:58.082] [multi_sink] [error] Broadcast error: Operation canceled
[2025-04-06 23:47:58.409] [multi_sink] [info] 📩 Received: {"jsonrpc":"2.0","method":"subscription","params":{"channel":"book.BTC-PERPETUAL.100ms","data":{"timestamp":1743963479246,"type":"change","change_id":41106246560,"instrument_name":"BTC-PERPETUAL","bids":[],"asks":[["new",80239.0,80230.0],["new",80289.0,120420.0]],"prev_change_id":41106245661}}}
[2025-04-06 23:47:58.413] [multi_sink] [info] Processing received message: {"jsonrpc":"2.0","method":"subscription","params":{"channel":"book.BTC-PERPETUAL.100ms","data":{"timestamp":1743963479246,"type":"change","change_id":41106246560,"instrument_name":"BTC-PERPETUAL","bids":[],"asks":[["new",80239.0,80230.0],["new",80289.0,120420.0]],"prev_change_id":41106245661}}}
[2025-04-06 23:47:58.414] [multi_sink] [error] Broadcast error: Operation canceled
[2025-04-06 23:47:58.738] [multi_sink] [info] 📩 Received: {"jsonrpc":"2.0","method":"subscription","params":{"channel":"book.BTC-PERPETUAL.100ms","data":{"timestamp":1743963479595,"type":"change","change_id":41106247064,"instrument_name":"BTC-PERPETUAL","bids":[["new",79906.5,7.99e4],["new",79856.5,119780.0]],"asks":[],"prev_change_id":41106246560}}}
[2025-04-06 23:47:58.741] [multi_sink] [info] Processing received message: {"jsonrpc":"2.0","method":"subscription","params":{"channel":"book.BTC-PERPETUAL.100ms","data":{"timestamp":1743963479595,"type":"change","change_id":41106247064,"instrument_name":"BTC-PERPETUAL","bids":[["new",79906.5,7.99e4],["new",79856.5,119780.0]],"asks":[],"prev_change_id":41106246560}}}
[2025-04-06 23:47:58.742] [multi_sink] [error] Broadcast error: Operation canceled
[2025-04-06 23:47:59.471] [multi_sink] [info] 📩 Received: {"jsonrpc":"2.0","method":"subscription","params":{"channel":"book.BTC-PERPETUAL.100ms","data":{"timestamp":1743963480297,"type":"change","change_id":41106247978,"instrument_name":"BTC-PERPETUAL","bids":[["delete",80070.0,0.0],["new",80030.5,5821010.0]],"asks":[],"prev_change_id":41106247064}}}
[2025-04-06 23:47:59.475] [multi_sink] [info] Processing received message: {"jsonrpc":"2.0","method":"subscription","params":{"channel":"book.BTC-PERPETUAL.100ms","data":{"timestamp":1743963480297,"type":"change","change_id":41106247978,"instrument_name":"BTC-PERPETUAL","bids":[["delete",80070.0,0.0],["new",80030.5,5821010.0]],"asks":[],"prev_change_id":41106247064}}}
[2025-04-06 23:47:59.475] [multi_sink] [error] Broadcast error: Operation canceled
[2025-04-06 23:48:00.132] [multi_sink] [info] 📩 Received: {"jsonrpc":"2.0","method":"subscription","params":{"channel":"book.BTC-PERPETUAL.100ms","data":{"timestamp":1743963480857,"type":"change","change_id":41106248821,"instrument_name":"BTC-PERPETUAL","bids":[],"asks":[["new",80228.0,80220.0],["delete",80239.0,0.0],["new",80278.0,120410.0],["delete",80289.0,0.0]],"prev_change_id":41106247978}}}
[2025-04-06 23:48:00.133] [multi_sink] [info] Processing received message: {"jsonrpc":"2.0","method":"subscription","params":{"channel":"book.BTC-PERPETUAL.100ms","data":{"timestamp":1743963480857,"type":"change","change_id":41106248821,"instrument_name":"BTC-PERPETUAL","bids":[],"asks":[["new",80228.0,80220.0],["delete",80239.0,0.0],["new",80278.0,120410.0],["delete",80289.0,0.0]],"prev_change_id":41106247978}}}
[2025-04-06 23:48:00.134] [multi_sink] [error] Broadcast error: Operation canceled
[2025-04-06 23:48:00.463] [multi_sink] [info] 📩 Received: {"jsonrpc":"2.0","method":"subscription","params":{"channel":"book.BTC-PERPETUAL.100ms","data":{"timestamp":1743963481348,"type":"change","change_id":41106249426,"instrument_name":"BTC-PERPETUAL","bids":[],"asks":[["delete",80228.0,0.0],["new",80240.0,80240.0],["delete",80278.0,0.0],["new",80290.0,120430.0]],"prev_change_id":41106248821}}}
[2025-04-06 23:48:00.465] [multi_sink] [info] Processing received message: {"jsonrpc":"2.0","method":"subscription","params":{"channel":"book.BTC-PERPETUAL.100ms","data":{"timestamp":1743963481348,"type":"change","change_id":41106249426,"instrument_name":"BTC-PERPETUAL","bids":[],"asks":[["delete",80228.0,0.0],["new",80240.0,80240.0],["delete",80278.0,0.0],["new",80290.0,120430.0]],"prev_change_id":41106248821}}}
[2025-04-06 23:48:00.465] [multi_sink] [error] Broadcast error: Operation canceled
[2025-04-06 23:48:01.124] [multi_sink] [info] 📩 Received: {"jsonrpc":"2.0","method":"subscription","params":{"channel":"book.BTC-PERPETUAL.100ms","data":{"timestamp":1743963481994,"type":"change","change_id":41106250124,"instrument_name":"BTC-PERPETUAL","bids":[["delete",80077.5,0.0]],"asks":[["change",80078.0,10.0],["new",80097.5,7140.0]],"prev_change_id":41106249426}}}
[2025-04-06 23:48:01.127] [multi_sink] [info] Processing received message: {"jsonrpc":"2.0","method":"subscription","params":{"channel":"book.BTC-PERPETUAL.100ms","data":{"timestamp":1743963481994,"type":"change","change_id":41106250124,"instrument_name":"BTC-PERPETUAL","bids":[["delete",80077.5,0.0]],"asks":[["change",80078.0,10.0],["new",80097.5,7140.0]],"prev_change_id":41106249426}}}
[2025-04-06 23:48:01.127] [multi_sink] [error] Broadcast error: Operation canceled
[2025-04-06 23:48:01.454] [multi_sink] [info] 📩 Received: {"jsonrpc":"2.0","method":"subscription","params":{"channel":"book.BTC-PERPETUAL.100ms","data":{"timestamp":1743963482331,"type":"change","change_id":41106250769,"instrument_name":"BTC-PERPETUAL","bids":[["delete",80072.5,0.0],["delete",80067.0,0.0],["new",80056.5,35160.0],["new",80056.0,1.5e5],["new",80053.0,24930.0],["new",80052.5,8.31e4],["new",80051.5,13530.0],["new",80049.0,1.0e4],["new",80048.5,8080.0],["new",80048.0,2.91e4],["new",80047.5,7.0e3]],"asks":[["new",80089.5,3660.0],["new",80090.0,2530.0],["new",80092.0,9650.0],["new",80092.5,35790.0],["new",80093.0,75160.0],["new",80093.5,80090.0],["new",80094.0,9660.0],["new",80095.0,1.1e3],["new",80096.0,2.9e3]],"prev_change_id":41106250124}}}
[2025-04-06 23:48:01.457] [multi_sink] [info] Processing received message: {"jsonrpc":"2.0","method":"subscription","params":{"channel":"book.BTC-PERPETUAL.100ms","data":{"timestamp":1743963482331,"type":"change","change_id":41106250769,"instrument_name":"BTC-PERPETUAL","bids":[["delete",80072.5,0.0],["delete",80067.0,0.0],["new",80056.5,35160.0],["new",80056.0,1.5e5],["new",80053.0,24930.0],["new",80052.5,8.31e4],["new",80051.5,13530.0],["new",80049.0,1.0e4],["new",80048.5,8080.0],["new",80048.0,2.91e4],["new",80047.5,7.0e3]],"asks":[["new",80089.5,3660.0],["new",80090.0,2530.0],["new",80092.0,9650.0],["new",80092.5,35790.0],["new",80093.0,75160.0],["new",80093.5,80090.0],["new",80094.0,9660.0],["new",80095.0,1.1e3],["new",80096.0,2.9e3]],"prev_change_id":41106250124}}}
[2025-04-06 23:48:01.458] [multi_sink] [error] Broadcast error: Operation canceled
[2025-04-06 23:48:01.784] [multi_sink] [info] 📩 Received: {"jsonrpc":"2.0","method":"subscription","params":{"channel":"book.BTC-PERPETUAL.100ms","data":{"timestamp":1743963482659,"type":"change","change_id":41106251143,"instrument_name":"BTC-PERPETUAL","bids":[["new",80065.5,4.09e4],["new",80065.0,7510.0],["new",80064.5,490.0],["new",80064.0,3.5e4],["new",80059.5,63420.0],["new",80058.5,2.0e4],["new",80057.5,1270.0],["new",80057.0,13760.0]],"asks":[["new",80069.5,12450.0],["new",80070.0,3.7e3],["new",80075.0,230.0],["new",80083.0,490.0],["new",80083.5,4120.0],["new",80084.0,13740.0],["new",80085.0,7520.0],["new",80085.5,5750.0],["new",80088.0,1.93e4]],"prev_change_id":41106250769}}}
[2025-04-06 23:48:01.787] [multi_sink] [info] Processing received message: {"jsonrpc":"2.0","method":"subscription","params":{"channel":"book.BTC-PERPETUAL.100ms","data":{"timestamp":1743963482659,"type":"change","change_id":41106251143,"instrument_name":"BTC-PERPETUAL","bids":[["new",80065.5,4.09e4],["new",80065.0,7510.0],["new",80064.5,490.0],["new",80064.0,3.5e4],["new",80059.5,63420.0],["new",80058.5,2.0e4],["new",80057.5,1270.0],["new",80057.0,13760.0]],"asks":[["new",80069.5,12450.0],["new",80070.0,3.7e3],["new",80075.0,230.0],["new",80083.0,490.0],["new",80083.5,4120.0],["new",80084.0,13740.0],["new",80085.0,7520.0],["new",80085.5,5750.0],["new",80088.0,1.93e4]],"prev_change_id":41106250769}}}
[2025-04-06 23:48:01.787] [multi_sink] [error] Broadcast error: Operation canceled
[2025-04-06 23:48:02.114] [multi_sink] [info] 📩 Received: {"jsonrpc":"2.0","method":"subscription","params":{"channel":"book.BTC-PERPETUAL.100ms","data":{"timestamp":1743963482715,"type":"change","change_id":41106251244,"instrument_name":"BTC-PERPETUAL","bids":[["change",80068.5,4220.0],["new",80068.0,163510.0],["new",80066.5,25030.0]],"asks":[],"prev_change_id":41106251143}}}
[2025-04-06 23:48:02.116] [multi_sink] [info] Processing received message: {"jsonrpc":"2.0","method":"subscription","params":{"channel":"book.BTC-PERPETUAL.100ms","data":{"timestamp":1743963482715,"type":"change","change_id":41106251244,"instrument_name":"BTC-PERPETUAL","bids":[["change",80068.5,4220.0],["new",80068.0,163510.0],["new",80066.5,25030.0]],"asks":[],"prev_change_id":41106251143}}}
[2025-04-06 23:48:02.116] [multi_sink] [error] Broadcast error: Operation canceled
[2025-04-06 23:48:02.949] [multi_sink] [info] 📩 Received: {"jsonrpc":"2.0","method":"subscription","params":{"channel":"book.BTC-PERPETUAL.100ms","data":{"timestamp":1743963483842,"type":"change","change_id":41106252990,"instrument_name":"BTC-PERPETUAL","bids":[],"asks":[["delete",80078.0,0.0]],"prev_change_id":41106251244}}}
[2025-04-06 23:48:02.949] [multi_sink] [info] Processing received message: {"jsonrpc":"2.0","method":"subscription","params":{"channel":"book.BTC-PERPETUAL.100ms","data":{"timestamp":1743963483842,"type":"change","change_id":41106252990,"instrument_name":"BTC-PERPETUAL","bids":[],"asks":[["delete",80078.0,0.0]],"prev_change_id":41106251244}}}
[2025-04-06 23:48:02.950] [multi_sink] [error] Broadcast error: Operation canceled
[2025-04-06 23:48:03.280] [multi_sink] [info] 📩 Received: {"jsonrpc":"2.0","method":"subscription","params":{"channel":"book.BTC-PERPETUAL.100ms","data":{"timestamp":1743963484161,"type":"change","change_id":41106253469,"instrument_name":"BTC-PERPETUAL","bids":[["new",79917.0,79910.0],["delete",79906.5,0.0],["new",79867.0,1.198e5],["delete",79856.5,0.0]],"asks":[["new",80069.0,10.0]],"prev_change_id":41106252990}}}
[2025-04-06 23:48:03.281] [multi_sink] [info] Processing received message: {"jsonrpc":"2.0","method":"subscription","params":{"channel":"book.BTC-PERPETUAL.100ms","data":{"timestamp":1743963484161,"type":"change","change_id":41106253469,"instrument_name":"BTC-PERPETUAL","bids":[["new",79917.0,79910.0],["delete",79906.5,0.0],["new",79867.0,1.198e5],["delete",79856.5,0.0]],"asks":[["new",80069.0,10.0]],"prev_change_id":41106252990}}}
[2025-04-06 23:48:03.282] [multi_sink] [error] Broadcast error: Operation canceled
[2025-04-06 23:48:04.843] [multi_sink] [info] 📩 Received: {"jsonrpc":"2.0","method":"subscription","params":{"channel":"book.BTC-PERPETUAL.100ms","data":{"timestamp":1743963485665,"type":"change","change_id":41106255327,"instrument_name":"BTC-PERPETUAL","bids":[["delete",79917.0,0.0],["delete",79867.0,0.0]],"asks":[["delete",80240.0,0.0],["new",80266.0,80260.0],["delete",80290.0,0.0],["new",80316.0,120470.0]],"prev_change_id":41106253469}}}
[2025-04-06 23:48:04.846] [multi_sink] [info] Processing received message: {"jsonrpc":"2.0","method":"subscription","params":{"channel":"book.BTC-PERPETUAL.100ms","data":{"timestamp":1743963485665,"type":"change","change_id":41106255327,"instrument_name":"BTC-PERPETUAL","bids":[["delete",79917.0,0.0],["delete",79867.0,0.0]],"asks":[["delete",80240.0,0.0],["new",80266.0,80260.0],["delete",80290.0,0.0],["new",80316.0,120470.0]],"prev_change_id":41106253469}}}
[2025-04-06 23:48:04.847] [multi_sink] [error] Broadcast error: Operation canceled
[2025-04-06 23:48:05.512] [multi_sink] [info] 📩 Received: {"jsonrpc":"2.0","method":"subscription","params":{"channel":"book.BTC-PERPETUAL.100ms","data":{"timestamp":1743963486165,"type":"change","change_id":41106256139,"instrument_name":"BTC-PERPETUAL","bids":[["delete",79897.0,0.0],["new",79872.5,8.0085e6]],"asks":[],"prev_change_id":41106255327}}}
[2025-04-06 23:48:05.515] [multi_sink] [info] Processing received message: {"jsonrpc":"2.0","method":"subscription","params":{"channel":"book.BTC-PERPETUAL.100ms","data":{"timestamp":1743963486165,"type":"change","change_id":41106256139,"instrument_name":"BTC-PERPETUAL","bids":[["delete",79897.0,0.0],["new",79872.5,8.0085e6]],"asks":[],"prev_change_id":41106255327}}}
[2025-04-06 23:48:05.515] [multi_sink] [error] Broadcast error: Operation canceled
[2025-04-06 23:48:05.846] [multi_sink] [info] 📩 Received: {"jsonrpc":"2.0","method":"subscription","params":{"channel":"book.BTC-PERPETUAL.100ms","data":{"timestamp":1743963486687,"type":"change","change_id":41106256684,"instrument_name":"BTC-PERPETUAL","bids":[],"asks":[["new",80264.0,7777770.0],["delete",80266.0,0.0],["delete",80288.5,0.0],["delete",80316.0,0.0]],"prev_change_id":41106256139}}}
[2025-04-06 23:48:05.847] [multi_sink] [info] Processing received message: {"jsonrpc":"2.0","method":"subscription","params":{"channel":"book.BTC-PERPETUAL.100ms","data":{"timestamp":1743963486687,"type":"change","change_id":41106256684,"instrument_name":"BTC-PERPETUAL","bids":[],"asks":[["new",80264.0,7777770.0],["delete",80266.0,0.0],["delete",80288.5,0.0],["delete",80316.0,0.0]],"prev_change_id":41106256139}}}
[2025-04-06 23:48:05.848] [multi_sink] [error] Broadcast error: Operation canceled
[2025-04-06 23:48:06.172] [multi_sink] [info] 📩 Received: {"jsonrpc":"2.0","method":"subscription","params":{"channel":"book.BTC-PERPETUAL.100ms","data":{"timestamp":1743963487038,"type":"change","change_id":41106257084,"instrument_name":"BTC-PERPETUAL","bids":[["delete",80068.0,0.0],["delete",80066.5,0.0],["change",80051.5,27060.0],["new",80051.0,860.0]],"asks":[["delete",80069.5,0.0],["delete",80070.0,0.0],["new",80108.5,5490.0],["new",80109.0,9810.0]],"prev_change_id":41106256684}}}
[2025-04-06 23:48:06.175] [multi_sink] [info] Processing received message: {"jsonrpc":"2.0","method":"subscription","params":{"channel":"book.BTC-PERPETUAL.100ms","data":{"timestamp":1743963487038,"type":"change","change_id":41106257084,"instrument_name":"BTC-PERPETUAL","bids":[["delete",80068.0,0.0],["delete",80066.5,0.0],["change",80051.5,27060.0],["new",80051.0,860.0]],"asks":[["delete",80069.5,0.0],["delete",80070.0,0.0],["new",80108.5,5490.0],["new",80109.0,9810.0]],"prev_change_id":41106256684}}}
[2025-04-06 23:48:06.175] [multi_sink] [error] Broadcast error: Operation canceled
[2025-04-06 23:48:06.502] [multi_sink] [info] 📩 Received: {"jsonrpc":"2.0","method":"subscription","params":{"channel":"book.BTC-PERPETUAL.100ms","data":{"timestamp":1743963487389,"type":"change","change_id":41106257722,"instrument_name":"BTC-PERPETUAL","bids":[["new",80066.5,5470.0],["new",80066.0,16490.0],["delete",80065.5,0.0],["change",80065.0,1260.0],["delete",80064.5,0.0],["delete",80064.0,0.0],["new",80060.0,650.0],["delete",80059.5,0.0],["delete",80058.5,0.0],["new",80058.0,1.5e5],["change",80057.5,1270.0],["delete",80057.0,0.0],["change",80056.5,35160.0],["change",80052.5,83260.0],["new",80052.0,8.31e4]],"asks":[["delete",80075.0,0.0],["delete",80083.0,0.0],["delete",80083.5,0.0],["delete",80084.0,0.0],["delete",80085.0,0.0],["delete",80085.5,0.0],["delete",80088.0,0.0],["delete",80089.5,0.0],["delete",80090.0,0.0],["delete",80092.0,0.0],["new",80094.5,5750.0],["new",8.01e4,1.89e4],["new",80101.0,32980.0],["new",80102.0,19320.0],["new",80102.5,35160.0],["new",80104.0,22350.0],["new",80106.0,9660.0],["new",80107.0,53620.0],["new",80107.5,9650.0],["new",80108.0,30210.0]],"prev_change_id":41106257084}}}
[2025-04-06 23:48:06.505] [multi_sink] [info] Processing received message: {"jsonrpc":"2.0","method":"subscription","params":{"channel":"book.BTC-PERPETUAL.100ms","data":{"timestamp":1743963487389,"type":"change","change_id":41106257722,"instrument_name":"BTC-PERPETUAL","bids":[["new",80066.5,5470.0],["new",80066.0,16490.0],["delete",80065.5,0.0],["change",80065.0,1260.0],["delete",80064.5,0.0],["delete",80064.0,0.0],["new",80060.0,650.0],["delete",80059.5,0.0],["delete",80058.5,0.0],["new",80058.0,1.5e5],["change",80057.5,1270.0],["delete",80057.0,0.0],["change",80056.5,35160.0],["change",80052.5,83260.0],["new",80052.0,8.31e4]],"asks":[["delete",80075.0,0.0],["delete",80083.0,0.0],["delete",80083.5,0.0],["delete",80084.0,0.0],["delete",80085.0,0.0],["delete",80085.5,0.0],["delete",80088.0,0.0],["delete",80089.5,0.0],["delete",80090.0,0.0],["delete",80092.0,0.0],["new",80094.5,5750.0],["new",8.01e4,1.89e4],["new",80101.0,32980.0],["new",80102.0,19320.0],["new",80102.5,35160.0],["new",80104.0,22350.0],["new",80106.0,9660.0],["new",80107.0,53620.0],["new",80107.5,9650.0],["new",80108.0,30210.0]],"prev_change_id":41106257084}}}
[2025-04-06 23:48:06.507] [multi_sink] [error] Broadcast error: Operation canceled
[2025-04-06 23:48:06.834] [multi_sink] [info] 📩 Received: {"jsonrpc":"2.0","method":"subscription","params":{"channel":"book.BTC-PERPETUAL.100ms","data":{"timestamp":1743963487682,"type":"change","change_id":41106258101,"instrument_name":"BTC-PERPETUAL","bids":[["new",80077.5,34990.0],["new",80074.5,3030.0],["new",80072.0,21690.0],["new",80071.5,160.0],["new",80069.5,16480.0],["new",80068.0,34940.0],["delete",80056.0,0.0],["delete",80053.0,0.0],["change",80052.5,160.0],["change",80051.5,13530.0],["new",80050.0,5821010.0],["delete",80049.0,0.0],["delete",80048.5,0.0],["delete",80030.5,0.0],["new",79902.0,7.99e4],["new",79852.0,119770.0]],"asks":[["delete",80069.0,0.0],["new",80085.0,1.58e4],["new",80087.0,4.08e4],["new",80087.5,1.0e4],["new",80089.0,11240.0],["new",80090.0,37470.0],["delete",80092.5,0.0],["delete",80093.0,0.0],["change",80093.5,1730.0],["delete",80094.0,0.0],["delete",80095.0,0.0],["delete",80096.0,0.0],["new",80237.0,80230.0],["new",80287.0,120430.0]],"prev_change_id":41106257722}}}
[2025-04-06 23:48:06.835] [multi_sink] [info] Processing received message: {"jsonrpc":"2.0","method":"subscription","params":{"channel":"book.BTC-PERPETUAL.100ms","data":{"timestamp":1743963487682,"type":"change","change_id":41106258101,"instrument_name":"BTC-PERPETUAL","bids":[["new",80077.5,34990.0],["new",80074.5,3030.0],["new",80072.0,21690.0],["new",80071.5,160.0],["new",80069.5,16480.0],["new",80068.0,34940.0],["delete",80056.0,0.0],["delete",80053.0,0.0],["change",80052.5,160.0],["change",80051.5,13530.0],["new",80050.0,5821010.0],["delete",80049.0,0.0],["delete",80048.5,0.0],["delete",80030.5,0.0],["new",79902.0,7.99e4],["new",79852.0,119770.0]],"asks":[["delete",80069.0,0.0],["new",80085.0,1.58e4],["new",80087.0,4.08e4],["new",80087.5,1.0e4],["new",80089.0,11240.0],["new",80090.0,37470.0],["delete",80092.5,0.0],["delete",80093.0,0.0],["change",80093.5,1730.0],["delete",80094.0,0.0],["delete",80095.0,0.0],["delete",80096.0,0.0],["new",80237.0,80230.0],["new",80287.0,120430.0]],"prev_change_id":41106257722}}}
[2025-04-06 23:48:06.836] [multi_sink] [error] Broadcast error: Operation canceled
[2025-04-06 23:48:07.163] [multi_sink] [info] 📩 Received: {"jsonrpc":"2.0","method":"subscription","params":{"channel":"book.BTC-PERPETUAL.100ms","data":{"timestamp":1743963487981,"type":"change","change_id":41106258598,"instrument_name":"BTC-PERPETUAL","bids":[["new",80082.0,5250.0],["new",80079.5,16540.0],["new",80079.0,24370.0],["delete",80048.0,0.0],["delete",80047.5,0.0]],"asks":[["new",80082.5,86160.0],["new",80084.0,7480.0],["delete",80097.5,0.0]],"prev_change_id":41106258101}}}
[2025-04-06 23:48:07.165] [multi_sink] [info] Processing received message: {"jsonrpc":"2.0","method":"subscription","params":{"channel":"book.BTC-PERPETUAL.100ms","data":{"timestamp":1743963487981,"type":"change","change_id":41106258598,"instrument_name":"BTC-PERPETUAL","bids":[["new",80082.0,5250.0],["new",80079.5,16540.0],["new",80079.0,24370.0],["delete",80048.0,0.0],["delete",80047.5,0.0]],"asks":[["new",80082.5,86160.0],["new",80084.0,7480.0],["delete",80097.5,0.0]],"prev_change_id":41106258101}}}
[2025-04-06 23:48:07.165] [multi_sink] [error] Broadcast error: Operation canceled
[2025-04-06 23:48:07.495] [multi_sink] [info] 📩 Received: {"jsonrpc":"2.0","method":"subscription","params":{"channel":"book.BTC-PERPETUAL.100ms","data":{"timestamp":1743963488138,"type":"change","change_id":41106259040,"instrument_name":"BTC-PERPETUAL","bids":[],"asks":[["new",80129.5,7777770.0]],"prev_change_id":41106258598}}}
[2025-04-06 23:48:07.496] [multi_sink] [info] Processing received message: {"jsonrpc":"2.0","method":"subscription","params":{"channel":"book.BTC-PERPETUAL.100ms","data":{"timestamp":1743963488138,"type":"change","change_id":41106259040,"instrument_name":"BTC-PERPETUAL","bids":[],"asks":[["new",80129.5,7777770.0]],"prev_change_id":41106258598}}}
[2025-04-06 23:48:07.496] [multi_sink] [error] Broadcast error: Operation canceled
[2025-04-06 23:48:07.824] [multi_sink] [info] 📩 Received: {"jsonrpc":"2.0","method":"subscription","params":{"channel":"book.BTC-PERPETUAL.100ms","data":{"timestamp":1743963488543,"type":"change","change_id":41106259655,"instrument_name":"BTC-PERPETUAL","bids":[["delete",79902.0,0.0],["delete",79852.0,0.0]],"asks":[["delete",80237.0,0.0],["delete",80287.0,0.0]],"prev_change_id":41106259040}}}
[2025-04-06 23:48:07.827] [multi_sink] [info] Processing received message: {"jsonrpc":"2.0","method":"subscription","params":{"channel":"book.BTC-PERPETUAL.100ms","data":{"timestamp":1743963488543,"type":"change","change_id":41106259655,"instrument_name":"BTC-PERPETUAL","bids":[["delete",79902.0,0.0],["delete",79852.0,0.0]],"asks":[["delete",80237.0,0.0],["delete",80287.0,0.0]],"prev_change_id":41106259040}}}
[2025-04-06 23:48:07.828] [multi_sink] [error] Broadcast error: Operation canceled
[2025-04-06 23:48:08.863] [multi_sink] [info] 📩 Received: {"jsonrpc":"2.0","method":"subscription","params":{"channel":"book.BTC-PERPETUAL.100ms","data":{"timestamp":1743963489685,"type":"change","change_id":41106261122,"instrument_name":"BTC-PERPETUAL","bids":[],"asks":[["new",80226.5,80220.0],["new",80276.5,120410.0]],"prev_change_id":41106259655}}}
[2025-04-06 23:48:08.864] [multi_sink] [info] Processing received message: {"jsonrpc":"2.0","method":"subscription","params":{"channel":"book.BTC-PERPETUAL.100ms","data":{"timestamp":1743963489685,"type":"change","change_id":41106261122,"instrument_name":"BTC-PERPETUAL","bids":[],"asks":[["new",80226.5,80220.0],["new",80276.5,120410.0]],"prev_change_id":41106259655}}}
[2025-04-06 23:48:08.865] [multi_sink] [error] Broadcast error: Operation canceled
[2025-04-06 23:48:09.194] [multi_sink] [info] 📩 Received: {"jsonrpc":"2.0","method":"subscription","params":{"channel":"book.BTC-PERPETUAL.100ms","data":{"timestamp":1743963490084,"type":"change","change_id":41106261515,"instrument_name":"BTC-PERPETUAL","bids":[],"asks":[["delete",80226.5,0.0],["delete",80276.5,0.0]],"prev_change_id":41106261122}}}
[2025-04-06 23:48:09.197] [multi_sink] [info] Processing received message: {"jsonrpc":"2.0","method":"subscription","params":{"channel":"book.BTC-PERPETUAL.100ms","data":{"timestamp":1743963490084,"type":"change","change_id":41106261515,"instrument_name":"BTC-PERPETUAL","bids":[],"asks":[["delete",80226.5,0.0],["delete",80276.5,0.0]],"prev_change_id":41106261122}}}
[2025-04-06 23:48:09.198] [multi_sink] [error] Broadcast error: Operation canceled
[2025-04-06 23:48:09.858] [multi_sink] [info] 📩 Received: {"jsonrpc":"2.0","method":"subscription","params":{"channel":"book.BTC-PERPETUAL.100ms","data":{"timestamp":1743963490549,"type":"change","change_id":41106262440,"instrument_name":"BTC-PERPETUAL","bids":[],"asks":[["new",80223.5,80220.0],["new",80273.5,120410.0]],"prev_change_id":41106261515}}}
[2025-04-06 23:48:09.859] [multi_sink] [info] Processing received message: {"jsonrpc":"2.0","method":"subscription","params":{"channel":"book.BTC-PERPETUAL.100ms","data":{"timestamp":1743963490549,"type":"change","change_id":41106262440,"instrument_name":"BTC-PERPETUAL","bids":[],"asks":[["new",80223.5,80220.0],["new",80273.5,120410.0]],"prev_change_id":41106261515}}}
[2025-04-06 23:48:09.860] [multi_sink] [error] Broadcast error: Operation canceled
[2025-04-06 23:48:10.546] [multi_sink] [info] 📩 Received: {"jsonrpc":"2.0","method":"subscription","params":{"channel":"book.BTC-PERPETUAL.100ms","data":{"timestamp":1743963491400,"type":"change","change_id":41106263580,"instrument_name":"BTC-PERPETUAL","bids":[],"asks":[["delete",80223.5,0.0],["delete",80273.5,0.0]],"prev_change_id":41106262440}}}
[2025-04-06 23:48:10.549] [multi_sink] [info] Processing received message: {"jsonrpc":"2.0","method":"subscription","params":{"channel":"book.BTC-PERPETUAL.100ms","data":{"timestamp":1743963491400,"type":"change","change_id":41106263580,"instrument_name":"BTC-PERPETUAL","bids":[],"asks":[["delete",80223.5,0.0],["delete",80273.5,0.0]],"prev_change_id":41106262440}}}
[2025-04-06 23:48:10.550] [multi_sink] [error] Broadcast error: Operation canceled
