[2025-04-07 08:31:28.595] [multi_sink] [info] Processing received message: {"jsonrpc":"2.0","method":"subscription","params":{"channel":"book.ETH-PERPETUAL.100ms","data":{"timestamp":1743994890054,"type":"change","change_id":23707216029,"instrument_name":"ETH-PERPETUAL","bids":[],"asks":[["new",1576.2,6111993.0],["delete",1577.45,0.0]],"prev_change_id":23707215472}}}
[2025-04-07 08:31:28.840] [multi_sink] [info] 📩 Received: {"jsonrpc":"2.0","method":"subscription","params":{"channel":"book.BTC-PERPETUAL.100ms","data":{"timestamp":1743994890443,"type":"change","change_id":41151989150,"instrument_name":"BTC-PERPETUAL","bids":[["delete",78344.5,0.0],["delete",78342.5,0.0],["delete",78342.0,0.0],["delete",78331.0,0.0],["delete",78330.0,0.0],["delete",78320.0,0.0],["delete",78318.5,0.0]],"asks":[["new",78315.5,3580.0],["new",78316.0,58640.0],["new",78317.0,18590.0],["change",78345.0,110.0],["delete",78345.5,0.0],["delete",78346.5,0.0]],"prev_change_id":41151988437}}}
[2025-04-07 08:31:28.843] [multi_sink] [info] Processing received message: {"jsonrpc":"2.0","method":"subscription","params":{"channel":"book.BTC-PERPETUAL.100ms","data":{"timestamp":1743994890443,"type":"change","change_id":41151989150,"instrument_name":"BTC-PERPETUAL","bids":[["delete",78344.5,0.0],["delete",78342.5,0.0],["delete",78342.0,0.0],["delete",78331.0,0.0],["delete",78330.0,0.0],["delete",78320.0,0.0],["delete",78318.5,0.0]],"asks":[["new",78315.5,3580.0],["new",78316.0,58640.0],["new",78317.0,18590.0],["change",78345.0,110.0],["delete",78345.5,0.0],["delete",78346.5,0.0]],"prev_change_id":41151988437}}}
[2025-04-07 08:31:29.170] [multi_sink] [info] 📩 Received: {"jsonrpc":"2.0","method":"subscription","params":{"channel":"book.BTC-PERPETUAL.100ms","data":{"timestamp":1743994890787,"type":"change","change_id":41151989437,"instrument_name":"BTC-PERPETUAL","bids":[["delete",78315.0,0.0],["delete",78313.5,0.0],["delete",78312.5,0.0],["delete",78312.0,0.0],["delete",78310.0,0.0],["delete",78308.0,0.0],["new",78285.0,8.0e4],["new",78282.5,14840.0]],"asks":[["new",78309.0,33870.0],["new",78310.0,34110.0],["new",78311.0,16120.0],["new",78311.5,14850.0],["new",78312.0,72750.0],["new",78313.5,16160.0],["new",78314.0,4270.0],["new",78314.5,390.0],["new",78315.0,82850.0],["delete",78345.0,0.0],["delete",78347.0,0.0],["delete",78347.5,0.0],["delete",78348.0,0.0],["delete",78349.5,0.0],["delete",78350.0,0.0],["delete",78350.5,0.0],["delete",78351.0,0.0],["delete",78351.5,0.0],["delete",78352.0,0.0]],"prev_change_id":41151989150}}}
[2025-04-07 08:31:29.173] [multi_sink] [info] Processing received message: {"jsonrpc":"2.0","method":"subscription","params":{"channel":"book.BTC-PERPETUAL.100ms","data":{"timestamp":1743994890787,"type":"change","change_id":41151989437,"instrument_name":"BTC-PERPETUAL","bids":[["delete",78315.0,0.0],["delete",78313.5,0.0],["delete",78312.5,0.0],["delete",78312.0,0.0],["delete",78310.0,0.0],["delete",78308.0,0.0],["new",78285.0,8.0e4],["new",78282.5,14840.0]],"asks":[["new",78309.0,33870.0],["new",78310.0,34110.0],["new",78311.0,16120.0],["new",78311.5,14850.0],["new",78312.0,72750.0],["new",78313.5,16160.0],["new",78314.0,4270.0],["new",78314.5,390.0],["new",78315.0,82850.0],["delete",78345.0,0.0],["delete",78347.0,0.0],["delete",78347.5,0.0],["delete",78348.0,0.0],["delete",78349.5,0.0],["delete",78350.0,0.0],["delete",78350.5,0.0],["delete",78351.0,0.0],["delete",78351.5,0.0],["delete",78352.0,0.0]],"prev_change_id":41151989150}}}
[2025-04-07 08:31:29.510] [multi_sink] [info] 📩 Received: {"jsonrpc":"2.0","method":"subscription","params":{"channel":"book.BTC-PERPETUAL.100ms","data":{"timestamp":1743994891085,"type":"change","change_id":41151989959,"instrument_name":"BTC-PERPETUAL","bids":[["delete",78307.5,0.0],["delete",78306.5,0.0],["delete",78306.0,0.0],["delete",78305.5,0.0],["delete",78303.5,0.0],["delete",78303.0,0.0],["delete",78302.5,0.0],["new",78300.5,1790.0],["new",78297.5,720.0],["new",78288.0,39010.0],["new",78287.5,2.13e4],["new",78287.0,650.0],["new",78286.0,470.0],["delete",78122.5,0.0],["delete",78072.5,0.0]],"asks":[["new",78301.0,115030.0],["new",78302.5,1.05e4],["new",78304.0,42120.0],["new",78304.5,15180.0],["new",78306.0,1.0e4],["new",78308.0,33690.0],["new",78308.5,5510.0],["delete",78352.5,0.0],["delete",78353.0,0.0],["delete",78356.0,0.0],["delete",78357.0,0.0],["delete",78357.5,0.0],["delete",78358.0,0.0],["delete",78358.5,0.0],["change",78359.0,6640830.0],["delete",78457.0,0.0],["delete",78507.0,0.0]],"prev_change_id":41151989437}}}
[2025-04-07 08:31:29.511] [multi_sink] [info] Processing received message: {"jsonrpc":"2.0","method":"subscription","params":{"channel":"book.BTC-PERPETUAL.100ms","data":{"timestamp":1743994891085,"type":"change","change_id":41151989959,"instrument_name":"BTC-PERPETUAL","bids":[["delete",78307.5,0.0],["delete",78306.5,0.0],["delete",78306.0,0.0],["delete",78305.5,0.0],["delete",78303.5,0.0],["delete",78303.0,0.0],["delete",78302.5,0.0],["new",78300.5,1790.0],["new",78297.5,720.0],["new",78288.0,39010.0],["new",78287.5,2.13e4],["new",78287.0,650.0],["new",78286.0,470.0],["delete",78122.5,0.0],["delete",78072.5,0.0]],"asks":[["new",78301.0,115030.0],["new",78302.5,1.05e4],["new",78304.0,42120.0],["new",78304.5,15180.0],["new",78306.0,1.0e4],["new",78308.0,33690.0],["new",78308.5,5510.0],["delete",78352.5,0.0],["delete",78353.0,0.0],["delete",78356.0,0.0],["delete",78357.0,0.0],["delete",78357.5,0.0],["delete",78358.0,0.0],["delete",78358.5,0.0],["change",78359.0,6640830.0],["delete",78457.0,0.0],["delete",78507.0,0.0]],"prev_change_id":41151989437}}}
[2025-04-07 08:31:29.831] [multi_sink] [info] 📩 Received: {"jsonrpc":"2.0","method":"subscription","params":{"channel":"book.BTC-PERPETUAL.100ms","data":{"timestamp":1743994891190,"type":"change","change_id":41151989991,"instrument_name":"BTC-PERPETUAL","bids":[],"asks":[["change",78301.0,115140.0],["change",78313.5,16050.0]],"prev_change_id":41151989959}}}
[2025-04-07 08:31:29.832] [multi_sink] [info] Processing received message: {"jsonrpc":"2.0","method":"subscription","params":{"channel":"book.BTC-PERPETUAL.100ms","data":{"timestamp":1743994891190,"type":"change","change_id":41151989991,"instrument_name":"BTC-PERPETUAL","bids":[],"asks":[["change",78301.0,115140.0],["change",78313.5,16050.0]],"prev_change_id":41151989959}}}
[2025-04-07 08:31:32.305] [multi_sink] [info] 📩 Received: {"jsonrpc":"2.0","method":"subscription","params":{"channel":"book.ETH-PERPETUAL.100ms","data":{"timestamp":1743994893921,"type":"change","change_id":23707219435,"instrument_name":"ETH-PERPETUAL","bids":[["delete",1575.0,0.0],["delete",1574.95,0.0],["delete",1574.9,0.0],["delete",1574.85,0.0],["new",1574.5,49081.0],["new",1574.45,3760.0],["new",1574.4,2544.0],["new",1574.35,925.0]],"asks":[["new",1576.4,29957.0],["new",1576.45,1003.0],["new",1576.5,105869.0],["new",1576.55,39946.0]],"prev_change_id":23707216029}}}
[2025-04-07 08:31:32.307] [multi_sink] [info] Processing received message: {"jsonrpc":"2.0","method":"subscription","params":{"channel":"book.ETH-PERPETUAL.100ms","data":{"timestamp":1743994893921,"type":"change","change_id":23707219435,"instrument_name":"ETH-PERPETUAL","bids":[["delete",1575.0,0.0],["delete",1574.95,0.0],["delete",1574.9,0.0],["delete",1574.85,0.0],["new",1574.5,49081.0],["new",1574.45,3760.0],["new",1574.4,2544.0],["new",1574.35,925.0]],"asks":[["new",1576.4,29957.0],["new",1576.45,1003.0],["new",1576.5,105869.0],["new",1576.55,39946.0]],"prev_change_id":23707216029}}}
[2025-04-07 08:31:32.636] [multi_sink] [info] 📩 Received: {"jsonrpc":"2.0","method":"subscription","params":{"channel":"book.ETH-PERPETUAL.100ms","data":{"timestamp":1743994894220,"type":"change","change_id":23707219818,"instrument_name":"ETH-PERPETUAL","bids":[["new",1574.9,1446.0],["new",1574.85,923.0],["change",1574.8,2397.0],["change",1574.75,7655.0],["change",1574.7,7545981.0],["new",1574.65,5931.0],["new",1574.6,7299.0],["new",1574.55,22627.0],["delete",1574.2,0.0]],"asks":[["new",1576.0,6012.0],["new",1576.05,14603.0],["new",1576.1,30971.0],["new",1576.15,75957.0],["change",1576.2,6118833.0],["new",1576.25,28928.0],["new",1576.3,20047.0],["new",1576.35,923.0]],"prev_change_id":23707219435}}}
[2025-04-07 08:31:32.637] [multi_sink] [info] Processing received message: {"jsonrpc":"2.0","method":"subscription","params":{"channel":"book.ETH-PERPETUAL.100ms","data":{"timestamp":1743994894220,"type":"change","change_id":23707219818,"instrument_name":"ETH-PERPETUAL","bids":[["new",1574.9,1446.0],["new",1574.85,923.0],["change",1574.8,2397.0],["change",1574.75,7655.0],["change",1574.7,7545981.0],["new",1574.65,5931.0],["new",1574.6,7299.0],["new",1574.55,22627.0],["delete",1574.2,0.0]],"asks":[["new",1576.0,6012.0],["new",1576.05,14603.0],["new",1576.1,30971.0],["new",1576.15,75957.0],["change",1576.2,6118833.0],["new",1576.25,28928.0],["new",1576.3,20047.0],["new",1576.35,923.0]],"prev_change_id":23707219435}}}
[2025-04-07 08:31:32.976] [multi_sink] [info] 📩 Received: {"jsonrpc":"2.0","method":"subscription","params":{"channel":"book.ETH-PERPETUAL.100ms","data":{"timestamp":1743994894579,"type":"change","change_id":23707220125,"instrument_name":"ETH-PERPETUAL","bids":[["new",1575.45,1.25e4],["new",1575.4,13052.0],["new",1575.25,2970.0],["new",1575.2,9.9e3],["new",1575.15,100.0],["new",1575.05,37088.0],["new",1575.0,85393.0],["new",1574.95,61673.0]],"asks":[["new",1575.5,19.0],["new",1575.6,6526.0],["new",1575.65,9919.0],["new",1575.7,11833.0],["new",1575.8,6.5e3],["new",1575.85,5.0e3],["new",1575.9,2330.0],["new",1575.95,6758.0]],"prev_change_id":23707219818}}}
[2025-04-07 08:31:32.978] [multi_sink] [info] Processing received message: {"jsonrpc":"2.0","method":"subscription","params":{"channel":"book.ETH-PERPETUAL.100ms","data":{"timestamp":1743994894579,"type":"change","change_id":23707220125,"instrument_name":"ETH-PERPETUAL","bids":[["new",1575.45,1.25e4],["new",1575.4,13052.0],["new",1575.25,2970.0],["new",1575.2,9.9e3],["new",1575.15,100.0],["new",1575.05,37088.0],["new",1575.0,85393.0],["new",1574.95,61673.0]],"asks":[["new",1575.5,19.0],["new",1575.6,6526.0],["new",1575.65,9919.0],["new",1575.7,11833.0],["new",1575.8,6.5e3],["new",1575.85,5.0e3],["new",1575.9,2330.0],["new",1575.95,6758.0]],"prev_change_id":23707219818}}}
[2025-04-07 08:31:33.306] [multi_sink] [info] 📩 Received: {"jsonrpc":"2.0","method":"subscription","params":{"channel":"book.ETH-PERPETUAL.100ms","data":{"timestamp":1743994894728,"type":"change","change_id":23707220249,"instrument_name":"ETH-PERPETUAL","bids":[],"asks":[["change",1575.5,14.0],["new",1580.35,500.0],["delete",1581.95,0.0]],"prev_change_id":23707220125}}}
[2025-04-07 08:31:33.308] [multi_sink] [info] Processing received message: {"jsonrpc":"2.0","method":"subscription","params":{"channel":"book.ETH-PERPETUAL.100ms","data":{"timestamp":1743994894728,"type":"change","change_id":23707220249,"instrument_name":"ETH-PERPETUAL","bids":[],"asks":[["change",1575.5,14.0],["new",1580.35,500.0],["delete",1581.95,0.0]],"prev_change_id":23707220125}}}
[2025-04-07 08:31:33.564] [multi_sink] [info] 📩 Received: {"jsonrpc":"2.0","method":"subscription","params":{"channel":"book.BTC-PERPETUAL.100ms","data":{"timestamp":1743994895091,"type":"change","change_id":41151995801,"instrument_name":"BTC-PERPETUAL","bids":[["delete",78281.5,0.0],["new",78265.0,7825720.0],["delete",78128.5,0.0],["new",78112.0,8000580.0]],"asks":[],"prev_change_id":41151989991}}}
[2025-04-07 08:31:33.566] [multi_sink] [info] Processing received message: {"jsonrpc":"2.0","method":"subscription","params":{"channel":"book.BTC-PERPETUAL.100ms","data":{"timestamp":1743994895091,"type":"change","change_id":41151995801,"instrument_name":"BTC-PERPETUAL","bids":[["delete",78281.5,0.0],["new",78265.0,7825720.0],["delete",78128.5,0.0],["new",78112.0,8000580.0]],"asks":[],"prev_change_id":41151989991}}}
[2025-04-07 08:31:33.898] [multi_sink] [info] 📩 Received: {"jsonrpc":"2.0","method":"subscription","params":{"channel":"book.BTC-PERPETUAL.100ms","data":{"timestamp":1743994895511,"type":"change","change_id":41151996519,"instrument_name":"BTC-PERPETUAL","bids":[["delete",78300.5,0.0],["delete",78297.5,0.0],["new",78296.5,1550.0],["new",78296.0,5180.0],["new",78295.0,76450.0],["new",78294.0,1.5e5],["new",78293.5,80430.0],["delete",78288.0,0.0],["delete",78287.5,0.0],["delete",78287.0,0.0]],"asks":[["change",78301.0,110.0],["delete",78302.5,0.0],["delete",78304.0,0.0],["delete",78304.5,0.0],["delete",78306.0,0.0],["new",78336.0,52850.0],["new",78336.5,5.5e3],["new",78338.0,1.65e4],["new",78339.0,99660.0],["new",78340.0,1.33e4],["new",78342.5,6640830.0],["delete",78359.0,0.0],["new",78495.5,7777770.0],["delete",78512.0,0.0]],"prev_change_id":41151995801}}}
[2025-04-07 08:31:33.903] [multi_sink] [info] Processing received message: {"jsonrpc":"2.0","method":"subscription","params":{"channel":"book.BTC-PERPETUAL.100ms","data":{"timestamp":1743994895511,"type":"change","change_id":41151996519,"instrument_name":"BTC-PERPETUAL","bids":[["delete",78300.5,0.0],["delete",78297.5,0.0],["new",78296.5,1550.0],["new",78296.0,5180.0],["new",78295.0,76450.0],["new",78294.0,1.5e5],["new",78293.5,80430.0],["delete",78288.0,0.0],["delete",78287.5,0.0],["delete",78287.0,0.0]],"asks":[["change",78301.0,110.0],["delete",78302.5,0.0],["delete",78304.0,0.0],["delete",78304.5,0.0],["delete",78306.0,0.0],["new",78336.0,52850.0],["new",78336.5,5.5e3],["new",78338.0,1.65e4],["new",78339.0,99660.0],["new",78340.0,1.33e4],["new",78342.5,6640830.0],["delete",78359.0,0.0],["new",78495.5,7777770.0],["delete",78512.0,0.0]],"prev_change_id":41151995801}}}
[2025-04-07 08:31:34.238] [multi_sink] [info] 📩 Received: {"jsonrpc":"2.0","method":"subscription","params":{"channel":"book.BTC-PERPETUAL.100ms","data":{"timestamp":1743994895843,"type":"change","change_id":41151996868,"instrument_name":"BTC-PERPETUAL","bids":[["new",78306.5,9430.0],["new",78304.5,16490.0],["new",78304.0,66310.0],["new",78303.5,34180.0],["new",78302.0,21730.0],["new",78301.5,85630.0],["new",78300.5,2870.0],["new",7.83e4,5180.0],["new",78297.5,720.0],["delete",78286.0,0.0],["delete",78285.0,0.0],["delete",78282.5,0.0]],"asks":[["delete",78301.0,0.0],["delete",78308.0,0.0],["delete",78308.5,0.0],["delete",78309.0,0.0],["delete",78310.0,0.0],["delete",78311.0,0.0],["delete",78311.5,0.0],["delete",78312.0,0.0],["delete",78313.5,0.0],["delete",78314.0,0.0],["new",78324.5,1840.0],["new",78332.0,26930.0],["new",78332.5,38380.0],["new",78333.0,8050.0],["new",78334.5,2.75e4],["new",78335.5,9670.0]],"prev_change_id":41151996519}}}
[2025-04-07 08:31:34.243] [multi_sink] [info] Processing received message: {"jsonrpc":"2.0","method":"subscription","params":{"channel":"book.BTC-PERPETUAL.100ms","data":{"timestamp":1743994895843,"type":"change","change_id":41151996868,"instrument_name":"BTC-PERPETUAL","bids":[["new",78306.5,9430.0],["new",78304.5,16490.0],["new",78304.0,66310.0],["new",78303.5,34180.0],["new",78302.0,21730.0],["new",78301.5,85630.0],["new",78300.5,2870.0],["new",7.83e4,5180.0],["new",78297.5,720.0],["delete",78286.0,0.0],["delete",78285.0,0.0],["delete",78282.5,0.0]],"asks":[["delete",78301.0,0.0],["delete",78308.0,0.0],["delete",78308.5,0.0],["delete",78309.0,0.0],["delete",78310.0,0.0],["delete",78311.0,0.0],["delete",78311.5,0.0],["delete",78312.0,0.0],["delete",78313.5,0.0],["delete",78314.0,0.0],["new",78324.5,1840.0],["new",78332.0,26930.0],["new",78332.5,38380.0],["new",78333.0,8050.0],["new",78334.5,2.75e4],["new",78335.5,9670.0]],"prev_change_id":41151996519}}}
[2025-04-07 08:31:34.556] [multi_sink] [info] 📩 Received: {"jsonrpc":"2.0","method":"subscription","params":{"channel":"book.BTC-PERPETUAL.100ms","data":{"timestamp":1743994896056,"type":"change","change_id":41151997278,"instrument_name":"BTC-PERPETUAL","bids":[["new",78316.0,200.0],["new",78309.0,490.0],["new",78308.5,9750.0],["new",78308.0,32980.0],["new",78307.5,15640.0],["new",78307.0,2.13e4],["new",78147.5,78140.0],["new",78097.5,117130.0]],"asks":[["delete",78314.5,0.0],["delete",78315.0,0.0],["delete",78315.5,0.0],["delete",78316.0,0.0],["new",78316.5,710.0],["delete",78317.0,0.0],["new",78321.5,190.0],["new",78322.0,40380.0],["new",78322.5,81330.0],["new",78324.0,9630.0],["new",78481.0,78480.0],["new",78531.0,117790.0]],"prev_change_id":41151996868}}}
[2025-04-07 08:31:34.559] [multi_sink] [info] Processing received message: {"jsonrpc":"2.0","method":"subscription","params":{"channel":"book.BTC-PERPETUAL.100ms","data":{"timestamp":1743994896056,"type":"change","change_id":41151997278,"instrument_name":"BTC-PERPETUAL","bids":[["new",78316.0,200.0],["new",78309.0,490.0],["new",78308.5,9750.0],["new",78308.0,32980.0],["new",78307.5,15640.0],["new",78307.0,2.13e4],["new",78147.5,78140.0],["new",78097.5,117130.0]],"asks":[["delete",78314.5,0.0],["delete",78315.0,0.0],["delete",78315.5,0.0],["delete",78316.0,0.0],["new",78316.5,710.0],["delete",78317.0,0.0],["new",78321.5,190.0],["new",78322.0,40380.0],["new",78322.5,81330.0],["new",78324.0,9630.0],["new",78481.0,78480.0],["new",78531.0,117790.0]],"prev_change_id":41151996868}}}
[2025-04-07 08:31:35.326] [multi_sink] [info] 📩 Received: {"jsonrpc":"2.0","method":"subscription","params":{"channel":"book.ETH-PERPETUAL.100ms","data":{"timestamp":1743994896935,"type":"change","change_id":23707222599,"instrument_name":"ETH-PERPETUAL","bids":[["change",1575.2,7555852.0],["change",1574.7,29.0]],"asks":[],"prev_change_id":23707220249}}}
[2025-04-07 08:31:35.328] [multi_sink] [info] Processing received message: {"jsonrpc":"2.0","method":"subscription","params":{"channel":"book.ETH-PERPETUAL.100ms","data":{"timestamp":1743994896935,"type":"change","change_id":23707222599,"instrument_name":"ETH-PERPETUAL","bids":[["change",1575.2,7555852.0],["change",1574.7,29.0]],"asks":[],"prev_change_id":23707220249}}}
[2025-04-07 08:31:35.578] [multi_sink] [info] 📩 Received: {"jsonrpc":"2.0","method":"subscription","params":{"channel":"book.BTC-PERPETUAL.100ms","data":{"timestamp":1743994896966,"type":"change","change_id":41151998734,"instrument_name":"BTC-PERPETUAL","bids":[],"asks":[["change",78316.5,8540.0]],"prev_change_id":41151997278}}}
[2025-04-07 08:31:35.581] [multi_sink] [info] Processing received message: {"jsonrpc":"2.0","method":"subscription","params":{"channel":"book.BTC-PERPETUAL.100ms","data":{"timestamp":1743994896966,"type":"change","change_id":41151998734,"instrument_name":"BTC-PERPETUAL","bids":[],"asks":[["change",78316.5,8540.0]],"prev_change_id":41151997278}}}
[2025-04-07 08:31:35.657] [multi_sink] [info] 📩 Received: {"jsonrpc":"2.0","method":"subscription","params":{"channel":"book.ETH-PERPETUAL.100ms","data":{"timestamp":1743994897264,"type":"change","change_id":23707223032,"instrument_name":"ETH-PERPETUAL","bids":[],"asks":[["change",1576.2,6840.0],["new",1576.6,6111993.0]],"prev_change_id":23707222599}}}
[2025-04-07 08:31:35.658] [multi_sink] [info] Processing received message: {"jsonrpc":"2.0","method":"subscription","params":{"channel":"book.ETH-PERPETUAL.100ms","data":{"timestamp":1743994897264,"type":"change","change_id":23707223032,"instrument_name":"ETH-PERPETUAL","bids":[],"asks":[["change",1576.2,6840.0],["new",1576.6,6111993.0]],"prev_change_id":23707222599}}}
[2025-04-07 08:31:35.917] [multi_sink] [info] 📩 Received: {"jsonrpc":"2.0","method":"subscription","params":{"channel":"book.BTC-PERPETUAL.100ms","data":{"timestamp":1743994897549,"type":"change","change_id":41151999631,"instrument_name":"BTC-PERPETUAL","bids":[["delete",78316.0,0.0],["delete",78309.0,0.0],["change",78308.5,2610.0]],"asks":[["change",78316.5,710.0]],"prev_change_id":41151998734}}}
[2025-04-07 08:31:35.922] [multi_sink] [info] Processing received message: {"jsonrpc":"2.0","method":"subscription","params":{"channel":"book.BTC-PERPETUAL.100ms","data":{"timestamp":1743994897549,"type":"change","change_id":41151999631,"instrument_name":"BTC-PERPETUAL","bids":[["delete",78316.0,0.0],["delete",78309.0,0.0],["change",78308.5,2610.0]],"asks":[["change",78316.5,710.0]],"prev_change_id":41151998734}}}
[2025-04-07 08:31:36.247] [multi_sink] [info] 📩 Received: {"jsonrpc":"2.0","method":"subscription","params":{"channel":"book.BTC-PERPETUAL.100ms","data":{"timestamp":1743994897562,"type":"change","change_id":41151999645,"instrument_name":"BTC-PERPETUAL","bids":[["delete",78147.5,0.0],["delete",78097.5,0.0]],"asks":[["delete",78481.0,0.0],["delete",78531.0,0.0]],"prev_change_id":41151999631}}}
[2025-04-07 08:31:36.247] [multi_sink] [info] Processing received message: {"jsonrpc":"2.0","method":"subscription","params":{"channel":"book.BTC-PERPETUAL.100ms","data":{"timestamp":1743994897562,"type":"change","change_id":41151999645,"instrument_name":"BTC-PERPETUAL","bids":[["delete",78147.5,0.0],["delete",78097.5,0.0]],"asks":[["delete",78481.0,0.0],["delete",78531.0,0.0]],"prev_change_id":41151999631}}}
[2025-04-07 08:31:37.350] [multi_sink] [info] 📩 Received: {"jsonrpc":"2.0","method":"subscription","params":{"channel":"book.ETH-PERPETUAL.100ms","data":{"timestamp":1743994898958,"type":"change","change_id":23707224528,"instrument_name":"ETH-PERPETUAL","bids":[["delete",1575.45,0.0],["delete",1575.4,0.0],["delete",1575.25,0.0],["change",1575.2,7545952.0],["delete",1575.15,0.0],["change",1574.4,3571.0],["change",1574.35,1850.0],["new",1574.3,1025.0],["new",1574.25,3770.0],["new",1574.2,8659.0]],"asks":[["delete",1575.5,0.0],["delete",1575.6,0.0],["delete",1575.65,0.0],["delete",1575.7,0.0],["delete",1575.8,0.0],["change",1576.6,6113016.0],["new",1576.65,1023.0],["new",1576.7,12329.0],["new",1576.75,923.0],["new",1576.8,918.0]],"prev_change_id":23707223032}}}
[2025-04-07 08:31:37.354] [multi_sink] [info] Processing received message: {"jsonrpc":"2.0","method":"subscription","params":{"channel":"book.ETH-PERPETUAL.100ms","data":{"timestamp":1743994898958,"type":"change","change_id":23707224528,"instrument_name":"ETH-PERPETUAL","bids":[["delete",1575.45,0.0],["delete",1575.4,0.0],["delete",1575.25,0.0],["change",1575.2,7545952.0],["delete",1575.15,0.0],["change",1574.4,3571.0],["change",1574.35,1850.0],["new",1574.3,1025.0],["new",1574.25,3770.0],["new",1574.2,8659.0]],"asks":[["delete",1575.5,0.0],["delete",1575.6,0.0],["delete",1575.65,0.0],["delete",1575.7,0.0],["delete",1575.8,0.0],["change",1576.6,6113016.0],["new",1576.65,1023.0],["new",1576.7,12329.0],["new",1576.75,923.0],["new",1576.8,918.0]],"prev_change_id":23707223032}}}
[2025-04-07 08:31:37.672] [multi_sink] [info] 📩 Received: {"jsonrpc":"2.0","method":"subscription","params":{"channel":"book.ETH-PERPETUAL.100ms","data":{"timestamp":1743994899287,"type":"change","change_id":23707224932,"instrument_name":"ETH-PERPETUAL","bids":[["delete",1575.05,0.0],["delete",1575.0,0.0],["delete",1574.95,0.0],["change",1574.9,6330.0],["delete",1574.85,0.0],["delete",1574.8,0.0],["change",1574.75,8578.0],["change",1574.7,925.0],["change",1574.65,3913.0],["change",1574.6,8224.0],["change",1574.55,44835.0],["change",1574.5,50006.0],["change",1574.45,46452.0]],"asks":[["delete",1575.85,0.0],["delete",1575.9,0.0],["delete",1575.95,0.0],["delete",1576.0,0.0],["delete",1576.05,0.0],["delete",1576.1,0.0],["change",1576.15,85403.0],["change",1576.2,13723.0],["change",1576.25,13867.0],["change",1576.3,33548.0],["change",1576.35,1023.0],["change",1576.4,38343.0],["change",1576.45,2006.0],["change",1576.5,114906.0],["change",1576.55,65969.0]],"prev_change_id":23707224528}}}
[2025-04-07 08:31:37.674] [multi_sink] [info] Processing received message: {"jsonrpc":"2.0","method":"subscription","params":{"channel":"book.ETH-PERPETUAL.100ms","data":{"timestamp":1743994899287,"type":"change","change_id":23707224932,"instrument_name":"ETH-PERPETUAL","bids":[["delete",1575.05,0.0],["delete",1575.0,0.0],["delete",1574.95,0.0],["change",1574.9,6330.0],["delete",1574.85,0.0],["delete",1574.8,0.0],["change",1574.75,8578.0],["change",1574.7,925.0],["change",1574.65,3913.0],["change",1574.6,8224.0],["change",1574.55,44835.0],["change",1574.5,50006.0],["change",1574.45,46452.0]],"asks":[["delete",1575.85,0.0],["delete",1575.9,0.0],["delete",1575.95,0.0],["delete",1576.0,0.0],["delete",1576.05,0.0],["delete",1576.1,0.0],["change",1576.15,85403.0],["change",1576.2,13723.0],["change",1576.25,13867.0],["change",1576.3,33548.0],["change",1576.35,1023.0],["change",1576.4,38343.0],["change",1576.45,2006.0],["change",1576.5,114906.0],["change",1576.55,65969.0]],"prev_change_id":23707224528}}}
[2025-04-07 08:31:38.002] [multi_sink] [info] 📩 Received: {"jsonrpc":"2.0","method":"subscription","params":{"channel":"book.ETH-PERPETUAL.100ms","data":{"timestamp":1743994899518,"type":"change","change_id":23707225183,"instrument_name":"ETH-PERPETUAL","bids":[["new",1575.75,596.0],["change",1575.2,7569884.0],["new",1575.15,9999.0],["new",1575.05,82849.0],["new",1575.0,30084.0],["new",1574.95,52772.0],["change",1574.6,925.0],["change",1574.55,22208.0],["change",1574.5,925.0],["change",1574.45,42692.0],["change",1574.4,1027.0],["change",1574.35,925.0]],"asks":[["new",1575.85,58479.0],["new",1575.9,4.5e4],["new",1575.95,1908.0],["new",1576.0,12220.0],["new",1576.05,7598.0],["new",1576.1,44420.0],["change",1576.3,13501.0],["change",1576.35,100.0],["change",1576.4,8386.0],["change",1576.45,1003.0],["change",1576.5,9037.0],["change",1576.55,26023.0]],"prev_change_id":23707224932}}}
[2025-04-07 08:31:38.005] [multi_sink] [info] Processing received message: {"jsonrpc":"2.0","method":"subscription","params":{"channel":"book.ETH-PERPETUAL.100ms","data":{"timestamp":1743994899518,"type":"change","change_id":23707225183,"instrument_name":"ETH-PERPETUAL","bids":[["new",1575.75,596.0],["change",1575.2,7569884.0],["new",1575.15,9999.0],["new",1575.05,82849.0],["new",1575.0,30084.0],["new",1574.95,52772.0],["change",1574.6,925.0],["change",1574.55,22208.0],["change",1574.5,925.0],["change",1574.45,42692.0],["change",1574.4,1027.0],["change",1574.35,925.0]],"asks":[["new",1575.85,58479.0],["new",1575.9,4.5e4],["new",1575.95,1908.0],["new",1576.0,12220.0],["new",1576.05,7598.0],["new",1576.1,44420.0],["change",1576.3,13501.0],["change",1576.35,100.0],["change",1576.4,8386.0],["change",1576.45,1003.0],["change",1576.5,9037.0],["change",1576.55,26023.0]],"prev_change_id":23707224932}}}
[2025-04-07 08:31:38.736] [multi_sink] [info] 📩 Received: {"jsonrpc":"2.0","method":"subscription","params":{"channel":"book.BTC-PERPETUAL.100ms","data":{"timestamp":1743994900368,"type":"change","change_id":41152003528,"instrument_name":"BTC-PERPETUAL","bids":[],"asks":[["delete",78316.5,0.0],["new",78330.5,83350.0]],"prev_change_id":41151999645}}}
[2025-04-07 08:31:38.738] [multi_sink] [info] Processing received message: {"jsonrpc":"2.0","method":"subscription","params":{"channel":"book.BTC-PERPETUAL.100ms","data":{"timestamp":1743994900368,"type":"change","change_id":41152003528,"instrument_name":"BTC-PERPETUAL","bids":[],"asks":[["delete",78316.5,0.0],["new",78330.5,83350.0]],"prev_change_id":41151999645}}}
[2025-04-07 08:31:39.066] [multi_sink] [info] 📩 Received: {"jsonrpc":"2.0","method":"subscription","params":{"channel":"book.BTC-PERPETUAL.100ms","data":{"timestamp":1743994900693,"type":"change","change_id":41152003906,"instrument_name":"BTC-PERPETUAL","bids":[["delete",78308.5,0.0],["delete",78308.0,0.0],["delete",78307.5,0.0],["delete",78307.0,0.0],["delete",78306.5,0.0],["delete",78304.5,0.0],["delete",78304.0,0.0],["delete",78303.5,0.0],["delete",78302.0,0.0],["delete",78301.5,0.0],["new",78277.0,5070.0],["new",78276.5,8.0e4],["new",78275.0,16840.0],["new",78274.5,11880.0],["new",78274.0,39680.0],["new",78273.0,5180.0],["new",78271.0,8.31e4],["new",78270.5,56660.0],["new",78268.0,195150.0]],"asks":[["delete",78321.5,0.0],["delete",78322.0,0.0],["delete",78322.5,0.0],["new",78323.5,5010.0],["change",78324.0,31430.0],["change",78324.5,32640.0],["new",78327.0,15270.0],["new",78327.5,5180.0],["new",78329.0,2890.0],["new",78330.0,310.0],["delete",78332.0,0.0],["delete",78332.5,0.0],["delete",78333.0,0.0],["delete",78334.5,0.0]],"prev_change_id":41152003528}}}
[2025-04-07 08:31:39.069] [multi_sink] [info] Processing received message: {"jsonrpc":"2.0","method":"subscription","params":{"channel":"book.BTC-PERPETUAL.100ms","data":{"timestamp":1743994900693,"type":"change","change_id":41152003906,"instrument_name":"BTC-PERPETUAL","bids":[["delete",78308.5,0.0],["delete",78308.0,0.0],["delete",78307.5,0.0],["delete",78307.0,0.0],["delete",78306.5,0.0],["delete",78304.5,0.0],["delete",78304.0,0.0],["delete",78303.5,0.0],["delete",78302.0,0.0],["delete",78301.5,0.0],["new",78277.0,5070.0],["new",78276.5,8.0e4],["new",78275.0,16840.0],["new",78274.5,11880.0],["new",78274.0,39680.0],["new",78273.0,5180.0],["new",78271.0,8.31e4],["new",78270.5,56660.0],["new",78268.0,195150.0]],"asks":[["delete",78321.5,0.0],["delete",78322.0,0.0],["delete",78322.5,0.0],["new",78323.5,5010.0],["change",78324.0,31430.0],["change",78324.5,32640.0],["new",78327.0,15270.0],["new",78327.5,5180.0],["new",78329.0,2890.0],["new",78330.0,310.0],["delete",78332.0,0.0],["delete",78332.5,0.0],["delete",78333.0,0.0],["delete",78334.5,0.0]],"prev_change_id":41152003528}}}
[2025-04-07 08:31:39.397] [multi_sink] [info] 📩 Received: {"jsonrpc":"2.0","method":"subscription","params":{"channel":"book.BTC-PERPETUAL.100ms","data":{"timestamp":1743994901020,"type":"change","change_id":41152004547,"instrument_name":"BTC-PERPETUAL","bids":[["new",78301.0,170.0],["change",78300.5,3.3e3],["delete",7.83e4,0.0],["new",78298.0,470.0],["change",78297.5,1070.0],["delete",78296.5,0.0],["delete",78296.0,0.0],["new",78295.5,510.0],["delete",78295.0,0.0],["change",78294.0,5110.0],["change",78293.5,32980.0],["new",78293.0,550.0],["new",78287.5,50310.0]],"asks":[["new",78307.5,150.0],["new",78314.5,3.0e3],["new",78315.5,1.0e4],["new",78316.0,44690.0],["new",78316.5,60660.0],["new",78319.5,78310.0],["new",78320.5,49680.0],["new",78322.0,27990.0],["new",78322.5,7.76e4],["delete",78335.5,0.0],["delete",78336.0,0.0],["delete",78336.5,0.0],["delete",78338.0,0.0],["delete",78339.0,0.0],["delete",78340.0,0.0]],"prev_change_id":41152003906}}}
[2025-04-07 08:31:39.401] [multi_sink] [info] Processing received message: {"jsonrpc":"2.0","method":"subscription","params":{"channel":"book.BTC-PERPETUAL.100ms","data":{"timestamp":1743994901020,"type":"change","change_id":41152004547,"instrument_name":"BTC-PERPETUAL","bids":[["new",78301.0,170.0],["change",78300.5,3.3e3],["delete",7.83e4,0.0],["new",78298.0,470.0],["change",78297.5,1070.0],["delete",78296.5,0.0],["delete",78296.0,0.0],["new",78295.5,510.0],["delete",78295.0,0.0],["change",78294.0,5110.0],["change",78293.5,32980.0],["new",78293.0,550.0],["new",78287.5,50310.0]],"asks":[["new",78307.5,150.0],["new",78314.5,3.0e3],["new",78315.5,1.0e4],["new",78316.0,44690.0],["new",78316.5,60660.0],["new",78319.5,78310.0],["new",78320.5,49680.0],["new",78322.0,27990.0],["new",78322.5,7.76e4],["delete",78335.5,0.0],["delete",78336.0,0.0],["delete",78336.5,0.0],["delete",78338.0,0.0],["delete",78339.0,0.0],["delete",78340.0,0.0]],"prev_change_id":41152003906}}}
[2025-04-07 08:31:39.727] [multi_sink] [info] 📩 Received: {"jsonrpc":"2.0","method":"subscription","params":{"channel":"book.BTC-PERPETUAL.100ms","data":{"timestamp":1743994901056,"type":"change","change_id":41152004561,"instrument_name":"BTC-PERPETUAL","bids":[["new",78303.5,4380.0]],"asks":[["new",78304.0,47220.0]],"prev_change_id":41152004547}}}
[2025-04-07 08:31:39.729] [multi_sink] [info] Processing received message: {"jsonrpc":"2.0","method":"subscription","params":{"channel":"book.BTC-PERPETUAL.100ms","data":{"timestamp":1743994901056,"type":"change","change_id":41152004561,"instrument_name":"BTC-PERPETUAL","bids":[["new",78303.5,4380.0]],"asks":[["new",78304.0,47220.0]],"prev_change_id":41152004547}}}
[2025-04-07 08:31:40.934] [multi_sink] [info] 📩 Received: {"jsonrpc":"2.0","method":"subscription","params":{"channel":"book.BTC-PERPETUAL.100ms","data":{"timestamp":1743994902564,"type":"change","change_id":41152006880,"instrument_name":"BTC-PERPETUAL","bids":[],"asks":[["new",78461.0,78460.0]],"prev_change_id":41152004561}}}
[2025-04-07 08:31:40.938] [multi_sink] [info] Processing received message: {"jsonrpc":"2.0","method":"subscription","params":{"channel":"book.BTC-PERPETUAL.100ms","data":{"timestamp":1743994902564,"type":"change","change_id":41152006880,"instrument_name":"BTC-PERPETUAL","bids":[],"asks":[["new",78461.0,78460.0]],"prev_change_id":41152004561}}}
[2025-04-07 08:31:41.272] [multi_sink] [info] 📩 Received: {"jsonrpc":"2.0","method":"subscription","params":{"channel":"book.BTC-PERPETUAL.100ms","data":{"timestamp":1743994902574,"type":"change","change_id":41152006883,"instrument_name":"BTC-PERPETUAL","bids":[["new",78130.0,78130.0],["new",78080.0,117120.0]],"asks":[["new",78511.0,117760.0]],"prev_change_id":41152006880}}}
[2025-04-07 08:31:41.274] [multi_sink] [info] Processing received message: {"jsonrpc":"2.0","method":"subscription","params":{"channel":"book.BTC-PERPETUAL.100ms","data":{"timestamp":1743994902574,"type":"change","change_id":41152006883,"instrument_name":"BTC-PERPETUAL","bids":[["new",78130.0,78130.0],["new",78080.0,117120.0]],"asks":[["new",78511.0,117760.0]],"prev_change_id":41152006880}}}
[2025-04-07 08:31:41.640] [multi_sink] [info] 📩 Received: {"jsonrpc":"2.0","method":"subscription","params":{"channel":"book.BTC-PERPETUAL.100ms","data":{"timestamp":1743994903269,"type":"change","change_id":41152007561,"instrument_name":"BTC-PERPETUAL","bids":[],"asks":[["delete",78461.0,0.0],["new",78471.5,78470.0]],"prev_change_id":41152006883}}}
[2025-04-07 08:31:41.644] [multi_sink] [info] Processing received message: {"jsonrpc":"2.0","method":"subscription","params":{"channel":"book.BTC-PERPETUAL.100ms","data":{"timestamp":1743994903269,"type":"change","change_id":41152007561,"instrument_name":"BTC-PERPETUAL","bids":[],"asks":[["delete",78461.0,0.0],["new",78471.5,78470.0]],"prev_change_id":41152006883}}}
[2025-04-07 08:31:41.967] [multi_sink] [info] 📩 Received: {"jsonrpc":"2.0","method":"subscription","params":{"channel":"book.BTC-PERPETUAL.100ms","data":{"timestamp":1743994903376,"type":"change","change_id":41152008071,"instrument_name":"BTC-PERPETUAL","bids":[["delete",78130.0,0.0],["delete",78080.0,0.0]],"asks":[["delete",78511.0,0.0],["new",78521.5,117780.0]],"prev_change_id":41152007561}}}
[2025-04-07 08:31:41.968] [multi_sink] [info] Processing received message: {"jsonrpc":"2.0","method":"subscription","params":{"channel":"book.BTC-PERPETUAL.100ms","data":{"timestamp":1743994903376,"type":"change","change_id":41152008071,"instrument_name":"BTC-PERPETUAL","bids":[["delete",78130.0,0.0],["delete",78080.0,0.0]],"asks":[["delete",78511.0,0.0],["new",78521.5,117780.0]],"prev_change_id":41152007561}}}
[2025-04-07 08:31:42.302] [multi_sink] [info] 📩 Received: {"jsonrpc":"2.0","method":"subscription","params":{"channel":"book.BTC-PERPETUAL.100ms","data":{"timestamp":1743994903904,"type":"change","change_id":41152008574,"instrument_name":"BTC-PERPETUAL","bids":[],"asks":[["delete",78471.5,0.0],["delete",78521.5,0.0]],"prev_change_id":41152008071}}}
[2025-04-07 08:31:42.303] [multi_sink] [info] Processing received message: {"jsonrpc":"2.0","method":"subscription","params":{"channel":"book.BTC-PERPETUAL.100ms","data":{"timestamp":1743994903904,"type":"change","change_id":41152008574,"instrument_name":"BTC-PERPETUAL","bids":[],"asks":[["delete",78471.5,0.0],["delete",78521.5,0.0]],"prev_change_id":41152008071}}}
[2025-04-07 08:31:42.379] [multi_sink] [info] 📩 Received: {"jsonrpc":"2.0","method":"subscription","params":{"channel":"book.ETH-PERPETUAL.100ms","data":{"timestamp":1743994903997,"type":"change","change_id":23707229963,"instrument_name":"ETH-PERPETUAL","bids":[["delete",1575.75,0.0],["change",1575.2,7545952.0],["delete",1575.15,0.0],["delete",1575.05,0.0],["delete",1575.0,0.0],["change",1574.95,100.0],["change",1574.9,7253.0],["new",1574.8,3596.0],["change",1574.75,39104.0],["change",1574.7,40966.0],["change",1574.65,7826.0]],"asks":[["delete",1575.85,0.0],["delete",1575.9,0.0],["delete",1575.95,0.0],["delete",1576.0,0.0],["delete",1576.05,0.0],["delete",1576.1,0.0],["change",1576.6,6114039.0],["change",1576.65,7141.0],["change",1576.7,21007.0],["change",1576.75,1846.0],["change",1576.8,1841.0],["new",1576.85,38758.0]],"prev_change_id":23707225183}}}
[2025-04-07 08:31:42.381] [multi_sink] [info] Processing received message: {"jsonrpc":"2.0","method":"subscription","params":{"channel":"book.ETH-PERPETUAL.100ms","data":{"timestamp":1743994903997,"type":"change","change_id":23707229963,"instrument_name":"ETH-PERPETUAL","bids":[["delete",1575.75,0.0],["change",1575.2,7545952.0],["delete",1575.15,0.0],["delete",1575.05,0.0],["delete",1575.0,0.0],["change",1574.95,100.0],["change",1574.9,7253.0],["new",1574.8,3596.0],["change",1574.75,39104.0],["change",1574.7,40966.0],["change",1574.65,7826.0]],"asks":[["delete",1575.85,0.0],["delete",1575.9,0.0],["delete",1575.95,0.0],["delete",1576.0,0.0],["delete",1576.05,0.0],["delete",1576.1,0.0],["change",1576.6,6114039.0],["change",1576.65,7141.0],["change",1576.7,21007.0],["change",1576.75,1846.0],["change",1576.8,1841.0],["new",1576.85,38758.0]],"prev_change_id":23707225183}}}
[2025-04-07 08:31:42.706] [multi_sink] [info] 📩 Received: {"jsonrpc":"2.0","method":"subscription","params":{"channel":"book.ETH-PERPETUAL.100ms","data":{"timestamp":1743994904325,"type":"change","change_id":23707230102,"instrument_name":"ETH-PERPETUAL","bids":[["new",1575.4,9998.0],["new",1575.35,13153.0],["new",1575.3,26501.0],["new",1575.25,20266.0],["change",1575.2,5277.0],["new",1575.15,23932.0],["new",1575.1,7598.0],["new",1575.05,90467.0],["new",1575.0,37371.0],["change",1574.9,923.0],["change",1574.8,7549548.0],["change",1574.75,30526.0],["change",1574.7,40041.0],["change",1574.65,3913.0],["delete",1574.6,0.0],["delete",1574.55,0.0],["delete",1574.5,0.0],["delete",1574.45,0.0],["delete",1574.4,0.0]],"asks":[["change",1576.15,7.14e4],["change",1576.2,16347.0],["change",1576.25,3876.0],["change",1576.3,4688.0],["change",1576.35,6025.0],["change",1576.4,7598.0],["change",1576.45,923.0],["change",1576.5,37830.0],["change",1576.55,37735.0]],"prev_change_id":23707229963}}}
[2025-04-07 08:31:42.707] [multi_sink] [info] Processing received message: {"jsonrpc":"2.0","method":"subscription","params":{"channel":"book.ETH-PERPETUAL.100ms","data":{"timestamp":1743994904325,"type":"change","change_id":23707230102,"instrument_name":"ETH-PERPETUAL","bids":[["new",1575.4,9998.0],["new",1575.35,13153.0],["new",1575.3,26501.0],["new",1575.25,20266.0],["change",1575.2,5277.0],["new",1575.15,23932.0],["new",1575.1,7598.0],["new",1575.05,90467.0],["new",1575.0,37371.0],["change",1574.9,923.0],["change",1574.8,7549548.0],["change",1574.75,30526.0],["change",1574.7,40041.0],["change",1574.65,3913.0],["delete",1574.6,0.0],["delete",1574.55,0.0],["delete",1574.5,0.0],["delete",1574.45,0.0],["delete",1574.4,0.0]],"asks":[["change",1576.15,7.14e4],["change",1576.2,16347.0],["change",1576.25,3876.0],["change",1576.3,4688.0],["change",1576.35,6025.0],["change",1576.4,7598.0],["change",1576.45,923.0],["change",1576.5,37830.0],["change",1576.55,37735.0]],"prev_change_id":23707229963}}}
[2025-04-07 08:31:43.038] [multi_sink] [info] 📩 Received: {"jsonrpc":"2.0","method":"subscription","params":{"channel":"book.ETH-PERPETUAL.100ms","data":{"timestamp":1743994904504,"type":"change","change_id":23707230313,"instrument_name":"ETH-PERPETUAL","bids":[["new",1575.75,6226.0],["new",1575.65,3750.0],["new",1575.55,19083.0],["new",1575.5,16908.0],["new",1575.45,7999.0],["delete",1574.35,0.0],["delete",1574.3,0.0],["delete",1574.25,0.0],["delete",1574.2,0.0]],"asks":[["new",1575.8,9946.0],["new",1575.9,17564.0],["new",1576.0,1530.0],["new",1576.05,5.0e3],["new",1576.1,22962.0],["change",1576.3,6116681.0],["change",1576.6,1023.0],["change",1576.65,6118.0],["change",1576.7,8678.0],["change",1576.75,923.0],["change",1576.8,923.0]],"prev_change_id":23707230102}}}
[2025-04-07 08:31:43.039] [multi_sink] [info] Processing received message: {"jsonrpc":"2.0","method":"subscription","params":{"channel":"book.ETH-PERPETUAL.100ms","data":{"timestamp":1743994904504,"type":"change","change_id":23707230313,"instrument_name":"ETH-PERPETUAL","bids":[["new",1575.75,6226.0],["new",1575.65,3750.0],["new",1575.55,19083.0],["new",1575.5,16908.0],["new",1575.45,7999.0],["delete",1574.35,0.0],["delete",1574.3,0.0],["delete",1574.25,0.0],["delete",1574.2,0.0]],"asks":[["new",1575.8,9946.0],["new",1575.9,17564.0],["new",1576.0,1530.0],["new",1576.05,5.0e3],["new",1576.1,22962.0],["change",1576.3,6116681.0],["change",1576.6,1023.0],["change",1576.65,6118.0],["change",1576.7,8678.0],["change",1576.75,923.0],["change",1576.8,923.0]],"prev_change_id":23707230102}}}
[2025-04-07 08:31:43.655] [multi_sink] [info] 📩 Received: {"jsonrpc":"2.0","method":"subscription","params":{"channel":"book.BTC-PERPETUAL.100ms","data":{"timestamp":1743994905288,"type":"change","change_id":41152010784,"instrument_name":"BTC-PERPETUAL","bids":[],"asks":[["new",78491.0,78490.0]],"prev_change_id":41152008574}}}
[2025-04-07 08:31:43.657] [multi_sink] [info] Processing received message: {"jsonrpc":"2.0","method":"subscription","params":{"channel":"book.BTC-PERPETUAL.100ms","data":{"timestamp":1743994905288,"type":"change","change_id":41152010784,"instrument_name":"BTC-PERPETUAL","bids":[],"asks":[["new",78491.0,78490.0]],"prev_change_id":41152008574}}}
[2025-04-07 08:31:43.985] [multi_sink] [info] 📩 Received: {"jsonrpc":"2.0","method":"subscription","params":{"channel":"book.BTC-PERPETUAL.100ms","data":{"timestamp":1743994905593,"type":"change","change_id":41152011004,"instrument_name":"BTC-PERPETUAL","bids":[["new",78310.0,530.0],["new",78308.5,5180.0],["new",78307.0,4.0e4],["new",78306.0,3.99e4],["new",78304.5,3.0e3],["new",78304.0,1.5e5],["change",78303.5,650.0],["delete",78301.0,0.0],["delete",78300.5,0.0],["delete",78298.0,0.0],["delete",78297.5,0.0],["delete",78295.5,0.0],["delete",78294.0,0.0],["new",78158.5,78150.0],["new",78108.5,117150.0]],"asks":[["delete",78304.0,0.0],["delete",78307.5,0.0],["delete",78314.5,0.0],["delete",78315.5,0.0],["delete",78316.0,0.0],["delete",78316.5,0.0],["delete",78319.5,0.0],["new",78344.0,490.0],["new",78344.5,29860.0],["new",78345.0,34660.0],["new",78346.0,16490.0],["new",78346.5,13740.0],["new",78347.5,38750.0],["new",78348.0,42410.0],["new",78541.0,117810.0]],"prev_change_id":41152010784}}}
[2025-04-07 08:31:43.990] [multi_sink] [info] Processing received message: {"jsonrpc":"2.0","method":"subscription","params":{"channel":"book.BTC-PERPETUAL.100ms","data":{"timestamp":1743994905593,"type":"change","change_id":41152011004,"instrument_name":"BTC-PERPETUAL","bids":[["new",78310.0,530.0],["new",78308.5,5180.0],["new",78307.0,4.0e4],["new",78306.0,3.99e4],["new",78304.5,3.0e3],["new",78304.0,1.5e5],["change",78303.5,650.0],["delete",78301.0,0.0],["delete",78300.5,0.0],["delete",78298.0,0.0],["delete",78297.5,0.0],["delete",78295.5,0.0],["delete",78294.0,0.0],["new",78158.5,78150.0],["new",78108.5,117150.0]],"asks":[["delete",78304.0,0.0],["delete",78307.5,0.0],["delete",78314.5,0.0],["delete",78315.5,0.0],["delete",78316.0,0.0],["delete",78316.5,0.0],["delete",78319.5,0.0],["new",78344.0,490.0],["new",78344.5,29860.0],["new",78345.0,34660.0],["new",78346.0,16490.0],["new",78346.5,13740.0],["new",78347.5,38750.0],["new",78348.0,42410.0],["new",78541.0,117810.0]],"prev_change_id":41152010784}}}
[2025-04-07 08:31:44.318] [multi_sink] [info] 📩 Received: {"jsonrpc":"2.0","method":"subscription","params":{"channel":"book.BTC-PERPETUAL.100ms","data":{"timestamp":1743994905945,"type":"change","change_id":41152011674,"instrument_name":"BTC-PERPETUAL","bids":[["new",78319.0,14750.0],["new",78318.5,32980.0],["new",78318.0,16490.0],["new",78317.5,510.0],["new",78317.0,15170.0],["new",78316.0,32660.0],["new",78315.5,4.0e4],["new",78315.0,69770.0],["new",78312.0,5180.0],["delete",78293.5,0.0],["delete",78293.0,0.0],["delete",78287.5,0.0],["delete",78277.0,0.0],["delete",78276.5,0.0],["delete",78275.0,0.0],["delete",78274.5,0.0],["delete",78274.0,0.0],["delete",78273.0,0.0]],"asks":[["delete",78320.5,0.0],["delete",78322.0,0.0],["delete",78322.5,0.0],["delete",78323.5,0.0],["delete",78324.0,0.0],["delete",78324.5,0.0],["delete",78327.0,0.0],["delete",78327.5,0.0],["delete",78329.0,0.0],["delete",78330.0,0.0],["new",78334.0,8330.0],["new",78334.5,2.12e4],["new",78335.5,6.0e3],["new",78337.0,2550.0],["new",78338.5,8940.0],["new",78341.0,5740.0],["new",78341.5,220.0]],"prev_change_id":41152011004}}}
[2025-04-07 08:31:44.320] [multi_sink] [info] Processing received message: {"jsonrpc":"2.0","method":"subscription","params":{"channel":"book.BTC-PERPETUAL.100ms","data":{"timestamp":1743994905945,"type":"change","change_id":41152011674,"instrument_name":"BTC-PERPETUAL","bids":[["new",78319.0,14750.0],["new",78318.5,32980.0],["new",78318.0,16490.0],["new",78317.5,510.0],["new",78317.0,15170.0],["new",78316.0,32660.0],["new",78315.5,4.0e4],["new",78315.0,69770.0],["new",78312.0,5180.0],["delete",78293.5,0.0],["delete",78293.0,0.0],["delete",78287.5,0.0],["delete",78277.0,0.0],["delete",78276.5,0.0],["delete",78275.0,0.0],["delete",78274.5,0.0],["delete",78274.0,0.0],["delete",78273.0,0.0]],"asks":[["delete",78320.5,0.0],["delete",78322.0,0.0],["delete",78322.5,0.0],["delete",78323.5,0.0],["delete",78324.0,0.0],["delete",78324.5,0.0],["delete",78327.0,0.0],["delete",78327.5,0.0],["delete",78329.0,0.0],["delete",78330.0,0.0],["new",78334.0,8330.0],["new",78334.5,2.12e4],["new",78335.5,6.0e3],["new",78337.0,2550.0],["new",78338.5,8940.0],["new",78341.0,5740.0],["new",78341.5,220.0]],"prev_change_id":41152011004}}}
[2025-04-07 08:31:44.646] [multi_sink] [info] 📩 Received: {"jsonrpc":"2.0","method":"subscription","params":{"channel":"book.BTC-PERPETUAL.100ms","data":{"timestamp":1743994906262,"type":"change","change_id":41152011932,"instrument_name":"BTC-PERPETUAL","bids":[["new",78329.5,7860.0],["new",78322.5,430.0],["new",78320.0,470.0],["new",78319.5,490.0],["delete",78271.0,0.0],["delete",78270.5,0.0],["delete",78268.0,0.0],["new",78168.5,78160.0],["delete",78158.5,0.0],["new",78118.5,117170.0],["delete",78108.5,0.0]],"asks":[["new",78330.0,83150.0],["delete",78330.5,0.0],["new",78331.0,1.0e4],["new",78331.5,10160.0],["delete",78491.0,0.0],["delete",78541.0,0.0]],"prev_change_id":41152011674}}}
[2025-04-07 08:31:44.647] [multi_sink] [info] Processing received message: {"jsonrpc":"2.0","method":"subscription","params":{"channel":"book.BTC-PERPETUAL.100ms","data":{"timestamp":1743994906262,"type":"change","change_id":41152011932,"instrument_name":"BTC-PERPETUAL","bids":[["new",78329.5,7860.0],["new",78322.5,430.0],["new",78320.0,470.0],["new",78319.5,490.0],["delete",78271.0,0.0],["delete",78270.5,0.0],["delete",78268.0,0.0],["new",78168.5,78160.0],["delete",78158.5,0.0],["new",78118.5,117170.0],["delete",78108.5,0.0]],"asks":[["new",78330.0,83150.0],["delete",78330.5,0.0],["new",78331.0,1.0e4],["new",78331.5,10160.0],["delete",78491.0,0.0],["delete",78541.0,0.0]],"prev_change_id":41152011674}}}
[2025-04-07 08:31:44.977] [multi_sink] [info] 📩 Received: {"jsonrpc":"2.0","method":"subscription","params":{"channel":"book.BTC-PERPETUAL.100ms","data":{"timestamp":1743994906578,"type":"change","change_id":41152012746,"instrument_name":"BTC-PERPETUAL","bids":[["delete",78168.5,0.0],["delete",78118.5,0.0]],"asks":[],"prev_change_id":41152011932}}}
[2025-04-07 08:31:44.977] [multi_sink] [info] Processing received message: {"jsonrpc":"2.0","method":"subscription","params":{"channel":"book.BTC-PERPETUAL.100ms","data":{"timestamp":1743994906578,"type":"change","change_id":41152012746,"instrument_name":"BTC-PERPETUAL","bids":[["delete",78168.5,0.0],["delete",78118.5,0.0]],"asks":[],"prev_change_id":41152011932}}}
[2025-04-07 08:31:46.653] [multi_sink] [info] 📩 Received: {"jsonrpc":"2.0","method":"subscription","params":{"channel":"book.BTC-PERPETUAL.100ms","data":{"timestamp":1743994908286,"type":"change","change_id":41152015291,"instrument_name":"BTC-PERPETUAL","bids":[["new",78158.5,78150.0]],"asks":[["new",78492.0,78490.0],["new",78542.0,117810.0]],"prev_change_id":41152012746}}}
[2025-04-07 08:31:46.657] [multi_sink] [info] Processing received message: {"jsonrpc":"2.0","method":"subscription","params":{"channel":"book.BTC-PERPETUAL.100ms","data":{"timestamp":1743994908286,"type":"change","change_id":41152015291,"instrument_name":"BTC-PERPETUAL","bids":[["new",78158.5,78150.0]],"asks":[["new",78492.0,78490.0],["new",78542.0,117810.0]],"prev_change_id":41152012746}}}
[2025-04-07 08:31:46.984] [multi_sink] [info] 📩 Received: {"jsonrpc":"2.0","method":"subscription","params":{"channel":"book.BTC-PERPETUAL.100ms","data":{"timestamp":1743994908290,"type":"change","change_id":41152015378,"instrument_name":"BTC-PERPETUAL","bids":[["new",78108.5,117150.0]],"asks":[],"prev_change_id":41152015291}}}
[2025-04-07 08:31:46.986] [multi_sink] [info] Processing received message: {"jsonrpc":"2.0","method":"subscription","params":{"channel":"book.BTC-PERPETUAL.100ms","data":{"timestamp":1743994908290,"type":"change","change_id":41152015378,"instrument_name":"BTC-PERPETUAL","bids":[["new",78108.5,117150.0]],"asks":[],"prev_change_id":41152015291}}}
[2025-04-07 08:31:47.314] [multi_sink] [info] 📩 Received: {"jsonrpc":"2.0","method":"subscription","params":{"channel":"book.BTC-PERPETUAL.100ms","data":{"timestamp":1743994908812,"type":"change","change_id":41152015967,"instrument_name":"BTC-PERPETUAL","bids":[["new",78297.5,7825720.0],["delete",78265.0,0.0],["delete",78158.5,0.0],["new",78144.5,8000580.0],["delete",78112.0,0.0],["delete",78108.5,0.0]],"asks":[["delete",78492.0,0.0],["new",78504.0,7.85e4],["delete",78542.0,0.0],["new",78554.0,117830.0]],"prev_change_id":41152015378}}}
[2025-04-07 08:31:47.317] [multi_sink] [info] Processing received message: {"jsonrpc":"2.0","method":"subscription","params":{"channel":"book.BTC-PERPETUAL.100ms","data":{"timestamp":1743994908812,"type":"change","change_id":41152015967,"instrument_name":"BTC-PERPETUAL","bids":[["new",78297.5,7825720.0],["delete",78265.0,0.0],["delete",78158.5,0.0],["new",78144.5,8000580.0],["delete",78112.0,0.0],["delete",78108.5,0.0]],"asks":[["delete",78492.0,0.0],["new",78504.0,7.85e4],["delete",78542.0,0.0],["new",78554.0,117830.0]],"prev_change_id":41152015378}}}
[2025-04-07 08:31:47.412] [multi_sink] [info] 📩 Received: {"jsonrpc":"2.0","method":"subscription","params":{"channel":"book.ETH-PERPETUAL.100ms","data":{"timestamp":1743994909044,"type":"change","change_id":23707235474,"instrument_name":"ETH-PERPETUAL","bids":[["delete",1575.75,0.0],["new",1575.7,748.0],["change",1575.65,11904.0],["change",1575.55,50512.0],["change",1575.5,11742.0],["change",1575.45,1173.0],["change",1575.4,1023.0],["change",1575.35,10576.0]],"asks":[["delete",1575.8,0.0],["delete",1575.9,0.0],["delete",1576.0,0.0],["delete",1576.05,0.0],["delete",1576.1,0.0],["delete",1576.15,0.0],["delete",1576.2,0.0],["new",1577.25,16585.0],["new",1577.3,7596.0],["new",1577.35,8632.0],["new",1577.4,9923.0],["new",1577.45,16380.0],["new",1577.5,63306.0],["new",1577.55,40823.0]],"prev_change_id":23707230313}}}
[2025-04-07 08:31:47.414] [multi_sink] [info] Processing received message: {"jsonrpc":"2.0","method":"subscription","params":{"channel":"book.ETH-PERPETUAL.100ms","data":{"timestamp":1743994909044,"type":"change","change_id":23707235474,"instrument_name":"ETH-PERPETUAL","bids":[["delete",1575.75,0.0],["new",1575.7,748.0],["change",1575.65,11904.0],["change",1575.55,50512.0],["change",1575.5,11742.0],["change",1575.45,1173.0],["change",1575.4,1023.0],["change",1575.35,10576.0]],"asks":[["delete",1575.8,0.0],["delete",1575.9,0.0],["delete",1576.0,0.0],["delete",1576.05,0.0],["delete",1576.1,0.0],["delete",1576.15,0.0],["delete",1576.2,0.0],["new",1577.25,16585.0],["new",1577.3,7596.0],["new",1577.35,8632.0],["new",1577.4,9923.0],["new",1577.45,16380.0],["new",1577.5,63306.0],["new",1577.55,40823.0]],"prev_change_id":23707230313}}}
[2025-04-07 08:31:47.653] [multi_sink] [info] 📩 Received: {"jsonrpc":"2.0","method":"subscription","params":{"channel":"book.BTC-PERPETUAL.100ms","data":{"timestamp":1743994909085,"type":"change","change_id":41152016368,"instrument_name":"BTC-PERPETUAL","bids":[],"asks":[["delete",78342.5,0.0],["new",78375.0,6640830.0],["delete",78495.5,0.0],["new",78528.0,7777770.0]],"prev_change_id":41152015967}}}
[2025-04-07 08:31:47.656] [multi_sink] [info] Processing received message: {"jsonrpc":"2.0","method":"subscription","params":{"channel":"book.BTC-PERPETUAL.100ms","data":{"timestamp":1743994909085,"type":"change","change_id":41152016368,"instrument_name":"BTC-PERPETUAL","bids":[],"asks":[["delete",78342.5,0.0],["new",78375.0,6640830.0],["delete",78495.5,0.0],["new",78528.0,7777770.0]],"prev_change_id":41152015967}}}
[2025-04-07 08:31:47.742] [multi_sink] [info] 📩 Received: {"jsonrpc":"2.0","method":"subscription","params":{"channel":"book.ETH-PERPETUAL.100ms","data":{"timestamp":1743994909361,"type":"change","change_id":23707235805,"instrument_name":"ETH-PERPETUAL","bids":[["new",1576.1,100.0],["new",1576.05,37541.0],["new",1576.0,9710.0],["new",1575.95,50862.0],["new",1575.9,1023.0],["new",1575.85,2730.0],["new",1575.8,100.0],["new",1575.75,9001.0],["delete",1575.3,0.0],["delete",1575.25,0.0],["delete",1575.2,0.0],["delete",1575.15,0.0],["delete",1575.1,0.0],["delete",1575.05,0.0],["delete",1575.0,0.0],["delete",1574.95,0.0]],"asks":[["delete",1576.25,0.0],["change",1576.3,6111993.0],["delete",1576.35,0.0],["delete",1576.4,0.0],["delete",1576.45,0.0],["delete",1576.5,0.0],["delete",1576.55,0.0],["delete",1576.6,0.0],["delete",1576.65,0.0],["change",1576.8,5923.0],["change",1576.85,38858.0],["new",1576.9,1905.0],["new",1576.95,5.0e3],["new",1577.0,6732.0],["new",1577.05,6274.0],["new",1577.1,35788.0],["new",1577.15,74343.0],["new",1577.2,20509.0]],"prev_change_id":23707235474}}}
[2025-04-07 08:31:47.745] [multi_sink] [info] Processing received message: {"jsonrpc":"2.0","method":"subscription","params":{"channel":"book.ETH-PERPETUAL.100ms","data":{"timestamp":1743994909361,"type":"change","change_id":23707235805,"instrument_name":"ETH-PERPETUAL","bids":[["new",1576.1,100.0],["new",1576.05,37541.0],["new",1576.0,9710.0],["new",1575.95,50862.0],["new",1575.9,1023.0],["new",1575.85,2730.0],["new",1575.8,100.0],["new",1575.75,9001.0],["delete",1575.3,0.0],["delete",1575.25,0.0],["delete",1575.2,0.0],["delete",1575.15,0.0],["delete",1575.1,0.0],["delete",1575.05,0.0],["delete",1575.0,0.0],["delete",1574.95,0.0]],"asks":[["delete",1576.25,0.0],["change",1576.3,6111993.0],["delete",1576.35,0.0],["delete",1576.4,0.0],["delete",1576.45,0.0],["delete",1576.5,0.0],["delete",1576.55,0.0],["delete",1576.6,0.0],["delete",1576.65,0.0],["change",1576.8,5923.0],["change",1576.85,38858.0],["new",1576.9,1905.0],["new",1576.95,5.0e3],["new",1577.0,6732.0],["new",1577.05,6274.0],["new",1577.1,35788.0],["new",1577.15,74343.0],["new",1577.2,20509.0]],"prev_change_id":23707235474}}}
[2025-04-07 08:31:47.982] [multi_sink] [info] 📩 Received: {"jsonrpc":"2.0","method":"subscription","params":{"channel":"book.BTC-PERPETUAL.100ms","data":{"timestamp":1743994909534,"type":"change","change_id":41152017079,"instrument_name":"BTC-PERPETUAL","bids":[],"asks":[["delete",78504.0,0.0],["delete",78554.0,0.0]],"prev_change_id":41152016368}}}
[2025-04-07 08:31:47.984] [multi_sink] [info] Processing received message: {"jsonrpc":"2.0","method":"subscription","params":{"channel":"book.BTC-PERPETUAL.100ms","data":{"timestamp":1743994909534,"type":"change","change_id":41152017079,"instrument_name":"BTC-PERPETUAL","bids":[],"asks":[["delete",78504.0,0.0],["delete",78554.0,0.0]],"prev_change_id":41152016368}}}
[2025-04-07 08:31:48.072] [multi_sink] [info] 📩 Received: {"jsonrpc":"2.0","method":"subscription","params":{"channel":"book.ETH-PERPETUAL.100ms","data":{"timestamp":1743994909533,"type":"change","change_id":23707236050,"instrument_name":"ETH-PERPETUAL","bids":[["new",1576.25,100.0],["new",1576.2,41330.0],["new",1576.15,75638.0],["delete",1574.9,0.0],["change",1574.8,7545952.0],["delete",1574.75,0.0],["delete",1574.7,0.0],["delete",1574.65,0.0]],"asks":[["change",1576.3,6063087.0],["new",1576.5,210.0],["new",1576.6,17564.0],["new",1576.65,9898.0],["delete",1576.7,0.0],["change",1576.75,1.5e3],["change",1576.8,5.0e3],["change",1576.85,100.0]],"prev_change_id":23707235805}}}
[2025-04-07 08:31:48.072] [multi_sink] [info] Processing received message: {"jsonrpc":"2.0","method":"subscription","params":{"channel":"book.ETH-PERPETUAL.100ms","data":{"timestamp":1743994909533,"type":"change","change_id":23707236050,"instrument_name":"ETH-PERPETUAL","bids":[["new",1576.25,100.0],["new",1576.2,41330.0],["new",1576.15,75638.0],["delete",1574.9,0.0],["change",1574.8,7545952.0],["delete",1574.75,0.0],["delete",1574.7,0.0],["delete",1574.65,0.0]],"asks":[["change",1576.3,6063087.0],["new",1576.5,210.0],["new",1576.6,17564.0],["new",1576.65,9898.0],["delete",1576.7,0.0],["change",1576.75,1.5e3],["change",1576.8,5.0e3],["change",1576.85,100.0]],"prev_change_id":23707235805}}}
[2025-04-07 08:31:48.738] [multi_sink] [info] 📩 Received: {"jsonrpc":"2.0","method":"subscription","params":{"channel":"book.BTC-PERPETUAL.100ms","data":{"timestamp":1743994910371,"type":"change","change_id":41152018295,"instrument_name":"BTC-PERPETUAL","bids":[],"asks":[["delete",78330.0,0.0],["change",78345.0,35080.0]],"prev_change_id":41152017079}}}
[2025-04-07 08:31:48.742] [multi_sink] [info] Processing received message: {"jsonrpc":"2.0","method":"subscription","params":{"channel":"book.BTC-PERPETUAL.100ms","data":{"timestamp":1743994910371,"type":"change","change_id":41152018295,"instrument_name":"BTC-PERPETUAL","bids":[],"asks":[["delete",78330.0,0.0],["change",78345.0,35080.0]],"prev_change_id":41152017079}}}
[2025-04-07 08:31:49.074] [multi_sink] [info] 📩 Received: {"jsonrpc":"2.0","method":"subscription","params":{"channel":"book.BTC-PERPETUAL.100ms","data":{"timestamp":1743994910701,"type":"change","change_id":41152018624,"instrument_name":"BTC-PERPETUAL","bids":[["delete",78329.5,0.0],["delete",78322.5,0.0],["delete",78320.0,0.0],["delete",78319.5,0.0],["delete",78319.0,0.0],["delete",78318.5,0.0],["delete",78318.0,0.0],["delete",78317.5,0.0],["delete",78317.0,0.0],["delete",78316.0,0.0],["new",78305.0,39890.0],["change",78304.0,151980.0],["change",78303.5,1010.0],["new",78301.0,490.0],["new",78300.5,2870.0],["new",7.83e4,2880.0],["new",78299.0,30960.0],["new",78298.5,49470.0],["new",78298.0,5180.0],["change",78297.5,7826440.0]],"asks":[["delete",78331.0,0.0],["delete",78331.5,0.0],["new",78332.5,1.0e4],["delete",78334.0,0.0],["delete",78334.5,0.0],["delete",78335.5,0.0],["new",78336.0,83160.0],["change",78337.0,22090.0],["new",78337.5,37610.0],["delete",78338.5,0.0],["new",78340.0,36150.0],["new",78340.5,3970.0],["change",78341.0,13750.0],["delete",78341.5,0.0],["new",78342.5,170.0],["change",78344.5,35040.0]],"prev_change_id":41152018295}}}
[2025-04-07 08:31:49.076] [multi_sink] [info] Processing received message: {"jsonrpc":"2.0","method":"subscription","params":{"channel":"book.BTC-PERPETUAL.100ms","data":{"timestamp":1743994910701,"type":"change","change_id":41152018624,"instrument_name":"BTC-PERPETUAL","bids":[["delete",78329.5,0.0],["delete",78322.5,0.0],["delete",78320.0,0.0],["delete",78319.5,0.0],["delete",78319.0,0.0],["delete",78318.5,0.0],["delete",78318.0,0.0],["delete",78317.5,0.0],["delete",78317.0,0.0],["delete",78316.0,0.0],["new",78305.0,39890.0],["change",78304.0,151980.0],["change",78303.5,1010.0],["new",78301.0,490.0],["new",78300.5,2870.0],["new",7.83e4,2880.0],["new",78299.0,30960.0],["new",78298.5,49470.0],["new",78298.0,5180.0],["change",78297.5,7826440.0]],"asks":[["delete",78331.0,0.0],["delete",78331.5,0.0],["new",78332.5,1.0e4],["delete",78334.0,0.0],["delete",78334.5,0.0],["delete",78335.5,0.0],["new",78336.0,83160.0],["change",78337.0,22090.0],["new",78337.5,37610.0],["delete",78338.5,0.0],["new",78340.0,36150.0],["new",78340.5,3970.0],["change",78341.0,13750.0],["delete",78341.5,0.0],["new",78342.5,170.0],["change",78344.5,35040.0]],"prev_change_id":41152018295}}}
[2025-04-07 08:31:49.401] [multi_sink] [info] 📩 Received: {"jsonrpc":"2.0","method":"subscription","params":{"channel":"book.BTC-PERPETUAL.100ms","data":{"timestamp":1743994911032,"type":"change","change_id":41152019242,"instrument_name":"BTC-PERPETUAL","bids":[["new",78321.5,430.0],["new",78319.0,470.0],["new",78316.5,510.0],["delete",78315.5,0.0],["delete",78315.0,0.0],["new",78314.0,550.0],["delete",78312.0,0.0],["new",78310.5,240.0],["change",78310.0,2830.0],["new",78309.5,9430.0],["delete",78308.5,0.0],["new",78308.0,15540.0],["delete",78307.0,0.0],["new",78306.5,1.0e3],["delete",78306.0,0.0],["delete",78304.5,0.0],["change",78304.0,1980.0],["new",78145.5,78140.0],["new",78095.5,117140.0]],"asks":[["new",78325.5,35120.0],["new",78326.0,19830.0],["new",78327.0,79480.0],["new",78327.5,2.11e4],["new",78328.0,11150.0],["new",78328.5,9430.0],["new",78331.0,2.2e4],["new",78331.5,1.65e4],["new",78332.0,38260.0],["delete",78344.0,0.0],["change",78344.5,5180.0],["change",78345.0,420.0],["delete",78346.0,0.0],["delete",78346.5,0.0],["delete",78347.5,0.0],["delete",78348.0,0.0],["new",78475.5,78470.0],["new",78525.5,117780.0]],"prev_change_id":41152018624}}}
[2025-04-07 08:31:49.403] [multi_sink] [info] Processing received message: {"jsonrpc":"2.0","method":"subscription","params":{"channel":"book.BTC-PERPETUAL.100ms","data":{"timestamp":1743994911032,"type":"change","change_id":41152019242,"instrument_name":"BTC-PERPETUAL","bids":[["new",78321.5,430.0],["new",78319.0,470.0],["new",78316.5,510.0],["delete",78315.5,0.0],["delete",78315.0,0.0],["new",78314.0,550.0],["delete",78312.0,0.0],["new",78310.5,240.0],["change",78310.0,2830.0],["new",78309.5,9430.0],["delete",78308.5,0.0],["new",78308.0,15540.0],["delete",78307.0,0.0],["new",78306.5,1.0e3],["delete",78306.0,0.0],["delete",78304.5,0.0],["change",78304.0,1980.0],["new",78145.5,78140.0],["new",78095.5,117140.0]],"asks":[["new",78325.5,35120.0],["new",78326.0,19830.0],["new",78327.0,79480.0],["new",78327.5,2.11e4],["new",78328.0,11150.0],["new",78328.5,9430.0],["new",78331.0,2.2e4],["new",78331.5,1.65e4],["new",78332.0,38260.0],["delete",78344.0,0.0],["change",78344.5,5180.0],["change",78345.0,420.0],["delete",78346.0,0.0],["delete",78346.5,0.0],["delete",78347.5,0.0],["delete",78348.0,0.0],["new",78475.5,78470.0],["new",78525.5,117780.0]],"prev_change_id":41152018624}}}
[2025-04-07 08:31:49.729] [multi_sink] [info] 📩 Received: {"jsonrpc":"2.0","method":"subscription","params":{"channel":"book.BTC-PERPETUAL.100ms","data":{"timestamp":1743994911067,"type":"change","change_id":41152019259,"instrument_name":"BTC-PERPETUAL","bids":[["new",78324.0,510.0],["change",78303.5,360.0]],"asks":[["new",78324.5,134410.0]],"prev_change_id":41152019242}}}
[2025-04-07 08:31:49.733] [multi_sink] [info] Processing received message: {"jsonrpc":"2.0","method":"subscription","params":{"channel":"book.BTC-PERPETUAL.100ms","data":{"timestamp":1743994911067,"type":"change","change_id":41152019259,"instrument_name":"BTC-PERPETUAL","bids":[["new",78324.0,510.0],["change",78303.5,360.0]],"asks":[["new",78324.5,134410.0]],"prev_change_id":41152019242}}}
[2025-04-07 08:31:49.760] [multi_sink] [info] 📩 Received: {"jsonrpc":"2.0","method":"subscription","params":{"channel":"book.ETH-PERPETUAL.100ms","data":{"timestamp":1743994911338,"type":"change","change_id":23707237917,"instrument_name":"ETH-PERPETUAL","bids":[["change",1575.7,7.5467e6],["delete",1574.8,0.0]],"asks":[],"prev_change_id":23707236050}}}
[2025-04-07 08:31:49.764] [multi_sink] [info] Processing received message: {"jsonrpc":"2.0","method":"subscription","params":{"channel":"book.ETH-PERPETUAL.100ms","data":{"timestamp":1743994911338,"type":"change","change_id":23707237917,"instrument_name":"ETH-PERPETUAL","bids":[["change",1575.7,7.5467e6],["delete",1574.8,0.0]],"asks":[],"prev_change_id":23707236050}}}
[2025-04-07 08:31:50.086] [multi_sink] [info] 📩 Received: {"jsonrpc":"2.0","method":"subscription","params":{"channel":"book.ETH-PERPETUAL.100ms","data":{"timestamp":1743994911673,"type":"change","change_id":23707238139,"instrument_name":"ETH-PERPETUAL","bids":[],"asks":[["delete",1576.3,0.0],["change",1577.2,6083596.0]],"prev_change_id":23707237917}}}
[2025-04-07 08:31:50.088] [multi_sink] [info] Processing received message: {"jsonrpc":"2.0","method":"subscription","params":{"channel":"book.ETH-PERPETUAL.100ms","data":{"timestamp":1743994911673,"type":"change","change_id":23707238139,"instrument_name":"ETH-PERPETUAL","bids":[],"asks":[["delete",1576.3,0.0],["change",1577.2,6083596.0]],"prev_change_id":23707237917}}}
[2025-04-07 08:31:52.457] [multi_sink] [info] 📩 Received: {"jsonrpc":"2.0","method":"subscription","params":{"channel":"book.ETH-PERPETUAL.100ms","data":{"timestamp":1743994914078,"type":"change","change_id":23707240754,"instrument_name":"ETH-PERPETUAL","bids":[["delete",1576.25,0.0],["delete",1576.2,0.0],["delete",1576.15,0.0],["delete",1576.1,0.0],["delete",1576.05,0.0],["delete",1576.0,0.0],["delete",1575.95,0.0],["change",1575.55,65412.0],["change",1575.5,20228.0],["change",1575.45,82413.0],["change",1575.4,5845.0],["change",1575.35,21072.0],["new",1575.3,32847.0],["new",1575.25,773.0]],"asks":[["delete",1576.5,0.0],["delete",1576.6,0.0],["delete",1576.65,0.0],["delete",1576.75,0.0],["delete",1576.8,0.0],["delete",1576.85,0.0],["delete",1576.9,0.0],["delete",1576.95,0.0],["change",1577.35,23264.0],["change",1577.4,10926.0],["change",1577.45,17303.0],["change",1577.5,67786.0],["change",1577.55,41846.0],["new",1577.6,16337.0],["new",1577.65,60358.0],["new",1577.7,6971.0]],"prev_change_id":23707238139}}}
[2025-04-07 08:31:52.461] [multi_sink] [info] Processing received message: {"jsonrpc":"2.0","method":"subscription","params":{"channel":"book.ETH-PERPETUAL.100ms","data":{"timestamp":1743994914078,"type":"change","change_id":23707240754,"instrument_name":"ETH-PERPETUAL","bids":[["delete",1576.25,0.0],["delete",1576.2,0.0],["delete",1576.15,0.0],["delete",1576.1,0.0],["delete",1576.05,0.0],["delete",1576.0,0.0],["delete",1575.95,0.0],["change",1575.55,65412.0],["change",1575.5,20228.0],["change",1575.45,82413.0],["change",1575.4,5845.0],["change",1575.35,21072.0],["new",1575.3,32847.0],["new",1575.25,773.0]],"asks":[["delete",1576.5,0.0],["delete",1576.6,0.0],["delete",1576.65,0.0],["delete",1576.75,0.0],["delete",1576.8,0.0],["delete",1576.85,0.0],["delete",1576.9,0.0],["delete",1576.95,0.0],["change",1577.35,23264.0],["change",1577.4,10926.0],["change",1577.45,17303.0],["change",1577.5,67786.0],["change",1577.55,41846.0],["new",1577.6,16337.0],["new",1577.65,60358.0],["new",1577.7,6971.0]],"prev_change_id":23707238139}}}
[2025-04-07 08:31:52.780] [multi_sink] [info] 📩 Received: {"jsonrpc":"2.0","method":"subscription","params":{"channel":"book.ETH-PERPETUAL.100ms","data":{"timestamp":1743994914401,"type":"change","change_id":23707240997,"instrument_name":"ETH-PERPETUAL","bids":[["new",1576.15,7.14e4],["new",1576.0,9022.0],["new",1575.95,16559.0],["change",1575.9,21289.0],["change",1575.85,3653.0],["change",1575.8,2512.0],["change",1575.75,8901.0],["change",1575.7,7548834.0],["change",1575.65,100.0],["change",1575.55,1.49e4],["change",1575.5,8486.0],["change",1575.45,81240.0]],"asks":[["new",1576.9,4104.0],["new",1576.95,13122.0],["change",1577.0,1283.0],["change",1577.05,100.0],["change",1577.1,43965.0],["change",1577.15,85502.0],["change",1577.2,6076424.0],["change",1577.25,40908.0],["change",1577.3,923.0],["change",1577.35,14632.0],["change",1577.4,1003.0]],"prev_change_id":23707240754}}}
[2025-04-07 08:31:52.781] [multi_sink] [info] Processing received message: {"jsonrpc":"2.0","method":"subscription","params":{"channel":"book.ETH-PERPETUAL.100ms","data":{"timestamp":1743994914401,"type":"change","change_id":23707240997,"instrument_name":"ETH-PERPETUAL","bids":[["new",1576.15,7.14e4],["new",1576.0,9022.0],["new",1575.95,16559.0],["change",1575.9,21289.0],["change",1575.85,3653.0],["change",1575.8,2512.0],["change",1575.75,8901.0],["change",1575.7,7548834.0],["change",1575.65,100.0],["change",1575.55,1.49e4],["change",1575.5,8486.0],["change",1575.45,81240.0]],"asks":[["new",1576.9,4104.0],["new",1576.95,13122.0],["change",1577.0,1283.0],["change",1577.05,100.0],["change",1577.1,43965.0],["change",1577.15,85502.0],["change",1577.2,6076424.0],["change",1577.25,40908.0],["change",1577.3,923.0],["change",1577.35,14632.0],["change",1577.4,1003.0]],"prev_change_id":23707240754}}}
[2025-04-07 08:31:53.111] [multi_sink] [info] 📩 Received: {"jsonrpc":"2.0","method":"subscription","params":{"channel":"book.ETH-PERPETUAL.100ms","data":{"timestamp":1743994914536,"type":"change","change_id":23707241166,"instrument_name":"ETH-PERPETUAL","bids":[["new",1576.45,12654.0],["new",1576.3,1.5e3],["new",1576.25,5.0e3],["new",1576.2,29832.0],["change",1575.4,4822.0],["change",1575.35,10496.0]],"asks":[["new",1576.5,33083.0],["new",1576.65,2969.0],["new",1576.7,9897.0],["change",1577.45,923.0],["change",1577.5,4480.0],["change",1577.55,1023.0]],"prev_change_id":23707240997}}}
[2025-04-07 08:31:53.112] [multi_sink] [info] Processing received message: {"jsonrpc":"2.0","method":"subscription","params":{"channel":"book.ETH-PERPETUAL.100ms","data":{"timestamp":1743994914536,"type":"change","change_id":23707241166,"instrument_name":"ETH-PERPETUAL","bids":[["new",1576.45,12654.0],["new",1576.3,1.5e3],["new",1576.25,5.0e3],["new",1576.2,29832.0],["change",1575.4,4822.0],["change",1575.35,10496.0]],"asks":[["new",1576.5,33083.0],["new",1576.65,2969.0],["new",1576.7,9897.0],["change",1577.45,923.0],["change",1577.5,4480.0],["change",1577.55,1023.0]],"prev_change_id":23707240997}}}
[2025-04-07 08:31:53.372] [multi_sink] [info] 📩 Received: {"jsonrpc":"2.0","method":"subscription","params":{"channel":"book.BTC-PERPETUAL.100ms","data":{"timestamp":1743994914981,"type":"change","change_id":41152024943,"instrument_name":"BTC-PERPETUAL","bids":[],"asks":[["delete",78475.5,0.0],["new",78486.0,78480.0],["delete",78525.5,0.0],["new",78536.0,1.178e5]],"prev_change_id":41152019259}}}
[2025-04-07 08:31:53.375] [multi_sink] [info] Processing received message: {"jsonrpc":"2.0","method":"subscription","params":{"channel":"book.BTC-PERPETUAL.100ms","data":{"timestamp":1743994914981,"type":"change","change_id":41152024943,"instrument_name":"BTC-PERPETUAL","bids":[],"asks":[["delete",78475.5,0.0],["new",78486.0,78480.0],["delete",78525.5,0.0],["new",78536.0,1.178e5]],"prev_change_id":41152019259}}}
[2025-04-07 08:31:54.033] [multi_sink] [info] 📩 Received: {"jsonrpc":"2.0","method":"subscription","params":{"channel":"book.BTC-PERPETUAL.100ms","data":{"timestamp":1743994915640,"type":"change","change_id":41152025909,"instrument_name":"BTC-PERPETUAL","bids":[["delete",78324.0,0.0],["delete",78321.5,0.0],["delete",78319.0,0.0],["delete",78316.5,0.0],["delete",78314.0,0.0],["delete",78310.5,0.0],["delete",78310.0,0.0],["delete",78309.5,0.0],["change",78298.0,10360.0],["change",78297.5,7827160.0],["new",78296.5,45180.0],["new",78296.0,11870.0],["new",78295.5,33820.0],["new",78293.5,5180.0],["new",78291.5,8.31e4],["new",78291.0,1.0e3],["new",78156.0,78150.0],["delete",78145.5,0.0],["new",78106.0,117150.0],["delete",78095.5,0.0]],"asks":[["delete",78324.5,0.0],["delete",78325.5,0.0],["delete",78326.0,0.0],["delete",78327.0,0.0],["delete",78327.5,0.0],["delete",78328.0,0.0],["delete",78328.5,0.0],["delete",78331.0,0.0],["change",78341.0,2.75e4],["change",78342.5,28160.0],["new",78343.0,14620.0],["new",78344.0,1.65e4],["change",78344.5,10360.0],["change",78345.0,650.0],["new",78345.5,8150.0],["new",78346.0,21990.0]],"prev_change_id":41152024943}}}
[2025-04-07 08:31:54.034] [multi_sink] [info] Processing received message: {"jsonrpc":"2.0","method":"subscription","params":{"channel":"book.BTC-PERPETUAL.100ms","data":{"timestamp":1743994915640,"type":"change","change_id":41152025909,"instrument_name":"BTC-PERPETUAL","bids":[["delete",78324.0,0.0],["delete",78321.5,0.0],["delete",78319.0,0.0],["delete",78316.5,0.0],["delete",78314.0,0.0],["delete",78310.5,0.0],["delete",78310.0,0.0],["delete",78309.5,0.0],["change",78298.0,10360.0],["change",78297.5,7827160.0],["new",78296.5,45180.0],["new",78296.0,11870.0],["new",78295.5,33820.0],["new",78293.5,5180.0],["new",78291.5,8.31e4],["new",78291.0,1.0e3],["new",78156.0,78150.0],["delete",78145.5,0.0],["new",78106.0,117150.0],["delete",78095.5,0.0]],"asks":[["delete",78324.5,0.0],["delete",78325.5,0.0],["delete",78326.0,0.0],["delete",78327.0,0.0],["delete",78327.5,0.0],["delete",78328.0,0.0],["delete",78328.5,0.0],["delete",78331.0,0.0],["change",78341.0,2.75e4],["change",78342.5,28160.0],["new",78343.0,14620.0],["new",78344.0,1.65e4],["change",78344.5,10360.0],["change",78345.0,650.0],["new",78345.5,8150.0],["new",78346.0,21990.0]],"prev_change_id":41152024943}}}
[2025-04-07 08:31:54.363] [multi_sink] [info] 📩 Received: {"jsonrpc":"2.0","method":"subscription","params":{"channel":"book.BTC-PERPETUAL.100ms","data":{"timestamp":1743994915977,"type":"change","change_id":41152026397,"instrument_name":"BTC-PERPETUAL","bids":[["delete",78308.0,0.0],["delete",78306.5,0.0],["new",78305.5,470.0],["change",78305.0,26990.0],["new",78304.5,45180.0],["change",78304.0,49960.0],["change",78301.0,5180.0],["change",78300.5,2760.0],["change",7.83e4,17310.0],["change",78299.0,9430.0],["change",78297.5,1440.0],["new",78285.5,7825720.0],["delete",78144.5,0.0],["new",78132.5,8000580.0]],"asks":[["delete",78331.5,0.0],["change",78332.0,6.0e3],["delete",78332.5,0.0],["new",78333.5,1870.0],["new",78334.0,5740.0],["delete",78336.0,0.0],["new",78336.5,19510.0],["change",78337.0,20770.0],["change",78337.5,3.45e4],["change",78340.0,34720.0],["change",78340.5,26570.0],["change",78341.0,13750.0]],"prev_change_id":41152025909}}}
[2025-04-07 08:31:54.372] [multi_sink] [info] Processing received message: {"jsonrpc":"2.0","method":"subscription","params":{"channel":"book.BTC-PERPETUAL.100ms","data":{"timestamp":1743994915977,"type":"change","change_id":41152026397,"instrument_name":"BTC-PERPETUAL","bids":[["delete",78308.0,0.0],["delete",78306.5,0.0],["new",78305.5,470.0],["change",78305.0,26990.0],["new",78304.5,45180.0],["change",78304.0,49960.0],["change",78301.0,5180.0],["change",78300.5,2760.0],["change",7.83e4,17310.0],["change",78299.0,9430.0],["change",78297.5,1440.0],["new",78285.5,7825720.0],["delete",78144.5,0.0],["new",78132.5,8000580.0]],"asks":[["delete",78331.5,0.0],["change",78332.0,6.0e3],["delete",78332.5,0.0],["new",78333.5,1870.0],["new",78334.0,5740.0],["delete",78336.0,0.0],["new",78336.5,19510.0],["change",78337.0,20770.0],["change",78337.5,3.45e4],["change",78340.0,34720.0],["change",78340.5,26570.0],["change",78341.0,13750.0]],"prev_change_id":41152025909}}}
[2025-04-07 08:31:54.693] [multi_sink] [info] 📩 Received: {"jsonrpc":"2.0","method":"subscription","params":{"channel":"book.BTC-PERPETUAL.100ms","data":{"timestamp":1743994916306,"type":"change","change_id":41152027167,"instrument_name":"BTC-PERPETUAL","bids":[["new",78324.0,960.0],["new",78308.5,1550.0],["new",78308.0,5180.0],["delete",78298.5,0.0],["change",78298.0,5180.0],["change",78297.5,720.0]],"asks":[["new",78324.5,35460.0],["new",78327.0,1.0e4],["new",78331.5,1.8e3],["change",78342.5,27990.0],["change",78344.5,5180.0],["change",78345.0,230.0],["new",78363.0,6640830.0],["delete",78375.0,0.0],["new",78516.0,7777770.0],["delete",78528.0,0.0]],"prev_change_id":41152026397}}}
[2025-04-07 08:31:54.694] [multi_sink] [info] Processing received message: {"jsonrpc":"2.0","method":"subscription","params":{"channel":"book.BTC-PERPETUAL.100ms","data":{"timestamp":1743994916306,"type":"change","change_id":41152027167,"instrument_name":"BTC-PERPETUAL","bids":[["new",78324.0,960.0],["new",78308.5,1550.0],["new",78308.0,5180.0],["delete",78298.5,0.0],["change",78298.0,5180.0],["change",78297.5,720.0]],"asks":[["new",78324.5,35460.0],["new",78327.0,1.0e4],["new",78331.5,1.8e3],["change",78342.5,27990.0],["change",78344.5,5180.0],["change",78345.0,230.0],["new",78363.0,6640830.0],["delete",78375.0,0.0],["new",78516.0,7777770.0],["delete",78528.0,0.0]],"prev_change_id":41152026397}}}
[2025-04-07 08:31:56.726] [multi_sink] [info] 📩 Received: {"jsonrpc":"2.0","method":"subscription","params":{"channel":"book.BTC-PERPETUAL.100ms","data":{"timestamp":1743994918143,"type":"change","change_id":41152029543,"instrument_name":"BTC-PERPETUAL","bids":[["new",78167.5,78160.0],["delete",78156.0,0.0],["new",78117.5,117160.0],["delete",78106.0,0.0]],"asks":[["delete",78486.0,0.0],["new",78498.0,78490.0],["delete",78536.0,0.0],["new",78548.0,117810.0]],"prev_change_id":41152027167}}}
[2025-04-07 08:31:56.728] [multi_sink] [info] Processing received message: {"jsonrpc":"2.0","method":"subscription","params":{"channel":"book.BTC-PERPETUAL.100ms","data":{"timestamp":1743994918143,"type":"change","change_id":41152029543,"instrument_name":"BTC-PERPETUAL","bids":[["new",78167.5,78160.0],["delete",78156.0,0.0],["new",78117.5,117160.0],["delete",78106.0,0.0]],"asks":[["delete",78486.0,0.0],["new",78498.0,78490.0],["delete",78536.0,0.0],["new",78548.0,117810.0]],"prev_change_id":41152027167}}}
[2025-04-07 08:31:56.913] [multi_sink] [info] 📩 Received: {"jsonrpc":"2.0","method":"subscription","params":{"channel":"book.ETH-PERPETUAL.100ms","data":{"timestamp":1743994918543,"type":"change","change_id":23707245216,"instrument_name":"ETH-PERPETUAL","bids":[["change",1576.0,7554974.0],["change",1575.7,2882.0]],"asks":[],"prev_change_id":23707241166}}}
[2025-04-07 08:31:56.914] [multi_sink] [info] Processing received message: {"jsonrpc":"2.0","method":"subscription","params":{"channel":"book.ETH-PERPETUAL.100ms","data":{"timestamp":1743994918543,"type":"change","change_id":23707245216,"instrument_name":"ETH-PERPETUAL","bids":[["change",1576.0,7554974.0],["change",1575.7,2882.0]],"asks":[],"prev_change_id":23707241166}}}
[2025-04-07 08:31:57.241] [multi_sink] [info] 📩 Received: {"jsonrpc":"2.0","method":"subscription","params":{"channel":"book.ETH-PERPETUAL.100ms","data":{"timestamp":1743994918861,"type":"change","change_id":23707245393,"instrument_name":"ETH-PERPETUAL","bids":[["delete",1576.45,0.0],["delete",1576.3,0.0],["change",1576.25,6367.0],["change",1576.2,33956.0]],"asks":[["delete",1576.5,0.0],["delete",1576.65,0.0],["new",1578.4,23469.0],["new",1578.45,4677.0]],"prev_change_id":23707245216}}}
[2025-04-07 08:31:57.243] [multi_sink] [info] Processing received message: {"jsonrpc":"2.0","method":"subscription","params":{"channel":"book.ETH-PERPETUAL.100ms","data":{"timestamp":1743994918861,"type":"change","change_id":23707245393,"instrument_name":"ETH-PERPETUAL","bids":[["delete",1576.45,0.0],["delete",1576.3,0.0],["change",1576.25,6367.0],["change",1576.2,33956.0]],"asks":[["delete",1576.5,0.0],["delete",1576.65,0.0],["new",1578.4,23469.0],["new",1578.45,4677.0]],"prev_change_id":23707245216}}}
[2025-04-07 08:31:57.572] [multi_sink] [info] 📩 Received: {"jsonrpc":"2.0","method":"subscription","params":{"channel":"book.ETH-PERPETUAL.100ms","data":{"timestamp":1743994919185,"type":"change","change_id":23707246096,"instrument_name":"ETH-PERPETUAL","bids":[["new",1576.7,96451.0],["new",1576.65,12450.0],["new",1576.6,100.0],["new",1576.55,15215.0],["new",1576.5,10105.0],["new",1576.45,39780.0],["new",1576.4,100.0],["new",1576.35,15781.0],["new",1576.3,7660.0],["change",1576.25,1367.0],["change",1576.2,4124.0],["delete",1576.15,0.0],["change",1576.0,7545952.0],["delete",1575.95,0.0],["delete",1575.9,0.0],["delete",1575.85,0.0],["delete",1575.8,0.0],["delete",1575.75,0.0]],"asks":[["delete",1576.7,0.0],["delete",1576.9,0.0],["delete",1576.95,0.0],["delete",1577.0,0.0],["delete",1577.05,0.0],["delete",1577.1,0.0],["delete",1577.15,0.0],["delete",1577.2,0.0],["delete",1577.25,0.0],["change",1577.5,6067567.0],["new",1577.95,8532.0],["new",1578.0,35785.0],["new",1578.05,86425.0],["new",1578.1,44723.0],["new",1578.15,8532.0],["new",1578.2,34988.0],["new",1578.25,11271.0],["new",1578.3,44583.0],["new",1578.35,57190.0]],"prev_change_id":23707245393}}}
[2025-04-07 08:31:57.573] [multi_sink] [info] Processing received message: {"jsonrpc":"2.0","method":"subscription","params":{"channel":"book.ETH-PERPETUAL.100ms","data":{"timestamp":1743994919185,"type":"change","change_id":23707246096,"instrument_name":"ETH-PERPETUAL","bids":[["new",1576.7,96451.0],["new",1576.65,12450.0],["new",1576.6,100.0],["new",1576.55,15215.0],["new",1576.5,10105.0],["new",1576.45,39780.0],["new",1576.4,100.0],["new",1576.35,15781.0],["new",1576.3,7660.0],["change",1576.25,1367.0],["change",1576.2,4124.0],["delete",1576.15,0.0],["change",1576.0,7545952.0],["delete",1575.95,0.0],["delete",1575.9,0.0],["delete",1575.85,0.0],["delete",1575.8,0.0],["delete",1575.75,0.0]],"asks":[["delete",1576.7,0.0],["delete",1576.9,0.0],["delete",1576.95,0.0],["delete",1577.0,0.0],["delete",1577.05,0.0],["delete",1577.1,0.0],["delete",1577.15,0.0],["delete",1577.2,0.0],["delete",1577.25,0.0],["change",1577.5,6067567.0],["new",1577.95,8532.0],["new",1578.0,35785.0],["new",1578.05,86425.0],["new",1578.1,44723.0],["new",1578.15,8532.0],["new",1578.2,34988.0],["new",1578.25,11271.0],["new",1578.3,44583.0],["new",1578.35,57190.0]],"prev_change_id":23707245393}}}
[2025-04-07 08:31:57.903] [multi_sink] [info] 📩 Received: {"jsonrpc":"2.0","method":"subscription","params":{"channel":"book.ETH-PERPETUAL.100ms","data":{"timestamp":1743994919524,"type":"change","change_id":23707246339,"instrument_name":"ETH-PERPETUAL","bids":[["new",1577.2,51364.0],["new",1577.15,2969.0],["new",1577.05,13676.0],["new",1577.0,100.0],["new",1576.95,23954.0],["new",1576.9,52410.0],["new",1576.85,9058.0],["new",1576.8,13992.0],["new",1576.75,44377.0],["delete",1575.7,0.0],["delete",1575.65,0.0],["delete",1575.55,0.0],["delete",1575.5,0.0],["delete",1575.45,0.0],["delete",1575.4,0.0],["delete",1575.35,0.0],["delete",1575.3,0.0],["delete",1575.25,0.0]],"asks":[["new",1577.25,486.0],["delete",1577.3,0.0],["delete",1577.35,0.0],["delete",1577.4,0.0],["delete",1577.45,0.0],["change",1577.5,6064193.0],["delete",1577.55,0.0],["change",1577.6,3061.0],["change",1577.65,15936.0],["change",1577.7,5723.0],["new",1577.75,19652.0],["new",1577.8,100.0],["new",1577.85,4860.0],["new",1577.9,15618.0],["delete",1580.35,0.0],["new",1581.95,500.0]],"prev_change_id":23707246096}}}
[2025-04-07 08:31:57.905] [multi_sink] [info] Processing received message: {"jsonrpc":"2.0","method":"subscription","params":{"channel":"book.ETH-PERPETUAL.100ms","data":{"timestamp":1743994919524,"type":"change","change_id":23707246339,"instrument_name":"ETH-PERPETUAL","bids":[["new",1577.2,51364.0],["new",1577.15,2969.0],["new",1577.05,13676.0],["new",1577.0,100.0],["new",1576.95,23954.0],["new",1576.9,52410.0],["new",1576.85,9058.0],["new",1576.8,13992.0],["new",1576.75,44377.0],["delete",1575.7,0.0],["delete",1575.65,0.0],["delete",1575.55,0.0],["delete",1575.5,0.0],["delete",1575.45,0.0],["delete",1575.4,0.0],["delete",1575.35,0.0],["delete",1575.3,0.0],["delete",1575.25,0.0]],"asks":[["new",1577.25,486.0],["delete",1577.3,0.0],["delete",1577.35,0.0],["delete",1577.4,0.0],["delete",1577.45,0.0],["change",1577.5,6064193.0],["delete",1577.55,0.0],["change",1577.6,3061.0],["change",1577.65,15936.0],["change",1577.7,5723.0],["new",1577.75,19652.0],["new",1577.8,100.0],["new",1577.85,4860.0],["new",1577.9,15618.0],["delete",1580.35,0.0],["new",1581.95,500.0]],"prev_change_id":23707246096}}}
[2025-04-07 08:31:58.743] [multi_sink] [info] 📩 Received: {"jsonrpc":"2.0","method":"subscription","params":{"channel":"book.BTC-PERPETUAL.100ms","data":{"timestamp":1743994920376,"type":"change","change_id":41152032796,"instrument_name":"BTC-PERPETUAL","bids":[],"asks":[["delete",78324.5,0.0],["new",78357.0,22720.0]],"prev_change_id":41152029543}}}
[2025-04-07 08:31:58.746] [multi_sink] [info] Processing received message: {"jsonrpc":"2.0","method":"subscription","params":{"channel":"book.BTC-PERPETUAL.100ms","data":{"timestamp":1743994920376,"type":"change","change_id":41152032796,"instrument_name":"BTC-PERPETUAL","bids":[],"asks":[["delete",78324.5,0.0],["new",78357.0,22720.0]],"prev_change_id":41152029543}}}
[2025-04-07 08:31:59.073] [multi_sink] [info] 📩 Received: {"jsonrpc":"2.0","method":"subscription","params":{"channel":"book.BTC-PERPETUAL.100ms","data":{"timestamp":1743994920699,"type":"change","change_id":41152033103,"instrument_name":"BTC-PERPETUAL","bids":[["delete",78324.0,0.0],["new",78320.0,5740.0],["new",78319.5,14840.0],["new",78318.0,16490.0],["new",78317.5,5180.0],["new",78317.0,1.0e4],["new",78316.0,34290.0],["new",78315.0,15280.0],["new",78314.0,5180.0],["new",78312.5,4.0e4],["delete",78308.5,0.0],["delete",78308.0,0.0],["delete",78305.5,0.0],["delete",78305.0,0.0],["delete",78304.5,0.0],["delete",78304.0,0.0],["delete",78303.5,0.0],["delete",78301.0,0.0]],"asks":[["delete",78327.0,0.0],["delete",78331.5,0.0],["delete",78332.0,0.0],["delete",78333.5,0.0],["delete",78334.0,0.0],["delete",78336.5,0.0],["delete",78337.0,0.0],["delete",78337.5,0.0],["delete",78340.0,0.0],["new",78351.0,2.93e4],["new",78351.5,81640.0],["new",78352.0,74440.0],["new",78352.5,34230.0],["new",78353.0,116160.0],["new",78353.5,20420.0],["new",78354.0,13770.0],["new",78355.0,36980.0],["new",78355.5,3.4e3]],"prev_change_id":41152032796}}}
[2025-04-07 08:31:59.075] [multi_sink] [info] Processing received message: {"jsonrpc":"2.0","method":"subscription","params":{"channel":"book.BTC-PERPETUAL.100ms","data":{"timestamp":1743994920699,"type":"change","change_id":41152033103,"instrument_name":"BTC-PERPETUAL","bids":[["delete",78324.0,0.0],["new",78320.0,5740.0],["new",78319.5,14840.0],["new",78318.0,16490.0],["new",78317.5,5180.0],["new",78317.0,1.0e4],["new",78316.0,34290.0],["new",78315.0,15280.0],["new",78314.0,5180.0],["new",78312.5,4.0e4],["delete",78308.5,0.0],["delete",78308.0,0.0],["delete",78305.5,0.0],["delete",78305.0,0.0],["delete",78304.5,0.0],["delete",78304.0,0.0],["delete",78303.5,0.0],["delete",78301.0,0.0]],"asks":[["delete",78327.0,0.0],["delete",78331.5,0.0],["delete",78332.0,0.0],["delete",78333.5,0.0],["delete",78334.0,0.0],["delete",78336.5,0.0],["delete",78337.0,0.0],["delete",78337.5,0.0],["delete",78340.0,0.0],["new",78351.0,2.93e4],["new",78351.5,81640.0],["new",78352.0,74440.0],["new",78352.5,34230.0],["new",78353.0,116160.0],["new",78353.5,20420.0],["new",78354.0,13770.0],["new",78355.0,36980.0],["new",78355.5,3.4e3]],"prev_change_id":41152032796}}}
[2025-04-07 08:31:59.409] [multi_sink] [info] 📩 Received: {"jsonrpc":"2.0","method":"subscription","params":{"channel":"book.BTC-PERPETUAL.100ms","data":{"timestamp":1743994921028,"type":"change","change_id":41152033786,"instrument_name":"BTC-PERPETUAL","bids":[["new",78325.0,21570.0],["new",78324.5,22280.0],["new",78324.0,240.0],["new",78323.5,490.0],["new",78323.0,32950.0],["new",78322.5,9430.0],["new",78322.0,16490.0],["new",78321.0,5180.0],["new",78320.5,56380.0],["delete",78300.5,0.0],["delete",7.83e4,0.0],["delete",78299.0,0.0],["delete",78298.0,0.0],["delete",78297.5,0.0],["delete",78296.5,0.0],["delete",78296.0,0.0],["delete",78295.5,0.0],["delete",78293.5,0.0]],"asks":[["new",78338.0,1.0e4],["new",78339.0,2.11e4],["delete",78340.5,0.0],["change",78341.0,490.0],["new",78341.5,1.0e4],["change",78342.5,2010.0],["delete",78343.0,0.0],["delete",78344.0,0.0],["change",78344.5,16990.0],["change",78345.0,10230.0],["delete",78345.5,0.0],["delete",78346.0,0.0],["new",78347.5,5740.0],["new",78348.0,44480.0]],"prev_change_id":41152033103}}}
[2025-04-07 08:31:59.410] [multi_sink] [info] Processing received message: {"jsonrpc":"2.0","method":"subscription","params":{"channel":"book.BTC-PERPETUAL.100ms","data":{"timestamp":1743994921028,"type":"change","change_id":41152033786,"instrument_name":"BTC-PERPETUAL","bids":[["new",78325.0,21570.0],["new",78324.5,22280.0],["new",78324.0,240.0],["new",78323.5,490.0],["new",78323.0,32950.0],["new",78322.5,9430.0],["new",78322.0,16490.0],["new",78321.0,5180.0],["new",78320.5,56380.0],["delete",78300.5,0.0],["delete",7.83e4,0.0],["delete",78299.0,0.0],["delete",78298.0,0.0],["delete",78297.5,0.0],["delete",78296.5,0.0],["delete",78296.0,0.0],["delete",78295.5,0.0],["delete",78293.5,0.0]],"asks":[["new",78338.0,1.0e4],["new",78339.0,2.11e4],["delete",78340.5,0.0],["change",78341.0,490.0],["new",78341.5,1.0e4],["change",78342.5,2010.0],["delete",78343.0,0.0],["delete",78344.0,0.0],["change",78344.5,16990.0],["change",78345.0,10230.0],["delete",78345.5,0.0],["delete",78346.0,0.0],["new",78347.5,5740.0],["new",78348.0,44480.0]],"prev_change_id":41152033103}}}
[2025-04-07 08:31:59.734] [multi_sink] [info] 📩 Received: {"jsonrpc":"2.0","method":"subscription","params":{"channel":"book.BTC-PERPETUAL.100ms","data":{"timestamp":1743994921085,"type":"change","change_id":41152033805,"instrument_name":"BTC-PERPETUAL","bids":[["new",78337.0,120.0],["new",78327.5,13370.0],["delete",78291.5,0.0],["delete",78291.0,0.0]],"asks":[["new",78337.5,121630.0]],"prev_change_id":41152033786}}}
[2025-04-07 08:31:59.734] [multi_sink] [info] Processing received message: {"jsonrpc":"2.0","method":"subscription","params":{"channel":"book.BTC-PERPETUAL.100ms","data":{"timestamp":1743994921085,"type":"change","change_id":41152033805,"instrument_name":"BTC-PERPETUAL","bids":[["new",78337.0,120.0],["new",78327.5,13370.0],["delete",78291.5,0.0],["delete",78291.0,0.0]],"asks":[["new",78337.5,121630.0]],"prev_change_id":41152033786}}}
[2025-04-07 08:32:01.430] [multi_sink] [info] 📩 Received: {"jsonrpc":"2.0","method":"subscription","params":{"channel":"book.BTC-PERPETUAL.100ms","data":{"timestamp":1743994923023,"type":"change","change_id":41152036754,"instrument_name":"BTC-PERPETUAL","bids":[["delete",78167.5,0.0],["new",78152.5,78150.0],["delete",78117.5,0.0],["new",78102.5,117150.0]],"asks":[["new",78487.5,78480.0],["delete",78498.0,0.0],["new",78537.5,117790.0],["delete",78548.0,0.0]],"prev_change_id":41152033805}}}
[2025-04-07 08:32:01.432] [multi_sink] [info] Processing received message: {"jsonrpc":"2.0","method":"subscription","params":{"channel":"book.BTC-PERPETUAL.100ms","data":{"timestamp":1743994923023,"type":"change","change_id":41152036754,"instrument_name":"BTC-PERPETUAL","bids":[["delete",78167.5,0.0],["new",78152.5,78150.0],["delete",78117.5,0.0],["new",78102.5,117150.0]],"asks":[["new",78487.5,78480.0],["delete",78498.0,0.0],["new",78537.5,117790.0],["delete",78548.0,0.0]],"prev_change_id":41152033805}}}
[2025-04-07 08:32:01.760] [multi_sink] [info] 📩 Received: {"jsonrpc":"2.0","method":"subscription","params":{"channel":"book.BTC-PERPETUAL.100ms","data":{"timestamp":1743994923198,"type":"change","change_id":41152036762,"instrument_name":"BTC-PERPETUAL","bids":[["new",78298.5,7825720.0],["delete",78285.5,0.0],["delete",78152.5,0.0],["new",78145.5,8000580.0],["delete",78132.5,0.0],["delete",78102.5,0.0]],"asks":[["new",78477.5,78470.0],["delete",78487.5,0.0],["new",78527.5,117780.0],["delete",78537.5,0.0]],"prev_change_id":41152036754}}}
[2025-04-07 08:32:01.763] [multi_sink] [info] Processing received message: {"jsonrpc":"2.0","method":"subscription","params":{"channel":"book.BTC-PERPETUAL.100ms","data":{"timestamp":1743994923198,"type":"change","change_id":41152036762,"instrument_name":"BTC-PERPETUAL","bids":[["new",78298.5,7825720.0],["delete",78285.5,0.0],["delete",78152.5,0.0],["new",78145.5,8000580.0],["delete",78132.5,0.0],["delete",78102.5,0.0]],"asks":[["new",78477.5,78470.0],["delete",78487.5,0.0],["new",78527.5,117780.0],["delete",78537.5,0.0]],"prev_change_id":41152036754}}}
[2025-04-07 08:32:02.090] [multi_sink] [info] 📩 Received: {"jsonrpc":"2.0","method":"subscription","params":{"channel":"book.BTC-PERPETUAL.100ms","data":{"timestamp":1743994923527,"type":"change","change_id":41152037470,"instrument_name":"BTC-PERPETUAL","bids":[],"asks":[["delete",78363.0,0.0],["new",78376.0,6640830.0],["delete",78516.0,0.0],["new",78529.0,7777770.0]],"prev_change_id":41152036762}}}
[2025-04-07 08:32:02.091] [multi_sink] [info] Processing received message: {"jsonrpc":"2.0","method":"subscription","params":{"channel":"book.BTC-PERPETUAL.100ms","data":{"timestamp":1743994923527,"type":"change","change_id":41152037470,"instrument_name":"BTC-PERPETUAL","bids":[],"asks":[["delete",78363.0,0.0],["new",78376.0,6640830.0],["delete",78516.0,0.0],["new",78529.0,7777770.0]],"prev_change_id":41152036762}}}
[2025-04-07 08:32:02.421] [multi_sink] [info] 📩 Received: {"jsonrpc":"2.0","method":"subscription","params":{"channel":"book.BTC-PERPETUAL.100ms","data":{"timestamp":1743994923777,"type":"change","change_id":41152037562,"instrument_name":"BTC-PERPETUAL","bids":[],"asks":[["delete",78477.5,0.0],["delete",78527.5,0.0]],"prev_change_id":41152037470}}}
[2025-04-07 08:32:02.426] [multi_sink] [info] Processing received message: {"jsonrpc":"2.0","method":"subscription","params":{"channel":"book.BTC-PERPETUAL.100ms","data":{"timestamp":1743994923777,"type":"change","change_id":41152037562,"instrument_name":"BTC-PERPETUAL","bids":[],"asks":[["delete",78477.5,0.0],["delete",78527.5,0.0]],"prev_change_id":41152037470}}}
[2025-04-07 08:32:02.522] [multi_sink] [info] 📩 Received: {"jsonrpc":"2.0","method":"subscription","params":{"channel":"book.ETH-PERPETUAL.100ms","data":{"timestamp":1743994924127,"type":"change","change_id":23707250954,"instrument_name":"ETH-PERPETUAL","bids":[["delete",1577.2,0.0],["delete",1577.15,0.0],["delete",1577.05,0.0],["delete",1577.0,0.0],["delete",1576.95,0.0],["delete",1576.9,0.0],["delete",1576.85,0.0],["delete",1576.8,0.0],["delete",1576.75,0.0],["new",1575.95,739.0],["new",1575.9,1023.0],["new",1575.85,2865.0],["new",1575.8,7297.0],["new",1575.75,5114.0],["new",1575.7,14288.0],["new",1575.65,17166.0],["new",1575.6,68440.0],["new",1575.55,14158.0]],"asks":[["delete",1577.25,0.0],["new",1577.3,18539.0],["new",1577.35,14002.0],["new",1577.4,4372.0],["new",1577.45,15442.0],["change",1577.5,6089812.0],["new",1577.55,7.16e4],["change",1577.6,4024.0],["change",1577.65,13560.0],["change",1577.7,7635.0],["delete",1577.75,0.0],["delete",1577.8,0.0],["delete",1577.85,0.0],["delete",1577.9,0.0]],"prev_change_id":23707246339}}}
[2025-04-07 08:32:02.524] [multi_sink] [info] Processing received message: {"jsonrpc":"2.0","method":"subscription","params":{"channel":"book.ETH-PERPETUAL.100ms","data":{"timestamp":1743994924127,"type":"change","change_id":23707250954,"instrument_name":"ETH-PERPETUAL","bids":[["delete",1577.2,0.0],["delete",1577.15,0.0],["delete",1577.05,0.0],["delete",1577.0,0.0],["delete",1576.95,0.0],["delete",1576.9,0.0],["delete",1576.85,0.0],["delete",1576.8,0.0],["delete",1576.75,0.0],["new",1575.95,739.0],["new",1575.9,1023.0],["new",1575.85,2865.0],["new",1575.8,7297.0],["new",1575.75,5114.0],["new",1575.7,14288.0],["new",1575.65,17166.0],["new",1575.6,68440.0],["new",1575.55,14158.0]],"asks":[["delete",1577.25,0.0],["new",1577.3,18539.0],["new",1577.35,14002.0],["new",1577.4,4372.0],["new",1577.45,15442.0],["change",1577.5,6089812.0],["new",1577.55,7.16e4],["change",1577.6,4024.0],["change",1577.65,13560.0],["change",1577.7,7635.0],["delete",1577.75,0.0],["delete",1577.8,0.0],["delete",1577.85,0.0],["delete",1577.9,0.0]],"prev_change_id":23707246339}}}
[2025-04-07 08:32:02.848] [multi_sink] [info] 📩 Received: {"jsonrpc":"2.0","method":"subscription","params":{"channel":"book.ETH-PERPETUAL.100ms","data":{"timestamp":1743994924466,"type":"change","change_id":23707251245,"instrument_name":"ETH-PERPETUAL","bids":[["delete",1576.7,0.0],["delete",1576.65,0.0],["delete",1576.6,0.0],["delete",1576.55,0.0],["change",1576.5,2354.0],["change",1576.45,7847.0],["delete",1576.4,0.0],["delete",1576.35,0.0],["change",1576.3,64885.0],["change",1576.25,82663.0],["change",1576.2,4578.0],["new",1576.15,7897.0],["new",1576.1,28085.0],["new",1576.05,7660.0],["change",1576.0,7547095.0]],"asks":[["new",1576.8,5231.0],["new",1576.85,5.0e3],["new",1576.9,7366.0],["new",1576.95,5.1e3],["new",1577.0,1643.0],["new",1577.1,5576.0],["new",1577.15,2953.0],["new",1577.2,25566.0],["new",1577.25,10715.0],["delete",1577.95,0.0],["delete",1578.0,0.0],["delete",1578.05,0.0],["delete",1578.1,0.0],["delete",1578.15,0.0],["delete",1578.2,0.0],["delete",1578.25,0.0],["delete",1578.3,0.0],["delete",1578.35,0.0]],"prev_change_id":23707250954}}}
[2025-04-07 08:32:02.853] [multi_sink] [info] Processing received message: {"jsonrpc":"2.0","method":"subscription","params":{"channel":"book.ETH-PERPETUAL.100ms","data":{"timestamp":1743994924466,"type":"change","change_id":23707251245,"instrument_name":"ETH-PERPETUAL","bids":[["delete",1576.7,0.0],["delete",1576.65,0.0],["delete",1576.6,0.0],["delete",1576.55,0.0],["change",1576.5,2354.0],["change",1576.45,7847.0],["delete",1576.4,0.0],["delete",1576.35,0.0],["change",1576.3,64885.0],["change",1576.25,82663.0],["change",1576.2,4578.0],["new",1576.15,7897.0],["new",1576.1,28085.0],["new",1576.05,7660.0],["change",1576.0,7547095.0]],"asks":[["new",1576.8,5231.0],["new",1576.85,5.0e3],["new",1576.9,7366.0],["new",1576.95,5.1e3],["new",1577.0,1643.0],["new",1577.1,5576.0],["new",1577.15,2953.0],["new",1577.2,25566.0],["new",1577.25,10715.0],["delete",1577.95,0.0],["delete",1578.0,0.0],["delete",1578.05,0.0],["delete",1578.1,0.0],["delete",1578.15,0.0],["delete",1578.2,0.0],["delete",1578.25,0.0],["delete",1578.3,0.0],["delete",1578.35,0.0]],"prev_change_id":23707250954}}}
[2025-04-07 08:32:03.178] [multi_sink] [info] 📩 Received: {"jsonrpc":"2.0","method":"subscription","params":{"channel":"book.ETH-PERPETUAL.100ms","data":{"timestamp":1743994924543,"type":"change","change_id":23707251340,"instrument_name":"ETH-PERPETUAL","bids":[["new",1576.65,6212.0],["new",1576.55,5.0e3],["change",1576.25,81296.0],["change",1576.2,454.0]],"asks":[["new",1576.7,12460.0],["new",1576.75,10781.0],["delete",1578.4,0.0],["delete",1578.45,0.0]],"prev_change_id":23707251245}}}
[2025-04-07 08:32:03.183] [multi_sink] [info] Processing received message: {"jsonrpc":"2.0","method":"subscription","params":{"channel":"book.ETH-PERPETUAL.100ms","data":{"timestamp":1743994924543,"type":"change","change_id":23707251340,"instrument_name":"ETH-PERPETUAL","bids":[["new",1576.65,6212.0],["new",1576.55,5.0e3],["change",1576.25,81296.0],["change",1576.2,454.0]],"asks":[["new",1576.7,12460.0],["new",1576.75,10781.0],["delete",1578.4,0.0],["delete",1578.45,0.0]],"prev_change_id":23707251245}}}
[2025-04-07 08:32:03.775] [multi_sink] [info] 📩 Received: {"jsonrpc":"2.0","method":"subscription","params":{"channel":"book.BTC-PERPETUAL.100ms","data":{"timestamp":1743994925378,"type":"change","change_id":41152040002,"instrument_name":"BTC-PERPETUAL","bids":[["delete",78337.0,0.0],["new",78292.5,5180.0]],"asks":[["delete",78337.5,0.0],["change",78352.5,68950.0]],"prev_change_id":41152037562}}}
[2025-04-07 08:32:03.776] [multi_sink] [info] Processing received message: {"jsonrpc":"2.0","method":"subscription","params":{"channel":"book.BTC-PERPETUAL.100ms","data":{"timestamp":1743994925378,"type":"change","change_id":41152040002,"instrument_name":"BTC-PERPETUAL","bids":[["delete",78337.0,0.0],["new",78292.5,5180.0]],"asks":[["delete",78337.5,0.0],["change",78352.5,68950.0]],"prev_change_id":41152037562}}}
[2025-04-07 08:32:04.106] [multi_sink] [info] 📩 Received: {"jsonrpc":"2.0","method":"subscription","params":{"channel":"book.BTC-PERPETUAL.100ms","data":{"timestamp":1743994925718,"type":"change","change_id":41152040312,"instrument_name":"BTC-PERPETUAL","bids":[["delete",78327.5,0.0],["delete",78325.0,0.0],["delete",78324.5,0.0],["delete",78324.0,0.0],["delete",78323.5,0.0],["delete",78323.0,0.0],["delete",78322.5,0.0],["delete",78322.0,0.0],["delete",78321.0,0.0],["new",78304.0,3280.0],["new",78303.5,5740.0],["new",78302.5,5180.0],["new",78299.5,1550.0],["new",78299.0,5180.0],["new",78296.0,16080.0],["new",78295.5,33820.0],["new",78295.0,2.0e3],["new",78294.0,5180.0]],"asks":[["delete",78338.0,0.0],["delete",78339.0,0.0],["delete",78341.0,0.0],["delete",78341.5,0.0],["change",78342.5,40190.0],["new",78343.5,5.5e3],["new",78344.0,35180.0],["change",78344.5,83160.0],["change",78345.0,230.0],["new",78346.0,5180.0],["delete",78347.5,0.0],["delete",78348.0,0.0],["new",78349.5,5180.0],["change",78351.5,88010.0],["change",78352.0,175190.0]],"prev_change_id":41152040002}}}
[2025-04-07 08:32:04.107] [multi_sink] [info] Processing received message: {"jsonrpc":"2.0","method":"subscription","params":{"channel":"book.BTC-PERPETUAL.100ms","data":{"timestamp":1743994925718,"type":"change","change_id":41152040312,"instrument_name":"BTC-PERPETUAL","bids":[["delete",78327.5,0.0],["delete",78325.0,0.0],["delete",78324.5,0.0],["delete",78324.0,0.0],["delete",78323.5,0.0],["delete",78323.0,0.0],["delete",78322.5,0.0],["delete",78322.0,0.0],["delete",78321.0,0.0],["new",78304.0,3280.0],["new",78303.5,5740.0],["new",78302.5,5180.0],["new",78299.5,1550.0],["new",78299.0,5180.0],["new",78296.0,16080.0],["new",78295.5,33820.0],["new",78295.0,2.0e3],["new",78294.0,5180.0]],"asks":[["delete",78338.0,0.0],["delete",78339.0,0.0],["delete",78341.0,0.0],["delete",78341.5,0.0],["change",78342.5,40190.0],["new",78343.5,5.5e3],["new",78344.0,35180.0],["change",78344.5,83160.0],["change",78345.0,230.0],["new",78346.0,5180.0],["delete",78347.5,0.0],["delete",78348.0,0.0],["new",78349.5,5180.0],["change",78351.5,88010.0],["change",78352.0,175190.0]],"prev_change_id":41152040002}}}
[2025-04-07 08:32:04.118] [multi_sink] [info] 📩 Received: {"jsonrpc":"2.0","method":"subscription","params":{"channel":"book.ETH-PERPETUAL.100ms","data":{"timestamp":1743994925750,"type":"change","change_id":23707252522,"instrument_name":"ETH-PERPETUAL","bids":[["change",1576.1,7574037.0],["change",1576.0,1143.0]],"asks":[],"prev_change_id":23707251340}}}
[2025-04-07 08:32:04.119] [multi_sink] [info] Processing received message: {"jsonrpc":"2.0","method":"subscription","params":{"channel":"book.ETH-PERPETUAL.100ms","data":{"timestamp":1743994925750,"type":"change","change_id":23707252522,"instrument_name":"ETH-PERPETUAL","bids":[["change",1576.1,7574037.0],["change",1576.0,1143.0]],"asks":[],"prev_change_id":23707251340}}}
[2025-04-07 08:32:04.438] [multi_sink] [info] 📩 Received: {"jsonrpc":"2.0","method":"subscription","params":{"channel":"book.BTC-PERPETUAL.100ms","data":{"timestamp":1743994926055,"type":"change","change_id":41152040956,"instrument_name":"BTC-PERPETUAL","bids":[["delete",78320.5,0.0],["delete",78320.0,0.0],["delete",78319.5,0.0],["change",78318.0,490.0],["change",78317.5,1.0e3],["delete",78317.0,0.0],["delete",78316.0,0.0],["change",78315.0,310.0],["delete",78314.0,0.0],["new",78311.0,25030.0],["new",78310.5,49470.0],["new",78310.0,1.0e3],["new",78309.5,39420.0],["new",78306.5,1.7e3],["new",78306.0,5540.0]],"asks":[["new",78332.5,11850.0],["new",78334.0,34240.0],["new",78335.5,6.0e3],["new",78336.5,15220.0],["new",78337.0,16990.0],["new",78337.5,5250.0],["new",78339.5,27990.0],["new",78340.5,19960.0],["new",78342.0,34240.0],["delete",78351.0,0.0],["change",78351.5,6370.0],["change",78352.0,100750.0],["change",78352.5,34720.0],["delete",78353.0,0.0],["delete",78353.5,0.0],["delete",78354.0,0.0],["delete",78355.0,0.0],["delete",78355.5,0.0]],"prev_change_id":41152040312}}}
[2025-04-07 08:32:04.440] [multi_sink] [info] Processing received message: {"jsonrpc":"2.0","method":"subscription","params":{"channel":"book.BTC-PERPETUAL.100ms","data":{"timestamp":1743994926055,"type":"change","change_id":41152040956,"instrument_name":"BTC-PERPETUAL","bids":[["delete",78320.5,0.0],["delete",78320.0,0.0],["delete",78319.5,0.0],["change",78318.0,490.0],["change",78317.5,1.0e3],["delete",78317.0,0.0],["delete",78316.0,0.0],["change",78315.0,310.0],["delete",78314.0,0.0],["new",78311.0,25030.0],["new",78310.5,49470.0],["new",78310.0,1.0e3],["new",78309.5,39420.0],["new",78306.5,1.7e3],["new",78306.0,5540.0]],"asks":[["new",78332.5,11850.0],["new",78334.0,34240.0],["new",78335.5,6.0e3],["new",78336.5,15220.0],["new",78337.0,16990.0],["new",78337.5,5250.0],["new",78339.5,27990.0],["new",78340.5,19960.0],["new",78342.0,34240.0],["delete",78351.0,0.0],["change",78351.5,6370.0],["change",78352.0,100750.0],["change",78352.5,34720.0],["delete",78353.0,0.0],["delete",78353.5,0.0],["delete",78354.0,0.0],["delete",78355.0,0.0],["delete",78355.5,0.0]],"prev_change_id":41152040312}}}
[2025-04-07 08:32:04.766] [multi_sink] [info] 📩 Received: {"jsonrpc":"2.0","method":"subscription","params":{"channel":"book.BTC-PERPETUAL.100ms","data":{"timestamp":1743994926091,"type":"change","change_id":41152040968,"instrument_name":"BTC-PERPETUAL","bids":[["new",78325.5,40660.0],["delete",78312.5,0.0]],"asks":[["new",78326.0,81360.0],["delete",78357.0,0.0]],"prev_change_id":41152040956}}}
[2025-04-07 08:32:04.767] [multi_sink] [info] Processing received message: {"jsonrpc":"2.0","method":"subscription","params":{"channel":"book.BTC-PERPETUAL.100ms","data":{"timestamp":1743994926091,"type":"change","change_id":41152040968,"instrument_name":"BTC-PERPETUAL","bids":[["new",78325.5,40660.0],["delete",78312.5,0.0]],"asks":[["new",78326.0,81360.0],["delete",78357.0,0.0]],"prev_change_id":41152040956}}}
[2025-04-07 08:32:04.780] [multi_sink] [info] 📩 Received: {"jsonrpc":"2.0","method":"subscription","params":{"channel":"book.ETH-PERPETUAL.100ms","data":{"timestamp":1743994926082,"type":"change","change_id":23707253168,"instrument_name":"ETH-PERPETUAL","bids":[],"asks":[["change",1577.5,26725.0],["change",1577.6,6067111.0]],"prev_change_id":23707252522}}}
[2025-04-07 08:32:04.783] [multi_sink] [info] Processing received message: {"jsonrpc":"2.0","method":"subscription","params":{"channel":"book.ETH-PERPETUAL.100ms","data":{"timestamp":1743994926082,"type":"change","change_id":23707253168,"instrument_name":"ETH-PERPETUAL","bids":[],"asks":[["change",1577.5,26725.0],["change",1577.6,6067111.0]],"prev_change_id":23707252522}}}
[2025-04-07 08:32:05.789] [multi_sink] [info] 📩 Received: {"jsonrpc":"2.0","method":"subscription","params":{"channel":"book.BTC-PERPETUAL.100ms","data":{"timestamp":1743994927329,"type":"change","change_id":41152043081,"instrument_name":"BTC-PERPETUAL","bids":[["new",78149.5,78150.0],["new",78099.5,117150.0]],"asks":[["new",78479.5,78480.0],["new",78529.5,117790.0]],"prev_change_id":41152040968}}}
[2025-04-07 08:32:05.790] [multi_sink] [info] Processing received message: {"jsonrpc":"2.0","method":"subscription","params":{"channel":"book.BTC-PERPETUAL.100ms","data":{"timestamp":1743994927329,"type":"change","change_id":41152043081,"instrument_name":"BTC-PERPETUAL","bids":[["new",78149.5,78150.0],["new",78099.5,117150.0]],"asks":[["new",78479.5,78480.0],["new",78529.5,117790.0]],"prev_change_id":41152040968}}}
[2025-04-07 08:32:06.795] [multi_sink] [info] 📩 Received: {"jsonrpc":"2.0","method":"subscription","params":{"channel":"book.BTC-PERPETUAL.100ms","data":{"timestamp":1743994928265,"type":"change","change_id":41152043949,"instrument_name":"BTC-PERPETUAL","bids":[["delete",78149.5,0.0],["delete",78099.5,0.0]],"asks":[["delete",78479.5,0.0],["new",78490.5,78490.0],["delete",78529.5,0.0],["new",78540.5,117810.0]],"prev_change_id":41152043081}}}
[2025-04-07 08:32:06.801] [multi_sink] [info] Processing received message: {"jsonrpc":"2.0","method":"subscription","params":{"channel":"book.BTC-PERPETUAL.100ms","data":{"timestamp":1743994928265,"type":"change","change_id":41152043949,"instrument_name":"BTC-PERPETUAL","bids":[["delete",78149.5,0.0],["delete",78099.5,0.0]],"asks":[["delete",78479.5,0.0],["new",78490.5,78490.0],["delete",78529.5,0.0],["new",78540.5,117810.0]],"prev_change_id":41152043081}}}
[2025-04-07 08:32:07.125] [multi_sink] [info] 📩 Received: {"jsonrpc":"2.0","method":"subscription","params":{"channel":"book.BTC-PERPETUAL.100ms","data":{"timestamp":1743994928439,"type":"change","change_id":41152044600,"instrument_name":"BTC-PERPETUAL","bids":[],"asks":[["delete",78490.5,0.0],["delete",78540.5,0.0]],"prev_change_id":41152043949}}}
[2025-04-07 08:32:07.126] [multi_sink] [info] Processing received message: {"jsonrpc":"2.0","method":"subscription","params":{"channel":"book.BTC-PERPETUAL.100ms","data":{"timestamp":1743994928439,"type":"change","change_id":41152044600,"instrument_name":"BTC-PERPETUAL","bids":[],"asks":[["delete",78490.5,0.0],["delete",78540.5,0.0]],"prev_change_id":41152043949}}}
[2025-04-07 08:32:07.189] [multi_sink] [info] 📩 Received: {"jsonrpc":"2.0","method":"subscription","params":{"channel":"book.ETH-PERPETUAL.100ms","data":{"timestamp":1743994928822,"type":"change","change_id":23707255373,"instrument_name":"ETH-PERPETUAL","bids":[],"asks":[["delete",1576.7,0.0],["new",1577.9,25704.0]],"prev_change_id":23707253168}}}
[2025-04-07 08:32:07.192] [multi_sink] [info] Processing received message: {"jsonrpc":"2.0","method":"subscription","params":{"channel":"book.ETH-PERPETUAL.100ms","data":{"timestamp":1743994928822,"type":"change","change_id":23707255373,"instrument_name":"ETH-PERPETUAL","bids":[],"asks":[["delete",1576.7,0.0],["new",1577.9,25704.0]],"prev_change_id":23707253168}}}
[2025-04-07 08:32:07.520] [multi_sink] [info] 📩 Received: {"jsonrpc":"2.0","method":"subscription","params":{"channel":"book.ETH-PERPETUAL.100ms","data":{"timestamp":1743994929123,"type":"change","change_id":23707256011,"instrument_name":"ETH-PERPETUAL","bids":[["delete",1576.65,0.0],["delete",1576.55,0.0],["delete",1576.5,0.0],["delete",1576.45,0.0],["delete",1576.3,0.0],["delete",1576.25,0.0],["delete",1576.2,0.0],["delete",1576.15,0.0],["change",1576.1,7545952.0],["change",1575.95,75217.0],["change",1575.9,2046.0],["change",1575.85,4861.0],["change",1575.8,12036.0],["change",1575.75,7.7e3],["change",1575.7,23147.0],["change",1575.65,23186.0],["change",1575.55,15081.0],["new",1575.5,18397.0]],"asks":[["delete",1576.75,0.0],["delete",1576.8,0.0],["delete",1576.85,0.0],["delete",1576.9,0.0],["delete",1576.95,0.0],["delete",1577.0,0.0],["delete",1577.1,0.0],["delete",1577.15,0.0],["change",1577.5,52727.0],["change",1577.55,150273.0],["change",1577.6,6069922.0],["change",1577.65,21120.0],["change",1577.7,14281.0],["new",1577.75,17720.0],["new",1577.8,1023.0],["new",1577.85,4679.0]],"prev_change_id":23707255373}}}
[2025-04-07 08:32:07.523] [multi_sink] [info] Processing received message: {"jsonrpc":"2.0","method":"subscription","params":{"channel":"book.ETH-PERPETUAL.100ms","data":{"timestamp":1743994929123,"type":"change","change_id":23707256011,"instrument_name":"ETH-PERPETUAL","bids":[["delete",1576.65,0.0],["delete",1576.55,0.0],["delete",1576.5,0.0],["delete",1576.45,0.0],["delete",1576.3,0.0],["delete",1576.25,0.0],["delete",1576.2,0.0],["delete",1576.15,0.0],["change",1576.1,7545952.0],["change",1575.95,75217.0],["change",1575.9,2046.0],["change",1575.85,4861.0],["change",1575.8,12036.0],["change",1575.75,7.7e3],["change",1575.7,23147.0],["change",1575.65,23186.0],["change",1575.55,15081.0],["new",1575.5,18397.0]],"asks":[["delete",1576.75,0.0],["delete",1576.8,0.0],["delete",1576.85,0.0],["delete",1576.9,0.0],["delete",1576.95,0.0],["delete",1577.0,0.0],["delete",1577.1,0.0],["delete",1577.15,0.0],["change",1577.5,52727.0],["change",1577.55,150273.0],["change",1577.6,6069922.0],["change",1577.65,21120.0],["change",1577.7,14281.0],["new",1577.75,17720.0],["new",1577.8,1023.0],["new",1577.85,4679.0]],"prev_change_id":23707255373}}}
[2025-04-07 08:32:07.851] [multi_sink] [info] 📩 Received: {"jsonrpc":"2.0","method":"subscription","params":{"channel":"book.ETH-PERPETUAL.100ms","data":{"timestamp":1743994929476,"type":"change","change_id":23707256240,"instrument_name":"ETH-PERPETUAL","bids":[["new",1576.45,35376.0],["new",1576.4,1347.0],["new",1576.3,24501.0],["new",1576.25,80645.0],["new",1576.2,38645.0],["new",1576.15,10923.0],["change",1576.1,7560967.0],["change",1576.05,2582.0],["change",1576.0,8378.0],["change",1575.95,74478.0],["change",1575.9,1023.0],["change",1575.85,1996.0],["change",1575.8,4739.0],["change",1575.75,2586.0],["change",1575.7,8859.0],["change",1575.65,6020.0]],"asks":[["new",1576.9,17576.0],["new",1577.05,3069.0],["new",1577.1,11416.0],["change",1577.2,5.0e3],["change",1577.25,7613.0],["change",1577.3,2838.0],["change",1577.35,9127.0],["change",1577.4,28004.0],["change",1577.45,9476.0],["change",1577.5,26002.0],["change",1577.55,78673.0],["change",1577.6,6065898.0]],"prev_change_id":23707256011}}}
[2025-04-07 08:32:07.853] [multi_sink] [info] Processing received message: {"jsonrpc":"2.0","method":"subscription","params":{"channel":"book.ETH-PERPETUAL.100ms","data":{"timestamp":1743994929476,"type":"change","change_id":23707256240,"instrument_name":"ETH-PERPETUAL","bids":[["new",1576.45,35376.0],["new",1576.4,1347.0],["new",1576.3,24501.0],["new",1576.25,80645.0],["new",1576.2,38645.0],["new",1576.15,10923.0],["change",1576.1,7560967.0],["change",1576.05,2582.0],["change",1576.0,8378.0],["change",1575.95,74478.0],["change",1575.9,1023.0],["change",1575.85,1996.0],["change",1575.8,4739.0],["change",1575.75,2586.0],["change",1575.7,8859.0],["change",1575.65,6020.0]],"asks":[["new",1576.9,17576.0],["new",1577.05,3069.0],["new",1577.1,11416.0],["change",1577.2,5.0e3],["change",1577.25,7613.0],["change",1577.3,2838.0],["change",1577.35,9127.0],["change",1577.4,28004.0],["change",1577.45,9476.0],["change",1577.5,26002.0],["change",1577.55,78673.0],["change",1577.6,6065898.0]],"prev_change_id":23707256011}}}
[2025-04-07 08:32:08.182] [multi_sink] [info] 📩 Received: {"jsonrpc":"2.0","method":"subscription","params":{"channel":"book.ETH-PERPETUAL.100ms","data":{"timestamp":1743994929550,"type":"change","change_id":23707256298,"instrument_name":"ETH-PERPETUAL","bids":[["new",1576.65,25973.0],["new",1576.5,10415.0],["delete",1575.6,0.0],["change",1575.55,923.0]],"asks":[["new",1576.7,19.0],["new",1576.85,5273.0],["change",1577.65,7560.0],["change",1577.7,6646.0]],"prev_change_id":23707256240}}}
[2025-04-07 08:32:08.186] [multi_sink] [info] Processing received message: {"jsonrpc":"2.0","method":"subscription","params":{"channel":"book.ETH-PERPETUAL.100ms","data":{"timestamp":1743994929550,"type":"change","change_id":23707256298,"instrument_name":"ETH-PERPETUAL","bids":[["new",1576.65,25973.0],["new",1576.5,10415.0],["delete",1575.6,0.0],["change",1575.55,923.0]],"asks":[["new",1576.7,19.0],["new",1576.85,5273.0],["change",1577.65,7560.0],["change",1577.7,6646.0]],"prev_change_id":23707256240}}}
[2025-04-07 08:32:08.809] [multi_sink] [info] 📩 Received: {"jsonrpc":"2.0","method":"subscription","params":{"channel":"book.BTC-PERPETUAL.100ms","data":{"timestamp":1743994930437,"type":"change","change_id":41152047308,"instrument_name":"BTC-PERPETUAL","bids":[["delete",78325.5,0.0],["delete",78318.0,0.0],["new",78307.5,4.0e4],["change",78306.0,160720.0],["new",78301.0,7825720.0],["delete",78298.5,0.0],["new",78166.0,78160.0],["new",78148.0,8000580.0],["delete",78145.5,0.0],["new",78116.0,117170.0]],"asks":[["delete",78326.0,0.0],["delete",78332.5,0.0],["new",78356.5,119560.0],["new",78357.0,50710.0],["new",78499.5,7.85e4],["new",78549.5,117820.0]],"prev_change_id":41152044600}}}
[2025-04-07 08:32:08.814] [multi_sink] [info] Processing received message: {"jsonrpc":"2.0","method":"subscription","params":{"channel":"book.BTC-PERPETUAL.100ms","data":{"timestamp":1743994930437,"type":"change","change_id":41152047308,"instrument_name":"BTC-PERPETUAL","bids":[["delete",78325.5,0.0],["delete",78318.0,0.0],["new",78307.5,4.0e4],["change",78306.0,160720.0],["new",78301.0,7825720.0],["delete",78298.5,0.0],["new",78166.0,78160.0],["new",78148.0,8000580.0],["delete",78145.5,0.0],["new",78116.0,117170.0]],"asks":[["delete",78326.0,0.0],["delete",78332.5,0.0],["new",78356.5,119560.0],["new",78357.0,50710.0],["new",78499.5,7.85e4],["new",78549.5,117820.0]],"prev_change_id":41152044600}}}
[2025-04-07 08:32:09.143] [multi_sink] [info] 📩 Received: {"jsonrpc":"2.0","method":"subscription","params":{"channel":"book.BTC-PERPETUAL.100ms","data":{"timestamp":1743994930755,"type":"change","change_id":41152047479,"instrument_name":"BTC-PERPETUAL","bids":[["new",78318.5,250.0],["new",78318.0,5070.0],["change",78317.5,35240.0],["new",78315.5,5180.0],["delete",78315.0,0.0],["new",78313.0,5180.0],["new",78312.0,13850.0],["delete",78311.0,0.0],["delete",78310.5,0.0],["change",78310.0,1.0e3],["change",78309.5,39420.0],["new",78308.0,56880.0],["delete",78306.5,0.0],["change",78306.0,155180.0],["delete",78304.0,0.0]],"asks":[["delete",78334.0,0.0],["delete",78335.5,0.0],["delete",78336.5,0.0],["delete",78337.0,0.0],["delete",78337.5,0.0],["delete",78339.5,0.0],["delete",78340.5,0.0],["delete",78342.0,0.0],["delete",78342.5,0.0],["new",78348.0,16020.0],["new",78349.0,36280.0],["new",78350.0,2960.0],["change",78352.0,166860.0],["change",78352.5,68950.0],["new",78354.5,1.65e4],["new",78355.0,2110.0],["new",78355.5,16490.0],["new",78356.0,1.538e5]],"prev_change_id":41152047308}}}
[2025-04-07 08:32:09.145] [multi_sink] [info] Processing received message: {"jsonrpc":"2.0","method":"subscription","params":{"channel":"book.BTC-PERPETUAL.100ms","data":{"timestamp":1743994930755,"type":"change","change_id":41152047479,"instrument_name":"BTC-PERPETUAL","bids":[["new",78318.5,250.0],["new",78318.0,5070.0],["change",78317.5,35240.0],["new",78315.5,5180.0],["delete",78315.0,0.0],["new",78313.0,5180.0],["new",78312.0,13850.0],["delete",78311.0,0.0],["delete",78310.5,0.0],["change",78310.0,1.0e3],["change",78309.5,39420.0],["new",78308.0,56880.0],["delete",78306.5,0.0],["change",78306.0,155180.0],["delete",78304.0,0.0]],"asks":[["delete",78334.0,0.0],["delete",78335.5,0.0],["delete",78336.5,0.0],["delete",78337.0,0.0],["delete",78337.5,0.0],["delete",78339.5,0.0],["delete",78340.5,0.0],["delete",78342.0,0.0],["delete",78342.5,0.0],["new",78348.0,16020.0],["new",78349.0,36280.0],["new",78350.0,2960.0],["change",78352.0,166860.0],["change",78352.5,68950.0],["new",78354.5,1.65e4],["new",78355.0,2110.0],["new",78355.5,16490.0],["new",78356.0,1.538e5]],"prev_change_id":41152047308}}}
[2025-04-07 08:32:09.476] [multi_sink] [info] 📩 Received: {"jsonrpc":"2.0","method":"subscription","params":{"channel":"book.BTC-PERPETUAL.100ms","data":{"timestamp":1743994931102,"type":"change","change_id":41152048158,"instrument_name":"BTC-PERPETUAL","bids":[["new",78327.0,490.0],["new",78326.5,16490.0],["new",78326.0,17580.0],["new",78325.5,58590.0],["new",78324.0,32980.0],["new",78323.5,5180.0],["new",78321.0,5740.0],["new",78320.0,17310.0],["delete",78303.5,0.0],["delete",78302.5,0.0],["delete",78299.5,0.0],["delete",78299.0,0.0],["delete",78296.0,0.0],["delete",78295.5,0.0],["delete",78295.0,0.0],["delete",78294.0,0.0]],"asks":[["new",78340.0,97630.0],["new",78340.5,1.29e4],["new",78341.0,1.0e4],["new",78342.0,2.1e4],["new",78342.5,2010.0],["delete",78343.5,0.0],["change",78344.0,1.0e4],["delete",78344.5,0.0],["delete",78345.0,0.0],["change",78346.0,12220.0],["new",78346.5,40740.0],["new",78347.5,490.0],["delete",78349.5,0.0],["delete",78351.5,0.0],["change",78352.0,66110.0],["change",78352.5,34230.0],["delete",78376.0,0.0],["new",78378.5,6640830.0],["delete",78529.0,0.0],["new",78531.5,7777770.0]],"prev_change_id":41152047479}}}
[2025-04-07 08:32:09.480] [multi_sink] [info] Processing received message: {"jsonrpc":"2.0","method":"subscription","params":{"channel":"book.BTC-PERPETUAL.100ms","data":{"timestamp":1743994931102,"type":"change","change_id":41152048158,"instrument_name":"BTC-PERPETUAL","bids":[["new",78327.0,490.0],["new",78326.5,16490.0],["new",78326.0,17580.0],["new",78325.5,58590.0],["new",78324.0,32980.0],["new",78323.5,5180.0],["new",78321.0,5740.0],["new",78320.0,17310.0],["delete",78303.5,0.0],["delete",78302.5,0.0],["delete",78299.5,0.0],["delete",78299.0,0.0],["delete",78296.0,0.0],["delete",78295.5,0.0],["delete",78295.0,0.0],["delete",78294.0,0.0]],"asks":[["new",78340.0,97630.0],["new",78340.5,1.29e4],["new",78341.0,1.0e4],["new",78342.0,2.1e4],["new",78342.5,2010.0],["delete",78343.5,0.0],["change",78344.0,1.0e4],["delete",78344.5,0.0],["delete",78345.0,0.0],["change",78346.0,12220.0],["new",78346.5,40740.0],["new",78347.5,490.0],["delete",78349.5,0.0],["delete",78351.5,0.0],["change",78352.0,66110.0],["change",78352.5,34230.0],["delete",78376.0,0.0],["new",78378.5,6640830.0],["delete",78529.0,0.0],["new",78531.5,7777770.0]],"prev_change_id":41152047479}}}
[2025-04-07 08:32:09.801] [multi_sink] [info] 📩 Received: {"jsonrpc":"2.0","method":"subscription","params":{"channel":"book.BTC-PERPETUAL.100ms","data":{"timestamp":1743994931433,"type":"change","change_id":41152048921,"instrument_name":"BTC-PERPETUAL","bids":[["new",78339.5,1090.0],["delete",78292.5,0.0],["new",78176.0,78170.0],["delete",78166.0,0.0],["new",78126.0,117180.0],["delete",78116.0,0.0]],"asks":[],"prev_change_id":41152048158}}}
[2025-04-07 08:32:09.805] [multi_sink] [info] Processing received message: {"jsonrpc":"2.0","method":"subscription","params":{"channel":"book.BTC-PERPETUAL.100ms","data":{"timestamp":1743994931433,"type":"change","change_id":41152048921,"instrument_name":"BTC-PERPETUAL","bids":[["new",78339.5,1090.0],["delete",78292.5,0.0],["new",78176.0,78170.0],["delete",78166.0,0.0],["new",78126.0,117180.0],["delete",78116.0,0.0]],"asks":[],"prev_change_id":41152048158}}}
[2025-04-07 08:32:10.494] [multi_sink] [info] 📩 Received: {"jsonrpc":"2.0","method":"subscription","params":{"channel":"book.BTC-PERPETUAL.100ms","data":{"timestamp":1743994932086,"type":"change","change_id":41152049773,"instrument_name":"BTC-PERPETUAL","bids":[],"asks":[["delete",78499.5,0.0],["delete",78549.5,0.0]],"prev_change_id":41152048921}}}
[2025-04-07 08:32:10.495] [multi_sink] [info] Processing received message: {"jsonrpc":"2.0","method":"subscription","params":{"channel":"book.BTC-PERPETUAL.100ms","data":{"timestamp":1743994932086,"type":"change","change_id":41152049773,"instrument_name":"BTC-PERPETUAL","bids":[],"asks":[["delete",78499.5,0.0],["delete",78549.5,0.0]],"prev_change_id":41152048921}}}
[2025-04-07 08:32:10.822] [multi_sink] [info] 📩 Received: {"jsonrpc":"2.0","method":"subscription","params":{"channel":"book.BTC-PERPETUAL.100ms","data":{"timestamp":1743994932281,"type":"change","change_id":41152049787,"instrument_name":"BTC-PERPETUAL","bids":[],"asks":[["new",78513.5,78510.0],["new",78563.5,117840.0]],"prev_change_id":41152049773}}}
[2025-04-07 08:32:10.830] [multi_sink] [info] Processing received message: {"jsonrpc":"2.0","method":"subscription","params":{"channel":"book.BTC-PERPETUAL.100ms","data":{"timestamp":1743994932281,"type":"change","change_id":41152049787,"instrument_name":"BTC-PERPETUAL","bids":[],"asks":[["new",78513.5,78510.0],["new",78563.5,117840.0]],"prev_change_id":41152049773}}}
[2025-04-07 08:32:11.579] [multi_sink] [info] 📩 Received: {"jsonrpc":"2.0","method":"subscription","params":{"channel":"book.ETH-PERPETUAL.100ms","data":{"timestamp":1743994933016,"type":"change","change_id":23707259983,"instrument_name":"ETH-PERPETUAL","bids":[["change",1576.2,7584597.0],["change",1576.1,15015.0]],"asks":[],"prev_change_id":23707256298}}}
[2025-04-07 08:32:11.583] [multi_sink] [info] Processing received message: {"jsonrpc":"2.0","method":"subscription","params":{"channel":"book.ETH-PERPETUAL.100ms","data":{"timestamp":1743994933016,"type":"change","change_id":23707259983,"instrument_name":"ETH-PERPETUAL","bids":[["change",1576.2,7584597.0],["change",1576.1,15015.0]],"asks":[],"prev_change_id":23707256298}}}
[2025-04-07 08:32:11.830] [multi_sink] [info] 📩 Received: {"jsonrpc":"2.0","method":"subscription","params":{"channel":"book.BTC-PERPETUAL.100ms","data":{"timestamp":1743994933275,"type":"change","change_id":41152051156,"instrument_name":"BTC-PERPETUAL","bids":[["delete",78176.0,0.0],["delete",78126.0,0.0]],"asks":[],"prev_change_id":41152049787}}}
[2025-04-07 08:32:11.831] [multi_sink] [info] Processing received message: {"jsonrpc":"2.0","method":"subscription","params":{"channel":"book.BTC-PERPETUAL.100ms","data":{"timestamp":1743994933275,"type":"change","change_id":41152051156,"instrument_name":"BTC-PERPETUAL","bids":[["delete",78176.0,0.0],["delete",78126.0,0.0]],"asks":[],"prev_change_id":41152049787}}}
[2025-04-07 08:32:11.910] [multi_sink] [info] 📩 Received: {"jsonrpc":"2.0","method":"subscription","params":{"channel":"book.ETH-PERPETUAL.100ms","data":{"timestamp":1743994933345,"type":"change","change_id":23707260304,"instrument_name":"ETH-PERPETUAL","bids":[],"asks":[["change",1577.6,2811.0],["change",1577.7,6069733.0]],"prev_change_id":23707259983}}}
[2025-04-07 08:32:11.914] [multi_sink] [info] Processing received message: {"jsonrpc":"2.0","method":"subscription","params":{"channel":"book.ETH-PERPETUAL.100ms","data":{"timestamp":1743994933345,"type":"change","change_id":23707260304,"instrument_name":"ETH-PERPETUAL","bids":[],"asks":[["change",1577.6,2811.0],["change",1577.7,6069733.0]],"prev_change_id":23707259983}}}
[2025-04-07 08:32:12.160] [multi_sink] [info] 📩 Received: {"jsonrpc":"2.0","method":"subscription","params":{"channel":"book.BTC-PERPETUAL.100ms","data":{"timestamp":1743994933534,"type":"change","change_id":41152051867,"instrument_name":"BTC-PERPETUAL","bids":[],"asks":[["delete",78513.5,0.0],["delete",78563.5,0.0]],"prev_change_id":41152051156}}}
[2025-04-07 08:32:12.162] [multi_sink] [info] Processing received message: {"jsonrpc":"2.0","method":"subscription","params":{"channel":"book.BTC-PERPETUAL.100ms","data":{"timestamp":1743994933534,"type":"change","change_id":41152051867,"instrument_name":"BTC-PERPETUAL","bids":[],"asks":[["delete",78513.5,0.0],["delete",78563.5,0.0]],"prev_change_id":41152051156}}}
[2025-04-07 08:32:12.241] [multi_sink] [info] 📩 Received: {"jsonrpc":"2.0","method":"subscription","params":{"channel":"book.ETH-PERPETUAL.100ms","data":{"timestamp":1743994933862,"type":"change","change_id":23707260600,"instrument_name":"ETH-PERPETUAL","bids":[["new",1576.8,200.0],["new",1576.75,9723.0],["delete",1576.65,0.0],["delete",1576.5,0.0]],"asks":[["delete",1576.7,0.0],["delete",1576.85,0.0],["new",1579.2,48064.0],["new",1579.25,51275.0]],"prev_change_id":23707260304}}}
[2025-04-07 08:32:12.244] [multi_sink] [info] Processing received message: {"jsonrpc":"2.0","method":"subscription","params":{"channel":"book.ETH-PERPETUAL.100ms","data":{"timestamp":1743994933862,"type":"change","change_id":23707260600,"instrument_name":"ETH-PERPETUAL","bids":[["new",1576.8,200.0],["new",1576.75,9723.0],["delete",1576.65,0.0],["delete",1576.5,0.0]],"asks":[["delete",1576.7,0.0],["delete",1576.85,0.0],["new",1579.2,48064.0],["new",1579.25,51275.0]],"prev_change_id":23707260304}}}
[2025-04-07 08:32:12.572] [multi_sink] [info] 📩 Received: {"jsonrpc":"2.0","method":"subscription","params":{"channel":"book.ETH-PERPETUAL.100ms","data":{"timestamp":1743994934186,"type":"change","change_id":23707261195,"instrument_name":"ETH-PERPETUAL","bids":[["new",1577.4,21580.0],["new",1577.3,7.15e4],["new",1577.25,6630.0],["new",1577.2,24719.0],["new",1577.15,4328.0],["new",1577.1,6020.0],["new",1577.05,3714.0],["new",1577.0,100.0],["new",1576.95,12238.0],["delete",1576.45,0.0],["delete",1576.4,0.0],["delete",1576.3,0.0],["delete",1576.25,0.0],["change",1576.2,7545952.0],["delete",1576.15,0.0],["delete",1576.1,0.0],["delete",1576.05,0.0],["delete",1576.0,0.0]],"asks":[["delete",1576.9,0.0],["delete",1577.05,0.0],["delete",1577.1,0.0],["delete",1577.2,0.0],["delete",1577.25,0.0],["delete",1577.3,0.0],["delete",1577.35,0.0],["delete",1577.4,0.0],["delete",1577.45,0.0],["new",1578.75,8358.0],["new",1578.8,24137.0],["new",1578.85,16098.0],["new",1578.9,35179.0],["new",1578.95,16936.0],["new",1579.0,99011.0],["new",1579.05,300924.0],["new",1579.1,55846.0],["new",1579.15,8801.0]],"prev_change_id":23707260600}}}
[2025-04-07 08:32:12.574] [multi_sink] [info] Processing received message: {"jsonrpc":"2.0","method":"subscription","params":{"channel":"book.ETH-PERPETUAL.100ms","data":{"timestamp":1743994934186,"type":"change","change_id":23707261195,"instrument_name":"ETH-PERPETUAL","bids":[["new",1577.4,21580.0],["new",1577.3,7.15e4],["new",1577.25,6630.0],["new",1577.2,24719.0],["new",1577.15,4328.0],["new",1577.1,6020.0],["new",1577.05,3714.0],["new",1577.0,100.0],["new",1576.95,12238.0],["delete",1576.45,0.0],["delete",1576.4,0.0],["delete",1576.3,0.0],["delete",1576.25,0.0],["change",1576.2,7545952.0],["delete",1576.15,0.0],["delete",1576.1,0.0],["delete",1576.05,0.0],["delete",1576.0,0.0]],"asks":[["delete",1576.9,0.0],["delete",1577.05,0.0],["delete",1577.1,0.0],["delete",1577.2,0.0],["delete",1577.25,0.0],["delete",1577.3,0.0],["delete",1577.35,0.0],["delete",1577.4,0.0],["delete",1577.45,0.0],["new",1578.75,8358.0],["new",1578.8,24137.0],["new",1578.85,16098.0],["new",1578.9,35179.0],["new",1578.95,16936.0],["new",1579.0,99011.0],["new",1579.05,300924.0],["new",1579.1,55846.0],["new",1579.15,8801.0]],"prev_change_id":23707260600}}}
[2025-04-07 08:32:12.820] [multi_sink] [info] 📩 Received: {"jsonrpc":"2.0","method":"subscription","params":{"channel":"book.BTC-PERPETUAL.100ms","data":{"timestamp":1743994934291,"type":"change","change_id":41152052584,"instrument_name":"BTC-PERPETUAL","bids":[],"asks":[["new",78542.5,78540.0],["new",78592.5,117880.0]],"prev_change_id":41152051867}}}
[2025-04-07 08:32:12.824] [multi_sink] [info] Processing received message: {"jsonrpc":"2.0","method":"subscription","params":{"channel":"book.BTC-PERPETUAL.100ms","data":{"timestamp":1743994934291,"type":"change","change_id":41152052584,"instrument_name":"BTC-PERPETUAL","bids":[],"asks":[["new",78542.5,78540.0],["new",78592.5,117880.0]],"prev_change_id":41152051867}}}
[2025-04-07 08:32:12.903] [multi_sink] [info] 📩 Received: {"jsonrpc":"2.0","method":"subscription","params":{"channel":"book.ETH-PERPETUAL.100ms","data":{"timestamp":1743994934513,"type":"change","change_id":23707261517,"instrument_name":"ETH-PERPETUAL","bids":[["new",1577.65,49007.0],["new",1577.55,9936.0],["new",1577.5,923.0],["new",1577.45,44125.0],["delete",1575.95,0.0],["delete",1575.9,0.0],["delete",1575.85,0.0],["delete",1575.8,0.0],["delete",1575.75,0.0],["delete",1575.7,0.0],["delete",1575.65,0.0],["delete",1575.55,0.0],["delete",1575.5,0.0]],"asks":[["delete",1577.5,0.0],["delete",1577.55,0.0],["delete",1577.6,0.0],["delete",1577.65,0.0],["change",1577.7,5947285.0],["delete",1577.75,0.0],["delete",1577.8,0.0],["delete",1577.85,0.0],["delete",1577.9,0.0],["new",1578.0,599.0],["new",1578.2,9895.0],["new",1578.35,100.0],["new",1578.45,5677.0],["new",1578.5,32937.0],["new",1578.55,72423.0],["new",1578.6,7831.0],["new",1578.65,13124.0],["new",1578.7,9141.0]],"prev_change_id":23707261195}}}
[2025-04-07 08:32:12.907] [multi_sink] [info] Processing received message: {"jsonrpc":"2.0","method":"subscription","params":{"channel":"book.ETH-PERPETUAL.100ms","data":{"timestamp":1743994934513,"type":"change","change_id":23707261517,"instrument_name":"ETH-PERPETUAL","bids":[["new",1577.65,49007.0],["new",1577.55,9936.0],["new",1577.5,923.0],["new",1577.45,44125.0],["delete",1575.95,0.0],["delete",1575.9,0.0],["delete",1575.85,0.0],["delete",1575.8,0.0],["delete",1575.75,0.0],["delete",1575.7,0.0],["delete",1575.65,0.0],["delete",1575.55,0.0],["delete",1575.5,0.0]],"asks":[["delete",1577.5,0.0],["delete",1577.55,0.0],["delete",1577.6,0.0],["delete",1577.65,0.0],["change",1577.7,5947285.0],["delete",1577.75,0.0],["delete",1577.8,0.0],["delete",1577.85,0.0],["delete",1577.9,0.0],["new",1578.0,599.0],["new",1578.2,9895.0],["new",1578.35,100.0],["new",1578.45,5677.0],["new",1578.5,32937.0],["new",1578.55,72423.0],["new",1578.6,7831.0],["new",1578.65,13124.0],["new",1578.7,9141.0]],"prev_change_id":23707261195}}}
[2025-04-07 08:32:13.843] [multi_sink] [info] 📩 Received: {"jsonrpc":"2.0","method":"subscription","params":{"channel":"book.BTC-PERPETUAL.100ms","data":{"timestamp":1743994935457,"type":"change","change_id":41152054613,"instrument_name":"BTC-PERPETUAL","bids":[["delete",78339.5,0.0],["delete",78327.0,0.0],["delete",78326.5,0.0],["new",78216.0,78210.0],["new",78166.0,117240.0]],"asks":[["delete",78340.0,0.0],["delete",78340.5,0.0],["delete",78341.0,0.0],["delete",78342.0,0.0],["delete",78342.5,0.0],["delete",78344.0,0.0],["change",78346.0,4330.0],["new",78404.0,57140.0]],"prev_change_id":41152052584}}}
[2025-04-07 08:32:13.848] [multi_sink] [info] Processing received message: {"jsonrpc":"2.0","method":"subscription","params":{"channel":"book.BTC-PERPETUAL.100ms","data":{"timestamp":1743994935457,"type":"change","change_id":41152054613,"instrument_name":"BTC-PERPETUAL","bids":[["delete",78339.5,0.0],["delete",78327.0,0.0],["delete",78326.5,0.0],["new",78216.0,78210.0],["new",78166.0,117240.0]],"asks":[["delete",78340.0,0.0],["delete",78340.5,0.0],["delete",78341.0,0.0],["delete",78342.0,0.0],["delete",78342.5,0.0],["delete",78344.0,0.0],["change",78346.0,4330.0],["new",78404.0,57140.0]],"prev_change_id":41152052584}}}
[2025-04-07 08:32:14.174] [multi_sink] [info] 📩 Received: {"jsonrpc":"2.0","method":"subscription","params":{"channel":"book.BTC-PERPETUAL.100ms","data":{"timestamp":1743994935798,"type":"change","change_id":41152054890,"instrument_name":"BTC-PERPETUAL","bids":[["new",78355.5,9280.0],["delete",78326.0,0.0],["delete",78325.5,0.0],["delete",78324.0,0.0],["delete",78323.5,0.0],["delete",78321.0,0.0],["delete",78320.0,0.0],["delete",78318.5,0.0],["delete",78318.0,0.0],["delete",78317.5,0.0]],"asks":[["delete",78346.0,0.0],["delete",78346.5,0.0],["delete",78347.5,0.0],["delete",78348.0,0.0],["delete",78349.0,0.0],["delete",78350.0,0.0],["delete",78352.0,0.0],["delete",78352.5,0.0],["delete",78354.5,0.0],["delete",78355.0,0.0],["delete",78355.5,0.0],["change",78356.0,58350.0]],"prev_change_id":41152054613}}}
[2025-04-07 08:32:14.176] [multi_sink] [info] Processing received message: {"jsonrpc":"2.0","method":"subscription","params":{"channel":"book.BTC-PERPETUAL.100ms","data":{"timestamp":1743994935798,"type":"change","change_id":41152054890,"instrument_name":"BTC-PERPETUAL","bids":[["new",78355.5,9280.0],["delete",78326.0,0.0],["delete",78325.5,0.0],["delete",78324.0,0.0],["delete",78323.5,0.0],["delete",78321.0,0.0],["delete",78320.0,0.0],["delete",78318.5,0.0],["delete",78318.0,0.0],["delete",78317.5,0.0]],"asks":[["delete",78346.0,0.0],["delete",78346.5,0.0],["delete",78347.5,0.0],["delete",78348.0,0.0],["delete",78349.0,0.0],["delete",78350.0,0.0],["delete",78352.0,0.0],["delete",78352.5,0.0],["delete",78354.5,0.0],["delete",78355.0,0.0],["delete",78355.5,0.0],["change",78356.0,58350.0]],"prev_change_id":41152054613}}}
[2025-04-07 08:32:14.504] [multi_sink] [info] 📩 Received: {"jsonrpc":"2.0","method":"subscription","params":{"channel":"book.BTC-PERPETUAL.100ms","data":{"timestamp":1743994936100,"type":"change","change_id":41152055599,"instrument_name":"BTC-PERPETUAL","bids":[["new",78378.0,8.54e4],["new",78377.5,2980.0],["delete",78315.5,0.0],["delete",78313.0,0.0],["delete",78312.0,0.0],["delete",78310.0,0.0],["delete",78309.5,0.0],["delete",78308.0,0.0],["delete",78307.5,0.0],["delete",78306.0,0.0]],"asks":[["delete",78356.0,0.0],["delete",78356.5,0.0],["delete",78357.0,0.0]],"prev_change_id":41152054890}}}
[2025-04-07 08:32:14.506] [multi_sink] [info] Processing received message: {"jsonrpc":"2.0","method":"subscription","params":{"channel":"book.BTC-PERPETUAL.100ms","data":{"timestamp":1743994936100,"type":"change","change_id":41152055599,"instrument_name":"BTC-PERPETUAL","bids":[["new",78378.0,8.54e4],["new",78377.5,2980.0],["delete",78315.5,0.0],["delete",78313.0,0.0],["delete",78312.0,0.0],["delete",78310.0,0.0],["delete",78309.5,0.0],["delete",78308.0,0.0],["delete",78307.5,0.0],["delete",78306.0,0.0]],"asks":[["delete",78356.0,0.0],["delete",78356.5,0.0],["delete",78357.0,0.0]],"prev_change_id":41152054890}}}
[2025-04-07 08:32:16.051] [multi_sink] [info] 📩 Received: {"jsonrpc":"2.0","method":"subscription","params":{"channel":"book.BTC-PERPETUAL.100ms","data":{"timestamp":1743994937684,"type":"change","change_id":41152058121,"instrument_name":"BTC-PERPETUAL","bids":[["new",78186.5,8000580.0],["delete",78148.0,0.0]],"asks":[],"prev_change_id":41152055599}}}
[2025-04-07 08:32:16.051] [multi_sink] [info] Processing received message: {"jsonrpc":"2.0","method":"subscription","params":{"channel":"book.BTC-PERPETUAL.100ms","data":{"timestamp":1743994937684,"type":"change","change_id":41152058121,"instrument_name":"BTC-PERPETUAL","bids":[["new",78186.5,8000580.0],["delete",78148.0,0.0]],"asks":[],"prev_change_id":41152055599}}}
[2025-04-07 08:32:16.384] [multi_sink] [info] 📩 Received: {"jsonrpc":"2.0","method":"subscription","params":{"channel":"book.BTC-PERPETUAL.100ms","data":{"timestamp":1743994937715,"type":"change","change_id":41152058124,"instrument_name":"BTC-PERPETUAL","bids":[["new",78339.5,7825720.0],["delete",78301.0,0.0]],"asks":[],"prev_change_id":41152058121}}}
[2025-04-07 08:32:16.386] [multi_sink] [info] Processing received message: {"jsonrpc":"2.0","method":"subscription","params":{"channel":"book.BTC-PERPETUAL.100ms","data":{"timestamp":1743994937715,"type":"change","change_id":41152058124,"instrument_name":"BTC-PERPETUAL","bids":[["new",78339.5,7825720.0],["delete",78301.0,0.0]],"asks":[],"prev_change_id":41152058121}}}
[2025-04-07 08:32:16.711] [multi_sink] [info] 📩 Received: {"jsonrpc":"2.0","method":"subscription","params":{"channel":"book.BTC-PERPETUAL.100ms","data":{"timestamp":1743994938046,"type":"change","change_id":41152058747,"instrument_name":"BTC-PERPETUAL","bids":[],"asks":[["delete",78378.5,0.0],["new",78417.0,6640830.0],["delete",78531.5,0.0],["new",78570.0,7777770.0]],"prev_change_id":41152058124}}}
[2025-04-07 08:32:16.715] [multi_sink] [info] Processing received message: {"jsonrpc":"2.0","method":"subscription","params":{"channel":"book.BTC-PERPETUAL.100ms","data":{"timestamp":1743994938046,"type":"change","change_id":41152058747,"instrument_name":"BTC-PERPETUAL","bids":[],"asks":[["delete",78378.5,0.0],["new",78417.0,6640830.0],["delete",78531.5,0.0],["new",78570.0,7777770.0]],"prev_change_id":41152058124}}}
[2025-04-07 08:32:17.048] [multi_sink] [info] 📩 Received: {"jsonrpc":"2.0","method":"subscription","params":{"channel":"book.BTC-PERPETUAL.100ms","data":{"timestamp":1743994938479,"type":"change","change_id":41152059460,"instrument_name":"BTC-PERPETUAL","bids":[["new",78226.0,78220.0],["delete",78216.0,0.0],["new",78176.0,117260.0],["delete",78166.0,0.0]],"asks":[["delete",78542.5,0.0],["new",78560.0,78560.0],["delete",78592.5,0.0],["new",78610.0,117910.0]],"prev_change_id":41152058747}}}
[2025-04-07 08:32:17.049] [multi_sink] [info] Processing received message: {"jsonrpc":"2.0","method":"subscription","params":{"channel":"book.BTC-PERPETUAL.100ms","data":{"timestamp":1743994938479,"type":"change","change_id":41152059460,"instrument_name":"BTC-PERPETUAL","bids":[["new",78226.0,78220.0],["delete",78216.0,0.0],["new",78176.0,117260.0],["delete",78166.0,0.0]],"asks":[["delete",78542.5,0.0],["new",78560.0,78560.0],["delete",78592.5,0.0],["new",78610.0,117910.0]],"prev_change_id":41152058747}}}
[2025-04-07 08:32:17.189] [multi_sink] [info] 📩 Received: {"jsonrpc":"2.0","method":"subscription","params":{"channel":"book.ETH-PERPETUAL.100ms","data":{"timestamp":1743994938823,"type":"change","change_id":23707266194,"instrument_name":"ETH-PERPETUAL","bids":[],"asks":[["delete",1578.0,0.0],["new",1580.5,72694.0]],"prev_change_id":23707261517}}}
[2025-04-07 08:32:17.194] [multi_sink] [info] Processing received message: {"jsonrpc":"2.0","method":"subscription","params":{"channel":"book.ETH-PERPETUAL.100ms","data":{"timestamp":1743994938823,"type":"change","change_id":23707266194,"instrument_name":"ETH-PERPETUAL","bids":[],"asks":[["delete",1578.0,0.0],["new",1580.5,72694.0]],"prev_change_id":23707261517}}}
[2025-04-07 08:32:17.520] [multi_sink] [info] 📩 Received: {"jsonrpc":"2.0","method":"subscription","params":{"channel":"book.ETH-PERPETUAL.100ms","data":{"timestamp":1743994939149,"type":"change","change_id":23707266846,"instrument_name":"ETH-PERPETUAL","bids":[["delete",1577.65,0.0],["delete",1577.55,0.0],["delete",1577.5,0.0],["delete",1577.45,0.0],["delete",1577.4,0.0],["delete",1577.3,0.0],["delete",1577.25,0.0],["delete",1577.2,0.0],["delete",1577.15,0.0]],"asks":[["change",1577.7,5848915.0],["delete",1578.2,0.0],["delete",1578.35,0.0],["delete",1578.45,0.0],["delete",1578.5,0.0],["delete",1578.55,0.0],["delete",1578.6,0.0],["delete",1578.65,0.0],["delete",1578.7,0.0],["new",1580.1,10223.0],["new",1580.15,1023.0],["new",1580.2,9190.0],["new",1580.25,1023.0],["new",1580.3,4775.0],["new",1580.35,4411.0],["new",1580.4,37321.0],["new",1580.45,25923.0]],"prev_change_id":23707266194}}}
[2025-04-07 08:32:17.523] [multi_sink] [info] Processing received message: {"jsonrpc":"2.0","method":"subscription","params":{"channel":"book.ETH-PERPETUAL.100ms","data":{"timestamp":1743994939149,"type":"change","change_id":23707266846,"instrument_name":"ETH-PERPETUAL","bids":[["delete",1577.65,0.0],["delete",1577.55,0.0],["delete",1577.5,0.0],["delete",1577.45,0.0],["delete",1577.4,0.0],["delete",1577.3,0.0],["delete",1577.25,0.0],["delete",1577.2,0.0],["delete",1577.15,0.0]],"asks":[["change",1577.7,5848915.0],["delete",1578.2,0.0],["delete",1578.35,0.0],["delete",1578.45,0.0],["delete",1578.5,0.0],["delete",1578.55,0.0],["delete",1578.6,0.0],["delete",1578.65,0.0],["delete",1578.7,0.0],["new",1580.1,10223.0],["new",1580.15,1023.0],["new",1580.2,9190.0],["new",1580.25,1023.0],["new",1580.3,4775.0],["new",1580.35,4411.0],["new",1580.4,37321.0],["new",1580.45,25923.0]],"prev_change_id":23707266194}}}
[2025-04-07 08:32:17.851] [multi_sink] [info] 📩 Received: {"jsonrpc":"2.0","method":"subscription","params":{"channel":"book.ETH-PERPETUAL.100ms","data":{"timestamp":1743994939477,"type":"change","change_id":23707267129,"instrument_name":"ETH-PERPETUAL","bids":[["delete",1577.1,0.0],["delete",1577.05,0.0],["delete",1577.0,0.0],["delete",1576.95,0.0],["delete",1576.8,0.0],["delete",1576.75,0.0]],"asks":[["change",1577.7,5705533.0],["delete",1578.75,0.0],["delete",1578.8,0.0],["delete",1578.85,0.0],["delete",1578.9,0.0],["delete",1578.95,0.0],["delete",1579.0,0.0],["delete",1579.05,0.0],["new",1579.75,963.0],["new",1579.8,10271.0],["new",1579.85,1023.0],["new",1579.9,38257.0],["new",1579.95,15035.0],["new",1580.0,98110.0],["new",1580.05,26023.0]],"prev_change_id":23707266846}}}
[2025-04-07 08:32:17.854] [multi_sink] [info] Processing received message: {"jsonrpc":"2.0","method":"subscription","params":{"channel":"book.ETH-PERPETUAL.100ms","data":{"timestamp":1743994939477,"type":"change","change_id":23707267129,"instrument_name":"ETH-PERPETUAL","bids":[["delete",1577.1,0.0],["delete",1577.05,0.0],["delete",1577.0,0.0],["delete",1576.95,0.0],["delete",1576.8,0.0],["delete",1576.75,0.0]],"asks":[["change",1577.7,5705533.0],["delete",1578.75,0.0],["delete",1578.8,0.0],["delete",1578.85,0.0],["delete",1578.9,0.0],["delete",1578.95,0.0],["delete",1579.0,0.0],["delete",1579.05,0.0],["new",1579.75,963.0],["new",1579.8,10271.0],["new",1579.85,1023.0],["new",1579.9,38257.0],["new",1579.95,15035.0],["new",1580.0,98110.0],["new",1580.05,26023.0]],"prev_change_id":23707266846}}}
[2025-04-07 08:32:18.181] [multi_sink] [info] 📩 Received: {"jsonrpc":"2.0","method":"subscription","params":{"channel":"book.ETH-PERPETUAL.100ms","data":{"timestamp":1743994939624,"type":"change","change_id":23707267304,"instrument_name":"ETH-PERPETUAL","bids":[],"asks":[["change",1577.7,5640865.0],["delete",1579.1,0.0],["delete",1579.15,0.0],["delete",1579.2,0.0],["change",1579.25,1839.0],["new",1579.6,1023.0],["new",1579.65,13422.0],["new",1579.7,6194.0]],"prev_change_id":23707267129}}}
[2025-04-07 08:32:18.184] [multi_sink] [info] Processing received message: {"jsonrpc":"2.0","method":"subscription","params":{"channel":"book.ETH-PERPETUAL.100ms","data":{"timestamp":1743994939624,"type":"change","change_id":23707267304,"instrument_name":"ETH-PERPETUAL","bids":[],"asks":[["change",1577.7,5640865.0],["delete",1579.1,0.0],["delete",1579.15,0.0],["delete",1579.2,0.0],["change",1579.25,1839.0],["new",1579.6,1023.0],["new",1579.65,13422.0],["new",1579.7,6194.0]],"prev_change_id":23707267129}}}
[2025-04-07 08:32:18.549] [multi_sink] [info] 📩 Received: {"jsonrpc":"2.0","method":"subscription","params":{"channel":"book.BTC-PERPETUAL.100ms","data":{"timestamp":1743994939919,"type":"change","change_id":41152061130,"instrument_name":"BTC-PERPETUAL","bids":[],"asks":[["new",78550.0,78550.0],["delete",78560.0,0.0],["new",7.86e4,1.179e5],["delete",78610.0,0.0]],"prev_change_id":41152059460}}}
[2025-04-07 08:32:18.549] [multi_sink] [info] Processing received message: {"jsonrpc":"2.0","method":"subscription","params":{"channel":"book.BTC-PERPETUAL.100ms","data":{"timestamp":1743994939919,"type":"change","change_id":41152061130,"instrument_name":"BTC-PERPETUAL","bids":[],"asks":[["new",78550.0,78550.0],["delete",78560.0,0.0],["new",7.86e4,1.179e5],["delete",78610.0,0.0]],"prev_change_id":41152059460}}}
[2025-04-07 08:32:18.880] [multi_sink] [info] 📩 Received: {"jsonrpc":"2.0","method":"subscription","params":{"channel":"book.BTC-PERPETUAL.100ms","data":{"timestamp":1743994940488,"type":"change","change_id":41152062202,"instrument_name":"BTC-PERPETUAL","bids":[["delete",78378.0,0.0],["delete",78377.5,0.0],["delete",78355.5,0.0],["new",78353.5,9.0e3],["new",78351.0,54280.0],["new",78350.0,2890.0],["delete",78226.0,0.0],["new",78197.5,78190.0],["delete",78176.0,0.0],["new",78147.5,117210.0]],"asks":[["delete",78404.0,0.0],["new",78415.0,5170.0],["new",78417.5,46730.0],["new",78418.0,1.5e5],["new",78418.5,35320.0],["new",78539.5,78540.0],["delete",78550.0,0.0],["new",78589.5,117880.0],["delete",7.86e4,0.0]],"prev_change_id":41152061130}}}
[2025-04-07 08:32:18.884] [multi_sink] [info] Processing received message: {"jsonrpc":"2.0","method":"subscription","params":{"channel":"book.BTC-PERPETUAL.100ms","data":{"timestamp":1743994940488,"type":"change","change_id":41152062202,"instrument_name":"BTC-PERPETUAL","bids":[["delete",78378.0,0.0],["delete",78377.5,0.0],["delete",78355.5,0.0],["new",78353.5,9.0e3],["new",78351.0,54280.0],["new",78350.0,2890.0],["delete",78226.0,0.0],["new",78197.5,78190.0],["delete",78176.0,0.0],["new",78147.5,117210.0]],"asks":[["delete",78404.0,0.0],["new",78415.0,5170.0],["new",78417.5,46730.0],["new",78418.0,1.5e5],["new",78418.5,35320.0],["new",78539.5,78540.0],["delete",78550.0,0.0],["new",78589.5,117880.0],["delete",7.86e4,0.0]],"prev_change_id":41152061130}}}
[2025-04-07 08:32:18.911] [multi_sink] [info] 📩 Received: {"jsonrpc":"2.0","method":"subscription","params":{"channel":"book.ETH-PERPETUAL.100ms","data":{"timestamp":1743994940545,"type":"change","change_id":23707268348,"instrument_name":"ETH-PERPETUAL","bids":[],"asks":[["delete",1577.7,0.0],["change",1579.95,5.6559e6]],"prev_change_id":23707267304}}}
[2025-04-07 08:32:18.915] [multi_sink] [info] Processing received message: {"jsonrpc":"2.0","method":"subscription","params":{"channel":"book.ETH-PERPETUAL.100ms","data":{"timestamp":1743994940545,"type":"change","change_id":23707268348,"instrument_name":"ETH-PERPETUAL","bids":[],"asks":[["delete",1577.7,0.0],["change",1579.95,5.6559e6]],"prev_change_id":23707267304}}}
[2025-04-07 08:32:19.209] [multi_sink] [info] 📩 Received: {"jsonrpc":"2.0","method":"subscription","params":{"channel":"book.BTC-PERPETUAL.100ms","data":{"timestamp":1743994940826,"type":"change","change_id":41152062378,"instrument_name":"BTC-PERPETUAL","bids":[["new",78366.0,33470.0],["new",78365.0,16490.0],["new",78364.5,39980.0],["new",78363.5,1550.0],["new",78362.0,5170.0],["new",78359.0,1550.0],["new",78358.5,5170.0],["new",78356.0,14520.0],["new",78355.0,39410.0]],"asks":[["new",78401.0,34940.0],["new",78401.5,81640.0],["new",78403.0,34810.0],["new",78407.0,290.0],["new",78408.0,10.0],["new",78408.5,6070.0],["new",78410.0,3290.0],["new",78411.5,13830.0],["new",78412.0,4650.0]],"prev_change_id":41152062202}}}
[2025-04-07 08:32:19.212] [multi_sink] [info] Processing received message: {"jsonrpc":"2.0","method":"subscription","params":{"channel":"book.BTC-PERPETUAL.100ms","data":{"timestamp":1743994940826,"type":"change","change_id":41152062378,"instrument_name":"BTC-PERPETUAL","bids":[["new",78366.0,33470.0],["new",78365.0,16490.0],["new",78364.5,39980.0],["new",78363.5,1550.0],["new",78362.0,5170.0],["new",78359.0,1550.0],["new",78358.5,5170.0],["new",78356.0,14520.0],["new",78355.0,39410.0]],"asks":[["new",78401.0,34940.0],["new",78401.5,81640.0],["new",78403.0,34810.0],["new",78407.0,290.0],["new",78408.0,10.0],["new",78408.5,6070.0],["new",78410.0,3290.0],["new",78411.5,13830.0],["new",78412.0,4650.0]],"prev_change_id":41152062202}}}
[2025-04-07 08:32:19.243] [multi_sink] [info] 📩 Received: {"jsonrpc":"2.0","method":"subscription","params":{"channel":"book.ETH-PERPETUAL.100ms","data":{"timestamp":1743994940694,"type":"change","change_id":23707268415,"instrument_name":"ETH-PERPETUAL","bids":[],"asks":[["delete",1581.95,0.0],["new",1584.0,500.0],["delete",1584.7,0.0],["new",1587.15,500.0]],"prev_change_id":23707268348}}}
[2025-04-07 08:32:19.245] [multi_sink] [info] Processing received message: {"jsonrpc":"2.0","method":"subscription","params":{"channel":"book.ETH-PERPETUAL.100ms","data":{"timestamp":1743994940694,"type":"change","change_id":23707268415,"instrument_name":"ETH-PERPETUAL","bids":[],"asks":[["delete",1581.95,0.0],["new",1584.0,500.0],["delete",1584.7,0.0],["new",1587.15,500.0]],"prev_change_id":23707268348}}}
[2025-04-07 08:32:19.539] [multi_sink] [info] 📩 Received: {"jsonrpc":"2.0","method":"subscription","params":{"channel":"book.BTC-PERPETUAL.100ms","data":{"timestamp":1743994941094,"type":"change","change_id":41152063069,"instrument_name":"BTC-PERPETUAL","bids":[["new",78394.5,3.03e4],["new",78382.5,9430.0],["new",78378.0,650.0],["new",78375.0,470.0],["new",78373.0,1720.0],["new",78372.5,5740.0],["new",78367.5,21890.0]],"asks":[["new",78395.0,235660.0],["new",78396.0,4.1e4],["new",78398.0,4.57e4],["new",78398.5,1.65e4],["new",78399.0,83160.0],["new",78399.5,2.1e4],["new",7.84e4,15170.0]],"prev_change_id":41152062378}}}
[2025-04-07 08:32:19.544] [multi_sink] [info] Processing received message: {"jsonrpc":"2.0","method":"subscription","params":{"channel":"book.BTC-PERPETUAL.100ms","data":{"timestamp":1743994941094,"type":"change","change_id":41152063069,"instrument_name":"BTC-PERPETUAL","bids":[["new",78394.5,3.03e4],["new",78382.5,9430.0],["new",78378.0,650.0],["new",78375.0,470.0],["new",78373.0,1720.0],["new",78372.5,5740.0],["new",78367.5,21890.0]],"asks":[["new",78395.0,235660.0],["new",78396.0,4.1e4],["new",78398.0,4.57e4],["new",78398.5,1.65e4],["new",78399.0,83160.0],["new",78399.5,2.1e4],["new",7.84e4,15170.0]],"prev_change_id":41152062378}}}
[2025-04-07 08:32:19.878] [multi_sink] [info] 📩 Received: {"jsonrpc":"2.0","method":"subscription","params":{"channel":"book.BTC-PERPETUAL.100ms","data":{"timestamp":1743994941251,"type":"change","change_id":41152063120,"instrument_name":"BTC-PERPETUAL","bids":[["delete",78197.5,0.0],["delete",78147.5,0.0]],"asks":[],"prev_change_id":41152063069}}}
[2025-04-07 08:32:19.880] [multi_sink] [info] Processing received message: {"jsonrpc":"2.0","method":"subscription","params":{"channel":"book.BTC-PERPETUAL.100ms","data":{"timestamp":1743994941251,"type":"change","change_id":41152063120,"instrument_name":"BTC-PERPETUAL","bids":[["delete",78197.5,0.0],["delete",78147.5,0.0]],"asks":[],"prev_change_id":41152063069}}}
[2025-04-07 08:32:20.896] [multi_sink] [info] 📩 Received: {"jsonrpc":"2.0","method":"subscription","params":{"channel":"book.BTC-PERPETUAL.100ms","data":{"timestamp":1743994942489,"type":"change","change_id":41152065370,"instrument_name":"BTC-PERPETUAL","bids":[["new",78203.0,7.82e4],["new",78153.0,117220.0]],"asks":[],"prev_change_id":41152063120}}}
[2025-04-07 08:32:20.900] [multi_sink] [info] Processing received message: {"jsonrpc":"2.0","method":"subscription","params":{"channel":"book.BTC-PERPETUAL.100ms","data":{"timestamp":1743994942489,"type":"change","change_id":41152065370,"instrument_name":"BTC-PERPETUAL","bids":[["new",78203.0,7.82e4],["new",78153.0,117220.0]],"asks":[],"prev_change_id":41152063120}}}
[2025-04-07 08:32:22.191] [multi_sink] [info] 📩 Received: {"jsonrpc":"2.0","method":"subscription","params":{"channel":"book.ETH-PERPETUAL.100ms","data":{"timestamp":1743994943825,"type":"change","change_id":23707271353,"instrument_name":"ETH-PERPETUAL","bids":[],"asks":[["delete",1579.25,0.0],["change",1580.5,130175.0]],"prev_change_id":23707268415}}}
[2025-04-07 08:32:22.192] [multi_sink] [info] Processing received message: {"jsonrpc":"2.0","method":"subscription","params":{"channel":"book.ETH-PERPETUAL.100ms","data":{"timestamp":1743994943825,"type":"change","change_id":23707271353,"instrument_name":"ETH-PERPETUAL","bids":[],"asks":[["delete",1579.25,0.0],["change",1580.5,130175.0]],"prev_change_id":23707268415}}}
[2025-04-07 08:32:22.521] [multi_sink] [info] 📩 Received: {"jsonrpc":"2.0","method":"subscription","params":{"channel":"book.ETH-PERPETUAL.100ms","data":{"timestamp":1743994944123,"type":"change","change_id":23707271919,"instrument_name":"ETH-PERPETUAL","bids":[["new",1578.75,2525.0],["new",1578.7,921.0],["new",1578.65,21699.0],["new",1578.6,42885.0],["new",1578.55,2216.0],["new",1578.5,3418.0],["new",1578.45,9423.0],["new",1578.4,8190.0],["new",1578.35,10516.0],["new",1573.6,500.0],["delete",1571.4,0.0]],"asks":[["delete",1579.6,0.0],["delete",1579.65,0.0],["delete",1579.7,0.0],["delete",1579.75,0.0],["delete",1579.8,0.0],["delete",1579.85,0.0],["delete",1579.9,0.0],["change",1579.95,5640865.0],["change",1580.1,35148.0],["change",1580.15,2981.0],["change",1580.2,17284.0],["change",1580.25,4009.0],["change",1580.3,8830.0],["change",1580.35,5474.0],["change",1580.4,1.094e5],["change",1580.45,51946.0]],"prev_change_id":23707271353}}}
[2025-04-07 08:32:22.526] [multi_sink] [info] Processing received message: {"jsonrpc":"2.0","method":"subscription","params":{"channel":"book.ETH-PERPETUAL.100ms","data":{"timestamp":1743994944123,"type":"change","change_id":23707271919,"instrument_name":"ETH-PERPETUAL","bids":[["new",1578.75,2525.0],["new",1578.7,921.0],["new",1578.65,21699.0],["new",1578.6,42885.0],["new",1578.55,2216.0],["new",1578.5,3418.0],["new",1578.45,9423.0],["new",1578.4,8190.0],["new",1578.35,10516.0],["new",1573.6,500.0],["delete",1571.4,0.0]],"asks":[["delete",1579.6,0.0],["delete",1579.65,0.0],["delete",1579.7,0.0],["delete",1579.75,0.0],["delete",1579.8,0.0],["delete",1579.85,0.0],["delete",1579.9,0.0],["change",1579.95,5640865.0],["change",1580.1,35148.0],["change",1580.15,2981.0],["change",1580.2,17284.0],["change",1580.25,4009.0],["change",1580.3,8830.0],["change",1580.35,5474.0],["change",1580.4,1.094e5],["change",1580.45,51946.0]],"prev_change_id":23707271353}}}
[2025-04-07 08:32:22.596] [multi_sink] [info] 📩 Received: {"jsonrpc":"2.0","method":"subscription","params":{"channel":"book.BTC-PERPETUAL.100ms","data":{"timestamp":1743994944152,"type":"change","change_id":41152067437,"instrument_name":"BTC-PERPETUAL","bids":[["delete",78203.0,0.0],["new",78185.5,78180.0],["delete",78153.0,0.0],["new",78135.5,1.172e5]],"asks":[["delete",78539.5,0.0],["delete",78589.5,0.0]],"prev_change_id":41152065370}}}
[2025-04-07 08:32:22.600] [multi_sink] [info] Processing received message: {"jsonrpc":"2.0","method":"subscription","params":{"channel":"book.BTC-PERPETUAL.100ms","data":{"timestamp":1743994944152,"type":"change","change_id":41152067437,"instrument_name":"BTC-PERPETUAL","bids":[["delete",78203.0,0.0],["new",78185.5,78180.0],["delete",78153.0,0.0],["new",78135.5,1.172e5]],"asks":[["delete",78539.5,0.0],["delete",78589.5,0.0]],"prev_change_id":41152065370}}}
[2025-04-07 08:32:22.851] [multi_sink] [info] 📩 Received: {"jsonrpc":"2.0","method":"subscription","params":{"channel":"book.ETH-PERPETUAL.100ms","data":{"timestamp":1743994944470,"type":"change","change_id":23707272321,"instrument_name":"ETH-PERPETUAL","bids":[["new",1579.2,400.0],["new",1579.15,3225.0],["new",1579.1,5.0e3],["new",1579.05,18747.0],["new",1579.0,100.0],["new",1578.95,51768.0],["new",1578.9,14882.0],["new",1578.85,37653.0],["new",1578.8,7.14e4]],"asks":[["new",1579.6,10276.0],["new",1579.65,17587.0],["new",1579.75,3068.0],["new",1579.8,13279.0],["new",1579.85,100.0],["new",1579.9,15874.0],["change",1579.95,5647811.0],["change",1580.0,33009.0],["change",1580.05,86808.0],["change",1580.1,24925.0],["change",1580.15,1958.0],["change",1580.2,8094.0],["change",1580.25,2986.0],["change",1580.3,4055.0],["change",1580.35,1063.0],["change",1580.4,72079.0]],"prev_change_id":23707271919}}}
[2025-04-07 08:32:22.853] [multi_sink] [info] Processing received message: {"jsonrpc":"2.0","method":"subscription","params":{"channel":"book.ETH-PERPETUAL.100ms","data":{"timestamp":1743994944470,"type":"change","change_id":23707272321,"instrument_name":"ETH-PERPETUAL","bids":[["new",1579.2,400.0],["new",1579.15,3225.0],["new",1579.1,5.0e3],["new",1579.05,18747.0],["new",1579.0,100.0],["new",1578.95,51768.0],["new",1578.9,14882.0],["new",1578.85,37653.0],["new",1578.8,7.14e4]],"asks":[["new",1579.6,10276.0],["new",1579.65,17587.0],["new",1579.75,3068.0],["new",1579.8,13279.0],["new",1579.85,100.0],["new",1579.9,15874.0],["change",1579.95,5647811.0],["change",1580.0,33009.0],["change",1580.05,86808.0],["change",1580.1,24925.0],["change",1580.15,1958.0],["change",1580.2,8094.0],["change",1580.25,2986.0],["change",1580.3,4055.0],["change",1580.35,1063.0],["change",1580.4,72079.0]],"prev_change_id":23707271919}}}
[2025-04-07 08:32:22.906] [multi_sink] [info] 📩 Received: {"jsonrpc":"2.0","method":"subscription","params":{"channel":"book.BTC-PERPETUAL.100ms","data":{"timestamp":1743994944252,"type":"change","change_id":41152067440,"instrument_name":"BTC-PERPETUAL","bids":[["delete",78185.5,0.0],["delete",78135.5,0.0]],"asks":[],"prev_change_id":41152067437}}}
[2025-04-07 08:32:22.906] [multi_sink] [info] Processing received message: {"jsonrpc":"2.0","method":"subscription","params":{"channel":"book.BTC-PERPETUAL.100ms","data":{"timestamp":1743994944252,"type":"change","change_id":41152067440,"instrument_name":"BTC-PERPETUAL","bids":[["delete",78185.5,0.0],["delete",78135.5,0.0]],"asks":[],"prev_change_id":41152067437}}}
[2025-04-07 08:32:23.198] [multi_sink] [info] 📩 Received: {"jsonrpc":"2.0","method":"subscription","params":{"channel":"book.ETH-PERPETUAL.100ms","data":{"timestamp":1743994944698,"type":"change","change_id":23707272456,"instrument_name":"ETH-PERPETUAL","bids":[["new",1579.45,15894.0],["new",1579.25,385.0],["new",1571.55,500.0],["delete",1569.1,0.0]],"asks":[["new",1579.5,12663.0],["new",1579.55,5.0e3],["change",1580.45,26023.0],["change",1580.5,57481.0]],"prev_change_id":23707272321}}}
[2025-04-07 08:32:23.199] [multi_sink] [info] Processing received message: {"jsonrpc":"2.0","method":"subscription","params":{"channel":"book.ETH-PERPETUAL.100ms","data":{"timestamp":1743994944698,"type":"change","change_id":23707272456,"instrument_name":"ETH-PERPETUAL","bids":[["new",1579.45,15894.0],["new",1579.25,385.0],["new",1571.55,500.0],["delete",1569.1,0.0]],"asks":[["new",1579.5,12663.0],["new",1579.55,5.0e3],["change",1580.45,26023.0],["change",1580.5,57481.0]],"prev_change_id":23707272321}}}
[2025-04-07 08:32:23.914] [multi_sink] [info] 📩 Received: {"jsonrpc":"2.0","method":"subscription","params":{"channel":"book.BTC-PERPETUAL.100ms","data":{"timestamp":1743994945521,"type":"change","change_id":41152069517,"instrument_name":"BTC-PERPETUAL","bids":[["delete",78394.5,0.0],["delete",78382.5,0.0],["delete",78378.0,0.0],["delete",78375.0,0.0],["delete",78373.0,0.0],["delete",78372.5,0.0]],"asks":[["new",78368.0,10310.0],["new",78368.5,34350.0],["new",78369.5,1.52e4],["new",78372.5,101570.0],["new",78373.0,78660.0],["delete",78395.0,0.0],["delete",78396.0,0.0],["delete",78398.0,0.0],["delete",78398.5,0.0],["delete",78399.0,0.0]],"prev_change_id":41152067440}}}
[2025-04-07 08:32:23.915] [multi_sink] [info] Processing received message: {"jsonrpc":"2.0","method":"subscription","params":{"channel":"book.BTC-PERPETUAL.100ms","data":{"timestamp":1743994945521,"type":"change","change_id":41152069517,"instrument_name":"BTC-PERPETUAL","bids":[["delete",78394.5,0.0],["delete",78382.5,0.0],["delete",78378.0,0.0],["delete",78375.0,0.0],["delete",78373.0,0.0],["delete",78372.5,0.0]],"asks":[["new",78368.0,10310.0],["new",78368.5,34350.0],["new",78369.5,1.52e4],["new",78372.5,101570.0],["new",78373.0,78660.0],["delete",78395.0,0.0],["delete",78396.0,0.0],["delete",78398.0,0.0],["delete",78398.5,0.0],["delete",78399.0,0.0]],"prev_change_id":41152067440}}}
[2025-04-07 08:32:24.244] [multi_sink] [info] 📩 Received: {"jsonrpc":"2.0","method":"subscription","params":{"channel":"book.BTC-PERPETUAL.100ms","data":{"timestamp":1743994945846,"type":"change","change_id":41152069779,"instrument_name":"BTC-PERPETUAL","bids":[["delete",78367.5,0.0],["delete",78366.0,0.0],["delete",78365.0,0.0],["delete",78364.5,0.0],["delete",78363.5,0.0],["delete",78362.0,0.0],["delete",78359.0,0.0],["delete",78358.5,0.0],["delete",78356.0,0.0],["new",78323.0,14940.0]],"asks":[["new",78356.0,33870.0],["new",78356.5,35570.0],["new",78359.0,81610.0],["new",78359.5,1.65e4],["new",78360.0,19160.0],["delete",78399.5,0.0],["delete",7.84e4,0.0],["delete",78401.0,0.0],["delete",78401.5,0.0],["delete",78403.0,0.0],["delete",78407.0,0.0],["delete",78408.0,0.0],["delete",78408.5,0.0],["delete",78410.0,0.0]],"prev_change_id":41152069517}}}
[2025-04-07 08:32:24.246] [multi_sink] [info] Processing received message: {"jsonrpc":"2.0","method":"subscription","params":{"channel":"book.BTC-PERPETUAL.100ms","data":{"timestamp":1743994945846,"type":"change","change_id":41152069779,"instrument_name":"BTC-PERPETUAL","bids":[["delete",78367.5,0.0],["delete",78366.0,0.0],["delete",78365.0,0.0],["delete",78364.5,0.0],["delete",78363.5,0.0],["delete",78362.0,0.0],["delete",78359.0,0.0],["delete",78358.5,0.0],["delete",78356.0,0.0],["new",78323.0,14940.0]],"asks":[["new",78356.0,33870.0],["new",78356.5,35570.0],["new",78359.0,81610.0],["new",78359.5,1.65e4],["new",78360.0,19160.0],["delete",78399.5,0.0],["delete",7.84e4,0.0],["delete",78401.0,0.0],["delete",78401.5,0.0],["delete",78403.0,0.0],["delete",78407.0,0.0],["delete",78408.0,0.0],["delete",78408.5,0.0],["delete",78410.0,0.0]],"prev_change_id":41152069517}}}
[2025-04-07 08:32:24.581] [multi_sink] [info] 📩 Received: {"jsonrpc":"2.0","method":"subscription","params":{"channel":"book.BTC-PERPETUAL.100ms","data":{"timestamp":1743994946157,"type":"change","change_id":41152070420,"instrument_name":"BTC-PERPETUAL","bids":[["delete",78355.0,0.0],["delete",78353.5,0.0],["delete",78351.0,0.0],["delete",78350.0,0.0],["new",78345.5,13750.0],["new",78338.0,5590.0],["new",78337.5,9430.0],["new",78336.5,9.0e3],["new",78180.0,78180.0],["new",78130.0,117190.0]],"asks":[["new",78346.0,6.17e4],["new",78346.5,2.1e4],["new",78349.0,600.0],["new",78352.0,17820.0],["new",78355.0,2.2e4],["new",78355.5,44480.0],["delete",78411.5,0.0],["delete",78412.0,0.0],["delete",78415.0,0.0],["delete",78417.5,0.0],["delete",78418.0,0.0],["delete",78418.5,0.0],["new",78515.0,78510.0],["new",78565.0,117840.0]],"prev_change_id":41152069779}}}
[2025-04-07 08:32:24.583] [multi_sink] [info] Processing received message: {"jsonrpc":"2.0","method":"subscription","params":{"channel":"book.BTC-PERPETUAL.100ms","data":{"timestamp":1743994946157,"type":"change","change_id":41152070420,"instrument_name":"BTC-PERPETUAL","bids":[["delete",78355.0,0.0],["delete",78353.5,0.0],["delete",78351.0,0.0],["delete",78350.0,0.0],["new",78345.5,13750.0],["new",78338.0,5590.0],["new",78337.5,9430.0],["new",78336.5,9.0e3],["new",78180.0,78180.0],["new",78130.0,117190.0]],"asks":[["new",78346.0,6.17e4],["new",78346.5,2.1e4],["new",78349.0,600.0],["new",78352.0,17820.0],["new",78355.0,2.2e4],["new",78355.5,44480.0],["delete",78411.5,0.0],["delete",78412.0,0.0],["delete",78415.0,0.0],["delete",78417.5,0.0],["delete",78418.0,0.0],["delete",78418.5,0.0],["new",78515.0,78510.0],["new",78565.0,117840.0]],"prev_change_id":41152069779}}}
[2025-04-07 08:32:25.010] [multi_sink] [info] 📩 Received: {"jsonrpc":"2.0","method":"subscription","params":{"channel":"book.BTC-PERPETUAL.100ms","data":{"timestamp":1743994946636,"type":"change","change_id":41152071309,"instrument_name":"BTC-PERPETUAL","bids":[["new",78191.0,78190.0],["delete",78180.0,0.0]],"asks":[],"prev_change_id":41152070420}}}
[2025-04-07 08:32:25.012] [multi_sink] [info] Processing received message: {"jsonrpc":"2.0","method":"subscription","params":{"channel":"book.BTC-PERPETUAL.100ms","data":{"timestamp":1743994946636,"type":"change","change_id":41152071309,"instrument_name":"BTC-PERPETUAL","bids":[["new",78191.0,78190.0],["delete",78180.0,0.0]],"asks":[],"prev_change_id":41152070420}}}
[2025-04-07 08:32:25.333] [multi_sink] [info] 📩 Received: {"jsonrpc":"2.0","method":"subscription","params":{"channel":"book.BTC-PERPETUAL.100ms","data":{"timestamp":1743994946638,"type":"change","change_id":41152071312,"instrument_name":"BTC-PERPETUAL","bids":[["new",78141.0,117210.0],["delete",78130.0,0.0]],"asks":[],"prev_change_id":41152071309}}}
[2025-04-07 08:32:25.337] [multi_sink] [info] Processing received message: {"jsonrpc":"2.0","method":"subscription","params":{"channel":"book.BTC-PERPETUAL.100ms","data":{"timestamp":1743994946638,"type":"change","change_id":41152071312,"instrument_name":"BTC-PERPETUAL","bids":[["new",78141.0,117210.0],["delete",78130.0,0.0]],"asks":[],"prev_change_id":41152071309}}}
[2025-04-07 08:32:25.662] [multi_sink] [info] 📩 Received: {"jsonrpc":"2.0","method":"subscription","params":{"channel":"book.BTC-PERPETUAL.100ms","data":{"timestamp":1743994947028,"type":"change","change_id":41152072002,"instrument_name":"BTC-PERPETUAL","bids":[],"asks":[["delete",78515.0,0.0],["delete",78565.0,0.0]],"prev_change_id":41152071312}}}
[2025-04-07 08:32:25.667] [multi_sink] [info] Processing received message: {"jsonrpc":"2.0","method":"subscription","params":{"channel":"book.BTC-PERPETUAL.100ms","data":{"timestamp":1743994947028,"type":"change","change_id":41152072002,"instrument_name":"BTC-PERPETUAL","bids":[],"asks":[["delete",78515.0,0.0],["delete",78565.0,0.0]],"prev_change_id":41152071312}}}
[2025-04-07 08:32:25.993] [multi_sink] [info] 📩 Received: {"jsonrpc":"2.0","method":"subscription","params":{"channel":"book.BTC-PERPETUAL.100ms","data":{"timestamp":1743994947326,"type":"change","change_id":41152072353,"instrument_name":"BTC-PERPETUAL","bids":[["delete",78191.0,0.0],["delete",78141.0,0.0]],"asks":[],"prev_change_id":41152072002}}}
[2025-04-07 08:32:25.995] [multi_sink] [info] Processing received message: {"jsonrpc":"2.0","method":"subscription","params":{"channel":"book.BTC-PERPETUAL.100ms","data":{"timestamp":1743994947326,"type":"change","change_id":41152072353,"instrument_name":"BTC-PERPETUAL","bids":[["delete",78191.0,0.0],["delete",78141.0,0.0]],"asks":[],"prev_change_id":41152072002}}}
[2025-04-07 08:32:26.016] [multi_sink] [info] 📩 Received: {"jsonrpc":"2.0","method":"subscription","params":{"channel":"book.ETH-PERPETUAL.100ms","data":{"timestamp":1743994947433,"type":"change","change_id":23707275284,"instrument_name":"ETH-PERPETUAL","bids":[["new",1577.9,7545952.0],["delete",1576.2,0.0]],"asks":[],"prev_change_id":23707272456}}}
[2025-04-07 08:32:26.021] [multi_sink] [info] Processing received message: {"jsonrpc":"2.0","method":"subscription","params":{"channel":"book.ETH-PERPETUAL.100ms","data":{"timestamp":1743994947433,"type":"change","change_id":23707275284,"instrument_name":"ETH-PERPETUAL","bids":[["new",1577.9,7545952.0],["delete",1576.2,0.0]],"asks":[],"prev_change_id":23707272456}}}
[2025-04-07 08:32:26.337] [multi_sink] [info] 📩 Received: {"jsonrpc":"2.0","method":"subscription","params":{"channel":"book.ETH-PERPETUAL.100ms","data":{"timestamp":1743994947775,"type":"change","change_id":23707275470,"instrument_name":"ETH-PERPETUAL","bids":[["delete",1579.45,0.0]],"asks":[["new",1579.4,5624971.0],["change",1579.95,6946.0]],"prev_change_id":23707275284}}}
[2025-04-07 08:32:26.341] [multi_sink] [info] Processing received message: {"jsonrpc":"2.0","method":"subscription","params":{"channel":"book.ETH-PERPETUAL.100ms","data":{"timestamp":1743994947775,"type":"change","change_id":23707275470,"instrument_name":"ETH-PERPETUAL","bids":[["delete",1579.45,0.0]],"asks":[["new",1579.4,5624971.0],["change",1579.95,6946.0]],"prev_change_id":23707275284}}}
[2025-04-07 08:32:27.055] [multi_sink] [info] 📩 Received: {"jsonrpc":"2.0","method":"subscription","params":{"channel":"book.BTC-PERPETUAL.100ms","data":{"timestamp":1743994948690,"type":"change","change_id":41152074275,"instrument_name":"BTC-PERPETUAL","bids":[],"asks":[["new",78538.5,78530.0]],"prev_change_id":41152072353}}}
[2025-04-07 08:32:27.060] [multi_sink] [info] Processing received message: {"jsonrpc":"2.0","method":"subscription","params":{"channel":"book.BTC-PERPETUAL.100ms","data":{"timestamp":1743994948690,"type":"change","change_id":41152074275,"instrument_name":"BTC-PERPETUAL","bids":[],"asks":[["new",78538.5,78530.0]],"prev_change_id":41152072353}}}
[2025-04-07 08:32:27.201] [multi_sink] [info] 📩 Received: {"jsonrpc":"2.0","method":"subscription","params":{"channel":"book.ETH-PERPETUAL.100ms","data":{"timestamp":1743994948831,"type":"change","change_id":23707276629,"instrument_name":"ETH-PERPETUAL","bids":[],"asks":[["delete",1579.5,0.0],["new",1580.65,918.0]],"prev_change_id":23707275470}}}
[2025-04-07 08:32:27.204] [multi_sink] [info] Processing received message: {"jsonrpc":"2.0","method":"subscription","params":{"channel":"book.ETH-PERPETUAL.100ms","data":{"timestamp":1743994948831,"type":"change","change_id":23707276629,"instrument_name":"ETH-PERPETUAL","bids":[],"asks":[["delete",1579.5,0.0],["new",1580.65,918.0]],"prev_change_id":23707275470}}}
[2025-04-07 08:32:27.387] [multi_sink] [info] 📩 Received: {"jsonrpc":"2.0","method":"subscription","params":{"channel":"book.BTC-PERPETUAL.100ms","data":{"timestamp":1743994948692,"type":"change","change_id":41152074276,"instrument_name":"BTC-PERPETUAL","bids":[],"asks":[["new",78588.5,117870.0]],"prev_change_id":41152074275}}}
[2025-04-07 08:32:27.390] [multi_sink] [info] Processing received message: {"jsonrpc":"2.0","method":"subscription","params":{"channel":"book.BTC-PERPETUAL.100ms","data":{"timestamp":1743994948692,"type":"change","change_id":41152074276,"instrument_name":"BTC-PERPETUAL","bids":[],"asks":[["new",78588.5,117870.0]],"prev_change_id":41152074275}}}
[2025-04-07 08:32:27.527] [multi_sink] [info] 📩 Received: {"jsonrpc":"2.0","method":"subscription","params":{"channel":"book.ETH-PERPETUAL.100ms","data":{"timestamp":1743994949135,"type":"change","change_id":23707277288,"instrument_name":"ETH-PERPETUAL","bids":[["delete",1579.25,0.0],["delete",1579.2,0.0],["delete",1579.15,0.0],["delete",1579.1,0.0],["delete",1579.05,0.0],["delete",1579.0,0.0],["delete",1578.95,0.0],["delete",1578.9,0.0],["change",1578.85,88313.0],["change",1578.8,126511.0],["change",1578.75,5543.0],["change",1578.7,1021.0],["change",1578.65,34048.0],["change",1578.6,43807.0],["change",1578.55,21131.0],["change",1578.5,5413.0],["change",1578.45,53623.0]],"asks":[["delete",1579.55,0.0],["delete",1579.6,0.0],["delete",1579.65,0.0],["delete",1579.75,0.0],["delete",1579.8,0.0],["delete",1579.85,0.0],["delete",1579.9,0.0],["delete",1579.95,0.0],["change",1580.25,4009.0],["change",1580.3,33082.0],["change",1580.35,5504.0],["change",1580.4,105607.0],["change",1580.45,54453.0],["change",1580.5,128138.0],["new",1580.55,7023.0],["new",1580.6,49542.0]],"prev_change_id":23707276629}}}
[2025-04-07 08:32:27.529] [multi_sink] [info] Processing received message: {"jsonrpc":"2.0","method":"subscription","params":{"channel":"book.ETH-PERPETUAL.100ms","data":{"timestamp":1743994949135,"type":"change","change_id":23707277288,"instrument_name":"ETH-PERPETUAL","bids":[["delete",1579.25,0.0],["delete",1579.2,0.0],["delete",1579.15,0.0],["delete",1579.1,0.0],["delete",1579.05,0.0],["delete",1579.0,0.0],["delete",1578.95,0.0],["delete",1578.9,0.0],["change",1578.85,88313.0],["change",1578.8,126511.0],["change",1578.75,5543.0],["change",1578.7,1021.0],["change",1578.65,34048.0],["change",1578.6,43807.0],["change",1578.55,21131.0],["change",1578.5,5413.0],["change",1578.45,53623.0]],"asks":[["delete",1579.55,0.0],["delete",1579.6,0.0],["delete",1579.65,0.0],["delete",1579.75,0.0],["delete",1579.8,0.0],["delete",1579.85,0.0],["delete",1579.9,0.0],["delete",1579.95,0.0],["change",1580.25,4009.0],["change",1580.3,33082.0],["change",1580.35,5504.0],["change",1580.4,105607.0],["change",1580.45,54453.0],["change",1580.5,128138.0],["new",1580.55,7023.0],["new",1580.6,49542.0]],"prev_change_id":23707276629}}}
[2025-04-07 08:32:27.718] [multi_sink] [info] 📩 Received: {"jsonrpc":"2.0","method":"subscription","params":{"channel":"book.BTC-PERPETUAL.100ms","data":{"timestamp":1743994949031,"type":"change","change_id":41152074887,"instrument_name":"BTC-PERPETUAL","bids":[["new",78211.5,78210.0],["new",78161.5,117240.0]],"asks":[],"prev_change_id":41152074276}}}
[2025-04-07 08:32:27.721] [multi_sink] [info] Processing received message: {"jsonrpc":"2.0","method":"subscription","params":{"channel":"book.BTC-PERPETUAL.100ms","data":{"timestamp":1743994949031,"type":"change","change_id":41152074887,"instrument_name":"BTC-PERPETUAL","bids":[["new",78211.5,78210.0],["new",78161.5,117240.0]],"asks":[],"prev_change_id":41152074276}}}
[2025-04-07 08:32:27.858] [multi_sink] [info] 📩 Received: {"jsonrpc":"2.0","method":"subscription","params":{"channel":"book.ETH-PERPETUAL.100ms","data":{"timestamp":1743994949474,"type":"change","change_id":23707277727,"instrument_name":"ETH-PERPETUAL","bids":[["new",1579.3,9894.0],["new",1579.25,33221.0],["new",1579.2,5.0e3],["new",1579.15,15560.0],["new",1579.1,31493.0],["new",1579.05,5117.0],["new",1579.0,15014.0],["new",1578.95,22093.0],["new",1578.9,8515.0],["change",1578.8,55111.0],["change",1578.75,3018.0],["change",1578.7,100.0],["change",1578.65,12349.0],["change",1578.6,922.0],["change",1578.55,18915.0],["change",1578.5,1995.0],["change",1578.45,4.42e4],["delete",1578.4,0.0]],"asks":[["new",1579.8,27489.0],["new",1579.85,100.0],["new",1579.9,1615.0],["new",1579.95,100.0],["change",1580.0,39794.0],["change",1580.05,1021.0],["change",1580.1,85584.0],["change",1580.15,3465.0],["change",1580.2,16645.0],["change",1580.25,1023.0],["change",1580.3,29027.0],["change",1580.35,4441.0],["change",1580.4,33528.0]],"prev_change_id":23707277288}}}
[2025-04-07 08:32:27.860] [multi_sink] [info] Processing received message: {"jsonrpc":"2.0","method":"subscription","params":{"channel":"book.ETH-PERPETUAL.100ms","data":{"timestamp":1743994949474,"type":"change","change_id":23707277727,"instrument_name":"ETH-PERPETUAL","bids":[["new",1579.3,9894.0],["new",1579.25,33221.0],["new",1579.2,5.0e3],["new",1579.15,15560.0],["new",1579.1,31493.0],["new",1579.05,5117.0],["new",1579.0,15014.0],["new",1578.95,22093.0],["new",1578.9,8515.0],["change",1578.8,55111.0],["change",1578.75,3018.0],["change",1578.7,100.0],["change",1578.65,12349.0],["change",1578.6,922.0],["change",1578.55,18915.0],["change",1578.5,1995.0],["change",1578.45,4.42e4],["delete",1578.4,0.0]],"asks":[["new",1579.8,27489.0],["new",1579.85,100.0],["new",1579.9,1615.0],["new",1579.95,100.0],["change",1580.0,39794.0],["change",1580.05,1021.0],["change",1580.1,85584.0],["change",1580.15,3465.0],["change",1580.2,16645.0],["change",1580.25,1023.0],["change",1580.3,29027.0],["change",1580.35,4441.0],["change",1580.4,33528.0]],"prev_change_id":23707277288}}}
[2025-04-07 08:32:28.190] [multi_sink] [info] 📩 Received: {"jsonrpc":"2.0","method":"subscription","params":{"channel":"book.ETH-PERPETUAL.100ms","data":{"timestamp":1743994949549,"type":"change","change_id":23707277808,"instrument_name":"ETH-PERPETUAL","bids":[["delete",1578.35,0.0]],"asks":[["change",1579.4,5.5624e6],["new",1579.5,11.0],["new",1579.75,7837.0],["change",1580.45,28430.0],["change",1580.5,70657.0]],"prev_change_id":23707277727}}}
[2025-04-07 08:32:28.195] [multi_sink] [info] Processing received message: {"jsonrpc":"2.0","method":"subscription","params":{"channel":"book.ETH-PERPETUAL.100ms","data":{"timestamp":1743994949549,"type":"change","change_id":23707277808,"instrument_name":"ETH-PERPETUAL","bids":[["delete",1578.35,0.0]],"asks":[["change",1579.4,5.5624e6],["new",1579.5,11.0],["new",1579.75,7837.0],["change",1580.45,28430.0],["change",1580.5,70657.0]],"prev_change_id":23707277727}}}
[2025-04-07 08:32:28.950] [multi_sink] [info] 📩 Received: {"jsonrpc":"2.0","method":"subscription","params":{"channel":"book.BTC-PERPETUAL.100ms","data":{"timestamp":1743994950571,"type":"change","change_id":41152077077,"instrument_name":"BTC-PERPETUAL","bids":[["new",78355.0,34350.0],["new",78354.0,14940.0],["new",78353.5,5160.0],["new",78350.5,1550.0],["new",78350.0,4560.0],["delete",78345.5,0.0],["delete",78338.0,0.0],["delete",78337.5,0.0],["delete",78336.5,0.0],["delete",78323.0,0.0],["delete",78211.5,0.0],["new",78201.0,7.82e4],["delete",78161.5,0.0],["new",78151.0,117220.0]],"asks":[["delete",78346.0,0.0],["delete",78346.5,0.0],["delete",78349.0,0.0],["delete",78352.0,0.0],["delete",78355.0,0.0],["delete",78355.5,0.0],["new",78390.5,14590.0],["new",78391.0,480.0],["new",78392.5,15210.0],["new",78394.5,29650.0],["new",78395.0,4.1e3],["delete",78538.5,0.0],["delete",78588.5,0.0]],"prev_change_id":41152074887}}}
[2025-04-07 08:32:28.954] [multi_sink] [info] Processing received message: {"jsonrpc":"2.0","method":"subscription","params":{"channel":"book.BTC-PERPETUAL.100ms","data":{"timestamp":1743994950571,"type":"change","change_id":41152077077,"instrument_name":"BTC-PERPETUAL","bids":[["new",78355.0,34350.0],["new",78354.0,14940.0],["new",78353.5,5160.0],["new",78350.5,1550.0],["new",78350.0,4560.0],["delete",78345.5,0.0],["delete",78338.0,0.0],["delete",78337.5,0.0],["delete",78336.5,0.0],["delete",78323.0,0.0],["delete",78211.5,0.0],["new",78201.0,7.82e4],["delete",78161.5,0.0],["new",78151.0,117220.0]],"asks":[["delete",78346.0,0.0],["delete",78346.5,0.0],["delete",78349.0,0.0],["delete",78352.0,0.0],["delete",78355.0,0.0],["delete",78355.5,0.0],["new",78390.5,14590.0],["new",78391.0,480.0],["new",78392.5,15210.0],["new",78394.5,29650.0],["new",78395.0,4.1e3],["delete",78538.5,0.0],["delete",78588.5,0.0]],"prev_change_id":41152074887}}}
[2025-04-07 08:32:29.287] [multi_sink] [info] 📩 Received: {"jsonrpc":"2.0","method":"subscription","params":{"channel":"book.BTC-PERPETUAL.100ms","data":{"timestamp":1743994950910,"type":"change","change_id":41152077401,"instrument_name":"BTC-PERPETUAL","bids":[["new",78359.0,490.0],["new",78358.5,11760.0],["new",78358.0,5740.0],["new",78357.0,16490.0],["new",78356.5,16490.0],["new",78355.5,11850.0]],"asks":[["delete",78356.0,0.0],["delete",78356.5,0.0],["delete",78359.0,0.0],["delete",78359.5,0.0],["delete",78360.0,0.0],["delete",78368.0,0.0],["delete",78368.5,0.0],["new",78386.0,40090.0],["new",78386.5,25190.0],["new",78387.0,21270.0],["new",78388.0,1.65e4],["new",78388.5,3950.0],["new",78389.0,44160.0],["new",78389.5,150280.0]],"prev_change_id":41152077077}}}
[2025-04-07 08:32:29.290] [multi_sink] [info] Processing received message: {"jsonrpc":"2.0","method":"subscription","params":{"channel":"book.BTC-PERPETUAL.100ms","data":{"timestamp":1743994950910,"type":"change","change_id":41152077401,"instrument_name":"BTC-PERPETUAL","bids":[["new",78359.0,490.0],["new",78358.5,11760.0],["new",78358.0,5740.0],["new",78357.0,16490.0],["new",78356.5,16490.0],["new",78355.5,11850.0]],"asks":[["delete",78356.0,0.0],["delete",78356.5,0.0],["delete",78359.0,0.0],["delete",78359.5,0.0],["delete",78360.0,0.0],["delete",78368.0,0.0],["delete",78368.5,0.0],["new",78386.0,40090.0],["new",78386.5,25190.0],["new",78387.0,21270.0],["new",78388.0,1.65e4],["new",78388.5,3950.0],["new",78389.0,44160.0],["new",78389.5,150280.0]],"prev_change_id":41152077077}}}
[2025-04-07 08:32:29.610] [multi_sink] [info] 📩 Received: {"jsonrpc":"2.0","method":"subscription","params":{"channel":"book.BTC-PERPETUAL.100ms","data":{"timestamp":1743994951177,"type":"change","change_id":41152077839,"instrument_name":"BTC-PERPETUAL","bids":[["new",78369.5,44640.0],["new",78368.5,16650.0],["new",78368.0,2.1e4],["new",78366.5,3.45e4],["new",78363.5,13830.0],["new",78363.0,14940.0],["new",78361.0,2.1e4],["new",78360.5,2510.0],["delete",78201.0,0.0],["delete",78151.0,0.0]],"asks":[["delete",78369.5,0.0],["new",78370.0,21930.0],["delete",78372.5,0.0],["delete",78373.0,0.0],["new",78377.5,650.0],["new",78378.0,3.0e3],["new",78378.5,1.0e4],["new",78385.5,26490.0],["new",78522.5,78520.0],["new",78572.5,117850.0]],"prev_change_id":41152077401}}}
[2025-04-07 08:32:29.614] [multi_sink] [info] Processing received message: {"jsonrpc":"2.0","method":"subscription","params":{"channel":"book.BTC-PERPETUAL.100ms","data":{"timestamp":1743994951177,"type":"change","change_id":41152077839,"instrument_name":"BTC-PERPETUAL","bids":[["new",78369.5,44640.0],["new",78368.5,16650.0],["new",78368.0,2.1e4],["new",78366.5,3.45e4],["new",78363.5,13830.0],["new",78363.0,14940.0],["new",78361.0,2.1e4],["new",78360.5,2510.0],["delete",78201.0,0.0],["delete",78151.0,0.0]],"asks":[["delete",78369.5,0.0],["new",78370.0,21930.0],["delete",78372.5,0.0],["delete",78373.0,0.0],["new",78377.5,650.0],["new",78378.0,3.0e3],["new",78378.5,1.0e4],["new",78385.5,26490.0],["new",78522.5,78520.0],["new",78572.5,117850.0]],"prev_change_id":41152077401}}}
[2025-04-07 08:32:29.946] [multi_sink] [info] 📩 Received: {"jsonrpc":"2.0","method":"subscription","params":{"channel":"book.BTC-PERPETUAL.100ms","data":{"timestamp":1743994951465,"type":"change","change_id":41152078628,"instrument_name":"BTC-PERPETUAL","bids":[["delete",78339.5,0.0],["new",78331.0,7825720.0],["delete",78186.5,0.0],["new",78178.0,8000580.0]],"asks":[["delete",78522.5,0.0],["delete",78572.5,0.0]],"prev_change_id":41152077839}}}
[2025-04-07 08:32:29.950] [multi_sink] [info] Processing received message: {"jsonrpc":"2.0","method":"subscription","params":{"channel":"book.BTC-PERPETUAL.100ms","data":{"timestamp":1743994951465,"type":"change","change_id":41152078628,"instrument_name":"BTC-PERPETUAL","bids":[["delete",78339.5,0.0],["new",78331.0,7825720.0],["delete",78186.5,0.0],["new",78178.0,8000580.0]],"asks":[["delete",78522.5,0.0],["delete",78572.5,0.0]],"prev_change_id":41152077839}}}
[2025-04-07 08:32:30.272] [multi_sink] [info] 📩 Received: {"jsonrpc":"2.0","method":"subscription","params":{"channel":"book.BTC-PERPETUAL.100ms","data":{"timestamp":1743994951796,"type":"change","change_id":41152078840,"instrument_name":"BTC-PERPETUAL","bids":[],"asks":[["new",78408.5,6640830.0],["delete",78417.0,0.0],["new",78561.5,7777770.0],["delete",78570.0,0.0]],"prev_change_id":41152078628}}}
[2025-04-07 08:32:30.275] [multi_sink] [info] Processing received message: {"jsonrpc":"2.0","method":"subscription","params":{"channel":"book.BTC-PERPETUAL.100ms","data":{"timestamp":1743994951796,"type":"change","change_id":41152078840,"instrument_name":"BTC-PERPETUAL","bids":[],"asks":[["new",78408.5,6640830.0],["delete",78417.0,0.0],["new",78561.5,7777770.0],["delete",78570.0,0.0]],"prev_change_id":41152078628}}}
[2025-04-07 08:32:31.646] [multi_sink] [info] 📩 Received: {"jsonrpc":"2.0","method":"subscription","params":{"channel":"book.BTC-PERPETUAL.100ms","data":{"timestamp":1743994953099,"type":"change","change_id":41152080891,"instrument_name":"BTC-PERPETUAL","bids":[["new",78213.0,78210.0],["new",78163.0,117240.0]],"asks":[["new",78542.0,78540.0],["new",78592.0,117880.0]],"prev_change_id":41152078840}}}
[2025-04-07 08:32:31.646] [multi_sink] [info] Processing received message: {"jsonrpc":"2.0","method":"subscription","params":{"channel":"book.BTC-PERPETUAL.100ms","data":{"timestamp":1743994953099,"type":"change","change_id":41152080891,"instrument_name":"BTC-PERPETUAL","bids":[["new",78213.0,78210.0],["new",78163.0,117240.0]],"asks":[["new",78542.0,78540.0],["new",78592.0,117880.0]],"prev_change_id":41152078840}}}
[2025-04-07 08:32:31.969] [multi_sink] [info] 📩 Received: {"jsonrpc":"2.0","method":"subscription","params":{"channel":"book.BTC-PERPETUAL.100ms","data":{"timestamp":1743994953502,"type":"change","change_id":41152081635,"instrument_name":"BTC-PERPETUAL","bids":[["delete",78213.0,0.0],["delete",78163.0,0.0]],"asks":[["delete",78542.0,0.0],["new",78555.0,78550.0],["delete",78592.0,0.0],["new",78605.0,1.179e5]],"prev_change_id":41152080891}}}
[2025-04-07 08:32:31.971] [multi_sink] [info] Processing received message: {"jsonrpc":"2.0","method":"subscription","params":{"channel":"book.BTC-PERPETUAL.100ms","data":{"timestamp":1743994953502,"type":"change","change_id":41152081635,"instrument_name":"BTC-PERPETUAL","bids":[["delete",78213.0,0.0],["delete",78163.0,0.0]],"asks":[["delete",78542.0,0.0],["new",78555.0,78550.0],["delete",78592.0,0.0],["new",78605.0,1.179e5]],"prev_change_id":41152080891}}}
[2025-04-07 08:32:32.204] [multi_sink] [info] 📩 Received: {"jsonrpc":"2.0","method":"subscription","params":{"channel":"book.ETH-PERPETUAL.100ms","data":{"timestamp":1743994953836,"type":"change","change_id":23707281904,"instrument_name":"ETH-PERPETUAL","bids":[],"asks":[["delete",1579.5,0.0],["new",1581.6,38524.0]],"prev_change_id":23707277808}}}
[2025-04-07 08:32:32.204] [multi_sink] [info] Processing received message: {"jsonrpc":"2.0","method":"subscription","params":{"channel":"book.ETH-PERPETUAL.100ms","data":{"timestamp":1743994953836,"type":"change","change_id":23707281904,"instrument_name":"ETH-PERPETUAL","bids":[],"asks":[["delete",1579.5,0.0],["new",1581.6,38524.0]],"prev_change_id":23707277808}}}
[2025-04-07 08:32:32.533] [multi_sink] [info] 📩 Received: {"jsonrpc":"2.0","method":"subscription","params":{"channel":"book.ETH-PERPETUAL.100ms","data":{"timestamp":1743994954164,"type":"change","change_id":23707282570,"instrument_name":"ETH-PERPETUAL","bids":[["new",1579.35,2516.0],["change",1579.3,922.0],["change",1579.25,2715.0],["delete",1579.2,0.0],["delete",1579.15,0.0],["delete",1579.1,0.0],["delete",1579.05,0.0],["delete",1579.0,0.0],["delete",1578.95,0.0],["delete",1578.9,0.0]],"asks":[["change",1579.4,5471975.0],["delete",1579.75,0.0],["delete",1579.8,0.0],["delete",1579.85,0.0],["delete",1579.9,0.0],["delete",1579.95,0.0],["delete",1580.0,0.0],["delete",1580.05,0.0],["delete",1580.1,0.0],["delete",1580.15,0.0],["new",1581.15,1021.0],["new",1581.2,31694.0],["new",1581.25,39943.0],["new",1581.3,4305.0],["new",1581.35,3444.0],["new",1581.4,21944.0],["new",1581.45,17727.0],["new",1581.5,136435.0],["new",1581.55,300921.0]],"prev_change_id":23707281904}}}
[2025-04-07 08:32:32.535] [multi_sink] [info] Processing received message: {"jsonrpc":"2.0","method":"subscription","params":{"channel":"book.ETH-PERPETUAL.100ms","data":{"timestamp":1743994954164,"type":"change","change_id":23707282570,"instrument_name":"ETH-PERPETUAL","bids":[["new",1579.35,2516.0],["change",1579.3,922.0],["change",1579.25,2715.0],["delete",1579.2,0.0],["delete",1579.15,0.0],["delete",1579.1,0.0],["delete",1579.05,0.0],["delete",1579.0,0.0],["delete",1578.95,0.0],["delete",1578.9,0.0]],"asks":[["change",1579.4,5471975.0],["delete",1579.75,0.0],["delete",1579.8,0.0],["delete",1579.85,0.0],["delete",1579.9,0.0],["delete",1579.95,0.0],["delete",1580.0,0.0],["delete",1580.05,0.0],["delete",1580.1,0.0],["delete",1580.15,0.0],["new",1581.15,1021.0],["new",1581.2,31694.0],["new",1581.25,39943.0],["new",1581.3,4305.0],["new",1581.35,3444.0],["new",1581.4,21944.0],["new",1581.45,17727.0],["new",1581.5,136435.0],["new",1581.55,300921.0]],"prev_change_id":23707281904}}}
[2025-04-07 08:32:32.866] [multi_sink] [info] 📩 Received: {"jsonrpc":"2.0","method":"subscription","params":{"channel":"book.ETH-PERPETUAL.100ms","data":{"timestamp":1743994954467,"type":"change","change_id":23707282902,"instrument_name":"ETH-PERPETUAL","bids":[["delete",1578.85,0.0],["delete",1578.8,0.0],["delete",1578.75,0.0],["delete",1578.7,0.0],["delete",1578.65,0.0],["delete",1578.6,0.0],["delete",1578.55,0.0],["delete",1578.5,0.0],["delete",1578.45,0.0]],"asks":[["change",1579.4,5299067.0],["delete",1580.2,0.0],["delete",1580.25,0.0],["delete",1580.3,0.0],["delete",1580.35,0.0],["delete",1580.4,0.0],["delete",1580.45,0.0],["delete",1580.5,0.0],["delete",1580.55,0.0],["new",1580.75,5555.0],["new",1580.8,18518.0],["new",1580.85,923.0],["new",1580.9,1408.0],["new",1580.95,28151.0],["new",1581.0,83143.0],["new",1581.05,6846.0],["new",1581.1,8339.0]],"prev_change_id":23707282570}}}
[2025-04-07 08:32:32.893] [multi_sink] [info] Processing received message: {"jsonrpc":"2.0","method":"subscription","params":{"channel":"book.ETH-PERPETUAL.100ms","data":{"timestamp":1743994954467,"type":"change","change_id":23707282902,"instrument_name":"ETH-PERPETUAL","bids":[["delete",1578.85,0.0],["delete",1578.8,0.0],["delete",1578.75,0.0],["delete",1578.7,0.0],["delete",1578.65,0.0],["delete",1578.6,0.0],["delete",1578.55,0.0],["delete",1578.5,0.0],["delete",1578.45,0.0]],"asks":[["change",1579.4,5299067.0],["delete",1580.2,0.0],["delete",1580.25,0.0],["delete",1580.3,0.0],["delete",1580.35,0.0],["delete",1580.4,0.0],["delete",1580.45,0.0],["delete",1580.5,0.0],["delete",1580.55,0.0],["new",1580.75,5555.0],["new",1580.8,18518.0],["new",1580.85,923.0],["new",1580.9,1408.0],["new",1580.95,28151.0],["new",1581.0,83143.0],["new",1581.05,6846.0],["new",1581.1,8339.0]],"prev_change_id":23707282570}}}
[2025-04-07 08:32:33.195] [multi_sink] [info] 📩 Received: {"jsonrpc":"2.0","method":"subscription","params":{"channel":"book.ETH-PERPETUAL.100ms","data":{"timestamp":1743994954541,"type":"change","change_id":23707283073,"instrument_name":"ETH-PERPETUAL","bids":[],"asks":[["change",1579.4,5252567.0],["new",1580.5,3597.0],["delete",1580.6,0.0],["delete",1580.65,0.0],["new",1580.7,9893.0]],"prev_change_id":23707282902}}}
[2025-04-07 08:32:33.199] [multi_sink] [info] Processing received message: {"jsonrpc":"2.0","method":"subscription","params":{"channel":"book.ETH-PERPETUAL.100ms","data":{"timestamp":1743994954541,"type":"change","change_id":23707283073,"instrument_name":"ETH-PERPETUAL","bids":[],"asks":[["change",1579.4,5252567.0],["new",1580.5,3597.0],["delete",1580.6,0.0],["delete",1580.65,0.0],["new",1580.7,9893.0]],"prev_change_id":23707282902}}}
[2025-04-07 08:32:33.527] [multi_sink] [info] 📩 Received: {"jsonrpc":"2.0","method":"subscription","params":{"channel":"book.ETH-PERPETUAL.100ms","data":{"timestamp":1743994954992,"type":"change","change_id":23707283642,"instrument_name":"ETH-PERPETUAL","bids":[],"asks":[["delete",1579.4,0.0],["change",1580.75,5258122.0]],"prev_change_id":23707283073}}}
[2025-04-07 08:32:33.529] [multi_sink] [info] Processing received message: {"jsonrpc":"2.0","method":"subscription","params":{"channel":"book.ETH-PERPETUAL.100ms","data":{"timestamp":1743994954992,"type":"change","change_id":23707283642,"instrument_name":"ETH-PERPETUAL","bids":[],"asks":[["delete",1579.4,0.0],["change",1580.75,5258122.0]],"prev_change_id":23707283073}}}
[2025-04-07 08:32:33.654] [multi_sink] [info] 📩 Received: {"jsonrpc":"2.0","method":"subscription","params":{"channel":"book.BTC-PERPETUAL.100ms","data":{"timestamp":1743994955115,"type":"change","change_id":41152083677,"instrument_name":"BTC-PERPETUAL","bids":[["new",78218.0,78210.0],["new",78168.0,117240.0]],"asks":[],"prev_change_id":41152081635}}}
[2025-04-07 08:32:33.659] [multi_sink] [info] Processing received message: {"jsonrpc":"2.0","method":"subscription","params":{"channel":"book.BTC-PERPETUAL.100ms","data":{"timestamp":1743994955115,"type":"change","change_id":41152083677,"instrument_name":"BTC-PERPETUAL","bids":[["new",78218.0,78210.0],["new",78168.0,117240.0]],"asks":[],"prev_change_id":41152081635}}}
[2025-04-07 08:32:33.988] [multi_sink] [info] 📩 Received: {"jsonrpc":"2.0","method":"subscription","params":{"channel":"book.BTC-PERPETUAL.100ms","data":{"timestamp":1743994955603,"type":"change","change_id":41152084471,"instrument_name":"BTC-PERPETUAL","bids":[["delete",78369.5,0.0],["change",78368.5,5160.0],["delete",78368.0,0.0],["new",78367.0,4550.0],["delete",78366.5,0.0],["new",78365.5,5160.0],["new",78364.0,1.0e4],["delete",78363.5,0.0],["delete",78363.0,0.0],["new",78362.0,15620.0],["new",78361.5,34350.0],["delete",78361.0,0.0],["change",78358.5,16920.0]],"asks":[["delete",78370.0,0.0],["delete",78377.5,0.0],["delete",78378.0,0.0],["delete",78378.5,0.0],["delete",78385.5,0.0],["delete",78386.0,0.0],["delete",78386.5,0.0],["new",78402.0,49990.0],["new",78403.0,49140.0],["new",78403.5,1.65e4],["new",78404.0,101880.0],["new",78404.5,81640.0],["new",78405.5,5160.0],["new",78407.5,5510.0]],"prev_change_id":41152083677}}}
[2025-04-07 08:32:33.993] [multi_sink] [info] Processing received message: {"jsonrpc":"2.0","method":"subscription","params":{"channel":"book.BTC-PERPETUAL.100ms","data":{"timestamp":1743994955603,"type":"change","change_id":41152084471,"instrument_name":"BTC-PERPETUAL","bids":[["delete",78369.5,0.0],["change",78368.5,5160.0],["delete",78368.0,0.0],["new",78367.0,4550.0],["delete",78366.5,0.0],["new",78365.5,5160.0],["new",78364.0,1.0e4],["delete",78363.5,0.0],["delete",78363.0,0.0],["new",78362.0,15620.0],["new",78361.5,34350.0],["delete",78361.0,0.0],["change",78358.5,16920.0]],"asks":[["delete",78370.0,0.0],["delete",78377.5,0.0],["delete",78378.0,0.0],["delete",78378.5,0.0],["delete",78385.5,0.0],["delete",78386.0,0.0],["delete",78386.5,0.0],["new",78402.0,49990.0],["new",78403.0,49140.0],["new",78403.5,1.65e4],["new",78404.0,101880.0],["new",78404.5,81640.0],["new",78405.5,5160.0],["new",78407.5,5510.0]],"prev_change_id":41152083677}}}
[2025-04-07 08:32:34.316] [multi_sink] [info] 📩 Received: {"jsonrpc":"2.0","method":"subscription","params":{"channel":"book.BTC-PERPETUAL.100ms","data":{"timestamp":1743994955946,"type":"change","change_id":41152084810,"instrument_name":"BTC-PERPETUAL","bids":[["new",78374.0,11880.0],["new",78373.5,16980.0],["new",78372.5,16490.0],["new",78372.0,9430.0],["new",78371.5,16490.0],["new",78370.0,13610.0],["new",78369.5,34450.0],["new",78369.0,5740.0],["delete",78360.5,0.0],["delete",78359.0,0.0],["change",78358.5,5160.0],["delete",78358.0,0.0],["delete",78357.0,0.0],["delete",78356.5,0.0],["delete",78355.5,0.0],["delete",78355.0,0.0]],"asks":[["delete",78387.0,0.0],["delete",78388.0,0.0],["delete",78388.5,0.0],["delete",78389.0,0.0],["delete",78389.5,0.0],["delete",78390.5,0.0],["delete",78391.0,0.0],["new",78391.5,4270.0],["change",78392.5,3.1e3],["change",78394.5,490.0],["change",78395.0,8.2e3],["new",78397.0,8450.0],["new",7.84e4,59470.0],["new",78400.5,9770.0]],"prev_change_id":41152084471}}}
[2025-04-07 08:32:34.321] [multi_sink] [info] Processing received message: {"jsonrpc":"2.0","method":"subscription","params":{"channel":"book.BTC-PERPETUAL.100ms","data":{"timestamp":1743994955946,"type":"change","change_id":41152084810,"instrument_name":"BTC-PERPETUAL","bids":[["new",78374.0,11880.0],["new",78373.5,16980.0],["new",78372.5,16490.0],["new",78372.0,9430.0],["new",78371.5,16490.0],["new",78370.0,13610.0],["new",78369.5,34450.0],["new",78369.0,5740.0],["delete",78360.5,0.0],["delete",78359.0,0.0],["change",78358.5,5160.0],["delete",78358.0,0.0],["delete",78357.0,0.0],["delete",78356.5,0.0],["delete",78355.5,0.0],["delete",78355.0,0.0]],"asks":[["delete",78387.0,0.0],["delete",78388.0,0.0],["delete",78388.5,0.0],["delete",78389.0,0.0],["delete",78389.5,0.0],["delete",78390.5,0.0],["delete",78391.0,0.0],["new",78391.5,4270.0],["change",78392.5,3.1e3],["change",78394.5,490.0],["change",78395.0,8.2e3],["new",78397.0,8450.0],["new",7.84e4,59470.0],["new",78400.5,9770.0]],"prev_change_id":41152084471}}}
[2025-04-07 08:32:34.646] [multi_sink] [info] 📩 Received: {"jsonrpc":"2.0","method":"subscription","params":{"channel":"book.BTC-PERPETUAL.100ms","data":{"timestamp":1743994956112,"type":"change","change_id":41152085264,"instrument_name":"BTC-PERPETUAL","bids":[["new",78384.5,3.5e4],["new",78384.0,7460.0],["new",78383.5,2.09e4],["new",78382.5,5.5e3],["delete",78354.0,0.0],["delete",78353.5,0.0],["delete",78350.5,0.0],["delete",78350.0,0.0]],"asks":[["new",78385.0,510.0],["new",78387.0,6270.0],["new",78388.0,27340.0],["new",78388.5,13130.0],["change",78395.0,4.1e3]],"prev_change_id":41152084810}}}
[2025-04-07 08:32:34.650] [multi_sink] [info] Processing received message: {"jsonrpc":"2.0","method":"subscription","params":{"channel":"book.BTC-PERPETUAL.100ms","data":{"timestamp":1743994956112,"type":"change","change_id":41152085264,"instrument_name":"BTC-PERPETUAL","bids":[["new",78384.5,3.5e4],["new",78384.0,7460.0],["new",78383.5,2.09e4],["new",78382.5,5.5e3],["delete",78354.0,0.0],["delete",78353.5,0.0],["delete",78350.5,0.0],["delete",78350.0,0.0]],"asks":[["new",78385.0,510.0],["new",78387.0,6270.0],["new",78388.0,27340.0],["new",78388.5,13130.0],["change",78395.0,4.1e3]],"prev_change_id":41152084810}}}
[2025-04-07 08:32:34.980] [multi_sink] [info] 📩 Received: {"jsonrpc":"2.0","method":"subscription","params":{"channel":"book.BTC-PERPETUAL.100ms","data":{"timestamp":1743994956485,"type":"change","change_id":41152086053,"instrument_name":"BTC-PERPETUAL","bids":[["new",78228.0,78220.0],["delete",78218.0,0.0],["change",78178.0,8117830.0],["delete",78168.0,0.0]],"asks":[],"prev_change_id":41152085264}}}
[2025-04-07 08:32:34.984] [multi_sink] [info] Processing received message: {"jsonrpc":"2.0","method":"subscription","params":{"channel":"book.BTC-PERPETUAL.100ms","data":{"timestamp":1743994956485,"type":"change","change_id":41152086053,"instrument_name":"BTC-PERPETUAL","bids":[["new",78228.0,78220.0],["delete",78218.0,0.0],["change",78178.0,8117830.0],["delete",78168.0,0.0]],"asks":[],"prev_change_id":41152085264}}}
[2025-04-07 08:32:35.319] [multi_sink] [info] 📩 Received: {"jsonrpc":"2.0","method":"subscription","params":{"channel":"book.BTC-PERPETUAL.100ms","data":{"timestamp":1743994956953,"type":"change","change_id":41152086487,"instrument_name":"BTC-PERPETUAL","bids":[],"asks":[["delete",78555.0,0.0],["new",78566.0,78560.0]],"prev_change_id":41152086053}}}
[2025-04-07 08:32:35.319] [multi_sink] [info] Processing received message: {"jsonrpc":"2.0","method":"subscription","params":{"channel":"book.BTC-PERPETUAL.100ms","data":{"timestamp":1743994956953,"type":"change","change_id":41152086487,"instrument_name":"BTC-PERPETUAL","bids":[],"asks":[["delete",78555.0,0.0],["new",78566.0,78560.0]],"prev_change_id":41152086053}}}
[2025-04-07 08:32:35.651] [multi_sink] [info] 📩 Received: {"jsonrpc":"2.0","method":"subscription","params":{"channel":"book.BTC-PERPETUAL.100ms","data":{"timestamp":1743994956956,"type":"change","change_id":41152086488,"instrument_name":"BTC-PERPETUAL","bids":[],"asks":[["delete",78605.0,0.0],["new",78616.0,117920.0]],"prev_change_id":41152086487}}}
[2025-04-07 08:32:35.653] [multi_sink] [info] Processing received message: {"jsonrpc":"2.0","method":"subscription","params":{"channel":"book.BTC-PERPETUAL.100ms","data":{"timestamp":1743994956956,"type":"change","change_id":41152086488,"instrument_name":"BTC-PERPETUAL","bids":[],"asks":[["delete",78605.0,0.0],["new",78616.0,117920.0]],"prev_change_id":41152086487}}}
[2025-04-07 08:32:35.986] [multi_sink] [info] 📩 Received: {"jsonrpc":"2.0","method":"subscription","params":{"channel":"book.BTC-PERPETUAL.100ms","data":{"timestamp":1743994957429,"type":"change","change_id":41152087398,"instrument_name":"BTC-PERPETUAL","bids":[["new",78238.0,78230.0],["delete",78228.0,0.0],["new",78188.0,117270.0],["change",78178.0,8000580.0]],"asks":[],"prev_change_id":41152086488}}}
