[2025-04-07 08:28:59.815] [multi_sink] [info] 📩 Received: {"jsonrpc":"2.0","method":"subscription","params":{"channel":"book.BTC-PERPETUAL.100ms","data":{"timestamp":1743994741068,"type":"snapshot","change_id":41151772092,"instrument_name":"BTC-PERPETUAL","bids":[["new",78379.5,77540.0],["new",78379.0,2.19e4],["new",78378.5,2.25e4],["new",78377.5,770.0],["new",78376.5,32980.0],["new",78376.0,2.25e4],["new",78375.5,4840.0],["new",78373.0,17220.0],["new",78372.5,22890.0],["new",78372.0,3.45e4],["new",78370.0,430.0],["new",78368.0,21680.0],["new",78367.5,40470.0],["new",78366.0,2.0e4],["new",78365.0,510.0],["new",78364.5,9470.0],["new",78364.0,38220.0],["new",78363.5,5230.0],["new",78362.5,550.0],["new",78362.0,11420.0],["new",78339.0,7825720.0],["new",78252.0,74820.0],["new",78229.0,78220.0],["new",78186.0,8000580.0],["new",78179.0,117260.0],["new",77348.0,9210.0],["new",7.7e4,1.0e6],["new",7.6e4,2.0e6],["new",7.5e4,89170.0],["new",74979.0,10.0],["new",7.4e4,50.0],["new",73273.5,10.0],["new",73246.5,10.0],["new",70582.5,80.0],["new",7.0e4,100310.0],["new",69557.0,10.0],["new",6.8e4,200.0],["new",6.55e4,40.0],["new",6.5e4,70.0],["new",64483.5,90.0],["new",6.4e4,64080.0],["new",6.39e4,150.0],["new",63755.5,160.0],["new",63524.5,70.0],["new",63027.5,290.0],["new",62503.0,5.0e5],["new",62299.5,500.0],["new",6.21e4,6.0e4],["new",61279.5,5.0e5],["new",60686.0,50.0],["new",6.05e4,20.0],["new",6.0e4,513410.0],["new",5.9e4,5.0e5],["new",5.8e4,5.0e5],["new",57172.0,60.0],["new",5.7e4,1.425e5],["new",5.6e4,1.4e5],["new",5.5e4,280.0],["new",54224.5,5420.0],["new",52718.5,10.0],["new",52683.0,10.0],["new",52635.0,10.0],["new",52629.5,10.0],["new",52620.5,10.0],["new",52610.0,10.0],["new",52547.0,10.0],["new",52130.5,10.0],["new",5.2e4,10.0],["new",51567.5,20.0],["new",51455.0,60.0],["new",5.1e4,730.0],["new",50023.0,10.0],["new",50022.0,10.0],["new",50021.0,10.0],["new",50020.0,10.0],["new",50019.0,10.0],["new",50018.0,10.0],["new",50017.0,10.0],["new",50016.0,10.0],["new",50015.0,10.0],["new",50014.0,10.0],["new",50013.0,10.0],["new",50012.0,10.0],["new",50011.0,10.0],["new",50010.0,10.0],["new",50009.0,20.0],["new",50008.0,20.0],["new",50007.0,20.0],["new",50006.0,20.0],["new",50005.0,20.0],["new",50004.0,20.0],["new",50003.0,20.0],["new",50002.0,20.0],["new",50001.0,20.0],["new",5.0e4,11790.0],["new",49133.5,2.5e4],["new",4.9e4,200.0],["new",48978.0,100.0],["new",4.8e4,20.0],["new",47983.0,50.0],["new",47981.0,50.0],["new",46605.0,10.0],["new",46580.0,10.0],["new",46309.5,50.0],["new",45000.5,30.0],["new",4.5e4,290.0],["new",4.49e4,30.0],["new",41678.5,50.0],["new",40575.0,40.0],["new",4.05e4,20.0],["new",4.0e4,3.0e3],["new",3.8e4,6.0e5],["new",37510.5,40.0],["new",3.7e4,4.0e4],["new",3.5e4,401860.0],["new",33759.5,40.0],["new",3.3e4,20.0],["new",3.2e4,20.0],["new",31313.0,10.0],["new",3.1e4,1020.0],["new",30383.5,10.0],["new",3.0e4,2120.0],["new",2.5e4,480.0],["new",2.4e4,10.0],["new",22706.0,13850.0],["new",2.25e4,1.08e5],["new",22392.5,8.0e4],["new",22310.5,10.0],["new",22284.5,300.0],["new",22250.0,1.08e5],["new",22209.0,5.0e5],["new",2.2e4,10.0],["new",21795.0,300.0],["new",21375.0,5.0e5],["new",21305.5,300.0],["new",2.1e4,2.01e4],["new",20949.5,40.0],["new",20816.0,300.0],["new",20326.5,300.0],["new",2.02e4,1.0e3],["new",2.01e4,1.0e3],["new",2.0e4,2320.0],["new",19940.0,10.0],["new",19582.0,120.0],["new",1.95e4,40.0],["new",1.94e4,10.0],["new",19373.0,300.0],["new",19347.5,600.0],["new",19288.5,5.0e5],["new",19129.0,180.0],["new",1.9e4,10.0],["new",18368.5,600.0],["new",18328.0,5.0e5],["new",18274.5,40.0],["new",1.8e4,80.0],["new",17612.5,5.0e5],["new",17503.0,10.0],["new",17389.5,600.0],["new",1.7e4,150.0],["new",16926.0,5.0e5],["new",1.69e4,20.0],["new",16625.0,92610.0],["new",1.66e4,1.0e5],["new",16575.0,1.0e5],["new",16550.0,1.0e5],["new",16525.0,1.0e5],["new",16515.0,10.0],["new",16410.5,600.0],["new",16328.0,5.0e5],["new",16141.5,2890.0],["new",16134.0,1080.0],["new",16088.0,2890.0],["new",16080.5,1080.0],["new",16034.5,2890.0],["new",16026.5,1080.0],["new",1.6e4,230.0],["new",15973.0,1080.0],["new",15919.5,1080.0],["new",15866.0,1110.0],["new",15704.5,5.0e5],["new",15620.0,1.0e3],["new",1.55e4,3.1e5],["new",15444.0,100.0],["new",15431.5,600.0],["new",1.54e4,10050.0],["new",15285.0,270.0],["new",15263.0,110.0],["new",15165.0,1.0e4],["new",15162.5,1.0e4],["new",1.51e4,10.0],["new",15063.0,270.0],["new",15045.0,810.0],["new",1.5e4,1100910.0],["new",14899.0,200.0],["new",14888.0,148880.0],["new",14864.5,2430.0],["new",14823.5,270.0],["new",14823.0,810.0],["new",14681.0,4.8e3],["new",14565.0,2430.0],["new",1.45e4,10.0],["new",14343.0,2430.0],["new",1.42e4,14210.0],["new",14090.0,400.0],["new",1.4e4,330.0],["new",13964.0,1.5e5],["new",13835.0,13840.0],["new",1.37e4,100.0],["new",13360.0,100.0],["new",13078.5,9.8e4],["new",1.3e4,530.0],["new",12839.0,23040.0],["new",1.28e4,111360.0],["new",12510.5,1.5e5],["new",1.25e4,1.25e4],["new",12345.0,550.0],["new",12334.0,500.0],["new",12304.5,7290.0],["new",1.23e4,125880.0],["new",12232.5,30.0],["new",1.22e4,5.0e5],["new",12189.5,1220.0],["new",12104.0,2.0e3],["new",1.2e4,5580.0],["new",11937.5,2.0e3],["new",11867.5,2.0e3],["new",11797.5,2.0e3],["new",11728.0,2.0e3],["new",1.17e4,4120.0],["new",11659.0,2.0e3],["new",11522.0,2.0e3],["new",11454.0,2.0e3],["new",11450.5,20.0],["new",11420.5,30.0],["new",11360.5,90.0],["new",11240.5,270.0],["new",11230.0,200.0],["new",1.12e4,10.0],["new",11187.0,2.0e3],["new",11121.0,2.0e3],["new",1.11e4,10.0],["new",11055.5,2.0e3],["new",11000.5,810.0],["new",1.1e4,5.003e5],["new",10990.5,2.0e3],["new",10926.0,2.0e3],["new",10861.5,2.0e3],["new",10797.5,2.0e3],["new",10734.0,2.0e3],["new",10682.5,2430.0],["new",10682.0,2430.0],["new",10520.5,2430.0],["new",10399.0,10.0],["new",1.02e4,130.0],["new",10179.0,50.0],["new",10172.5,810.0],["new",10164.5,2430.0],["new",10142.0,1.0e5],["new",10027.5,90.0],["new",10026.0,810.0],["new",10022.0,26730.0],["new",10009.5,150.0],["new",1.0e4,2108110.0],["new",9951.5,2.2e3],["new",9876.0,2430.0],["new",9874.0,2430.0],["new",9866.0,1.0e5],["new",9811.5,2430.0],["new",9785.5,7290.0],["new",9775.5,2430.0],["new",9743.5,2430.0],["new",9693.5,2430.0],["new",9692.5,2430.0],["new",9687.5,2430.0],["new",9687.0,2.43e4],["new",9674.0,3660.0],["new",9657.5,100.0],["new",9650.0,2430.0],["new",9640.5,7290.0],["new",9632.5,1.0e3],["new",9607.5,1.0e4],["new",9.6e3,100.0],["new",9597.0,2430.0],["new",9595.5,2430.0],["new",9582.5,9.7e4],["new",9546.0,2430.0],["new",9524.5,7290.0],["new",9.5e3,9.5e4],["new",9411.0,8560.0],["new",9362.0,43740.0],["new",9326.5,1.5e5],["new",9317.5,890.0],["new",9274.0,1.0e5],["new",9250.5,7290.0],["new",9250.0,167450.0],["new",9234.0,7290.0],["new",9210.0,7.368e5],["new",9155.5,5.5e5],["new",9142.5,40.0],["new",9127.0,330.0],["new",9103.5,7290.0],["new",9102.5,160.0],["new",9.1e3,2.73e5],["new",9053.5,7290.0],["new",9047.5,7290.0],["new",9022.5,640.0],["new",9010.0,7290.0],["new",9.0e3,1220.0],["new",8957.0,7290.0],["new",8.9e3,100.0],["new",8878.0,2560.0],["new",8862.5,2560.0],["new",8854.0,1.5e5],["new",8839.0,600.0],["new",8802.0,2560.0],["new",8.8e3,100.0],["new",8785.0,9740.0],["new",8761.5,1040.0],["new",8760.0,1.0e5],["new",8735.0,9.0e3],["new",8.7e3,100.0],["new",8685.0,9.0e3],["new",8651.5,1560.0],["new",8638.5,10.0],["new",8635.0,9.0e3],["new",8.6e3,100.0],["new",8599.0,720.0],["new",8585.0,9.0e3],["new",8571.0,1250.0],["new",8546.0,2430.0],["new",8535.0,9.0e3],["new",8.5e3,8.93e4],["new",8485.0,9.0e3],["new",8450.0,2110.0],["new",8435.0,9.0e3],["new",8.4e3,100.0],["new",8393.0,14630.0],["new",8385.0,9.0e3],["new",8350.0,2090.0],["new",8338.5,320.0],["new",8335.0,9.0e3],["new",8.3e3,100.0],["new",8290.0,1.6e3],["new",8285.0,9.0e3],["new",8241.5,4120.0],["new",8235.0,9.0e3],["new",8218.0,8.1e3],["new",8.2e3,100.0],["new",8185.0,9.0e3],["new",8135.0,9.0e3],["new",8.1e3,100.0],["new",8085.0,9.0e3],["new",8066.5,17120.0],["new",8035.0,9.0e3],["new",8.0e3,1220.0],["new",7987.5,900.0],["new",7985.0,9.0e3],["new",7973.0,29260.0],["new",7.9e3,100.0],["new",7892.0,7.0e5],["new",7890.5,640.0],["new",7876.0,58520.0],["new",7809.0,5.0e5],["new",7.8e3,1.01e4],["new",7777.0,10.0],["new",7.7e3,100.0],["new",7672.0,150.0],["new",7659.5,150.0],["new",7.6e3,100.0],["new",7555.5,10.0],["new",7523.5,40.0],["new",7.5e3,2250.0],["new",7472.0,160.0],["new",7447.0,450.0],["new",7434.5,450.0],["new",7420.5,10.0],["new",7.4e3,100.0],["new",7390.0,640.0],["new",7353.0,1280.0],["new",7.3e3,100.0],["new",7.2e3,1.1e3],["new",7190.0,450.0],["new",7170.5,500.0],["new",7160.0,7160.0],["new",7.1e3,1.001e5],["new",7048.5,10240.0],["new",7005.5,3.2e4],["new",7.0e3,1110.0],["new",6931.0,5.0e3],["new",6.9e3,100.0],["new",6.8e3,100.0],["new",6735.5,1.28e5],["new",6708.0,2560.0],["new",6.7e3,100.0],["new",6.6e3,100.0],["new",6590.0,8620.0],["new",6589.0,6470.0],["new",6588.0,28390.0],["new",6587.0,24480.0],["new",6551.0,20.0],["new",6550.0,20.0],["new",6512.0,35850.0],["new",6511.0,69260.0],["new",6510.0,221750.0],["new",6509.0,35860.0],["new",6.5e3,1.6e3],["new",6418.5,10.0],["new",6.4e3,100.0],["new",6395.0,64660.0],["new",6394.0,92760.0],["new",6393.0,217970.0],["new",6392.0,66110.0],["new",6390.5,10.0],["new",6.3e3,100.0],["new",6295.0,100.0],["new",6286.5,1.383e5],["new",6285.5,286720.0],["new",6284.5,211380.0],["new",6283.5,246610.0],["new",6259.5,750.0],["new",6.2e3,100.0],["new",6186.5,73690.0],["new",6185.5,340510.0],["new",6184.5,21880.0],["new",6183.5,186350.0],["new",6169.5,450.0],["new",6.1e3,100.0],["new",6050.0,40.0],["new",6.0e3,4140.0],["new",5999.0,5.0e3],["new",5934.0,5120.0],["new",5925.5,5.12e5],["new",5.9e3,210.0],["new",5.8e3,100.0],["new",5.7e3,100.0],["new",5.6e3,100.0],["new",5.5e3,2.1e3],["new",5.4e3,100.0],["new",5359.5,2250.0],["new",5346.0,7290.0],["new",5309.0,50.0],["new",5.3e3,100.0],["new",5.2e3,100.0],["new",5118.0,2560.0],["new",5.1e3,100.0],["new",5050.5,450.0],["new",5044.5,150.0],["new",5005.0,10240.0],["new",5.0e3,10110.0],["new",4999.0,20520.0],["new",4964.0,10.0],["new",4922.0,450.0],["new",4757.5,200.0],["new",4690.0,1.0e3],["new",4610.0,1.0e4],["new",4.6e3,2.0e3],["new",4597.0,1.6e3],["new",4594.5,450.0],["new",4514.5,1.0e6],["new",4.5e3,800.0],["new",4414.0,46280.0],["new",4003.0,40.0],["new",4001.0,20.0],["new",4.0e3,640.0],["new",3921.0,23040.0],["new",3845.0,40.0],["new",3.8e3,10050.0],["new",3777.5,6.4e3],["new",3774.0,3.0e3],["new",3773.0,1.0e3],["new",3754.5,1.0e3],["new",3708.0,2.7e4],["new",3.7e3,30.0],["new",3680.0,10.0],["new",3655.0,20.0],["new",3650.0,10.0],["new",3.6e3,3.6e4],["new",3590.0,1.0e4],["new",3567.0,500.0],["new",3.5e3,230.0],["new",3.4e3,80.0],["new",3230.0,10.0],["new",3228.0,10.0],["new",3.2e3,20.0],["new",3001.0,20.0],["new",3.0e3,7.2e3],["new",2999.0,40.0],["new",2879.0,300.0],["new",2601.0,20.0],["new",2544.0,10.0],["new",2.5e3,20.0],["new",2467.0,2.56e4],["new",2.4e3,1.0e3],["new",2309.0,250.0],["new",2.3e3,20.0],["new",2222.0,680.0],["new",2211.0,40.0],["new",2005.0,140.0],["new",2.0e3,21250.0],["new",1999.0,10.0],["new",1994.5,5.0e3],["new",1979.0,60.0],["new",1.9e3,30.0],["new",1.7e3,300.0],["new",1.4e3,40.0],["new",1234.0,10.0],["new",1205.0,40.0],["new",1.1e3,20.0],["new",1099.0,10.0],["new",1002.5,70.0],["new",1001.5,60.0],["new",1000.5,80.0],["new",1.0e3,12450.0],["new",900.0,10.0],["new",800.0,10.0],["new",648.0,40.0],["new",600.0,760.0],["new",541.5,1.0e4],["new",502.0,1350.0],["new",500.0,3580.0],["new",400.0,150.0],["new",300.0,540.0],["new",288.0,10.0],["new",287.0,10.0],["new",281.0,100.0],["new",234.0,20.0],["new",222.0,300.0],["new",200.0,1220.0],["new",123.0,1.0e3],["new",120.0,110.0],["new",110.0,80.0],["new",101.0,110.0],["new",100.0,123510.0],["new",60.0,270.0],["new",58.0,10.0],["new",50.0,1350.0],["new",40.0,120.0],["new",35.5,20.0],["new",30.0,10350.0],["new",25.0,30.0],["new",23.0,20.0],["new",20.0,2210.0],["new",16.5,10.0],["new",15.0,20.0],["new",13.0,30.0],["new",12.0,2160.0],["new",11.0,10.0],["new",10.0,4010.0],["new",9.0,20.0],["new",6.5,10.0],["new",6.0,40.0],["new",5.0,300.0],["new",4.0,40.0],["new",3.0,20.0],["new",1.0,390.0],["new",0.5,61150.0]],"asks":[["new",78380.0,10080.0],["new",78381.0,81640.0],["new",78382.0,1.0e4],["new",78382.5,9470.0],["new",78383.5,190.0],["new",78385.0,1.0e4],["new",78385.5,160.0],["new",78388.0,6170.0],["new",78390.5,190.0],["new",78393.0,200.0],["new",78393.5,7680.0],["new",78394.5,8530.0],["new",78395.0,16860.0],["new",78395.5,220.0],["new",78396.0,25920.0],["new",78397.0,16490.0],["new",78397.5,16490.0],["new",78398.0,3.94e4],["new",78398.5,1.0e4],["new",78399.0,500.0],["new",78416.5,6640830.0],["new",78556.5,7.5e6],["new",78561.0,78560.0],["new",78569.5,7777770.0],["new",78611.0,117910.0],["new",78647.5,6930.0],["new",7.9e4,7.5e6],["new",79062.5,10.0],["new",7.95e4,2.5e6],["new",8.0e4,2.5e6],["new",80290.5,10.0],["new",81962.0,81590.0],["new",8.2e4,2.5e6],["new",82168.0,81830.0],["new",82526.0,100.0],["new",82848.0,83220.0],["new",83422.5,170.0],["new",83749.0,1.0e4],["new",84318.5,300.0],["new",8.45e4,1.0e6],["new",8.5e4,1.0e6],["new",85215.0,520.0],["new",8.55e4,1.0e6],["new",8.6e4,1.0e6],["new",8.7e4,1.0e6],["new",8.75e4,1.0e6],["new",8.8e4,1.0e6],["new",9.0e4,20.0],["new",91747.0,300.0],["new",92036.5,100.0],["new",92823.0,6810.0],["new",92838.5,520.0],["new",95042.0,4190.0],["new",9.52e4,5950.0],["new",9.8e4,10.0],["new",9.9e4,20.0],["new",99670.0,5630.0],["new",1.0e5,10020.0],["new",100094.5,170.0],["new",100128.0,100.0],["new",100141.5,30.0],["new",100166.5,190.0],["new",1.002e5,10.0],["new",1.004e5,10.0],["new",1.006e5,10.0],["new",1.008e5,5580.0],["new",100894.0,20.0],["new",1.01e5,20.0],["new",101144.5,190.0],["new",1.012e5,20.0],["new",1.014e5,20.0],["new",1.016e5,20.0],["new",1.018e5,20.0],["new",1.02e5,30.0],["new",102106.5,20.0],["new",1.022e5,30.0],["new",1.024e5,30.0],["new",1.026e5,30.0],["new",1.028e5,30.0],["new",1.03e5,40.0],["new",103085.5,30.0],["new",103097.5,70.0],["new",103102.0,200.0],["new",103114.0,90.0],["new",1.032e5,40.0],["new",1.034e5,40.0],["new",1.036e5,40.0],["new",1.038e5,40.0],["new",1.04e5,50.0],["new",104059.0,180.0],["new",104115.5,40.0],["new",104160.5,70.0],["new",1.042e5,50.0],["new",104228.0,50.0],["new",1.044e5,50.0],["new",1.046e5,50.0],["new",1.048e5,50.0],["new",1.05e5,60.0],["new",1.052e5,60.0],["new",105206.5,80.0],["new",1.054e5,60.0],["new",1.056e5,60.0],["new",1.058e5,60.0],["new",1.06e5,70.0],["new",1.062e5,70.0],["new",1.064e5,70.0],["new",1.066e5,70.0],["new",1.068e5,70.0],["new",1.07e5,80.0],["new",1.072e5,80.0],["new",107232.0,230.0],["new",1.074e5,80.0],["new",1.076e5,80.0],["new",107667.0,290.0],["new",1.078e5,80.0],["new",1.08e5,90.0],["new",1.082e5,90.0],["new",1.084e5,90.0],["new",1.086e5,90.0],["new",1.088e5,90.0],["new",1.09e5,100.0],["new",109004.5,500.0],["new",1.092e5,100.0],["new",1.094e5,100.0],["new",1.096e5,100.0],["new",1.098e5,100.0],["new",110298.0,210.0],["new",110763.0,260.0],["new",111228.0,310.0],["new",111693.0,370.0],["new",112158.0,440.0],["new",112285.0,450.0],["new",112623.0,530.0],["new",113088.0,640.0],["new",113553.0,770.0],["new",114018.0,920.0],["new",114483.5,1.1e3],["new",114948.5,1320.0],["new",115164.0,550.0],["new",115413.5,1590.0],["new",118043.5,680.0],["new",119094.5,120.0],["new",1.2e5,100020.0],["new",120922.5,820.0],["new",123801.5,1010.0],["new",126680.5,1230.0],["new",129559.5,1.5e3],["new",130318.5,130.0],["new",145037.0,150.0],["new",145090.5,150.0],["new",145306.5,300.0],["new",1.5e5,38100030.0]]}}}
[2025-04-07 08:28:59.819] [multi_sink] [info] Processing received message: {"jsonrpc":"2.0","method":"subscription","params":{"channel":"book.BTC-PERPETUAL.100ms","data":{"timestamp":1743994741068,"type":"snapshot","change_id":41151772092,"instrument_name":"BTC-PERPETUAL","bids":[["new",78379.5,77540.0],["new",78379.0,2.19e4],["new",78378.5,2.25e4],["new",78377.5,770.0],["new",78376.5,32980.0],["new",78376.0,2.25e4],["new",78375.5,4840.0],["new",78373.0,17220.0],["new",78372.5,22890.0],["new",78372.0,3.45e4],["new",78370.0,430.0],["new",78368.0,21680.0],["new",78367.5,40470.0],["new",78366.0,2.0e4],["new",78365.0,510.0],["new",78364.5,9470.0],["new",78364.0,38220.0],["new",78363.5,5230.0],["new",78362.5,550.0],["new",78362.0,11420.0],["new",78339.0,7825720.0],["new",78252.0,74820.0],["new",78229.0,78220.0],["new",78186.0,8000580.0],["new",78179.0,117260.0],["new",77348.0,9210.0],["new",7.7e4,1.0e6],["new",7.6e4,2.0e6],["new",7.5e4,89170.0],["new",74979.0,10.0],["new",7.4e4,50.0],["new",73273.5,10.0],["new",73246.5,10.0],["new",70582.5,80.0],["new",7.0e4,100310.0],["new",69557.0,10.0],["new",6.8e4,200.0],["new",6.55e4,40.0],["new",6.5e4,70.0],["new",64483.5,90.0],["new",6.4e4,64080.0],["new",6.39e4,150.0],["new",63755.5,160.0],["new",63524.5,70.0],["new",63027.5,290.0],["new",62503.0,5.0e5],["new",62299.5,500.0],["new",6.21e4,6.0e4],["new",61279.5,5.0e5],["new",60686.0,50.0],["new",6.05e4,20.0],["new",6.0e4,513410.0],["new",5.9e4,5.0e5],["new",5.8e4,5.0e5],["new",57172.0,60.0],["new",5.7e4,1.425e5],["new",5.6e4,1.4e5],["new",5.5e4,280.0],["new",54224.5,5420.0],["new",52718.5,10.0],["new",52683.0,10.0],["new",52635.0,10.0],["new",52629.5,10.0],["new",52620.5,10.0],["new",52610.0,10.0],["new",52547.0,10.0],["new",52130.5,10.0],["new",5.2e4,10.0],["new",51567.5,20.0],["new",51455.0,60.0],["new",5.1e4,730.0],["new",50023.0,10.0],["new",50022.0,10.0],["new",50021.0,10.0],["new",50020.0,10.0],["new",50019.0,10.0],["new",50018.0,10.0],["new",50017.0,10.0],["new",50016.0,10.0],["new",50015.0,10.0],["new",50014.0,10.0],["new",50013.0,10.0],["new",50012.0,10.0],["new",50011.0,10.0],["new",50010.0,10.0],["new",50009.0,20.0],["new",50008.0,20.0],["new",50007.0,20.0],["new",50006.0,20.0],["new",50005.0,20.0],["new",50004.0,20.0],["new",50003.0,20.0],["new",50002.0,20.0],["new",50001.0,20.0],["new",5.0e4,11790.0],["new",49133.5,2.5e4],["new",4.9e4,200.0],["new",48978.0,100.0],["new",4.8e4,20.0],["new",47983.0,50.0],["new",47981.0,50.0],["new",46605.0,10.0],["new",46580.0,10.0],["new",46309.5,50.0],["new",45000.5,30.0],["new",4.5e4,290.0],["new",4.49e4,30.0],["new",41678.5,50.0],["new",40575.0,40.0],["new",4.05e4,20.0],["new",4.0e4,3.0e3],["new",3.8e4,6.0e5],["new",37510.5,40.0],["new",3.7e4,4.0e4],["new",3.5e4,401860.0],["new",33759.5,40.0],["new",3.3e4,20.0],["new",3.2e4,20.0],["new",31313.0,10.0],["new",3.1e4,1020.0],["new",30383.5,10.0],["new",3.0e4,2120.0],["new",2.5e4,480.0],["new",2.4e4,10.0],["new",22706.0,13850.0],["new",2.25e4,1.08e5],["new",22392.5,8.0e4],["new",22310.5,10.0],["new",22284.5,300.0],["new",22250.0,1.08e5],["new",22209.0,5.0e5],["new",2.2e4,10.0],["new",21795.0,300.0],["new",21375.0,5.0e5],["new",21305.5,300.0],["new",2.1e4,2.01e4],["new",20949.5,40.0],["new",20816.0,300.0],["new",20326.5,300.0],["new",2.02e4,1.0e3],["new",2.01e4,1.0e3],["new",2.0e4,2320.0],["new",19940.0,10.0],["new",19582.0,120.0],["new",1.95e4,40.0],["new",1.94e4,10.0],["new",19373.0,300.0],["new",19347.5,600.0],["new",19288.5,5.0e5],["new",19129.0,180.0],["new",1.9e4,10.0],["new",18368.5,600.0],["new",18328.0,5.0e5],["new",18274.5,40.0],["new",1.8e4,80.0],["new",17612.5,5.0e5],["new",17503.0,10.0],["new",17389.5,600.0],["new",1.7e4,150.0],["new",16926.0,5.0e5],["new",1.69e4,20.0],["new",16625.0,92610.0],["new",1.66e4,1.0e5],["new",16575.0,1.0e5],["new",16550.0,1.0e5],["new",16525.0,1.0e5],["new",16515.0,10.0],["new",16410.5,600.0],["new",16328.0,5.0e5],["new",16141.5,2890.0],["new",16134.0,1080.0],["new",16088.0,2890.0],["new",16080.5,1080.0],["new",16034.5,2890.0],["new",16026.5,1080.0],["new",1.6e4,230.0],["new",15973.0,1080.0],["new",15919.5,1080.0],["new",15866.0,1110.0],["new",15704.5,5.0e5],["new",15620.0,1.0e3],["new",1.55e4,3.1e5],["new",15444.0,100.0],["new",15431.5,600.0],["new",1.54e4,10050.0],["new",15285.0,270.0],["new",15263.0,110.0],["new",15165.0,1.0e4],["new",15162.5,1.0e4],["new",1.51e4,10.0],["new",15063.0,270.0],["new",15045.0,810.0],["new",1.5e4,1100910.0],["new",14899.0,200.0],["new",14888.0,148880.0],["new",14864.5,2430.0],["new",14823.5,270.0],["new",14823.0,810.0],["new",14681.0,4.8e3],["new",14565.0,2430.0],["new",1.45e4,10.0],["new",14343.0,2430.0],["new",1.42e4,14210.0],["new",14090.0,400.0],["new",1.4e4,330.0],["new",13964.0,1.5e5],["new",13835.0,13840.0],["new",1.37e4,100.0],["new",13360.0,100.0],["new",13078.5,9.8e4],["new",1.3e4,530.0],["new",12839.0,23040.0],["new",1.28e4,111360.0],["new",12510.5,1.5e5],["new",1.25e4,1.25e4],["new",12345.0,550.0],["new",12334.0,500.0],["new",12304.5,7290.0],["new",1.23e4,125880.0],["new",12232.5,30.0],["new",1.22e4,5.0e5],["new",12189.5,1220.0],["new",12104.0,2.0e3],["new",1.2e4,5580.0],["new",11937.5,2.0e3],["new",11867.5,2.0e3],["new",11797.5,2.0e3],["new",11728.0,2.0e3],["new",1.17e4,4120.0],["new",11659.0,2.0e3],["new",11522.0,2.0e3],["new",11454.0,2.0e3],["new",11450.5,20.0],["new",11420.5,30.0],["new",11360.5,90.0],["new",11240.5,270.0],["new",11230.0,200.0],["new",1.12e4,10.0],["new",11187.0,2.0e3],["new",11121.0,2.0e3],["new",1.11e4,10.0],["new",11055.5,2.0e3],["new",11000.5,810.0],["new",1.1e4,5.003e5],["new",10990.5,2.0e3],["new",10926.0,2.0e3],["new",10861.5,2.0e3],["new",10797.5,2.0e3],["new",10734.0,2.0e3],["new",10682.5,2430.0],["new",10682.0,2430.0],["new",10520.5,2430.0],["new",10399.0,10.0],["new",1.02e4,130.0],["new",10179.0,50.0],["new",10172.5,810.0],["new",10164.5,2430.0],["new",10142.0,1.0e5],["new",10027.5,90.0],["new",10026.0,810.0],["new",10022.0,26730.0],["new",10009.5,150.0],["new",1.0e4,2108110.0],["new",9951.5,2.2e3],["new",9876.0,2430.0],["new",9874.0,2430.0],["new",9866.0,1.0e5],["new",9811.5,2430.0],["new",9785.5,7290.0],["new",9775.5,2430.0],["new",9743.5,2430.0],["new",9693.5,2430.0],["new",9692.5,2430.0],["new",9687.5,2430.0],["new",9687.0,2.43e4],["new",9674.0,3660.0],["new",9657.5,100.0],["new",9650.0,2430.0],["new",9640.5,7290.0],["new",9632.5,1.0e3],["new",9607.5,1.0e4],["new",9.6e3,100.0],["new",9597.0,2430.0],["new",9595.5,2430.0],["new",9582.5,9.7e4],["new",9546.0,2430.0],["new",9524.5,7290.0],["new",9.5e3,9.5e4],["new",9411.0,8560.0],["new",9362.0,43740.0],["new",9326.5,1.5e5],["new",9317.5,890.0],["new",9274.0,1.0e5],["new",9250.5,7290.0],["new",9250.0,167450.0],["new",9234.0,7290.0],["new",9210.0,7.368e5],["new",9155.5,5.5e5],["new",9142.5,40.0],["new",9127.0,330.0],["new",9103.5,7290.0],["new",9102.5,160.0],["new",9.1e3,2.73e5],["new",9053.5,7290.0],["new",9047.5,7290.0],["new",9022.5,640.0],["new",9010.0,7290.0],["new",9.0e3,1220.0],["new",8957.0,7290.0],["new",8.9e3,100.0],["new",8878.0,2560.0],["new",8862.5,2560.0],["new",8854.0,1.5e5],["new",8839.0,600.0],["new",8802.0,2560.0],["new",8.8e3,100.0],["new",8785.0,9740.0],["new",8761.5,1040.0],["new",8760.0,1.0e5],["new",8735.0,9.0e3],["new",8.7e3,100.0],["new",8685.0,9.0e3],["new",8651.5,1560.0],["new",8638.5,10.0],["new",8635.0,9.0e3],["new",8.6e3,100.0],["new",8599.0,720.0],["new",8585.0,9.0e3],["new",8571.0,1250.0],["new",8546.0,2430.0],["new",8535.0,9.0e3],["new",8.5e3,8.93e4],["new",8485.0,9.0e3],["new",8450.0,2110.0],["new",8435.0,9.0e3],["new",8.4e3,100.0],["new",8393.0,14630.0],["new",8385.0,9.0e3],["new",8350.0,2090.0],["new",8338.5,320.0],["new",8335.0,9.0e3],["new",8.3e3,100.0],["new",8290.0,1.6e3],["new",8285.0,9.0e3],["new",8241.5,4120.0],["new",8235.0,9.0e3],["new",8218.0,8.1e3],["new",8.2e3,100.0],["new",8185.0,9.0e3],["new",8135.0,9.0e3],["new",8.1e3,100.0],["new",8085.0,9.0e3],["new",8066.5,17120.0],["new",8035.0,9.0e3],["new",8.0e3,1220.0],["new",7987.5,900.0],["new",7985.0,9.0e3],["new",7973.0,29260.0],["new",7.9e3,100.0],["new",7892.0,7.0e5],["new",7890.5,640.0],["new",7876.0,58520.0],["new",7809.0,5.0e5],["new",7.8e3,1.01e4],["new",7777.0,10.0],["new",7.7e3,100.0],["new",7672.0,150.0],["new",7659.5,150.0],["new",7.6e3,100.0],["new",7555.5,10.0],["new",7523.5,40.0],["new",7.5e3,2250.0],["new",7472.0,160.0],["new",7447.0,450.0],["new",7434.5,450.0],["new",7420.5,10.0],["new",7.4e3,100.0],["new",7390.0,640.0],["new",7353.0,1280.0],["new",7.3e3,100.0],["new",7.2e3,1.1e3],["new",7190.0,450.0],["new",7170.5,500.0],["new",7160.0,7160.0],["new",7.1e3,1.001e5],["new",7048.5,10240.0],["new",7005.5,3.2e4],["new",7.0e3,1110.0],["new",6931.0,5.0e3],["new",6.9e3,100.0],["new",6.8e3,100.0],["new",6735.5,1.28e5],["new",6708.0,2560.0],["new",6.7e3,100.0],["new",6.6e3,100.0],["new",6590.0,8620.0],["new",6589.0,6470.0],["new",6588.0,28390.0],["new",6587.0,24480.0],["new",6551.0,20.0],["new",6550.0,20.0],["new",6512.0,35850.0],["new",6511.0,69260.0],["new",6510.0,221750.0],["new",6509.0,35860.0],["new",6.5e3,1.6e3],["new",6418.5,10.0],["new",6.4e3,100.0],["new",6395.0,64660.0],["new",6394.0,92760.0],["new",6393.0,217970.0],["new",6392.0,66110.0],["new",6390.5,10.0],["new",6.3e3,100.0],["new",6295.0,100.0],["new",6286.5,1.383e5],["new",6285.5,286720.0],["new",6284.5,211380.0],["new",6283.5,246610.0],["new",6259.5,750.0],["new",6.2e3,100.0],["new",6186.5,73690.0],["new",6185.5,340510.0],["new",6184.5,21880.0],["new",6183.5,186350.0],["new",6169.5,450.0],["new",6.1e3,100.0],["new",6050.0,40.0],["new",6.0e3,4140.0],["new",5999.0,5.0e3],["new",5934.0,5120.0],["new",5925.5,5.12e5],["new",5.9e3,210.0],["new",5.8e3,100.0],["new",5.7e3,100.0],["new",5.6e3,100.0],["new",5.5e3,2.1e3],["new",5.4e3,100.0],["new",5359.5,2250.0],["new",5346.0,7290.0],["new",5309.0,50.0],["new",5.3e3,100.0],["new",5.2e3,100.0],["new",5118.0,2560.0],["new",5.1e3,100.0],["new",5050.5,450.0],["new",5044.5,150.0],["new",5005.0,10240.0],["new",5.0e3,10110.0],["new",4999.0,20520.0],["new",4964.0,10.0],["new",4922.0,450.0],["new",4757.5,200.0],["new",4690.0,1.0e3],["new",4610.0,1.0e4],["new",4.6e3,2.0e3],["new",4597.0,1.6e3],["new",4594.5,450.0],["new",4514.5,1.0e6],["new",4.5e3,800.0],["new",4414.0,46280.0],["new",4003.0,40.0],["new",4001.0,20.0],["new",4.0e3,640.0],["new",3921.0,23040.0],["new",3845.0,40.0],["new",3.8e3,10050.0],["new",3777.5,6.4e3],["new",3774.0,3.0e3],["new",3773.0,1.0e3],["new",3754.5,1.0e3],["new",3708.0,2.7e4],["new",3.7e3,30.0],["new",3680.0,10.0],["new",3655.0,20.0],["new",3650.0,10.0],["new",3.6e3,3.6e4],["new",3590.0,1.0e4],["new",3567.0,500.0],["new",3.5e3,230.0],["new",3.4e3,80.0],["new",3230.0,10.0],["new",3228.0,10.0],["new",3.2e3,20.0],["new",3001.0,20.0],["new",3.0e3,7.2e3],["new",2999.0,40.0],["new",2879.0,300.0],["new",2601.0,20.0],["new",2544.0,10.0],["new",2.5e3,20.0],["new",2467.0,2.56e4],["new",2.4e3,1.0e3],["new",2309.0,250.0],["new",2.3e3,20.0],["new",2222.0,680.0],["new",2211.0,40.0],["new",2005.0,140.0],["new",2.0e3,21250.0],["new",1999.0,10.0],["new",1994.5,5.0e3],["new",1979.0,60.0],["new",1.9e3,30.0],["new",1.7e3,300.0],["new",1.4e3,40.0],["new",1234.0,10.0],["new",1205.0,40.0],["new",1.1e3,20.0],["new",1099.0,10.0],["new",1002.5,70.0],["new",1001.5,60.0],["new",1000.5,80.0],["new",1.0e3,12450.0],["new",900.0,10.0],["new",800.0,10.0],["new",648.0,40.0],["new",600.0,760.0],["new",541.5,1.0e4],["new",502.0,1350.0],["new",500.0,3580.0],["new",400.0,150.0],["new",300.0,540.0],["new",288.0,10.0],["new",287.0,10.0],["new",281.0,100.0],["new",234.0,20.0],["new",222.0,300.0],["new",200.0,1220.0],["new",123.0,1.0e3],["new",120.0,110.0],["new",110.0,80.0],["new",101.0,110.0],["new",100.0,123510.0],["new",60.0,270.0],["new",58.0,10.0],["new",50.0,1350.0],["new",40.0,120.0],["new",35.5,20.0],["new",30.0,10350.0],["new",25.0,30.0],["new",23.0,20.0],["new",20.0,2210.0],["new",16.5,10.0],["new",15.0,20.0],["new",13.0,30.0],["new",12.0,2160.0],["new",11.0,10.0],["new",10.0,4010.0],["new",9.0,20.0],["new",6.5,10.0],["new",6.0,40.0],["new",5.0,300.0],["new",4.0,40.0],["new",3.0,20.0],["new",1.0,390.0],["new",0.5,61150.0]],"asks":[["new",78380.0,10080.0],["new",78381.0,81640.0],["new",78382.0,1.0e4],["new",78382.5,9470.0],["new",78383.5,190.0],["new",78385.0,1.0e4],["new",78385.5,160.0],["new",78388.0,6170.0],["new",78390.5,190.0],["new",78393.0,200.0],["new",78393.5,7680.0],["new",78394.5,8530.0],["new",78395.0,16860.0],["new",78395.5,220.0],["new",78396.0,25920.0],["new",78397.0,16490.0],["new",78397.5,16490.0],["new",78398.0,3.94e4],["new",78398.5,1.0e4],["new",78399.0,500.0],["new",78416.5,6640830.0],["new",78556.5,7.5e6],["new",78561.0,78560.0],["new",78569.5,7777770.0],["new",78611.0,117910.0],["new",78647.5,6930.0],["new",7.9e4,7.5e6],["new",79062.5,10.0],["new",7.95e4,2.5e6],["new",8.0e4,2.5e6],["new",80290.5,10.0],["new",81962.0,81590.0],["new",8.2e4,2.5e6],["new",82168.0,81830.0],["new",82526.0,100.0],["new",82848.0,83220.0],["new",83422.5,170.0],["new",83749.0,1.0e4],["new",84318.5,300.0],["new",8.45e4,1.0e6],["new",8.5e4,1.0e6],["new",85215.0,520.0],["new",8.55e4,1.0e6],["new",8.6e4,1.0e6],["new",8.7e4,1.0e6],["new",8.75e4,1.0e6],["new",8.8e4,1.0e6],["new",9.0e4,20.0],["new",91747.0,300.0],["new",92036.5,100.0],["new",92823.0,6810.0],["new",92838.5,520.0],["new",95042.0,4190.0],["new",9.52e4,5950.0],["new",9.8e4,10.0],["new",9.9e4,20.0],["new",99670.0,5630.0],["new",1.0e5,10020.0],["new",100094.5,170.0],["new",100128.0,100.0],["new",100141.5,30.0],["new",100166.5,190.0],["new",1.002e5,10.0],["new",1.004e5,10.0],["new",1.006e5,10.0],["new",1.008e5,5580.0],["new",100894.0,20.0],["new",1.01e5,20.0],["new",101144.5,190.0],["new",1.012e5,20.0],["new",1.014e5,20.0],["new",1.016e5,20.0],["new",1.018e5,20.0],["new",1.02e5,30.0],["new",102106.5,20.0],["new",1.022e5,30.0],["new",1.024e5,30.0],["new",1.026e5,30.0],["new",1.028e5,30.0],["new",1.03e5,40.0],["new",103085.5,30.0],["new",103097.5,70.0],["new",103102.0,200.0],["new",103114.0,90.0],["new",1.032e5,40.0],["new",1.034e5,40.0],["new",1.036e5,40.0],["new",1.038e5,40.0],["new",1.04e5,50.0],["new",104059.0,180.0],["new",104115.5,40.0],["new",104160.5,70.0],["new",1.042e5,50.0],["new",104228.0,50.0],["new",1.044e5,50.0],["new",1.046e5,50.0],["new",1.048e5,50.0],["new",1.05e5,60.0],["new",1.052e5,60.0],["new",105206.5,80.0],["new",1.054e5,60.0],["new",1.056e5,60.0],["new",1.058e5,60.0],["new",1.06e5,70.0],["new",1.062e5,70.0],["new",1.064e5,70.0],["new",1.066e5,70.0],["new",1.068e5,70.0],["new",1.07e5,80.0],["new",1.072e5,80.0],["new",107232.0,230.0],["new",1.074e5,80.0],["new",1.076e5,80.0],["new",107667.0,290.0],["new",1.078e5,80.0],["new",1.08e5,90.0],["new",1.082e5,90.0],["new",1.084e5,90.0],["new",1.086e5,90.0],["new",1.088e5,90.0],["new",1.09e5,100.0],["new",109004.5,500.0],["new",1.092e5,100.0],["new",1.094e5,100.0],["new",1.096e5,100.0],["new",1.098e5,100.0],["new",110298.0,210.0],["new",110763.0,260.0],["new",111228.0,310.0],["new",111693.0,370.0],["new",112158.0,440.0],["new",112285.0,450.0],["new",112623.0,530.0],["new",113088.0,640.0],["new",113553.0,770.0],["new",114018.0,920.0],["new",114483.5,1.1e3],["new",114948.5,1320.0],["new",115164.0,550.0],["new",115413.5,1590.0],["new",118043.5,680.0],["new",119094.5,120.0],["new",1.2e5,100020.0],["new",120922.5,820.0],["new",123801.5,1010.0],["new",126680.5,1230.0],["new",129559.5,1.5e3],["new",130318.5,130.0],["new",145037.0,150.0],["new",145090.5,150.0],["new",145306.5,300.0],["new",1.5e5,38100030.0]]}}}
[2025-04-07 08:29:03.690] [multi_sink] [info] 📩 Received: {"jsonrpc":"2.0","method":"subscription","params":{"channel":"book.BTC-PERPETUAL.100ms","data":{"timestamp":1743994745318,"type":"change","change_id":41151777988,"instrument_name":"BTC-PERPETUAL","bids":[["new",78202.5,8000580.0],["delete",78186.0,0.0]],"asks":[],"prev_change_id":41151772092}}}
[2025-04-07 08:29:03.695] [multi_sink] [info] Processing received message: {"jsonrpc":"2.0","method":"subscription","params":{"channel":"book.BTC-PERPETUAL.100ms","data":{"timestamp":1743994745318,"type":"change","change_id":41151777988,"instrument_name":"BTC-PERPETUAL","bids":[["new",78202.5,8000580.0],["delete",78186.0,0.0]],"asks":[],"prev_change_id":41151772092}}}
[2025-04-07 08:29:04.018] [multi_sink] [info] 📩 Received: {"jsonrpc":"2.0","method":"subscription","params":{"channel":"book.BTC-PERPETUAL.100ms","data":{"timestamp":1743994745639,"type":"change","change_id":41151778261,"instrument_name":"BTC-PERPETUAL","bids":[["delete",78379.5,0.0],["delete",78379.0,0.0],["change",78378.5,29470.0],["new",78378.0,5230.0],["change",78377.5,4.0e4],["delete",78376.5,0.0],["delete",78376.0,0.0],["change",78375.5,470.0],["new",78375.0,16490.0],["new",78374.5,5230.0],["new",78373.5,390.0],["delete",78373.0,0.0],["delete",78372.5,0.0],["new",78371.5,50730.0],["new",78371.0,5330.0],["new",78355.5,7825720.0],["delete",78339.0,0.0]],"asks":[["delete",78380.0,0.0],["delete",78381.0,0.0],["delete",78382.0,0.0],["delete",78382.5,0.0],["delete",78383.5,0.0],["delete",78385.0,0.0],["delete",78385.5,0.0],["delete",78388.0,0.0],["delete",78390.5,0.0],["new",78402.5,34760.0],["new",78403.0,200.0],["new",78403.5,500.0],["new",78405.0,8530.0],["new",78405.5,220.0],["new",78407.0,83160.0],["new",78407.5,1.0e4],["new",78408.0,81640.0],["new",78409.0,5710.0]],"prev_change_id":41151777988}}}
[2025-04-07 08:29:04.020] [multi_sink] [info] Processing received message: {"jsonrpc":"2.0","method":"subscription","params":{"channel":"book.BTC-PERPETUAL.100ms","data":{"timestamp":1743994745639,"type":"change","change_id":41151778261,"instrument_name":"BTC-PERPETUAL","bids":[["delete",78379.5,0.0],["delete",78379.0,0.0],["change",78378.5,29470.0],["new",78378.0,5230.0],["change",78377.5,4.0e4],["delete",78376.5,0.0],["delete",78376.0,0.0],["change",78375.5,470.0],["new",78375.0,16490.0],["new",78374.5,5230.0],["new",78373.5,390.0],["delete",78373.0,0.0],["delete",78372.5,0.0],["new",78371.5,50730.0],["new",78371.0,5330.0],["new",78355.5,7825720.0],["delete",78339.0,0.0]],"asks":[["delete",78380.0,0.0],["delete",78381.0,0.0],["delete",78382.0,0.0],["delete",78382.5,0.0],["delete",78383.5,0.0],["delete",78385.0,0.0],["delete",78385.5,0.0],["delete",78388.0,0.0],["delete",78390.5,0.0],["new",78402.5,34760.0],["new",78403.0,200.0],["new",78403.5,500.0],["new",78405.0,8530.0],["new",78405.5,220.0],["new",78407.0,83160.0],["new",78407.5,1.0e4],["new",78408.0,81640.0],["new",78409.0,5710.0]],"prev_change_id":41151777988}}}
[2025-04-07 08:29:04.346] [multi_sink] [info] 📩 Received: {"jsonrpc":"2.0","method":"subscription","params":{"channel":"book.BTC-PERPETUAL.100ms","data":{"timestamp":1743994745946,"type":"change","change_id":41151779245,"instrument_name":"BTC-PERPETUAL","bids":[["new",78385.5,4920.0],["new",78385.0,13050.0],["new",78383.0,1.35e4],["new",78380.5,2.25e4],["new",78380.0,53370.0],["new",78379.5,33010.0],["new",78379.0,3840.0],["delete",78372.0,0.0],["delete",78370.0,0.0],["delete",78368.0,0.0],["delete",78367.5,0.0],["delete",78366.0,0.0],["delete",78365.0,0.0],["delete",78364.5,0.0],["delete",78364.0,0.0]],"asks":[["delete",78393.0,0.0],["delete",78393.5,0.0],["delete",78394.5,0.0],["delete",78395.0,0.0],["delete",78395.5,0.0],["delete",78396.0,0.0],["delete",78397.0,0.0],["delete",78397.5,0.0],["change",78398.0,39570.0],["change",78398.5,26490.0],["change",78399.0,16990.0],["new",78399.5,3010.0],["new",78400.5,190.0],["new",78401.0,3.5e4],["new",78401.5,33480.0],["new",78402.0,1.0e4],["delete",78416.5,0.0],["new",78433.0,6640830.0],["delete",78569.5,0.0],["new",78586.0,7777770.0]],"prev_change_id":41151778261}}}
[2025-04-07 08:29:04.349] [multi_sink] [info] Processing received message: {"jsonrpc":"2.0","method":"subscription","params":{"channel":"book.BTC-PERPETUAL.100ms","data":{"timestamp":1743994745946,"type":"change","change_id":41151779245,"instrument_name":"BTC-PERPETUAL","bids":[["new",78385.5,4920.0],["new",78385.0,13050.0],["new",78383.0,1.35e4],["new",78380.5,2.25e4],["new",78380.0,53370.0],["new",78379.5,33010.0],["new",78379.0,3840.0],["delete",78372.0,0.0],["delete",78370.0,0.0],["delete",78368.0,0.0],["delete",78367.5,0.0],["delete",78366.0,0.0],["delete",78365.0,0.0],["delete",78364.5,0.0],["delete",78364.0,0.0]],"asks":[["delete",78393.0,0.0],["delete",78393.5,0.0],["delete",78394.5,0.0],["delete",78395.0,0.0],["delete",78395.5,0.0],["delete",78396.0,0.0],["delete",78397.0,0.0],["delete",78397.5,0.0],["change",78398.0,39570.0],["change",78398.5,26490.0],["change",78399.0,16990.0],["new",78399.5,3010.0],["new",78400.5,190.0],["new",78401.0,3.5e4],["new",78401.5,33480.0],["new",78402.0,1.0e4],["delete",78416.5,0.0],["new",78433.0,6640830.0],["delete",78569.5,0.0],["new",78586.0,7777770.0]],"prev_change_id":41151778261}}}
[2025-04-07 08:29:04.683] [multi_sink] [info] 📩 Received: {"jsonrpc":"2.0","method":"subscription","params":{"channel":"book.BTC-PERPETUAL.100ms","data":{"timestamp":1743994746063,"type":"change","change_id":41151779280,"instrument_name":"BTC-PERPETUAL","bids":[["new",78394.0,1.08e4],["new",78392.0,6750.0],["new",78391.5,2.25e4],["delete",78363.5,0.0],["delete",78362.5,0.0],["delete",78362.0,0.0]],"asks":[["new",78394.5,52780.0],["new",78395.0,28490.0],["new",78395.5,160.0],["change",78398.0,170.0],["change",78398.5,16490.0],["change",78399.0,16490.0]],"prev_change_id":41151779245}}}
[2025-04-07 08:29:04.686] [multi_sink] [info] Processing received message: {"jsonrpc":"2.0","method":"subscription","params":{"channel":"book.BTC-PERPETUAL.100ms","data":{"timestamp":1743994746063,"type":"change","change_id":41151779280,"instrument_name":"BTC-PERPETUAL","bids":[["new",78394.0,1.08e4],["new",78392.0,6750.0],["new",78391.5,2.25e4],["delete",78363.5,0.0],["delete",78362.5,0.0],["delete",78362.0,0.0]],"asks":[["new",78394.5,52780.0],["new",78395.0,28490.0],["new",78395.5,160.0],["change",78398.0,170.0],["change",78398.5,16490.0],["change",78399.0,16490.0]],"prev_change_id":41151779245}}}
[2025-04-07 08:29:05.341] [multi_sink] [info] 📩 Received: {"jsonrpc":"2.0","method":"subscription","params":{"channel":"book.BTC-PERPETUAL.100ms","data":{"timestamp":1743994746973,"type":"change","change_id":41151780845,"instrument_name":"BTC-PERPETUAL","bids":[],"asks":[["new",78551.0,78550.0],["delete",78561.0,0.0]],"prev_change_id":41151779280}}}
[2025-04-07 08:29:05.344] [multi_sink] [info] Processing received message: {"jsonrpc":"2.0","method":"subscription","params":{"channel":"book.BTC-PERPETUAL.100ms","data":{"timestamp":1743994746973,"type":"change","change_id":41151780845,"instrument_name":"BTC-PERPETUAL","bids":[],"asks":[["new",78551.0,78550.0],["delete",78561.0,0.0]],"prev_change_id":41151779280}}}
[2025-04-07 08:29:05.684] [multi_sink] [info] 📩 Received: {"jsonrpc":"2.0","method":"subscription","params":{"channel":"book.BTC-PERPETUAL.100ms","data":{"timestamp":1743994746976,"type":"change","change_id":41151780846,"instrument_name":"BTC-PERPETUAL","bids":[],"asks":[["new",78601.0,1.179e5],["delete",78611.0,0.0]],"prev_change_id":41151780845}}}
[2025-04-07 08:29:05.689] [multi_sink] [info] Processing received message: {"jsonrpc":"2.0","method":"subscription","params":{"channel":"book.BTC-PERPETUAL.100ms","data":{"timestamp":1743994746976,"type":"change","change_id":41151780846,"instrument_name":"BTC-PERPETUAL","bids":[],"asks":[["new",78601.0,1.179e5],["delete",78611.0,0.0]],"prev_change_id":41151780845}}}
[2025-04-07 08:29:06.006] [multi_sink] [info] 📩 Received: {"jsonrpc":"2.0","method":"subscription","params":{"channel":"book.BTC-PERPETUAL.100ms","data":{"timestamp":1743994747584,"type":"change","change_id":41151781186,"instrument_name":"BTC-PERPETUAL","bids":[],"asks":[["delete",78551.0,0.0],["new",78563.5,78560.0],["delete",78601.0,0.0],["new",78613.5,117920.0]],"prev_change_id":41151780846}}}
[2025-04-07 08:29:06.008] [multi_sink] [info] Processing received message: {"jsonrpc":"2.0","method":"subscription","params":{"channel":"book.BTC-PERPETUAL.100ms","data":{"timestamp":1743994747584,"type":"change","change_id":41151781186,"instrument_name":"BTC-PERPETUAL","bids":[],"asks":[["delete",78551.0,0.0],["new",78563.5,78560.0],["delete",78601.0,0.0],["new",78613.5,117920.0]],"prev_change_id":41151780846}}}
[2025-04-07 08:29:07.566] [multi_sink] [info] 📩 Received: {"jsonrpc":"2.0","method":"subscription","params":{"channel":"book.BTC-PERPETUAL.100ms","data":{"timestamp":1743994749195,"type":"change","change_id":41151783579,"instrument_name":"BTC-PERPETUAL","bids":[],"asks":[["new",78553.0,78550.0],["delete",78563.5,0.0]],"prev_change_id":41151781186}}}
[2025-04-07 08:29:07.568] [multi_sink] [info] Processing received message: {"jsonrpc":"2.0","method":"subscription","params":{"channel":"book.BTC-PERPETUAL.100ms","data":{"timestamp":1743994749195,"type":"change","change_id":41151783579,"instrument_name":"BTC-PERPETUAL","bids":[],"asks":[["new",78553.0,78550.0],["delete",78563.5,0.0]],"prev_change_id":41151781186}}}
[2025-04-07 08:29:07.894] [multi_sink] [info] 📩 Received: {"jsonrpc":"2.0","method":"subscription","params":{"channel":"book.BTC-PERPETUAL.100ms","data":{"timestamp":1743994749199,"type":"change","change_id":41151783580,"instrument_name":"BTC-PERPETUAL","bids":[],"asks":[["new",78603.0,1.179e5],["delete",78613.5,0.0]],"prev_change_id":41151783579}}}
[2025-04-07 08:29:07.897] [multi_sink] [info] Processing received message: {"jsonrpc":"2.0","method":"subscription","params":{"channel":"book.BTC-PERPETUAL.100ms","data":{"timestamp":1743994749199,"type":"change","change_id":41151783580,"instrument_name":"BTC-PERPETUAL","bids":[],"asks":[["new",78603.0,1.179e5],["delete",78613.5,0.0]],"prev_change_id":41151783579}}}
[2025-04-07 08:29:08.709] [multi_sink] [info] 📩 Received: {"jsonrpc":"2.0","method":"subscription","params":{"channel":"book.BTC-PERPETUAL.100ms","data":{"timestamp":1743994750340,"type":"change","change_id":41151785149,"instrument_name":"BTC-PERPETUAL","bids":[],"asks":[["delete",78394.5,0.0],["new",78412.5,13770.0]],"prev_change_id":41151783580}}}
[2025-04-07 08:29:08.714] [multi_sink] [info] Processing received message: {"jsonrpc":"2.0","method":"subscription","params":{"channel":"book.BTC-PERPETUAL.100ms","data":{"timestamp":1743994750340,"type":"change","change_id":41151785149,"instrument_name":"BTC-PERPETUAL","bids":[],"asks":[["delete",78394.5,0.0],["new",78412.5,13770.0]],"prev_change_id":41151783580}}}
[2025-04-07 08:29:09.042] [multi_sink] [info] 📩 Received: {"jsonrpc":"2.0","method":"subscription","params":{"channel":"book.BTC-PERPETUAL.100ms","data":{"timestamp":1743994750643,"type":"change","change_id":41151785419,"instrument_name":"BTC-PERPETUAL","bids":[["delete",78394.0,0.0],["delete",78392.0,0.0],["delete",78391.5,0.0],["delete",78385.5,0.0],["delete",78385.0,0.0],["delete",78383.0,0.0],["delete",78380.5,0.0],["delete",78380.0,0.0],["delete",78379.5,0.0],["change",78379.0,20820.0],["change",78378.5,60370.0],["change",78378.0,44950.0],["change",78377.5,90470.0],["change",78375.0,32980.0],["change",78374.5,10460.0],["new",78370.5,1.0e4],["new",78369.0,5230.0],["new",78368.0,29840.0]],"asks":[["delete",78395.0,0.0],["delete",78395.5,0.0],["delete",78398.0,0.0],["delete",78398.5,0.0],["delete",78399.0,0.0],["delete",78399.5,0.0],["delete",78400.5,0.0],["delete",78401.0,0.0],["change",78405.0,36520.0],["change",78405.5,49820.0],["change",78407.0,83380.0],["change",78407.5,93680.0],["change",78408.0,181820.0],["new",78409.5,10350.0],["new",78410.5,34490.0],["new",78412.0,20470.0]],"prev_change_id":41151785149}}}
[2025-04-07 08:29:09.044] [multi_sink] [info] Processing received message: {"jsonrpc":"2.0","method":"subscription","params":{"channel":"book.BTC-PERPETUAL.100ms","data":{"timestamp":1743994750643,"type":"change","change_id":41151785419,"instrument_name":"BTC-PERPETUAL","bids":[["delete",78394.0,0.0],["delete",78392.0,0.0],["delete",78391.5,0.0],["delete",78385.5,0.0],["delete",78385.0,0.0],["delete",78383.0,0.0],["delete",78380.5,0.0],["delete",78380.0,0.0],["delete",78379.5,0.0],["change",78379.0,20820.0],["change",78378.5,60370.0],["change",78378.0,44950.0],["change",78377.5,90470.0],["change",78375.0,32980.0],["change",78374.5,10460.0],["new",78370.5,1.0e4],["new",78369.0,5230.0],["new",78368.0,29840.0]],"asks":[["delete",78395.0,0.0],["delete",78395.5,0.0],["delete",78398.0,0.0],["delete",78398.5,0.0],["delete",78399.0,0.0],["delete",78399.5,0.0],["delete",78400.5,0.0],["delete",78401.0,0.0],["change",78405.0,36520.0],["change",78405.5,49820.0],["change",78407.0,83380.0],["change",78407.5,93680.0],["change",78408.0,181820.0],["new",78409.5,10350.0],["new",78410.5,34490.0],["new",78412.0,20470.0]],"prev_change_id":41151785149}}}
[2025-04-07 08:29:09.370] [multi_sink] [info] 📩 Received: {"jsonrpc":"2.0","method":"subscription","params":{"channel":"book.BTC-PERPETUAL.100ms","data":{"timestamp":1743994750987,"type":"change","change_id":41151786401,"instrument_name":"BTC-PERPETUAL","bids":[["new",78389.0,430.0],["new",78388.0,4060.0],["new",78386.5,470.0],["new",78385.0,12870.0],["new",78384.0,510.0],["new",78382.5,5260.0],["new",78382.0,16490.0],["new",78381.5,550.0],["new",78380.5,480.0],["change",78379.0,16980.0],["change",78378.5,3.09e4],["change",78378.0,39720.0],["change",78377.5,50470.0],["delete",78375.5,0.0],["change",78375.0,16490.0],["change",78374.5,5230.0],["delete",78373.5,0.0],["delete",78371.5,0.0]],"asks":[["new",78397.0,650.0],["new",78397.5,10380.0],["new",78399.5,9640.0],["new",7.84e4,16650.0],["new",78400.5,29110.0],["new",78401.0,3.5e4],["delete",78401.5,0.0],["change",78402.0,22170.0],["change",78402.5,38330.0],["delete",78403.0,0.0],["delete",78403.5,0.0],["new",78404.5,200.0],["change",78405.0,27990.0],["change",78405.5,4.96e4],["change",78407.0,220.0],["change",78407.5,83680.0]],"prev_change_id":41151785419}}}
[2025-04-07 08:29:09.374] [multi_sink] [info] Processing received message: {"jsonrpc":"2.0","method":"subscription","params":{"channel":"book.BTC-PERPETUAL.100ms","data":{"timestamp":1743994750987,"type":"change","change_id":41151786401,"instrument_name":"BTC-PERPETUAL","bids":[["new",78389.0,430.0],["new",78388.0,4060.0],["new",78386.5,470.0],["new",78385.0,12870.0],["new",78384.0,510.0],["new",78382.5,5260.0],["new",78382.0,16490.0],["new",78381.5,550.0],["new",78380.5,480.0],["change",78379.0,16980.0],["change",78378.5,3.09e4],["change",78378.0,39720.0],["change",78377.5,50470.0],["delete",78375.5,0.0],["change",78375.0,16490.0],["change",78374.5,5230.0],["delete",78373.5,0.0],["delete",78371.5,0.0]],"asks":[["new",78397.0,650.0],["new",78397.5,10380.0],["new",78399.5,9640.0],["new",7.84e4,16650.0],["new",78400.5,29110.0],["new",78401.0,3.5e4],["delete",78401.5,0.0],["change",78402.0,22170.0],["change",78402.5,38330.0],["delete",78403.0,0.0],["delete",78403.5,0.0],["new",78404.5,200.0],["change",78405.0,27990.0],["change",78405.5,4.96e4],["change",78407.0,220.0],["change",78407.5,83680.0]],"prev_change_id":41151785419}}}
[2025-04-07 08:29:09.701] [multi_sink] [info] 📩 Received: {"jsonrpc":"2.0","method":"subscription","params":{"channel":"book.BTC-PERPETUAL.100ms","data":{"timestamp":1743994751063,"type":"change","change_id":41151786438,"instrument_name":"BTC-PERPETUAL","bids":[["new",78394.0,49310.0],["new",78393.5,3.3e3],["delete",78371.0,0.0]],"asks":[["new",78394.5,78770.0],["new",78395.0,14220.0],["change",78408.0,100180.0],["delete",78409.0,0.0]],"prev_change_id":41151786401}}}
[2025-04-07 08:29:09.706] [multi_sink] [info] Processing received message: {"jsonrpc":"2.0","method":"subscription","params":{"channel":"book.BTC-PERPETUAL.100ms","data":{"timestamp":1743994751063,"type":"change","change_id":41151786438,"instrument_name":"BTC-PERPETUAL","bids":[["new",78394.0,49310.0],["new",78393.5,3.3e3],["delete",78371.0,0.0]],"asks":[["new",78394.5,78770.0],["new",78395.0,14220.0],["change",78408.0,100180.0],["delete",78409.0,0.0]],"prev_change_id":41151786401}}}
[2025-04-07 08:29:13.708] [multi_sink] [info] 📩 Received: {"jsonrpc":"2.0","method":"subscription","params":{"channel":"book.BTC-PERPETUAL.100ms","data":{"timestamp":1743994755340,"type":"change","change_id":41151792298,"instrument_name":"BTC-PERPETUAL","bids":[],"asks":[["delete",78394.5,0.0],["change",78408.0,200360.0]],"prev_change_id":41151786438}}}
[2025-04-07 08:29:13.710] [multi_sink] [info] Processing received message: {"jsonrpc":"2.0","method":"subscription","params":{"channel":"book.BTC-PERPETUAL.100ms","data":{"timestamp":1743994755340,"type":"change","change_id":41151792298,"instrument_name":"BTC-PERPETUAL","bids":[],"asks":[["delete",78394.5,0.0],["change",78408.0,200360.0]],"prev_change_id":41151786438}}}
[2025-04-07 08:29:14.039] [multi_sink] [info] 📩 Received: {"jsonrpc":"2.0","method":"subscription","params":{"channel":"book.BTC-PERPETUAL.100ms","data":{"timestamp":1743994755668,"type":"change","change_id":41151792555,"instrument_name":"BTC-PERPETUAL","bids":[["delete",78394.0,0.0],["delete",78393.5,0.0],["delete",78389.0,0.0],["delete",78388.0,0.0],["delete",78386.5,0.0],["delete",78385.0,0.0],["delete",78384.0,0.0],["delete",78382.5,0.0],["delete",78382.0,0.0],["change",78378.5,34740.0],["change",78378.0,40210.0],["change",78377.5,90470.0],["new",78377.0,16490.0],["new",78376.5,9470.0],["new",78375.5,6140.0],["change",78374.5,10460.0],["new",78374.0,1.0e4],["new",78373.0,5230.0]],"asks":[["delete",78395.0,0.0],["delete",78397.0,0.0],["delete",78397.5,0.0],["delete",78399.5,0.0],["delete",7.84e4,0.0],["delete",78400.5,0.0],["change",78401.0,16490.0],["new",78401.5,5490.0],["change",78402.0,1.0e4],["change",78402.5,35040.0],["new",78403.0,3840.0],["new",78403.5,27990.0],["new",78404.0,38730.0],["change",78405.0,37990.0],["change",78407.5,8.42e4]],"prev_change_id":41151792298}}}
[2025-04-07 08:29:14.042] [multi_sink] [info] Processing received message: {"jsonrpc":"2.0","method":"subscription","params":{"channel":"book.BTC-PERPETUAL.100ms","data":{"timestamp":1743994755668,"type":"change","change_id":41151792555,"instrument_name":"BTC-PERPETUAL","bids":[["delete",78394.0,0.0],["delete",78393.5,0.0],["delete",78389.0,0.0],["delete",78388.0,0.0],["delete",78386.5,0.0],["delete",78385.0,0.0],["delete",78384.0,0.0],["delete",78382.5,0.0],["delete",78382.0,0.0],["change",78378.5,34740.0],["change",78378.0,40210.0],["change",78377.5,90470.0],["new",78377.0,16490.0],["new",78376.5,9470.0],["new",78375.5,6140.0],["change",78374.5,10460.0],["new",78374.0,1.0e4],["new",78373.0,5230.0]],"asks":[["delete",78395.0,0.0],["delete",78397.0,0.0],["delete",78397.5,0.0],["delete",78399.5,0.0],["delete",7.84e4,0.0],["delete",78400.5,0.0],["change",78401.0,16490.0],["new",78401.5,5490.0],["change",78402.0,1.0e4],["change",78402.5,35040.0],["new",78403.0,3840.0],["new",78403.5,27990.0],["new",78404.0,38730.0],["change",78405.0,37990.0],["change",78407.5,8.42e4]],"prev_change_id":41151792298}}}
[2025-04-07 08:29:14.369] [multi_sink] [info] 📩 Received: {"jsonrpc":"2.0","method":"subscription","params":{"channel":"book.BTC-PERPETUAL.100ms","data":{"timestamp":1743994755978,"type":"change","change_id":41151793533,"instrument_name":"BTC-PERPETUAL","bids":[["new",78389.5,2.25e4],["new",78389.0,170.0],["new",78387.0,1.0e3],["new",78386.5,190.0],["new",78384.0,200.0],["new",78383.0,1.04e4],["change",78381.5,220.0],["change",78380.5,33460.0],["new",78379.5,19140.0],["delete",78379.0,0.0],["change",78378.5,3840.0],["change",78378.0,490.0],["change",78377.5,4.0e4],["delete",78375.0,0.0],["change",78374.5,5230.0],["delete",78370.5,0.0]],"asks":[["new",78395.5,9350.0],["new",78396.0,1.0e4],["new",78396.5,2.25e4],["new",78397.0,3.5e4],["new",78397.5,850.0],["new",78399.5,15470.0],["new",7.84e4,17160.0],["new",78400.5,21530.0],["delete",78404.5,0.0],["change",78405.0,1.0e4],["delete",78405.5,0.0],["delete",78407.0,0.0],["change",78407.5,520.0],["change",78408.0,100180.0],["delete",78409.5,0.0],["delete",78410.5,0.0]],"prev_change_id":41151792555}}}
[2025-04-07 08:29:14.373] [multi_sink] [info] Processing received message: {"jsonrpc":"2.0","method":"subscription","params":{"channel":"book.BTC-PERPETUAL.100ms","data":{"timestamp":1743994755978,"type":"change","change_id":41151793533,"instrument_name":"BTC-PERPETUAL","bids":[["new",78389.5,2.25e4],["new",78389.0,170.0],["new",78387.0,1.0e3],["new",78386.5,190.0],["new",78384.0,200.0],["new",78383.0,1.04e4],["change",78381.5,220.0],["change",78380.5,33460.0],["new",78379.5,19140.0],["delete",78379.0,0.0],["change",78378.5,3840.0],["change",78378.0,490.0],["change",78377.5,4.0e4],["delete",78375.0,0.0],["change",78374.5,5230.0],["delete",78370.5,0.0]],"asks":[["new",78395.5,9350.0],["new",78396.0,1.0e4],["new",78396.5,2.25e4],["new",78397.0,3.5e4],["new",78397.5,850.0],["new",78399.5,15470.0],["new",7.84e4,17160.0],["new",78400.5,21530.0],["delete",78404.5,0.0],["change",78405.0,1.0e4],["delete",78405.5,0.0],["delete",78407.0,0.0],["change",78407.5,520.0],["change",78408.0,100180.0],["delete",78409.5,0.0],["delete",78410.5,0.0]],"prev_change_id":41151792555}}}
[2025-04-07 08:29:14.698] [multi_sink] [info] 📩 Received: {"jsonrpc":"2.0","method":"subscription","params":{"channel":"book.BTC-PERPETUAL.100ms","data":{"timestamp":1743994756052,"type":"change","change_id":41151793561,"instrument_name":"BTC-PERPETUAL","bids":[["new",78394.0,7570.0],["new",78390.0,7180.0],["delete",78369.0,0.0],["delete",78368.0,0.0]],"asks":[["new",78394.5,113750.0],["new",78395.0,39020.0],["delete",78412.0,0.0],["delete",78412.5,0.0]],"prev_change_id":41151793533}}}
[2025-04-07 08:29:14.699] [multi_sink] [info] Processing received message: {"jsonrpc":"2.0","method":"subscription","params":{"channel":"book.BTC-PERPETUAL.100ms","data":{"timestamp":1743994756052,"type":"change","change_id":41151793561,"instrument_name":"BTC-PERPETUAL","bids":[["new",78394.0,7570.0],["new",78390.0,7180.0],["delete",78369.0,0.0],["delete",78368.0,0.0]],"asks":[["new",78394.5,113750.0],["new",78395.0,39020.0],["delete",78412.0,0.0],["delete",78412.5,0.0]],"prev_change_id":41151793533}}}
[2025-04-07 08:29:18.624] [multi_sink] [info] 📩 Received: {"jsonrpc":"2.0","method":"subscription","params":{"channel":"book.BTC-PERPETUAL.100ms","data":{"timestamp":1743994760152,"type":"change","change_id":41151799182,"instrument_name":"BTC-PERPETUAL","bids":[["new",78239.0,78230.0],["delete",78229.0,0.0],["new",78189.0,117270.0],["delete",78179.0,0.0]],"asks":[["delete",78553.0,0.0],["new",78565.0,78560.0],["delete",78603.0,0.0],["new",78615.0,117920.0]],"prev_change_id":41151793561}}}
[2025-04-07 08:29:18.628] [multi_sink] [info] Processing received message: {"jsonrpc":"2.0","method":"subscription","params":{"channel":"book.BTC-PERPETUAL.100ms","data":{"timestamp":1743994760152,"type":"change","change_id":41151799182,"instrument_name":"BTC-PERPETUAL","bids":[["new",78239.0,78230.0],["delete",78229.0,0.0],["new",78189.0,117270.0],["delete",78179.0,0.0]],"asks":[["delete",78553.0,0.0],["new",78565.0,78560.0],["delete",78603.0,0.0],["new",78615.0,117920.0]],"prev_change_id":41151793561}}}
[2025-04-07 08:29:18.955] [multi_sink] [info] 📩 Received: {"jsonrpc":"2.0","method":"subscription","params":{"channel":"book.BTC-PERPETUAL.100ms","data":{"timestamp":1743994760563,"type":"change","change_id":41151799479,"instrument_name":"BTC-PERPETUAL","bids":[["delete",78394.0,0.0],["delete",78390.0,0.0],["delete",78389.5,0.0],["delete",78389.0,0.0],["delete",78387.0,0.0],["delete",78386.5,0.0],["new",78385.5,4.0e4],["new",78385.0,200.0],["new",78384.5,9470.0],["delete",78384.0,0.0],["new",78382.5,220.0],["change",78380.5,38680.0],["change",78379.5,43020.0],["change",78378.0,50080.0]],"asks":[["delete",78394.5,0.0],["delete",78395.0,0.0],["delete",78395.5,0.0],["delete",78396.0,0.0],["delete",78396.5,0.0],["delete",78397.0,0.0],["delete",78397.5,0.0],["new",78423.0,105530.0],["new",78423.5,2890.0],["new",78424.0,31080.0],["new",78424.5,40670.0],["new",78425.0,310.0],["new",78425.5,27990.0],["new",78426.0,22950.0]],"prev_change_id":41151799182}}}
[2025-04-07 08:29:18.960] [multi_sink] [info] Processing received message: {"jsonrpc":"2.0","method":"subscription","params":{"channel":"book.BTC-PERPETUAL.100ms","data":{"timestamp":1743994760563,"type":"change","change_id":41151799479,"instrument_name":"BTC-PERPETUAL","bids":[["delete",78394.0,0.0],["delete",78390.0,0.0],["delete",78389.5,0.0],["delete",78389.0,0.0],["delete",78387.0,0.0],["delete",78386.5,0.0],["new",78385.5,4.0e4],["new",78385.0,200.0],["new",78384.5,9470.0],["delete",78384.0,0.0],["new",78382.5,220.0],["change",78380.5,38680.0],["change",78379.5,43020.0],["change",78378.0,50080.0]],"asks":[["delete",78394.5,0.0],["delete",78395.0,0.0],["delete",78395.5,0.0],["delete",78396.0,0.0],["delete",78396.5,0.0],["delete",78397.0,0.0],["delete",78397.5,0.0],["new",78423.0,105530.0],["new",78423.5,2890.0],["new",78424.0,31080.0],["new",78424.5,40670.0],["new",78425.0,310.0],["new",78425.5,27990.0],["new",78426.0,22950.0]],"prev_change_id":41151799182}}}
[2025-04-07 08:29:19.287] [multi_sink] [info] 📩 Received: {"jsonrpc":"2.0","method":"subscription","params":{"channel":"book.BTC-PERPETUAL.100ms","data":{"timestamp":1743994760907,"type":"change","change_id":41151800598,"instrument_name":"BTC-PERPETUAL","bids":[["new",78392.5,160.0],["new",78392.0,40930.0],["new",78391.0,2.25e4],["new",78390.5,3840.0],["new",78390.0,170.0],["new",78389.0,1.0e3],["new",78387.5,190.0],["new",78386.5,29710.0],["new",78386.0,34370.0],["delete",78383.0,0.0],["delete",78381.5,0.0],["change",78380.5,5220.0],["change",78379.5,23880.0],["delete",78378.5,0.0],["change",78378.0,49590.0],["delete",78377.5,0.0],["delete",78377.0,0.0],["delete",78376.5,0.0]],"asks":[["delete",78399.5,0.0],["delete",7.84e4,0.0],["delete",78400.5,0.0],["delete",78401.0,0.0],["delete",78401.5,0.0],["change",78402.0,510.0],["delete",78402.5,0.0],["delete",78403.0,0.0],["delete",78403.5,0.0],["new",78404.5,550.0],["change",78407.5,1040.0],["new",78416.0,4950.0],["new",78419.0,16490.0],["new",78421.0,19330.0],["new",78421.5,35550.0],["new",78422.0,1480.0],["new",78422.5,1260.0]],"prev_change_id":41151799479}}}
[2025-04-07 08:29:19.288] [multi_sink] [info] Processing received message: {"jsonrpc":"2.0","method":"subscription","params":{"channel":"book.BTC-PERPETUAL.100ms","data":{"timestamp":1743994760907,"type":"change","change_id":41151800598,"instrument_name":"BTC-PERPETUAL","bids":[["new",78392.5,160.0],["new",78392.0,40930.0],["new",78391.0,2.25e4],["new",78390.5,3840.0],["new",78390.0,170.0],["new",78389.0,1.0e3],["new",78387.5,190.0],["new",78386.5,29710.0],["new",78386.0,34370.0],["delete",78383.0,0.0],["delete",78381.5,0.0],["change",78380.5,5220.0],["change",78379.5,23880.0],["delete",78378.5,0.0],["change",78378.0,49590.0],["delete",78377.5,0.0],["delete",78377.0,0.0],["delete",78376.5,0.0]],"asks":[["delete",78399.5,0.0],["delete",7.84e4,0.0],["delete",78400.5,0.0],["delete",78401.0,0.0],["delete",78401.5,0.0],["change",78402.0,510.0],["delete",78402.5,0.0],["delete",78403.0,0.0],["delete",78403.5,0.0],["new",78404.5,550.0],["change",78407.5,1040.0],["new",78416.0,4950.0],["new",78419.0,16490.0],["new",78421.0,19330.0],["new",78421.5,35550.0],["new",78422.0,1480.0],["new",78422.5,1260.0]],"prev_change_id":41151799479}}}
[2025-04-07 08:29:19.616] [multi_sink] [info] 📩 Received: {"jsonrpc":"2.0","method":"subscription","params":{"channel":"book.BTC-PERPETUAL.100ms","data":{"timestamp":1743994761054,"type":"change","change_id":41151800643,"instrument_name":"BTC-PERPETUAL","bids":[["new",78396.5,114240.0],["new",78395.0,116270.0],["new",78394.5,97590.0],["new",78394.0,66130.0],["delete",78375.5,0.0],["delete",78374.5,0.0],["delete",78374.0,0.0],["delete",78373.0,0.0]],"asks":[["new",78397.0,430.0],["new",78397.5,380.0],["new",78399.5,470.0],["new",7.84e4,160.0],["delete",78404.0,0.0],["delete",78405.0,0.0],["change",78407.5,520.0],["delete",78408.0,0.0]],"prev_change_id":41151800598}}}
[2025-04-07 08:29:19.620] [multi_sink] [info] Processing received message: {"jsonrpc":"2.0","method":"subscription","params":{"channel":"book.BTC-PERPETUAL.100ms","data":{"timestamp":1743994761054,"type":"change","change_id":41151800643,"instrument_name":"BTC-PERPETUAL","bids":[["new",78396.5,114240.0],["new",78395.0,116270.0],["new",78394.5,97590.0],["new",78394.0,66130.0],["delete",78375.5,0.0],["delete",78374.5,0.0],["delete",78374.0,0.0],["delete",78373.0,0.0]],"asks":[["new",78397.0,430.0],["new",78397.5,380.0],["new",78399.5,470.0],["new",7.84e4,160.0],["delete",78404.0,0.0],["delete",78405.0,0.0],["change",78407.5,520.0],["delete",78408.0,0.0]],"prev_change_id":41151800598}}}
[2025-04-07 08:29:23.717] [multi_sink] [info] 📩 Received: {"jsonrpc":"2.0","method":"subscription","params":{"channel":"book.BTC-PERPETUAL.100ms","data":{"timestamp":1743994765342,"type":"change","change_id":41151806535,"instrument_name":"BTC-PERPETUAL","bids":[],"asks":[["delete",78397.0,0.0],["new",78413.5,7.07e4]],"prev_change_id":41151800643}}}
[2025-04-07 08:29:23.722] [multi_sink] [info] Processing received message: {"jsonrpc":"2.0","method":"subscription","params":{"channel":"book.BTC-PERPETUAL.100ms","data":{"timestamp":1743994765342,"type":"change","change_id":41151806535,"instrument_name":"BTC-PERPETUAL","bids":[],"asks":[["delete",78397.0,0.0],["new",78413.5,7.07e4]],"prev_change_id":41151800643}}}
[2025-04-07 08:29:24.043] [multi_sink] [info] 📩 Received: {"jsonrpc":"2.0","method":"subscription","params":{"channel":"book.BTC-PERPETUAL.100ms","data":{"timestamp":1743994765673,"type":"change","change_id":41151806805,"instrument_name":"BTC-PERPETUAL","bids":[["delete",78396.5,0.0],["delete",78395.0,0.0],["delete",78394.5,0.0],["delete",78394.0,0.0],["delete",78392.5,0.0],["delete",78392.0,0.0],["delete",78391.0,0.0],["delete",78390.5,0.0],["delete",78390.0,0.0],["delete",78389.0,0.0],["change",78386.0,50860.0],["change",78385.5,40970.0],["change",78385.0,850.0],["change",78384.5,25960.0],["new",78384.0,14550.0],["new",78383.5,9470.0],["new",78383.0,2.0e4],["change",78382.5,770.0],["new",78382.0,1.0e4],["new",78381.0,16490.0],["new",78358.5,7825720.0],["delete",78355.5,0.0],["new",78205.5,8000580.0],["delete",78202.5,0.0]],"asks":[["delete",78397.5,0.0],["delete",78399.5,0.0],["delete",7.84e4,0.0],["delete",78402.0,0.0],["delete",78404.5,0.0],["new",78406.5,28160.0],["new",78407.0,5490.0],["change",78407.5,520.0],["new",78408.0,2.93e4],["new",78409.0,190.0],["new",78411.0,1.0e4],["new",78411.5,200.0],["new",78412.0,8.7e4],["new",78412.5,26940.0],["delete",78416.0,0.0],["delete",78419.0,0.0],["delete",78421.0,0.0]],"prev_change_id":41151806535}}}
[2025-04-07 08:29:24.048] [multi_sink] [info] Processing received message: {"jsonrpc":"2.0","method":"subscription","params":{"channel":"book.BTC-PERPETUAL.100ms","data":{"timestamp":1743994765673,"type":"change","change_id":41151806805,"instrument_name":"BTC-PERPETUAL","bids":[["delete",78396.5,0.0],["delete",78395.0,0.0],["delete",78394.5,0.0],["delete",78394.0,0.0],["delete",78392.5,0.0],["delete",78392.0,0.0],["delete",78391.0,0.0],["delete",78390.5,0.0],["delete",78390.0,0.0],["delete",78389.0,0.0],["change",78386.0,50860.0],["change",78385.5,40970.0],["change",78385.0,850.0],["change",78384.5,25960.0],["new",78384.0,14550.0],["new",78383.5,9470.0],["new",78383.0,2.0e4],["change",78382.5,770.0],["new",78382.0,1.0e4],["new",78381.0,16490.0],["new",78358.5,7825720.0],["delete",78355.5,0.0],["new",78205.5,8000580.0],["delete",78202.5,0.0]],"asks":[["delete",78397.5,0.0],["delete",78399.5,0.0],["delete",7.84e4,0.0],["delete",78402.0,0.0],["delete",78404.5,0.0],["new",78406.5,28160.0],["new",78407.0,5490.0],["change",78407.5,520.0],["new",78408.0,2.93e4],["new",78409.0,190.0],["new",78411.0,1.0e4],["new",78411.5,200.0],["new",78412.0,8.7e4],["new",78412.5,26940.0],["delete",78416.0,0.0],["delete",78419.0,0.0],["delete",78421.0,0.0]],"prev_change_id":41151806535}}}
[2025-04-07 08:29:24.373] [multi_sink] [info] 📩 Received: {"jsonrpc":"2.0","method":"subscription","params":{"channel":"book.BTC-PERPETUAL.100ms","data":{"timestamp":1743994765990,"type":"change","change_id":41151807791,"instrument_name":"BTC-PERPETUAL","bids":[["new",78396.0,22580.0],["new",78395.5,2.25e4],["new",78394.5,2.25e4],["new",78394.0,16080.0],["new",78392.5,4230.0],["new",78390.0,430.0],["change",78387.5,470.0],["change",78386.5,10380.0],["change",78386.0,16490.0],["change",78385.5,970.0],["change",78385.0,650.0],["change",78384.5,16490.0],["change",78382.5,550.0],["delete",78380.5,0.0]],"asks":[["new",78398.0,15830.0],["new",7.84e4,9630.0],["new",78401.5,6.0e3],["new",78402.5,10490.0],["new",78403.0,1.0e4],["new",78403.5,16490.0],["new",78404.0,19770.0],["new",78405.0,16490.0],["new",78405.5,34780.0],["delete",78421.5,0.0],["delete",78422.0,0.0],["delete",78422.5,0.0],["delete",78423.0,0.0],["delete",78423.5,0.0],["delete",78424.0,0.0],["delete",78424.5,0.0],["delete",78425.0,0.0],["delete",78425.5,0.0],["delete",78433.0,0.0],["new",78436.0,6640830.0],["delete",78586.0,0.0],["new",78589.0,7777770.0]],"prev_change_id":41151806805}}}
[2025-04-07 08:29:24.374] [multi_sink] [info] Processing received message: {"jsonrpc":"2.0","method":"subscription","params":{"channel":"book.BTC-PERPETUAL.100ms","data":{"timestamp":1743994765990,"type":"change","change_id":41151807791,"instrument_name":"BTC-PERPETUAL","bids":[["new",78396.0,22580.0],["new",78395.5,2.25e4],["new",78394.5,2.25e4],["new",78394.0,16080.0],["new",78392.5,4230.0],["new",78390.0,430.0],["change",78387.5,470.0],["change",78386.5,10380.0],["change",78386.0,16490.0],["change",78385.5,970.0],["change",78385.0,650.0],["change",78384.5,16490.0],["change",78382.5,550.0],["delete",78380.5,0.0]],"asks":[["new",78398.0,15830.0],["new",7.84e4,9630.0],["new",78401.5,6.0e3],["new",78402.5,10490.0],["new",78403.0,1.0e4],["new",78403.5,16490.0],["new",78404.0,19770.0],["new",78405.0,16490.0],["new",78405.5,34780.0],["delete",78421.5,0.0],["delete",78422.0,0.0],["delete",78422.5,0.0],["delete",78423.0,0.0],["delete",78423.5,0.0],["delete",78424.0,0.0],["delete",78424.5,0.0],["delete",78425.0,0.0],["delete",78425.5,0.0],["delete",78433.0,0.0],["new",78436.0,6640830.0],["delete",78586.0,0.0],["new",78589.0,7777770.0]],"prev_change_id":41151806805}}}
[2025-04-07 08:29:24.715] [multi_sink] [info] 📩 Received: {"jsonrpc":"2.0","method":"subscription","params":{"channel":"book.BTC-PERPETUAL.100ms","data":{"timestamp":1743994766044,"type":"change","change_id":41151807807,"instrument_name":"BTC-PERPETUAL","bids":[["new",78397.0,42070.0],["new",78396.5,2.41e4],["delete",78379.5,0.0],["delete",78378.0,0.0]],"asks":[["new",78397.5,55150.0],["delete",78426.0,0.0]],"prev_change_id":41151807791}}}
[2025-04-07 08:29:24.717] [multi_sink] [info] Processing received message: {"jsonrpc":"2.0","method":"subscription","params":{"channel":"book.BTC-PERPETUAL.100ms","data":{"timestamp":1743994766044,"type":"change","change_id":41151807807,"instrument_name":"BTC-PERPETUAL","bids":[["new",78397.0,42070.0],["new",78396.5,2.41e4],["delete",78379.5,0.0],["delete",78378.0,0.0]],"asks":[["new",78397.5,55150.0],["delete",78426.0,0.0]],"prev_change_id":41151807791}}}
[2025-04-07 08:29:25.037] [multi_sink] [info] 📩 Received: {"jsonrpc":"2.0","method":"subscription","params":{"channel":"book.BTC-PERPETUAL.100ms","data":{"timestamp":1743994766442,"type":"change","change_id":41151808145,"instrument_name":"BTC-PERPETUAL","bids":[["delete",78239.0,0.0],["new",78227.5,78220.0],["delete",78189.0,0.0],["new",78177.5,117250.0]],"asks":[["new",78554.0,78550.0],["delete",78565.0,0.0],["new",78604.0,1.179e5],["delete",78615.0,0.0]],"prev_change_id":41151807807}}}
[2025-04-07 08:29:25.037] [multi_sink] [info] Processing received message: {"jsonrpc":"2.0","method":"subscription","params":{"channel":"book.BTC-PERPETUAL.100ms","data":{"timestamp":1743994766442,"type":"change","change_id":41151808145,"instrument_name":"BTC-PERPETUAL","bids":[["delete",78239.0,0.0],["new",78227.5,78220.0],["delete",78189.0,0.0],["new",78177.5,117250.0]],"asks":[["new",78554.0,78550.0],["delete",78565.0,0.0],["new",78604.0,1.179e5],["delete",78615.0,0.0]],"prev_change_id":41151807807}}}
[2025-04-07 08:29:25.395] [multi_sink] [info] 📩 Received: {"jsonrpc":"2.0","method":"subscription","params":{"channel":"book.BTC-PERPETUAL.100ms","data":{"timestamp":1743994766921,"type":"change","change_id":41151809362,"instrument_name":"BTC-PERPETUAL","bids":[],"asks":[["delete",78554.0,0.0],["new",78565.5,78560.0],["delete",78604.0,0.0],["new",78615.5,117920.0]],"prev_change_id":41151808145}}}
[2025-04-07 08:29:25.398] [multi_sink] [info] Processing received message: {"jsonrpc":"2.0","method":"subscription","params":{"channel":"book.BTC-PERPETUAL.100ms","data":{"timestamp":1743994766921,"type":"change","change_id":41151809362,"instrument_name":"BTC-PERPETUAL","bids":[],"asks":[["delete",78554.0,0.0],["new",78565.5,78560.0],["delete",78604.0,0.0],["new",78615.5,117920.0]],"prev_change_id":41151808145}}}
[2025-04-07 08:29:26.697] [multi_sink] [info] 📩 Received: {"jsonrpc":"2.0","method":"subscription","params":{"channel":"book.BTC-PERPETUAL.100ms","data":{"timestamp":1743994768025,"type":"change","change_id":41151810753,"instrument_name":"BTC-PERPETUAL","bids":[],"asks":[["delete",78565.5,0.0],["delete",78615.5,0.0]],"prev_change_id":41151809362}}}
[2025-04-07 08:29:26.701] [multi_sink] [info] Processing received message: {"jsonrpc":"2.0","method":"subscription","params":{"channel":"book.BTC-PERPETUAL.100ms","data":{"timestamp":1743994768025,"type":"change","change_id":41151810753,"instrument_name":"BTC-PERPETUAL","bids":[],"asks":[["delete",78565.5,0.0],["delete",78615.5,0.0]],"prev_change_id":41151809362}}}
[2025-04-07 08:29:27.021] [multi_sink] [info] 📩 Received: {"jsonrpc":"2.0","method":"subscription","params":{"channel":"book.BTC-PERPETUAL.100ms","data":{"timestamp":1743994768459,"type":"change","change_id":41151810956,"instrument_name":"BTC-PERPETUAL","bids":[],"asks":[["new",78553.5,78550.0],["new",78603.5,1.179e5]],"prev_change_id":41151810753}}}
[2025-04-07 08:29:27.024] [multi_sink] [info] Processing received message: {"jsonrpc":"2.0","method":"subscription","params":{"channel":"book.BTC-PERPETUAL.100ms","data":{"timestamp":1743994768459,"type":"change","change_id":41151810956,"instrument_name":"BTC-PERPETUAL","bids":[],"asks":[["new",78553.5,78550.0],["new",78603.5,1.179e5]],"prev_change_id":41151810753}}}
[2025-04-07 08:29:28.713] [multi_sink] [info] 📩 Received: {"jsonrpc":"2.0","method":"subscription","params":{"channel":"book.BTC-PERPETUAL.100ms","data":{"timestamp":1743994770341,"type":"change","change_id":41151813660,"instrument_name":"BTC-PERPETUAL","bids":[],"asks":[["delete",78397.5,0.0],["new",78415.0,3.0e3]],"prev_change_id":41151810956}}}
[2025-04-07 08:29:28.713] [multi_sink] [info] Processing received message: {"jsonrpc":"2.0","method":"subscription","params":{"channel":"book.BTC-PERPETUAL.100ms","data":{"timestamp":1743994770341,"type":"change","change_id":41151813660,"instrument_name":"BTC-PERPETUAL","bids":[],"asks":[["delete",78397.5,0.0],["new",78415.0,3.0e3]],"prev_change_id":41151810956}}}
[2025-04-07 08:29:29.042] [multi_sink] [info] 📩 Received: {"jsonrpc":"2.0","method":"subscription","params":{"channel":"book.BTC-PERPETUAL.100ms","data":{"timestamp":1743994770645,"type":"change","change_id":41151813819,"instrument_name":"BTC-PERPETUAL","bids":[["delete",78397.0,0.0],["delete",78396.5,0.0],["delete",78396.0,0.0],["delete",78395.5,0.0],["delete",78394.5,0.0],["delete",78394.0,0.0],["delete",78392.5,0.0],["delete",78390.0,0.0],["delete",78387.5,0.0],["change",78382.5,930.0],["new",78381.5,16490.0],["change",78381.0,32980.0],["new",78380.5,550.0],["new",78380.0,970.0],["new",78379.5,17310.0],["new",78377.5,150.0],["new",78377.0,16490.0],["new",78376.5,4.0e4]],"asks":[["delete",78398.0,0.0],["delete",7.84e4,0.0],["delete",78401.5,0.0],["delete",78402.5,0.0],["delete",78403.0,0.0],["delete",78403.5,0.0],["delete",78404.0,0.0],["delete",78405.0,0.0],["change",78406.5,28360.0],["change",78407.0,88650.0],["change",78407.5,25140.0],["new",78410.0,160.0],["change",78412.5,44680.0],["change",78413.5,105480.0],["new",78414.0,5220.0],["new",78414.5,8550.0]],"prev_change_id":41151813660}}}
[2025-04-07 08:29:29.045] [multi_sink] [info] Processing received message: {"jsonrpc":"2.0","method":"subscription","params":{"channel":"book.BTC-PERPETUAL.100ms","data":{"timestamp":1743994770645,"type":"change","change_id":41151813819,"instrument_name":"BTC-PERPETUAL","bids":[["delete",78397.0,0.0],["delete",78396.5,0.0],["delete",78396.0,0.0],["delete",78395.5,0.0],["delete",78394.5,0.0],["delete",78394.0,0.0],["delete",78392.5,0.0],["delete",78390.0,0.0],["delete",78387.5,0.0],["change",78382.5,930.0],["new",78381.5,16490.0],["change",78381.0,32980.0],["new",78380.5,550.0],["new",78380.0,970.0],["new",78379.5,17310.0],["new",78377.5,150.0],["new",78377.0,16490.0],["new",78376.5,4.0e4]],"asks":[["delete",78398.0,0.0],["delete",7.84e4,0.0],["delete",78401.5,0.0],["delete",78402.5,0.0],["delete",78403.0,0.0],["delete",78403.5,0.0],["delete",78404.0,0.0],["delete",78405.0,0.0],["change",78406.5,28360.0],["change",78407.0,88650.0],["change",78407.5,25140.0],["new",78410.0,160.0],["change",78412.5,44680.0],["change",78413.5,105480.0],["new",78414.0,5220.0],["new",78414.5,8550.0]],"prev_change_id":41151813660}}}
[2025-04-07 08:29:29.371] [multi_sink] [info] 📩 Received: {"jsonrpc":"2.0","method":"subscription","params":{"channel":"book.BTC-PERPETUAL.100ms","data":{"timestamp":1743994770997,"type":"change","change_id":41151814912,"instrument_name":"BTC-PERPETUAL","bids":[["new",78390.5,390.0],["new",78390.0,90.0],["new",78388.0,430.0],["new",78387.5,1250.0],["new",78387.0,3840.0],["delete",78386.5,0.0],["delete",78386.0,0.0],["change",78385.5,470.0],["change",78385.0,140.0],["delete",78384.5,0.0],["change",78384.0,9630.0],["delete",78383.5,0.0],["change",78383.0,510.0],["change",78382.5,380.0],["delete",78227.5,0.0],["new",78213.5,78210.0],["delete",78177.5,0.0],["new",78163.5,117240.0]],"asks":[["new",7.84e4,160.0],["new",78401.5,2.25e4],["new",78402.0,16490.0],["new",78403.0,16490.0],["new",78403.5,33480.0],["new",78404.0,79560.0],["new",78405.0,1.0e4],["change",78405.5,34780.0],["new",78406.0,3840.0],["change",78406.5,200.0],["change",78407.0,83160.0],["change",78407.5,24620.0],["delete",78408.0,0.0],["delete",78409.0,0.0],["delete",78411.0,0.0],["delete",78411.5,0.0],["delete",78412.0,0.0],["new",78543.5,78540.0],["delete",78553.5,0.0],["new",78593.5,117890.0],["delete",78603.5,0.0]],"prev_change_id":41151813819}}}
[2025-04-07 08:29:29.372] [multi_sink] [info] Processing received message: {"jsonrpc":"2.0","method":"subscription","params":{"channel":"book.BTC-PERPETUAL.100ms","data":{"timestamp":1743994770997,"type":"change","change_id":41151814912,"instrument_name":"BTC-PERPETUAL","bids":[["new",78390.5,390.0],["new",78390.0,90.0],["new",78388.0,430.0],["new",78387.5,1250.0],["new",78387.0,3840.0],["delete",78386.5,0.0],["delete",78386.0,0.0],["change",78385.5,470.0],["change",78385.0,140.0],["delete",78384.5,0.0],["change",78384.0,9630.0],["delete",78383.5,0.0],["change",78383.0,510.0],["change",78382.5,380.0],["delete",78227.5,0.0],["new",78213.5,78210.0],["delete",78177.5,0.0],["new",78163.5,117240.0]],"asks":[["new",7.84e4,160.0],["new",78401.5,2.25e4],["new",78402.0,16490.0],["new",78403.0,16490.0],["new",78403.5,33480.0],["new",78404.0,79560.0],["new",78405.0,1.0e4],["change",78405.5,34780.0],["new",78406.0,3840.0],["change",78406.5,200.0],["change",78407.0,83160.0],["change",78407.5,24620.0],["delete",78408.0,0.0],["delete",78409.0,0.0],["delete",78411.0,0.0],["delete",78411.5,0.0],["delete",78412.0,0.0],["new",78543.5,78540.0],["delete",78553.5,0.0],["new",78593.5,117890.0],["delete",78603.5,0.0]],"prev_change_id":41151813819}}}
[2025-04-07 08:29:29.701] [multi_sink] [info] 📩 Received: {"jsonrpc":"2.0","method":"subscription","params":{"channel":"book.BTC-PERPETUAL.100ms","data":{"timestamp":1743994771070,"type":"change","change_id":41151814943,"instrument_name":"BTC-PERPETUAL","bids":[["new",78397.0,10380.0],["new",78396.5,1.6e3],["delete",78382.0,0.0],["change",78381.0,16490.0]],"asks":[["new",78397.5,173730.0],["new",78398.0,36440.0],["change",78412.5,17740.0],["change",78413.5,34780.0]],"prev_change_id":41151814912}}}
[2025-04-07 08:29:29.703] [multi_sink] [info] Processing received message: {"jsonrpc":"2.0","method":"subscription","params":{"channel":"book.BTC-PERPETUAL.100ms","data":{"timestamp":1743994771070,"type":"change","change_id":41151814943,"instrument_name":"BTC-PERPETUAL","bids":[["new",78397.0,10380.0],["new",78396.5,1.6e3],["delete",78382.0,0.0],["change",78381.0,16490.0]],"asks":[["new",78397.5,173730.0],["new",78398.0,36440.0],["change",78412.5,17740.0],["change",78413.5,34780.0]],"prev_change_id":41151814912}}}
[2025-04-07 08:29:30.859] [multi_sink] [info] 📩 Received: {"jsonrpc":"2.0","method":"subscription","params":{"channel":"book.BTC-PERPETUAL.100ms","data":{"timestamp":1743994772491,"type":"change","change_id":41151816822,"instrument_name":"BTC-PERPETUAL","bids":[["delete",78213.5,0.0],["new",78203.0,7.82e4]],"asks":[],"prev_change_id":41151814943}}}
[2025-04-07 08:29:30.860] [multi_sink] [info] Processing received message: {"jsonrpc":"2.0","method":"subscription","params":{"channel":"book.BTC-PERPETUAL.100ms","data":{"timestamp":1743994772491,"type":"change","change_id":41151816822,"instrument_name":"BTC-PERPETUAL","bids":[["delete",78213.5,0.0],["new",78203.0,7.82e4]],"asks":[],"prev_change_id":41151814943}}}
[2025-04-07 08:29:31.196] [multi_sink] [info] 📩 Received: {"jsonrpc":"2.0","method":"subscription","params":{"channel":"book.BTC-PERPETUAL.100ms","data":{"timestamp":1743994772802,"type":"change","change_id":41151817844,"instrument_name":"BTC-PERPETUAL","bids":[["delete",78163.5,0.0],["new",78153.0,117220.0]],"asks":[["new",78531.0,78530.0],["delete",78543.5,0.0],["new",78581.0,117870.0],["delete",78593.5,0.0]],"prev_change_id":41151816822}}}
[2025-04-07 08:29:31.200] [multi_sink] [info] Processing received message: {"jsonrpc":"2.0","method":"subscription","params":{"channel":"book.BTC-PERPETUAL.100ms","data":{"timestamp":1743994772802,"type":"change","change_id":41151817844,"instrument_name":"BTC-PERPETUAL","bids":[["delete",78163.5,0.0],["new",78153.0,117220.0]],"asks":[["new",78531.0,78530.0],["delete",78543.5,0.0],["new",78581.0,117870.0],["delete",78593.5,0.0]],"prev_change_id":41151816822}}}
[2025-04-07 08:29:31.553] [multi_sink] [info] 📩 Received: {"jsonrpc":"2.0","method":"subscription","params":{"channel":"book.BTC-PERPETUAL.100ms","data":{"timestamp":1743994772855,"type":"change","change_id":41151817974,"instrument_name":"BTC-PERPETUAL","bids":[["delete",78358.5,0.0],["new",78352.0,7825720.0],["delete",78205.5,0.0],["new",78199.0,8000580.0]],"asks":[],"prev_change_id":41151817844}}}
[2025-04-07 08:29:31.555] [multi_sink] [info] Processing received message: {"jsonrpc":"2.0","method":"subscription","params":{"channel":"book.BTC-PERPETUAL.100ms","data":{"timestamp":1743994772855,"type":"change","change_id":41151817974,"instrument_name":"BTC-PERPETUAL","bids":[["delete",78358.5,0.0],["new",78352.0,7825720.0],["delete",78205.5,0.0],["new",78199.0,8000580.0]],"asks":[],"prev_change_id":41151817844}}}
[2025-04-07 08:29:31.876] [multi_sink] [info] 📩 Received: {"jsonrpc":"2.0","method":"subscription","params":{"channel":"book.BTC-PERPETUAL.100ms","data":{"timestamp":1743994773185,"type":"change","change_id":41151818053,"instrument_name":"BTC-PERPETUAL","bids":[],"asks":[["new",78429.5,6640830.0],["delete",78436.0,0.0],["new",78582.5,7777770.0],["delete",78589.0,0.0]],"prev_change_id":41151817974}}}
[2025-04-07 08:29:31.881] [multi_sink] [info] Processing received message: {"jsonrpc":"2.0","method":"subscription","params":{"channel":"book.BTC-PERPETUAL.100ms","data":{"timestamp":1743994773185,"type":"change","change_id":41151818053,"instrument_name":"BTC-PERPETUAL","bids":[],"asks":[["new",78429.5,6640830.0],["delete",78436.0,0.0],["new",78582.5,7777770.0],["delete",78589.0,0.0]],"prev_change_id":41151817974}}}
[2025-04-07 08:29:33.398] [multi_sink] [info] 📩 Received: {"jsonrpc":"2.0","method":"subscription","params":{"channel":"book.BTC-PERPETUAL.100ms","data":{"timestamp":1743994775009,"type":"change","change_id":41151820835,"instrument_name":"BTC-PERPETUAL","bids":[],"asks":[["delete",78531.0,0.0],["new",78542.5,78540.0],["delete",78581.0,0.0],["new",78592.5,117880.0]],"prev_change_id":41151818053}}}
[2025-04-07 08:29:33.403] [multi_sink] [info] Processing received message: {"jsonrpc":"2.0","method":"subscription","params":{"channel":"book.BTC-PERPETUAL.100ms","data":{"timestamp":1743994775009,"type":"change","change_id":41151820835,"instrument_name":"BTC-PERPETUAL","bids":[],"asks":[["delete",78531.0,0.0],["new",78542.5,78540.0],["delete",78581.0,0.0],["new",78592.5,117880.0]],"prev_change_id":41151818053}}}
[2025-04-07 08:29:33.750] [multi_sink] [info] 📩 Received: {"jsonrpc":"2.0","method":"subscription","params":{"channel":"book.BTC-PERPETUAL.100ms","data":{"timestamp":1743994775342,"type":"change","change_id":41151821050,"instrument_name":"BTC-PERPETUAL","bids":[["delete",78397.0,0.0],["new",78360.0,35180.0],["delete",78203.0,0.0],["delete",78153.0,0.0]],"asks":[["delete",78397.5,0.0],["change",78404.0,126510.0],["delete",78542.5,0.0],["new",78554.0,78550.0],["delete",78592.5,0.0],["new",78604.0,1.179e5]],"prev_change_id":41151820835}}}
[2025-04-07 08:29:33.755] [multi_sink] [info] Processing received message: {"jsonrpc":"2.0","method":"subscription","params":{"channel":"book.BTC-PERPETUAL.100ms","data":{"timestamp":1743994775342,"type":"change","change_id":41151821050,"instrument_name":"BTC-PERPETUAL","bids":[["delete",78397.0,0.0],["new",78360.0,35180.0],["delete",78203.0,0.0],["delete",78153.0,0.0]],"asks":[["delete",78397.5,0.0],["change",78404.0,126510.0],["delete",78542.5,0.0],["new",78554.0,78550.0],["delete",78592.5,0.0],["new",78604.0,1.179e5]],"prev_change_id":41151820835}}}
[2025-04-07 08:29:34.063] [multi_sink] [info] 📩 Received: {"jsonrpc":"2.0","method":"subscription","params":{"channel":"book.BTC-PERPETUAL.100ms","data":{"timestamp":1743994775668,"type":"change","change_id":41151821296,"instrument_name":"BTC-PERPETUAL","bids":[["delete",78396.5,0.0],["delete",78390.5,0.0],["delete",78390.0,0.0],["delete",78388.0,0.0],["delete",78387.5,0.0],["delete",78387.0,0.0],["delete",78385.5,0.0],["delete",78385.0,0.0],["delete",78384.0,0.0],["new",78368.5,56980.0],["new",78368.0,46680.0],["new",78367.5,380.0],["new",78366.5,9460.0],["new",78365.5,1.0e3],["new",78364.5,5220.0],["new",78364.0,30780.0],["new",78362.5,3030.0],["new",78360.5,4.0e4]],"asks":[["delete",78398.0,0.0],["new",78398.5,500.0],["new",78399.0,2110.0],["new",78399.5,16490.0],["change",7.84e4,670.0],["new",78401.0,13750.0],["change",78401.5,36510.0],["delete",78402.0,0.0],["new",78402.5,29370.0],["change",78403.0,81640.0],["change",78403.5,5220.0],["change",78404.0,46950.0],["delete",78405.0,0.0],["delete",78405.5,0.0]],"prev_change_id":41151821050}}}
[2025-04-07 08:29:34.065] [multi_sink] [info] Processing received message: {"jsonrpc":"2.0","method":"subscription","params":{"channel":"book.BTC-PERPETUAL.100ms","data":{"timestamp":1743994775668,"type":"change","change_id":41151821296,"instrument_name":"BTC-PERPETUAL","bids":[["delete",78396.5,0.0],["delete",78390.5,0.0],["delete",78390.0,0.0],["delete",78388.0,0.0],["delete",78387.5,0.0],["delete",78387.0,0.0],["delete",78385.5,0.0],["delete",78385.0,0.0],["delete",78384.0,0.0],["new",78368.5,56980.0],["new",78368.0,46680.0],["new",78367.5,380.0],["new",78366.5,9460.0],["new",78365.5,1.0e3],["new",78364.5,5220.0],["new",78364.0,30780.0],["new",78362.5,3030.0],["new",78360.5,4.0e4]],"asks":[["delete",78398.0,0.0],["new",78398.5,500.0],["new",78399.0,2110.0],["new",78399.5,16490.0],["change",7.84e4,670.0],["new",78401.0,13750.0],["change",78401.5,36510.0],["delete",78402.0,0.0],["new",78402.5,29370.0],["change",78403.0,81640.0],["change",78403.5,5220.0],["change",78404.0,46950.0],["delete",78405.0,0.0],["delete",78405.5,0.0]],"prev_change_id":41151821050}}}
[2025-04-07 08:29:34.388] [multi_sink] [info] 📩 Received: {"jsonrpc":"2.0","method":"subscription","params":{"channel":"book.BTC-PERPETUAL.100ms","data":{"timestamp":1743994776001,"type":"change","change_id":41151822321,"instrument_name":"BTC-PERPETUAL","bids":[["change",78383.0,650.0],["change",78382.5,380.0],["change",78381.5,200.0],["delete",78381.0,0.0],["delete",78380.5,0.0],["delete",78380.0,0.0],["delete",78379.5,0.0],["new",78379.0,220.0],["delete",78377.5,0.0],["change",78377.0,1.2e4],["change",78376.5,8.0e4],["new",78375.5,1260.0],["new",78375.0,4210.0],["new",78369.0,59670.0]],"asks":[["new",78385.0,2840.0],["new",78385.5,9460.0],["new",78392.0,2050.0],["new",78392.5,6390.0],["new",78394.0,480.0],["new",78395.0,430.0],["new",78396.5,10090.0],["new",78397.5,850.0],["new",78398.0,10.0],["delete",78406.0,0.0],["delete",78406.5,0.0],["delete",78407.0,0.0],["delete",78407.5,0.0],["delete",78410.0,0.0],["delete",78412.5,0.0],["delete",78413.5,0.0],["delete",78414.0,0.0],["delete",78414.5,0.0]],"prev_change_id":41151821296}}}
[2025-04-07 08:29:34.390] [multi_sink] [info] Processing received message: {"jsonrpc":"2.0","method":"subscription","params":{"channel":"book.BTC-PERPETUAL.100ms","data":{"timestamp":1743994776001,"type":"change","change_id":41151822321,"instrument_name":"BTC-PERPETUAL","bids":[["change",78383.0,650.0],["change",78382.5,380.0],["change",78381.5,200.0],["delete",78381.0,0.0],["delete",78380.5,0.0],["delete",78380.0,0.0],["delete",78379.5,0.0],["new",78379.0,220.0],["delete",78377.5,0.0],["change",78377.0,1.2e4],["change",78376.5,8.0e4],["new",78375.5,1260.0],["new",78375.0,4210.0],["new",78369.0,59670.0]],"asks":[["new",78385.0,2840.0],["new",78385.5,9460.0],["new",78392.0,2050.0],["new",78392.5,6390.0],["new",78394.0,480.0],["new",78395.0,430.0],["new",78396.5,10090.0],["new",78397.5,850.0],["new",78398.0,10.0],["delete",78406.0,0.0],["delete",78406.5,0.0],["delete",78407.0,0.0],["delete",78407.5,0.0],["delete",78410.0,0.0],["delete",78412.5,0.0],["delete",78413.5,0.0],["delete",78414.0,0.0],["delete",78414.5,0.0]],"prev_change_id":41151821296}}}
[2025-04-07 08:29:34.728] [multi_sink] [info] 📩 Received: {"jsonrpc":"2.0","method":"subscription","params":{"channel":"book.BTC-PERPETUAL.100ms","data":{"timestamp":1743994776037,"type":"change","change_id":41151822343,"instrument_name":"BTC-PERPETUAL","bids":[["new",78384.0,8830.0],["change",78376.5,4.0e4]],"asks":[["new",78384.5,3060.0],["delete",78415.0,0.0]],"prev_change_id":41151822321}}}
[2025-04-07 08:29:34.732] [multi_sink] [info] Processing received message: {"jsonrpc":"2.0","method":"subscription","params":{"channel":"book.BTC-PERPETUAL.100ms","data":{"timestamp":1743994776037,"type":"change","change_id":41151822343,"instrument_name":"BTC-PERPETUAL","bids":[["new",78384.0,8830.0],["change",78376.5,4.0e4]],"asks":[["new",78384.5,3060.0],["delete",78415.0,0.0]],"prev_change_id":41151822321}}}
[2025-04-07 08:29:35.742] [multi_sink] [info] 📩 Received: {"jsonrpc":"2.0","method":"subscription","params":{"channel":"book.BTC-PERPETUAL.100ms","data":{"timestamp":1743994777071,"type":"change","change_id":41151823943,"instrument_name":"BTC-PERPETUAL","bids":[["new",78223.5,78220.0],["new",78173.5,117260.0]],"asks":[],"prev_change_id":41151822343}}}
[2025-04-07 08:29:35.743] [multi_sink] [info] Processing received message: {"jsonrpc":"2.0","method":"subscription","params":{"channel":"book.BTC-PERPETUAL.100ms","data":{"timestamp":1743994777071,"type":"change","change_id":41151823943,"instrument_name":"BTC-PERPETUAL","bids":[["new",78223.5,78220.0],["new",78173.5,117260.0]],"asks":[],"prev_change_id":41151822343}}}
[2025-04-07 08:29:38.515] [multi_sink] [info] 📩 Received: {"jsonrpc":"2.0","method":"subscription","params":{"channel":"book.BTC-PERPETUAL.100ms","data":{"timestamp":1743994780057,"type":"change","change_id":41151828115,"instrument_name":"BTC-PERPETUAL","bids":[["delete",78352.0,0.0],["new",78346.5,7825720.0],["delete",78199.0,0.0],["new",78193.5,8000580.0]],"asks":[],"prev_change_id":41151823943}}}
[2025-04-07 08:29:38.519] [multi_sink] [info] Processing received message: {"jsonrpc":"2.0","method":"subscription","params":{"channel":"book.BTC-PERPETUAL.100ms","data":{"timestamp":1743994780057,"type":"change","change_id":41151828115,"instrument_name":"BTC-PERPETUAL","bids":[["delete",78352.0,0.0],["new",78346.5,7825720.0],["delete",78199.0,0.0],["new",78193.5,8000580.0]],"asks":[],"prev_change_id":41151823943}}}
[2025-04-07 08:29:38.765] [multi_sink] [info] 📩 Received: {"jsonrpc":"2.0","method":"subscription","params":{"channel":"book.BTC-PERPETUAL.100ms","data":{"timestamp":1743994780386,"type":"change","change_id":41151828321,"instrument_name":"BTC-PERPETUAL","bids":[["delete",78384.0,0.0],["delete",78383.0,0.0],["change",78368.0,8.88e4],["change",78367.5,760.0]],"asks":[["delete",78384.5,0.0],["delete",78385.0,0.0],["change",78399.5,99650.0],["change",7.84e4,1190.0],["new",78424.0,6640830.0],["delete",78429.5,0.0],["new",78577.0,7777770.0],["delete",78582.5,0.0]],"prev_change_id":41151828115}}}
[2025-04-07 08:29:38.766] [multi_sink] [info] Processing received message: {"jsonrpc":"2.0","method":"subscription","params":{"channel":"book.BTC-PERPETUAL.100ms","data":{"timestamp":1743994780386,"type":"change","change_id":41151828321,"instrument_name":"BTC-PERPETUAL","bids":[["delete",78384.0,0.0],["delete",78383.0,0.0],["change",78368.0,8.88e4],["change",78367.5,760.0]],"asks":[["delete",78384.5,0.0],["delete",78385.0,0.0],["change",78399.5,99650.0],["change",7.84e4,1190.0],["new",78424.0,6640830.0],["delete",78429.5,0.0],["new",78577.0,7777770.0],["delete",78582.5,0.0]],"prev_change_id":41151828115}}}
[2025-04-07 08:29:39.114] [multi_sink] [info] 📩 Received: {"jsonrpc":"2.0","method":"subscription","params":{"channel":"book.BTC-PERPETUAL.100ms","data":{"timestamp":1743994780702,"type":"change","change_id":41151828631,"instrument_name":"BTC-PERPETUAL","bids":[["delete",78382.5,0.0],["delete",78381.5,0.0],["delete",78379.0,0.0],["delete",78377.0,0.0],["delete",78376.5,0.0],["delete",78375.5,0.0],["delete",78375.0,0.0],["new",78374.0,16980.0],["new",78373.5,1.0e3],["new",78373.0,160.0],["new",78372.0,17490.0],["new",78371.5,3840.0],["new",78371.0,27310.0],["new",78370.5,170.0],["change",78369.0,21710.0],["change",78368.5,49460.0]],"asks":[["delete",78385.5,0.0],["delete",78392.0,0.0],["change",78392.5,16490.0],["delete",78394.0,0.0],["new",78394.5,44480.0],["change",78395.0,3840.0],["new",78396.0,27570.0],["change",78396.5,1.0e4],["new",78397.0,5.5e3],["change",78397.5,380.0],["change",78398.0,10.0],["change",78398.5,390.0]],"prev_change_id":41151828321}}}
[2025-04-07 08:29:39.118] [multi_sink] [info] Processing received message: {"jsonrpc":"2.0","method":"subscription","params":{"channel":"book.BTC-PERPETUAL.100ms","data":{"timestamp":1743994780702,"type":"change","change_id":41151828631,"instrument_name":"BTC-PERPETUAL","bids":[["delete",78382.5,0.0],["delete",78381.5,0.0],["delete",78379.0,0.0],["delete",78377.0,0.0],["delete",78376.5,0.0],["delete",78375.5,0.0],["delete",78375.0,0.0],["new",78374.0,16980.0],["new",78373.5,1.0e3],["new",78373.0,160.0],["new",78372.0,17490.0],["new",78371.5,3840.0],["new",78371.0,27310.0],["new",78370.5,170.0],["change",78369.0,21710.0],["change",78368.5,49460.0]],"asks":[["delete",78385.5,0.0],["delete",78392.0,0.0],["change",78392.5,16490.0],["delete",78394.0,0.0],["new",78394.5,44480.0],["change",78395.0,3840.0],["new",78396.0,27570.0],["change",78396.5,1.0e4],["new",78397.0,5.5e3],["change",78397.5,380.0],["change",78398.0,10.0],["change",78398.5,390.0]],"prev_change_id":41151828321}}}
[2025-04-07 08:29:39.524] [multi_sink] [info] 📩 Received: {"jsonrpc":"2.0","method":"subscription","params":{"channel":"book.BTC-PERPETUAL.100ms","data":{"timestamp":1743994781031,"type":"change","change_id":41151829578,"instrument_name":"BTC-PERPETUAL","bids":[["new",78385.0,23740.0],["new",78384.0,1180.0],["new",78382.5,380.0],["new",78381.0,6720.0],["new",78380.5,2.24e4],["new",78380.0,1.2e4],["new",78376.5,4.0e4],["new",78375.0,370.0],["new",78374.5,10690.0],["change",78368.0,42120.0],["change",78367.5,380.0],["delete",78366.5,0.0],["delete",78365.5,0.0],["delete",78364.5,0.0],["delete",78364.0,0.0],["delete",78362.5,0.0],["delete",78360.5,0.0],["delete",78360.0,0.0]],"asks":[["new",78385.5,81510.0],["new",78386.5,1.0e4],["new",78387.0,6430.0],["new",78387.5,1.41e4],["new",78388.5,6.0e3],["new",78389.0,460.0],["new",78390.0,380.0],["new",78391.5,490.0],["new",78392.0,19690.0],["delete",78399.0,0.0],["change",78399.5,83160.0],["change",7.84e4,520.0],["delete",78401.0,0.0],["delete",78401.5,0.0],["delete",78402.5,0.0],["delete",78403.0,0.0],["delete",78403.5,0.0],["delete",78404.0,0.0],["new",78544.0,78540.0],["delete",78554.0,0.0],["new",78594.0,117890.0],["delete",78604.0,0.0]],"prev_change_id":41151828631}}}
[2025-04-07 08:29:39.526] [multi_sink] [info] Processing received message: {"jsonrpc":"2.0","method":"subscription","params":{"channel":"book.BTC-PERPETUAL.100ms","data":{"timestamp":1743994781031,"type":"change","change_id":41151829578,"instrument_name":"BTC-PERPETUAL","bids":[["new",78385.0,23740.0],["new",78384.0,1180.0],["new",78382.5,380.0],["new",78381.0,6720.0],["new",78380.5,2.24e4],["new",78380.0,1.2e4],["new",78376.5,4.0e4],["new",78375.0,370.0],["new",78374.5,10690.0],["change",78368.0,42120.0],["change",78367.5,380.0],["delete",78366.5,0.0],["delete",78365.5,0.0],["delete",78364.5,0.0],["delete",78364.0,0.0],["delete",78362.5,0.0],["delete",78360.5,0.0],["delete",78360.0,0.0]],"asks":[["new",78385.5,81510.0],["new",78386.5,1.0e4],["new",78387.0,6430.0],["new",78387.5,1.41e4],["new",78388.5,6.0e3],["new",78389.0,460.0],["new",78390.0,380.0],["new",78391.5,490.0],["new",78392.0,19690.0],["delete",78399.0,0.0],["change",78399.5,83160.0],["change",7.84e4,520.0],["delete",78401.0,0.0],["delete",78401.5,0.0],["delete",78402.5,0.0],["delete",78403.0,0.0],["delete",78403.5,0.0],["delete",78404.0,0.0],["new",78544.0,78540.0],["delete",78554.0,0.0],["new",78594.0,117890.0],["delete",78604.0,0.0]],"prev_change_id":41151828631}}}
[2025-04-07 08:29:40.548] [multi_sink] [info] 📩 Received: {"jsonrpc":"2.0","method":"subscription","params":{"channel":"book.BTC-PERPETUAL.100ms","data":{"timestamp":1743994781993,"type":"change","change_id":41151831135,"instrument_name":"BTC-PERPETUAL","bids":[],"asks":[["delete",78544.0,0.0],["new",78555.5,78550.0],["delete",78594.0,0.0],["new",78605.5,1.179e5]],"prev_change_id":41151829578}}}
[2025-04-07 08:29:40.550] [multi_sink] [info] Processing received message: {"jsonrpc":"2.0","method":"subscription","params":{"channel":"book.BTC-PERPETUAL.100ms","data":{"timestamp":1743994781993,"type":"change","change_id":41151831135,"instrument_name":"BTC-PERPETUAL","bids":[],"asks":[["delete",78544.0,0.0],["new",78555.5,78550.0],["delete",78594.0,0.0],["new",78605.5,1.179e5]],"prev_change_id":41151829578}}}
[2025-04-07 08:29:43.799] [multi_sink] [info] 📩 Received: {"jsonrpc":"2.0","method":"subscription","params":{"channel":"book.BTC-PERPETUAL.100ms","data":{"timestamp":1743994785422,"type":"change","change_id":41151835484,"instrument_name":"BTC-PERPETUAL","bids":[["delete",78385.0,0.0],["delete",78384.0,0.0],["delete",78382.5,0.0],["new",78370.0,150.0],["change",78369.0,26930.0],["change",78368.5,89460.0]],"asks":[["delete",78385.5,0.0],["delete",78386.5,0.0],["delete",78387.0,0.0],["new",78405.0,27990.0],["new",78406.5,3840.0],["new",78407.0,5.5e3]],"prev_change_id":41151831135}}}
[2025-04-07 08:29:43.800] [multi_sink] [info] Processing received message: {"jsonrpc":"2.0","method":"subscription","params":{"channel":"book.BTC-PERPETUAL.100ms","data":{"timestamp":1743994785422,"type":"change","change_id":41151835484,"instrument_name":"BTC-PERPETUAL","bids":[["delete",78385.0,0.0],["delete",78384.0,0.0],["delete",78382.5,0.0],["new",78370.0,150.0],["change",78369.0,26930.0],["change",78368.5,89460.0]],"asks":[["delete",78385.5,0.0],["delete",78386.5,0.0],["delete",78387.0,0.0],["new",78405.0,27990.0],["new",78406.5,3840.0],["new",78407.0,5.5e3]],"prev_change_id":41151831135}}}
[2025-04-07 08:29:44.131] [multi_sink] [info] 📩 Received: {"jsonrpc":"2.0","method":"subscription","params":{"channel":"book.BTC-PERPETUAL.100ms","data":{"timestamp":1743994785744,"type":"change","change_id":41151835796,"instrument_name":"BTC-PERPETUAL","bids":[["delete",78381.0,0.0],["delete",78380.5,0.0],["change",78380.0,29910.0],["new",78378.0,20190.0],["new",78377.5,150.0],["new",78377.0,60750.0],["change",78376.5,4.0e4],["new",78375.5,200.0],["change",78375.0,370.0],["delete",78374.5,0.0],["delete",78374.0,0.0],["delete",78373.5,0.0],["change",78373.0,220.0],["change",78371.0,94850.0]],"asks":[["delete",78387.5,0.0],["delete",78388.5,0.0],["delete",78389.0,0.0],["delete",78390.0,0.0],["delete",78391.5,0.0],["delete",78392.0,0.0],["delete",78392.5,0.0],["delete",78394.5,0.0],["delete",78395.0,0.0],["change",78398.0,20.0],["new",78399.0,490.0],["change",78399.5,88430.0],["change",7.84e4,18080.0],["new",78400.5,2950.0],["new",78402.0,16490.0],["new",78402.5,25320.0],["new",78403.0,81640.0],["new",78404.0,16590.0]],"prev_change_id":41151835484}}}
[2025-04-07 08:29:44.135] [multi_sink] [info] Processing received message: {"jsonrpc":"2.0","method":"subscription","params":{"channel":"book.BTC-PERPETUAL.100ms","data":{"timestamp":1743994785744,"type":"change","change_id":41151835796,"instrument_name":"BTC-PERPETUAL","bids":[["delete",78381.0,0.0],["delete",78380.5,0.0],["change",78380.0,29910.0],["new",78378.0,20190.0],["new",78377.5,150.0],["new",78377.0,60750.0],["change",78376.5,4.0e4],["new",78375.5,200.0],["change",78375.0,370.0],["delete",78374.5,0.0],["delete",78374.0,0.0],["delete",78373.5,0.0],["change",78373.0,220.0],["change",78371.0,94850.0]],"asks":[["delete",78387.5,0.0],["delete",78388.5,0.0],["delete",78389.0,0.0],["delete",78390.0,0.0],["delete",78391.5,0.0],["delete",78392.0,0.0],["delete",78392.5,0.0],["delete",78394.5,0.0],["delete",78395.0,0.0],["change",78398.0,20.0],["new",78399.0,490.0],["change",78399.5,88430.0],["change",7.84e4,18080.0],["new",78400.5,2950.0],["new",78402.0,16490.0],["new",78402.5,25320.0],["new",78403.0,81640.0],["new",78404.0,16590.0]],"prev_change_id":41151835484}}}
[2025-04-07 08:29:44.472] [multi_sink] [info] 📩 Received: {"jsonrpc":"2.0","method":"subscription","params":{"channel":"book.BTC-PERPETUAL.100ms","data":{"timestamp":1743994786042,"type":"change","change_id":41151836739,"instrument_name":"BTC-PERPETUAL","bids":[["new",78385.0,1.031e5],["new",78384.5,86450.0],["new",78384.0,1180.0],["new",78383.0,17140.0],["new",78382.5,380.0],["new",78382.0,16490.0],["new",78381.0,2.24e4],["new",78380.5,22570.0],["delete",78372.0,0.0],["delete",78371.5,0.0],["change",78371.0,67540.0],["delete",78370.5,0.0],["change",78369.0,5220.0],["change",78368.5,4.0e4],["delete",78368.0,0.0],["delete",78367.5,0.0]],"asks":[["new",78385.5,140.0],["new",78389.0,460.0],["new",78390.0,770.0],["new",78392.5,430.0],["new",78394.5,2980.0],["new",78395.0,470.0],["change",78396.0,9460.0],["delete",78396.5,0.0],["delete",78397.0,0.0],["change",78397.5,890.0],["change",78398.0,10.0],["delete",78398.5,0.0],["change",78399.5,5270.0],["change",7.84e4,17560.0]],"prev_change_id":41151835796}}}
[2025-04-07 08:29:44.472] [multi_sink] [info] Processing received message: {"jsonrpc":"2.0","method":"subscription","params":{"channel":"book.BTC-PERPETUAL.100ms","data":{"timestamp":1743994786042,"type":"change","change_id":41151836739,"instrument_name":"BTC-PERPETUAL","bids":[["new",78385.0,1.031e5],["new",78384.5,86450.0],["new",78384.0,1180.0],["new",78383.0,17140.0],["new",78382.5,380.0],["new",78382.0,16490.0],["new",78381.0,2.24e4],["new",78380.5,22570.0],["delete",78372.0,0.0],["delete",78371.5,0.0],["change",78371.0,67540.0],["delete",78370.5,0.0],["change",78369.0,5220.0],["change",78368.5,4.0e4],["delete",78368.0,0.0],["delete",78367.5,0.0]],"asks":[["new",78385.5,140.0],["new",78389.0,460.0],["new",78390.0,770.0],["new",78392.5,430.0],["new",78394.5,2980.0],["new",78395.0,470.0],["change",78396.0,9460.0],["delete",78396.5,0.0],["delete",78397.0,0.0],["change",78397.5,890.0],["change",78398.0,10.0],["delete",78398.5,0.0],["change",78399.5,5270.0],["change",7.84e4,17560.0]],"prev_change_id":41151835796}}}
[2025-04-07 08:29:48.846] [multi_sink] [info] 📩 Received: {"jsonrpc":"2.0","method":"subscription","params":{"channel":"book.BTC-PERPETUAL.100ms","data":{"timestamp":1743994790444,"type":"change","change_id":41151842609,"instrument_name":"BTC-PERPETUAL","bids":[["delete",78385.0,0.0],["delete",78384.5,0.0],["delete",78384.0,0.0],["change",78373.0,420.0],["new",78372.5,5220.0],["change",78371.0,94850.0]],"asks":[["delete",78385.5,0.0],["delete",78389.0,0.0],["delete",78390.0,0.0],["new",78410.0,11010.0],["new",78411.5,3840.0],["new",78412.0,74080.0]],"prev_change_id":41151836739}}}
[2025-04-07 08:29:48.850] [multi_sink] [info] Processing received message: {"jsonrpc":"2.0","method":"subscription","params":{"channel":"book.BTC-PERPETUAL.100ms","data":{"timestamp":1743994790444,"type":"change","change_id":41151842609,"instrument_name":"BTC-PERPETUAL","bids":[["delete",78385.0,0.0],["delete",78384.5,0.0],["delete",78384.0,0.0],["change",78373.0,420.0],["new",78372.5,5220.0],["change",78371.0,94850.0]],"asks":[["delete",78385.5,0.0],["delete",78389.0,0.0],["delete",78390.0,0.0],["new",78410.0,11010.0],["new",78411.5,3840.0],["new",78412.0,74080.0]],"prev_change_id":41151836739}}}
[2025-04-07 08:29:49.173] [multi_sink] [info] 📩 Received: {"jsonrpc":"2.0","method":"subscription","params":{"channel":"book.BTC-PERPETUAL.100ms","data":{"timestamp":1743994790788,"type":"change","change_id":41151842924,"instrument_name":"BTC-PERPETUAL","bids":[["change",78383.0,3840.0],["delete",78382.5,0.0],["delete",78382.0,0.0],["delete",78381.0,0.0],["delete",78380.5,0.0],["delete",78380.0,0.0],["new",78379.5,9460.0],["new",78378.5,1.0e3],["change",78378.0,47650.0],["change",78377.5,4.0e4],["change",78377.0,94720.0],["change",78375.5,49690.0],["new",78374.0,1.6e5]],"asks":[["delete",78392.5,0.0],["delete",78394.5,0.0],["delete",78395.0,0.0],["delete",78396.0,0.0],["delete",78397.5,0.0],["delete",78398.0,0.0],["delete",78399.0,0.0],["delete",78399.5,0.0],["new",78401.0,510.0],["change",78402.5,26150.0],["change",78403.0,173280.0],["new",78403.5,550.0],["new",78407.5,850.0],["new",78408.0,21220.0],["new",78409.0,25020.0],["new",78409.5,16490.0]],"prev_change_id":41151842609}}}
[2025-04-07 08:29:49.176] [multi_sink] [info] Processing received message: {"jsonrpc":"2.0","method":"subscription","params":{"channel":"book.BTC-PERPETUAL.100ms","data":{"timestamp":1743994790788,"type":"change","change_id":41151842924,"instrument_name":"BTC-PERPETUAL","bids":[["change",78383.0,3840.0],["delete",78382.5,0.0],["delete",78382.0,0.0],["delete",78381.0,0.0],["delete",78380.5,0.0],["delete",78380.0,0.0],["new",78379.5,9460.0],["new",78378.5,1.0e3],["change",78378.0,47650.0],["change",78377.5,4.0e4],["change",78377.0,94720.0],["change",78375.5,49690.0],["new",78374.0,1.6e5]],"asks":[["delete",78392.5,0.0],["delete",78394.5,0.0],["delete",78395.0,0.0],["delete",78396.0,0.0],["delete",78397.5,0.0],["delete",78398.0,0.0],["delete",78399.0,0.0],["delete",78399.5,0.0],["new",78401.0,510.0],["change",78402.5,26150.0],["change",78403.0,173280.0],["new",78403.5,550.0],["new",78407.5,850.0],["new",78408.0,21220.0],["new",78409.0,25020.0],["new",78409.5,16490.0]],"prev_change_id":41151842609}}}
[2025-04-07 08:29:49.495] [multi_sink] [info] 📩 Received: {"jsonrpc":"2.0","method":"subscription","params":{"channel":"book.BTC-PERPETUAL.100ms","data":{"timestamp":1743994791105,"type":"change","change_id":41151843878,"instrument_name":"BTC-PERPETUAL","bids":[["new",78388.0,58380.0],["new",78387.5,56490.0],["new",78386.5,2.23e4],["new",78386.0,1.0e3],["new",78385.5,2.23e4],["new",78385.0,3.45e4],["new",78384.5,16490.0],["new",78384.0,2480.0],["change",78377.0,33970.0],["delete",78376.5,0.0],["change",78375.5,49490.0],["delete",78375.0,0.0],["change",78373.0,200.0],["change",78371.0,27310.0],["delete",78370.0,0.0],["delete",78369.0,0.0],["new",78234.0,78230.0],["delete",78223.5,0.0],["new",78184.0,117270.0],["delete",78173.5,0.0]],"asks":[["new",78389.0,460.0],["new",78390.0,360.0],["new",78393.5,390.0],["new",78396.0,430.0],["new",78397.0,9460.0],["new",78398.0,10.0],["new",78398.5,470.0],["change",7.84e4,360.0],["change",78400.5,31210.0],["delete",78402.0,0.0],["change",78402.5,830.0],["change",78403.0,91640.0],["delete",78404.0,0.0],["delete",78405.0,0.0],["delete",78406.5,0.0],["delete",78407.0,0.0],["delete",78555.5,0.0],["new",78568.5,78560.0],["delete",78605.5,0.0],["new",78618.5,117920.0]],"prev_change_id":41151842924}}}
[2025-04-07 08:29:49.498] [multi_sink] [info] Processing received message: {"jsonrpc":"2.0","method":"subscription","params":{"channel":"book.BTC-PERPETUAL.100ms","data":{"timestamp":1743994791105,"type":"change","change_id":41151843878,"instrument_name":"BTC-PERPETUAL","bids":[["new",78388.0,58380.0],["new",78387.5,56490.0],["new",78386.5,2.23e4],["new",78386.0,1.0e3],["new",78385.5,2.23e4],["new",78385.0,3.45e4],["new",78384.5,16490.0],["new",78384.0,2480.0],["change",78377.0,33970.0],["delete",78376.5,0.0],["change",78375.5,49490.0],["delete",78375.0,0.0],["change",78373.0,200.0],["change",78371.0,27310.0],["delete",78370.0,0.0],["delete",78369.0,0.0],["new",78234.0,78230.0],["delete",78223.5,0.0],["new",78184.0,117270.0],["delete",78173.5,0.0]],"asks":[["new",78389.0,460.0],["new",78390.0,360.0],["new",78393.5,390.0],["new",78396.0,430.0],["new",78397.0,9460.0],["new",78398.0,10.0],["new",78398.5,470.0],["change",7.84e4,360.0],["change",78400.5,31210.0],["delete",78402.0,0.0],["change",78402.5,830.0],["change",78403.0,91640.0],["delete",78404.0,0.0],["delete",78405.0,0.0],["delete",78406.5,0.0],["delete",78407.0,0.0],["delete",78555.5,0.0],["new",78568.5,78560.0],["delete",78605.5,0.0],["new",78618.5,117920.0]],"prev_change_id":41151842924}}}
[2025-04-07 08:29:49.857] [multi_sink] [info] 📩 Received: {"jsonrpc":"2.0","method":"subscription","params":{"channel":"book.BTC-PERPETUAL.100ms","data":{"timestamp":1743994791127,"type":"change","change_id":41151843885,"instrument_name":"BTC-PERPETUAL","bids":[["new",78388.5,99250.0],["delete",78368.5,0.0]],"asks":[],"prev_change_id":41151843878}}}
[2025-04-07 08:29:49.861] [multi_sink] [info] Processing received message: {"jsonrpc":"2.0","method":"subscription","params":{"channel":"book.BTC-PERPETUAL.100ms","data":{"timestamp":1743994791127,"type":"change","change_id":41151843885,"instrument_name":"BTC-PERPETUAL","bids":[["new",78388.5,99250.0],["delete",78368.5,0.0]],"asks":[],"prev_change_id":41151843878}}}
[2025-04-07 08:29:50.516] [multi_sink] [info] 📩 Received: {"jsonrpc":"2.0","method":"subscription","params":{"channel":"book.BTC-PERPETUAL.100ms","data":{"timestamp":1743994792036,"type":"change","change_id":41151845419,"instrument_name":"BTC-PERPETUAL","bids":[],"asks":[["new",78557.5,78550.0],["delete",78568.5,0.0],["new",78607.5,1.179e5],["delete",78618.5,0.0]],"prev_change_id":41151843885}}}
[2025-04-07 08:29:50.520] [multi_sink] [info] Processing received message: {"jsonrpc":"2.0","method":"subscription","params":{"channel":"book.BTC-PERPETUAL.100ms","data":{"timestamp":1743994792036,"type":"change","change_id":41151845419,"instrument_name":"BTC-PERPETUAL","bids":[],"asks":[["new",78557.5,78550.0],["delete",78568.5,0.0],["new",78607.5,1.179e5],["delete",78618.5,0.0]],"prev_change_id":41151843885}}}
[2025-04-07 08:29:50.963] [multi_sink] [info] 📩 Received: {"jsonrpc":"2.0","method":"subscription","params":{"channel":"book.BTC-PERPETUAL.100ms","data":{"timestamp":1743994792595,"type":"change","change_id":41151845735,"instrument_name":"BTC-PERPETUAL","bids":[["delete",78234.0,0.0]],"asks":[],"prev_change_id":41151845419}}}
[2025-04-07 08:29:50.967] [multi_sink] [info] Processing received message: {"jsonrpc":"2.0","method":"subscription","params":{"channel":"book.BTC-PERPETUAL.100ms","data":{"timestamp":1743994792595,"type":"change","change_id":41151845735,"instrument_name":"BTC-PERPETUAL","bids":[["delete",78234.0,0.0]],"asks":[],"prev_change_id":41151845419}}}
[2025-04-07 08:29:51.294] [multi_sink] [info] 📩 Received: {"jsonrpc":"2.0","method":"subscription","params":{"channel":"book.BTC-PERPETUAL.100ms","data":{"timestamp":1743994792597,"type":"change","change_id":41151845736,"instrument_name":"BTC-PERPETUAL","bids":[["delete",78184.0,0.0]],"asks":[],"prev_change_id":41151845735}}}
[2025-04-07 08:29:51.299] [multi_sink] [info] Processing received message: {"jsonrpc":"2.0","method":"subscription","params":{"channel":"book.BTC-PERPETUAL.100ms","data":{"timestamp":1743994792597,"type":"change","change_id":41151845736,"instrument_name":"BTC-PERPETUAL","bids":[["delete",78184.0,0.0]],"asks":[],"prev_change_id":41151845735}}}
[2025-04-07 08:29:51.628] [multi_sink] [info] 📩 Received: {"jsonrpc":"2.0","method":"subscription","params":{"channel":"book.BTC-PERPETUAL.100ms","data":{"timestamp":1743994792946,"type":"change","change_id":41151846805,"instrument_name":"BTC-PERPETUAL","bids":[["new",78219.5,78220.0],["new",78169.5,117250.0]],"asks":[],"prev_change_id":41151845736}}}
[2025-04-07 08:29:51.633] [multi_sink] [info] Processing received message: {"jsonrpc":"2.0","method":"subscription","params":{"channel":"book.BTC-PERPETUAL.100ms","data":{"timestamp":1743994792946,"type":"change","change_id":41151846805,"instrument_name":"BTC-PERPETUAL","bids":[["new",78219.5,78220.0],["new",78169.5,117250.0]],"asks":[],"prev_change_id":41151845736}}}
[2025-04-07 08:29:52.529] [multi_sink] [info] 📩 Received: {"jsonrpc":"2.0","method":"subscription","params":{"channel":"book.BTC-PERPETUAL.100ms","data":{"timestamp":1743994793855,"type":"change","change_id":41151848141,"instrument_name":"BTC-PERPETUAL","bids":[["new",78359.0,7825720.0],["delete",78346.5,0.0],["new",78206.0,8000580.0],["delete",78193.5,0.0]],"asks":[],"prev_change_id":41151846805}}}
[2025-04-07 08:29:52.534] [multi_sink] [info] Processing received message: {"jsonrpc":"2.0","method":"subscription","params":{"channel":"book.BTC-PERPETUAL.100ms","data":{"timestamp":1743994793855,"type":"change","change_id":41151848141,"instrument_name":"BTC-PERPETUAL","bids":[["new",78359.0,7825720.0],["delete",78346.5,0.0],["new",78206.0,8000580.0],["delete",78193.5,0.0]],"asks":[],"prev_change_id":41151846805}}}
[2025-04-07 08:29:52.861] [multi_sink] [info] 📩 Received: {"jsonrpc":"2.0","method":"subscription","params":{"channel":"book.BTC-PERPETUAL.100ms","data":{"timestamp":1743994794185,"type":"change","change_id":41151848152,"instrument_name":"BTC-PERPETUAL","bids":[],"asks":[["delete",78424.0,0.0],["new",78436.5,6640830.0],["delete",78577.0,0.0],["new",78589.5,7777770.0]],"prev_change_id":41151848141}}}
[2025-04-07 08:29:52.863] [multi_sink] [info] Processing received message: {"jsonrpc":"2.0","method":"subscription","params":{"channel":"book.BTC-PERPETUAL.100ms","data":{"timestamp":1743994794185,"type":"change","change_id":41151848152,"instrument_name":"BTC-PERPETUAL","bids":[],"asks":[["delete",78424.0,0.0],["new",78436.5,6640830.0],["delete",78577.0,0.0],["new",78589.5,7777770.0]],"prev_change_id":41151848141}}}
[2025-04-07 08:29:53.869] [multi_sink] [info] 📩 Received: {"jsonrpc":"2.0","method":"subscription","params":{"channel":"book.BTC-PERPETUAL.100ms","data":{"timestamp":1743994795492,"type":"change","change_id":41151849709,"instrument_name":"BTC-PERPETUAL","bids":[["delete",78388.5,0.0],["delete",78388.0,0.0],["delete",78387.5,0.0],["delete",78386.5,0.0],["delete",78386.0,0.0],["new",78376.5,9460.0],["change",78375.5,54710.0],["change",78371.0,59840.0],["new",78370.0,1.6e5],["new",78368.5,4.0e4]],"asks":[["delete",78389.0,0.0],["delete",78390.0,0.0],["delete",78393.5,0.0],["delete",78396.0,0.0],["delete",78397.0,0.0],["change",78410.0,22020.0],["new",78411.0,5770.0],["change",78412.0,76890.0],["new",78413.5,5.8e3],["new",78414.0,5220.0]],"prev_change_id":41151848152}}}
[2025-04-07 08:29:53.870] [multi_sink] [info] Processing received message: {"jsonrpc":"2.0","method":"subscription","params":{"channel":"book.BTC-PERPETUAL.100ms","data":{"timestamp":1743994795492,"type":"change","change_id":41151849709,"instrument_name":"BTC-PERPETUAL","bids":[["delete",78388.5,0.0],["delete",78388.0,0.0],["delete",78387.5,0.0],["delete",78386.5,0.0],["delete",78386.0,0.0],["new",78376.5,9460.0],["change",78375.5,54710.0],["change",78371.0,59840.0],["new",78370.0,1.6e5],["new",78368.5,4.0e4]],"asks":[["delete",78389.0,0.0],["delete",78390.0,0.0],["delete",78393.5,0.0],["delete",78396.0,0.0],["delete",78397.0,0.0],["change",78410.0,22020.0],["new",78411.0,5770.0],["change",78412.0,76890.0],["new",78413.5,5.8e3],["new",78414.0,5220.0]],"prev_change_id":41151848152}}}
[2025-04-07 08:29:54.200] [multi_sink] [info] 📩 Received: {"jsonrpc":"2.0","method":"subscription","params":{"channel":"book.BTC-PERPETUAL.100ms","data":{"timestamp":1743994795813,"type":"change","change_id":41151850033,"instrument_name":"BTC-PERPETUAL","bids":[["delete",78385.5,0.0],["change",78385.0,2030.0],["delete",78384.5,0.0],["delete",78384.0,0.0],["change",78383.0,33470.0],["new",78382.5,19320.0],["new",78382.0,16490.0],["new",78381.0,33940.0],["change",78379.5,1.36e4],["new",78379.0,1.0e3],["change",78378.5,3840.0],["delete",78378.0,0.0],["change",78377.5,4.0e4]],"asks":[["delete",78398.0,0.0],["delete",78398.5,0.0],["delete",7.84e4,0.0],["delete",78400.5,0.0],["delete",78401.0,0.0],["delete",78402.5,0.0],["delete",78403.0,0.0],["change",78403.5,4270.0],["new",78405.0,13990.0],["new",78405.5,27990.0],["new",78406.0,470.0],["new",78407.0,21990.0],["change",78407.5,360.0],["change",78408.0,64390.0],["new",78408.5,47570.0],["change",78409.5,99650.0]],"prev_change_id":41151849709}}}
[2025-04-07 08:29:54.205] [multi_sink] [info] Processing received message: {"jsonrpc":"2.0","method":"subscription","params":{"channel":"book.BTC-PERPETUAL.100ms","data":{"timestamp":1743994795813,"type":"change","change_id":41151850033,"instrument_name":"BTC-PERPETUAL","bids":[["delete",78385.5,0.0],["change",78385.0,2030.0],["delete",78384.5,0.0],["delete",78384.0,0.0],["change",78383.0,33470.0],["new",78382.5,19320.0],["new",78382.0,16490.0],["new",78381.0,33940.0],["change",78379.5,1.36e4],["new",78379.0,1.0e3],["change",78378.5,3840.0],["delete",78378.0,0.0],["change",78377.5,4.0e4]],"asks":[["delete",78398.0,0.0],["delete",78398.5,0.0],["delete",7.84e4,0.0],["delete",78400.5,0.0],["delete",78401.0,0.0],["delete",78402.5,0.0],["delete",78403.0,0.0],["change",78403.5,4270.0],["new",78405.0,13990.0],["new",78405.5,27990.0],["new",78406.0,470.0],["new",78407.0,21990.0],["change",78407.5,360.0],["change",78408.0,64390.0],["new",78408.5,47570.0],["change",78409.5,99650.0]],"prev_change_id":41151849709}}}
[2025-04-07 08:29:54.531] [multi_sink] [info] 📩 Received: {"jsonrpc":"2.0","method":"subscription","params":{"channel":"book.BTC-PERPETUAL.100ms","data":{"timestamp":1743994796030,"type":"change","change_id":41151850955,"instrument_name":"BTC-PERPETUAL","bids":[["new",78397.0,4710.0],["new",78395.5,160.0],["new",78393.0,170.0],["new",78390.5,190.0],["new",78388.0,200.0],["new",78385.5,220.0],["delete",78377.0,0.0],["change",78375.5,5220.0],["delete",78374.0,0.0],["delete",78373.0,0.0],["delete",78372.5,0.0],["change",78371.0,32530.0]],"asks":[["new",78397.5,145780.0],["new",78398.0,28570.0],["new",78400.5,9460.0],["new",78401.0,890.0],["new",78402.0,480.0],["new",78403.0,80130.0],["change",78408.0,43170.0],["delete",78409.0,0.0],["change",78409.5,83160.0],["change",78410.0,11010.0],["delete",78411.5,0.0],["change",78412.0,2810.0]],"prev_change_id":41151850033}}}
[2025-04-07 08:29:54.535] [multi_sink] [info] Processing received message: {"jsonrpc":"2.0","method":"subscription","params":{"channel":"book.BTC-PERPETUAL.100ms","data":{"timestamp":1743994796030,"type":"change","change_id":41151850955,"instrument_name":"BTC-PERPETUAL","bids":[["new",78397.0,4710.0],["new",78395.5,160.0],["new",78393.0,170.0],["new",78390.5,190.0],["new",78388.0,200.0],["new",78385.5,220.0],["delete",78377.0,0.0],["change",78375.5,5220.0],["delete",78374.0,0.0],["delete",78373.0,0.0],["delete",78372.5,0.0],["change",78371.0,32530.0]],"asks":[["new",78397.5,145780.0],["new",78398.0,28570.0],["new",78400.5,9460.0],["new",78401.0,890.0],["new",78402.0,480.0],["new",78403.0,80130.0],["change",78408.0,43170.0],["delete",78409.0,0.0],["change",78409.5,83160.0],["change",78410.0,11010.0],["delete",78411.5,0.0],["change",78412.0,2810.0]],"prev_change_id":41151850033}}}
[2025-04-07 08:29:58.903] [multi_sink] [info] 📩 Received: {"jsonrpc":"2.0","method":"subscription","params":{"channel":"book.BTC-PERPETUAL.100ms","data":{"timestamp":1743994800530,"type":"change","change_id":41151856886,"instrument_name":"BTC-PERPETUAL","bids":[["delete",78397.0,0.0],["delete",78395.5,0.0],["delete",78393.0,0.0],["delete",78390.5,0.0],["delete",78388.0,0.0],["delete",78385.5,0.0],["change",78371.0,41990.0],["new",78370.5,27390.0],["change",78370.0,1.7e5],["change",78368.5,8.0e4],["new",78368.0,40020.0],["new",78367.5,1570.0]],"asks":[["delete",78397.5,0.0],["delete",78398.0,0.0],["delete",78400.5,0.0],["delete",78401.0,0.0],["delete",78402.0,0.0],["delete",78403.0,0.0],["change",78410.0,22020.0],["change",78411.0,10990.0],["new",78411.5,32970.0],["change",78412.0,192110.0],["new",78413.0,115390.0],["change",78414.0,10440.0]],"prev_change_id":41151850955}}}
[2025-04-07 08:29:58.904] [multi_sink] [info] Processing received message: {"jsonrpc":"2.0","method":"subscription","params":{"channel":"book.BTC-PERPETUAL.100ms","data":{"timestamp":1743994800530,"type":"change","change_id":41151856886,"instrument_name":"BTC-PERPETUAL","bids":[["delete",78397.0,0.0],["delete",78395.5,0.0],["delete",78393.0,0.0],["delete",78390.5,0.0],["delete",78388.0,0.0],["delete",78385.5,0.0],["change",78371.0,41990.0],["new",78370.5,27390.0],["change",78370.0,1.7e5],["change",78368.5,8.0e4],["new",78368.0,40020.0],["new",78367.5,1570.0]],"asks":[["delete",78397.5,0.0],["delete",78398.0,0.0],["delete",78400.5,0.0],["delete",78401.0,0.0],["delete",78402.0,0.0],["delete",78403.0,0.0],["change",78410.0,22020.0],["change",78411.0,10990.0],["new",78411.5,32970.0],["change",78412.0,192110.0],["new",78413.0,115390.0],["change",78414.0,10440.0]],"prev_change_id":41151850955}}}
[2025-04-07 08:29:59.237] [multi_sink] [info] 📩 Received: {"jsonrpc":"2.0","method":"subscription","params":{"channel":"book.BTC-PERPETUAL.100ms","data":{"timestamp":1743994800850,"type":"change","change_id":41151857317,"instrument_name":"BTC-PERPETUAL","bids":[["delete",78385.0,0.0],["delete",78383.0,0.0],["delete",78382.5,0.0],["delete",78382.0,0.0],["change",78381.0,550.0],["new",78380.0,20490.0],["delete",78379.5,0.0],["delete",78379.0,0.0],["delete",78378.5,0.0],["new",78377.0,16490.0],["change",78376.5,49460.0],["new",78376.0,22890.0],["new",78375.0,4330.0],["new",78374.5,1.0e3],["new",78372.0,16490.0]],"asks":[["new",78401.0,5.5e3],["new",78401.5,24630.0],["new",78403.0,53640.0],["delete",78403.5,0.0],["new",78404.0,3.5e4],["change",78405.0,83160.0],["change",78405.5,33940.0],["delete",78406.0,0.0],["change",78407.0,2810.0],["change",78407.5,360.0],["change",78408.0,55260.0],["delete",78408.5,0.0],["delete",78409.5,0.0]],"prev_change_id":41151856886}}}
[2025-04-07 08:29:59.241] [multi_sink] [info] Processing received message: {"jsonrpc":"2.0","method":"subscription","params":{"channel":"book.BTC-PERPETUAL.100ms","data":{"timestamp":1743994800850,"type":"change","change_id":41151857317,"instrument_name":"BTC-PERPETUAL","bids":[["delete",78385.0,0.0],["delete",78383.0,0.0],["delete",78382.5,0.0],["delete",78382.0,0.0],["change",78381.0,550.0],["new",78380.0,20490.0],["delete",78379.5,0.0],["delete",78379.0,0.0],["delete",78378.5,0.0],["new",78377.0,16490.0],["change",78376.5,49460.0],["new",78376.0,22890.0],["new",78375.0,4330.0],["new",78374.5,1.0e3],["new",78372.0,16490.0]],"asks":[["new",78401.0,5.5e3],["new",78401.5,24630.0],["new",78403.0,53640.0],["delete",78403.5,0.0],["new",78404.0,3.5e4],["change",78405.0,83160.0],["change",78405.5,33940.0],["delete",78406.0,0.0],["change",78407.0,2810.0],["change",78407.5,360.0],["change",78408.0,55260.0],["delete",78408.5,0.0],["delete",78409.5,0.0]],"prev_change_id":41151856886}}}
[2025-04-07 08:29:59.564] [multi_sink] [info] 📩 Received: {"jsonrpc":"2.0","method":"subscription","params":{"channel":"book.BTC-PERPETUAL.100ms","data":{"timestamp":1743994801075,"type":"change","change_id":41151858056,"instrument_name":"BTC-PERPETUAL","bids":[["new",78397.0,3790.0],["new",78388.5,430.0],["new",78386.0,470.0],["new",78385.0,2030.0],["new",78383.5,510.0],["new",78382.0,480.0],["delete",78377.5,0.0],["change",78376.5,4.0e4],["delete",78375.5,0.0],["change",78371.0,9460.0],["change",78370.0,1.0e4],["change",78368.5,4.0e4],["delete",78359.0,0.0],["new",78358.5,7825720.0],["new",78230.5,78230.0],["delete",78219.5,0.0],["delete",78206.0,0.0],["new",78205.5,8000580.0],["new",78180.5,117270.0],["delete",78169.5,0.0]],"asks":[["new",78397.5,210810.0],["new",78398.0,66280.0],["new",78399.0,6460.0],["new",78399.5,27990.0],["new",7.84e4,3.5e4],["change",78410.0,11010.0],["change",78411.0,5220.0],["change",78412.0,1.893e5],["delete",78413.5,0.0],["change",78414.0,5220.0]],"prev_change_id":41151857317}}}
[2025-04-07 08:29:59.567] [multi_sink] [info] Processing received message: {"jsonrpc":"2.0","method":"subscription","params":{"channel":"book.BTC-PERPETUAL.100ms","data":{"timestamp":1743994801075,"type":"change","change_id":41151858056,"instrument_name":"BTC-PERPETUAL","bids":[["new",78397.0,3790.0],["new",78388.5,430.0],["new",78386.0,470.0],["new",78385.0,2030.0],["new",78383.5,510.0],["new",78382.0,480.0],["delete",78377.5,0.0],["change",78376.5,4.0e4],["delete",78375.5,0.0],["change",78371.0,9460.0],["change",78370.0,1.0e4],["change",78368.5,4.0e4],["delete",78359.0,0.0],["new",78358.5,7825720.0],["new",78230.5,78230.0],["delete",78219.5,0.0],["delete",78206.0,0.0],["new",78205.5,8000580.0],["new",78180.5,117270.0],["delete",78169.5,0.0]],"asks":[["new",78397.5,210810.0],["new",78398.0,66280.0],["new",78399.0,6460.0],["new",78399.5,27990.0],["new",7.84e4,3.5e4],["change",78410.0,11010.0],["change",78411.0,5220.0],["change",78412.0,1.893e5],["delete",78413.5,0.0],["change",78414.0,5220.0]],"prev_change_id":41151857317}}}
[2025-04-07 08:29:59.895] [multi_sink] [info] 📩 Received: {"jsonrpc":"2.0","method":"subscription","params":{"channel":"book.BTC-PERPETUAL.100ms","data":{"timestamp":1743994801407,"type":"change","change_id":41151858374,"instrument_name":"BTC-PERPETUAL","bids":[],"asks":[["new",78436.0,6640830.0],["delete",78436.5,0.0],["delete",78557.5,0.0],["new",78569.0,78560.0],["new",78589.0,7777770.0],["delete",78589.5,0.0],["delete",78607.5,0.0],["new",78619.0,117920.0]],"prev_change_id":41151858056}}}
[2025-04-07 08:29:59.898] [multi_sink] [info] Processing received message: {"jsonrpc":"2.0","method":"subscription","params":{"channel":"book.BTC-PERPETUAL.100ms","data":{"timestamp":1743994801407,"type":"change","change_id":41151858374,"instrument_name":"BTC-PERPETUAL","bids":[],"asks":[["new",78436.0,6640830.0],["delete",78436.5,0.0],["delete",78557.5,0.0],["new",78569.0,78560.0],["new",78589.0,7777770.0],["delete",78589.5,0.0],["delete",78607.5,0.0],["new",78619.0,117920.0]],"prev_change_id":41151858056}}}
[2025-04-07 08:30:00.226] [multi_sink] [info] 📩 Received: {"jsonrpc":"2.0","method":"subscription","params":{"channel":"book.BTC-PERPETUAL.100ms","data":{"timestamp":1743994801765,"type":"change","change_id":41151858730,"instrument_name":"BTC-PERPETUAL","bids":[["new",78241.5,78240.0],["delete",78230.5,0.0],["new",78191.5,117280.0],["delete",78180.5,0.0]],"asks":[],"prev_change_id":41151858374}}}
[2025-04-07 08:30:00.228] [multi_sink] [info] Processing received message: {"jsonrpc":"2.0","method":"subscription","params":{"channel":"book.BTC-PERPETUAL.100ms","data":{"timestamp":1743994801765,"type":"change","change_id":41151858730,"instrument_name":"BTC-PERPETUAL","bids":[["new",78241.5,78240.0],["delete",78230.5,0.0],["new",78191.5,117280.0],["delete",78180.5,0.0]],"asks":[],"prev_change_id":41151858374}}}
[2025-04-07 08:30:00.557] [multi_sink] [info] 📩 Received: {"jsonrpc":"2.0","method":"subscription","params":{"channel":"book.BTC-PERPETUAL.100ms","data":{"timestamp":1743994802099,"type":"change","change_id":41151859645,"instrument_name":"BTC-PERPETUAL","bids":[],"asks":[["change",78397.5,221150.0]],"prev_change_id":41151858730}}}
[2025-04-07 08:30:00.559] [multi_sink] [info] Processing received message: {"jsonrpc":"2.0","method":"subscription","params":{"channel":"book.BTC-PERPETUAL.100ms","data":{"timestamp":1743994802099,"type":"change","change_id":41151859645,"instrument_name":"BTC-PERPETUAL","bids":[],"asks":[["change",78397.5,221150.0]],"prev_change_id":41151858730}}}
[2025-04-07 08:30:03.606] [multi_sink] [info] 📩 Received: {"jsonrpc":"2.0","method":"subscription","params":{"channel":"book.BTC-PERPETUAL.100ms","data":{"timestamp":1743994805236,"type":"change","change_id":41151863849,"instrument_name":"BTC-PERPETUAL","bids":[["delete",78241.5,0.0],["new",78231.0,78230.0],["delete",78191.5,0.0],["new",78181.0,117270.0]],"asks":[],"prev_change_id":41151859645}}}
[2025-04-07 08:30:03.609] [multi_sink] [info] Processing received message: {"jsonrpc":"2.0","method":"subscription","params":{"channel":"book.BTC-PERPETUAL.100ms","data":{"timestamp":1743994805236,"type":"change","change_id":41151863849,"instrument_name":"BTC-PERPETUAL","bids":[["delete",78241.5,0.0],["new",78231.0,78230.0],["delete",78191.5,0.0],["new",78181.0,117270.0]],"asks":[],"prev_change_id":41151859645}}}
[2025-04-07 08:30:03.938] [multi_sink] [info] 📩 Received: {"jsonrpc":"2.0","method":"subscription","params":{"channel":"book.BTC-PERPETUAL.100ms","data":{"timestamp":1743994805566,"type":"change","change_id":41151864145,"instrument_name":"BTC-PERPETUAL","bids":[["delete",78397.0,0.0],["delete",78388.5,0.0],["delete",78386.0,0.0],["delete",78385.0,0.0],["delete",78383.5,0.0],["delete",78382.0,0.0],["change",78381.0,37780.0],["new",78380.5,490.0],["change",78380.0,40840.0],["change",78377.0,32980.0],["change",78376.5,8.0e4],["change",78375.0,4490.0],["new",78371.5,5220.0]],"asks":[["delete",78397.5,0.0],["delete",78398.0,0.0],["change",78399.0,10340.0],["delete",78399.5,0.0],["delete",7.84e4,0.0],["delete",78401.0,0.0],["delete",78401.5,0.0],["new",78419.5,13790.0],["new",78420.0,14860.0],["new",78420.5,1.0e4],["new",78422.5,360.0],["new",78423.0,39160.0],["new",78425.0,57780.0],["new",78425.5,1.0e4]],"prev_change_id":41151863849}}}
[2025-04-07 08:30:03.943] [multi_sink] [info] Processing received message: {"jsonrpc":"2.0","method":"subscription","params":{"channel":"book.BTC-PERPETUAL.100ms","data":{"timestamp":1743994805566,"type":"change","change_id":41151864145,"instrument_name":"BTC-PERPETUAL","bids":[["delete",78397.0,0.0],["delete",78388.5,0.0],["delete",78386.0,0.0],["delete",78385.0,0.0],["delete",78383.5,0.0],["delete",78382.0,0.0],["change",78381.0,37780.0],["new",78380.5,490.0],["change",78380.0,40840.0],["change",78377.0,32980.0],["change",78376.5,8.0e4],["change",78375.0,4490.0],["new",78371.5,5220.0]],"asks":[["delete",78397.5,0.0],["delete",78398.0,0.0],["change",78399.0,10340.0],["delete",78399.5,0.0],["delete",7.84e4,0.0],["delete",78401.0,0.0],["delete",78401.5,0.0],["new",78419.5,13790.0],["new",78420.0,14860.0],["new",78420.5,1.0e4],["new",78422.5,360.0],["new",78423.0,39160.0],["new",78425.0,57780.0],["new",78425.5,1.0e4]],"prev_change_id":41151863849}}}
[2025-04-07 08:30:04.266] [multi_sink] [info] 📩 Received: {"jsonrpc":"2.0","method":"subscription","params":{"channel":"book.BTC-PERPETUAL.100ms","data":{"timestamp":1743994805879,"type":"change","change_id":41151864724,"instrument_name":"BTC-PERPETUAL","bids":[["new",78390.0,230.0],["new",78387.5,220.0],["new",78385.0,4870.0],["new",78384.5,9450.0],["new",78383.5,19980.0],["new",78382.5,150.0],["new",78382.0,16490.0],["new",78381.5,17490.0],["change",78380.0,20350.0],["change",78377.0,16490.0],["change",78376.5,4.0e4],["delete",78376.0,0.0],["change",78375.0,160.0],["delete",78374.5,0.0],["delete",78372.0,0.0],["delete",78371.0,0.0]],"asks":[["delete",78403.0,0.0],["delete",78404.0,0.0],["delete",78405.0,0.0],["delete",78405.5,0.0],["delete",78407.0,0.0],["delete",78407.5,0.0],["delete",78408.0,0.0],["change",78410.0,1010.0],["new",78410.5,3.5e4],["change",78411.5,33520.0],["change",78412.0,2.169e5],["new",78415.0,360.0],["new",78416.0,81640.0],["new",78416.5,15610.0],["new",78417.5,32740.0]],"prev_change_id":41151864145}}}
[2025-04-07 08:30:04.269] [multi_sink] [info] Processing received message: {"jsonrpc":"2.0","method":"subscription","params":{"channel":"book.BTC-PERPETUAL.100ms","data":{"timestamp":1743994805879,"type":"change","change_id":41151864724,"instrument_name":"BTC-PERPETUAL","bids":[["new",78390.0,230.0],["new",78387.5,220.0],["new",78385.0,4870.0],["new",78384.5,9450.0],["new",78383.5,19980.0],["new",78382.5,150.0],["new",78382.0,16490.0],["new",78381.5,17490.0],["change",78380.0,20350.0],["change",78377.0,16490.0],["change",78376.5,4.0e4],["delete",78376.0,0.0],["change",78375.0,160.0],["delete",78374.5,0.0],["delete",78372.0,0.0],["delete",78371.0,0.0]],"asks":[["delete",78403.0,0.0],["delete",78404.0,0.0],["delete",78405.0,0.0],["delete",78405.5,0.0],["delete",78407.0,0.0],["delete",78407.5,0.0],["delete",78408.0,0.0],["change",78410.0,1010.0],["new",78410.5,3.5e4],["change",78411.5,33520.0],["change",78412.0,2.169e5],["new",78415.0,360.0],["new",78416.0,81640.0],["new",78416.5,15610.0],["new",78417.5,32740.0]],"prev_change_id":41151864145}}}
[2025-04-07 08:30:04.597] [multi_sink] [info] 📩 Received: {"jsonrpc":"2.0","method":"subscription","params":{"channel":"book.BTC-PERPETUAL.100ms","data":{"timestamp":1743994806067,"type":"change","change_id":41151865320,"instrument_name":"BTC-PERPETUAL","bids":[["new",78407.0,10970.0],["new",78397.5,160.0],["new",78397.0,3620.0],["new",78395.0,170.0],["new",78392.5,190.0],["delete",78370.5,0.0],["delete",78370.0,0.0],["delete",78368.5,0.0],["delete",78368.0,0.0],["delete",78367.5,0.0]],"asks":[["delete",78399.0,0.0],["new",78407.5,224810.0],["new",78408.0,2.23e4],["new",78408.5,9460.0],["new",78409.0,35180.0],["new",78409.5,83640.0],["delete",78411.0,0.0],["change",78411.5,550.0],["change",78412.0,2.76e4],["delete",78413.0,0.0],["delete",78414.0,0.0]],"prev_change_id":41151864724}}}
[2025-04-07 08:30:04.601] [multi_sink] [info] Processing received message: {"jsonrpc":"2.0","method":"subscription","params":{"channel":"book.BTC-PERPETUAL.100ms","data":{"timestamp":1743994806067,"type":"change","change_id":41151865320,"instrument_name":"BTC-PERPETUAL","bids":[["new",78407.0,10970.0],["new",78397.5,160.0],["new",78397.0,3620.0],["new",78395.0,170.0],["new",78392.5,190.0],["delete",78370.5,0.0],["delete",78370.0,0.0],["delete",78368.5,0.0],["delete",78368.0,0.0],["delete",78367.5,0.0]],"asks":[["delete",78399.0,0.0],["new",78407.5,224810.0],["new",78408.0,2.23e4],["new",78408.5,9460.0],["new",78409.0,35180.0],["new",78409.5,83640.0],["delete",78411.0,0.0],["change",78411.5,550.0],["change",78412.0,2.76e4],["delete",78413.0,0.0],["delete",78414.0,0.0]],"prev_change_id":41151864724}}}
[2025-04-07 08:30:05.887] [multi_sink] [info] Received message from client 140042643180592: {"subscribe": "ETH-PERPETUAL.100ms"}
[2025-04-07 08:30:05.888] [multi_sink] [info] Added subscription for client 140042643180592 to channel ETH-PERPETUAL.100ms
[2025-04-07 08:30:05.888] [multi_sink] [info] ➡️ Added to send queue: {"id":"subscribe#11","jsonrpc":"2.0","method":"private/subscribe","params":{"channels":["book.ETH-PERPETUAL.100ms"]}}
[2025-04-07 08:30:05.888] [multi_sink] [info] ➡️ Sent: {"id":"subscribe#11","jsonrpc":"2.0","method":"private/subscribe","params":{"channels":["book.ETH-PERPETUAL.100ms"]}}
[2025-04-07 08:30:05.888] [multi_sink] [info]  Subscribed to ETH-PERPETUAL.100ms order book
[2025-04-07 08:30:05.889] [multi_sink] [debug] Updated activity for client: 140042643180592
[2025-04-07 08:30:06.056] [multi_sink] [info] 📩 Received: {"jsonrpc":"2.0","id":"subscribe#11","result":["book.ETH-PERPETUAL.100ms"],"usIn":1743994807687672,"usOut":1743994807687843,"usDiff":171,"testnet":true}
[2025-04-07 08:30:06.059] [multi_sink] [info] Processing received message: {"jsonrpc":"2.0","id":"subscribe#11","result":["book.ETH-PERPETUAL.100ms"],"usIn":1743994807687672,"usOut":1743994807687843,"usDiff":171,"testnet":true}
[2025-04-07 08:30:06.068] [multi_sink] [info] 📩 Received: {"jsonrpc":"2.0","method":"subscription","params":{"channel":"book.ETH-PERPETUAL.100ms","data":{"timestamp":1743994805998,"type":"snapshot","change_id":23707124060,"instrument_name":"ETH-PERPETUAL","bids":[["new",1578.05,380.0],["new",1578.0,1268.0],["new",1577.95,9921.0],["new",1577.8,1408.0],["new",1577.75,26730.0],["new",1577.7,71501.0],["new",1577.65,1361.0],["new",1577.6,100.0],["new",1577.55,928.0],["new",1577.5,15021.0],["new",1577.45,7766105.0],["new",1577.4,1574.0],["new",1577.35,5231.0],["new",1577.25,12148.0],["new",1577.2,1405.0],["new",1577.15,928.0],["new",1577.1,1028.0],["new",1577.05,10685.0],["new",1577.0,25813.0],["new",1576.95,42871.0],["new",1573.05,500.0],["new",1569.1,500.0],["new",1561.45,700.0],["new",1.5e3,1402018.0],["new",1386.9,4.0],["new",1359.3,1.0],["new",1242.0,64580.0],["new",1234.0,120.0],["new",1215.1,223.0],["new",1.2e3,709.0],["new",1199.9,1.0e4],["new",1193.9,2.0e4],["new",1102.0,43740.0],["new",1.0e3,1006.0],["new",942.0,131220.0],["new",900.0,4.6e3],["new",800.0,1.74e4],["new",762.0,393660.0],["new",750.8,386.0],["new",701.0,45.0],["new",691.0,49.0],["new",681.0,53.0],["new",671.0,56.0],["new",661.0,59.0],["new",651.0,61.0],["new",641.0,61.0],["new",631.0,62.0],["new",623.45,915.0],["new",621.0,62.0],["new",611.0,60.0],["new",601.0,58.0],["new",600.0,2509.0],["new",591.0,55.0],["new",581.0,52.0],["new",571.0,47.0],["new",561.0,43.0],["new",551.0,37.0],["new",541.0,32.0],["new",531.0,27.0],["new",524.0,87474.0],["new",521.0,22.0],["new",511.0,17.0],["new",501.0,13.0],["new",500.0,3119.0],["new",400.0,250033.0],["new",350.0,240.0],["new",345.0,50.0],["new",332.1,301.0],["new",324.65,482.0],["new",317.2,784.0],["new",309.75,1267.0],["new",302.35,2052.0],["new",300.0,251006.0],["new",294.9,3320.0],["new",287.45,5372.0],["new",260.0,5.0e5],["new",222.0,20.0],["new",212.0,2.0],["new",200.0,62.0],["new",199.0,100.0],["new",195.0,2.0e3],["new",192.0,2.0],["new",181.0,1.2e5],["new",172.05,30.0],["new",150.0,30.0],["new",143.55,20.0],["new",140.0,1.0e5],["new",135.0,200010.0],["new",130.0,300020.0],["new",125.0,400020.0],["new",121.0,12.0],["new",120.0,130.0],["new",115.0,20.0],["new",110.0,30.0],["new",105.0,20.0],["new",101.0,10.0],["new",100.0,1018.0],["new",60.0,280.0],["new",58.0,1.0],["new",55.0,45.0],["new",50.0,710.0],["new",45.0,10000005.0],["new",32.0,5.0],["new",30.0,70.0],["new",29.0,220.0],["new",25.0,20.0],["new",22.2,1.0],["new",21.0,10.0],["new",20.0,2210.0],["new",10.0,370.0],["new",9.95,1.0],["new",6.0,200.0],["new",5.0,43.0],["new",4.0,1844.0],["new",1.45,1330.0],["new",1.1,7.0],["new",1.0,86.0],["new",0.5,24.0]],"asks":[["new",1578.15,37884.0],["new",1578.2,16168.0],["new",1578.25,6599.0],["new",1578.3,12669.0],["new",1578.35,10021.0],["new",1578.4,100.0],["new",1578.45,100.0],["new",1578.5,1.0e3],["new",1578.55,1259.0],["new",1578.6,4198.0],["new",1578.65,39423.0],["new",1578.7,44305.0],["new",1578.75,73135.0],["new",1578.8,17121.0],["new",1578.85,7470.0],["new",1578.9,19081.0],["new",1578.95,6159268.0],["new",1579.0,3862.0],["new",1579.05,920.0],["new",1579.1,12105.0],["new",1579.15,6923.0],["new",1581.95,500.0],["new",1584.7,500.0],["new",1591.25,700.0],["new",2341.0,26.0],["new",2.4e3,2.4e3],["new",2571.75,1.0],["new",3024.2,1.0e6],["new",4.0e3,92.0],["new",4048.1,4.0],["new",4160.0,16.0],["new",4.5e3,135.0],["new",5.0e3,15450.0],["new",5555.0,10001.0],["new",7180.4,1.0],["new",9999.95,1.0],["new",1.0e4,15.0],["new",1.1e4,20.0],["new",18285.0,3.0e4],["new",2.0e4,3.4e3],["new",3.01e4,170.0],["new",3.85e4,40.0],["new",5.0e4,11.0],["new",51853.0,10.0],["new",9.0e4,2.0e3]]}}}
[2025-04-07 08:30:06.072] [multi_sink] [info] Processing received message: {"jsonrpc":"2.0","method":"subscription","params":{"channel":"book.ETH-PERPETUAL.100ms","data":{"timestamp":1743994805998,"type":"snapshot","change_id":23707124060,"instrument_name":"ETH-PERPETUAL","bids":[["new",1578.05,380.0],["new",1578.0,1268.0],["new",1577.95,9921.0],["new",1577.8,1408.0],["new",1577.75,26730.0],["new",1577.7,71501.0],["new",1577.65,1361.0],["new",1577.6,100.0],["new",1577.55,928.0],["new",1577.5,15021.0],["new",1577.45,7766105.0],["new",1577.4,1574.0],["new",1577.35,5231.0],["new",1577.25,12148.0],["new",1577.2,1405.0],["new",1577.15,928.0],["new",1577.1,1028.0],["new",1577.05,10685.0],["new",1577.0,25813.0],["new",1576.95,42871.0],["new",1573.05,500.0],["new",1569.1,500.0],["new",1561.45,700.0],["new",1.5e3,1402018.0],["new",1386.9,4.0],["new",1359.3,1.0],["new",1242.0,64580.0],["new",1234.0,120.0],["new",1215.1,223.0],["new",1.2e3,709.0],["new",1199.9,1.0e4],["new",1193.9,2.0e4],["new",1102.0,43740.0],["new",1.0e3,1006.0],["new",942.0,131220.0],["new",900.0,4.6e3],["new",800.0,1.74e4],["new",762.0,393660.0],["new",750.8,386.0],["new",701.0,45.0],["new",691.0,49.0],["new",681.0,53.0],["new",671.0,56.0],["new",661.0,59.0],["new",651.0,61.0],["new",641.0,61.0],["new",631.0,62.0],["new",623.45,915.0],["new",621.0,62.0],["new",611.0,60.0],["new",601.0,58.0],["new",600.0,2509.0],["new",591.0,55.0],["new",581.0,52.0],["new",571.0,47.0],["new",561.0,43.0],["new",551.0,37.0],["new",541.0,32.0],["new",531.0,27.0],["new",524.0,87474.0],["new",521.0,22.0],["new",511.0,17.0],["new",501.0,13.0],["new",500.0,3119.0],["new",400.0,250033.0],["new",350.0,240.0],["new",345.0,50.0],["new",332.1,301.0],["new",324.65,482.0],["new",317.2,784.0],["new",309.75,1267.0],["new",302.35,2052.0],["new",300.0,251006.0],["new",294.9,3320.0],["new",287.45,5372.0],["new",260.0,5.0e5],["new",222.0,20.0],["new",212.0,2.0],["new",200.0,62.0],["new",199.0,100.0],["new",195.0,2.0e3],["new",192.0,2.0],["new",181.0,1.2e5],["new",172.05,30.0],["new",150.0,30.0],["new",143.55,20.0],["new",140.0,1.0e5],["new",135.0,200010.0],["new",130.0,300020.0],["new",125.0,400020.0],["new",121.0,12.0],["new",120.0,130.0],["new",115.0,20.0],["new",110.0,30.0],["new",105.0,20.0],["new",101.0,10.0],["new",100.0,1018.0],["new",60.0,280.0],["new",58.0,1.0],["new",55.0,45.0],["new",50.0,710.0],["new",45.0,10000005.0],["new",32.0,5.0],["new",30.0,70.0],["new",29.0,220.0],["new",25.0,20.0],["new",22.2,1.0],["new",21.0,10.0],["new",20.0,2210.0],["new",10.0,370.0],["new",9.95,1.0],["new",6.0,200.0],["new",5.0,43.0],["new",4.0,1844.0],["new",1.45,1330.0],["new",1.1,7.0],["new",1.0,86.0],["new",0.5,24.0]],"asks":[["new",1578.15,37884.0],["new",1578.2,16168.0],["new",1578.25,6599.0],["new",1578.3,12669.0],["new",1578.35,10021.0],["new",1578.4,100.0],["new",1578.45,100.0],["new",1578.5,1.0e3],["new",1578.55,1259.0],["new",1578.6,4198.0],["new",1578.65,39423.0],["new",1578.7,44305.0],["new",1578.75,73135.0],["new",1578.8,17121.0],["new",1578.85,7470.0],["new",1578.9,19081.0],["new",1578.95,6159268.0],["new",1579.0,3862.0],["new",1579.05,920.0],["new",1579.1,12105.0],["new",1579.15,6923.0],["new",1581.95,500.0],["new",1584.7,500.0],["new",1591.25,700.0],["new",2341.0,26.0],["new",2.4e3,2.4e3],["new",2571.75,1.0],["new",3024.2,1.0e6],["new",4.0e3,92.0],["new",4048.1,4.0],["new",4160.0,16.0],["new",4.5e3,135.0],["new",5.0e3,15450.0],["new",5555.0,10001.0],["new",7180.4,1.0],["new",9999.95,1.0],["new",1.0e4,15.0],["new",1.1e4,20.0],["new",18285.0,3.0e4],["new",2.0e4,3.4e3],["new",3.01e4,170.0],["new",3.85e4,40.0],["new",5.0e4,11.0],["new",51853.0,10.0],["new",9.0e4,2.0e3]]}}}
[2025-04-07 08:30:06.959] [multi_sink] [info] 📩 Received: {"jsonrpc":"2.0","method":"subscription","params":{"channel":"book.BTC-PERPETUAL.100ms","data":{"timestamp":1743994808319,"type":"change","change_id":41151868430,"instrument_name":"BTC-PERPETUAL","bids":[["new",78368.5,7825720.0],["delete",78358.5,0.0],["new",78215.5,8000580.0],["delete",78205.5,0.0]],"asks":[],"prev_change_id":41151865320}}}
[2025-04-07 08:30:06.961] [multi_sink] [info] Processing received message: {"jsonrpc":"2.0","method":"subscription","params":{"channel":"book.BTC-PERPETUAL.100ms","data":{"timestamp":1743994808319,"type":"change","change_id":41151868430,"instrument_name":"BTC-PERPETUAL","bids":[["new",78368.5,7825720.0],["delete",78358.5,0.0],["new",78215.5,8000580.0],["delete",78205.5,0.0]],"asks":[],"prev_change_id":41151865320}}}
[2025-04-07 08:30:07.167] [multi_sink] [info] 📩 Received: {"jsonrpc":"2.0","method":"subscription","params":{"channel":"book.ETH-PERPETUAL.100ms","data":{"timestamp":1743994808796,"type":"change","change_id":23707128317,"instrument_name":"ETH-PERPETUAL","bids":[],"asks":[["delete",1578.15,0.0],["change",1578.9,19181.0]],"prev_change_id":23707124060}}}
[2025-04-07 08:30:07.171] [multi_sink] [info] Processing received message: {"jsonrpc":"2.0","method":"subscription","params":{"channel":"book.ETH-PERPETUAL.100ms","data":{"timestamp":1743994808796,"type":"change","change_id":23707128317,"instrument_name":"ETH-PERPETUAL","bids":[],"asks":[["delete",1578.15,0.0],["change",1578.9,19181.0]],"prev_change_id":23707124060}}}
[2025-04-07 08:30:07.297] [multi_sink] [info] 📩 Received: {"jsonrpc":"2.0","method":"subscription","params":{"channel":"book.BTC-PERPETUAL.100ms","data":{"timestamp":1743994808658,"type":"change","change_id":41151868571,"instrument_name":"BTC-PERPETUAL","bids":[],"asks":[["delete",78436.0,0.0],["new",78446.0,6640830.0],["delete",78589.0,0.0],["new",78599.0,7777770.0]],"prev_change_id":41151868430}}}
[2025-04-07 08:30:07.297] [multi_sink] [info] Processing received message: {"jsonrpc":"2.0","method":"subscription","params":{"channel":"book.BTC-PERPETUAL.100ms","data":{"timestamp":1743994808658,"type":"change","change_id":41151868571,"instrument_name":"BTC-PERPETUAL","bids":[],"asks":[["delete",78436.0,0.0],["new",78446.0,6640830.0],["delete",78589.0,0.0],["new",78599.0,7777770.0]],"prev_change_id":41151868430}}}
[2025-04-07 08:30:07.502] [multi_sink] [info] 📩 Received: {"jsonrpc":"2.0","method":"subscription","params":{"channel":"book.ETH-PERPETUAL.100ms","data":{"timestamp":1743994809123,"type":"change","change_id":23707128705,"instrument_name":"ETH-PERPETUAL","bids":[["delete",1578.05,0.0],["delete",1578.0,0.0],["delete",1577.95,0.0],["delete",1577.8,0.0],["delete",1577.75,0.0],["delete",1577.7,0.0],["delete",1577.65,0.0],["delete",1577.6,0.0],["delete",1577.55,0.0],["delete",1577.5,0.0],["new",1577.3,29766.0],["change",1577.25,34484.0],["change",1577.2,2898.0],["change",1577.15,5206.0],["change",1577.1,36745.0],["change",1577.05,21370.0],["change",1577.0,51746.0],["change",1576.95,79822.0],["new",1576.9,9821.0],["new",1576.85,16814.0]],"asks":[["delete",1578.2,0.0],["delete",1578.25,0.0],["delete",1578.3,0.0],["delete",1578.35,0.0],["delete",1578.4,0.0],["change",1578.45,2072.0],["change",1578.5,15002.0],["change",1578.55,14002.0],["change",1578.6,14707.0],["change",1578.65,73021.0],["change",1578.7,72511.0],["change",1578.75,147449.0],["change",1578.8,20240.0],["change",1578.85,14940.0]],"prev_change_id":23707128317}}}
[2025-04-07 08:30:07.509] [multi_sink] [info] Processing received message: {"jsonrpc":"2.0","method":"subscription","params":{"channel":"book.ETH-PERPETUAL.100ms","data":{"timestamp":1743994809123,"type":"change","change_id":23707128705,"instrument_name":"ETH-PERPETUAL","bids":[["delete",1578.05,0.0],["delete",1578.0,0.0],["delete",1577.95,0.0],["delete",1577.8,0.0],["delete",1577.75,0.0],["delete",1577.7,0.0],["delete",1577.65,0.0],["delete",1577.6,0.0],["delete",1577.55,0.0],["delete",1577.5,0.0],["new",1577.3,29766.0],["change",1577.25,34484.0],["change",1577.2,2898.0],["change",1577.15,5206.0],["change",1577.1,36745.0],["change",1577.05,21370.0],["change",1577.0,51746.0],["change",1576.95,79822.0],["new",1576.9,9821.0],["new",1576.85,16814.0]],"asks":[["delete",1578.2,0.0],["delete",1578.25,0.0],["delete",1578.3,0.0],["delete",1578.35,0.0],["delete",1578.4,0.0],["change",1578.45,2072.0],["change",1578.5,15002.0],["change",1578.55,14002.0],["change",1578.6,14707.0],["change",1578.65,73021.0],["change",1578.7,72511.0],["change",1578.75,147449.0],["change",1578.8,20240.0],["change",1578.85,14940.0]],"prev_change_id":23707128317}}}
[2025-04-07 08:30:07.825] [multi_sink] [info] 📩 Received: {"jsonrpc":"2.0","method":"subscription","params":{"channel":"book.ETH-PERPETUAL.100ms","data":{"timestamp":1743994809446,"type":"change","change_id":23707128984,"instrument_name":"ETH-PERPETUAL","bids":[["new",1577.75,9921.0],["new",1577.7,72358.0],["new",1577.65,1408.0],["new",1577.6,4693.0],["new",1577.55,1052.0],["new",1577.5,928.0],["change",1577.45,7748208.0],["change",1577.4,2502.0],["change",1577.35,17347.0],["change",1577.25,22336.0],["change",1577.2,1493.0],["change",1577.15,4278.0],["change",1577.1,35717.0],["change",1577.05,10685.0],["change",1577.0,25933.0]],"asks":[["new",1578.0,1.5e3],["new",1578.05,5.0e3],["new",1578.1,12691.0],["new",1578.15,5.1e3],["new",1578.2,40872.0],["new",1578.25,5807.0],["new",1578.3,11739.0],["new",1578.35,7749.0],["new",1578.4,16025.0],["change",1578.65,33598.0],["change",1578.7,28206.0],["change",1578.75,74314.0],["change",1578.8,3119.0],["change",1578.85,7470.0],["change",1578.9,100.0],["delete",1579.0,0.0],["delete",1579.05,0.0],["delete",1579.1,0.0]],"prev_change_id":23707128705}}}
[2025-04-07 08:30:07.829] [multi_sink] [info] Processing received message: {"jsonrpc":"2.0","method":"subscription","params":{"channel":"book.ETH-PERPETUAL.100ms","data":{"timestamp":1743994809446,"type":"change","change_id":23707128984,"instrument_name":"ETH-PERPETUAL","bids":[["new",1577.75,9921.0],["new",1577.7,72358.0],["new",1577.65,1408.0],["new",1577.6,4693.0],["new",1577.55,1052.0],["new",1577.5,928.0],["change",1577.45,7748208.0],["change",1577.4,2502.0],["change",1577.35,17347.0],["change",1577.25,22336.0],["change",1577.2,1493.0],["change",1577.15,4278.0],["change",1577.1,35717.0],["change",1577.05,10685.0],["change",1577.0,25933.0]],"asks":[["new",1578.0,1.5e3],["new",1578.05,5.0e3],["new",1578.1,12691.0],["new",1578.15,5.1e3],["new",1578.2,40872.0],["new",1578.25,5807.0],["new",1578.3,11739.0],["new",1578.35,7749.0],["new",1578.4,16025.0],["change",1578.65,33598.0],["change",1578.7,28206.0],["change",1578.75,74314.0],["change",1578.8,3119.0],["change",1578.85,7470.0],["change",1578.9,100.0],["delete",1579.0,0.0],["delete",1579.05,0.0],["delete",1579.1,0.0]],"prev_change_id":23707128705}}}
[2025-04-07 08:30:08.156] [multi_sink] [info] 📩 Received: {"jsonrpc":"2.0","method":"subscription","params":{"channel":"book.ETH-PERPETUAL.100ms","data":{"timestamp":1743994809485,"type":"change","change_id":23707129028,"instrument_name":"ETH-PERPETUAL","bids":[["new",1577.9,1778.0],["change",1576.95,36951.0]],"asks":[["new",1577.95,37924.0],["delete",1579.15,0.0]],"prev_change_id":23707128984}}}
[2025-04-07 08:30:08.161] [multi_sink] [info] Processing received message: {"jsonrpc":"2.0","method":"subscription","params":{"channel":"book.ETH-PERPETUAL.100ms","data":{"timestamp":1743994809485,"type":"change","change_id":23707129028,"instrument_name":"ETH-PERPETUAL","bids":[["new",1577.9,1778.0],["change",1576.95,36951.0]],"asks":[["new",1577.95,37924.0],["delete",1579.15,0.0]],"prev_change_id":23707128984}}}
[2025-04-07 08:30:08.641] [multi_sink] [info] 📩 Received: {"jsonrpc":"2.0","method":"subscription","params":{"channel":"book.BTC-PERPETUAL.100ms","data":{"timestamp":1743994810254,"type":"change","change_id":41151870982,"instrument_name":"BTC-PERPETUAL","bids":[["delete",78231.0,0.0],["new",78220.0,78220.0],["delete",78181.0,0.0],["new",78170.0,117250.0]],"asks":[["new",78557.5,78550.0],["delete",78569.0,0.0],["new",78607.5,1.179e5],["delete",78619.0,0.0]],"prev_change_id":41151868571}}}
[2025-04-07 08:30:08.642] [multi_sink] [info] Processing received message: {"jsonrpc":"2.0","method":"subscription","params":{"channel":"book.BTC-PERPETUAL.100ms","data":{"timestamp":1743994810254,"type":"change","change_id":41151870982,"instrument_name":"BTC-PERPETUAL","bids":[["delete",78231.0,0.0],["new",78220.0,78220.0],["delete",78181.0,0.0],["new",78170.0,117250.0]],"asks":[["new",78557.5,78550.0],["delete",78569.0,0.0],["new",78607.5,1.179e5],["delete",78619.0,0.0]],"prev_change_id":41151868571}}}
[2025-04-07 08:30:08.972] [multi_sink] [info] 📩 Received: {"jsonrpc":"2.0","method":"subscription","params":{"channel":"book.BTC-PERPETUAL.100ms","data":{"timestamp":1743994810601,"type":"change","change_id":41151871279,"instrument_name":"BTC-PERPETUAL","bids":[["delete",78407.0,0.0],["delete",78397.5,0.0],["delete",78397.0,0.0],["delete",78395.0,0.0],["delete",78392.5,0.0],["delete",78390.0,0.0],["delete",78387.5,0.0],["change",78380.0,38330.0],["new",78379.0,490.0],["new",78378.0,1.0e4],["new",78377.5,9450.0],["change",78377.0,32980.0],["change",78376.5,8.0e4]],"asks":[["delete",78407.5,0.0],["delete",78408.0,0.0],["delete",78408.5,0.0],["delete",78409.0,0.0],["delete",78409.5,0.0],["delete",78410.0,0.0],["delete",78410.5,0.0],["delete",78411.5,0.0],["change",78417.5,33750.0],["new",78418.0,150390.0],["change",78419.5,31420.0],["change",78420.0,34860.0],["change",78420.5,20430.0],["change",78422.5,51240.0],["change",78423.0,78790.0],["new",78424.0,108760.0]],"prev_change_id":41151870982}}}
[2025-04-07 08:30:08.976] [multi_sink] [info] Processing received message: {"jsonrpc":"2.0","method":"subscription","params":{"channel":"book.BTC-PERPETUAL.100ms","data":{"timestamp":1743994810601,"type":"change","change_id":41151871279,"instrument_name":"BTC-PERPETUAL","bids":[["delete",78407.0,0.0],["delete",78397.5,0.0],["delete",78397.0,0.0],["delete",78395.0,0.0],["delete",78392.5,0.0],["delete",78390.0,0.0],["delete",78387.5,0.0],["change",78380.0,38330.0],["new",78379.0,490.0],["new",78378.0,1.0e4],["new",78377.5,9450.0],["change",78377.0,32980.0],["change",78376.5,8.0e4]],"asks":[["delete",78407.5,0.0],["delete",78408.0,0.0],["delete",78408.5,0.0],["delete",78409.0,0.0],["delete",78409.5,0.0],["delete",78410.0,0.0],["delete",78410.5,0.0],["delete",78411.5,0.0],["change",78417.5,33750.0],["new",78418.0,150390.0],["change",78419.5,31420.0],["change",78420.0,34860.0],["change",78420.5,20430.0],["change",78422.5,51240.0],["change",78423.0,78790.0],["new",78424.0,108760.0]],"prev_change_id":41151870982}}}
[2025-04-07 08:30:09.303] [multi_sink] [info] 📩 Received: {"jsonrpc":"2.0","method":"subscription","params":{"channel":"book.BTC-PERPETUAL.100ms","data":{"timestamp":1743994810905,"type":"change","change_id":41151871874,"instrument_name":"BTC-PERPETUAL","bids":[["new",78395.0,200.0],["new",78392.5,220.0],["new",78390.0,1390.0],["new",78386.0,480.0],["change",78385.0,2030.0],["delete",78384.5,0.0],["delete",78383.5,0.0],["new",78383.0,10440.0],["change",78382.5,510.0],["delete",78382.0,0.0],["delete",78381.5,0.0],["change",78381.0,3840.0],["change",78380.5,32980.0],["change",78380.0,17980.0]],"asks":[["new",78410.5,3.5e4],["change",78412.0,2.76e4],["new",78414.5,160.0],["change",78415.0,520.0],["new",78415.5,1.0e4],["change",78416.5,57210.0],["new",78417.0,1.0e4],["change",78417.5,1010.0],["change",78419.5,17630.0],["change",78420.0,2.0e4],["change",78420.5,10430.0]],"prev_change_id":41151871279}}}
[2025-04-07 08:30:09.306] [multi_sink] [info] Processing received message: {"jsonrpc":"2.0","method":"subscription","params":{"channel":"book.BTC-PERPETUAL.100ms","data":{"timestamp":1743994810905,"type":"change","change_id":41151871874,"instrument_name":"BTC-PERPETUAL","bids":[["new",78395.0,200.0],["new",78392.5,220.0],["new",78390.0,1390.0],["new",78386.0,480.0],["change",78385.0,2030.0],["delete",78384.5,0.0],["delete",78383.5,0.0],["new",78383.0,10440.0],["change",78382.5,510.0],["delete",78382.0,0.0],["delete",78381.5,0.0],["change",78381.0,3840.0],["change",78380.5,32980.0],["change",78380.0,17980.0]],"asks":[["new",78410.5,3.5e4],["change",78412.0,2.76e4],["new",78414.5,160.0],["change",78415.0,520.0],["new",78415.5,1.0e4],["change",78416.5,57210.0],["new",78417.0,1.0e4],["change",78417.5,1010.0],["change",78419.5,17630.0],["change",78420.0,2.0e4],["change",78420.5,10430.0]],"prev_change_id":41151871279}}}
[2025-04-07 08:30:09.342] [multi_sink] [info] 📩 Received: {"jsonrpc":"2.0","method":"subscription","params":{"channel":"book.ETH-PERPETUAL.100ms","data":{"timestamp":1743994810972,"type":"change","change_id":23707130611,"instrument_name":"ETH-PERPETUAL","bids":[["change",1577.45,3654.0],["change",1577.15,7748832.0]],"asks":[],"prev_change_id":23707129028}}}
[2025-04-07 08:30:09.344] [multi_sink] [info] Processing received message: {"jsonrpc":"2.0","method":"subscription","params":{"channel":"book.ETH-PERPETUAL.100ms","data":{"timestamp":1743994810972,"type":"change","change_id":23707130611,"instrument_name":"ETH-PERPETUAL","bids":[["change",1577.45,3654.0],["change",1577.15,7748832.0]],"asks":[],"prev_change_id":23707129028}}}
[2025-04-07 08:30:09.633] [multi_sink] [info] 📩 Received: {"jsonrpc":"2.0","method":"subscription","params":{"channel":"book.BTC-PERPETUAL.100ms","data":{"timestamp":1743994811058,"type":"change","change_id":41151872445,"instrument_name":"BTC-PERPETUAL","bids":[["new",78407.0,20590.0],["new",7.84e4,250.0],["new",78397.5,190.0],["new",78397.0,20.0],["change",78377.0,16490.0],["change",78376.5,4.0e4],["delete",78375.0,0.0],["delete",78371.5,0.0]],"asks":[["new",78407.5,340330.0],["new",78408.0,4.53e4],["new",78408.5,9460.0],["new",78410.0,1010.0],["change",78422.5,50880.0],["change",78423.0,39630.0],["delete",78425.0,0.0],["delete",78425.5,0.0]],"prev_change_id":41151871874}}}
[2025-04-07 08:30:09.637] [multi_sink] [info] Processing received message: {"jsonrpc":"2.0","method":"subscription","params":{"channel":"book.BTC-PERPETUAL.100ms","data":{"timestamp":1743994811058,"type":"change","change_id":41151872445,"instrument_name":"BTC-PERPETUAL","bids":[["new",78407.0,20590.0],["new",7.84e4,250.0],["new",78397.5,190.0],["new",78397.0,20.0],["change",78377.0,16490.0],["change",78376.5,4.0e4],["delete",78375.0,0.0],["delete",78371.5,0.0]],"asks":[["new",78407.5,340330.0],["new",78408.0,4.53e4],["new",78408.5,9460.0],["new",78410.0,1010.0],["change",78422.5,50880.0],["change",78423.0,39630.0],["delete",78425.0,0.0],["delete",78425.5,0.0]],"prev_change_id":41151871874}}}
[2025-04-07 08:30:09.974] [multi_sink] [info] 📩 Received: {"jsonrpc":"2.0","method":"subscription","params":{"channel":"book.BTC-PERPETUAL.100ms","data":{"timestamp":1743994811584,"type":"change","change_id":41151872893,"instrument_name":"BTC-PERPETUAL","bids":[],"asks":[["new",78546.5,78540.0],["delete",78557.5,0.0],["new",78596.5,117890.0],["delete",78607.5,0.0]],"prev_change_id":41151872445}}}
[2025-04-07 08:30:09.978] [multi_sink] [info] Processing received message: {"jsonrpc":"2.0","method":"subscription","params":{"channel":"book.BTC-PERPETUAL.100ms","data":{"timestamp":1743994811584,"type":"change","change_id":41151872893,"instrument_name":"BTC-PERPETUAL","bids":[],"asks":[["new",78546.5,78540.0],["delete",78557.5,0.0],["new",78596.5,117890.0],["delete",78607.5,0.0]],"prev_change_id":41151872445}}}
[2025-04-07 08:30:10.001] [multi_sink] [info] 📩 Received: {"jsonrpc":"2.0","method":"subscription","params":{"channel":"book.ETH-PERPETUAL.100ms","data":{"timestamp":1743994811305,"type":"change","change_id":23707130882,"instrument_name":"ETH-PERPETUAL","bids":[],"asks":[["change",1578.65,6192866.0],["delete",1578.95,0.0]],"prev_change_id":23707130611}}}
[2025-04-07 08:30:10.003] [multi_sink] [info] Processing received message: {"jsonrpc":"2.0","method":"subscription","params":{"channel":"book.ETH-PERPETUAL.100ms","data":{"timestamp":1743994811305,"type":"change","change_id":23707130882,"instrument_name":"ETH-PERPETUAL","bids":[],"asks":[["change",1578.65,6192866.0],["delete",1578.95,0.0]],"prev_change_id":23707130611}}}
[2025-04-07 08:30:11.663] [multi_sink] [info] 📩 Received: {"jsonrpc":"2.0","method":"subscription","params":{"channel":"book.BTC-PERPETUAL.100ms","data":{"timestamp":1743994813116,"type":"change","change_id":41151875440,"instrument_name":"BTC-PERPETUAL","bids":[["delete",78220.0,0.0],["new",78208.5,7.82e4],["delete",78170.0,0.0],["new",78158.5,117230.0]],"asks":[],"prev_change_id":41151872893}}}
[2025-04-07 08:30:11.667] [multi_sink] [info] Processing received message: {"jsonrpc":"2.0","method":"subscription","params":{"channel":"book.BTC-PERPETUAL.100ms","data":{"timestamp":1743994813116,"type":"change","change_id":41151875440,"instrument_name":"BTC-PERPETUAL","bids":[["delete",78220.0,0.0],["new",78208.5,7.82e4],["delete",78170.0,0.0],["new",78158.5,117230.0]],"asks":[],"prev_change_id":41151872893}}}
[2025-04-07 08:30:12.164] [multi_sink] [info] 📩 Received: {"jsonrpc":"2.0","method":"subscription","params":{"channel":"book.ETH-PERPETUAL.100ms","data":{"timestamp":1743994813797,"type":"change","change_id":23707133157,"instrument_name":"ETH-PERPETUAL","bids":[],"asks":[["delete",1577.95,0.0],["change",1578.8,6238.0]],"prev_change_id":23707130882}}}
[2025-04-07 08:30:12.167] [multi_sink] [info] Processing received message: {"jsonrpc":"2.0","method":"subscription","params":{"channel":"book.ETH-PERPETUAL.100ms","data":{"timestamp":1743994813797,"type":"change","change_id":23707133157,"instrument_name":"ETH-PERPETUAL","bids":[],"asks":[["delete",1577.95,0.0],["change",1578.8,6238.0]],"prev_change_id":23707130882}}}
[2025-04-07 08:30:12.505] [multi_sink] [info] 📩 Received: {"jsonrpc":"2.0","method":"subscription","params":{"channel":"book.ETH-PERPETUAL.100ms","data":{"timestamp":1743994814103,"type":"change","change_id":23707133553,"instrument_name":"ETH-PERPETUAL","bids":[["delete",1577.9,0.0],["delete",1577.75,0.0],["delete",1577.7,0.0],["delete",1577.65,0.0],["delete",1577.6,0.0],["delete",1577.55,0.0],["delete",1577.5,0.0],["delete",1577.45,0.0],["delete",1577.4,0.0],["change",1576.9,21635.0],["change",1576.85,31452.0],["new",1576.8,36946.0],["new",1576.75,9880.0],["new",1576.7,1934.0],["new",1576.65,6251.0],["new",1576.6,10780.0],["new",1576.55,8184.0],["new",1576.5,8554.0]],"asks":[["delete",1578.0,0.0],["delete",1578.05,0.0],["delete",1578.1,0.0],["delete",1578.15,0.0],["delete",1578.2,0.0],["delete",1578.25,0.0],["delete",1578.3,0.0],["delete",1578.35,0.0],["change",1578.4,49720.0],["change",1578.45,3.1e3],["change",1578.5,27853.0],["change",1578.55,49485.0],["change",1578.6,30570.0],["change",1578.65,6241364.0],["change",1578.7,48769.0],["change",1578.75,75004.0]],"prev_change_id":23707133157}}}
[2025-04-07 08:30:12.507] [multi_sink] [info] Processing received message: {"jsonrpc":"2.0","method":"subscription","params":{"channel":"book.ETH-PERPETUAL.100ms","data":{"timestamp":1743994814103,"type":"change","change_id":23707133553,"instrument_name":"ETH-PERPETUAL","bids":[["delete",1577.9,0.0],["delete",1577.75,0.0],["delete",1577.7,0.0],["delete",1577.65,0.0],["delete",1577.6,0.0],["delete",1577.55,0.0],["delete",1577.5,0.0],["delete",1577.45,0.0],["delete",1577.4,0.0],["change",1576.9,21635.0],["change",1576.85,31452.0],["new",1576.8,36946.0],["new",1576.75,9880.0],["new",1576.7,1934.0],["new",1576.65,6251.0],["new",1576.6,10780.0],["new",1576.55,8184.0],["new",1576.5,8554.0]],"asks":[["delete",1578.0,0.0],["delete",1578.05,0.0],["delete",1578.1,0.0],["delete",1578.15,0.0],["delete",1578.2,0.0],["delete",1578.25,0.0],["delete",1578.3,0.0],["delete",1578.35,0.0],["change",1578.4,49720.0],["change",1578.45,3.1e3],["change",1578.5,27853.0],["change",1578.55,49485.0],["change",1578.6,30570.0],["change",1578.65,6241364.0],["change",1578.7,48769.0],["change",1578.75,75004.0]],"prev_change_id":23707133157}}}
[2025-04-07 08:30:12.670] [multi_sink] [info] 📩 Received: {"jsonrpc":"2.0","method":"subscription","params":{"channel":"book.BTC-PERPETUAL.100ms","data":{"timestamp":1743994814170,"type":"change","change_id":41151876790,"instrument_name":"BTC-PERPETUAL","bids":[["new",78220.0,78220.0],["delete",78208.5,0.0],["new",78170.0,117250.0],["delete",78158.5,0.0]],"asks":[],"prev_change_id":41151875440}}}
[2025-04-07 08:30:12.675] [multi_sink] [info] Processing received message: {"jsonrpc":"2.0","method":"subscription","params":{"channel":"book.BTC-PERPETUAL.100ms","data":{"timestamp":1743994814170,"type":"change","change_id":41151876790,"instrument_name":"BTC-PERPETUAL","bids":[["new",78220.0,78220.0],["delete",78208.5,0.0],["new",78170.0,117250.0],["delete",78158.5,0.0]],"asks":[],"prev_change_id":41151875440}}}
[2025-04-07 08:30:12.837] [multi_sink] [info] 📩 Received: {"jsonrpc":"2.0","method":"subscription","params":{"channel":"book.ETH-PERPETUAL.100ms","data":{"timestamp":1743994814447,"type":"change","change_id":23707133822,"instrument_name":"ETH-PERPETUAL","bids":[["new",1577.4,45473.0],["delete",1577.35,0.0],["change",1577.3,23007.0],["change",1577.25,80461.0],["change",1577.2,1314.0],["change",1577.15,7753010.0],["change",1577.1,14093.0],["change",1577.05,13204.0],["change",1577.0,15311.0],["change",1576.95,48996.0]],"asks":[["new",1577.85,9918.0],["new",1577.95,152.0],["new",1578.0,100.0],["new",1578.1,5919.0],["new",1578.15,15117.0],["new",1578.2,23483.0],["new",1578.25,87224.0],["new",1578.3,27916.0],["new",1578.35,7749.0],["change",1578.4,33695.0],["change",1578.45,1028.0],["change",1578.5,12851.0],["change",1578.55,35483.0],["change",1578.6,15863.0],["change",1578.65,6207766.0],["change",1578.7,20563.0],["change",1578.75,690.0],["change",1578.8,3119.0]],"prev_change_id":23707133553}}}
[2025-04-07 08:30:12.841] [multi_sink] [info] Processing received message: {"jsonrpc":"2.0","method":"subscription","params":{"channel":"book.ETH-PERPETUAL.100ms","data":{"timestamp":1743994814447,"type":"change","change_id":23707133822,"instrument_name":"ETH-PERPETUAL","bids":[["new",1577.4,45473.0],["delete",1577.35,0.0],["change",1577.3,23007.0],["change",1577.25,80461.0],["change",1577.2,1314.0],["change",1577.15,7753010.0],["change",1577.1,14093.0],["change",1577.05,13204.0],["change",1577.0,15311.0],["change",1576.95,48996.0]],"asks":[["new",1577.85,9918.0],["new",1577.95,152.0],["new",1578.0,100.0],["new",1578.1,5919.0],["new",1578.15,15117.0],["new",1578.2,23483.0],["new",1578.25,87224.0],["new",1578.3,27916.0],["new",1578.35,7749.0],["change",1578.4,33695.0],["change",1578.45,1028.0],["change",1578.5,12851.0],["change",1578.55,35483.0],["change",1578.6,15863.0],["change",1578.65,6207766.0],["change",1578.7,20563.0],["change",1578.75,690.0],["change",1578.8,3119.0]],"prev_change_id":23707133553}}}
[2025-04-07 08:30:13.007] [multi_sink] [info] 📩 Received: {"jsonrpc":"2.0","method":"subscription","params":{"channel":"book.BTC-PERPETUAL.100ms","data":{"timestamp":1743994814506,"type":"change","change_id":41151876996,"instrument_name":"BTC-PERPETUAL","bids":[["delete",78220.0,0.0],["delete",78170.0,0.0]],"asks":[["delete",78546.5,0.0],["new",78558.5,78550.0],["delete",78596.5,0.0],["new",78608.5,1.179e5]],"prev_change_id":41151876790}}}
[2025-04-07 08:30:13.008] [multi_sink] [info] Processing received message: {"jsonrpc":"2.0","method":"subscription","params":{"channel":"book.BTC-PERPETUAL.100ms","data":{"timestamp":1743994814506,"type":"change","change_id":41151876996,"instrument_name":"BTC-PERPETUAL","bids":[["delete",78220.0,0.0],["delete",78170.0,0.0]],"asks":[["delete",78546.5,0.0],["new",78558.5,78550.0],["delete",78596.5,0.0],["new",78608.5,1.179e5]],"prev_change_id":41151876790}}}
[2025-04-07 08:30:13.161] [multi_sink] [info] 📩 Received: {"jsonrpc":"2.0","method":"subscription","params":{"channel":"book.ETH-PERPETUAL.100ms","data":{"timestamp":1743994814518,"type":"change","change_id":23707133878,"instrument_name":"ETH-PERPETUAL","bids":[["new",1577.5,19540.0],["new",1577.45,31902.0],["change",1576.9,11814.0],["change",1576.85,14638.0]],"asks":[["new",1577.75,34147.0],["new",1577.8,67242.0],["delete",1578.85,0.0],["delete",1578.9,0.0]],"prev_change_id":23707133822}}}
[2025-04-07 08:30:13.163] [multi_sink] [info] Processing received message: {"jsonrpc":"2.0","method":"subscription","params":{"channel":"book.ETH-PERPETUAL.100ms","data":{"timestamp":1743994814518,"type":"change","change_id":23707133878,"instrument_name":"ETH-PERPETUAL","bids":[["new",1577.5,19540.0],["new",1577.45,31902.0],["change",1576.9,11814.0],["change",1576.85,14638.0]],"asks":[["new",1577.75,34147.0],["new",1577.8,67242.0],["delete",1578.85,0.0],["delete",1578.9,0.0]],"prev_change_id":23707133822}}}
[2025-04-07 08:30:13.347] [multi_sink] [info] 📩 Received: {"jsonrpc":"2.0","method":"subscription","params":{"channel":"book.BTC-PERPETUAL.100ms","data":{"timestamp":1743994814753,"type":"change","change_id":41151877277,"instrument_name":"BTC-PERPETUAL","bids":[],"asks":[["delete",78558.5,0.0],["delete",78608.5,0.0]],"prev_change_id":41151876996}}}
[2025-04-07 08:30:13.349] [multi_sink] [info] Processing received message: {"jsonrpc":"2.0","method":"subscription","params":{"channel":"book.BTC-PERPETUAL.100ms","data":{"timestamp":1743994814753,"type":"change","change_id":41151877277,"instrument_name":"BTC-PERPETUAL","bids":[],"asks":[["delete",78558.5,0.0],["delete",78608.5,0.0]],"prev_change_id":41151876996}}}
[2025-04-07 08:30:13.995] [multi_sink] [info] 📩 Received: {"jsonrpc":"2.0","method":"subscription","params":{"channel":"book.BTC-PERPETUAL.100ms","data":{"timestamp":1743994815606,"type":"change","change_id":41151878514,"instrument_name":"BTC-PERPETUAL","bids":[["delete",78407.0,0.0],["delete",7.84e4,0.0],["delete",78397.5,0.0],["delete",78397.0,0.0],["delete",78395.0,0.0],["delete",78392.5,0.0],["delete",78390.0,0.0],["delete",78386.0,0.0],["new",78383.5,31840.0],["change",78383.0,50440.0],["change",78382.5,5880.0],["new",78382.0,33940.0],["change",78380.5,33150.0],["change",78379.0,5710.0],["change",78378.0,10190.0],["change",78377.0,21710.0],["delete",78368.5,0.0],["new",78351.5,7825720.0],["delete",78215.5,0.0],["new",78198.5,8000580.0]],"asks":[["delete",78407.5,0.0],["delete",78408.0,0.0],["delete",78408.5,0.0],["delete",78410.0,0.0],["delete",78410.5,0.0],["delete",78412.0,0.0],["new",78414.0,16490.0],["change",78414.5,33940.0],["change",78415.0,4.0e3],["change",78415.5,37990.0],["change",78416.0,163280.0],["change",78416.5,61380.0],["change",78417.0,1.55e4],["change",78417.5,2020.0]],"prev_change_id":41151877277}}}
[2025-04-07 08:30:13.999] [multi_sink] [info] Processing received message: {"jsonrpc":"2.0","method":"subscription","params":{"channel":"book.BTC-PERPETUAL.100ms","data":{"timestamp":1743994815606,"type":"change","change_id":41151878514,"instrument_name":"BTC-PERPETUAL","bids":[["delete",78407.0,0.0],["delete",7.84e4,0.0],["delete",78397.5,0.0],["delete",78397.0,0.0],["delete",78395.0,0.0],["delete",78392.5,0.0],["delete",78390.0,0.0],["delete",78386.0,0.0],["new",78383.5,31840.0],["change",78383.0,50440.0],["change",78382.5,5880.0],["new",78382.0,33940.0],["change",78380.5,33150.0],["change",78379.0,5710.0],["change",78378.0,10190.0],["change",78377.0,21710.0],["delete",78368.5,0.0],["new",78351.5,7825720.0],["delete",78215.5,0.0],["new",78198.5,8000580.0]],"asks":[["delete",78407.5,0.0],["delete",78408.0,0.0],["delete",78408.5,0.0],["delete",78410.0,0.0],["delete",78410.5,0.0],["delete",78412.0,0.0],["new",78414.0,16490.0],["change",78414.5,33940.0],["change",78415.0,4.0e3],["change",78415.5,37990.0],["change",78416.0,163280.0],["change",78416.5,61380.0],["change",78417.0,1.55e4],["change",78417.5,2020.0]],"prev_change_id":41151877277}}}
[2025-04-07 08:30:14.324] [multi_sink] [info] 📩 Received: {"jsonrpc":"2.0","method":"subscription","params":{"channel":"book.BTC-PERPETUAL.100ms","data":{"timestamp":1743994815945,"type":"change","change_id":41151879119,"instrument_name":"BTC-PERPETUAL","bids":[["new",78393.0,490.0],["new",78392.5,14510.0],["new",78392.0,63280.0],["new",78391.5,29040.0],["new",78391.0,16490.0],["new",78390.0,690.0],["new",78386.0,5560.0],["new",78385.5,16490.0],["change",78383.0,4.0e4],["change",78382.5,5370.0],["delete",78381.0,0.0],["change",78380.5,170.0],["delete",78380.0,0.0],["change",78379.0,5220.0],["change",78378.0,190.0],["delete",78377.5,0.0]],"asks":[["new",78403.0,9450.0],["new",78404.0,470.0],["new",78406.5,3590.0],["new",78407.0,1.0e4],["new",78407.5,280.0],["new",78409.0,16730.0],["new",78410.0,1010.0],["new",78411.5,16980.0],["new",78412.0,75270.0],["change",78415.5,27990.0],["change",78416.0,81640.0],["change",78416.5,4170.0],["change",78417.0,5.5e3],["change",78417.5,1010.0],["delete",78418.0,0.0],["delete",78419.5,0.0],["delete",78420.0,0.0],["delete",78420.5,0.0],["new",78429.0,6640830.0],["delete",78446.0,0.0],["new",78582.0,7777770.0],["delete",78599.0,0.0]],"prev_change_id":41151878514}}}
[2025-04-07 08:30:14.329] [multi_sink] [info] Processing received message: {"jsonrpc":"2.0","method":"subscription","params":{"channel":"book.BTC-PERPETUAL.100ms","data":{"timestamp":1743994815945,"type":"change","change_id":41151879119,"instrument_name":"BTC-PERPETUAL","bids":[["new",78393.0,490.0],["new",78392.5,14510.0],["new",78392.0,63280.0],["new",78391.5,29040.0],["new",78391.0,16490.0],["new",78390.0,690.0],["new",78386.0,5560.0],["new",78385.5,16490.0],["change",78383.0,4.0e4],["change",78382.5,5370.0],["delete",78381.0,0.0],["change",78380.5,170.0],["delete",78380.0,0.0],["change",78379.0,5220.0],["change",78378.0,190.0],["delete",78377.5,0.0]],"asks":[["new",78403.0,9450.0],["new",78404.0,470.0],["new",78406.5,3590.0],["new",78407.0,1.0e4],["new",78407.5,280.0],["new",78409.0,16730.0],["new",78410.0,1010.0],["new",78411.5,16980.0],["new",78412.0,75270.0],["change",78415.5,27990.0],["change",78416.0,81640.0],["change",78416.5,4170.0],["change",78417.0,5.5e3],["change",78417.5,1010.0],["delete",78418.0,0.0],["delete",78419.5,0.0],["delete",78420.0,0.0],["delete",78420.5,0.0],["new",78429.0,6640830.0],["delete",78446.0,0.0],["new",78582.0,7777770.0],["delete",78599.0,0.0]],"prev_change_id":41151878514}}}
[2025-04-07 08:30:14.656] [multi_sink] [info] 📩 Received: {"jsonrpc":"2.0","method":"subscription","params":{"channel":"book.BTC-PERPETUAL.100ms","data":{"timestamp":1743994816051,"type":"change","change_id":41151879690,"instrument_name":"BTC-PERPETUAL","bids":[["new",7.84e4,82850.0],["new",78399.5,2.22e4],["new",78399.0,440.0],["change",78377.0,5220.0],["delete",78376.5,0.0]],"asks":[["new",78400.5,7470.0],["new",78401.5,430.0],["new",78402.5,2980.0],["delete",78422.5,0.0],["delete",78423.0,0.0],["delete",78424.0,0.0]],"prev_change_id":41151879119}}}
[2025-04-07 08:30:14.658] [multi_sink] [info] Processing received message: {"jsonrpc":"2.0","method":"subscription","params":{"channel":"book.BTC-PERPETUAL.100ms","data":{"timestamp":1743994816051,"type":"change","change_id":41151879690,"instrument_name":"BTC-PERPETUAL","bids":[["new",7.84e4,82850.0],["new",78399.5,2.22e4],["new",78399.0,440.0],["change",78377.0,5220.0],["delete",78376.5,0.0]],"asks":[["new",78400.5,7470.0],["new",78401.5,430.0],["new",78402.5,2980.0],["delete",78422.5,0.0],["delete",78423.0,0.0],["delete",78424.0,0.0]],"prev_change_id":41151879119}}}
[2025-04-07 08:30:14.989] [multi_sink] [info] 📩 Received: {"jsonrpc":"2.0","method":"subscription","params":{"channel":"book.BTC-PERPETUAL.100ms","data":{"timestamp":1743994816515,"type":"change","change_id":41151880136,"instrument_name":"BTC-PERPETUAL","bids":[["new",78230.5,78230.0],["new",78180.5,117270.0]],"asks":[["new",78564.5,78560.0],["new",78614.5,117920.0]],"prev_change_id":41151879690}}}
[2025-04-07 08:30:14.994] [multi_sink] [info] Processing received message: {"jsonrpc":"2.0","method":"subscription","params":{"channel":"book.BTC-PERPETUAL.100ms","data":{"timestamp":1743994816515,"type":"change","change_id":41151880136,"instrument_name":"BTC-PERPETUAL","bids":[["new",78230.5,78230.0],["new",78180.5,117270.0]],"asks":[["new",78564.5,78560.0],["new",78614.5,117920.0]],"prev_change_id":41151879690}}}
[2025-04-07 08:30:16.796] [multi_sink] [info] 📩 Received: {"jsonrpc":"2.0","method":"subscription","params":{"channel":"book.ETH-PERPETUAL.100ms","data":{"timestamp":1743994818218,"type":"change","change_id":23707137996,"instrument_name":"ETH-PERPETUAL","bids":[["change",1577.4,7790027.0],["change",1577.15,8456.0]],"asks":[],"prev_change_id":23707133878}}}
[2025-04-07 08:30:16.799] [multi_sink] [info] Processing received message: {"jsonrpc":"2.0","method":"subscription","params":{"channel":"book.ETH-PERPETUAL.100ms","data":{"timestamp":1743994818218,"type":"change","change_id":23707137996,"instrument_name":"ETH-PERPETUAL","bids":[["change",1577.4,7790027.0],["change",1577.15,8456.0]],"asks":[],"prev_change_id":23707133878}}}
[2025-04-07 08:30:17.031] [multi_sink] [info] 📩 Received: {"jsonrpc":"2.0","method":"subscription","params":{"channel":"book.BTC-PERPETUAL.100ms","data":{"timestamp":1743994818588,"type":"change","change_id":41151883056,"instrument_name":"BTC-PERPETUAL","bids":[["delete",78230.5,0.0],["new",78218.5,78210.0],["delete",78180.5,0.0],["new",78168.5,117240.0]],"asks":[["new",78553.0,78550.0],["delete",78564.5,0.0],["new",78603.0,1.179e5],["delete",78614.5,0.0]],"prev_change_id":41151880136}}}
[2025-04-07 08:30:17.032] [multi_sink] [info] Processing received message: {"jsonrpc":"2.0","method":"subscription","params":{"channel":"book.BTC-PERPETUAL.100ms","data":{"timestamp":1743994818588,"type":"change","change_id":41151883056,"instrument_name":"BTC-PERPETUAL","bids":[["delete",78230.5,0.0],["new",78218.5,78210.0],["delete",78180.5,0.0],["new",78168.5,117240.0]],"asks":[["new",78553.0,78550.0],["delete",78564.5,0.0],["new",78603.0,1.179e5],["delete",78614.5,0.0]],"prev_change_id":41151880136}}}
[2025-04-07 08:30:17.114] [multi_sink] [info] 📩 Received: {"jsonrpc":"2.0","method":"subscription","params":{"channel":"book.ETH-PERPETUAL.100ms","data":{"timestamp":1743994818547,"type":"change","change_id":23707138217,"instrument_name":"ETH-PERPETUAL","bids":[],"asks":[["change",1578.65,48498.0],["new",1578.9,6159268.0]],"prev_change_id":23707137996}}}
[2025-04-07 08:30:17.116] [multi_sink] [info] Processing received message: {"jsonrpc":"2.0","method":"subscription","params":{"channel":"book.ETH-PERPETUAL.100ms","data":{"timestamp":1743994818547,"type":"change","change_id":23707138217,"instrument_name":"ETH-PERPETUAL","bids":[],"asks":[["change",1578.65,48498.0],["new",1578.9,6159268.0]],"prev_change_id":23707137996}}}
[2025-04-07 08:30:17.444] [multi_sink] [info] 📩 Received: {"jsonrpc":"2.0","method":"subscription","params":{"channel":"book.ETH-PERPETUAL.100ms","data":{"timestamp":1743994819050,"type":"change","change_id":23707138824,"instrument_name":"ETH-PERPETUAL","bids":[["delete",1577.5,0.0],["delete",1577.45,0.0],["change",1577.4,7744554.0],["delete",1577.3,0.0],["delete",1577.25,0.0],["change",1577.2,37796.0],["change",1577.15,7563.0],["change",1577.1,1745.0],["change",1577.05,26609.0],["change",1577.0,16338.0],["change",1576.95,93223.0],["change",1576.9,17612.0],["change",1576.85,34445.0]],"asks":[["delete",1577.75,0.0],["delete",1577.8,0.0],["delete",1577.85,0.0],["delete",1577.95,0.0],["delete",1578.0,0.0],["delete",1578.1,0.0],["delete",1578.15,0.0],["delete",1578.2,0.0],["change",1578.65,89525.0],["change",1578.7,93375.0],["change",1578.75,2168.0],["change",1578.8,8464.0],["new",1578.85,7470.0],["change",1578.9,6159368.0],["new",1579.0,51108.0],["new",1579.05,45069.0]],"prev_change_id":23707138217}}}
[2025-04-07 08:30:17.446] [multi_sink] [info] Processing received message: {"jsonrpc":"2.0","method":"subscription","params":{"channel":"book.ETH-PERPETUAL.100ms","data":{"timestamp":1743994819050,"type":"change","change_id":23707138824,"instrument_name":"ETH-PERPETUAL","bids":[["delete",1577.5,0.0],["delete",1577.45,0.0],["change",1577.4,7744554.0],["delete",1577.3,0.0],["delete",1577.25,0.0],["change",1577.2,37796.0],["change",1577.15,7563.0],["change",1577.1,1745.0],["change",1577.05,26609.0],["change",1577.0,16338.0],["change",1576.95,93223.0],["change",1576.9,17612.0],["change",1576.85,34445.0]],"asks":[["delete",1577.75,0.0],["delete",1577.8,0.0],["delete",1577.85,0.0],["delete",1577.95,0.0],["delete",1578.0,0.0],["delete",1578.1,0.0],["delete",1578.15,0.0],["delete",1578.2,0.0],["change",1578.65,89525.0],["change",1578.7,93375.0],["change",1578.75,2168.0],["change",1578.8,8464.0],["new",1578.85,7470.0],["change",1578.9,6159368.0],["new",1579.0,51108.0],["new",1579.05,45069.0]],"prev_change_id":23707138217}}}
[2025-04-07 08:30:17.772] [multi_sink] [info] 📩 Received: {"jsonrpc":"2.0","method":"subscription","params":{"channel":"book.ETH-PERPETUAL.100ms","data":{"timestamp":1743994819373,"type":"change","change_id":23707139206,"instrument_name":"ETH-PERPETUAL","bids":[["new",1577.75,7.14e4],["new",1577.7,179.0],["new",1577.65,5.0e3],["new",1577.6,32.0],["new",1577.5,3027.0],["new",1577.45,10089.0],["change",1577.4,7754883.0],["new",1577.3,17051.0],["new",1577.25,14919.0],["change",1577.05,13405.0],["change",1577.0,1027.0],["change",1576.95,44227.0],["change",1576.9,5798.0],["change",1576.85,19807.0],["delete",1576.8,0.0],["delete",1576.75,0.0],["delete",1576.7,0.0],["delete",1576.65,0.0]],"asks":[["new",1578.2,5.77e4],["change",1578.25,383.0],["change",1578.3,3889.0],["change",1578.35,13488.0],["change",1578.4,7534.0],["change",1578.45,4793.0],["change",1578.5,20424.0],["change",1578.55,21665.0],["change",1578.6,36168.0],["change",1578.65,41027.0]],"prev_change_id":23707138824}}}
[2025-04-07 08:30:17.773] [multi_sink] [info] Processing received message: {"jsonrpc":"2.0","method":"subscription","params":{"channel":"book.ETH-PERPETUAL.100ms","data":{"timestamp":1743994819373,"type":"change","change_id":23707139206,"instrument_name":"ETH-PERPETUAL","bids":[["new",1577.75,7.14e4],["new",1577.7,179.0],["new",1577.65,5.0e3],["new",1577.6,32.0],["new",1577.5,3027.0],["new",1577.45,10089.0],["change",1577.4,7754883.0],["new",1577.3,17051.0],["new",1577.25,14919.0],["change",1577.05,13405.0],["change",1577.0,1027.0],["change",1576.95,44227.0],["change",1576.9,5798.0],["change",1576.85,19807.0],["delete",1576.8,0.0],["delete",1576.75,0.0],["delete",1576.7,0.0],["delete",1576.65,0.0]],"asks":[["new",1578.2,5.77e4],["change",1578.25,383.0],["change",1578.3,3889.0],["change",1578.35,13488.0],["change",1578.4,7534.0],["change",1578.45,4793.0],["change",1578.5,20424.0],["change",1578.55,21665.0],["change",1578.6,36168.0],["change",1578.65,41027.0]],"prev_change_id":23707138824}}}
[2025-04-07 08:30:18.105] [multi_sink] [info] 📩 Received: {"jsonrpc":"2.0","method":"subscription","params":{"channel":"book.ETH-PERPETUAL.100ms","data":{"timestamp":1743994819483,"type":"change","change_id":23707139346,"instrument_name":"ETH-PERPETUAL","bids":[["new",1578.0,70.0],["new",1577.9,423.0],["new",1577.8,9916.0],["delete",1576.6,0.0],["delete",1576.55,0.0],["delete",1576.5,0.0]],"asks":[["new",1578.05,40691.0],["new",1578.1,31425.0],["new",1578.15,12735.0],["change",1578.7,72812.0],["change",1578.75,1478.0],["change",1578.8,5345.0]],"prev_change_id":23707139206}}}
[2025-04-07 08:30:18.107] [multi_sink] [info] Processing received message: {"jsonrpc":"2.0","method":"subscription","params":{"channel":"book.ETH-PERPETUAL.100ms","data":{"timestamp":1743994819483,"type":"change","change_id":23707139346,"instrument_name":"ETH-PERPETUAL","bids":[["new",1578.0,70.0],["new",1577.9,423.0],["new",1577.8,9916.0],["delete",1576.6,0.0],["delete",1576.55,0.0],["delete",1576.5,0.0]],"asks":[["new",1578.05,40691.0],["new",1578.1,31425.0],["new",1578.15,12735.0],["change",1578.7,72812.0],["change",1578.75,1478.0],["change",1578.8,5345.0]],"prev_change_id":23707139206}}}
[2025-04-07 08:30:18.712] [multi_sink] [info] 📩 Received: {"jsonrpc":"2.0","method":"subscription","params":{"channel":"book.BTC-PERPETUAL.100ms","data":{"timestamp":1743994820066,"type":"change","change_id":41151885471,"instrument_name":"BTC-PERPETUAL","bids":[["new",78229.0,78220.0],["delete",78218.5,0.0],["new",78179.0,117260.0],["delete",78168.5,0.0]],"asks":[["delete",78553.0,0.0],["delete",78603.0,0.0]],"prev_change_id":41151883056}}}
[2025-04-07 08:30:18.716] [multi_sink] [info] Processing received message: {"jsonrpc":"2.0","method":"subscription","params":{"channel":"book.BTC-PERPETUAL.100ms","data":{"timestamp":1743994820066,"type":"change","change_id":41151885471,"instrument_name":"BTC-PERPETUAL","bids":[["new",78229.0,78220.0],["delete",78218.5,0.0],["new",78179.0,117260.0],["delete",78168.5,0.0]],"asks":[["delete",78553.0,0.0],["delete",78603.0,0.0]],"prev_change_id":41151883056}}}
[2025-04-07 08:30:19.042] [multi_sink] [info] 📩 Received: {"jsonrpc":"2.0","method":"subscription","params":{"channel":"book.BTC-PERPETUAL.100ms","data":{"timestamp":1743994820649,"type":"change","change_id":41151885810,"instrument_name":"BTC-PERPETUAL","bids":[["delete",7.84e4,0.0],["delete",78399.5,0.0],["delete",78399.0,0.0],["delete",78393.0,0.0],["delete",78392.5,0.0],["delete",78392.0,0.0],["delete",78391.5,0.0],["delete",78391.0,0.0],["delete",78390.0,0.0],["new",78386.5,220.0],["change",78385.0,6980.0],["new",78384.5,16490.0],["new",78384.0,2.6e3],["change",78383.5,35140.0],["change",78382.5,5520.0],["change",78380.5,5390.0],["new",78380.0,16430.0],["new",78379.5,16490.0]],"asks":[["delete",78400.5,0.0],["delete",78401.5,0.0],["delete",78402.5,0.0],["delete",78403.0,0.0],["delete",78404.0,0.0],["new",78405.0,1.0e4],["new",78405.5,17440.0],["new",78406.0,510.0],["delete",78406.5,0.0],["change",78407.0,500.0],["change",78407.5,10270.0],["new",78408.0,5110.0],["new",78408.5,550.0],["delete",78409.0,0.0],["change",78410.0,1.75e4],["change",78412.0,144050.0],["new",78567.5,78560.0],["new",78617.5,117910.0]],"prev_change_id":41151885471}}}
[2025-04-07 08:30:19.046] [multi_sink] [info] Processing received message: {"jsonrpc":"2.0","method":"subscription","params":{"channel":"book.BTC-PERPETUAL.100ms","data":{"timestamp":1743994820649,"type":"change","change_id":41151885810,"instrument_name":"BTC-PERPETUAL","bids":[["delete",7.84e4,0.0],["delete",78399.5,0.0],["delete",78399.0,0.0],["delete",78393.0,0.0],["delete",78392.5,0.0],["delete",78392.0,0.0],["delete",78391.5,0.0],["delete",78391.0,0.0],["delete",78390.0,0.0],["new",78386.5,220.0],["change",78385.0,6980.0],["new",78384.5,16490.0],["new",78384.0,2.6e3],["change",78383.5,35140.0],["change",78382.5,5520.0],["change",78380.5,5390.0],["new",78380.0,16430.0],["new",78379.5,16490.0]],"asks":[["delete",78400.5,0.0],["delete",78401.5,0.0],["delete",78402.5,0.0],["delete",78403.0,0.0],["delete",78404.0,0.0],["new",78405.0,1.0e4],["new",78405.5,17440.0],["new",78406.0,510.0],["delete",78406.5,0.0],["change",78407.0,500.0],["change",78407.5,10270.0],["new",78408.0,5110.0],["new",78408.5,550.0],["delete",78409.0,0.0],["change",78410.0,1.75e4],["change",78412.0,144050.0],["new",78567.5,78560.0],["new",78617.5,117910.0]],"prev_change_id":41151885471}}}
[2025-04-07 08:30:19.375] [multi_sink] [info] 📩 Received: {"jsonrpc":"2.0","method":"subscription","params":{"channel":"book.BTC-PERPETUAL.100ms","data":{"timestamp":1743994821001,"type":"change","change_id":41151886428,"instrument_name":"BTC-PERPETUAL","bids":[["new",78394.0,170.0],["new",78392.5,6660.0],["new",78392.0,2.22e4],["new",78391.5,190.0],["new",78390.0,30.0],["new",78389.0,1.9e4],["new",78388.5,33940.0],["new",78388.0,16980.0],["new",78387.5,1010.0],["delete",78386.0,0.0],["delete",78385.5,0.0],["change",78385.0,4950.0],["change",78383.5,3.3e3],["delete",78383.0,0.0],["change",78382.5,150.0],["delete",78382.0,0.0],["change",78380.5,5220.0],["delete",78379.0,0.0]],"asks":[["new",78398.5,1.8e3],["new",78399.5,6.0e3],["new",7.84e4,4210.0],["new",78400.5,3380.0],["new",78401.0,430.0],["new",78402.5,9510.0],["new",78403.0,3840.0],["new",78403.5,470.0],["new",78404.0,8660.0],["new",78404.5,170.0],["change",78410.0,16490.0],["delete",78411.5,0.0],["change",78412.0,68780.0],["delete",78414.0,0.0],["delete",78414.5,0.0],["delete",78415.0,0.0],["delete",78415.5,0.0],["delete",78416.0,0.0],["delete",78416.5,0.0],["delete",78417.0,0.0]],"prev_change_id":41151885810}}}
[2025-04-07 08:30:19.377] [multi_sink] [info] Processing received message: {"jsonrpc":"2.0","method":"subscription","params":{"channel":"book.BTC-PERPETUAL.100ms","data":{"timestamp":1743994821001,"type":"change","change_id":41151886428,"instrument_name":"BTC-PERPETUAL","bids":[["new",78394.0,170.0],["new",78392.5,6660.0],["new",78392.0,2.22e4],["new",78391.5,190.0],["new",78390.0,30.0],["new",78389.0,1.9e4],["new",78388.5,33940.0],["new",78388.0,16980.0],["new",78387.5,1010.0],["delete",78386.0,0.0],["delete",78385.5,0.0],["change",78385.0,4950.0],["change",78383.5,3.3e3],["delete",78383.0,0.0],["change",78382.5,150.0],["delete",78382.0,0.0],["change",78380.5,5220.0],["delete",78379.0,0.0]],"asks":[["new",78398.5,1.8e3],["new",78399.5,6.0e3],["new",7.84e4,4210.0],["new",78400.5,3380.0],["new",78401.0,430.0],["new",78402.5,9510.0],["new",78403.0,3840.0],["new",78403.5,470.0],["new",78404.0,8660.0],["new",78404.5,170.0],["change",78410.0,16490.0],["delete",78411.5,0.0],["change",78412.0,68780.0],["delete",78414.0,0.0],["delete",78414.5,0.0],["delete",78415.0,0.0],["delete",78415.5,0.0],["delete",78416.0,0.0],["delete",78416.5,0.0],["delete",78417.0,0.0]],"prev_change_id":41151885810}}}
[2025-04-07 08:30:19.704] [multi_sink] [info] 📩 Received: {"jsonrpc":"2.0","method":"subscription","params":{"channel":"book.BTC-PERPETUAL.100ms","data":{"timestamp":1743994821077,"type":"change","change_id":41151886984,"instrument_name":"BTC-PERPETUAL","bids":[["new",78396.5,35890.0],["new",78395.0,940.0],["delete",78378.0,0.0],["delete",78377.0,0.0]],"asks":[["new",78397.0,10880.0],["delete",78417.5,0.0]],"prev_change_id":41151886428}}}
[2025-04-07 08:30:19.707] [multi_sink] [info] Processing received message: {"jsonrpc":"2.0","method":"subscription","params":{"channel":"book.BTC-PERPETUAL.100ms","data":{"timestamp":1743994821077,"type":"change","change_id":41151886984,"instrument_name":"BTC-PERPETUAL","bids":[["new",78396.5,35890.0],["new",78395.0,940.0],["delete",78378.0,0.0],["delete",78377.0,0.0]],"asks":[["new",78397.0,10880.0],["delete",78417.5,0.0]],"prev_change_id":41151886428}}}
[2025-04-07 08:30:20.726] [multi_sink] [info] 📩 Received: {"jsonrpc":"2.0","method":"subscription","params":{"channel":"book.BTC-PERPETUAL.100ms","data":{"timestamp":1743994822351,"type":"change","change_id":41151888722,"instrument_name":"BTC-PERPETUAL","bids":[["new",78240.5,78240.0],["delete",78229.0,0.0],["new",78190.5,117280.0],["delete",78179.0,0.0]],"asks":[],"prev_change_id":41151886984}}}
[2025-04-07 08:30:20.731] [multi_sink] [info] Processing received message: {"jsonrpc":"2.0","method":"subscription","params":{"channel":"book.BTC-PERPETUAL.100ms","data":{"timestamp":1743994822351,"type":"change","change_id":41151888722,"instrument_name":"BTC-PERPETUAL","bids":[["new",78240.5,78240.0],["delete",78229.0,0.0],["new",78190.5,117280.0],["delete",78179.0,0.0]],"asks":[],"prev_change_id":41151886984}}}
[2025-04-07 08:30:21.118] [multi_sink] [info] 📩 Received: {"jsonrpc":"2.0","method":"subscription","params":{"channel":"book.BTC-PERPETUAL.100ms","data":{"timestamp":1743994822751,"type":"change","change_id":41151889080,"instrument_name":"BTC-PERPETUAL","bids":[["new",78205.0,8000580.0],["delete",78198.5,0.0]],"asks":[],"prev_change_id":41151888722}}}
[2025-04-07 08:30:21.118] [multi_sink] [info] Processing received message: {"jsonrpc":"2.0","method":"subscription","params":{"channel":"book.BTC-PERPETUAL.100ms","data":{"timestamp":1743994822751,"type":"change","change_id":41151889080,"instrument_name":"BTC-PERPETUAL","bids":[["new",78205.0,8000580.0],["delete",78198.5,0.0]],"asks":[],"prev_change_id":41151888722}}}
[2025-04-07 08:30:21.461] [multi_sink] [info] 📩 Received: {"jsonrpc":"2.0","method":"subscription","params":{"channel":"book.BTC-PERPETUAL.100ms","data":{"timestamp":1743994823021,"type":"change","change_id":41151889438,"instrument_name":"BTC-PERPETUAL","bids":[["new",78358.0,7825720.0],["delete",78351.5,0.0],["delete",78240.5,0.0],["delete",78190.5,0.0]],"asks":[["delete",78567.5,0.0],["delete",78617.5,0.0]],"prev_change_id":41151889080}}}
[2025-04-07 08:30:21.463] [multi_sink] [info] Processing received message: {"jsonrpc":"2.0","method":"subscription","params":{"channel":"book.BTC-PERPETUAL.100ms","data":{"timestamp":1743994823021,"type":"change","change_id":41151889438,"instrument_name":"BTC-PERPETUAL","bids":[["new",78358.0,7825720.0],["delete",78351.5,0.0],["delete",78240.5,0.0],["delete",78190.5,0.0]],"asks":[["delete",78567.5,0.0],["delete",78617.5,0.0]],"prev_change_id":41151889080}}}
[2025-04-07 08:30:21.782] [multi_sink] [info] 📩 Received: {"jsonrpc":"2.0","method":"subscription","params":{"channel":"book.BTC-PERPETUAL.100ms","data":{"timestamp":1743994823095,"type":"change","change_id":41151889982,"instrument_name":"BTC-PERPETUAL","bids":[],"asks":[["delete",78429.0,0.0],["new",78435.5,6640830.0],["delete",78582.0,0.0],["new",78588.5,7777770.0]],"prev_change_id":41151889438}}}
[2025-04-07 08:30:21.784] [multi_sink] [info] Processing received message: {"jsonrpc":"2.0","method":"subscription","params":{"channel":"book.BTC-PERPETUAL.100ms","data":{"timestamp":1743994823095,"type":"change","change_id":41151889982,"instrument_name":"BTC-PERPETUAL","bids":[],"asks":[["delete",78429.0,0.0],["new",78435.5,6640830.0],["delete",78582.0,0.0],["new",78588.5,7777770.0]],"prev_change_id":41151889438}}}
[2025-04-07 08:30:22.165] [multi_sink] [info] 📩 Received: {"jsonrpc":"2.0","method":"subscription","params":{"channel":"book.ETH-PERPETUAL.100ms","data":{"timestamp":1743994823798,"type":"change","change_id":23707143498,"instrument_name":"ETH-PERPETUAL","bids":[],"asks":[["delete",1578.05,0.0],["new",1579.9,39021.0]],"prev_change_id":23707139346}}}
[2025-04-07 08:30:22.169] [multi_sink] [info] Processing received message: {"jsonrpc":"2.0","method":"subscription","params":{"channel":"book.ETH-PERPETUAL.100ms","data":{"timestamp":1743994823798,"type":"change","change_id":23707143498,"instrument_name":"ETH-PERPETUAL","bids":[],"asks":[["delete",1578.05,0.0],["new",1579.9,39021.0]],"prev_change_id":23707139346}}}
[2025-04-07 08:30:22.496] [multi_sink] [info] 📩 Received: {"jsonrpc":"2.0","method":"subscription","params":{"channel":"book.ETH-PERPETUAL.100ms","data":{"timestamp":1743994824120,"type":"change","change_id":23707143904,"instrument_name":"ETH-PERPETUAL","bids":[["change",1578.0,6011.0],["new",1577.95,31399.0],["change",1577.9,79466.0],["new",1577.85,2236.0],["change",1577.8,100.0],["change",1577.75,2778.0],["change",1577.7,7842.0],["change",1577.65,1418.0],["change",1577.6,1213.0],["delete",1577.5,0.0],["delete",1577.45,0.0]],"asks":[["delete",1578.1,0.0],["delete",1578.15,0.0],["delete",1578.2,0.0],["delete",1578.25,0.0],["delete",1578.3,0.0],["delete",1578.35,0.0],["delete",1578.4,0.0],["delete",1578.45,0.0],["delete",1578.5,0.0],["new",1579.45,3635.0],["new",1579.5,38293.0],["new",1579.55,15028.0],["new",1579.6,97597.0],["new",1579.65,3499.0],["new",1579.7,36212.0],["new",1579.75,2792.0],["new",1579.8,27389.0],["new",1579.85,59480.0]],"prev_change_id":23707143498}}}
[2025-04-07 08:30:22.499] [multi_sink] [info] Processing received message: {"jsonrpc":"2.0","method":"subscription","params":{"channel":"book.ETH-PERPETUAL.100ms","data":{"timestamp":1743994824120,"type":"change","change_id":23707143904,"instrument_name":"ETH-PERPETUAL","bids":[["change",1578.0,6011.0],["new",1577.95,31399.0],["change",1577.9,79466.0],["new",1577.85,2236.0],["change",1577.8,100.0],["change",1577.75,2778.0],["change",1577.7,7842.0],["change",1577.65,1418.0],["change",1577.6,1213.0],["delete",1577.5,0.0],["delete",1577.45,0.0]],"asks":[["delete",1578.1,0.0],["delete",1578.15,0.0],["delete",1578.2,0.0],["delete",1578.25,0.0],["delete",1578.3,0.0],["delete",1578.35,0.0],["delete",1578.4,0.0],["delete",1578.45,0.0],["delete",1578.5,0.0],["new",1579.45,3635.0],["new",1579.5,38293.0],["new",1579.55,15028.0],["new",1579.6,97597.0],["new",1579.65,3499.0],["new",1579.7,36212.0],["new",1579.75,2792.0],["new",1579.8,27389.0],["new",1579.85,59480.0]],"prev_change_id":23707143498}}}
[2025-04-07 08:30:22.826] [multi_sink] [info] 📩 Received: {"jsonrpc":"2.0","method":"subscription","params":{"channel":"book.ETH-PERPETUAL.100ms","data":{"timestamp":1743994824446,"type":"change","change_id":23707144364,"instrument_name":"ETH-PERPETUAL","bids":[["new",1578.5,29716.0],["new",1578.45,32446.0],["new",1578.4,95621.0],["new",1578.3,7663.0],["new",1578.25,2706.0],["new",1578.2,5161.0],["new",1578.15,6284.0],["new",1578.1,3.2e3],["new",1578.05,2512.0],["change",1577.4,7744554.0],["delete",1577.3,0.0],["delete",1577.25,0.0],["delete",1577.2,0.0],["delete",1577.15,0.0],["delete",1577.1,0.0],["delete",1577.05,0.0],["delete",1577.0,0.0],["delete",1576.95,0.0]],"asks":[["delete",1578.55,0.0],["delete",1578.6,0.0],["delete",1578.65,0.0],["delete",1578.7,0.0],["delete",1578.75,0.0],["delete",1578.8,0.0],["delete",1578.85,0.0],["change",1578.9,6159268.0],["new",1578.95,10596.0],["change",1579.0,18319.0],["new",1579.1,100.0],["new",1579.15,3004.0],["new",1579.2,20740.0],["new",1579.25,31119.0],["new",1579.3,2748.0],["new",1579.35,100.0],["new",1579.4,9719.0],["delete",1581.95,0.0],["new",1583.55,500.0],["delete",1591.25,0.0],["new",1594.45,700.0]],"prev_change_id":23707143904}}}
[2025-04-07 08:30:22.829] [multi_sink] [info] Processing received message: {"jsonrpc":"2.0","method":"subscription","params":{"channel":"book.ETH-PERPETUAL.100ms","data":{"timestamp":1743994824446,"type":"change","change_id":23707144364,"instrument_name":"ETH-PERPETUAL","bids":[["new",1578.5,29716.0],["new",1578.45,32446.0],["new",1578.4,95621.0],["new",1578.3,7663.0],["new",1578.25,2706.0],["new",1578.2,5161.0],["new",1578.15,6284.0],["new",1578.1,3.2e3],["new",1578.05,2512.0],["change",1577.4,7744554.0],["delete",1577.3,0.0],["delete",1577.25,0.0],["delete",1577.2,0.0],["delete",1577.15,0.0],["delete",1577.1,0.0],["delete",1577.05,0.0],["delete",1577.0,0.0],["delete",1576.95,0.0]],"asks":[["delete",1578.55,0.0],["delete",1578.6,0.0],["delete",1578.65,0.0],["delete",1578.7,0.0],["delete",1578.75,0.0],["delete",1578.8,0.0],["delete",1578.85,0.0],["change",1578.9,6159268.0],["new",1578.95,10596.0],["change",1579.0,18319.0],["new",1579.1,100.0],["new",1579.15,3004.0],["new",1579.2,20740.0],["new",1579.25,31119.0],["new",1579.3,2748.0],["new",1579.35,100.0],["new",1579.4,9719.0],["delete",1581.95,0.0],["new",1583.55,500.0],["delete",1591.25,0.0],["new",1594.45,700.0]],"prev_change_id":23707143904}}}
[2025-04-07 08:30:23.162] [multi_sink] [info] 📩 Received: {"jsonrpc":"2.0","method":"subscription","params":{"channel":"book.ETH-PERPETUAL.100ms","data":{"timestamp":1743994824509,"type":"change","change_id":23707144427,"instrument_name":"ETH-PERPETUAL","bids":[["new",1578.7,59257.0],["new",1578.65,9914.0],["delete",1576.9,0.0],["delete",1576.85,0.0]],"asks":[["new",1578.75,689.0],["delete",1579.05,0.0]],"prev_change_id":23707144364}}}
[2025-04-07 08:30:23.165] [multi_sink] [info] Processing received message: {"jsonrpc":"2.0","method":"subscription","params":{"channel":"book.ETH-PERPETUAL.100ms","data":{"timestamp":1743994824509,"type":"change","change_id":23707144427,"instrument_name":"ETH-PERPETUAL","bids":[["new",1578.7,59257.0],["new",1578.65,9914.0],["delete",1576.9,0.0],["delete",1576.85,0.0]],"asks":[["new",1578.75,689.0],["delete",1579.05,0.0]],"prev_change_id":23707144364}}}
[2025-04-07 08:30:23.368] [multi_sink] [info] 📩 Received: {"jsonrpc":"2.0","method":"subscription","params":{"channel":"book.BTC-PERPETUAL.100ms","data":{"timestamp":1743994825000,"type":"change","change_id":41151892269,"instrument_name":"BTC-PERPETUAL","bids":[],"asks":[["new",78608.5,7.86e4]],"prev_change_id":41151889982}}}
[2025-04-07 08:30:23.371] [multi_sink] [info] Processing received message: {"jsonrpc":"2.0","method":"subscription","params":{"channel":"book.BTC-PERPETUAL.100ms","data":{"timestamp":1743994825000,"type":"change","change_id":41151892269,"instrument_name":"BTC-PERPETUAL","bids":[],"asks":[["new",78608.5,7.86e4]],"prev_change_id":41151889982}}}
[2025-04-07 08:30:23.696] [multi_sink] [info] 📩 Received: {"jsonrpc":"2.0","method":"subscription","params":{"channel":"book.BTC-PERPETUAL.100ms","data":{"timestamp":1743994825008,"type":"change","change_id":41151892273,"instrument_name":"BTC-PERPETUAL","bids":[["new",78277.0,78270.0],["new",78227.0,117340.0]],"asks":[["new",78658.5,117980.0]],"prev_change_id":41151892269}}}
[2025-04-07 08:30:23.701] [multi_sink] [info] Processing received message: {"jsonrpc":"2.0","method":"subscription","params":{"channel":"book.BTC-PERPETUAL.100ms","data":{"timestamp":1743994825008,"type":"change","change_id":41151892273,"instrument_name":"BTC-PERPETUAL","bids":[["new",78277.0,78270.0],["new",78227.0,117340.0]],"asks":[["new",78658.5,117980.0]],"prev_change_id":41151892269}}}
[2025-04-07 08:30:23.831] [multi_sink] [info] 📩 Received: {"jsonrpc":"2.0","method":"subscription","params":{"channel":"book.ETH-PERPETUAL.100ms","data":{"timestamp":1743994825419,"type":"change","change_id":23707145553,"instrument_name":"ETH-PERPETUAL","bids":[["change",1577.95,7775953.0],["delete",1577.4,0.0]],"asks":[],"prev_change_id":23707144427}}}
[2025-04-07 08:30:23.832] [multi_sink] [info] Processing received message: {"jsonrpc":"2.0","method":"subscription","params":{"channel":"book.ETH-PERPETUAL.100ms","data":{"timestamp":1743994825419,"type":"change","change_id":23707145553,"instrument_name":"ETH-PERPETUAL","bids":[["change",1577.95,7775953.0],["delete",1577.4,0.0]],"asks":[],"prev_change_id":23707144427}}}
[2025-04-07 08:30:24.028] [multi_sink] [info] 📩 Received: {"jsonrpc":"2.0","method":"subscription","params":{"channel":"book.BTC-PERPETUAL.100ms","data":{"timestamp":1743994825648,"type":"change","change_id":41151893218,"instrument_name":"BTC-PERPETUAL","bids":[["new",78417.0,32330.0],["new",78416.5,9450.0],["new",78415.0,42440.0],["new",78414.5,33940.0],["new",78414.0,45670.0],["delete",78396.5,0.0],["delete",78395.0,0.0],["delete",78394.0,0.0],["delete",78392.5,0.0],["delete",78392.0,0.0],["delete",78391.5,0.0],["delete",78390.0,0.0],["delete",78389.0,0.0],["delete",78388.5,0.0]],"asks":[["delete",78397.0,0.0],["delete",78398.5,0.0],["delete",78399.5,0.0],["delete",7.84e4,0.0],["delete",78400.5,0.0],["delete",78401.0,0.0],["delete",78402.5,0.0],["delete",78403.0,0.0],["delete",78403.5,0.0],["delete",78404.0,0.0],["delete",78404.5,0.0],["delete",78405.0,0.0],["delete",78405.5,0.0],["delete",78406.0,0.0],["delete",78407.0,0.0],["delete",78407.5,0.0],["delete",78408.0,0.0],["delete",78408.5,0.0],["delete",78410.0,0.0],["delete",78412.0,0.0],["new",78446.5,490.0]],"prev_change_id":41151892273}}}
[2025-04-07 08:30:24.033] [multi_sink] [info] Processing received message: {"jsonrpc":"2.0","method":"subscription","params":{"channel":"book.BTC-PERPETUAL.100ms","data":{"timestamp":1743994825648,"type":"change","change_id":41151893218,"instrument_name":"BTC-PERPETUAL","bids":[["new",78417.0,32330.0],["new",78416.5,9450.0],["new",78415.0,42440.0],["new",78414.5,33940.0],["new",78414.0,45670.0],["delete",78396.5,0.0],["delete",78395.0,0.0],["delete",78394.0,0.0],["delete",78392.5,0.0],["delete",78392.0,0.0],["delete",78391.5,0.0],["delete",78390.0,0.0],["delete",78389.0,0.0],["delete",78388.5,0.0]],"asks":[["delete",78397.0,0.0],["delete",78398.5,0.0],["delete",78399.5,0.0],["delete",7.84e4,0.0],["delete",78400.5,0.0],["delete",78401.0,0.0],["delete",78402.5,0.0],["delete",78403.0,0.0],["delete",78403.5,0.0],["delete",78404.0,0.0],["delete",78404.5,0.0],["delete",78405.0,0.0],["delete",78405.5,0.0],["delete",78406.0,0.0],["delete",78407.0,0.0],["delete",78407.5,0.0],["delete",78408.0,0.0],["delete",78408.5,0.0],["delete",78410.0,0.0],["delete",78412.0,0.0],["new",78446.5,490.0]],"prev_change_id":41151892273}}}
[2025-04-07 08:30:24.160] [multi_sink] [info] 📩 Received: {"jsonrpc":"2.0","method":"subscription","params":{"channel":"book.ETH-PERPETUAL.100ms","data":{"timestamp":1743994825751,"type":"change","change_id":23707145890,"instrument_name":"ETH-PERPETUAL","bids":[],"asks":[["delete",1578.9,0.0],["change",1579.45,6162903.0]],"prev_change_id":23707145553}}}
