[2025-04-07 08:32:35.986] [multi_sink] [info] Processing received message: {"jsonrpc":"2.0","method":"subscription","params":{"channel":"book.BTC-PERPETUAL.100ms","data":{"timestamp":1743994957429,"type":"change","change_id":41152087398,"instrument_name":"BTC-PERPETUAL","bids":[["new",78238.0,78230.0],["delete",78228.0,0.0],["new",78188.0,117270.0],["change",78178.0,8000580.0]],"asks":[],"prev_change_id":41152086488}}}
[2025-04-07 08:32:36.674] [multi_sink] [info] 📩 Received: {"jsonrpc":"2.0","method":"subscription","params":{"channel":"book.BTC-PERPETUAL.100ms","data":{"timestamp":1743994958105,"type":"change","change_id":41152088271,"instrument_name":"BTC-PERPETUAL","bids":[["delete",78238.0,0.0],["delete",78188.0,0.0]],"asks":[["delete",78566.0,0.0],["delete",78616.0,0.0]],"prev_change_id":41152087398}}}
[2025-04-07 08:32:36.675] [multi_sink] [info] Processing received message: {"jsonrpc":"2.0","method":"subscription","params":{"channel":"book.BTC-PERPETUAL.100ms","data":{"timestamp":1743994958105,"type":"change","change_id":41152088271,"instrument_name":"BTC-PERPETUAL","bids":[["delete",78238.0,0.0],["delete",78188.0,0.0]],"asks":[["delete",78566.0,0.0],["delete",78616.0,0.0]],"prev_change_id":41152087398}}}
[2025-04-07 08:32:37.032] [multi_sink] [info] 📩 Received: {"jsonrpc":"2.0","method":"subscription","params":{"channel":"book.BTC-PERPETUAL.100ms","data":{"timestamp":1743994958666,"type":"change","change_id":41152089058,"instrument_name":"BTC-PERPETUAL","bids":[["new",78353.5,7825720.0],["delete",78331.0,0.0]],"asks":[],"prev_change_id":41152088271}}}
[2025-04-07 08:32:37.035] [multi_sink] [info] Processing received message: {"jsonrpc":"2.0","method":"subscription","params":{"channel":"book.BTC-PERPETUAL.100ms","data":{"timestamp":1743994958666,"type":"change","change_id":41152089058,"instrument_name":"BTC-PERPETUAL","bids":[["new",78353.5,7825720.0],["delete",78331.0,0.0]],"asks":[],"prev_change_id":41152088271}}}
[2025-04-07 08:32:37.205] [multi_sink] [info] 📩 Received: {"jsonrpc":"2.0","method":"subscription","params":{"channel":"book.ETH-PERPETUAL.100ms","data":{"timestamp":1743994958839,"type":"change","change_id":23707287633,"instrument_name":"ETH-PERPETUAL","bids":[],"asks":[["delete",1580.5,0.0],["new",1582.6,8311.0]],"prev_change_id":23707283642}}}
[2025-04-07 08:32:37.210] [multi_sink] [info] Processing received message: {"jsonrpc":"2.0","method":"subscription","params":{"channel":"book.ETH-PERPETUAL.100ms","data":{"timestamp":1743994958839,"type":"change","change_id":23707287633,"instrument_name":"ETH-PERPETUAL","bids":[],"asks":[["delete",1580.5,0.0],["new",1582.6,8311.0]],"prev_change_id":23707283642}}}
[2025-04-07 08:32:37.373] [multi_sink] [info] 📩 Received: {"jsonrpc":"2.0","method":"subscription","params":{"channel":"book.BTC-PERPETUAL.100ms","data":{"timestamp":1743994958996,"type":"change","change_id":41152089455,"instrument_name":"BTC-PERPETUAL","bids":[["new",78200.5,8000580.0],["delete",78178.0,0.0]],"asks":[["delete",78408.5,0.0],["new",78431.0,6640830.0]],"prev_change_id":41152089058}}}
[2025-04-07 08:32:37.375] [multi_sink] [info] Processing received message: {"jsonrpc":"2.0","method":"subscription","params":{"channel":"book.BTC-PERPETUAL.100ms","data":{"timestamp":1743994958996,"type":"change","change_id":41152089455,"instrument_name":"BTC-PERPETUAL","bids":[["new",78200.5,8000580.0],["delete",78178.0,0.0]],"asks":[["delete",78408.5,0.0],["new",78431.0,6640830.0]],"prev_change_id":41152089058}}}
[2025-04-07 08:32:37.536] [multi_sink] [info] 📩 Received: {"jsonrpc":"2.0","method":"subscription","params":{"channel":"book.ETH-PERPETUAL.100ms","data":{"timestamp":1743994959166,"type":"change","change_id":23707288277,"instrument_name":"ETH-PERPETUAL","bids":[["new",1580.65,1317.0],["new",1580.6,100.0],["new",1580.55,30109.0],["new",1580.5,8643.0],["new",1580.45,86013.0],["new",1580.4,922.0],["new",1580.35,3685.0],["new",1580.3,7621.0],["new",1580.25,922.0],["delete",1579.35,0.0],["delete",1579.3,0.0],["delete",1579.25,0.0],["new",1575.5,500.0],["delete",1573.6,0.0],["new",1564.6,700.0],["delete",1561.45,0.0]],"asks":[["delete",1580.7,0.0],["change",1580.75,5252567.0],["delete",1580.8,0.0],["delete",1580.85,0.0],["delete",1580.9,0.0],["delete",1580.95,0.0],["delete",1581.0,0.0],["delete",1581.05,0.0],["delete",1581.1,0.0],["new",1582.15,40124.0],["new",1582.2,46464.0],["new",1582.25,8527.0],["new",1582.3,83750.0],["new",1582.35,29336.0],["new",1582.4,8425.0],["new",1582.45,17372.0],["new",1582.5,53693.0],["new",1582.55,922.0]],"prev_change_id":23707287633}}}
[2025-04-07 08:32:37.540] [multi_sink] [info] Processing received message: {"jsonrpc":"2.0","method":"subscription","params":{"channel":"book.ETH-PERPETUAL.100ms","data":{"timestamp":1743994959166,"type":"change","change_id":23707288277,"instrument_name":"ETH-PERPETUAL","bids":[["new",1580.65,1317.0],["new",1580.6,100.0],["new",1580.55,30109.0],["new",1580.5,8643.0],["new",1580.45,86013.0],["new",1580.4,922.0],["new",1580.35,3685.0],["new",1580.3,7621.0],["new",1580.25,922.0],["delete",1579.35,0.0],["delete",1579.3,0.0],["delete",1579.25,0.0],["new",1575.5,500.0],["delete",1573.6,0.0],["new",1564.6,700.0],["delete",1561.45,0.0]],"asks":[["delete",1580.7,0.0],["change",1580.75,5252567.0],["delete",1580.8,0.0],["delete",1580.85,0.0],["delete",1580.9,0.0],["delete",1580.95,0.0],["delete",1581.0,0.0],["delete",1581.05,0.0],["delete",1581.1,0.0],["new",1582.15,40124.0],["new",1582.2,46464.0],["new",1582.25,8527.0],["new",1582.3,83750.0],["new",1582.35,29336.0],["new",1582.4,8425.0],["new",1582.45,17372.0],["new",1582.5,53693.0],["new",1582.55,922.0]],"prev_change_id":23707287633}}}
[2025-04-07 08:32:37.693] [multi_sink] [info] 📩 Received: {"jsonrpc":"2.0","method":"subscription","params":{"channel":"book.BTC-PERPETUAL.100ms","data":{"timestamp":1743994958999,"type":"change","change_id":41152089458,"instrument_name":"BTC-PERPETUAL","bids":[],"asks":[["delete",78561.5,0.0],["new",78584.0,7777770.0]],"prev_change_id":41152089455}}}
[2025-04-07 08:32:37.695] [multi_sink] [info] Processing received message: {"jsonrpc":"2.0","method":"subscription","params":{"channel":"book.BTC-PERPETUAL.100ms","data":{"timestamp":1743994958999,"type":"change","change_id":41152089458,"instrument_name":"BTC-PERPETUAL","bids":[],"asks":[["delete",78561.5,0.0],["new",78584.0,7777770.0]],"prev_change_id":41152089455}}}
[2025-04-07 08:32:37.866] [multi_sink] [info] 📩 Received: {"jsonrpc":"2.0","method":"subscription","params":{"channel":"book.ETH-PERPETUAL.100ms","data":{"timestamp":1743994959476,"type":"change","change_id":23707288669,"instrument_name":"ETH-PERPETUAL","bids":[["new",1580.7,14994.0]],"asks":[["change",1580.75,5101456.0],["delete",1581.15,0.0],["delete",1581.2,0.0],["delete",1581.25,0.0],["delete",1581.3,0.0],["delete",1581.35,0.0],["delete",1581.4,0.0],["delete",1581.45,0.0],["delete",1581.5,0.0],["new",1581.75,27613.0],["new",1581.8,922.0],["new",1581.85,962.0],["new",1581.9,7936.0],["new",1581.95,1022.0],["new",1582.0,19846.0],["new",1582.05,6847.0],["new",1582.1,21918.0]],"prev_change_id":23707288277}}}
[2025-04-07 08:32:37.871] [multi_sink] [info] Processing received message: {"jsonrpc":"2.0","method":"subscription","params":{"channel":"book.ETH-PERPETUAL.100ms","data":{"timestamp":1743994959476,"type":"change","change_id":23707288669,"instrument_name":"ETH-PERPETUAL","bids":[["new",1580.7,14994.0]],"asks":[["change",1580.75,5101456.0],["delete",1581.15,0.0],["delete",1581.2,0.0],["delete",1581.25,0.0],["delete",1581.3,0.0],["delete",1581.35,0.0],["delete",1581.4,0.0],["delete",1581.45,0.0],["delete",1581.5,0.0],["new",1581.75,27613.0],["new",1581.8,922.0],["new",1581.85,962.0],["new",1581.9,7936.0],["new",1581.95,1022.0],["new",1582.0,19846.0],["new",1582.05,6847.0],["new",1582.1,21918.0]],"prev_change_id":23707288277}}}
[2025-04-07 08:32:38.023] [multi_sink] [info] 📩 Received: {"jsonrpc":"2.0","method":"subscription","params":{"channel":"book.BTC-PERPETUAL.100ms","data":{"timestamp":1743994959433,"type":"change","change_id":41152090234,"instrument_name":"BTC-PERPETUAL","bids":[],"asks":[["new",78583.5,78580.0],["new",78633.5,117950.0]],"prev_change_id":41152089458}}}
[2025-04-07 08:32:38.027] [multi_sink] [info] Processing received message: {"jsonrpc":"2.0","method":"subscription","params":{"channel":"book.BTC-PERPETUAL.100ms","data":{"timestamp":1743994959433,"type":"change","change_id":41152090234,"instrument_name":"BTC-PERPETUAL","bids":[],"asks":[["new",78583.5,78580.0],["new",78633.5,117950.0]],"prev_change_id":41152089458}}}
[2025-04-07 08:32:38.196] [multi_sink] [info] 📩 Received: {"jsonrpc":"2.0","method":"subscription","params":{"channel":"book.ETH-PERPETUAL.100ms","data":{"timestamp":1743994959549,"type":"change","change_id":23707288784,"instrument_name":"ETH-PERPETUAL","bids":[],"asks":[["change",1580.75,5049063.0],["change",1581.55,7.5e3],["delete",1581.6,0.0],["new",1581.7,8551.0]],"prev_change_id":23707288669}}}
[2025-04-07 08:32:38.199] [multi_sink] [info] Processing received message: {"jsonrpc":"2.0","method":"subscription","params":{"channel":"book.ETH-PERPETUAL.100ms","data":{"timestamp":1743994959549,"type":"change","change_id":23707288784,"instrument_name":"ETH-PERPETUAL","bids":[],"asks":[["change",1580.75,5049063.0],["change",1581.55,7.5e3],["delete",1581.6,0.0],["new",1581.7,8551.0]],"prev_change_id":23707288669}}}
[2025-04-07 08:32:38.354] [multi_sink] [info] 📩 Received: {"jsonrpc":"2.0","method":"subscription","params":{"channel":"book.BTC-PERPETUAL.100ms","data":{"timestamp":1743994959989,"type":"change","change_id":41152090897,"instrument_name":"BTC-PERPETUAL","bids":[["change",78252.0,153070.0]],"asks":[],"prev_change_id":41152090234}}}
[2025-04-07 08:32:38.359] [multi_sink] [info] Processing received message: {"jsonrpc":"2.0","method":"subscription","params":{"channel":"book.BTC-PERPETUAL.100ms","data":{"timestamp":1743994959989,"type":"change","change_id":41152090897,"instrument_name":"BTC-PERPETUAL","bids":[["change",78252.0,153070.0]],"asks":[],"prev_change_id":41152090234}}}
[2025-04-07 08:32:38.684] [multi_sink] [info] 📩 Received: {"jsonrpc":"2.0","method":"subscription","params":{"channel":"book.BTC-PERPETUAL.100ms","data":{"timestamp":1743994959994,"type":"change","change_id":41152090906,"instrument_name":"BTC-PERPETUAL","bids":[["new",78202.0,1.173e5]],"asks":[],"prev_change_id":41152090897}}}
[2025-04-07 08:32:38.685] [multi_sink] [info] Processing received message: {"jsonrpc":"2.0","method":"subscription","params":{"channel":"book.BTC-PERPETUAL.100ms","data":{"timestamp":1743994959994,"type":"change","change_id":41152090906,"instrument_name":"BTC-PERPETUAL","bids":[["new",78202.0,1.173e5]],"asks":[],"prev_change_id":41152090897}}}
[2025-04-07 08:32:39.015] [multi_sink] [info] 📩 Received: {"jsonrpc":"2.0","method":"subscription","params":{"channel":"book.BTC-PERPETUAL.100ms","data":{"timestamp":1743994960644,"type":"change","change_id":41152091889,"instrument_name":"BTC-PERPETUAL","bids":[["new",78396.5,16490.0],["new",78395.5,13550.0],["new",78395.0,5410.0],["new",78392.5,32050.0],["new",78391.5,48670.0],["new",78391.0,4560.0],["new",78389.0,31640.0],["delete",78384.5,0.0],["delete",78384.0,0.0],["delete",78383.5,0.0],["delete",78382.5,0.0],["delete",78374.0,0.0],["delete",78373.5,0.0],["delete",78372.5,0.0],["delete",78372.0,0.0]],"asks":[["delete",78385.0,0.0],["delete",78387.0,0.0],["delete",78388.0,0.0],["delete",78388.5,0.0],["delete",78391.5,0.0],["delete",78392.5,0.0],["delete",78394.5,0.0],["delete",78395.0,0.0],["change",78397.0,3.5e3],["new",78433.0,490.0]],"prev_change_id":41152090906}}}
[2025-04-07 08:32:39.019] [multi_sink] [info] Processing received message: {"jsonrpc":"2.0","method":"subscription","params":{"channel":"book.BTC-PERPETUAL.100ms","data":{"timestamp":1743994960644,"type":"change","change_id":41152091889,"instrument_name":"BTC-PERPETUAL","bids":[["new",78396.5,16490.0],["new",78395.5,13550.0],["new",78395.0,5410.0],["new",78392.5,32050.0],["new",78391.5,48670.0],["new",78391.0,4560.0],["new",78389.0,31640.0],["delete",78384.5,0.0],["delete",78384.0,0.0],["delete",78383.5,0.0],["delete",78382.5,0.0],["delete",78374.0,0.0],["delete",78373.5,0.0],["delete",78372.5,0.0],["delete",78372.0,0.0]],"asks":[["delete",78385.0,0.0],["delete",78387.0,0.0],["delete",78388.0,0.0],["delete",78388.5,0.0],["delete",78391.5,0.0],["delete",78392.5,0.0],["delete",78394.5,0.0],["delete",78395.0,0.0],["change",78397.0,3.5e3],["new",78433.0,490.0]],"prev_change_id":41152090906}}}
[2025-04-07 08:32:39.346] [multi_sink] [info] 📩 Received: {"jsonrpc":"2.0","method":"subscription","params":{"channel":"book.BTC-PERPETUAL.100ms","data":{"timestamp":1743994960955,"type":"change","change_id":41152092237,"instrument_name":"BTC-PERPETUAL","bids":[["new",78405.0,5740.0],["new",78402.0,10.0],["new",78401.0,16490.0],["new",78400.5,26720.0],["delete",78371.5,0.0],["delete",78370.0,0.0],["delete",78369.5,0.0],["delete",78369.0,0.0],["delete",78368.5,0.0],["delete",78367.0,0.0],["delete",78365.5,0.0],["delete",78364.0,0.0]],"asks":[["delete",78397.0,0.0],["delete",7.84e4,0.0],["delete",78400.5,0.0],["delete",78402.0,0.0],["delete",78403.0,0.0],["delete",78403.5,0.0],["delete",78404.0,0.0],["delete",78404.5,0.0],["delete",78405.5,0.0],["new",78419.5,6.0e3],["new",78420.0,9510.0],["new",78423.5,35150.0],["new",78426.5,3150.0],["new",78428.5,43270.0]],"prev_change_id":41152091889}}}
[2025-04-07 08:32:39.350] [multi_sink] [info] Processing received message: {"jsonrpc":"2.0","method":"subscription","params":{"channel":"book.BTC-PERPETUAL.100ms","data":{"timestamp":1743994960955,"type":"change","change_id":41152092237,"instrument_name":"BTC-PERPETUAL","bids":[["new",78405.0,5740.0],["new",78402.0,10.0],["new",78401.0,16490.0],["new",78400.5,26720.0],["delete",78371.5,0.0],["delete",78370.0,0.0],["delete",78369.5,0.0],["delete",78369.0,0.0],["delete",78368.5,0.0],["delete",78367.0,0.0],["delete",78365.5,0.0],["delete",78364.0,0.0]],"asks":[["delete",78397.0,0.0],["delete",7.84e4,0.0],["delete",78400.5,0.0],["delete",78402.0,0.0],["delete",78403.0,0.0],["delete",78403.5,0.0],["delete",78404.0,0.0],["delete",78404.5,0.0],["delete",78405.5,0.0],["new",78419.5,6.0e3],["new",78420.0,9510.0],["new",78423.5,35150.0],["new",78426.5,3150.0],["new",78428.5,43270.0]],"prev_change_id":41152091889}}}
[2025-04-07 08:32:39.680] [multi_sink] [info] 📩 Received: {"jsonrpc":"2.0","method":"subscription","params":{"channel":"book.BTC-PERPETUAL.100ms","data":{"timestamp":1743994961109,"type":"change","change_id":41152092651,"instrument_name":"BTC-PERPETUAL","bids":[["new",78407.0,94210.0],["new",78406.5,18340.0],["new",78406.0,2.09e4],["new",78405.5,2.09e4],["delete",78362.0,0.0],["delete",78361.5,0.0],["delete",78358.5,0.0]],"asks":[["change",78407.5,590.0],["new",78408.0,10.0],["new",78419.0,4580.0]],"prev_change_id":41152092237}}}
[2025-04-07 08:32:39.682] [multi_sink] [info] Processing received message: {"jsonrpc":"2.0","method":"subscription","params":{"channel":"book.BTC-PERPETUAL.100ms","data":{"timestamp":1743994961109,"type":"change","change_id":41152092651,"instrument_name":"BTC-PERPETUAL","bids":[["new",78407.0,94210.0],["new",78406.5,18340.0],["new",78406.0,2.09e4],["new",78405.5,2.09e4],["delete",78362.0,0.0],["delete",78361.5,0.0],["delete",78358.5,0.0]],"asks":[["change",78407.5,590.0],["new",78408.0,10.0],["new",78419.0,4580.0]],"prev_change_id":41152092237}}}
[2025-04-07 08:32:40.236] [multi_sink] [info] 📩 Received: {"jsonrpc":"2.0","method":"subscription","params":{"channel":"book.ETH-PERPETUAL.100ms","data":{"timestamp":1743994961867,"type":"change","change_id":23707291008,"instrument_name":"ETH-PERPETUAL","bids":[["change",1580.35,7549637.0],["delete",1577.9,0.0]],"asks":[],"prev_change_id":23707288784}}}
[2025-04-07 08:32:40.238] [multi_sink] [info] Processing received message: {"jsonrpc":"2.0","method":"subscription","params":{"channel":"book.ETH-PERPETUAL.100ms","data":{"timestamp":1743994961867,"type":"change","change_id":23707291008,"instrument_name":"ETH-PERPETUAL","bids":[["change",1580.35,7549637.0],["delete",1577.9,0.0]],"asks":[],"prev_change_id":23707288784}}}
[2025-04-07 08:32:40.311] [multi_sink] [info] 📩 Received: {"jsonrpc":"2.0","method":"subscription","params":{"channel":"book.BTC-PERPETUAL.100ms","data":{"timestamp":1743994961942,"type":"change","change_id":41152093859,"instrument_name":"BTC-PERPETUAL","bids":[["change",78252.0,74820.0],["new",78240.5,78240.0]],"asks":[],"prev_change_id":41152092651}}}
[2025-04-07 08:32:40.311] [multi_sink] [info] Processing received message: {"jsonrpc":"2.0","method":"subscription","params":{"channel":"book.BTC-PERPETUAL.100ms","data":{"timestamp":1743994961942,"type":"change","change_id":41152093859,"instrument_name":"BTC-PERPETUAL","bids":[["change",78252.0,74820.0],["new",78240.5,78240.0]],"asks":[],"prev_change_id":41152092651}}}
[2025-04-07 08:32:40.640] [multi_sink] [info] 📩 Received: {"jsonrpc":"2.0","method":"subscription","params":{"channel":"book.BTC-PERPETUAL.100ms","data":{"timestamp":1743994961965,"type":"change","change_id":41152093863,"instrument_name":"BTC-PERPETUAL","bids":[["delete",78202.0,0.0],["new",78190.5,117280.0]],"asks":[["new",78572.5,78570.0],["delete",78583.5,0.0],["new",78622.5,117930.0],["delete",78633.5,0.0]],"prev_change_id":41152093859}}}
[2025-04-07 08:32:40.640] [multi_sink] [info] Processing received message: {"jsonrpc":"2.0","method":"subscription","params":{"channel":"book.BTC-PERPETUAL.100ms","data":{"timestamp":1743994961965,"type":"change","change_id":41152093863,"instrument_name":"BTC-PERPETUAL","bids":[["delete",78202.0,0.0],["new",78190.5,117280.0]],"asks":[["new",78572.5,78570.0],["delete",78583.5,0.0],["new",78622.5,117930.0],["delete",78633.5,0.0]],"prev_change_id":41152093859}}}
[2025-04-07 08:32:40.894] [multi_sink] [info] 📩 Received: {"jsonrpc":"2.0","method":"subscription","params":{"channel":"book.ETH-PERPETUAL.100ms","data":{"timestamp":1743994962352,"type":"change","change_id":23707291606,"instrument_name":"ETH-PERPETUAL","bids":[],"asks":[["delete",1580.75,0.0],["change",1581.85,5050025.0],["delete",1584.0,0.0],["new",1586.3,500.0]],"prev_change_id":23707291008}}}
[2025-04-07 08:32:40.899] [multi_sink] [info] Processing received message: {"jsonrpc":"2.0","method":"subscription","params":{"channel":"book.ETH-PERPETUAL.100ms","data":{"timestamp":1743994962352,"type":"change","change_id":23707291606,"instrument_name":"ETH-PERPETUAL","bids":[],"asks":[["delete",1580.75,0.0],["change",1581.85,5050025.0],["delete",1584.0,0.0],["new",1586.3,500.0]],"prev_change_id":23707291008}}}
[2025-04-07 08:32:41.317] [multi_sink] [info] 📩 Received: {"jsonrpc":"2.0","method":"subscription","params":{"channel":"book.BTC-PERPETUAL.100ms","data":{"timestamp":1743994962952,"type":"change","change_id":41152095264,"instrument_name":"BTC-PERPETUAL","bids":[],"asks":[["new",78562.0,78560.0],["delete",78572.5,0.0]],"prev_change_id":41152093863}}}
[2025-04-07 08:32:41.318] [multi_sink] [info] Processing received message: {"jsonrpc":"2.0","method":"subscription","params":{"channel":"book.BTC-PERPETUAL.100ms","data":{"timestamp":1743994962952,"type":"change","change_id":41152095264,"instrument_name":"BTC-PERPETUAL","bids":[],"asks":[["new",78562.0,78560.0],["delete",78572.5,0.0]],"prev_change_id":41152093863}}}
[2025-04-07 08:32:41.663] [multi_sink] [info] 📩 Received: {"jsonrpc":"2.0","method":"subscription","params":{"channel":"book.BTC-PERPETUAL.100ms","data":{"timestamp":1743994963143,"type":"change","change_id":41152095647,"instrument_name":"BTC-PERPETUAL","bids":[["delete",78240.5,0.0],["delete",78190.5,0.0]],"asks":[["delete",78562.0,0.0],["delete",78622.5,0.0]],"prev_change_id":41152095264}}}
[2025-04-07 08:32:41.667] [multi_sink] [info] Processing received message: {"jsonrpc":"2.0","method":"subscription","params":{"channel":"book.BTC-PERPETUAL.100ms","data":{"timestamp":1743994963143,"type":"change","change_id":41152095647,"instrument_name":"BTC-PERPETUAL","bids":[["delete",78240.5,0.0],["delete",78190.5,0.0]],"asks":[["delete",78562.0,0.0],["delete",78622.5,0.0]],"prev_change_id":41152095264}}}
[2025-04-07 08:32:42.198] [multi_sink] [info] 📩 Received: {"jsonrpc":"2.0","method":"subscription","params":{"channel":"book.ETH-PERPETUAL.100ms","data":{"timestamp":1743994963832,"type":"change","change_id":23707292857,"instrument_name":"ETH-PERPETUAL","bids":[],"asks":[["new",1581.3,79797.0],["delete",1581.55,0.0]],"prev_change_id":23707291606}}}
[2025-04-07 08:32:42.202] [multi_sink] [info] Processing received message: {"jsonrpc":"2.0","method":"subscription","params":{"channel":"book.ETH-PERPETUAL.100ms","data":{"timestamp":1743994963832,"type":"change","change_id":23707292857,"instrument_name":"ETH-PERPETUAL","bids":[],"asks":[["new",1581.3,79797.0],["delete",1581.55,0.0]],"prev_change_id":23707291606}}}
[2025-04-07 08:32:42.528] [multi_sink] [info] 📩 Received: {"jsonrpc":"2.0","method":"subscription","params":{"channel":"book.ETH-PERPETUAL.100ms","data":{"timestamp":1743994964153,"type":"change","change_id":23707293474,"instrument_name":"ETH-PERPETUAL","bids":[["delete",1580.7,0.0],["delete",1580.65,0.0],["delete",1580.6,0.0],["delete",1580.55,0.0],["delete",1580.5,0.0],["delete",1580.45,0.0],["delete",1580.4,0.0],["change",1580.35,7545952.0],["new",1579.35,8.6e3],["new",1579.3,25261.0],["new",1579.25,8592.0],["new",1579.2,8615.0],["new",1579.15,7942.0],["new",1579.1,922.0],["new",1579.05,3812.0],["new",1579.0,8613.0]],"asks":[["new",1580.85,3904.0],["new",1580.9,47729.0],["new",1580.95,14093.0],["new",1581.0,58015.0],["new",1581.05,2.5e4],["new",1581.1,3323.0],["new",1581.15,7993.0],["new",1581.2,28206.0],["delete",1581.7,0.0],["delete",1581.75,0.0],["delete",1581.8,0.0],["change",1581.85,5049063.0],["delete",1581.9,0.0],["delete",1581.95,0.0],["delete",1582.0,0.0],["delete",1582.05,0.0]],"prev_change_id":23707292857}}}
[2025-04-07 08:32:42.531] [multi_sink] [info] Processing received message: {"jsonrpc":"2.0","method":"subscription","params":{"channel":"book.ETH-PERPETUAL.100ms","data":{"timestamp":1743994964153,"type":"change","change_id":23707293474,"instrument_name":"ETH-PERPETUAL","bids":[["delete",1580.7,0.0],["delete",1580.65,0.0],["delete",1580.6,0.0],["delete",1580.55,0.0],["delete",1580.5,0.0],["delete",1580.45,0.0],["delete",1580.4,0.0],["change",1580.35,7545952.0],["new",1579.35,8.6e3],["new",1579.3,25261.0],["new",1579.25,8592.0],["new",1579.2,8615.0],["new",1579.15,7942.0],["new",1579.1,922.0],["new",1579.05,3812.0],["new",1579.0,8613.0]],"asks":[["new",1580.85,3904.0],["new",1580.9,47729.0],["new",1580.95,14093.0],["new",1581.0,58015.0],["new",1581.05,2.5e4],["new",1581.1,3323.0],["new",1581.15,7993.0],["new",1581.2,28206.0],["delete",1581.7,0.0],["delete",1581.75,0.0],["delete",1581.8,0.0],["change",1581.85,5049063.0],["delete",1581.9,0.0],["delete",1581.95,0.0],["delete",1582.0,0.0],["delete",1582.05,0.0]],"prev_change_id":23707292857}}}
[2025-04-07 08:32:42.858] [multi_sink] [info] 📩 Received: {"jsonrpc":"2.0","method":"subscription","params":{"channel":"book.ETH-PERPETUAL.100ms","data":{"timestamp":1743994964474,"type":"change","change_id":23707293793,"instrument_name":"ETH-PERPETUAL","bids":[["change",1580.35,7538452.0],["delete",1580.3,0.0],["delete",1580.25,0.0],["new",1579.9,5.0e3],["new",1579.75,2.25e4],["new",1579.7,47422.0],["new",1579.65,14913.0],["new",1579.6,1020.0],["new",1579.55,922.0],["new",1579.5,26207.0],["new",1579.45,40953.0],["new",1579.4,8515.0]],"asks":[["new",1580.4,10468.0],["new",1580.45,9893.0],["new",1580.55,100.0],["new",1580.6,4240.0],["new",1580.65,1020.0],["new",1580.7,12621.0],["new",1580.75,1979.0],["new",1580.8,16422.0],["delete",1582.1,0.0],["delete",1582.15,0.0],["delete",1582.2,0.0],["delete",1582.25,0.0],["delete",1582.3,0.0],["delete",1582.35,0.0],["delete",1582.4,0.0],["delete",1582.45,0.0],["delete",1582.5,0.0]],"prev_change_id":23707293474}}}
[2025-04-07 08:32:42.861] [multi_sink] [info] Processing received message: {"jsonrpc":"2.0","method":"subscription","params":{"channel":"book.ETH-PERPETUAL.100ms","data":{"timestamp":1743994964474,"type":"change","change_id":23707293793,"instrument_name":"ETH-PERPETUAL","bids":[["change",1580.35,7538452.0],["delete",1580.3,0.0],["delete",1580.25,0.0],["new",1579.9,5.0e3],["new",1579.75,2.25e4],["new",1579.7,47422.0],["new",1579.65,14913.0],["new",1579.6,1020.0],["new",1579.55,922.0],["new",1579.5,26207.0],["new",1579.45,40953.0],["new",1579.4,8515.0]],"asks":[["new",1580.4,10468.0],["new",1580.45,9893.0],["new",1580.55,100.0],["new",1580.6,4240.0],["new",1580.65,1020.0],["new",1580.7,12621.0],["new",1580.75,1979.0],["new",1580.8,16422.0],["delete",1582.1,0.0],["delete",1582.15,0.0],["delete",1582.2,0.0],["delete",1582.25,0.0],["delete",1582.3,0.0],["delete",1582.35,0.0],["delete",1582.4,0.0],["delete",1582.45,0.0],["delete",1582.5,0.0]],"prev_change_id":23707293474}}}
[2025-04-07 08:32:43.196] [multi_sink] [info] 📩 Received: {"jsonrpc":"2.0","method":"subscription","params":{"channel":"book.ETH-PERPETUAL.100ms","data":{"timestamp":1743994964582,"type":"change","change_id":23707294003,"instrument_name":"ETH-PERPETUAL","bids":[["change",1580.35,7526481.0],["new",1580.15,7325.0],["new",1580.0,21554.0],["new",1579.95,81739.0]],"asks":[["delete",1582.55,0.0],["delete",1582.6,0.0]],"prev_change_id":23707293793}}}
[2025-04-07 08:32:43.197] [multi_sink] [info] Processing received message: {"jsonrpc":"2.0","method":"subscription","params":{"channel":"book.ETH-PERPETUAL.100ms","data":{"timestamp":1743994964582,"type":"change","change_id":23707294003,"instrument_name":"ETH-PERPETUAL","bids":[["change",1580.35,7526481.0],["new",1580.15,7325.0],["new",1580.0,21554.0],["new",1579.95,81739.0]],"asks":[["delete",1582.55,0.0],["delete",1582.6,0.0]],"prev_change_id":23707293793}}}
[2025-04-07 08:32:43.321] [multi_sink] [info] 📩 Received: {"jsonrpc":"2.0","method":"subscription","params":{"channel":"book.BTC-PERPETUAL.100ms","data":{"timestamp":1743994964955,"type":"change","change_id":41152097982,"instrument_name":"BTC-PERPETUAL","bids":[],"asks":[["new",78534.5,78530.0]],"prev_change_id":41152095647}}}
[2025-04-07 08:32:43.321] [multi_sink] [info] Processing received message: {"jsonrpc":"2.0","method":"subscription","params":{"channel":"book.BTC-PERPETUAL.100ms","data":{"timestamp":1743994964955,"type":"change","change_id":41152097982,"instrument_name":"BTC-PERPETUAL","bids":[],"asks":[["new",78534.5,78530.0]],"prev_change_id":41152095647}}}
[2025-04-07 08:32:43.652] [multi_sink] [info] 📩 Received: {"jsonrpc":"2.0","method":"subscription","params":{"channel":"book.BTC-PERPETUAL.100ms","data":{"timestamp":1743994965043,"type":"change","change_id":41152098341,"instrument_name":"BTC-PERPETUAL","bids":[["new",78205.5,7.82e4],["new",78155.5,117230.0]],"asks":[["new",78584.5,117870.0]],"prev_change_id":41152097982}}}
[2025-04-07 08:32:43.654] [multi_sink] [info] Processing received message: {"jsonrpc":"2.0","method":"subscription","params":{"channel":"book.BTC-PERPETUAL.100ms","data":{"timestamp":1743994965043,"type":"change","change_id":41152098341,"instrument_name":"BTC-PERPETUAL","bids":[["new",78205.5,7.82e4],["new",78155.5,117230.0]],"asks":[["new",78584.5,117870.0]],"prev_change_id":41152097982}}}
[2025-04-07 08:32:43.980] [multi_sink] [info] 📩 Received: {"jsonrpc":"2.0","method":"subscription","params":{"channel":"book.BTC-PERPETUAL.100ms","data":{"timestamp":1743994965615,"type":"change","change_id":41152099175,"instrument_name":"BTC-PERPETUAL","bids":[["delete",78407.0,0.0],["delete",78406.5,0.0],["delete",78406.0,0.0],["delete",78405.5,0.0],["delete",78405.0,0.0],["delete",78402.0,0.0],["delete",78401.0,0.0],["delete",78400.5,0.0],["delete",78396.5,0.0],["delete",78395.5,0.0],["change",78395.0,3290.0],["new",78344.0,11850.0]],"asks":[["delete",78407.5,0.0],["delete",78408.0,0.0],["delete",78419.0,0.0],["delete",78419.5,0.0],["delete",78420.0,0.0],["delete",78423.5,0.0],["delete",78426.5,0.0]],"prev_change_id":41152098341}}}
[2025-04-07 08:32:43.984] [multi_sink] [info] Processing received message: {"jsonrpc":"2.0","method":"subscription","params":{"channel":"book.BTC-PERPETUAL.100ms","data":{"timestamp":1743994965615,"type":"change","change_id":41152099175,"instrument_name":"BTC-PERPETUAL","bids":[["delete",78407.0,0.0],["delete",78406.5,0.0],["delete",78406.0,0.0],["delete",78405.5,0.0],["delete",78405.0,0.0],["delete",78402.0,0.0],["delete",78401.0,0.0],["delete",78400.5,0.0],["delete",78396.5,0.0],["delete",78395.5,0.0],["change",78395.0,3290.0],["new",78344.0,11850.0]],"asks":[["delete",78407.5,0.0],["delete",78408.0,0.0],["delete",78419.0,0.0],["delete",78419.5,0.0],["delete",78420.0,0.0],["delete",78423.5,0.0],["delete",78426.5,0.0]],"prev_change_id":41152098341}}}
[2025-04-07 08:32:44.312] [multi_sink] [info] 📩 Received: {"jsonrpc":"2.0","method":"subscription","params":{"channel":"book.BTC-PERPETUAL.100ms","data":{"timestamp":1743994965945,"type":"change","change_id":41152099503,"instrument_name":"BTC-PERPETUAL","bids":[["delete",78395.0,0.0],["delete",78392.5,0.0],["delete",78391.5,0.0],["delete",78391.0,0.0],["delete",78389.0,0.0],["new",78361.5,9430.0],["new",78360.0,16930.0]],"asks":[["new",78379.5,35040.0],["new",78382.0,1.05e4],["new",78383.5,3.5e4],["new",78384.5,36230.0],["new",78385.0,44480.0],["new",78386.0,1.0e4],["new",78388.0,17910.0],["delete",78428.5,0.0],["delete",78433.0,0.0]],"prev_change_id":41152099175}}}
[2025-04-07 08:32:44.313] [multi_sink] [info] Processing received message: {"jsonrpc":"2.0","method":"subscription","params":{"channel":"book.BTC-PERPETUAL.100ms","data":{"timestamp":1743994965945,"type":"change","change_id":41152099503,"instrument_name":"BTC-PERPETUAL","bids":[["delete",78395.0,0.0],["delete",78392.5,0.0],["delete",78391.5,0.0],["delete",78391.0,0.0],["delete",78389.0,0.0],["new",78361.5,9430.0],["new",78360.0,16930.0]],"asks":[["new",78379.5,35040.0],["new",78382.0,1.05e4],["new",78383.5,3.5e4],["new",78384.5,36230.0],["new",78385.0,44480.0],["new",78386.0,1.0e4],["new",78388.0,17910.0],["delete",78428.5,0.0],["delete",78433.0,0.0]],"prev_change_id":41152099175}}}
[2025-04-07 08:32:44.646] [multi_sink] [info] 📩 Received: {"jsonrpc":"2.0","method":"subscription","params":{"channel":"book.BTC-PERPETUAL.100ms","data":{"timestamp":1743994966153,"type":"change","change_id":41152099979,"instrument_name":"BTC-PERPETUAL","bids":[["new",78375.5,500.0],["new",78365.0,470.0],["new",78362.5,5830.0],["delete",78353.5,0.0],["new",78337.0,7825720.0],["delete",78205.5,0.0],["new",78195.0,78190.0],["delete",78155.5,0.0],["new",78145.0,117210.0]],"asks":[["new",78376.0,9.43e4],["new",78376.5,31410.0],["new",78377.0,2.09e4],["new",78377.5,9430.0],["new",78379.0,6.0e3]],"prev_change_id":41152099503}}}
[2025-04-07 08:32:44.647] [multi_sink] [info] Processing received message: {"jsonrpc":"2.0","method":"subscription","params":{"channel":"book.BTC-PERPETUAL.100ms","data":{"timestamp":1743994966153,"type":"change","change_id":41152099979,"instrument_name":"BTC-PERPETUAL","bids":[["new",78375.5,500.0],["new",78365.0,470.0],["new",78362.5,5830.0],["delete",78353.5,0.0],["new",78337.0,7825720.0],["delete",78205.5,0.0],["new",78195.0,78190.0],["delete",78155.5,0.0],["new",78145.0,117210.0]],"asks":[["new",78376.0,9.43e4],["new",78376.5,31410.0],["new",78377.0,2.09e4],["new",78377.5,9430.0],["new",78379.0,6.0e3]],"prev_change_id":41152099503}}}
[2025-04-07 08:32:44.974] [multi_sink] [info] 📩 Received: {"jsonrpc":"2.0","method":"subscription","params":{"channel":"book.BTC-PERPETUAL.100ms","data":{"timestamp":1743994966451,"type":"change","change_id":41152100766,"instrument_name":"BTC-PERPETUAL","bids":[["delete",78200.5,0.0],["delete",78195.0,0.0],["new",78184.0,8000580.0],["delete",78145.0,0.0]],"asks":[["new",78414.5,6640830.0],["delete",78431.0,0.0],["delete",78534.5,0.0],["delete",78584.5,0.0]],"prev_change_id":41152099979}}}
[2025-04-07 08:32:44.976] [multi_sink] [info] Processing received message: {"jsonrpc":"2.0","method":"subscription","params":{"channel":"book.BTC-PERPETUAL.100ms","data":{"timestamp":1743994966451,"type":"change","change_id":41152100766,"instrument_name":"BTC-PERPETUAL","bids":[["delete",78200.5,0.0],["delete",78195.0,0.0],["new",78184.0,8000580.0],["delete",78145.0,0.0]],"asks":[["new",78414.5,6640830.0],["delete",78431.0,0.0],["delete",78534.5,0.0],["delete",78584.5,0.0]],"prev_change_id":41152099979}}}
[2025-04-07 08:32:45.304] [multi_sink] [info] 📩 Received: {"jsonrpc":"2.0","method":"subscription","params":{"channel":"book.BTC-PERPETUAL.100ms","data":{"timestamp":1743994966787,"type":"change","change_id":41152100980,"instrument_name":"BTC-PERPETUAL","bids":[],"asks":[["new",78567.5,7777770.0],["delete",78584.0,0.0]],"prev_change_id":41152100766}}}
[2025-04-07 08:32:45.306] [multi_sink] [info] Processing received message: {"jsonrpc":"2.0","method":"subscription","params":{"channel":"book.BTC-PERPETUAL.100ms","data":{"timestamp":1743994966787,"type":"change","change_id":41152100980,"instrument_name":"BTC-PERPETUAL","bids":[],"asks":[["new",78567.5,7777770.0],["delete",78584.0,0.0]],"prev_change_id":41152100766}}}
[2025-04-07 08:32:46.745] [multi_sink] [info] 📩 Received: {"jsonrpc":"2.0","method":"subscription","params":{"channel":"book.BTC-PERPETUAL.100ms","data":{"timestamp":1743994968287,"type":"change","change_id":41152103051,"instrument_name":"BTC-PERPETUAL","bids":[["new",78219.0,78210.0],["new",78169.0,117240.0]],"asks":[["new",78546.5,78540.0],["new",78596.5,117890.0]],"prev_change_id":41152100980}}}
[2025-04-07 08:32:46.748] [multi_sink] [info] Processing received message: {"jsonrpc":"2.0","method":"subscription","params":{"channel":"book.BTC-PERPETUAL.100ms","data":{"timestamp":1743994968287,"type":"change","change_id":41152103051,"instrument_name":"BTC-PERPETUAL","bids":[["new",78219.0,78210.0],["new",78169.0,117240.0]],"asks":[["new",78546.5,78540.0],["new",78596.5,117890.0]],"prev_change_id":41152100980}}}
[2025-04-07 08:32:47.085] [multi_sink] [info] 📩 Received: {"jsonrpc":"2.0","method":"subscription","params":{"channel":"book.BTC-PERPETUAL.100ms","data":{"timestamp":1743994968641,"type":"change","change_id":41152103763,"instrument_name":"BTC-PERPETUAL","bids":[],"asks":[["delete",78546.5,0.0],["new",78557.0,78550.0],["delete",78596.5,0.0],["new",78607.0,117910.0]],"prev_change_id":41152103051}}}
[2025-04-07 08:32:47.086] [multi_sink] [info] Processing received message: {"jsonrpc":"2.0","method":"subscription","params":{"channel":"book.BTC-PERPETUAL.100ms","data":{"timestamp":1743994968641,"type":"change","change_id":41152103763,"instrument_name":"BTC-PERPETUAL","bids":[],"asks":[["delete",78546.5,0.0],["new",78557.0,78550.0],["delete",78596.5,0.0],["new",78607.0,117910.0]],"prev_change_id":41152103051}}}
[2025-04-07 08:32:47.199] [multi_sink] [info] 📩 Received: {"jsonrpc":"2.0","method":"subscription","params":{"channel":"book.ETH-PERPETUAL.100ms","data":{"timestamp":1743994968834,"type":"change","change_id":23707298319,"instrument_name":"ETH-PERPETUAL","bids":[],"asks":[["delete",1580.4,0.0],["new",1581.6,28788.0]],"prev_change_id":23707294003}}}
[2025-04-07 08:32:47.200] [multi_sink] [info] Processing received message: {"jsonrpc":"2.0","method":"subscription","params":{"channel":"book.ETH-PERPETUAL.100ms","data":{"timestamp":1743994968834,"type":"change","change_id":23707298319,"instrument_name":"ETH-PERPETUAL","bids":[],"asks":[["delete",1580.4,0.0],["new",1581.6,28788.0]],"prev_change_id":23707294003}}}
[2025-04-07 08:32:47.405] [multi_sink] [info] 📩 Received: {"jsonrpc":"2.0","method":"subscription","params":{"channel":"book.BTC-PERPETUAL.100ms","data":{"timestamp":1743994968835,"type":"change","change_id":41152103902,"instrument_name":"BTC-PERPETUAL","bids":[["delete",78219.0,0.0],["delete",78169.0,0.0]],"asks":[],"prev_change_id":41152103763}}}
[2025-04-07 08:32:47.407] [multi_sink] [info] Processing received message: {"jsonrpc":"2.0","method":"subscription","params":{"channel":"book.BTC-PERPETUAL.100ms","data":{"timestamp":1743994968835,"type":"change","change_id":41152103902,"instrument_name":"BTC-PERPETUAL","bids":[["delete",78219.0,0.0],["delete",78169.0,0.0]],"asks":[],"prev_change_id":41152103763}}}
[2025-04-07 08:32:47.530] [multi_sink] [info] 📩 Received: {"jsonrpc":"2.0","method":"subscription","params":{"channel":"book.ETH-PERPETUAL.100ms","data":{"timestamp":1743994969160,"type":"change","change_id":23707298919,"instrument_name":"ETH-PERPETUAL","bids":[["delete",1580.35,0.0],["delete",1580.15,0.0],["delete",1580.0,0.0],["delete",1579.95,0.0],["delete",1579.9,0.0],["delete",1579.75,0.0],["delete",1579.7,0.0],["change",1579.65,20257.0],["change",1579.6,40323.0],["change",1579.55,12360.0],["change",1579.5,922.0],["change",1579.45,81906.0],["change",1579.4,7547121.0],["change",1579.35,18151.0],["change",1579.3,52674.0],["change",1579.25,13985.0],["change",1579.2,17230.0]],"asks":[["delete",1580.45,0.0],["delete",1580.55,0.0],["delete",1580.6,0.0],["delete",1580.65,0.0],["delete",1580.7,0.0],["delete",1580.75,0.0],["delete",1580.8,0.0],["delete",1580.85,0.0],["delete",1580.9,0.0],["change",1581.15,15614.0],["change",1581.2,59453.0],["new",1581.25,8893.0],["change",1581.3,192449.0],["new",1581.35,20002.0],["new",1581.4,34911.0],["new",1581.45,11105.0],["new",1581.5,52072.0],["new",1581.55,8949.0]],"prev_change_id":23707298319}}}
[2025-04-07 08:32:47.531] [multi_sink] [info] Processing received message: {"jsonrpc":"2.0","method":"subscription","params":{"channel":"book.ETH-PERPETUAL.100ms","data":{"timestamp":1743994969160,"type":"change","change_id":23707298919,"instrument_name":"ETH-PERPETUAL","bids":[["delete",1580.35,0.0],["delete",1580.15,0.0],["delete",1580.0,0.0],["delete",1579.95,0.0],["delete",1579.9,0.0],["delete",1579.75,0.0],["delete",1579.7,0.0],["change",1579.65,20257.0],["change",1579.6,40323.0],["change",1579.55,12360.0],["change",1579.5,922.0],["change",1579.45,81906.0],["change",1579.4,7547121.0],["change",1579.35,18151.0],["change",1579.3,52674.0],["change",1579.25,13985.0],["change",1579.2,17230.0]],"asks":[["delete",1580.45,0.0],["delete",1580.55,0.0],["delete",1580.6,0.0],["delete",1580.65,0.0],["delete",1580.7,0.0],["delete",1580.75,0.0],["delete",1580.8,0.0],["delete",1580.85,0.0],["delete",1580.9,0.0],["change",1581.15,15614.0],["change",1581.2,59453.0],["new",1581.25,8893.0],["change",1581.3,192449.0],["new",1581.35,20002.0],["new",1581.4,34911.0],["new",1581.45,11105.0],["new",1581.5,52072.0],["new",1581.55,8949.0]],"prev_change_id":23707298319}}}
[2025-04-07 08:32:47.860] [multi_sink] [info] 📩 Received: {"jsonrpc":"2.0","method":"subscription","params":{"channel":"book.ETH-PERPETUAL.100ms","data":{"timestamp":1743994969490,"type":"change","change_id":23707299182,"instrument_name":"ETH-PERPETUAL","bids":[["new",1580.05,23466.0],["new",1580.0,16374.0],["new",1579.95,74089.0],["new",1579.9,7376.0],["new",1579.85,1395.0],["new",1579.8,889.0],["new",1579.75,6516.0],["new",1579.7,24093.0],["change",1579.45,40953.0],["change",1579.4,7538606.0],["change",1579.35,9551.0],["change",1579.3,27413.0],["change",1579.25,5393.0],["change",1579.2,8615.0],["delete",1579.15,0.0],["delete",1579.1,0.0]],"asks":[["new",1580.5,366.0],["new",1580.7,5.0e3],["new",1580.75,367.0],["new",1580.8,2998.0],["new",1580.85,9893.0],["new",1580.9,5049163.0],["change",1580.95,100.0],["change",1581.0,467.0],["delete",1581.05,0.0],["change",1581.1,4867.0],["change",1581.15,7621.0],["change",1581.2,31247.0],["change",1581.3,112652.0],["delete",1581.85,0.0]],"prev_change_id":23707298919}}}
[2025-04-07 08:32:47.861] [multi_sink] [info] Processing received message: {"jsonrpc":"2.0","method":"subscription","params":{"channel":"book.ETH-PERPETUAL.100ms","data":{"timestamp":1743994969490,"type":"change","change_id":23707299182,"instrument_name":"ETH-PERPETUAL","bids":[["new",1580.05,23466.0],["new",1580.0,16374.0],["new",1579.95,74089.0],["new",1579.9,7376.0],["new",1579.85,1395.0],["new",1579.8,889.0],["new",1579.75,6516.0],["new",1579.7,24093.0],["change",1579.45,40953.0],["change",1579.4,7538606.0],["change",1579.35,9551.0],["change",1579.3,27413.0],["change",1579.25,5393.0],["change",1579.2,8615.0],["delete",1579.15,0.0],["delete",1579.1,0.0]],"asks":[["new",1580.5,366.0],["new",1580.7,5.0e3],["new",1580.75,367.0],["new",1580.8,2998.0],["new",1580.85,9893.0],["new",1580.9,5049163.0],["change",1580.95,100.0],["change",1581.0,467.0],["delete",1581.05,0.0],["change",1581.1,4867.0],["change",1581.15,7621.0],["change",1581.2,31247.0],["change",1581.3,112652.0],["delete",1581.85,0.0]],"prev_change_id":23707298919}}}
[2025-04-07 08:32:48.190] [multi_sink] [info] 📩 Received: {"jsonrpc":"2.0","method":"subscription","params":{"channel":"book.ETH-PERPETUAL.100ms","data":{"timestamp":1743994969536,"type":"change","change_id":23707299231,"instrument_name":"ETH-PERPETUAL","bids":[["new",1580.2,65587.0],["new",1580.15,81896.0],["delete",1579.05,0.0],["delete",1579.0,0.0]],"asks":[["new",1580.25,548.0]],"prev_change_id":23707299182}}}
[2025-04-07 08:32:48.191] [multi_sink] [info] Processing received message: {"jsonrpc":"2.0","method":"subscription","params":{"channel":"book.ETH-PERPETUAL.100ms","data":{"timestamp":1743994969536,"type":"change","change_id":23707299231,"instrument_name":"ETH-PERPETUAL","bids":[["new",1580.2,65587.0],["new",1580.15,81896.0],["delete",1579.05,0.0],["delete",1579.0,0.0]],"asks":[["new",1580.25,548.0]],"prev_change_id":23707299182}}}
[2025-04-07 08:32:48.760] [multi_sink] [info] 📩 Received: {"jsonrpc":"2.0","method":"subscription","params":{"channel":"book.BTC-PERPETUAL.100ms","data":{"timestamp":1743994970388,"type":"change","change_id":41152106308,"instrument_name":"BTC-PERPETUAL","bids":[["delete",78375.5,0.0],["new",78352.5,9.0e3]],"asks":[["delete",78376.0,0.0],["new",78413.5,5150.0],["delete",78557.0,0.0],["delete",78607.0,0.0]],"prev_change_id":41152103902}}}
