[2025-04-06 23:48:11.207] [multi_sink] [info] 📩 Received: {"jsonrpc":"2.0","method":"subscription","params":{"channel":"book.BTC-PERPETUAL.100ms","data":{"timestamp":1743963492099,"type":"change","change_id":41106264290,"instrument_name":"BTC-PERPETUAL","bids":[["delete",80082.0,0.0],["delete",80079.5,0.0],["delete",80079.0,0.0],["delete",80077.5,0.0],["delete",80074.5,0.0],["delete",80072.0,0.0],["delete",80071.5,0.0],["delete",80069.5,0.0],["delete",80068.5,0.0],["change",80068.0,30230.0]],"asks":[["change",80082.5,10.0],["delete",80084.0,0.0],["delete",80085.0,0.0],["delete",80087.0,0.0],["new",80204.5,8.02e4],["new",80254.5,120380.0]],"prev_change_id":41106263580}}}
[2025-04-06 23:48:11.208] [multi_sink] [info] Processing received message: {"jsonrpc":"2.0","method":"subscription","params":{"channel":"book.BTC-PERPETUAL.100ms","data":{"timestamp":1743963492099,"type":"change","change_id":41106264290,"instrument_name":"BTC-PERPETUAL","bids":[["delete",80082.0,0.0],["delete",80079.5,0.0],["delete",80079.0,0.0],["delete",80077.5,0.0],["delete",80074.5,0.0],["delete",80072.0,0.0],["delete",80071.5,0.0],["delete",80069.5,0.0],["delete",80068.5,0.0],["change",80068.0,30230.0]],"asks":[["change",80082.5,10.0],["delete",80084.0,0.0],["delete",80085.0,0.0],["delete",80087.0,0.0],["new",80204.5,8.02e4],["new",80254.5,120380.0]],"prev_change_id":41106263580}}}
[2025-04-06 23:48:11.209] [multi_sink] [error] Broadcast error: Operation canceled
[2025-04-06 23:48:11.538] [multi_sink] [info] 📩 Received: {"jsonrpc":"2.0","method":"subscription","params":{"channel":"book.BTC-PERPETUAL.100ms","data":{"timestamp":1743963492424,"type":"change","change_id":41106264943,"instrument_name":"BTC-PERPETUAL","bids":[["delete",80068.0,0.0],["delete",80066.5,0.0],["delete",80066.0,0.0],["delete",80065.0,0.0],["delete",80060.0,0.0],["change",80058.0,135490.0]],"asks":[["new",80058.5,5.06e4],["new",80060.0,23790.0],["new",80060.5,420.0],["new",80061.0,4.0e4],["new",80061.5,34450.0],["new",80062.5,14740.0],["delete",80087.5,0.0],["delete",80089.0,0.0],["delete",80090.0,0.0],["delete",80093.5,0.0],["delete",80094.5,0.0],["delete",8.01e4,0.0],["delete",80101.0,0.0],["delete",80102.0,0.0],["delete",80102.5,0.0]],"prev_change_id":41106264290}}}
[2025-04-06 23:48:11.539] [multi_sink] [info] Processing received message: {"jsonrpc":"2.0","method":"subscription","params":{"channel":"book.BTC-PERPETUAL.100ms","data":{"timestamp":1743963492424,"type":"change","change_id":41106264943,"instrument_name":"BTC-PERPETUAL","bids":[["delete",80068.0,0.0],["delete",80066.5,0.0],["delete",80066.0,0.0],["delete",80065.0,0.0],["delete",80060.0,0.0],["change",80058.0,135490.0]],"asks":[["new",80058.5,5.06e4],["new",80060.0,23790.0],["new",80060.5,420.0],["new",80061.0,4.0e4],["new",80061.5,34450.0],["new",80062.5,14740.0],["delete",80087.5,0.0],["delete",80089.0,0.0],["delete",80090.0,0.0],["delete",80093.5,0.0],["delete",80094.5,0.0],["delete",8.01e4,0.0],["delete",80101.0,0.0],["delete",80102.0,0.0],["delete",80102.5,0.0]],"prev_change_id":41106264290}}}
[2025-04-06 23:48:11.540] [multi_sink] [error] Broadcast error: Operation canceled
[2025-04-06 23:48:11.867] [multi_sink] [info] 📩 Received: {"jsonrpc":"2.0","method":"subscription","params":{"channel":"book.BTC-PERPETUAL.100ms","data":{"timestamp":1743963492696,"type":"change","change_id":41106265335,"instrument_name":"BTC-PERPETUAL","bids":[["delete",80058.0,0.0],["delete",80057.5,0.0],["delete",80056.5,0.0],["delete",80052.5,0.0],["delete",80052.0,0.0],["delete",80051.5,0.0],["delete",80051.0,0.0],["change",80050.0,5719560.0],["new",80042.5,34110.0],["new",80039.0,20950.0],["new",79875.5,79870.0],["new",79825.5,119730.0]],"asks":[["new",80052.5,73750.0],["new",80098.5,3680.0],["delete",80104.0,0.0],["delete",80106.0,0.0],["delete",80107.0,0.0],["delete",80107.5,0.0],["delete",80108.0,0.0],["delete",80108.5,0.0],["delete",80109.0,0.0]],"prev_change_id":41106264943}}}
[2025-04-06 23:48:11.869] [multi_sink] [info] Processing received message: {"jsonrpc":"2.0","method":"subscription","params":{"channel":"book.BTC-PERPETUAL.100ms","data":{"timestamp":1743963492696,"type":"change","change_id":41106265335,"instrument_name":"BTC-PERPETUAL","bids":[["delete",80058.0,0.0],["delete",80057.5,0.0],["delete",80056.5,0.0],["delete",80052.5,0.0],["delete",80052.0,0.0],["delete",80051.5,0.0],["delete",80051.0,0.0],["change",80050.0,5719560.0],["new",80042.5,34110.0],["new",80039.0,20950.0],["new",79875.5,79870.0],["new",79825.5,119730.0]],"asks":[["new",80052.5,73750.0],["new",80098.5,3680.0],["delete",80104.0,0.0],["delete",80106.0,0.0],["delete",80107.0,0.0],["delete",80107.5,0.0],["delete",80108.0,0.0],["delete",80108.5,0.0],["delete",80109.0,0.0]],"prev_change_id":41106264943}}}
[2025-04-06 23:48:11.871] [multi_sink] [error] Broadcast error: Operation canceled
[2025-04-06 23:48:12.562] [multi_sink] [info] 📩 Received: {"jsonrpc":"2.0","method":"subscription","params":{"channel":"book.BTC-PERPETUAL.100ms","data":{"timestamp":1743963493305,"type":"change","change_id":41106266417,"instrument_name":"BTC-PERPETUAL","bids":[],"asks":[["delete",80082.5,0.0]],"prev_change_id":41106265335}}}
[2025-04-06 23:48:12.566] [multi_sink] [info] Processing received message: {"jsonrpc":"2.0","method":"subscription","params":{"channel":"book.BTC-PERPETUAL.100ms","data":{"timestamp":1743963493305,"type":"change","change_id":41106266417,"instrument_name":"BTC-PERPETUAL","bids":[],"asks":[["delete",80082.5,0.0]],"prev_change_id":41106265335}}}
[2025-04-06 23:48:12.567] [multi_sink] [error] Broadcast error: Operation canceled
[2025-04-06 23:48:12.892] [multi_sink] [info] 📩 Received: {"jsonrpc":"2.0","method":"subscription","params":{"channel":"book.BTC-PERPETUAL.100ms","data":{"timestamp":1743963493601,"type":"change","change_id":41106266899,"instrument_name":"BTC-PERPETUAL","bids":[],"asks":[["new",80050.5,10.0]],"prev_change_id":41106266417}}}
[2025-04-06 23:48:12.897] [multi_sink] [info] Processing received message: {"jsonrpc":"2.0","method":"subscription","params":{"channel":"book.BTC-PERPETUAL.100ms","data":{"timestamp":1743963493601,"type":"change","change_id":41106266899,"instrument_name":"BTC-PERPETUAL","bids":[],"asks":[["new",80050.5,10.0]],"prev_change_id":41106266417}}}
[2025-04-06 23:48:12.897] [multi_sink] [error] Broadcast error: Operation canceled
[2025-04-06 23:48:13.223] [multi_sink] [info] 📩 Received: {"jsonrpc":"2.0","method":"subscription","params":{"channel":"book.BTC-PERPETUAL.100ms","data":{"timestamp":1743963493898,"type":"change","change_id":41106267312,"instrument_name":"BTC-PERPETUAL","bids":[["change",80050.0,5710350.0],["delete",79875.5,0.0],["delete",79825.5,0.0]],"asks":[["delete",80204.5,0.0],["delete",80254.5,0.0]],"prev_change_id":41106266899}}}
[2025-04-06 23:48:13.227] [multi_sink] [info] Processing received message: {"jsonrpc":"2.0","method":"subscription","params":{"channel":"book.BTC-PERPETUAL.100ms","data":{"timestamp":1743963493898,"type":"change","change_id":41106267312,"instrument_name":"BTC-PERPETUAL","bids":[["change",80050.0,5710350.0],["delete",79875.5,0.0],["delete",79825.5,0.0]],"asks":[["delete",80204.5,0.0],["delete",80254.5,0.0]],"prev_change_id":41106266899}}}
[2025-04-06 23:48:13.229] [multi_sink] [error] Broadcast error: Operation canceled
[2025-04-06 23:48:13.554] [multi_sink] [info] 📩 Received: {"jsonrpc":"2.0","method":"subscription","params":{"channel":"book.BTC-PERPETUAL.100ms","data":{"timestamp":1743963494117,"type":"change","change_id":41106267325,"instrument_name":"BTC-PERPETUAL","bids":[],"asks":[["new",80091.5,7350.0]],"prev_change_id":41106267312}}}
[2025-04-06 23:48:13.554] [multi_sink] [info] Processing received message: {"jsonrpc":"2.0","method":"subscription","params":{"channel":"book.BTC-PERPETUAL.100ms","data":{"timestamp":1743963494117,"type":"change","change_id":41106267325,"instrument_name":"BTC-PERPETUAL","bids":[],"asks":[["new",80091.5,7350.0]],"prev_change_id":41106267312}}}
[2025-04-06 23:48:13.555] [multi_sink] [error] Broadcast error: Operation canceled
[2025-04-06 23:48:13.885] [multi_sink] [info] 📩 Received: {"jsonrpc":"2.0","method":"subscription","params":{"channel":"book.BTC-PERPETUAL.100ms","data":{"timestamp":1743963494552,"type":"change","change_id":41106268317,"instrument_name":"BTC-PERPETUAL","bids":[["delete",79872.5,0.0],["new",79847.0,8.0085e6]],"asks":[],"prev_change_id":41106267325}}}
[2025-04-06 23:48:13.888] [multi_sink] [info] Processing received message: {"jsonrpc":"2.0","method":"subscription","params":{"channel":"book.BTC-PERPETUAL.100ms","data":{"timestamp":1743963494552,"type":"change","change_id":41106268317,"instrument_name":"BTC-PERPETUAL","bids":[["delete",79872.5,0.0],["new",79847.0,8.0085e6]],"asks":[],"prev_change_id":41106267325}}}
[2025-04-06 23:48:13.888] [multi_sink] [error] Broadcast error: Operation canceled
[2025-04-06 23:48:14.215] [multi_sink] [info] 📩 Received: {"jsonrpc":"2.0","method":"subscription","params":{"channel":"book.BTC-PERPETUAL.100ms","data":{"timestamp":1743963495026,"type":"change","change_id":41106268709,"instrument_name":"BTC-PERPETUAL","bids":[],"asks":[["new",80238.5,7777770.0],["delete",80264.0,0.0]],"prev_change_id":41106268317}}}
[2025-04-06 23:48:14.218] [multi_sink] [info] Processing received message: {"jsonrpc":"2.0","method":"subscription","params":{"channel":"book.BTC-PERPETUAL.100ms","data":{"timestamp":1743963495026,"type":"change","change_id":41106268709,"instrument_name":"BTC-PERPETUAL","bids":[],"asks":[["new",80238.5,7777770.0],["delete",80264.0,0.0]],"prev_change_id":41106268317}}}
[2025-04-06 23:48:14.219] [multi_sink] [error] Broadcast error: Operation canceled
[2025-04-06 23:48:14.880] [multi_sink] [info] 📩 Received: {"jsonrpc":"2.0","method":"subscription","params":{"channel":"book.BTC-PERPETUAL.100ms","data":{"timestamp":1743963495559,"type":"change","change_id":41106269622,"instrument_name":"BTC-PERPETUAL","bids":[["delete",80050.0,0.0],["new",79998.5,5710350.0]],"asks":[],"prev_change_id":41106268709}}}
[2025-04-06 23:48:14.881] [multi_sink] [info] Processing received message: {"jsonrpc":"2.0","method":"subscription","params":{"channel":"book.BTC-PERPETUAL.100ms","data":{"timestamp":1743963495559,"type":"change","change_id":41106269622,"instrument_name":"BTC-PERPETUAL","bids":[["delete",80050.0,0.0],["new",79998.5,5710350.0]],"asks":[],"prev_change_id":41106268709}}}
[2025-04-06 23:48:14.882] [multi_sink] [error] Broadcast error: Operation canceled
[2025-04-06 23:48:15.582] [multi_sink] [info] 📩 Received: {"jsonrpc":"2.0","method":"subscription","params":{"channel":"book.BTC-PERPETUAL.100ms","data":{"timestamp":1743963496403,"type":"change","change_id":41106270669,"instrument_name":"BTC-PERPETUAL","bids":[],"asks":[["delete",80129.5,0.0]],"prev_change_id":41106269622}}}
[2025-04-06 23:48:15.584] [multi_sink] [info] Processing received message: {"jsonrpc":"2.0","method":"subscription","params":{"channel":"book.BTC-PERPETUAL.100ms","data":{"timestamp":1743963496403,"type":"change","change_id":41106270669,"instrument_name":"BTC-PERPETUAL","bids":[],"asks":[["delete",80129.5,0.0]],"prev_change_id":41106269622}}}
[2025-04-06 23:48:15.584] [multi_sink] [error] Broadcast error: Operation canceled
[2025-04-06 23:48:16.248] [multi_sink] [info] 📩 Received: {"jsonrpc":"2.0","method":"subscription","params":{"channel":"book.BTC-PERPETUAL.100ms","data":{"timestamp":1743963497137,"type":"change","change_id":41106271374,"instrument_name":"BTC-PERPETUAL","bids":[["delete",80042.5,0.0],["delete",80039.0,0.0],["change",80017.5,18430.0],["new",80017.0,81640.0],["new",80016.0,83190.0],["new",80015.5,1.19e4]],"asks":[["delete",80052.5,0.0],["delete",80058.5,0.0],["delete",80060.0,0.0],["delete",80060.5,0.0],["delete",80061.0,0.0],["change",80062.5,24410.0],["new",80063.5,1.1e3],["new",80064.0,34590.0],["new",80064.5,81640.0],["new",80066.0,8360.0]],"prev_change_id":41106270669}}}
[2025-04-06 23:48:16.250] [multi_sink] [info] Processing received message: {"jsonrpc":"2.0","method":"subscription","params":{"channel":"book.BTC-PERPETUAL.100ms","data":{"timestamp":1743963497137,"type":"change","change_id":41106271374,"instrument_name":"BTC-PERPETUAL","bids":[["delete",80042.5,0.0],["delete",80039.0,0.0],["change",80017.5,18430.0],["new",80017.0,81640.0],["new",80016.0,83190.0],["new",80015.5,1.19e4]],"asks":[["delete",80052.5,0.0],["delete",80058.5,0.0],["delete",80060.0,0.0],["delete",80060.5,0.0],["delete",80061.0,0.0],["change",80062.5,24410.0],["new",80063.5,1.1e3],["new",80064.0,34590.0],["new",80064.5,81640.0],["new",80066.0,8360.0]],"prev_change_id":41106270669}}}
[2025-04-06 23:48:16.251] [multi_sink] [error] Broadcast error: Operation canceled
[2025-04-06 23:48:16.578] [multi_sink] [info] 📩 Received: {"jsonrpc":"2.0","method":"subscription","params":{"channel":"book.BTC-PERPETUAL.100ms","data":{"timestamp":1743963497457,"type":"change","change_id":41106272025,"instrument_name":"BTC-PERPETUAL","bids":[["new",80025.0,653270.0],["new",80024.5,8.0e4],["new",80023.0,58310.0],["new",80022.5,13570.0],["new",80021.0,34770.0],["new",80020.5,4180.0],["new",80020.0,199250.0],["new",80018.0,5750.0]],"asks":[["new",80051.5,1.0e4],["new",80052.0,20860.0],["new",80052.5,3.5e4],["new",80053.0,34450.0],["new",80057.0,2.9e3],["new",80057.5,9670.0],["new",80061.0,4.0e4],["change",80061.5,29850.0],["new",80062.0,16490.0],["change",80062.5,9670.0]],"prev_change_id":41106271374}}}
[2025-04-06 23:48:16.578] [multi_sink] [info] Processing received message: {"jsonrpc":"2.0","method":"subscription","params":{"channel":"book.BTC-PERPETUAL.100ms","data":{"timestamp":1743963497457,"type":"change","change_id":41106272025,"instrument_name":"BTC-PERPETUAL","bids":[["new",80025.0,653270.0],["new",80024.5,8.0e4],["new",80023.0,58310.0],["new",80022.5,13570.0],["new",80021.0,34770.0],["new",80020.5,4180.0],["new",80020.0,199250.0],["new",80018.0,5750.0]],"asks":[["new",80051.5,1.0e4],["new",80052.0,20860.0],["new",80052.5,3.5e4],["new",80053.0,34450.0],["new",80057.0,2.9e3],["new",80057.5,9670.0],["new",80061.0,4.0e4],["change",80061.5,29850.0],["new",80062.0,16490.0],["change",80062.5,9670.0]],"prev_change_id":41106271374}}}
[2025-04-06 23:48:16.579] [multi_sink] [error] Broadcast error: Operation canceled
[2025-04-06 23:48:16.911] [multi_sink] [info] 📩 Received: {"jsonrpc":"2.0","method":"subscription","params":{"channel":"book.BTC-PERPETUAL.100ms","data":{"timestamp":1743963497695,"type":"change","change_id":41106272394,"instrument_name":"BTC-PERPETUAL","bids":[["new",80029.5,1.447e5],["new",80029.0,3.5e4],["new",80028.5,1.0e4],["new",80027.0,490.0],["new",80026.5,16490.0],["new",80026.0,62750.0],["new",80025.5,1.656e5]],"asks":[["new",80030.0,54650.0],["new",80043.0,100.0],["new",80048.5,490.0],["new",80049.0,8.8e3],["new",80049.5,5750.0],["change",80050.5,13580.0]],"prev_change_id":41106272025}}}
[2025-04-06 23:48:16.915] [multi_sink] [info] Processing received message: {"jsonrpc":"2.0","method":"subscription","params":{"channel":"book.BTC-PERPETUAL.100ms","data":{"timestamp":1743963497695,"type":"change","change_id":41106272394,"instrument_name":"BTC-PERPETUAL","bids":[["new",80029.5,1.447e5],["new",80029.0,3.5e4],["new",80028.5,1.0e4],["new",80027.0,490.0],["new",80026.5,16490.0],["new",80026.0,62750.0],["new",80025.5,1.656e5]],"asks":[["new",80030.0,54650.0],["new",80043.0,100.0],["new",80048.5,490.0],["new",80049.0,8.8e3],["new",80049.5,5750.0],["change",80050.5,13580.0]],"prev_change_id":41106272025}}}
[2025-04-06 23:48:16.916] [multi_sink] [error] Broadcast error: Operation canceled
[2025-04-06 23:48:18.006] [multi_sink] [info] 📩 Received: {"jsonrpc":"2.0","method":"subscription","params":{"channel":"book.BTC-PERPETUAL.100ms","data":{"timestamp":1743963498898,"type":"change","change_id":41106274317,"instrument_name":"BTC-PERPETUAL","bids":[],"asks":[["new",80196.5,80190.0]],"prev_change_id":41106272394}}}
[2025-04-06 23:48:18.010] [multi_sink] [info] Processing received message: {"jsonrpc":"2.0","method":"subscription","params":{"channel":"book.BTC-PERPETUAL.100ms","data":{"timestamp":1743963498898,"type":"change","change_id":41106274317,"instrument_name":"BTC-PERPETUAL","bids":[],"asks":[["new",80196.5,80190.0]],"prev_change_id":41106272394}}}
[2025-04-06 23:48:18.011] [multi_sink] [error] Broadcast error: Operation canceled
[2025-04-06 23:48:18.338] [multi_sink] [info] 📩 Received: {"jsonrpc":"2.0","method":"subscription","params":{"channel":"book.BTC-PERPETUAL.100ms","data":{"timestamp":1743963499201,"type":"change","change_id":41106274719,"instrument_name":"BTC-PERPETUAL","bids":[["new",79872.5,79870.0],["new",79822.5,119730.0]],"asks":[["change",80030.0,54660.0],["change",80050.5,13570.0],["new",80246.5,120370.0]],"prev_change_id":41106274317}}}
[2025-04-06 23:48:18.340] [multi_sink] [info] Processing received message: {"jsonrpc":"2.0","method":"subscription","params":{"channel":"book.BTC-PERPETUAL.100ms","data":{"timestamp":1743963499201,"type":"change","change_id":41106274719,"instrument_name":"BTC-PERPETUAL","bids":[["new",79872.5,79870.0],["new",79822.5,119730.0]],"asks":[["change",80030.0,54660.0],["change",80050.5,13570.0],["new",80246.5,120370.0]],"prev_change_id":41106274317}}}
[2025-04-06 23:48:18.341] [multi_sink] [error] Broadcast error: Operation canceled
[2025-04-06 23:48:19.001] [multi_sink] [info] 📩 Received: {"jsonrpc":"2.0","method":"subscription","params":{"channel":"book.BTC-PERPETUAL.100ms","data":{"timestamp":1743963499895,"type":"change","change_id":41106275699,"instrument_name":"BTC-PERPETUAL","bids":[],"asks":[["new",80031.5,8.0e3]],"prev_change_id":41106274719}}}
[2025-04-06 23:48:19.005] [multi_sink] [info] Processing received message: {"jsonrpc":"2.0","method":"subscription","params":{"channel":"book.BTC-PERPETUAL.100ms","data":{"timestamp":1743963499895,"type":"change","change_id":41106275699,"instrument_name":"BTC-PERPETUAL","bids":[],"asks":[["new",80031.5,8.0e3]],"prev_change_id":41106274719}}}
[2025-04-06 23:48:19.006] [multi_sink] [error] Broadcast error: Operation canceled
[2025-04-06 23:48:19.023] [multi_sink] [info] Removed client session: 140545758343024
[2025-04-06 23:48:19.334] [multi_sink] [info] 📩 Received: {"jsonrpc":"2.0","method":"subscription","params":{"channel":"book.BTC-PERPETUAL.100ms","data":{"timestamp":1743963499968,"type":"change","change_id":41106275700,"instrument_name":"BTC-PERPETUAL","bids":[],"asks":[["new",80031.0,8.0e3],["delete",80031.5,0.0]],"prev_change_id":41106275699}}}
[2025-04-06 23:48:19.335] [multi_sink] [info] Processing received message: {"jsonrpc":"2.0","method":"subscription","params":{"channel":"book.BTC-PERPETUAL.100ms","data":{"timestamp":1743963499968,"type":"change","change_id":41106275700,"instrument_name":"BTC-PERPETUAL","bids":[],"asks":[["new",80031.0,8.0e3],["delete",80031.5,0.0]],"prev_change_id":41106275699}}}
[2025-04-06 23:48:19.336] [multi_sink] [error] Broadcast error: Operation canceled
[2025-04-06 23:48:19.337] [multi_sink] [error] Broadcast error: Operation canceled
[2025-04-06 23:48:19.663] [multi_sink] [info] 📩 Received: {"jsonrpc":"2.0","method":"subscription","params":{"channel":"book.BTC-PERPETUAL.100ms","data":{"timestamp":1743963500374,"type":"change","change_id":41106276325,"instrument_name":"BTC-PERPETUAL","bids":[],"asks":[["new",80030.5,8.0e3],["delete",80031.0,0.0]],"prev_change_id":41106275700}}}
[2025-04-06 23:48:19.666] [multi_sink] [info] Processing received message: {"jsonrpc":"2.0","method":"subscription","params":{"channel":"book.BTC-PERPETUAL.100ms","data":{"timestamp":1743963500374,"type":"change","change_id":41106276325,"instrument_name":"BTC-PERPETUAL","bids":[],"asks":[["new",80030.5,8.0e3],["delete",80031.0,0.0]],"prev_change_id":41106275700}}}
[2025-04-06 23:48:19.667] [multi_sink] [error] Broadcast error: Operation canceled
[2025-04-06 23:48:19.667] [multi_sink] [error] Broadcast error: Operation canceled
[2025-04-06 23:48:20.593] [multi_sink] [info] Received message from client 140545758343072: {"subscribe": "ETH-PERPETUAL.100ms"}
[2025-04-06 23:48:20.593] [multi_sink] [info] Added subscription for client 140545758343072 to channel ETH-PERPETUAL.100ms
[2025-04-06 23:48:20.593] [multi_sink] [info] ➡️ Added to send queue: {"id":"subscribe#5","jsonrpc":"2.0","method":"private/subscribe","params":{"channels":["book.ETH-PERPETUAL.100ms"]}}
[2025-04-06 23:48:20.593] [multi_sink] [info] ➡️ Sent: {"id":"subscribe#5","jsonrpc":"2.0","method":"private/subscribe","params":{"channels":["book.ETH-PERPETUAL.100ms"]}}
[2025-04-06 23:48:20.593] [multi_sink] [info]  Subscribed to ETH-PERPETUAL.100ms order book
[2025-04-06 23:48:20.594] [multi_sink] [debug] Updated activity for client: 140545758343072
[2025-04-06 23:48:20.766] [multi_sink] [info] 📩 Received: {"jsonrpc":"2.0","id":"subscribe#5","result":["book.ETH-PERPETUAL.100ms"],"usIn":1743963501647775,"usOut":1743963501647950,"usDiff":175,"testnet":true}
[2025-04-06 23:48:20.766] [multi_sink] [info] 📩 Received: {"jsonrpc":"2.0","method":"subscription","params":{"channel":"book.ETH-PERPETUAL.100ms","data":{"timestamp":1743963501167,"type":"snapshot","change_id":23674083665,"instrument_name":"ETH-PERPETUAL","bids":[["new",1658.55,7362413.0],["new",1656.7,356.0],["new",1656.65,672.0],["new",1656.55,63.0],["new",1656.45,1519.0],["new",1656.4,10646.0],["new",1656.3,5.1e3],["new",1656.25,15807.0],["new",1656.2,5.2e3],["new",1656.15,7731.0],["new",1656.1,8593.0],["new",1656.05,1171.0],["new",1656.0,1171.0],["new",1655.95,7640.0],["new",1655.9,2.5e4],["new",1655.85,18224.0],["new",1655.8,9062.0],["new",1655.75,17902.0],["new",1655.7,30920.0],["new",1655.65,5.56e4],["new",1655.6,8615.0],["new",1650.2,500.0],["new",1642.7,700.0],["new",1.5e3,1402018.0],["new",1386.9,4.0],["new",1359.3,1.0],["new",1242.0,64580.0],["new",1234.0,120.0],["new",1215.1,223.0],["new",1.2e3,709.0],["new",1199.9,1.0e4],["new",1193.9,2.0e4],["new",1102.0,43740.0],["new",1.0e3,1006.0],["new",942.0,131220.0],["new",900.0,4.6e3],["new",800.0,1.74e4],["new",762.0,393660.0],["new",750.8,386.0],["new",701.0,45.0],["new",691.0,49.0],["new",681.0,53.0],["new",671.0,56.0],["new",661.0,59.0],["new",651.0,61.0],["new",641.0,61.0],["new",631.0,62.0],["new",623.45,915.0],["new",621.0,62.0],["new",611.0,60.0],["new",601.0,58.0],["new",600.0,2509.0],["new",591.0,55.0],["new",581.0,52.0],["new",571.0,47.0],["new",561.0,43.0],["new",551.0,37.0],["new",541.0,32.0],["new",531.0,27.0],["new",524.0,87474.0],["new",521.0,22.0],["new",511.0,17.0],["new",501.0,13.0],["new",500.0,3119.0],["new",400.0,250033.0],["new",350.0,240.0],["new",345.0,50.0],["new",332.1,301.0],["new",324.65,482.0],["new",317.2,784.0],["new",309.75,1267.0],["new",302.35,2052.0],["new",300.0,251006.0],["new",294.9,3320.0],["new",287.45,5372.0],["new",260.0,5.0e5],["new",222.0,20.0],["new",212.0,2.0],["new",200.0,62.0],["new",199.0,100.0],["new",195.0,2.0e3],["new",192.0,2.0],["new",181.0,1.2e5],["new",172.05,30.0],["new",150.0,30.0],["new",143.55,20.0],["new",140.0,1.0e5],["new",135.0,200010.0],["new",130.0,300020.0],["new",125.0,400020.0],["new",121.0,12.0],["new",120.0,130.0],["new",115.0,20.0],["new",110.0,30.0],["new",105.0,20.0],["new",101.0,10.0],["new",100.0,1018.0],["new",60.0,280.0],["new",58.0,1.0],["new",55.0,45.0],["new",50.0,710.0],["new",45.0,10000005.0],["new",32.0,5.0],["new",30.0,70.0],["new",29.0,220.0],["new",25.0,20.0],["new",22.2,1.0],["new",21.0,10.0],["new",20.0,2210.0],["new",10.0,370.0],["new",9.95,1.0],["new",6.0,200.0],["new",5.0,43.0],["new",4.0,1844.0],["new",1.45,1330.0],["new",1.1,7.0],["new",1.0,86.0],["new",0.5,24.0]],"asks":[["new",1660.15,5398965.0],["new",1663.7,500.0],["new",1667.6,500.0],["new",1676.75,700.0],["new",1718.15,1.3e3],["new",2341.0,26.0],["new",2.4e3,2.4e3],["new",2571.75,1.0],["new",3024.2,1.0e6],["new",4.0e3,92.0],["new",4048.1,4.0],["new",4160.0,16.0],["new",4.5e3,135.0],["new",5.0e3,15450.0],["new",5555.0,10001.0],["new",7180.4,1.0],["new",9999.95,1.0],["new",1.0e4,15.0],["new",1.1e4,20.0],["new",18285.0,3.0e4],["new",2.0e4,3.4e3],["new",3.01e4,170.0],["new",3.85e4,40.0],["new",5.0e4,11.0],["new",51853.0,10.0],["new",9.0e4,2.0e3]]}}}
[2025-04-06 23:48:20.770] [multi_sink] [info] Processing received message: {"jsonrpc":"2.0","id":"subscribe#5","result":["book.ETH-PERPETUAL.100ms"],"usIn":1743963501647775,"usOut":1743963501647950,"usDiff":175,"testnet":true}
[2025-04-06 23:48:20.770] [multi_sink] [error] Broadcast error: Operation canceled
[2025-04-06 23:48:20.770] [multi_sink] [error] Broadcast error: Operation canceled
[2025-04-06 23:48:20.771] [multi_sink] [info] Processing received message: {"jsonrpc":"2.0","method":"subscription","params":{"channel":"book.ETH-PERPETUAL.100ms","data":{"timestamp":1743963501167,"type":"snapshot","change_id":23674083665,"instrument_name":"ETH-PERPETUAL","bids":[["new",1658.55,7362413.0],["new",1656.7,356.0],["new",1656.65,672.0],["new",1656.55,63.0],["new",1656.45,1519.0],["new",1656.4,10646.0],["new",1656.3,5.1e3],["new",1656.25,15807.0],["new",1656.2,5.2e3],["new",1656.15,7731.0],["new",1656.1,8593.0],["new",1656.05,1171.0],["new",1656.0,1171.0],["new",1655.95,7640.0],["new",1655.9,2.5e4],["new",1655.85,18224.0],["new",1655.8,9062.0],["new",1655.75,17902.0],["new",1655.7,30920.0],["new",1655.65,5.56e4],["new",1655.6,8615.0],["new",1650.2,500.0],["new",1642.7,700.0],["new",1.5e3,1402018.0],["new",1386.9,4.0],["new",1359.3,1.0],["new",1242.0,64580.0],["new",1234.0,120.0],["new",1215.1,223.0],["new",1.2e3,709.0],["new",1199.9,1.0e4],["new",1193.9,2.0e4],["new",1102.0,43740.0],["new",1.0e3,1006.0],["new",942.0,131220.0],["new",900.0,4.6e3],["new",800.0,1.74e4],["new",762.0,393660.0],["new",750.8,386.0],["new",701.0,45.0],["new",691.0,49.0],["new",681.0,53.0],["new",671.0,56.0],["new",661.0,59.0],["new",651.0,61.0],["new",641.0,61.0],["new",631.0,62.0],["new",623.45,915.0],["new",621.0,62.0],["new",611.0,60.0],["new",601.0,58.0],["new",600.0,2509.0],["new",591.0,55.0],["new",581.0,52.0],["new",571.0,47.0],["new",561.0,43.0],["new",551.0,37.0],["new",541.0,32.0],["new",531.0,27.0],["new",524.0,87474.0],["new",521.0,22.0],["new",511.0,17.0],["new",501.0,13.0],["new",500.0,3119.0],["new",400.0,250033.0],["new",350.0,240.0],["new",345.0,50.0],["new",332.1,301.0],["new",324.65,482.0],["new",317.2,784.0],["new",309.75,1267.0],["new",302.35,2052.0],["new",300.0,251006.0],["new",294.9,3320.0],["new",287.45,5372.0],["new",260.0,5.0e5],["new",222.0,20.0],["new",212.0,2.0],["new",200.0,62.0],["new",199.0,100.0],["new",195.0,2.0e3],["new",192.0,2.0],["new",181.0,1.2e5],["new",172.05,30.0],["new",150.0,30.0],["new",143.55,20.0],["new",140.0,1.0e5],["new",135.0,200010.0],["new",130.0,300020.0],["new",125.0,400020.0],["new",121.0,12.0],["new",120.0,130.0],["new",115.0,20.0],["new",110.0,30.0],["new",105.0,20.0],["new",101.0,10.0],["new",100.0,1018.0],["new",60.0,280.0],["new",58.0,1.0],["new",55.0,45.0],["new",50.0,710.0],["new",45.0,10000005.0],["new",32.0,5.0],["new",30.0,70.0],["new",29.0,220.0],["new",25.0,20.0],["new",22.2,1.0],["new",21.0,10.0],["new",20.0,2210.0],["new",10.0,370.0],["new",9.95,1.0],["new",6.0,200.0],["new",5.0,43.0],["new",4.0,1844.0],["new",1.45,1330.0],["new",1.1,7.0],["new",1.0,86.0],["new",0.5,24.0]],"asks":[["new",1660.15,5398965.0],["new",1663.7,500.0],["new",1667.6,500.0],["new",1676.75,700.0],["new",1718.15,1.3e3],["new",2341.0,26.0],["new",2.4e3,2.4e3],["new",2571.75,1.0],["new",3024.2,1.0e6],["new",4.0e3,92.0],["new",4048.1,4.0],["new",4160.0,16.0],["new",4.5e3,135.0],["new",5.0e3,15450.0],["new",5555.0,10001.0],["new",7180.4,1.0],["new",9999.95,1.0],["new",1.0e4,15.0],["new",1.1e4,20.0],["new",18285.0,3.0e4],["new",2.0e4,3.4e3],["new",3.01e4,170.0],["new",3.85e4,40.0],["new",5.0e4,11.0],["new",51853.0,10.0],["new",9.0e4,2.0e3]]}}}
[2025-04-06 23:48:20.773] [multi_sink] [error] Broadcast error: Operation canceled
[2025-04-06 23:48:20.773] [multi_sink] [error] Broadcast error: Operation canceled
[2025-04-06 23:48:20.868] [multi_sink] [info] 📩 Received: {"jsonrpc":"2.0","method":"subscription","params":{"channel":"book.ETH-PERPETUAL.100ms","data":{"timestamp":1743963501722,"type":"change","change_id":23674084329,"instrument_name":"ETH-PERPETUAL","bids":[["delete",1658.55,0.0],["change",1655.9,7387413.0]],"asks":[],"prev_change_id":23674083665}}}
[2025-04-06 23:48:20.871] [multi_sink] [info] Processing received message: {"jsonrpc":"2.0","method":"subscription","params":{"channel":"book.ETH-PERPETUAL.100ms","data":{"timestamp":1743963501722,"type":"change","change_id":23674084329,"instrument_name":"ETH-PERPETUAL","bids":[["delete",1658.55,0.0],["change",1655.9,7387413.0]],"asks":[],"prev_change_id":23674083665}}}
[2025-04-06 23:48:20.872] [multi_sink] [error] Broadcast error: Operation canceled
[2025-04-06 23:48:20.873] [multi_sink] [error] Broadcast error: Operation canceled
[2025-04-06 23:48:20.949] [multi_sink] [info] 📩 Received: {"jsonrpc":"2.0","method":"subscription","params":{"channel":"book.BTC-PERPETUAL.100ms","data":{"timestamp":1743963501743,"type":"change","change_id":41106278038,"instrument_name":"BTC-PERPETUAL","bids":[],"asks":[["change",80030.0,62660.0],["delete",80030.5,0.0]],"prev_change_id":41106276325}}}
[2025-04-06 23:48:20.950] [multi_sink] [info] Processing received message: {"jsonrpc":"2.0","method":"subscription","params":{"channel":"book.BTC-PERPETUAL.100ms","data":{"timestamp":1743963501743,"type":"change","change_id":41106278038,"instrument_name":"BTC-PERPETUAL","bids":[],"asks":[["change",80030.0,62660.0],["delete",80030.5,0.0]],"prev_change_id":41106276325}}}
[2025-04-06 23:48:20.950] [multi_sink] [error] Broadcast error: Operation canceled
[2025-04-06 23:48:20.950] [multi_sink] [error] Broadcast error: Operation canceled
[2025-04-06 23:48:21.283] [multi_sink] [info] 📩 Received: {"jsonrpc":"2.0","method":"subscription","params":{"channel":"book.BTC-PERPETUAL.100ms","data":{"timestamp":1743963502139,"type":"change","change_id":41106278361,"instrument_name":"BTC-PERPETUAL","bids":[["delete",80029.5,0.0],["delete",80029.0,0.0],["delete",80028.5,0.0],["delete",80027.0,0.0],["delete",80026.5,0.0],["new",80013.0,16490.0],["new",80012.0,60.0],["new",80011.0,339460.0],["new",80010.5,1.0e6]],"asks":[["new",80027.0,7510.0],["change",80030.0,10.0],["delete",80043.0,0.0],["delete",80048.5,0.0],["delete",80049.0,0.0],["delete",80049.5,0.0],["change",80053.0,6.89e4],["new",80053.5,9670.0],["change",80057.5,21790.0],["new",80060.5,54140.0],["change",80061.0,8.0e4]],"prev_change_id":41106278038}}}
[2025-04-06 23:48:21.285] [multi_sink] [info] Processing received message: {"jsonrpc":"2.0","method":"subscription","params":{"channel":"book.BTC-PERPETUAL.100ms","data":{"timestamp":1743963502139,"type":"change","change_id":41106278361,"instrument_name":"BTC-PERPETUAL","bids":[["delete",80029.5,0.0],["delete",80029.0,0.0],["delete",80028.5,0.0],["delete",80027.0,0.0],["delete",80026.5,0.0],["new",80013.0,16490.0],["new",80012.0,60.0],["new",80011.0,339460.0],["new",80010.5,1.0e6]],"asks":[["new",80027.0,7510.0],["change",80030.0,10.0],["delete",80043.0,0.0],["delete",80048.5,0.0],["delete",80049.0,0.0],["delete",80049.5,0.0],["change",80053.0,6.89e4],["new",80053.5,9670.0],["change",80057.5,21790.0],["new",80060.5,54140.0],["change",80061.0,8.0e4]],"prev_change_id":41106278038}}}
[2025-04-06 23:48:21.286] [multi_sink] [error] Broadcast error: Operation canceled
[2025-04-06 23:48:21.287] [multi_sink] [error] Broadcast error: Operation canceled
[2025-04-06 23:48:21.539] [multi_sink] [info] 📩 Received: {"jsonrpc":"2.0","method":"subscription","params":{"channel":"book.ETH-PERPETUAL.100ms","data":{"timestamp":1743963502192,"type":"change","change_id":23674084681,"instrument_name":"ETH-PERPETUAL","bids":[],"asks":[["new",1657.5,5398965.0],["delete",1660.15,0.0]],"prev_change_id":23674084329}}}
[2025-04-06 23:48:21.539] [multi_sink] [info] Processing received message: {"jsonrpc":"2.0","method":"subscription","params":{"channel":"book.ETH-PERPETUAL.100ms","data":{"timestamp":1743963502192,"type":"change","change_id":23674084681,"instrument_name":"ETH-PERPETUAL","bids":[],"asks":[["new",1657.5,5398965.0],["delete",1660.15,0.0]],"prev_change_id":23674084329}}}
[2025-04-06 23:48:21.540] [multi_sink] [error] Broadcast error: Operation canceled
[2025-04-06 23:48:21.540] [multi_sink] [error] Broadcast error: Operation canceled
[2025-04-06 23:48:21.610] [multi_sink] [info] 📩 Received: {"jsonrpc":"2.0","method":"subscription","params":{"channel":"book.BTC-PERPETUAL.100ms","data":{"timestamp":1743963502500,"type":"change","change_id":41106279032,"instrument_name":"BTC-PERPETUAL","bids":[["delete",80026.0,0.0],["delete",80025.5,0.0],["delete",80025.0,0.0],["delete",80024.5,0.0],["new",80024.0,26490.0],["delete",80023.0,0.0],["delete",80022.5,0.0],["change",80021.0,1260.0],["change",80020.0,12010.0],["change",80018.0,13590.0],["change",80017.5,24210.0],["change",80016.0,1.351e5],["new",80015.0,16980.0],["new",80014.5,1.0e4],["new",80014.0,30.0]],"asks":[["new",80041.5,3030.0],["new",80042.0,5.4e3],["new",80047.0,1730.0],["new",80047.5,5750.0],["new",80048.5,16490.0],["new",80049.0,43310.0],["new",80049.5,19340.0],["change",80050.5,13570.0],["delete",80051.5,0.0],["change",80052.0,60860.0],["change",80052.5,115050.0],["change",80053.0,34450.0],["delete",80057.0,0.0],["change",80057.5,12120.0],["change",80061.0,4.0e4],["delete",80061.5,0.0],["delete",80062.0,0.0]],"prev_change_id":41106278361}}}
[2025-04-06 23:48:21.612] [multi_sink] [info] Processing received message: {"jsonrpc":"2.0","method":"subscription","params":{"channel":"book.BTC-PERPETUAL.100ms","data":{"timestamp":1743963502500,"type":"change","change_id":41106279032,"instrument_name":"BTC-PERPETUAL","bids":[["delete",80026.0,0.0],["delete",80025.5,0.0],["delete",80025.0,0.0],["delete",80024.5,0.0],["new",80024.0,26490.0],["delete",80023.0,0.0],["delete",80022.5,0.0],["change",80021.0,1260.0],["change",80020.0,12010.0],["change",80018.0,13590.0],["change",80017.5,24210.0],["change",80016.0,1.351e5],["new",80015.0,16980.0],["new",80014.5,1.0e4],["new",80014.0,30.0]],"asks":[["new",80041.5,3030.0],["new",80042.0,5.4e3],["new",80047.0,1730.0],["new",80047.5,5750.0],["new",80048.5,16490.0],["new",80049.0,43310.0],["new",80049.5,19340.0],["change",80050.5,13570.0],["delete",80051.5,0.0],["change",80052.0,60860.0],["change",80052.5,115050.0],["change",80053.0,34450.0],["delete",80057.0,0.0],["change",80057.5,12120.0],["change",80061.0,4.0e4],["delete",80061.5,0.0],["delete",80062.0,0.0]],"prev_change_id":41106278361}}}
[2025-04-06 23:48:21.613] [multi_sink] [error] Broadcast error: Operation canceled
[2025-04-06 23:48:21.614] [multi_sink] [error] Broadcast error: Operation canceled
[2025-04-06 23:48:21.942] [multi_sink] [info] 📩 Received: {"jsonrpc":"2.0","method":"subscription","params":{"channel":"book.BTC-PERPETUAL.100ms","data":{"timestamp":1743963502687,"type":"change","change_id":41106279393,"instrument_name":"BTC-PERPETUAL","bids":[["new",80029.0,43530.0],["new",80026.5,38970.0],["new",80026.0,62750.0],["new",80025.0,653270.0],["new",80024.5,8.0e4],["change",80017.5,18430.0],["delete",80017.0,0.0],["change",80016.0,51910.0],["delete",80015.5,0.0],["delete",79872.5,0.0],["delete",79847.0,0.0],["new",79833.5,8.0085e6],["delete",79822.5,0.0]],"asks":[["delete",80027.0,0.0],["new",80029.5,121230.0],["change",80030.0,140.0],["new",80038.0,10430.0],["new",80038.5,34770.0],["delete",80062.5,0.0],["delete",80063.5,0.0],["delete",80064.0,0.0],["delete",80064.5,0.0],["delete",80066.0,0.0],["delete",80196.5,0.0],["delete",80246.5,0.0]],"prev_change_id":41106279032}}}
[2025-04-06 23:48:21.946] [multi_sink] [info] Processing received message: {"jsonrpc":"2.0","method":"subscription","params":{"channel":"book.BTC-PERPETUAL.100ms","data":{"timestamp":1743963502687,"type":"change","change_id":41106279393,"instrument_name":"BTC-PERPETUAL","bids":[["new",80029.0,43530.0],["new",80026.5,38970.0],["new",80026.0,62750.0],["new",80025.0,653270.0],["new",80024.5,8.0e4],["change",80017.5,18430.0],["delete",80017.0,0.0],["change",80016.0,51910.0],["delete",80015.5,0.0],["delete",79872.5,0.0],["delete",79847.0,0.0],["new",79833.5,8.0085e6],["delete",79822.5,0.0]],"asks":[["delete",80027.0,0.0],["new",80029.5,121230.0],["change",80030.0,140.0],["new",80038.0,10430.0],["new",80038.5,34770.0],["delete",80062.5,0.0],["delete",80063.5,0.0],["delete",80064.0,0.0],["delete",80064.5,0.0],["delete",80066.0,0.0],["delete",80196.5,0.0],["delete",80246.5,0.0]],"prev_change_id":41106279032}}}
[2025-04-06 23:48:21.947] [multi_sink] [error] Broadcast error: Operation canceled
[2025-04-06 23:48:21.948] [multi_sink] [error] Broadcast error: Operation canceled
[2025-04-06 23:48:22.193] [multi_sink] [info] 📩 Received: {"jsonrpc":"2.0","method":"subscription","params":{"channel":"book.ETH-PERPETUAL.100ms","data":{"timestamp":1743963503060,"type":"change","change_id":23674085845,"instrument_name":"ETH-PERPETUAL","bids":[],"asks":[["change",1657.5,5396465.0]],"prev_change_id":23674084681}}}
[2025-04-06 23:48:22.194] [multi_sink] [info] Processing received message: {"jsonrpc":"2.0","method":"subscription","params":{"channel":"book.ETH-PERPETUAL.100ms","data":{"timestamp":1743963503060,"type":"change","change_id":23674085845,"instrument_name":"ETH-PERPETUAL","bids":[],"asks":[["change",1657.5,5396465.0]],"prev_change_id":23674084681}}}
[2025-04-06 23:48:22.195] [multi_sink] [error] Broadcast error: Operation canceled
[2025-04-06 23:48:22.195] [multi_sink] [error] Broadcast error: Operation canceled
[2025-04-06 23:48:22.270] [multi_sink] [info] 📩 Received: {"jsonrpc":"2.0","method":"subscription","params":{"channel":"book.BTC-PERPETUAL.100ms","data":{"timestamp":1743963503090,"type":"change","change_id":41106279911,"instrument_name":"BTC-PERPETUAL","bids":[],"asks":[["new",80225.0,7777770.0],["delete",80238.5,0.0]],"prev_change_id":41106279393}}}
[2025-04-06 23:48:22.272] [multi_sink] [info] Processing received message: {"jsonrpc":"2.0","method":"subscription","params":{"channel":"book.BTC-PERPETUAL.100ms","data":{"timestamp":1743963503090,"type":"change","change_id":41106279911,"instrument_name":"BTC-PERPETUAL","bids":[],"asks":[["new",80225.0,7777770.0],["delete",80238.5,0.0]],"prev_change_id":41106279393}}}
[2025-04-06 23:48:22.273] [multi_sink] [error] Broadcast error: Operation canceled
[2025-04-06 23:48:22.273] [multi_sink] [error] Broadcast error: Operation canceled
[2025-04-06 23:48:23.585] [multi_sink] [info] 📩 Received: {"jsonrpc":"2.0","method":"subscription","params":{"channel":"book.ETH-PERPETUAL.100ms","data":{"timestamp":1743963504476,"type":"change","change_id":23674087185,"instrument_name":"ETH-PERPETUAL","bids":[["delete",1656.7,0.0],["delete",1656.65,0.0],["delete",1656.55,0.0],["delete",1656.45,0.0],["delete",1656.4,0.0],["delete",1656.3,0.0],["delete",1656.25,0.0],["delete",1656.2,0.0],["delete",1656.15,0.0],["delete",1656.1,0.0],["delete",1656.05,0.0],["delete",1656.0,0.0],["delete",1655.95,0.0],["change",1655.9,7353082.0]],"asks":[],"prev_change_id":23674085845}}}
[2025-04-06 23:48:23.588] [multi_sink] [info] Processing received message: {"jsonrpc":"2.0","method":"subscription","params":{"channel":"book.ETH-PERPETUAL.100ms","data":{"timestamp":1743963504476,"type":"change","change_id":23674087185,"instrument_name":"ETH-PERPETUAL","bids":[["delete",1656.7,0.0],["delete",1656.65,0.0],["delete",1656.55,0.0],["delete",1656.45,0.0],["delete",1656.4,0.0],["delete",1656.3,0.0],["delete",1656.25,0.0],["delete",1656.2,0.0],["delete",1656.15,0.0],["delete",1656.1,0.0],["delete",1656.05,0.0],["delete",1656.0,0.0],["delete",1655.95,0.0],["change",1655.9,7353082.0]],"asks":[],"prev_change_id":23674085845}}}
[2025-04-06 23:48:23.589] [multi_sink] [error] Broadcast error: Operation canceled
[2025-04-06 23:48:23.589] [multi_sink] [error] Broadcast error: Operation canceled
[2025-04-06 23:48:23.646] [multi_sink] [info] 📩 Received: {"jsonrpc":"2.0","method":"subscription","params":{"channel":"book.BTC-PERPETUAL.100ms","data":{"timestamp":1743963504481,"type":"change","change_id":41106281948,"instrument_name":"BTC-PERPETUAL","bids":[["delete",79998.5,0.0],["new",79989.5,5710350.0]],"asks":[["change",80030.0,130.0]],"prev_change_id":41106279911}}}
[2025-04-06 23:48:23.647] [multi_sink] [info] Processing received message: {"jsonrpc":"2.0","method":"subscription","params":{"channel":"book.BTC-PERPETUAL.100ms","data":{"timestamp":1743963504481,"type":"change","change_id":41106281948,"instrument_name":"BTC-PERPETUAL","bids":[["delete",79998.5,0.0],["new",79989.5,5710350.0]],"asks":[["change",80030.0,130.0]],"prev_change_id":41106279911}}}
[2025-04-06 23:48:23.647] [multi_sink] [error] Broadcast error: Operation canceled
[2025-04-06 23:48:23.648] [multi_sink] [error] Broadcast error: Operation canceled
[2025-04-06 23:48:23.915] [multi_sink] [info] 📩 Received: {"jsonrpc":"2.0","method":"subscription","params":{"channel":"book.ETH-PERPETUAL.100ms","data":{"timestamp":1743963504625,"type":"change","change_id":23674087406,"instrument_name":"ETH-PERPETUAL","bids":[["delete",1650.2,0.0],["new",1647.6,500.0],["delete",1642.7,0.0],["new",1639.3,700.0]],"asks":[],"prev_change_id":23674087185}}}
[2025-04-06 23:48:23.920] [multi_sink] [info] Processing received message: {"jsonrpc":"2.0","method":"subscription","params":{"channel":"book.ETH-PERPETUAL.100ms","data":{"timestamp":1743963504625,"type":"change","change_id":23674087406,"instrument_name":"ETH-PERPETUAL","bids":[["delete",1650.2,0.0],["new",1647.6,500.0],["delete",1642.7,0.0],["new",1639.3,700.0]],"asks":[],"prev_change_id":23674087185}}}
[2025-04-06 23:48:23.921] [multi_sink] [error] Broadcast error: Operation canceled
[2025-04-06 23:48:23.921] [multi_sink] [error] Broadcast error: Operation canceled
[2025-04-06 23:48:23.969] [multi_sink] [info] 📩 Received: {"jsonrpc":"2.0","method":"subscription","params":{"channel":"book.BTC-PERPETUAL.100ms","data":{"timestamp":1743963504802,"type":"change","change_id":41106282519,"instrument_name":"BTC-PERPETUAL","bids":[],"asks":[["change",80029.5,121240.0]],"prev_change_id":41106281948}}}
[2025-04-06 23:48:23.973] [multi_sink] [info] Processing received message: {"jsonrpc":"2.0","method":"subscription","params":{"channel":"book.BTC-PERPETUAL.100ms","data":{"timestamp":1743963504802,"type":"change","change_id":41106282519,"instrument_name":"BTC-PERPETUAL","bids":[],"asks":[["change",80029.5,121240.0]],"prev_change_id":41106281948}}}
[2025-04-06 23:48:23.974] [multi_sink] [error] Broadcast error: Operation canceled
[2025-04-06 23:48:23.975] [multi_sink] [error] Broadcast error: Operation canceled
[2025-04-06 23:48:24.548] [multi_sink] [info] 📩 Received: {"jsonrpc":"2.0","method":"subscription","params":{"channel":"book.ETH-PERPETUAL.100ms","data":{"timestamp":1743963505440,"type":"change","change_id":23674088382,"instrument_name":"ETH-PERPETUAL","bids":[],"asks":[["new",1657.3,8593.0]],"prev_change_id":23674087406}}}
[2025-04-06 23:48:24.552] [multi_sink] [info] Processing received message: {"jsonrpc":"2.0","method":"subscription","params":{"channel":"book.ETH-PERPETUAL.100ms","data":{"timestamp":1743963505440,"type":"change","change_id":23674088382,"instrument_name":"ETH-PERPETUAL","bids":[],"asks":[["new",1657.3,8593.0]],"prev_change_id":23674087406}}}
[2025-04-06 23:48:24.553] [multi_sink] [error] Broadcast error: Operation canceled
[2025-04-06 23:48:24.554] [multi_sink] [error] Broadcast error: Operation canceled
[2025-04-06 23:48:24.877] [multi_sink] [info] 📩 Received: {"jsonrpc":"2.0","method":"subscription","params":{"channel":"book.ETH-PERPETUAL.100ms","data":{"timestamp":1743963505762,"type":"change","change_id":23674088596,"instrument_name":"ETH-PERPETUAL","bids":[["delete",1655.85,0.0],["delete",1655.8,0.0],["delete",1655.75,0.0],["delete",1655.7,0.0],["delete",1655.65,0.0],["delete",1655.6,0.0],["new",1655.4,64433.0],["new",1655.35,2547.0],["new",1655.3,1069.0],["new",1655.25,4426.0],["new",1655.2,10018.0],["new",1655.15,14231.0],["new",1655.1,1170.0],["new",1655.05,50686.0],["new",1655.0,8594.0]],"asks":[["new",1656.85,36585.0],["new",1656.9,17181.0],["new",1656.95,53373.0],["new",1657.0,3067.0],["new",1657.05,2698.0],["new",1657.1,29754.0],["new",1657.15,7.15e4],["new",1657.2,7871.0],["new",1657.25,18718.0]],"prev_change_id":23674088382}}}
[2025-04-06 23:48:24.880] [multi_sink] [info] Processing received message: {"jsonrpc":"2.0","method":"subscription","params":{"channel":"book.ETH-PERPETUAL.100ms","data":{"timestamp":1743963505762,"type":"change","change_id":23674088596,"instrument_name":"ETH-PERPETUAL","bids":[["delete",1655.85,0.0],["delete",1655.8,0.0],["delete",1655.75,0.0],["delete",1655.7,0.0],["delete",1655.65,0.0],["delete",1655.6,0.0],["new",1655.4,64433.0],["new",1655.35,2547.0],["new",1655.3,1069.0],["new",1655.25,4426.0],["new",1655.2,10018.0],["new",1655.15,14231.0],["new",1655.1,1170.0],["new",1655.05,50686.0],["new",1655.0,8594.0]],"asks":[["new",1656.85,36585.0],["new",1656.9,17181.0],["new",1656.95,53373.0],["new",1657.0,3067.0],["new",1657.05,2698.0],["new",1657.1,29754.0],["new",1657.15,7.15e4],["new",1657.2,7871.0],["new",1657.25,18718.0]],"prev_change_id":23674088382}}}
[2025-04-06 23:48:24.881] [multi_sink] [error] Broadcast error: Operation canceled
[2025-04-06 23:48:24.882] [multi_sink] [error] Broadcast error: Operation canceled
[2025-04-06 23:48:25.206] [multi_sink] [info] 📩 Received: {"jsonrpc":"2.0","method":"subscription","params":{"channel":"book.ETH-PERPETUAL.100ms","data":{"timestamp":1743963506089,"type":"change","change_id":23674089037,"instrument_name":"ETH-PERPETUAL","bids":[["change",1655.9,7358567.0],["new",1655.8,14288.0],["new",1655.75,2228.0],["new",1655.7,7525.0],["new",1655.65,21420.0],["new",1655.6,72227.0],["new",1655.55,12613.0],["new",1655.5,19293.0],["new",1655.45,44845.0]],"asks":[["new",1656.2,10616.0],["new",1656.45,14294.0],["new",1656.5,15516.0],["new",1656.55,5150.0],["new",1656.6,31482.0],["new",1656.65,6269.0],["new",1656.7,10547.0],["new",1656.75,34632.0],["new",1656.8,12209.0],["new",1662.0,500.0],["delete",1663.7,0.0],["new",1665.05,500.0],["delete",1667.6,0.0],["new",1673.35,700.0],["delete",1676.75,0.0]],"prev_change_id":23674088596}}}
[2025-04-06 23:48:25.207] [multi_sink] [info] Processing received message: {"jsonrpc":"2.0","method":"subscription","params":{"channel":"book.ETH-PERPETUAL.100ms","data":{"timestamp":1743963506089,"type":"change","change_id":23674089037,"instrument_name":"ETH-PERPETUAL","bids":[["change",1655.9,7358567.0],["new",1655.8,14288.0],["new",1655.75,2228.0],["new",1655.7,7525.0],["new",1655.65,21420.0],["new",1655.6,72227.0],["new",1655.55,12613.0],["new",1655.5,19293.0],["new",1655.45,44845.0]],"asks":[["new",1656.2,10616.0],["new",1656.45,14294.0],["new",1656.5,15516.0],["new",1656.55,5150.0],["new",1656.6,31482.0],["new",1656.65,6269.0],["new",1656.7,10547.0],["new",1656.75,34632.0],["new",1656.8,12209.0],["new",1662.0,500.0],["delete",1663.7,0.0],["new",1665.05,500.0],["delete",1667.6,0.0],["new",1673.35,700.0],["delete",1676.75,0.0]],"prev_change_id":23674088596}}}
[2025-04-06 23:48:25.208] [multi_sink] [error] Broadcast error: Operation canceled
[2025-04-06 23:48:25.209] [multi_sink] [error] Broadcast error: Operation canceled
[2025-04-06 23:48:25.546] [multi_sink] [info] 📩 Received: {"jsonrpc":"2.0","method":"subscription","params":{"channel":"book.ETH-PERPETUAL.100ms","data":{"timestamp":1743963506152,"type":"change","change_id":23674089090,"instrument_name":"ETH-PERPETUAL","bids":[["new",1656.0,7536.0],["new",1655.95,687.0]],"asks":[["new",1656.05,8.4e3]],"prev_change_id":23674089037}}}
[2025-04-06 23:48:25.548] [multi_sink] [info] Processing received message: {"jsonrpc":"2.0","method":"subscription","params":{"channel":"book.ETH-PERPETUAL.100ms","data":{"timestamp":1743963506152,"type":"change","change_id":23674089090,"instrument_name":"ETH-PERPETUAL","bids":[["new",1656.0,7536.0],["new",1655.95,687.0]],"asks":[["new",1656.05,8.4e3]],"prev_change_id":23674089037}}}
[2025-04-06 23:48:25.549] [multi_sink] [error] Broadcast error: Operation canceled
[2025-04-06 23:48:25.550] [multi_sink] [error] Broadcast error: Operation canceled
[2025-04-06 23:48:26.102] [multi_sink] [info] 📩 Received: {"jsonrpc":"2.0","method":"subscription","params":{"channel":"book.BTC-PERPETUAL.100ms","data":{"timestamp":1743963506994,"type":"change","change_id":41106285284,"instrument_name":"BTC-PERPETUAL","bids":[],"asks":[["change",80029.5,10.0],["new",80075.5,410.0]],"prev_change_id":41106282519}}}
[2025-04-06 23:48:26.103] [multi_sink] [info] Processing received message: {"jsonrpc":"2.0","method":"subscription","params":{"channel":"book.BTC-PERPETUAL.100ms","data":{"timestamp":1743963506994,"type":"change","change_id":41106285284,"instrument_name":"BTC-PERPETUAL","bids":[],"asks":[["change",80029.5,10.0],["new",80075.5,410.0]],"prev_change_id":41106282519}}}
[2025-04-06 23:48:26.103] [multi_sink] [error] Broadcast error: Operation canceled
[2025-04-06 23:48:26.104] [multi_sink] [error] Broadcast error: Operation canceled
[2025-04-06 23:48:26.434] [multi_sink] [info] 📩 Received: {"jsonrpc":"2.0","method":"subscription","params":{"channel":"book.BTC-PERPETUAL.100ms","data":{"timestamp":1743963507321,"type":"change","change_id":41106285803,"instrument_name":"BTC-PERPETUAL","bids":[["delete",80029.0,0.0],["new",80028.5,3.53e4],["delete",80026.5,0.0],["change",80026.0,145850.0],["new",80025.5,233480.0],["change",80025.0,653270.0],["change",80024.5,8.0e4],["delete",80024.0,0.0],["new",80023.5,10280.0],["new",80021.5,27970.0],["change",80021.0,3.0e3],["change",80020.5,3760.0],["delete",80020.0,0.0],["delete",80018.0,0.0]],"asks":[["delete",80030.0,0.0],["delete",80038.0,0.0],["delete",80038.5,0.0],["delete",80041.5,0.0],["delete",80042.0,0.0],["delete",80047.0,0.0],["delete",80047.5,0.0],["delete",80048.5,0.0],["delete",80049.0,0.0],["new",80066.5,100.0],["new",80069.0,150.0],["new",80069.5,4950.0],["new",80071.5,16490.0],["new",80072.0,8.8e3],["new",80072.5,34450.0],["new",80073.0,210.0],["new",80074.5,3020.0],["new",80075.0,1260.0]],"prev_change_id":41106285284}}}
[2025-04-06 23:48:26.438] [multi_sink] [info] Processing received message: {"jsonrpc":"2.0","method":"subscription","params":{"channel":"book.BTC-PERPETUAL.100ms","data":{"timestamp":1743963507321,"type":"change","change_id":41106285803,"instrument_name":"BTC-PERPETUAL","bids":[["delete",80029.0,0.0],["new",80028.5,3.53e4],["delete",80026.5,0.0],["change",80026.0,145850.0],["new",80025.5,233480.0],["change",80025.0,653270.0],["change",80024.5,8.0e4],["delete",80024.0,0.0],["new",80023.5,10280.0],["new",80021.5,27970.0],["change",80021.0,3.0e3],["change",80020.5,3760.0],["delete",80020.0,0.0],["delete",80018.0,0.0]],"asks":[["delete",80030.0,0.0],["delete",80038.0,0.0],["delete",80038.5,0.0],["delete",80041.5,0.0],["delete",80042.0,0.0],["delete",80047.0,0.0],["delete",80047.5,0.0],["delete",80048.5,0.0],["delete",80049.0,0.0],["new",80066.5,100.0],["new",80069.0,150.0],["new",80069.5,4950.0],["new",80071.5,16490.0],["new",80072.0,8.8e3],["new",80072.5,34450.0],["new",80073.0,210.0],["new",80074.5,3020.0],["new",80075.0,1260.0]],"prev_change_id":41106285284}}}
[2025-04-06 23:48:26.439] [multi_sink] [error] Broadcast error: Operation canceled
[2025-04-06 23:48:26.440] [multi_sink] [error] Broadcast error: Operation canceled
[2025-04-06 23:48:26.766] [multi_sink] [info] 📩 Received: {"jsonrpc":"2.0","method":"subscription","params":{"channel":"book.BTC-PERPETUAL.100ms","data":{"timestamp":1743963507648,"type":"change","change_id":41106286324,"instrument_name":"BTC-PERPETUAL","bids":[["new",80039.5,95420.0],["new",80039.0,3.5e4],["new",80036.0,175780.0],["new",80035.0,3840.0],["new",80033.5,13620.0],["new",80033.0,5.5e4],["new",80030.0,76930.0],["new",80029.5,159990.0],["new",80029.0,30.0],["change",80017.5,12650.0],["delete",80016.0,0.0],["delete",80015.0,0.0],["delete",80014.5,0.0],["delete",80014.0,0.0],["delete",80013.0,0.0],["delete",80012.0,0.0],["delete",80011.0,0.0],["delete",80010.5,0.0]],"asks":[["delete",80029.5,0.0],["new",80041.0,17050.0],["delete",80049.5,0.0],["delete",80050.5,0.0],["delete",80052.0,0.0],["delete",80052.5,0.0],["delete",80053.0,0.0],["delete",80053.5,0.0],["new",80054.5,2.4e3],["new",80055.0,1.0e4],["change",80057.5,2450.0],["new",80060.0,490.0],["change",80060.5,3.0e3],["delete",80061.0,0.0],["new",80064.0,35070.0],["new",80064.5,81640.0],["new",80065.0,1270.0]],"prev_change_id":41106285803}}}
[2025-04-06 23:48:26.771] [multi_sink] [info] Processing received message: {"jsonrpc":"2.0","method":"subscription","params":{"channel":"book.BTC-PERPETUAL.100ms","data":{"timestamp":1743963507648,"type":"change","change_id":41106286324,"instrument_name":"BTC-PERPETUAL","bids":[["new",80039.5,95420.0],["new",80039.0,3.5e4],["new",80036.0,175780.0],["new",80035.0,3840.0],["new",80033.5,13620.0],["new",80033.0,5.5e4],["new",80030.0,76930.0],["new",80029.5,159990.0],["new",80029.0,30.0],["change",80017.5,12650.0],["delete",80016.0,0.0],["delete",80015.0,0.0],["delete",80014.5,0.0],["delete",80014.0,0.0],["delete",80013.0,0.0],["delete",80012.0,0.0],["delete",80011.0,0.0],["delete",80010.5,0.0]],"asks":[["delete",80029.5,0.0],["new",80041.0,17050.0],["delete",80049.5,0.0],["delete",80050.5,0.0],["delete",80052.0,0.0],["delete",80052.5,0.0],["delete",80053.0,0.0],["delete",80053.5,0.0],["new",80054.5,2.4e3],["new",80055.0,1.0e4],["change",80057.5,2450.0],["new",80060.0,490.0],["change",80060.5,3.0e3],["delete",80061.0,0.0],["new",80064.0,35070.0],["new",80064.5,81640.0],["new",80065.0,1270.0]],"prev_change_id":41106285803}}}
[2025-04-06 23:48:26.772] [multi_sink] [error] Broadcast error: Operation canceled
[2025-04-06 23:48:26.773] [multi_sink] [error] Broadcast error: Operation canceled
[2025-04-06 23:48:27.094] [multi_sink] [info] 📩 Received: {"jsonrpc":"2.0","method":"subscription","params":{"channel":"book.BTC-PERPETUAL.100ms","data":{"timestamp":1743963507952,"type":"change","change_id":41106286818,"instrument_name":"BTC-PERPETUAL","bids":[["new",80040.0,259280.0],["new",79876.5,79870.0],["new",79826.5,119740.0]],"asks":[["new",80040.5,420.0],["new",80209.5,80210.0],["new",80259.5,120390.0]],"prev_change_id":41106286324}}}
[2025-04-06 23:48:27.094] [multi_sink] [info] Processing received message: {"jsonrpc":"2.0","method":"subscription","params":{"channel":"book.BTC-PERPETUAL.100ms","data":{"timestamp":1743963507952,"type":"change","change_id":41106286818,"instrument_name":"BTC-PERPETUAL","bids":[["new",80040.0,259280.0],["new",79876.5,79870.0],["new",79826.5,119740.0]],"asks":[["new",80040.5,420.0],["new",80209.5,80210.0],["new",80259.5,120390.0]],"prev_change_id":41106286324}}}
[2025-04-06 23:48:27.095] [multi_sink] [error] Broadcast error: Operation canceled
[2025-04-06 23:48:27.096] [multi_sink] [error] Broadcast error: Operation canceled
[2025-04-06 23:48:27.792] [multi_sink] [info] 📩 Received: {"jsonrpc":"2.0","method":"subscription","params":{"channel":"book.BTC-PERPETUAL.100ms","data":{"timestamp":1743963508686,"type":"change","change_id":41106287869,"instrument_name":"BTC-PERPETUAL","bids":[],"asks":[["new",80043.0,8.0e3]],"prev_change_id":41106286818}}}
[2025-04-06 23:48:27.795] [multi_sink] [info] Processing received message: {"jsonrpc":"2.0","method":"subscription","params":{"channel":"book.BTC-PERPETUAL.100ms","data":{"timestamp":1743963508686,"type":"change","change_id":41106287869,"instrument_name":"BTC-PERPETUAL","bids":[],"asks":[["new",80043.0,8.0e3]],"prev_change_id":41106286818}}}
[2025-04-06 23:48:27.796] [multi_sink] [error] Broadcast error: Operation canceled
[2025-04-06 23:48:27.797] [multi_sink] [error] Broadcast error: Operation canceled
[2025-04-06 23:48:28.125] [multi_sink] [info] 📩 Received: {"jsonrpc":"2.0","method":"subscription","params":{"channel":"book.BTC-PERPETUAL.100ms","data":{"timestamp":1743963508884,"type":"change","change_id":41106288277,"instrument_name":"BTC-PERPETUAL","bids":[],"asks":[["change",80041.0,25050.0],["delete",80043.0,0.0]],"prev_change_id":41106287869}}}
[2025-04-06 23:48:28.128] [multi_sink] [info] Processing received message: {"jsonrpc":"2.0","method":"subscription","params":{"channel":"book.BTC-PERPETUAL.100ms","data":{"timestamp":1743963508884,"type":"change","change_id":41106288277,"instrument_name":"BTC-PERPETUAL","bids":[],"asks":[["change",80041.0,25050.0],["delete",80043.0,0.0]],"prev_change_id":41106287869}}}
[2025-04-06 23:48:28.129] [multi_sink] [error] Broadcast error: Operation canceled
[2025-04-06 23:48:28.130] [multi_sink] [error] Broadcast error: Operation canceled
[2025-04-06 23:48:28.821] [multi_sink] [info] 📩 Received: {"jsonrpc":"2.0","method":"subscription","params":{"channel":"book.BTC-PERPETUAL.100ms","data":{"timestamp":1743963509709,"type":"change","change_id":41106289213,"instrument_name":"BTC-PERPETUAL","bids":[["change",80040.0,251280.0]],"asks":[["change",80041.0,17050.0]],"prev_change_id":41106288277}}}
[2025-04-06 23:48:28.822] [multi_sink] [info] Processing received message: {"jsonrpc":"2.0","method":"subscription","params":{"channel":"book.BTC-PERPETUAL.100ms","data":{"timestamp":1743963509709,"type":"change","change_id":41106289213,"instrument_name":"BTC-PERPETUAL","bids":[["change",80040.0,251280.0]],"asks":[["change",80041.0,17050.0]],"prev_change_id":41106288277}}}
[2025-04-06 23:48:28.823] [multi_sink] [error] Broadcast error: Operation canceled
[2025-04-06 23:48:28.823] [multi_sink] [error] Broadcast error: Operation canceled
[2025-04-06 23:48:28.952] [multi_sink] [info] 📩 Received: {"jsonrpc":"2.0","method":"subscription","params":{"channel":"book.ETH-PERPETUAL.100ms","data":{"timestamp":1743963509757,"type":"change","change_id":23674092573,"instrument_name":"ETH-PERPETUAL","bids":[["change",1655.9,5485.0],["change",1655.3,7354151.0]],"asks":[],"prev_change_id":23674089090}}}
[2025-04-06 23:48:28.952] [multi_sink] [info] Processing received message: {"jsonrpc":"2.0","method":"subscription","params":{"channel":"book.ETH-PERPETUAL.100ms","data":{"timestamp":1743963509757,"type":"change","change_id":23674092573,"instrument_name":"ETH-PERPETUAL","bids":[["change",1655.9,5485.0],["change",1655.3,7354151.0]],"asks":[],"prev_change_id":23674089090}}}
[2025-04-06 23:48:28.952] [multi_sink] [error] Broadcast error: Operation canceled
[2025-04-06 23:48:28.953] [multi_sink] [error] Broadcast error: Operation canceled
[2025-04-06 23:48:29.146] [multi_sink] [info] 📩 Received: {"jsonrpc":"2.0","method":"subscription","params":{"channel":"book.BTC-PERPETUAL.100ms","data":{"timestamp":1743963509716,"type":"change","change_id":41106289217,"instrument_name":"BTC-PERPETUAL","bids":[["delete",79876.5,0.0],["delete",79826.5,0.0]],"asks":[["delete",80209.5,0.0],["delete",80259.5,0.0]],"prev_change_id":41106289213}}}
[2025-04-06 23:48:29.149] [multi_sink] [info] Processing received message: {"jsonrpc":"2.0","method":"subscription","params":{"channel":"book.BTC-PERPETUAL.100ms","data":{"timestamp":1743963509716,"type":"change","change_id":41106289217,"instrument_name":"BTC-PERPETUAL","bids":[["delete",79876.5,0.0],["delete",79826.5,0.0]],"asks":[["delete",80209.5,0.0],["delete",80259.5,0.0]],"prev_change_id":41106289213}}}
[2025-04-06 23:48:29.149] [multi_sink] [error] Broadcast error: Operation canceled
[2025-04-06 23:48:29.150] [multi_sink] [error] Broadcast error: Operation canceled
[2025-04-06 23:48:29.612] [multi_sink] [info] 📩 Received: {"jsonrpc":"2.0","method":"subscription","params":{"channel":"book.ETH-PERPETUAL.100ms","data":{"timestamp":1743963510479,"type":"change","change_id":23674093221,"instrument_name":"ETH-PERPETUAL","bids":[["delete",1656.0,0.0],["delete",1655.95,0.0],["change",1655.2,18513.0],["change",1655.15,15855.0]],"asks":[["delete",1656.05,0.0],["delete",1656.2,0.0],["change",1656.9,5413646.0],["delete",1657.5,0.0],["new",1657.55,13173.0],["new",1657.6,2618.0]],"prev_change_id":23674092573}}}
[2025-04-06 23:48:29.616] [multi_sink] [info] Processing received message: {"jsonrpc":"2.0","method":"subscription","params":{"channel":"book.ETH-PERPETUAL.100ms","data":{"timestamp":1743963510479,"type":"change","change_id":23674093221,"instrument_name":"ETH-PERPETUAL","bids":[["delete",1656.0,0.0],["delete",1655.95,0.0],["change",1655.2,18513.0],["change",1655.15,15855.0]],"asks":[["delete",1656.05,0.0],["delete",1656.2,0.0],["change",1656.9,5413646.0],["delete",1657.5,0.0],["new",1657.55,13173.0],["new",1657.6,2618.0]],"prev_change_id":23674092573}}}
[2025-04-06 23:48:29.617] [multi_sink] [error] Broadcast error: Operation canceled
[2025-04-06 23:48:29.617] [multi_sink] [error] Broadcast error: Operation canceled
[2025-04-06 23:48:29.882] [multi_sink] [info] 📩 Received: {"jsonrpc":"2.0","method":"subscription","params":{"channel":"book.BTC-PERPETUAL.100ms","data":{"timestamp":1743963510776,"type":"change","change_id":41106290713,"instrument_name":"BTC-PERPETUAL","bids":[["new",79839.5,8.0085e6],["delete",79833.5,0.0]],"asks":[],"prev_change_id":41106289217}}}
[2025-04-06 23:48:29.885] [multi_sink] [info] Processing received message: {"jsonrpc":"2.0","method":"subscription","params":{"channel":"book.BTC-PERPETUAL.100ms","data":{"timestamp":1743963510776,"type":"change","change_id":41106290713,"instrument_name":"BTC-PERPETUAL","bids":[["new",79839.5,8.0085e6],["delete",79833.5,0.0]],"asks":[],"prev_change_id":41106289217}}}
[2025-04-06 23:48:29.886] [multi_sink] [error] Broadcast error: Operation canceled
[2025-04-06 23:48:29.886] [multi_sink] [error] Broadcast error: Operation canceled
[2025-04-06 23:48:29.946] [multi_sink] [info] 📩 Received: {"jsonrpc":"2.0","method":"subscription","params":{"channel":"book.ETH-PERPETUAL.100ms","data":{"timestamp":1743963510835,"type":"change","change_id":23674093564,"instrument_name":"ETH-PERPETUAL","bids":[["delete",1655.9,0.0],["delete",1655.8,0.0],["change",1655.75,2358.0],["change",1655.7,7525.0],["delete",1655.65,0.0],["delete",1655.6,0.0],["change",1655.55,8715.0],["change",1655.5,18925.0],["change",1655.45,17031.0],["change",1655.4,90601.0],["change",1655.35,20353.0],["change",1655.3,7411158.0],["change",1655.25,10156.0]],"asks":[["delete",1656.45,0.0],["delete",1656.5,0.0],["delete",1656.55,0.0],["delete",1656.6,0.0],["delete",1656.65,0.0],["delete",1656.7,0.0],["delete",1656.75,0.0],["delete",1656.8,0.0],["delete",1656.85,0.0],["change",1656.9,5396465.0],["change",1657.05,11354.0],["change",1657.1,80616.0],["change",1657.15,153549.0],["change",1657.2,11517.0],["change",1657.25,19786.0],["change",1657.3,17186.0],["new",1657.35,1173.0],["new",1657.4,1073.0],["new",1657.45,3720.0],["new",1657.5,13417.0]],"prev_change_id":23674093221}}}
[2025-04-06 23:48:29.949] [multi_sink] [info] Processing received message: {"jsonrpc":"2.0","method":"subscription","params":{"channel":"book.ETH-PERPETUAL.100ms","data":{"timestamp":1743963510835,"type":"change","change_id":23674093564,"instrument_name":"ETH-PERPETUAL","bids":[["delete",1655.9,0.0],["delete",1655.8,0.0],["change",1655.75,2358.0],["change",1655.7,7525.0],["delete",1655.65,0.0],["delete",1655.6,0.0],["change",1655.55,8715.0],["change",1655.5,18925.0],["change",1655.45,17031.0],["change",1655.4,90601.0],["change",1655.35,20353.0],["change",1655.3,7411158.0],["change",1655.25,10156.0]],"asks":[["delete",1656.45,0.0],["delete",1656.5,0.0],["delete",1656.55,0.0],["delete",1656.6,0.0],["delete",1656.65,0.0],["delete",1656.7,0.0],["delete",1656.75,0.0],["delete",1656.8,0.0],["delete",1656.85,0.0],["change",1656.9,5396465.0],["change",1657.05,11354.0],["change",1657.1,80616.0],["change",1657.15,153549.0],["change",1657.2,11517.0],["change",1657.25,19786.0],["change",1657.3,17186.0],["new",1657.35,1173.0],["new",1657.4,1073.0],["new",1657.45,3720.0],["new",1657.5,13417.0]],"prev_change_id":23674093221}}}
[2025-04-06 23:48:29.950] [multi_sink] [error] Broadcast error: Operation canceled
[2025-04-06 23:48:29.951] [multi_sink] [error] Broadcast error: Operation canceled
[2025-04-06 23:48:30.274] [multi_sink] [info] 📩 Received: {"jsonrpc":"2.0","method":"subscription","params":{"channel":"book.ETH-PERPETUAL.100ms","data":{"timestamp":1743963511132,"type":"change","change_id":23674093938,"instrument_name":"ETH-PERPETUAL","bids":[["new",1656.5,773.0],["new",1656.25,5.1e3],["new",1656.2,5.1e3],["new",1656.15,8249.0],["new",1656.05,24404.0],["new",1656.0,2228.0],["new",1655.95,7425.0],["new",1655.9,21988.0],["new",1655.8,7.14e4],["change",1655.4,26168.0],["change",1655.35,17806.0],["change",1655.3,7410089.0],["change",1655.25,5730.0],["change",1655.2,8495.0],["change",1655.15,1624.0],["delete",1655.1,0.0],["delete",1655.05,0.0],["delete",1655.0,0.0]],"asks":[["new",1656.55,5561.0],["new",1656.65,725.0],["new",1656.7,100.0],["new",1656.8,19930.0],["new",1656.85,70479.0],["change",1656.9,5399834.0],["change",1656.95,6270.0],["change",1657.0,1068.0],["change",1657.05,8656.0],["change",1657.1,50862.0],["change",1657.15,82049.0],["change",1657.2,3646.0],["change",1657.25,1068.0],["change",1657.3,8593.0]],"prev_change_id":23674093564}}}
[2025-04-06 23:48:30.276] [multi_sink] [info] Processing received message: {"jsonrpc":"2.0","method":"subscription","params":{"channel":"book.ETH-PERPETUAL.100ms","data":{"timestamp":1743963511132,"type":"change","change_id":23674093938,"instrument_name":"ETH-PERPETUAL","bids":[["new",1656.5,773.0],["new",1656.25,5.1e3],["new",1656.2,5.1e3],["new",1656.15,8249.0],["new",1656.05,24404.0],["new",1656.0,2228.0],["new",1655.95,7425.0],["new",1655.9,21988.0],["new",1655.8,7.14e4],["change",1655.4,26168.0],["change",1655.35,17806.0],["change",1655.3,7410089.0],["change",1655.25,5730.0],["change",1655.2,8495.0],["change",1655.15,1624.0],["delete",1655.1,0.0],["delete",1655.05,0.0],["delete",1655.0,0.0]],"asks":[["new",1656.55,5561.0],["new",1656.65,725.0],["new",1656.7,100.0],["new",1656.8,19930.0],["new",1656.85,70479.0],["change",1656.9,5399834.0],["change",1656.95,6270.0],["change",1657.0,1068.0],["change",1657.05,8656.0],["change",1657.1,50862.0],["change",1657.15,82049.0],["change",1657.2,3646.0],["change",1657.25,1068.0],["change",1657.3,8593.0]],"prev_change_id":23674093564}}}
[2025-04-06 23:48:30.277] [multi_sink] [error] Broadcast error: Operation canceled
[2025-04-06 23:48:30.277] [multi_sink] [error] Broadcast error: Operation canceled
[2025-04-06 23:48:30.544] [multi_sink] [info] 📩 Received: {"jsonrpc":"2.0","method":"subscription","params":{"channel":"book.BTC-PERPETUAL.100ms","data":{"timestamp":1743963511275,"type":"change","change_id":41106291339,"instrument_name":"BTC-PERPETUAL","bids":[],"asks":[["delete",80225.0,0.0],["new",80231.0,7777770.0]],"prev_change_id":41106290713}}}
[2025-04-06 23:48:30.544] [multi_sink] [info] Processing received message: {"jsonrpc":"2.0","method":"subscription","params":{"channel":"book.BTC-PERPETUAL.100ms","data":{"timestamp":1743963511275,"type":"change","change_id":41106291339,"instrument_name":"BTC-PERPETUAL","bids":[],"asks":[["delete",80225.0,0.0],["new",80231.0,7777770.0]],"prev_change_id":41106290713}}}
[2025-04-06 23:48:30.545] [multi_sink] [error] Broadcast error: Operation canceled
[2025-04-06 23:48:30.545] [multi_sink] [error] Broadcast error: Operation canceled
[2025-04-06 23:48:31.103] [multi_sink] [info] 📩 Received: {"jsonrpc":"2.0","method":"subscription","params":{"channel":"book.BTC-PERPETUAL.100ms","data":{"timestamp":1743963511995,"type":"change","change_id":41106292246,"instrument_name":"BTC-PERPETUAL","bids":[],"asks":[["change",80040.5,10.0],["change",80074.5,6040.0]],"prev_change_id":41106291339}}}
[2025-04-06 23:48:31.104] [multi_sink] [info] Processing received message: {"jsonrpc":"2.0","method":"subscription","params":{"channel":"book.BTC-PERPETUAL.100ms","data":{"timestamp":1743963511995,"type":"change","change_id":41106292246,"instrument_name":"BTC-PERPETUAL","bids":[],"asks":[["change",80040.5,10.0],["change",80074.5,6040.0]],"prev_change_id":41106291339}}}
[2025-04-06 23:48:31.104] [multi_sink] [error] Broadcast error: Operation canceled
[2025-04-06 23:48:31.105] [multi_sink] [error] Broadcast error: Operation canceled
[2025-04-06 23:48:31.432] [multi_sink] [info] 📩 Received: {"jsonrpc":"2.0","method":"subscription","params":{"channel":"book.BTC-PERPETUAL.100ms","data":{"timestamp":1743963512324,"type":"change","change_id":41106292740,"instrument_name":"BTC-PERPETUAL","bids":[["delete",80040.0,0.0],["delete",80039.5,0.0],["delete",80039.0,0.0],["delete",80036.0,0.0],["delete",80035.0,0.0],["delete",80033.5,0.0],["delete",80033.0,0.0],["delete",80030.0,0.0],["delete",80029.5,0.0],["new",80024.0,44680.0],["change",80023.5,116010.0],["new",80022.5,1060.0],["new",80022.0,7040.0],["new",80020.0,4.2e3],["new",80019.5,1.56e4],["new",80019.0,1.06e4],["change",80017.5,53950.0],["new",79995.5,5710350.0],["delete",79989.5,0.0]],"asks":[["delete",80041.0,0.0],["delete",80054.5,0.0],["delete",80055.0,0.0],["delete",80057.5,0.0],["delete",80060.0,0.0],["delete",80060.5,0.0],["delete",80064.0,0.0],["delete",80064.5,0.0],["delete",80065.0,0.0],["new",80067.0,19340.0],["new",80068.0,16490.0],["new",80068.5,26910.0],["change",80069.0,14020.0],["new",80070.5,4.0e4],["new",80071.0,19340.0],["change",80072.0,77950.0],["change",80072.5,6.89e4],["change",80073.0,420.0]],"prev_change_id":41106292246}}}
[2025-04-06 23:48:31.434] [multi_sink] [info] Processing received message: {"jsonrpc":"2.0","method":"subscription","params":{"channel":"book.BTC-PERPETUAL.100ms","data":{"timestamp":1743963512324,"type":"change","change_id":41106292740,"instrument_name":"BTC-PERPETUAL","bids":[["delete",80040.0,0.0],["delete",80039.5,0.0],["delete",80039.0,0.0],["delete",80036.0,0.0],["delete",80035.0,0.0],["delete",80033.5,0.0],["delete",80033.0,0.0],["delete",80030.0,0.0],["delete",80029.5,0.0],["new",80024.0,44680.0],["change",80023.5,116010.0],["new",80022.5,1060.0],["new",80022.0,7040.0],["new",80020.0,4.2e3],["new",80019.5,1.56e4],["new",80019.0,1.06e4],["change",80017.5,53950.0],["new",79995.5,5710350.0],["delete",79989.5,0.0]],"asks":[["delete",80041.0,0.0],["delete",80054.5,0.0],["delete",80055.0,0.0],["delete",80057.5,0.0],["delete",80060.0,0.0],["delete",80060.5,0.0],["delete",80064.0,0.0],["delete",80064.5,0.0],["delete",80065.0,0.0],["new",80067.0,19340.0],["new",80068.0,16490.0],["new",80068.5,26910.0],["change",80069.0,14020.0],["new",80070.5,4.0e4],["new",80071.0,19340.0],["change",80072.0,77950.0],["change",80072.5,6.89e4],["change",80073.0,420.0]],"prev_change_id":41106292246}}}
[2025-04-06 23:48:31.435] [multi_sink] [error] Broadcast error: Operation canceled
[2025-04-06 23:48:31.436] [multi_sink] [error] Broadcast error: Operation canceled
[2025-04-06 23:48:31.763] [multi_sink] [info] 📩 Received: {"jsonrpc":"2.0","method":"subscription","params":{"channel":"book.BTC-PERPETUAL.100ms","data":{"timestamp":1743963512628,"type":"change","change_id":41106293255,"instrument_name":"BTC-PERPETUAL","bids":[["new",80034.0,4.5e4],["new",80033.5,2.0e4],["new",80032.5,1.0e4],["delete",80029.0,0.0],["delete",80028.5,0.0],["new",80027.0,13690.0],["new",80026.5,3.53e4],["change",80026.0,62750.0],["change",80025.5,316580.0],["change",80025.0,653270.0],["change",80024.5,160020.0],["change",80023.5,105730.0],["delete",80021.5,0.0],["delete",80021.0,0.0]],"asks":[["new",80057.0,490.0],["new",80057.5,2450.0],["new",80060.0,14370.0],["new",80061.0,34540.0],["new",80063.0,9670.0],["new",80065.0,1270.0],["new",80066.0,16490.0],["change",80066.5,1.29e4],["change",80069.0,13870.0],["delete",80069.5,0.0],["delete",80071.5,0.0],["change",80072.0,69150.0],["change",80072.5,34450.0],["change",80073.0,210.0],["change",80074.5,3020.0]],"prev_change_id":41106292740}}}
[2025-04-06 23:48:31.764] [multi_sink] [info] Processing received message: {"jsonrpc":"2.0","method":"subscription","params":{"channel":"book.BTC-PERPETUAL.100ms","data":{"timestamp":1743963512628,"type":"change","change_id":41106293255,"instrument_name":"BTC-PERPETUAL","bids":[["new",80034.0,4.5e4],["new",80033.5,2.0e4],["new",80032.5,1.0e4],["delete",80029.0,0.0],["delete",80028.5,0.0],["new",80027.0,13690.0],["new",80026.5,3.53e4],["change",80026.0,62750.0],["change",80025.5,316580.0],["change",80025.0,653270.0],["change",80024.5,160020.0],["change",80023.5,105730.0],["delete",80021.5,0.0],["delete",80021.0,0.0]],"asks":[["new",80057.0,490.0],["new",80057.5,2450.0],["new",80060.0,14370.0],["new",80061.0,34540.0],["new",80063.0,9670.0],["new",80065.0,1270.0],["new",80066.0,16490.0],["change",80066.5,1.29e4],["change",80069.0,13870.0],["delete",80069.5,0.0],["delete",80071.5,0.0],["change",80072.0,69150.0],["change",80072.5,34450.0],["change",80073.0,210.0],["change",80074.5,3020.0]],"prev_change_id":41106292740}}}
[2025-04-06 23:48:31.765] [multi_sink] [error] Broadcast error: Operation canceled
[2025-04-06 23:48:31.766] [multi_sink] [error] Broadcast error: Operation canceled
[2025-04-06 23:48:32.093] [multi_sink] [info] 📩 Received: {"jsonrpc":"2.0","method":"subscription","params":{"channel":"book.BTC-PERPETUAL.100ms","data":{"timestamp":1743963512971,"type":"change","change_id":41106293766,"instrument_name":"BTC-PERPETUAL","bids":[["new",80035.0,560630.0],["new",80034.5,67680.0],["delete",80020.5,0.0]],"asks":[["new",80035.5,17050.0],["delete",80040.5,0.0],["new",80041.0,1.4e3],["delete",80075.0,0.0],["delete",80075.5,0.0]],"prev_change_id":41106293255}}}
[2025-04-06 23:48:32.095] [multi_sink] [info] Processing received message: {"jsonrpc":"2.0","method":"subscription","params":{"channel":"book.BTC-PERPETUAL.100ms","data":{"timestamp":1743963512971,"type":"change","change_id":41106293766,"instrument_name":"BTC-PERPETUAL","bids":[["new",80035.0,560630.0],["new",80034.5,67680.0],["delete",80020.5,0.0]],"asks":[["new",80035.5,17050.0],["delete",80040.5,0.0],["new",80041.0,1.4e3],["delete",80075.0,0.0],["delete",80075.5,0.0]],"prev_change_id":41106293255}}}
[2025-04-06 23:48:32.095] [multi_sink] [error] Broadcast error: Operation canceled
[2025-04-06 23:48:32.096] [multi_sink] [error] Broadcast error: Operation canceled
[2025-04-06 23:48:32.429] [multi_sink] [info] 📩 Received: {"jsonrpc":"2.0","method":"subscription","params":{"channel":"book.BTC-PERPETUAL.100ms","data":{"timestamp":1743963513292,"type":"change","change_id":41106294319,"instrument_name":"BTC-PERPETUAL","bids":[],"asks":[["change",80035.5,17060.0]],"prev_change_id":41106293766}}}
[2025-04-06 23:48:32.434] [multi_sink] [info] Processing received message: {"jsonrpc":"2.0","method":"subscription","params":{"channel":"book.BTC-PERPETUAL.100ms","data":{"timestamp":1743963513292,"type":"change","change_id":41106294319,"instrument_name":"BTC-PERPETUAL","bids":[],"asks":[["change",80035.5,17060.0]],"prev_change_id":41106293766}}}
[2025-04-06 23:48:32.434] [multi_sink] [error] Broadcast error: Operation canceled
[2025-04-06 23:48:32.434] [multi_sink] [error] Broadcast error: Operation canceled
[2025-04-06 23:48:34.038] [multi_sink] [info] 📩 Received: {"jsonrpc":"2.0","method":"subscription","params":{"channel":"book.BTC-PERPETUAL.100ms","data":{"timestamp":1743963514722,"type":"change","change_id":41106296213,"instrument_name":"BTC-PERPETUAL","bids":[["new",79871.5,79870.0],["new",79821.5,119730.0]],"asks":[["new",80194.5,80190.0],["new",80244.5,120360.0]],"prev_change_id":41106294319}}}
[2025-04-06 23:48:34.040] [multi_sink] [info] Processing received message: {"jsonrpc":"2.0","method":"subscription","params":{"channel":"book.BTC-PERPETUAL.100ms","data":{"timestamp":1743963514722,"type":"change","change_id":41106296213,"instrument_name":"BTC-PERPETUAL","bids":[["new",79871.5,79870.0],["new",79821.5,119730.0]],"asks":[["new",80194.5,80190.0],["new",80244.5,120360.0]],"prev_change_id":41106294319}}}
[2025-04-06 23:48:34.040] [multi_sink] [error] Broadcast error: Operation canceled
[2025-04-06 23:48:34.041] [multi_sink] [error] Broadcast error: Operation canceled
[2025-04-06 23:48:34.372] [multi_sink] [info] 📩 Received: {"jsonrpc":"2.0","method":"subscription","params":{"channel":"book.ETH-PERPETUAL.100ms","data":{"timestamp":1743963515265,"type":"change","change_id":23674098058,"instrument_name":"ETH-PERPETUAL","bids":[],"asks":[["change",1656.55,4308.0]],"prev_change_id":23674093938}}}
[2025-04-06 23:48:34.375] [multi_sink] [info] Processing received message: {"jsonrpc":"2.0","method":"subscription","params":{"channel":"book.ETH-PERPETUAL.100ms","data":{"timestamp":1743963515265,"type":"change","change_id":23674098058,"instrument_name":"ETH-PERPETUAL","bids":[],"asks":[["change",1656.55,4308.0]],"prev_change_id":23674093938}}}
[2025-04-06 23:48:34.376] [multi_sink] [error] Broadcast error: Operation canceled
[2025-04-06 23:48:34.377] [multi_sink] [error] Broadcast error: Operation canceled
[2025-04-06 23:48:34.703] [multi_sink] [info] 📩 Received: {"jsonrpc":"2.0","method":"subscription","params":{"channel":"book.ETH-PERPETUAL.100ms","data":{"timestamp":1743963515594,"type":"change","change_id":23674098543,"instrument_name":"ETH-PERPETUAL","bids":[["delete",1656.5,0.0],["delete",1656.25,0.0],["delete",1656.2,0.0],["delete",1656.15,0.0],["delete",1656.05,0.0],["new",1653.4,15594.0],["new",1653.35,39503.0],["new",1653.3,5315.0]],"asks":[["delete",1656.55,0.0],["delete",1656.65,0.0],["delete",1656.7,0.0],["delete",1656.8,0.0],["delete",1656.85,0.0]],"prev_change_id":23674098058}}}
[2025-04-06 23:48:34.710] [multi_sink] [info] Processing received message: {"jsonrpc":"2.0","method":"subscription","params":{"channel":"book.ETH-PERPETUAL.100ms","data":{"timestamp":1743963515594,"type":"change","change_id":23674098543,"instrument_name":"ETH-PERPETUAL","bids":[["delete",1656.5,0.0],["delete",1656.25,0.0],["delete",1656.2,0.0],["delete",1656.15,0.0],["delete",1656.05,0.0],["new",1653.4,15594.0],["new",1653.35,39503.0],["new",1653.3,5315.0]],"asks":[["delete",1656.55,0.0],["delete",1656.65,0.0],["delete",1656.7,0.0],["delete",1656.8,0.0],["delete",1656.85,0.0]],"prev_change_id":23674098058}}}
[2025-04-06 23:48:34.711] [multi_sink] [error] Broadcast error: Operation canceled
[2025-04-06 23:48:34.712] [multi_sink] [error] Broadcast error: Operation canceled
[2025-04-06 23:48:35.034] [multi_sink] [info] 📩 Received: {"jsonrpc":"2.0","method":"subscription","params":{"channel":"book.ETH-PERPETUAL.100ms","data":{"timestamp":1743963515893,"type":"change","change_id":23674098893,"instrument_name":"ETH-PERPETUAL","bids":[["delete",1656.0,0.0],["delete",1655.95,0.0],["delete",1655.9,0.0],["delete",1655.8,0.0],["delete",1655.75,0.0],["delete",1655.7,0.0],["delete",1655.55,0.0],["delete",1655.5,0.0],["delete",1655.45,0.0]],"asks":[["new",1655.45,59369.0],["new",1655.5,8720.0],["new",1655.55,19260.0],["new",1655.6,7542.0],["change",1656.9,5396465.0],["delete",1656.95,0.0],["delete",1657.0,0.0],["delete",1657.05,0.0],["delete",1657.1,0.0],["delete",1657.15,0.0],["delete",1657.2,0.0],["delete",1657.25,0.0]],"prev_change_id":23674098543}}}
[2025-04-06 23:48:35.035] [multi_sink] [info] Processing received message: {"jsonrpc":"2.0","method":"subscription","params":{"channel":"book.ETH-PERPETUAL.100ms","data":{"timestamp":1743963515893,"type":"change","change_id":23674098893,"instrument_name":"ETH-PERPETUAL","bids":[["delete",1656.0,0.0],["delete",1655.95,0.0],["delete",1655.9,0.0],["delete",1655.8,0.0],["delete",1655.75,0.0],["delete",1655.7,0.0],["delete",1655.55,0.0],["delete",1655.5,0.0],["delete",1655.45,0.0]],"asks":[["new",1655.45,59369.0],["new",1655.5,8720.0],["new",1655.55,19260.0],["new",1655.6,7542.0],["change",1656.9,5396465.0],["delete",1656.95,0.0],["delete",1657.0,0.0],["delete",1657.05,0.0],["delete",1657.1,0.0],["delete",1657.15,0.0],["delete",1657.2,0.0],["delete",1657.25,0.0]],"prev_change_id":23674098543}}}
[2025-04-06 23:48:35.037] [multi_sink] [error] Broadcast error: Operation canceled
[2025-04-06 23:48:35.038] [multi_sink] [error] Broadcast error: Operation canceled
[2025-04-06 23:48:35.366] [multi_sink] [info] 📩 Received: {"jsonrpc":"2.0","method":"subscription","params":{"channel":"book.ETH-PERPETUAL.100ms","data":{"timestamp":1743963516161,"type":"change","change_id":23674099316,"instrument_name":"ETH-PERPETUAL","bids":[["delete",1655.4,0.0],["delete",1655.35,0.0],["change",1655.3,7220760.0],["delete",1655.25,0.0],["delete",1655.2,0.0],["delete",1655.15,0.0],["new",1654.4,22547.0],["new",1654.3,3.0e3],["new",1654.25,17936.0],["new",1654.05,1071.0]],"asks":[["new",1655.4,20479.0],["delete",1657.3,0.0],["delete",1657.35,0.0],["delete",1657.4,0.0],["delete",1657.45,0.0],["delete",1657.5,0.0],["delete",1657.55,0.0],["delete",1657.6,0.0]],"prev_change_id":23674098893}}}
[2025-04-06 23:48:35.370] [multi_sink] [info] Processing received message: {"jsonrpc":"2.0","method":"subscription","params":{"channel":"book.ETH-PERPETUAL.100ms","data":{"timestamp":1743963516161,"type":"change","change_id":23674099316,"instrument_name":"ETH-PERPETUAL","bids":[["delete",1655.4,0.0],["delete",1655.35,0.0],["change",1655.3,7220760.0],["delete",1655.25,0.0],["delete",1655.2,0.0],["delete",1655.15,0.0],["new",1654.4,22547.0],["new",1654.3,3.0e3],["new",1654.25,17936.0],["new",1654.05,1071.0]],"asks":[["new",1655.4,20479.0],["delete",1657.3,0.0],["delete",1657.35,0.0],["delete",1657.4,0.0],["delete",1657.45,0.0],["delete",1657.5,0.0],["delete",1657.55,0.0],["delete",1657.6,0.0]],"prev_change_id":23674098893}}}
[2025-04-06 23:48:35.371] [multi_sink] [error] Broadcast error: Operation canceled
[2025-04-06 23:48:35.372] [multi_sink] [error] Broadcast error: Operation canceled
[2025-04-06 23:48:35.788] [multi_sink] [info] Removed client session: 140545758343072
[2025-04-06 23:48:36.028] [multi_sink] [info] 📩 Received: {"jsonrpc":"2.0","method":"subscription","params":{"channel":"book.ETH-PERPETUAL.100ms","data":{"timestamp":1743963516818,"type":"change","change_id":23674100124,"instrument_name":"ETH-PERPETUAL","bids":[["change",1655.3,7120760.0]],"asks":[],"prev_change_id":23674099316}}}
[2025-04-06 23:48:36.031] [multi_sink] [info] Processing received message: {"jsonrpc":"2.0","method":"subscription","params":{"channel":"book.ETH-PERPETUAL.100ms","data":{"timestamp":1743963516818,"type":"change","change_id":23674100124,"instrument_name":"ETH-PERPETUAL","bids":[["change",1655.3,7120760.0]],"asks":[],"prev_change_id":23674099316}}}
[2025-04-06 23:48:36.031] [multi_sink] [error] Broadcast error: Operation canceled
[2025-04-06 23:48:36.032] [multi_sink] [error] Broadcast error: Operation canceled
[2025-04-06 23:48:36.032] [multi_sink] [error] Broadcast error: Operation canceled
[2025-04-06 23:48:36.100] [multi_sink] [info] 📩 Received: {"jsonrpc":"2.0","method":"subscription","params":{"channel":"book.BTC-PERPETUAL.100ms","data":{"timestamp":1743963516993,"type":"change","change_id":41106299327,"instrument_name":"BTC-PERPETUAL","bids":[],"asks":[["change",80035.5,10.0],["new",80047.0,8.13e4]],"prev_change_id":41106296213}}}
[2025-04-06 23:48:36.104] [multi_sink] [info] Processing received message: {"jsonrpc":"2.0","method":"subscription","params":{"channel":"book.BTC-PERPETUAL.100ms","data":{"timestamp":1743963516993,"type":"change","change_id":41106299327,"instrument_name":"BTC-PERPETUAL","bids":[],"asks":[["change",80035.5,10.0],["new",80047.0,8.13e4]],"prev_change_id":41106296213}}}
[2025-04-06 23:48:36.105] [multi_sink] [error] Broadcast error: Operation canceled
[2025-04-06 23:48:36.105] [multi_sink] [error] Broadcast error: Operation canceled
[2025-04-06 23:48:36.105] [multi_sink] [error] Broadcast error: Operation canceled
[2025-04-06 23:48:36.433] [multi_sink] [info] 📩 Received: {"jsonrpc":"2.0","method":"subscription","params":{"channel":"book.BTC-PERPETUAL.100ms","data":{"timestamp":1743963517290,"type":"change","change_id":41106299438,"instrument_name":"BTC-PERPETUAL","bids":[["delete",80035.0,0.0],["delete",80034.5,0.0],["delete",80034.0,0.0],["delete",80033.5,0.0],["delete",80032.5,0.0],["delete",80027.0,0.0],["delete",80026.5,0.0],["delete",80026.0,0.0],["delete",80025.5,0.0],["new",80010.0,20.0],["new",80008.0,9350.0],["new",80007.5,1060.0],["new",80001.5,30820.0],["new",80001.0,22830.0],["new",8.0e4,88680.0],["new",79999.5,490.0],["new",79999.0,70.0],["new",79997.0,16490.0]],"asks":[["new",80038.5,24010.0],["new",80039.0,80030.0],["delete",80041.0,0.0],["new",80041.5,22760.0],["new",80042.0,3.54e4],["new",80043.0,44490.0],["new",80044.0,99070.0],["new",80044.5,5490.0],["new",80046.0,19340.0],["delete",80057.0,0.0],["delete",80057.5,0.0],["delete",80060.0,0.0],["delete",80061.0,0.0],["delete",80063.0,0.0],["delete",80065.0,0.0],["delete",80066.0,0.0]],"prev_change_id":41106299327}}}
[2025-04-06 23:48:36.437] [multi_sink] [info] Processing received message: {"jsonrpc":"2.0","method":"subscription","params":{"channel":"book.BTC-PERPETUAL.100ms","data":{"timestamp":1743963517290,"type":"change","change_id":41106299438,"instrument_name":"BTC-PERPETUAL","bids":[["delete",80035.0,0.0],["delete",80034.5,0.0],["delete",80034.0,0.0],["delete",80033.5,0.0],["delete",80032.5,0.0],["delete",80027.0,0.0],["delete",80026.5,0.0],["delete",80026.0,0.0],["delete",80025.5,0.0],["new",80010.0,20.0],["new",80008.0,9350.0],["new",80007.5,1060.0],["new",80001.5,30820.0],["new",80001.0,22830.0],["new",8.0e4,88680.0],["new",79999.5,490.0],["new",79999.0,70.0],["new",79997.0,16490.0]],"asks":[["new",80038.5,24010.0],["new",80039.0,80030.0],["delete",80041.0,0.0],["new",80041.5,22760.0],["new",80042.0,3.54e4],["new",80043.0,44490.0],["new",80044.0,99070.0],["new",80044.5,5490.0],["new",80046.0,19340.0],["delete",80057.0,0.0],["delete",80057.5,0.0],["delete",80060.0,0.0],["delete",80061.0,0.0],["delete",80063.0,0.0],["delete",80065.0,0.0],["delete",80066.0,0.0]],"prev_change_id":41106299327}}}
[2025-04-06 23:48:36.437] [multi_sink] [error] Broadcast error: Operation canceled
[2025-04-06 23:48:36.438] [multi_sink] [error] Broadcast error: Operation canceled
[2025-04-06 23:48:36.438] [multi_sink] [error] Broadcast error: Operation canceled
[2025-04-06 23:48:36.762] [multi_sink] [info] 📩 Received: {"jsonrpc":"2.0","method":"subscription","params":{"channel":"book.BTC-PERPETUAL.100ms","data":{"timestamp":1743963517633,"type":"change","change_id":41106300354,"instrument_name":"BTC-PERPETUAL","bids":[["delete",80025.0,0.0],["delete",80024.5,0.0],["delete",80024.0,0.0],["delete",80023.5,0.0],["change",80022.5,1060.0],["delete",80022.0,0.0],["change",80020.0,4.2e3],["delete",80019.5,0.0],["delete",80019.0,0.0],["change",80017.5,59730.0],["new",80016.0,90.0],["new",80015.0,1.0e4],["new",80014.0,30.0],["new",80013.5,26480.0],["new",80012.0,60.0],["new",80010.5,1.0e6]],"asks":[["new",80026.5,220960.0],["new",80031.0,1150.0],["new",80031.5,3840.0],["new",80033.5,56490.0],["new",80034.0,30310.0],["new",80034.5,4.78e4],["new",80035.0,4.05e4],["change",80035.5,76370.0],["new",80036.0,3.1e3],["delete",80066.5,0.0],["delete",80067.0,0.0],["delete",80068.0,0.0],["delete",80068.5,0.0],["delete",80069.0,0.0],["delete",80070.5,0.0],["delete",80071.0,0.0],["delete",80072.0,0.0],["delete",80072.5,0.0]],"prev_change_id":41106299438}}}
[2025-04-06 23:48:36.766] [multi_sink] [info] Processing received message: {"jsonrpc":"2.0","method":"subscription","params":{"channel":"book.BTC-PERPETUAL.100ms","data":{"timestamp":1743963517633,"type":"change","change_id":41106300354,"instrument_name":"BTC-PERPETUAL","bids":[["delete",80025.0,0.0],["delete",80024.5,0.0],["delete",80024.0,0.0],["delete",80023.5,0.0],["change",80022.5,1060.0],["delete",80022.0,0.0],["change",80020.0,4.2e3],["delete",80019.5,0.0],["delete",80019.0,0.0],["change",80017.5,59730.0],["new",80016.0,90.0],["new",80015.0,1.0e4],["new",80014.0,30.0],["new",80013.5,26480.0],["new",80012.0,60.0],["new",80010.5,1.0e6]],"asks":[["new",80026.5,220960.0],["new",80031.0,1150.0],["new",80031.5,3840.0],["new",80033.5,56490.0],["new",80034.0,30310.0],["new",80034.5,4.78e4],["new",80035.0,4.05e4],["change",80035.5,76370.0],["new",80036.0,3.1e3],["delete",80066.5,0.0],["delete",80067.0,0.0],["delete",80068.0,0.0],["delete",80068.5,0.0],["delete",80069.0,0.0],["delete",80070.5,0.0],["delete",80071.0,0.0],["delete",80072.0,0.0],["delete",80072.5,0.0]],"prev_change_id":41106299438}}}
[2025-04-06 23:48:36.767] [multi_sink] [error] Broadcast error: Operation canceled
[2025-04-06 23:48:36.768] [multi_sink] [error] Broadcast error: Operation canceled
[2025-04-06 23:48:36.768] [multi_sink] [error] Broadcast error: Operation canceled
[2025-04-06 23:48:37.091] [multi_sink] [info] 📩 Received: {"jsonrpc":"2.0","method":"subscription","params":{"channel":"book.BTC-PERPETUAL.100ms","data":{"timestamp":1743963517707,"type":"change","change_id":41106300388,"instrument_name":"BTC-PERPETUAL","bids":[["new",80025.0,487320.0],["new",80024.5,79990.0],["change",80017.5,18430.0]],"asks":[["new",80025.5,125560.0],["new",80026.0,190.0],["delete",80073.0,0.0],["delete",80074.5,0.0]],"prev_change_id":41106300354}}}
[2025-04-06 23:48:37.092] [multi_sink] [info] Processing received message: {"jsonrpc":"2.0","method":"subscription","params":{"channel":"book.BTC-PERPETUAL.100ms","data":{"timestamp":1743963517707,"type":"change","change_id":41106300388,"instrument_name":"BTC-PERPETUAL","bids":[["new",80025.0,487320.0],["new",80024.5,79990.0],["change",80017.5,18430.0]],"asks":[["new",80025.5,125560.0],["new",80026.0,190.0],["delete",80073.0,0.0],["delete",80074.5,0.0]],"prev_change_id":41106300354}}}
[2025-04-06 23:48:37.093] [multi_sink] [error] Broadcast error: Operation canceled
[2025-04-06 23:48:37.093] [multi_sink] [error] Broadcast error: Operation canceled
[2025-04-06 23:48:37.094] [multi_sink] [error] Broadcast error: Operation canceled
[2025-04-06 23:48:37.501] [multi_sink] [info] 📩 Received: {"jsonrpc":"2.0","method":"subscription","params":{"channel":"book.ETH-PERPETUAL.100ms","data":{"timestamp":1743963518394,"type":"change","change_id":23674102092,"instrument_name":"ETH-PERPETUAL","bids":[["delete",1655.3,0.0],["change",1653.35,7160263.0]],"asks":[],"prev_change_id":23674100124}}}
[2025-04-06 23:48:37.506] [multi_sink] [info] Processing received message: {"jsonrpc":"2.0","method":"subscription","params":{"channel":"book.ETH-PERPETUAL.100ms","data":{"timestamp":1743963518394,"type":"change","change_id":23674102092,"instrument_name":"ETH-PERPETUAL","bids":[["delete",1655.3,0.0],["change",1653.35,7160263.0]],"asks":[],"prev_change_id":23674100124}}}
[2025-04-06 23:48:37.507] [multi_sink] [error] Broadcast error: Operation canceled
[2025-04-06 23:48:37.508] [multi_sink] [error] Broadcast error: Operation canceled
[2025-04-06 23:48:37.509] [multi_sink] [error] Broadcast error: Operation canceled
[2025-04-06 23:48:37.754] [multi_sink] [info] 📩 Received: {"jsonrpc":"2.0","method":"subscription","params":{"channel":"book.BTC-PERPETUAL.100ms","data":{"timestamp":1743963518571,"type":"change","change_id":41106301949,"instrument_name":"BTC-PERPETUAL","bids":[],"asks":[["change",80035.5,76360.0]],"prev_change_id":41106300388}}}
[2025-04-06 23:48:37.756] [multi_sink] [info] Processing received message: {"jsonrpc":"2.0","method":"subscription","params":{"channel":"book.BTC-PERPETUAL.100ms","data":{"timestamp":1743963518571,"type":"change","change_id":41106301949,"instrument_name":"BTC-PERPETUAL","bids":[],"asks":[["change",80035.5,76360.0]],"prev_change_id":41106300388}}}
[2025-04-06 23:48:37.757] [multi_sink] [error] Broadcast error: Operation canceled
[2025-04-06 23:48:37.758] [multi_sink] [error] Broadcast error: Operation canceled
[2025-04-06 23:48:37.758] [multi_sink] [error] Broadcast error: Operation canceled
[2025-04-06 23:48:38.085] [multi_sink] [info] 📩 Received: {"jsonrpc":"2.0","method":"subscription","params":{"channel":"book.BTC-PERPETUAL.100ms","data":{"timestamp":1743963518892,"type":"change","change_id":41106302359,"instrument_name":"BTC-PERPETUAL","bids":[["delete",79839.5,0.0],["new",79830.5,8.0085e6]],"asks":[["change",80025.5,125570.0]],"prev_change_id":41106301949}}}
[2025-04-06 23:48:38.087] [multi_sink] [info] Processing received message: {"jsonrpc":"2.0","method":"subscription","params":{"channel":"book.BTC-PERPETUAL.100ms","data":{"timestamp":1743963518892,"type":"change","change_id":41106302359,"instrument_name":"BTC-PERPETUAL","bids":[["delete",79839.5,0.0],["new",79830.5,8.0085e6]],"asks":[["change",80025.5,125570.0]],"prev_change_id":41106301949}}}
[2025-04-06 23:48:38.088] [multi_sink] [error] Broadcast error: Operation canceled
[2025-04-06 23:48:38.088] [multi_sink] [error] Broadcast error: Operation canceled
[2025-04-06 23:48:38.089] [multi_sink] [error] Broadcast error: Operation canceled
[2025-04-06 23:48:38.162] [multi_sink] [info] 📩 Received: {"jsonrpc":"2.0","method":"subscription","params":{"channel":"book.ETH-PERPETUAL.100ms","data":{"timestamp":1743963519019,"type":"change","change_id":23674102701,"instrument_name":"ETH-PERPETUAL","bids":[["delete",1654.4,0.0],["delete",1654.3,0.0],["delete",1654.25,0.0],["delete",1654.05,0.0],["delete",1653.4,0.0],["change",1653.35,7120411.0],["delete",1647.6,0.0],["new",1645.05,500.0]],"asks":[["new",1654.65,5396465.0],["delete",1656.9,0.0],["new",1659.65,500.0],["delete",1662.0,0.0]],"prev_change_id":23674102092}}}
[2025-04-06 23:48:38.167] [multi_sink] [info] Processing received message: {"jsonrpc":"2.0","method":"subscription","params":{"channel":"book.ETH-PERPETUAL.100ms","data":{"timestamp":1743963519019,"type":"change","change_id":23674102701,"instrument_name":"ETH-PERPETUAL","bids":[["delete",1654.4,0.0],["delete",1654.3,0.0],["delete",1654.25,0.0],["delete",1654.05,0.0],["delete",1653.4,0.0],["change",1653.35,7120411.0],["delete",1647.6,0.0],["new",1645.05,500.0]],"asks":[["new",1654.65,5396465.0],["delete",1656.9,0.0],["new",1659.65,500.0],["delete",1662.0,0.0]],"prev_change_id":23674102092}}}
[2025-04-06 23:48:38.167] [multi_sink] [error] Broadcast error: Operation canceled
[2025-04-06 23:48:38.168] [multi_sink] [error] Broadcast error: Operation canceled
[2025-04-06 23:48:38.168] [multi_sink] [error] Broadcast error: Operation canceled
[2025-04-06 23:48:38.413] [multi_sink] [info] 📩 Received: {"jsonrpc":"2.0","method":"subscription","params":{"channel":"book.BTC-PERPETUAL.100ms","data":{"timestamp":1743963519173,"type":"change","change_id":41106302376,"instrument_name":"BTC-PERPETUAL","bids":[],"asks":[["new",80222.0,7777770.0],["delete",80231.0,0.0]],"prev_change_id":41106302359}}}
[2025-04-06 23:48:38.414] [multi_sink] [info] Processing received message: {"jsonrpc":"2.0","method":"subscription","params":{"channel":"book.BTC-PERPETUAL.100ms","data":{"timestamp":1743963519173,"type":"change","change_id":41106302376,"instrument_name":"BTC-PERPETUAL","bids":[],"asks":[["new",80222.0,7777770.0],["delete",80231.0,0.0]],"prev_change_id":41106302359}}}
[2025-04-06 23:48:38.415] [multi_sink] [error] Broadcast error: Operation canceled
[2025-04-06 23:48:38.415] [multi_sink] [error] Broadcast error: Operation canceled
[2025-04-06 23:48:38.415] [multi_sink] [error] Broadcast error: Operation canceled
[2025-04-06 23:48:38.744] [multi_sink] [info] 📩 Received: {"jsonrpc":"2.0","method":"subscription","params":{"channel":"book.BTC-PERPETUAL.100ms","data":{"timestamp":1743963519591,"type":"change","change_id":41106303308,"instrument_name":"BTC-PERPETUAL","bids":[["delete",79995.5,0.0],["new",79985.5,5710350.0]],"asks":[],"prev_change_id":41106302376}}}
[2025-04-06 23:48:38.747] [multi_sink] [info] Processing received message: {"jsonrpc":"2.0","method":"subscription","params":{"channel":"book.BTC-PERPETUAL.100ms","data":{"timestamp":1743963519591,"type":"change","change_id":41106303308,"instrument_name":"BTC-PERPETUAL","bids":[["delete",79995.5,0.0],["new",79985.5,5710350.0]],"asks":[],"prev_change_id":41106302376}}}
[2025-04-06 23:48:38.756] [multi_sink] [error] Broadcast error: Operation canceled
[2025-04-06 23:48:38.759] [multi_sink] [error] Broadcast error: Operation canceled
[2025-04-06 23:48:38.759] [multi_sink] [error] Broadcast error: Operation canceled
[2025-04-06 23:48:39.182] [multi_sink] [info] 📩 Received: {"jsonrpc":"2.0","method":"subscription","params":{"channel":"book.BTC-PERPETUAL.100ms","data":{"timestamp":1743963520075,"type":"change","change_id":41106303699,"instrument_name":"BTC-PERPETUAL","bids":[],"asks":[["change",80025.5,134060.0]],"prev_change_id":41106303308}}}
[2025-04-06 23:48:39.186] [multi_sink] [info] Processing received message: {"jsonrpc":"2.0","method":"subscription","params":{"channel":"book.BTC-PERPETUAL.100ms","data":{"timestamp":1743963520075,"type":"change","change_id":41106303699,"instrument_name":"BTC-PERPETUAL","bids":[],"asks":[["change",80025.5,134060.0]],"prev_change_id":41106303308}}}
[2025-04-06 23:48:39.186] [multi_sink] [error] Broadcast error: Operation canceled
[2025-04-06 23:48:39.186] [multi_sink] [error] Broadcast error: Operation canceled
[2025-04-06 23:48:39.186] [multi_sink] [error] Broadcast error: Operation canceled
[2025-04-06 23:48:39.552] [multi_sink] [info] 📩 Received: {"jsonrpc":"2.0","method":"subscription","params":{"channel":"book.ETH-PERPETUAL.100ms","data":{"timestamp":1743963520442,"type":"change","change_id":23674104454,"instrument_name":"ETH-PERPETUAL","bids":[],"asks":[["delete",1655.4,0.0]],"prev_change_id":23674102701}}}
[2025-04-06 23:48:39.556] [multi_sink] [info] Processing received message: {"jsonrpc":"2.0","method":"subscription","params":{"channel":"book.ETH-PERPETUAL.100ms","data":{"timestamp":1743963520442,"type":"change","change_id":23674104454,"instrument_name":"ETH-PERPETUAL","bids":[],"asks":[["delete",1655.4,0.0]],"prev_change_id":23674102701}}}
[2025-04-06 23:48:39.556] [multi_sink] [error] Broadcast error: Operation canceled
[2025-04-06 23:48:39.557] [multi_sink] [error] Broadcast error: Operation canceled
[2025-04-06 23:48:39.557] [multi_sink] [error] Broadcast error: Operation canceled
[2025-04-06 23:48:39.879] [multi_sink] [info] 📩 Received: {"jsonrpc":"2.0","method":"subscription","params":{"channel":"book.ETH-PERPETUAL.100ms","data":{"timestamp":1743963520768,"type":"change","change_id":23674104676,"instrument_name":"ETH-PERPETUAL","bids":[["delete",1653.3,0.0],["new",1653.25,20152.0],["new",1653.2,7551.0],["new",1653.15,21550.0],["new",1653.1,74393.0],["new",1653.05,2235.0],["new",1653.0,7451.0],["new",1652.95,10103.0],["new",1652.9,32711.0]],"asks":[["new",1654.95,6716.0],["new",1655.0,18836.0],["new",1655.05,3647.0],["new",1655.1,8614.0],["new",1655.15,1063.0],["delete",1655.45,0.0],["delete",1655.5,0.0],["delete",1655.55,0.0],["delete",1655.6,0.0]],"prev_change_id":23674104454}}}
[2025-04-06 23:48:39.884] [multi_sink] [info] Processing received message: {"jsonrpc":"2.0","method":"subscription","params":{"channel":"book.ETH-PERPETUAL.100ms","data":{"timestamp":1743963520768,"type":"change","change_id":23674104676,"instrument_name":"ETH-PERPETUAL","bids":[["delete",1653.3,0.0],["new",1653.25,20152.0],["new",1653.2,7551.0],["new",1653.15,21550.0],["new",1653.1,74393.0],["new",1653.05,2235.0],["new",1653.0,7451.0],["new",1652.95,10103.0],["new",1652.9,32711.0]],"asks":[["new",1654.95,6716.0],["new",1655.0,18836.0],["new",1655.05,3647.0],["new",1655.1,8614.0],["new",1655.15,1063.0],["delete",1655.45,0.0],["delete",1655.5,0.0],["delete",1655.55,0.0],["delete",1655.6,0.0]],"prev_change_id":23674104454}}}
[2025-04-06 23:48:39.885] [multi_sink] [error] Broadcast error: Operation canceled
[2025-04-06 23:48:39.886] [multi_sink] [error] Broadcast error: Operation canceled
[2025-04-06 23:48:39.887] [multi_sink] [error] Broadcast error: Operation canceled
[2025-04-06 23:48:40.209] [multi_sink] [info] 📩 Received: {"jsonrpc":"2.0","method":"subscription","params":{"channel":"book.ETH-PERPETUAL.100ms","data":{"timestamp":1743963521094,"type":"change","change_id":23674105073,"instrument_name":"ETH-PERPETUAL","bids":[["new",1653.8,7451.0],["new",1653.75,5.0e3],["new",1653.7,4555.0],["new",1653.65,15183.0],["new",1653.55,2235.0],["new",1653.5,7451.0],["new",1653.45,8421.0],["new",1653.4,41848.0],["new",1653.3,28069.0]],"asks":[["new",1654.5,13927.0],["new",1654.55,4.8e4],["new",1654.6,30261.0],["change",1654.65,5511031.0],["new",1654.7,33894.0],["new",1654.75,15748.0],["new",1654.8,7319.0],["new",1654.85,3769.0],["new",1654.9,9042.0]],"prev_change_id":23674104676}}}
[2025-04-06 23:48:40.212] [multi_sink] [info] Processing received message: {"jsonrpc":"2.0","method":"subscription","params":{"channel":"book.ETH-PERPETUAL.100ms","data":{"timestamp":1743963521094,"type":"change","change_id":23674105073,"instrument_name":"ETH-PERPETUAL","bids":[["new",1653.8,7451.0],["new",1653.75,5.0e3],["new",1653.7,4555.0],["new",1653.65,15183.0],["new",1653.55,2235.0],["new",1653.5,7451.0],["new",1653.45,8421.0],["new",1653.4,41848.0],["new",1653.3,28069.0]],"asks":[["new",1654.5,13927.0],["new",1654.55,4.8e4],["new",1654.6,30261.0],["change",1654.65,5511031.0],["new",1654.7,33894.0],["new",1654.75,15748.0],["new",1654.8,7319.0],["new",1654.85,3769.0],["new",1654.9,9042.0]],"prev_change_id":23674104676}}}
[2025-04-06 23:48:40.212] [multi_sink] [error] Broadcast error: Operation canceled
[2025-04-06 23:48:40.213] [multi_sink] [error] Broadcast error: Operation canceled
[2025-04-06 23:48:40.213] [multi_sink] [error] Broadcast error: Operation canceled
[2025-04-06 23:48:40.540] [multi_sink] [info] 📩 Received: {"jsonrpc":"2.0","method":"subscription","params":{"channel":"book.ETH-PERPETUAL.100ms","data":{"timestamp":1743963521154,"type":"change","change_id":23674105128,"instrument_name":"ETH-PERPETUAL","bids":[["new",1654.3,526.0],["new",1653.95,5.0e3]],"asks":[["new",1654.4,5.0e3]],"prev_change_id":23674105073}}}
[2025-04-06 23:48:40.541] [multi_sink] [info] Processing received message: {"jsonrpc":"2.0","method":"subscription","params":{"channel":"book.ETH-PERPETUAL.100ms","data":{"timestamp":1743963521154,"type":"change","change_id":23674105128,"instrument_name":"ETH-PERPETUAL","bids":[["new",1654.3,526.0],["new",1653.95,5.0e3]],"asks":[["new",1654.4,5.0e3]],"prev_change_id":23674105073}}}
[2025-04-06 23:48:40.542] [multi_sink] [error] Broadcast error: Operation canceled
[2025-04-06 23:48:40.542] [multi_sink] [error] Broadcast error: Operation canceled
[2025-04-06 23:48:40.543] [multi_sink] [error] Broadcast error: Operation canceled
[2025-04-06 23:48:41.103] [multi_sink] [info] 📩 Received: {"jsonrpc":"2.0","method":"subscription","params":{"channel":"book.BTC-PERPETUAL.100ms","data":{"timestamp":1743963521996,"type":"change","change_id":41106306320,"instrument_name":"BTC-PERPETUAL","bids":[],"asks":[["change",80025.5,8.5e3],["new",80049.5,5490.0]],"prev_change_id":41106303699}}}
[2025-04-06 23:48:41.104] [multi_sink] [info] Processing received message: {"jsonrpc":"2.0","method":"subscription","params":{"channel":"book.BTC-PERPETUAL.100ms","data":{"timestamp":1743963521996,"type":"change","change_id":41106306320,"instrument_name":"BTC-PERPETUAL","bids":[],"asks":[["change",80025.5,8.5e3],["new",80049.5,5490.0]],"prev_change_id":41106303699}}}
[2025-04-06 23:48:41.105] [multi_sink] [error] Broadcast error: Operation canceled
[2025-04-06 23:48:41.105] [multi_sink] [error] Broadcast error: Operation canceled
[2025-04-06 23:48:41.106] [multi_sink] [error] Broadcast error: Operation canceled
[2025-04-06 23:48:41.432] [multi_sink] [info] 📩 Received: {"jsonrpc":"2.0","method":"subscription","params":{"channel":"book.BTC-PERPETUAL.100ms","data":{"timestamp":1743963522303,"type":"change","change_id":41106306433,"instrument_name":"BTC-PERPETUAL","bids":[["delete",80025.0,0.0],["delete",80024.5,0.0],["delete",80022.5,0.0],["delete",80020.0,0.0],["change",80017.5,12650.0],["delete",80016.0,0.0],["delete",80015.0,0.0],["delete",80014.0,0.0],["delete",80013.5,0.0],["change",80010.0,30.0],["new",80009.0,1.0e4],["change",80008.0,55050.0],["change",80007.5,5270.0],["new",80007.0,1.0e4],["new",80003.5,16490.0],["new",80002.0,7.17e4],["change",80001.5,4.73e4],["change",80001.0,45660.0]],"asks":[["delete",80026.0,0.0],["delete",80026.5,0.0],["delete",80031.0,0.0],["delete",80031.5,0.0],["delete",80033.5,0.0],["delete",80034.0,0.0],["delete",80034.5,0.0],["delete",80035.0,0.0],["new",80040.0,3810.0],["new",80042.5,65840.0],["change",80043.0,84490.0],["change",80044.0,134930.0],["change",80044.5,21980.0],["new",80045.0,19360.0],["change",80047.0,105790.0],["new",80047.5,81640.0]],"prev_change_id":41106306320}}}
[2025-04-06 23:48:41.433] [multi_sink] [info] Processing received message: {"jsonrpc":"2.0","method":"subscription","params":{"channel":"book.BTC-PERPETUAL.100ms","data":{"timestamp":1743963522303,"type":"change","change_id":41106306433,"instrument_name":"BTC-PERPETUAL","bids":[["delete",80025.0,0.0],["delete",80024.5,0.0],["delete",80022.5,0.0],["delete",80020.0,0.0],["change",80017.5,12650.0],["delete",80016.0,0.0],["delete",80015.0,0.0],["delete",80014.0,0.0],["delete",80013.5,0.0],["change",80010.0,30.0],["new",80009.0,1.0e4],["change",80008.0,55050.0],["change",80007.5,5270.0],["new",80007.0,1.0e4],["new",80003.5,16490.0],["new",80002.0,7.17e4],["change",80001.5,4.73e4],["change",80001.0,45660.0]],"asks":[["delete",80026.0,0.0],["delete",80026.5,0.0],["delete",80031.0,0.0],["delete",80031.5,0.0],["delete",80033.5,0.0],["delete",80034.0,0.0],["delete",80034.5,0.0],["delete",80035.0,0.0],["new",80040.0,3810.0],["new",80042.5,65840.0],["change",80043.0,84490.0],["change",80044.0,134930.0],["change",80044.5,21980.0],["new",80045.0,19360.0],["change",80047.0,105790.0],["new",80047.5,81640.0]],"prev_change_id":41106306320}}}
[2025-04-06 23:48:41.435] [multi_sink] [error] Broadcast error: Operation canceled
[2025-04-06 23:48:41.435] [multi_sink] [error] Broadcast error: Operation canceled
[2025-04-06 23:48:41.436] [multi_sink] [error] Broadcast error: Operation canceled
[2025-04-06 23:48:41.763] [multi_sink] [info] 📩 Received: {"jsonrpc":"2.0","method":"subscription","params":{"channel":"book.BTC-PERPETUAL.100ms","data":{"timestamp":1743963522636,"type":"change","change_id":41106307355,"instrument_name":"BTC-PERPETUAL","bids":[["new",80022.5,1060.0],["new",80021.5,3.5e4],["new",80020.0,4.2e3],["change",80017.5,27680.0],["new",80016.0,90.0],["new",80014.0,30.0],["change",80012.0,60.0],["new",80011.0,313720.0],["change",80010.5,1.0e6],["change",80010.0,10.0],["change",80008.0,4.57e4],["change",80007.5,4210.0],["change",80001.5,16480.0],["change",80001.0,22830.0],["delete",8.0e4,0.0],["delete",79999.5,0.0]],"asks":[["new",80027.5,1.23e4],["new",80028.0,4.1e4],["new",80034.0,1.0e4],["new",80034.5,18460.0],["new",80035.0,4.05e4],["change",80035.5,35860.0],["change",80036.0,10790.0],["new",80037.5,1.45e4],["delete",80038.5,0.0],["delete",80039.0,0.0],["new",80039.5,16490.0],["delete",80041.5,0.0],["delete",80042.0,0.0],["change",80043.0,4.0e4],["change",80044.0,35860.0],["change",80044.5,16490.0]],"prev_change_id":41106306433}}}
[2025-04-06 23:48:41.765] [multi_sink] [info] Processing received message: {"jsonrpc":"2.0","method":"subscription","params":{"channel":"book.BTC-PERPETUAL.100ms","data":{"timestamp":1743963522636,"type":"change","change_id":41106307355,"instrument_name":"BTC-PERPETUAL","bids":[["new",80022.5,1060.0],["new",80021.5,3.5e4],["new",80020.0,4.2e3],["change",80017.5,27680.0],["new",80016.0,90.0],["new",80014.0,30.0],["change",80012.0,60.0],["new",80011.0,313720.0],["change",80010.5,1.0e6],["change",80010.0,10.0],["change",80008.0,4.57e4],["change",80007.5,4210.0],["change",80001.5,16480.0],["change",80001.0,22830.0],["delete",8.0e4,0.0],["delete",79999.5,0.0]],"asks":[["new",80027.5,1.23e4],["new",80028.0,4.1e4],["new",80034.0,1.0e4],["new",80034.5,18460.0],["new",80035.0,4.05e4],["change",80035.5,35860.0],["change",80036.0,10790.0],["new",80037.5,1.45e4],["delete",80038.5,0.0],["delete",80039.0,0.0],["new",80039.5,16490.0],["delete",80041.5,0.0],["delete",80042.0,0.0],["change",80043.0,4.0e4],["change",80044.0,35860.0],["change",80044.5,16490.0]],"prev_change_id":41106306433}}}
[2025-04-06 23:48:41.766] [multi_sink] [error] Broadcast error: Operation canceled
[2025-04-06 23:48:41.767] [multi_sink] [error] Broadcast error: Operation canceled
[2025-04-06 23:48:41.767] [multi_sink] [error] Broadcast error: Operation canceled
[2025-04-06 23:48:42.092] [multi_sink] [info] 📩 Received: {"jsonrpc":"2.0","method":"subscription","params":{"channel":"book.BTC-PERPETUAL.100ms","data":{"timestamp":1743963522711,"type":"change","change_id":41106307380,"instrument_name":"BTC-PERPETUAL","bids":[["new",80025.0,444530.0],["new",80024.5,78270.0],["delete",79999.0,0.0],["delete",79997.0,0.0]],"asks":[["change",80025.5,217840.0],["new",80026.5,5.0e3],["delete",80046.0,0.0],["change",80047.0,24490.0]],"prev_change_id":41106307355}}}
[2025-04-06 23:48:42.096] [multi_sink] [info] Processing received message: {"jsonrpc":"2.0","method":"subscription","params":{"channel":"book.BTC-PERPETUAL.100ms","data":{"timestamp":1743963522711,"type":"change","change_id":41106307380,"instrument_name":"BTC-PERPETUAL","bids":[["new",80025.0,444530.0],["new",80024.5,78270.0],["delete",79999.0,0.0],["delete",79997.0,0.0]],"asks":[["change",80025.5,217840.0],["new",80026.5,5.0e3],["delete",80046.0,0.0],["change",80047.0,24490.0]],"prev_change_id":41106307355}}}
[2025-04-06 23:48:42.097] [multi_sink] [error] Broadcast error: Operation canceled
[2025-04-06 23:48:42.098] [multi_sink] [error] Broadcast error: Operation canceled
[2025-04-06 23:48:42.098] [multi_sink] [error] Broadcast error: Operation canceled
[2025-04-06 23:48:44.548] [multi_sink] [info] 📩 Received: {"jsonrpc":"2.0","method":"subscription","params":{"channel":"book.ETH-PERPETUAL.100ms","data":{"timestamp":1743963525442,"type":"change","change_id":23674109979,"instrument_name":"ETH-PERPETUAL","bids":[],"asks":[["delete",1654.4,0.0],["new",1656.1,6455.0]],"prev_change_id":23674105128}}}
[2025-04-06 23:48:44.548] [multi_sink] [info] Processing received message: {"jsonrpc":"2.0","method":"subscription","params":{"channel":"book.ETH-PERPETUAL.100ms","data":{"timestamp":1743963525442,"type":"change","change_id":23674109979,"instrument_name":"ETH-PERPETUAL","bids":[],"asks":[["delete",1654.4,0.0],["new",1656.1,6455.0]],"prev_change_id":23674105128}}}
[2025-04-06 23:48:44.549] [multi_sink] [error] Broadcast error: Operation canceled
[2025-04-06 23:48:44.550] [multi_sink] [error] Broadcast error: Operation canceled
[2025-04-06 23:48:44.550] [multi_sink] [error] Broadcast error: Operation canceled
[2025-04-06 23:48:44.879] [multi_sink] [info] 📩 Received: {"jsonrpc":"2.0","method":"subscription","params":{"channel":"book.ETH-PERPETUAL.100ms","data":{"timestamp":1743963525766,"type":"change","change_id":23674110164,"instrument_name":"ETH-PERPETUAL","bids":[["delete",1654.3,0.0],["new",1654.05,8585.0],["new",1654.0,2.5e4],["change",1653.95,24390.0],["new",1653.9,79909.0],["new",1653.85,1424.0],["change",1653.8,100.0],["change",1653.75,4125.0],["change",1653.7,8511.0],["change",1653.65,1160.0],["delete",1653.55,0.0],["delete",1653.5,0.0],["delete",1653.45,0.0]],"asks":[["delete",1654.5,0.0],["delete",1654.55,0.0],["delete",1654.6,0.0],["change",1654.65,5396465.0],["delete",1654.7,0.0],["delete",1654.75,0.0],["delete",1654.8,0.0],["delete",1654.85,0.0],["delete",1654.9,0.0],["new",1655.65,23768.0],["new",1655.7,2.5e3],["new",1655.75,4059.0],["new",1655.8,4668.0],["new",1655.85,8768.0],["new",1655.9,1156.0],["new",1655.95,1155.0],["new",1656.0,7208.0],["new",1656.05,18841.0]],"prev_change_id":23674109979}}}
[2025-04-06 23:48:44.880] [multi_sink] [info] Processing received message: {"jsonrpc":"2.0","method":"subscription","params":{"channel":"book.ETH-PERPETUAL.100ms","data":{"timestamp":1743963525766,"type":"change","change_id":23674110164,"instrument_name":"ETH-PERPETUAL","bids":[["delete",1654.3,0.0],["new",1654.05,8585.0],["new",1654.0,2.5e4],["change",1653.95,24390.0],["new",1653.9,79909.0],["new",1653.85,1424.0],["change",1653.8,100.0],["change",1653.75,4125.0],["change",1653.7,8511.0],["change",1653.65,1160.0],["delete",1653.55,0.0],["delete",1653.5,0.0],["delete",1653.45,0.0]],"asks":[["delete",1654.5,0.0],["delete",1654.55,0.0],["delete",1654.6,0.0],["change",1654.65,5396465.0],["delete",1654.7,0.0],["delete",1654.75,0.0],["delete",1654.8,0.0],["delete",1654.85,0.0],["delete",1654.9,0.0],["new",1655.65,23768.0],["new",1655.7,2.5e3],["new",1655.75,4059.0],["new",1655.8,4668.0],["new",1655.85,8768.0],["new",1655.9,1156.0],["new",1655.95,1155.0],["new",1656.0,7208.0],["new",1656.05,18841.0]],"prev_change_id":23674109979}}}
[2025-04-06 23:48:44.881] [multi_sink] [error] Broadcast error: Operation canceled
[2025-04-06 23:48:44.882] [multi_sink] [error] Broadcast error: Operation canceled
[2025-04-06 23:48:44.882] [multi_sink] [error] Broadcast error: Operation canceled
[2025-04-06 23:48:45.209] [multi_sink] [info] 📩 Received: {"jsonrpc":"2.0","method":"subscription","params":{"channel":"book.ETH-PERPETUAL.100ms","data":{"timestamp":1743963526088,"type":"change","change_id":23674110591,"instrument_name":"ETH-PERPETUAL","bids":[["new",1654.5,11876.0],["new",1654.45,26296.0],["new",1654.4,23061.0],["new",1654.3,38611.0],["new",1654.25,36055.0],["new",1654.2,100.0],["new",1654.15,1155.0],["delete",1653.4,0.0],["delete",1653.3,0.0],["delete",1653.25,0.0],["delete",1653.2,0.0],["delete",1653.15,0.0],["delete",1653.1,0.0],["delete",1653.05,0.0],["delete",1653.0,0.0],["delete",1652.95,0.0]],"asks":[["change",1654.65,5377079.0],["delete",1654.95,0.0],["delete",1655.0,0.0],["delete",1655.05,0.0],["change",1655.1,15309.0],["delete",1655.15,0.0],["new",1655.2,3910.0],["new",1655.25,5.0e3],["new",1655.3,6255.0],["new",1655.35,100.0],["new",1655.4,7096.0],["new",1655.45,11369.0],["new",1655.5,38726.0],["new",1655.6,136008.0]],"prev_change_id":23674110164}}}
[2025-04-06 23:48:45.210] [multi_sink] [info] Processing received message: {"jsonrpc":"2.0","method":"subscription","params":{"channel":"book.ETH-PERPETUAL.100ms","data":{"timestamp":1743963526088,"type":"change","change_id":23674110591,"instrument_name":"ETH-PERPETUAL","bids":[["new",1654.5,11876.0],["new",1654.45,26296.0],["new",1654.4,23061.0],["new",1654.3,38611.0],["new",1654.25,36055.0],["new",1654.2,100.0],["new",1654.15,1155.0],["delete",1653.4,0.0],["delete",1653.3,0.0],["delete",1653.25,0.0],["delete",1653.2,0.0],["delete",1653.15,0.0],["delete",1653.1,0.0],["delete",1653.05,0.0],["delete",1653.0,0.0],["delete",1652.95,0.0]],"asks":[["change",1654.65,5377079.0],["delete",1654.95,0.0],["delete",1655.0,0.0],["delete",1655.05,0.0],["change",1655.1,15309.0],["delete",1655.15,0.0],["new",1655.2,3910.0],["new",1655.25,5.0e3],["new",1655.3,6255.0],["new",1655.35,100.0],["new",1655.4,7096.0],["new",1655.45,11369.0],["new",1655.5,38726.0],["new",1655.6,136008.0]],"prev_change_id":23674110164}}}
[2025-04-06 23:48:45.210] [multi_sink] [error] Broadcast error: Operation canceled
[2025-04-06 23:48:45.211] [multi_sink] [error] Broadcast error: Operation canceled
[2025-04-06 23:48:45.211] [multi_sink] [error] Broadcast error: Operation canceled
[2025-04-06 23:48:45.541] [multi_sink] [info] 📩 Received: {"jsonrpc":"2.0","method":"subscription","params":{"channel":"book.ETH-PERPETUAL.100ms","data":{"timestamp":1743963526156,"type":"change","change_id":23674110654,"instrument_name":"ETH-PERPETUAL","bids":[["delete",1652.9,0.0]],"asks":[["change",1654.65,5368234.0],["new",1655.05,4593.0]],"prev_change_id":23674110591}}}
[2025-04-06 23:48:45.543] [multi_sink] [info] Processing received message: {"jsonrpc":"2.0","method":"subscription","params":{"channel":"book.ETH-PERPETUAL.100ms","data":{"timestamp":1743963526156,"type":"change","change_id":23674110654,"instrument_name":"ETH-PERPETUAL","bids":[["delete",1652.9,0.0]],"asks":[["change",1654.65,5368234.0],["new",1655.05,4593.0]],"prev_change_id":23674110591}}}
[2025-04-06 23:48:45.544] [multi_sink] [error] Broadcast error: Operation canceled
[2025-04-06 23:48:45.544] [multi_sink] [error] Broadcast error: Operation canceled
[2025-04-06 23:48:45.544] [multi_sink] [error] Broadcast error: Operation canceled
[2025-04-06 23:48:45.792] [multi_sink] [info] 📩 Received: {"jsonrpc":"2.0","method":"subscription","params":{"channel":"book.BTC-PERPETUAL.100ms","data":{"timestamp":1743963526507,"type":"change","change_id":41106312589,"instrument_name":"BTC-PERPETUAL","bids":[],"asks":[["change",80025.5,209840.0]],"prev_change_id":41106307380}}}
[2025-04-06 23:48:45.794] [multi_sink] [info] Processing received message: {"jsonrpc":"2.0","method":"subscription","params":{"channel":"book.BTC-PERPETUAL.100ms","data":{"timestamp":1743963526507,"type":"change","change_id":41106312589,"instrument_name":"BTC-PERPETUAL","bids":[],"asks":[["change",80025.5,209840.0]],"prev_change_id":41106307380}}}
[2025-04-06 23:48:45.794] [multi_sink] [error] Broadcast error: Operation canceled
[2025-04-06 23:48:45.795] [multi_sink] [error] Broadcast error: Operation canceled
[2025-04-06 23:48:45.795] [multi_sink] [error] Broadcast error: Operation canceled
[2025-04-06 23:48:46.123] [multi_sink] [info] 📩 Received: {"jsonrpc":"2.0","method":"subscription","params":{"channel":"book.BTC-PERPETUAL.100ms","data":{"timestamp":1743963527000,"type":"change","change_id":41106313296,"instrument_name":"BTC-PERPETUAL","bids":[["delete",80025.0,0.0],["change",80008.0,9.05e4],["delete",79871.5,0.0],["delete",79821.5,0.0]],"asks":[["change",80025.5,10.0],["delete",80194.5,0.0],["delete",80244.5,0.0]],"prev_change_id":41106312589}}}
[2025-04-06 23:48:46.127] [multi_sink] [info] Processing received message: {"jsonrpc":"2.0","method":"subscription","params":{"channel":"book.BTC-PERPETUAL.100ms","data":{"timestamp":1743963527000,"type":"change","change_id":41106313296,"instrument_name":"BTC-PERPETUAL","bids":[["delete",80025.0,0.0],["change",80008.0,9.05e4],["delete",79871.5,0.0],["delete",79821.5,0.0]],"asks":[["change",80025.5,10.0],["delete",80194.5,0.0],["delete",80244.5,0.0]],"prev_change_id":41106312589}}}
[2025-04-06 23:48:46.127] [multi_sink] [error] Broadcast error: Operation canceled
[2025-04-06 23:48:46.128] [multi_sink] [error] Broadcast error: Operation canceled
[2025-04-06 23:48:46.128] [multi_sink] [error] Broadcast error: Operation canceled
[2025-04-06 23:48:46.394] [multi_sink] [info] 📩 Received: {"jsonrpc":"2.0","method":"subscription","params":{"channel":"book.ETH-PERPETUAL.100ms","data":{"timestamp":1743963527287,"type":"change","change_id":23674111802,"instrument_name":"ETH-PERPETUAL","bids":[["change",1653.85,7121835.0],["delete",1653.35,0.0]],"asks":[],"prev_change_id":23674110654}}}
[2025-04-06 23:48:46.399] [multi_sink] [info] Processing received message: {"jsonrpc":"2.0","method":"subscription","params":{"channel":"book.ETH-PERPETUAL.100ms","data":{"timestamp":1743963527287,"type":"change","change_id":23674111802,"instrument_name":"ETH-PERPETUAL","bids":[["change",1653.85,7121835.0],["delete",1653.35,0.0]],"asks":[],"prev_change_id":23674110654}}}
[2025-04-06 23:48:46.400] [multi_sink] [error] Broadcast error: Operation canceled
[2025-04-06 23:48:46.400] [multi_sink] [error] Broadcast error: Operation canceled
[2025-04-06 23:48:46.401] [multi_sink] [error] Broadcast error: Operation canceled
[2025-04-06 23:48:46.452] [multi_sink] [info] 📩 Received: {"jsonrpc":"2.0","method":"subscription","params":{"channel":"book.BTC-PERPETUAL.100ms","data":{"timestamp":1743963527339,"type":"change","change_id":41106313417,"instrument_name":"BTC-PERPETUAL","bids":[["delete",80024.5,0.0],["delete",80022.5,0.0],["delete",80021.5,0.0],["delete",80020.0,0.0],["change",80017.5,12650.0],["change",80016.0,90.0],["new",80015.5,1250.0],["new",80015.0,3840.0],["new",80014.5,230.0],["change",80014.0,30.0],["change",80012.0,60.0],["change",80011.0,396820.0],["change",80010.5,2.0e6],["delete",79830.5,0.0],["new",79829.5,8.0085e6]],"asks":[["delete",80026.5,0.0],["delete",80027.5,0.0],["delete",80028.0,0.0],["delete",80034.0,0.0],["delete",80034.5,0.0],["delete",80035.0,0.0],["delete",80035.5,0.0],["delete",80036.0,0.0],["delete",80037.5,0.0],["new",80052.0,15030.0],["new",80052.5,3.53e4],["new",80053.0,9690.0],["new",80055.0,3090.0],["new",80055.5,11890.0],["new",80056.5,1.49e4],["new",80058.0,16490.0],["new",80058.5,1.0e3],["new",80059.0,9670.0]],"prev_change_id":41106313296}}}
[2025-04-06 23:48:46.453] [multi_sink] [info] Processing received message: {"jsonrpc":"2.0","method":"subscription","params":{"channel":"book.BTC-PERPETUAL.100ms","data":{"timestamp":1743963527339,"type":"change","change_id":41106313417,"instrument_name":"BTC-PERPETUAL","bids":[["delete",80024.5,0.0],["delete",80022.5,0.0],["delete",80021.5,0.0],["delete",80020.0,0.0],["change",80017.5,12650.0],["change",80016.0,90.0],["new",80015.5,1250.0],["new",80015.0,3840.0],["new",80014.5,230.0],["change",80014.0,30.0],["change",80012.0,60.0],["change",80011.0,396820.0],["change",80010.5,2.0e6],["delete",79830.5,0.0],["new",79829.5,8.0085e6]],"asks":[["delete",80026.5,0.0],["delete",80027.5,0.0],["delete",80028.0,0.0],["delete",80034.0,0.0],["delete",80034.5,0.0],["delete",80035.0,0.0],["delete",80035.5,0.0],["delete",80036.0,0.0],["delete",80037.5,0.0],["new",80052.0,15030.0],["new",80052.5,3.53e4],["new",80053.0,9690.0],["new",80055.0,3090.0],["new",80055.5,11890.0],["new",80056.5,1.49e4],["new",80058.0,16490.0],["new",80058.5,1.0e3],["new",80059.0,9670.0]],"prev_change_id":41106313296}}}
[2025-04-06 23:48:46.455] [multi_sink] [error] Broadcast error: Operation canceled
[2025-04-06 23:48:46.455] [multi_sink] [error] Broadcast error: Operation canceled
[2025-04-06 23:48:46.455] [multi_sink] [error] Broadcast error: Operation canceled
[2025-04-06 23:48:46.782] [multi_sink] [info] 📩 Received: {"jsonrpc":"2.0","method":"subscription","params":{"channel":"book.BTC-PERPETUAL.100ms","data":{"timestamp":1743963527674,"type":"change","change_id":41106314365,"instrument_name":"BTC-PERPETUAL","bids":[["new",80023.5,13660.0],["new",80023.0,32980.0],["new",80022.5,1060.0],["new",80022.0,1.0e4],["new",80020.0,4.2e3],["new",80018.5,11410.0],["change",80017.5,14640.0],["new",80016.5,35450.0],["change",80010.5,1.0e6],["delete",80010.0,0.0],["delete",80009.0,0.0],["change",80008.0,4.48e4],["delete",80007.5,0.0],["delete",80007.0,0.0],["delete",80003.5,0.0],["delete",80002.0,0.0]],"asks":[["new",80026.5,4890.0],["new",80036.0,1330.0],["change",80039.5,490.0],["change",80040.0,14660.0],["delete",80042.5,0.0],["delete",80043.0,0.0],["new",80043.5,1.0e4],["change",80044.0,35860.0],["delete",80044.5,0.0],["change",80045.0,28870.0],["new",80046.0,1.46e4],["delete",80047.0,0.0],["change",80047.5,82160.0],["new",80221.0,7777770.0],["delete",80222.0,0.0]],"prev_change_id":41106313417}}}
[2025-04-06 23:48:46.785] [multi_sink] [info] Processing received message: {"jsonrpc":"2.0","method":"subscription","params":{"channel":"book.BTC-PERPETUAL.100ms","data":{"timestamp":1743963527674,"type":"change","change_id":41106314365,"instrument_name":"BTC-PERPETUAL","bids":[["new",80023.5,13660.0],["new",80023.0,32980.0],["new",80022.5,1060.0],["new",80022.0,1.0e4],["new",80020.0,4.2e3],["new",80018.5,11410.0],["change",80017.5,14640.0],["new",80016.5,35450.0],["change",80010.5,1.0e6],["delete",80010.0,0.0],["delete",80009.0,0.0],["change",80008.0,4.48e4],["delete",80007.5,0.0],["delete",80007.0,0.0],["delete",80003.5,0.0],["delete",80002.0,0.0]],"asks":[["new",80026.5,4890.0],["new",80036.0,1330.0],["change",80039.5,490.0],["change",80040.0,14660.0],["delete",80042.5,0.0],["delete",80043.0,0.0],["new",80043.5,1.0e4],["change",80044.0,35860.0],["delete",80044.5,0.0],["change",80045.0,28870.0],["new",80046.0,1.46e4],["delete",80047.0,0.0],["change",80047.5,82160.0],["new",80221.0,7777770.0],["delete",80222.0,0.0]],"prev_change_id":41106313417}}}
[2025-04-06 23:48:46.787] [multi_sink] [error] Broadcast error: Operation canceled
[2025-04-06 23:48:46.787] [multi_sink] [error] Broadcast error: Operation canceled
[2025-04-06 23:48:46.788] [multi_sink] [error] Broadcast error: Operation canceled
[2025-04-06 23:48:47.055] [multi_sink] [info] 📩 Received: {"jsonrpc":"2.0","method":"subscription","params":{"channel":"book.ETH-PERPETUAL.100ms","data":{"timestamp":1743963527785,"type":"change","change_id":23674112315,"instrument_name":"ETH-PERPETUAL","bids":[],"asks":[["delete",1654.65,0.0],["change",1655.45,5379603.0]],"prev_change_id":23674111802}}}
[2025-04-06 23:48:47.056] [multi_sink] [info] Processing received message: {"jsonrpc":"2.0","method":"subscription","params":{"channel":"book.ETH-PERPETUAL.100ms","data":{"timestamp":1743963527785,"type":"change","change_id":23674112315,"instrument_name":"ETH-PERPETUAL","bids":[],"asks":[["delete",1654.65,0.0],["change",1655.45,5379603.0]],"prev_change_id":23674111802}}}
[2025-04-06 23:48:47.056] [multi_sink] [error] Broadcast error: Operation canceled
[2025-04-06 23:48:47.057] [multi_sink] [error] Broadcast error: Operation canceled
[2025-04-06 23:48:47.057] [multi_sink] [error] Broadcast error: Operation canceled
[2025-04-06 23:48:47.112] [multi_sink] [info] 📩 Received: {"jsonrpc":"2.0","method":"subscription","params":{"channel":"book.BTC-PERPETUAL.100ms","data":{"timestamp":1743963527712,"type":"change","change_id":41106314378,"instrument_name":"BTC-PERPETUAL","bids":[["new",80025.0,455040.0],["new",80024.5,79990.0],["delete",80001.5,0.0],["delete",80001.0,0.0]],"asks":[["change",80025.5,13620.0],["delete",80049.5,0.0]],"prev_change_id":41106314365}}}
[2025-04-06 23:48:47.114] [multi_sink] [info] Processing received message: {"jsonrpc":"2.0","method":"subscription","params":{"channel":"book.BTC-PERPETUAL.100ms","data":{"timestamp":1743963527712,"type":"change","change_id":41106314378,"instrument_name":"BTC-PERPETUAL","bids":[["new",80025.0,455040.0],["new",80024.5,79990.0],["delete",80001.5,0.0],["delete",80001.0,0.0]],"asks":[["change",80025.5,13620.0],["delete",80049.5,0.0]],"prev_change_id":41106314365}}}
[2025-04-06 23:48:47.115] [multi_sink] [error] Broadcast error: Operation canceled
[2025-04-06 23:48:47.115] [multi_sink] [error] Broadcast error: Operation canceled
[2025-04-06 23:48:47.116] [multi_sink] [error] Broadcast error: Operation canceled
[2025-04-06 23:48:47.385] [multi_sink] [info] 📩 Received: {"jsonrpc":"2.0","method":"subscription","params":{"channel":"book.ETH-PERPETUAL.100ms","data":{"timestamp":1743963527991,"type":"change","change_id":23674112598,"instrument_name":"ETH-PERPETUAL","bids":[],"asks":[["change",1655.05,3967.0]],"prev_change_id":23674112315}}}
[2025-04-06 23:48:47.388] [multi_sink] [info] Processing received message: {"jsonrpc":"2.0","method":"subscription","params":{"channel":"book.ETH-PERPETUAL.100ms","data":{"timestamp":1743963527991,"type":"change","change_id":23674112598,"instrument_name":"ETH-PERPETUAL","bids":[],"asks":[["change",1655.05,3967.0]],"prev_change_id":23674112315}}}
[2025-04-06 23:48:47.389] [multi_sink] [error] Broadcast error: Operation canceled
[2025-04-06 23:48:47.389] [multi_sink] [error] Broadcast error: Operation canceled
[2025-04-06 23:48:47.389] [multi_sink] [error] Broadcast error: Operation canceled
[2025-04-06 23:48:49.552] [multi_sink] [info] 📩 Received: {"jsonrpc":"2.0","method":"subscription","params":{"channel":"book.ETH-PERPETUAL.100ms","data":{"timestamp":1743963530445,"type":"change","change_id":23674115173,"instrument_name":"ETH-PERPETUAL","bids":[],"asks":[["delete",1655.05,0.0],["new",1656.2,442.0]],"prev_change_id":23674112598}}}
[2025-04-06 23:48:49.553] [multi_sink] [info] Processing received message: {"jsonrpc":"2.0","method":"subscription","params":{"channel":"book.ETH-PERPETUAL.100ms","data":{"timestamp":1743963530445,"type":"change","change_id":23674115173,"instrument_name":"ETH-PERPETUAL","bids":[],"asks":[["delete",1655.05,0.0],["new",1656.2,442.0]],"prev_change_id":23674112598}}}
[2025-04-06 23:48:49.554] [multi_sink] [error] Broadcast error: Operation canceled
[2025-04-06 23:48:49.555] [multi_sink] [error] Broadcast error: Operation canceled
[2025-04-06 23:48:49.555] [multi_sink] [error] Broadcast error: Operation canceled
[2025-04-06 23:48:49.887] [multi_sink] [info] 📩 Received: {"jsonrpc":"2.0","method":"subscription","params":{"channel":"book.ETH-PERPETUAL.100ms","data":{"timestamp":1743963530744,"type":"change","change_id":23674115390,"instrument_name":"ETH-PERPETUAL","bids":[["delete",1654.5,0.0],["delete",1654.45,0.0],["delete",1654.4,0.0],["delete",1654.3,0.0],["delete",1654.25,0.0],["delete",1654.2,0.0],["delete",1654.15,0.0],["change",1654.05,2699.0],["change",1654.0,7612.0],["change",1653.95,24490.0],["change",1653.9,89996.0],["change",1653.8,28623.0],["change",1653.75,17350.0],["change",1653.7,36999.0],["change",1653.65,2214.0],["new",1653.6,7846.0]],"asks":[["delete",1655.1,0.0],["delete",1655.2,0.0],["delete",1655.25,0.0],["delete",1655.3,0.0],["delete",1655.35,0.0],["delete",1655.4,0.0],["change",1655.45,5368234.0],["delete",1655.5,0.0],["change",1655.8,18992.0],["change",1655.85,17536.0],["change",1655.9,21885.0],["change",1655.95,4803.0],["change",1656.0,8286.0],["change",1656.05,37699.0],["change",1656.1,68630.0],["new",1656.15,8519.0]],"prev_change_id":23674115173}}}
[2025-04-06 23:48:49.889] [multi_sink] [info] Processing received message: {"jsonrpc":"2.0","method":"subscription","params":{"channel":"book.ETH-PERPETUAL.100ms","data":{"timestamp":1743963530744,"type":"change","change_id":23674115390,"instrument_name":"ETH-PERPETUAL","bids":[["delete",1654.5,0.0],["delete",1654.45,0.0],["delete",1654.4,0.0],["delete",1654.3,0.0],["delete",1654.25,0.0],["delete",1654.2,0.0],["delete",1654.15,0.0],["change",1654.05,2699.0],["change",1654.0,7612.0],["change",1653.95,24490.0],["change",1653.9,89996.0],["change",1653.8,28623.0],["change",1653.75,17350.0],["change",1653.7,36999.0],["change",1653.65,2214.0],["new",1653.6,7846.0]],"asks":[["delete",1655.1,0.0],["delete",1655.2,0.0],["delete",1655.25,0.0],["delete",1655.3,0.0],["delete",1655.35,0.0],["delete",1655.4,0.0],["change",1655.45,5368234.0],["delete",1655.5,0.0],["change",1655.8,18992.0],["change",1655.85,17536.0],["change",1655.9,21885.0],["change",1655.95,4803.0],["change",1656.0,8286.0],["change",1656.05,37699.0],["change",1656.1,68630.0],["new",1656.15,8519.0]],"prev_change_id":23674115173}}}
[2025-04-06 23:48:49.891] [multi_sink] [error] Broadcast error: Operation canceled
[2025-04-06 23:48:49.891] [multi_sink] [error] Broadcast error: Operation canceled
[2025-04-06 23:48:49.892] [multi_sink] [error] Broadcast error: Operation canceled
[2025-04-07 08:01:51.871] [multi_sink] [info]  Logger initialized successfully.
[2025-04-07 08:01:51.871] [multi_sink] [info]  DeribitClient created for test.deribit.com:443/ws/api/v2
[2025-04-07 08:01:52.580] [multi_sink] [info] Starting receive_thread...
[2025-04-07 08:01:52.580] [multi_sink] [info]  Starting process_thread...
[2025-04-07 08:01:52.580] [multi_sink] [info]  Starting send_thread...
[2025-04-07 08:01:52.580] [multi_sink] [info] Starting WebSocket server on port 8080
[2025-04-07 08:01:52.580] [multi_sink] [info] Local WebSocket server running on port 8080
[2025-04-07 08:02:07.076] [multi_sink] [info] ➡️ Added to send queue: {"id":"auth#2","jsonrpc":"2.0","method":"public/auth","params":{"client_id":"KrYGD58Z","client_secret":"gI4vZ-kp10WPIwcRjdbNexOPOfppHpQWqHp6_fzEc3k","grant_type":"client_credentials"}}
[2025-04-07 08:02:07.076] [multi_sink] [info]  Sent authentication request
[2025-04-07 08:02:07.076] [multi_sink] [info] ➡️ Sent: {"id":"auth#2","jsonrpc":"2.0","method":"public/auth","params":{"client_id":"KrYGD58Z","client_secret":"gI4vZ-kp10WPIwcRjdbNexOPOfppHpQWqHp6_fzEc3k","grant_type":"client_credentials"}}
[2025-04-07 08:02:07.256] [multi_sink] [info] 📩 Received: {"jsonrpc":"2.0","id":"auth#2","result":{"enabled_features":["block_trade_approval","restricted_block_trades"],"access_token":"1775529128849.1WY3FTrB.7oni6gWT83Sp4Pmphrzyb1DIP0CYRBbTNvlrvTQgCRbIuX8X_h7t3kc48d5sSmNIeJF2fAOoHmGAwNolTxku9Pny4J_XKI9vl8TwCEkpOLlD95_2SR_c3boJnbvBaJfzIyx3tQLWIa-F-r4BYUwNQFAIx8Dv4zWcJvMT15p6cTwWzaHTnriBjTUw7FOa6ONz8aEi14xwPLGECplblnXg4OqqiosDLUplqXIzRsjh2_0qJ-kZjew_rbzkMvDRSGyQub3l_wXVdakwj3PVNHFayBMFwBHSCv6GBQ1-6Xbnv2cFRXWfNWvpVSQ0ejvgdnhe8oWVd4Di8m5B3pPtBlIRWMmc9UawrbsMXoBhu6QKGZznhCuSpsYP0xiSPMg2","expires_in":31536000,"refresh_token":"1775529128849.1bnlNOEW.9XjIEiSyGj1YJaecC7lS1IfGLWB5U_S4rxYSayUNwcAj8YwqtnwfKhpdj8eqtIHGyOZ1wynFzKFn1rN8Fzp6GOsEfN1vjDY_5rBxhJaOJoC0gau4t_0HUo_FSNr2eZ1LdMGBjv0wHAgkRAPjrW19gq3AN7JhPkppeYRzryFIM0K6Gz-NpXtRgMxmsEwnILh37lEZspJHOb8TI-Ns2rQrTtZs94nGKRtJM-iQ-aCDyz_X2YKv8mF6gM3CetVzGpjQFott2KjNY6QXi-3RHKZv_DhUapWW687sNEbN6H3zuYF9xuQHD41W92MzsstpcaIHwX8vNv-aNIJXqk-yPIa6XSpBvuKAEUbL5J_QePz3C6Ul3H5lb9geHovioy4","scope":"name:test block_rfq:read_write block_trade:read_write connection trade:read_write custody:read_write account:read_write wallet:read_write mainaccount","token_type":"bearer"},"usIn":1743993128849052,"usOut":1743993128849266,"usDiff":214,"testnet":true}
[2025-04-07 08:02:07.259] [multi_sink] [info] Processing received message: {"jsonrpc":"2.0","id":"auth#2","result":{"enabled_features":["block_trade_approval","restricted_block_trades"],"access_token":"1775529128849.1WY3FTrB.7oni6gWT83Sp4Pmphrzyb1DIP0CYRBbTNvlrvTQgCRbIuX8X_h7t3kc48d5sSmNIeJF2fAOoHmGAwNolTxku9Pny4J_XKI9vl8TwCEkpOLlD95_2SR_c3boJnbvBaJfzIyx3tQLWIa-F-r4BYUwNQFAIx8Dv4zWcJvMT15p6cTwWzaHTnriBjTUw7FOa6ONz8aEi14xwPLGECplblnXg4OqqiosDLUplqXIzRsjh2_0qJ-kZjew_rbzkMvDRSGyQub3l_wXVdakwj3PVNHFayBMFwBHSCv6GBQ1-6Xbnv2cFRXWfNWvpVSQ0ejvgdnhe8oWVd4Di8m5B3pPtBlIRWMmc9UawrbsMXoBhu6QKGZznhCuSpsYP0xiSPMg2","expires_in":31536000,"refresh_token":"1775529128849.1bnlNOEW.9XjIEiSyGj1YJaecC7lS1IfGLWB5U_S4rxYSayUNwcAj8YwqtnwfKhpdj8eqtIHGyOZ1wynFzKFn1rN8Fzp6GOsEfN1vjDY_5rBxhJaOJoC0gau4t_0HUo_FSNr2eZ1LdMGBjv0wHAgkRAPjrW19gq3AN7JhPkppeYRzryFIM0K6Gz-NpXtRgMxmsEwnILh37lEZspJHOb8TI-Ns2rQrTtZs94nGKRtJM-iQ-aCDyz_X2YKv8mF6gM3CetVzGpjQFott2KjNY6QXi-3RHKZv_DhUapWW687sNEbN6H3zuYF9xuQHD41W92MzsstpcaIHwX8vNv-aNIJXqk-yPIa6XSpBvuKAEUbL5J_QePz3C6Ul3H5lb9geHovioy4","scope":"name:test block_rfq:read_write block_trade:read_write connection trade:read_write custody:read_write account:read_write wallet:read_write mainaccount","token_type":"bearer"},"usIn":1743993128849052,"usOut":1743993128849266,"usDiff":214,"testnet":true}
[2025-04-07 08:02:19.707] [multi_sink] [info] ➡️ Added to send queue: {"id":"get_orderbook#3","jsonrpc":"2.0","method":"public/get_order_book","params":{"depth":10,"instrument_name":"BTC-PERPETUAL"}}
[2025-04-07 08:02:19.707] [multi_sink] [info] ➡️ Sent: {"id":"get_orderbook#3","jsonrpc":"2.0","method":"public/get_order_book","params":{"depth":10,"instrument_name":"BTC-PERPETUAL"}}
[2025-04-07 08:02:19.878] [multi_sink] [info] 📩 Received: {"jsonrpc":"2.0","id":"get_orderbook#3","result":{"timestamp":1743993141277,"state":"open","stats":{"high":83490.0,"low":75871.5,"price_change":-5.7114,"volume":37148.46799539,"volume_usd":2950978330.0,"volume_notional":2950978330.0},"change_id":41149454851,"index_price":78634.46,"instrument_name":"BTC-PERPETUAL","bids":[[78635.0,3160.0],[78630.0,60.0],[78627.5,320.0],[78625.0,170.0],[78622.5,2170.0],[78620.0,350.0],[78619.0,2920.0],[78618.5,9720.0],[78617.5,220.0],[78612.5,40.0]],"asks":[[78635.5,532070.0],[78636.0,1.0e4],[78637.5,15030.0],[78638.0,39320.0],[78640.0,5780.0],[78640.5,3.0e3],[78643.5,1.0e4],[78644.0,390.0],[78644.5,16930.0],[78645.0,23040.0]],"last_price":78632.0,"settlement_price":82998.58,"min_price":76269.5,"max_price":80987.5,"open_interest":10211017930,"mark_price":78628.62,"interest_value":-0.020843075990598987,"best_ask_price":78635.5,"best_bid_price":78635.0,"estimated_delivery_price":78634.46,"best_ask_amount":532070.0,"best_bid_amount":3160.0,"current_funding":0.0,"funding_8h":-1.25e-6},"usIn":1743993141479567,"usOut":1743993141479934,"usDiff":367,"testnet":true}
[2025-04-07 08:02:19.882] [multi_sink] [info] Processing received message: {"jsonrpc":"2.0","id":"get_orderbook#3","result":{"timestamp":1743993141277,"state":"open","stats":{"high":83490.0,"low":75871.5,"price_change":-5.7114,"volume":37148.46799539,"volume_usd":2950978330.0,"volume_notional":2950978330.0},"change_id":41149454851,"index_price":78634.46,"instrument_name":"BTC-PERPETUAL","bids":[[78635.0,3160.0],[78630.0,60.0],[78627.5,320.0],[78625.0,170.0],[78622.5,2170.0],[78620.0,350.0],[78619.0,2920.0],[78618.5,9720.0],[78617.5,220.0],[78612.5,40.0]],"asks":[[78635.5,532070.0],[78636.0,1.0e4],[78637.5,15030.0],[78638.0,39320.0],[78640.0,5780.0],[78640.5,3.0e3],[78643.5,1.0e4],[78644.0,390.0],[78644.5,16930.0],[78645.0,23040.0]],"last_price":78632.0,"settlement_price":82998.58,"min_price":76269.5,"max_price[2025-04-07 08:04:29.053] [multi_sink] [info]  Logger initialized successfully.
[2025-04-07 08:04:29.053] [multi_sink] [info]  DeribitClient created for test.deribit.com:443/ws/api/v2
[2025-04-07 08:04:29.711] [multi_sink] [info] Starting receive_thread...
[2025-04-07 08:04:29.711] [multi_sink] [info]  Starting process_thread...
[2025-04-07 08:04:29.711] [multi_sink] [info]  Starting send_thread...
[2025-04-07 08:04:29.712] [multi_sink] [info] Starting WebSocket server on port 8080
[2025-04-07 08:04:29.712] [multi_sink] [info] Local WebSocket server running on port 8080
[2025-04-07 08:04:43.846] [multi_sink] [info] ➡️ Added to send queue: {"id":"auth#2","jsonrpc":"2.0","method":"public/auth","params":{"client_id":"KrYGD58Z","client_secret":"gI4vZ-kp10WPIwcRjdbNexOPOfppHpQWqHp6_fzEc3k","grant_type":"client_credentials"}}
[2025-04-07 08:04:43.846] [multi_sink] [info]  Sent authentication request
[2025-04-07 08:04:43.846] [multi_sink] [info] ➡️ Sent: {"id":"auth#2","jsonrpc":"2.0","method":"public/auth","params":{"client_id":"KrYGD58Z","client_secret":"gI4vZ-kp10WPIwcRjdbNexOPOfppHpQWqHp6_fzEc3k","grant_type":"client_credentials"}}
[2025-04-07 08:04:44.001] [multi_sink] [info] 📩 Received: {"jsonrpc":"2.0","id":"auth#2","result":{"enabled_features":["block_trade_approval","restricted_block_trades"],"access_token":"1775529285619.1YTd-srK.AWKh7Sv2LuLlxE9q5Fz7mY8bDcDYKLAB-KoC4CHKu0iC7nI7NhPUz0Gf7k46Qa9IT37wZV5Y2ylyKn5ggFnjxuKmRHt571E_je_cvMhngzcRckiLqiykFii7RZEmpT_fotReU2mjBrllC8xlBcPGfWq4lN23t9bsET890AIDS4dMoIPj9AO0SAfJK5ncrNokRlKHxSSTJ-KFDCzTZsUeqUAOQ-0ApjpG_pErTOEu6gi76s6SJ4Vasz4dSwW83OVLeYGiza4cpcfWbM_Q7myATWd1JqjMqYo92BPtUh5eqxFh9wO9R7N0o7LytliKVO-llMs59ucKAKs2Qnr-WaXhjmYlXRMRLyQCUr4HPin4UWCBr_iz5BX43vPc-h1x","expires_in":31536000,"refresh_token":"1775529285619.1Vog6LkW.X5Pk39006KcnzAapUzqmmnhb8zAP0kKSjw484seWVYJOGJwKNNxkREPkKPMz5h3E8MFw_0nZzBc3JZwsOJllgzxyxstuqcZ6EK2X9_nNJvoKKTAlI-5-dBYfNsJFc-6NZ-RIBpI13xq0QVnv8F3T3Dtivyh_1sk4D_rc7FzcOQytgMUXEuYKXNYc44N8qoluG8AfjiH4THULjYXZS3We0ylPKA4JNx_ZWu0_x3pi2Od_1n2CSlTqp2kV3YdlAPCdD7YXHIjjSCnlDRS-oa1oh1KPZSHosQHU6qxrEPlI_ExGGkM2P1ABiSlwqzgttF8Cr8AmMtVp8uz6lcR2Kc2EoADEbrD1w5YMKY79vrdNHADt2iLdWnPIRult6Q4","scope":"name:test block_rfq:read_write block_trade:read_write connection trade:read_write custody:read_write account:read_write wallet:read_write mainaccount","token_type":"bearer"},"usIn":1743993285619673,"usOut":1743993285619873,"usDiff":200,"testnet":true}
[2025-04-07 08:04:44.003] [multi_sink] [info] Processing received message: {"jsonrpc":"2.0","id":"auth#2","result":{"enabled_features":["block_trade_approval","restricted_block_trades"],"access_token":"1775529285619.1YTd-srK.AWKh7Sv2LuLlxE9q5Fz7mY8bDcDYKLAB-KoC4CHKu0iC7nI7NhPUz0Gf7k46Qa9IT37wZV5Y2ylyKn5ggFnjxuKmRHt571E_je_cvMhngzcRckiLqiykFii7RZEmpT_fotReU2mjBrllC8xlBcPGfWq4lN23t9bsET890AIDS4dMoIPj9AO0SAfJK5ncrNokRlKHxSSTJ-KFDCzTZsUeqUAOQ-0ApjpG_pErTOEu6gi76s6SJ4Vasz4dSwW83OVLeYGiza4cpcfWbM_Q7myATWd1JqjMqYo92BPtUh5eqxFh9wO9R7N0o7LytliKVO-llMs59ucKAKs2Qnr-WaXhjmYlXRMRLyQCUr4HPin4UWCBr_iz5BX43vPc-h1x","expires_in":31536000,"refresh_token":"1775529285619.1Vog6LkW.X5Pk39006KcnzAapUzqmmnhb8zAP0kKSjw484seWVYJOGJwKNNxkREPkKPMz5h3E8MFw_0nZzBc3JZwsOJllgzxyxstuqcZ6EK2X9_nNJvoKKTAlI-5-dBYfNsJFc-6NZ-RIBpI13xq0QVnv8F3T3Dtivyh_1sk4D_rc7FzcOQytgMUXEuYKXNYc44N8qoluG8AfjiH4THULjYXZS3We0ylPKA4JNx_ZWu0_x3pi2Od_1n2CSlTqp2kV3YdlAPCdD7YXHIjjSCnlDRS-oa1oh1KPZSHosQHU6qxrEPlI_ExGGkM2P1ABiSlwqzgttF8Cr8AmMtVp8uz6lcR2Kc2EoADEbrD1w5YMKY79vrdNHADt2iLdWnPIRult6Q4","scope":"name:test block_rfq:read_write block_trade:read_write connection trade:read_write custody:read_write account:read_write wallet:read_write mainaccount","token_type":"bearer"},"usIn":1743993285619673,"usOut":1743993285619873,"usDiff":200,"testnet":true}
[2025-04-07 08:04:57.723] [multi_sink] [info] ➡️ Added to send queue: {"id":"get_orderbook#3","jsonrpc":"2.0","method":"public/get_order_book","params":{"depth":10,"instrument_name":"BTC-PERPETUAL"}}
[2025-04-07 08:04:57.724] [multi_sink] [info] ➡️ Sent: {"id":"get_orderbook#3","jsonrpc":"2.0","method":"public/get_order_book","params":{"depth":10,"instrument_name":"BTC-PERPETUAL"}}
[2025-04-07 08:04:57.886] [multi_sink] [info] 📩 Received: {"jsonrpc":"2.0","id":"get_orderbook#3","result":{"timestamp":1743993299380,"state":"open","stats":{"high":83490.0,"low":75871.5,"price_change":-5.5042,"volume":37153.39217517,"volume_usd":2951364010.0,"volume_notional":2951364010.0},"change_id":41149681354,"index_price":78800.32,"instrument_name":"BTC-PERPETUAL","bids":[[78791.0,119630.0],[78789.0,9730.0],[78788.5,32430.0],[78788.0,4340.0],[78787.5,3820.0],[78786.0,470.0],[78785.5,490.0],[78785.0,9680.0],[78784.0,5460.0],[78783.5,510.0]],"asks":[[78791.5,27520.0],[78794.0,160.0],[78795.0,1060.0],[78796.0,3.2e4],[78796.5,160.0],[78797.5,1170.0],[78799.0,190.0],[7.88e4,78850.0],[78801.5,200.0],[78802.0,16980.0]],"last_price":78767.0,"settlement_price":82998.58,"min_price":76420.0,"max_price":81147.5,"open_interest":10211371830,"mark_price":78783.71,"interest_value":-0.020843075990598987,"best_ask_price":78791.5,"best_bid_price":78791.0,"estimated_delivery_price":78800.32,"best_ask_amount":27520.0,"best_bid_amount":119630.0,"current_funding":0.0,"funding_8h":-1.25e-6},"usIn":1743993299497413,"usOut":1743993299497742,"usDiff":329,"testnet":true}
[2025-04-07 08:04:57.891] [multi_sink] [info] Processing received message: {"jsonrpc":"2.0","id":"get_orderbook#3","result":{"timestamp":1743993299380,"state":"open","stats":{"high":83490.0,"low":75871.5,"price_change":-5.5042,"volume":37153.39217517,"volume_usd":2951364010.0,"volume_notional":2951364010.0},"change_id":41149681354,"index_price":78800.32,"instrument_name":"BTC-PERPETUAL","bids":[[78791.0,119630.0],[78789.0,9730.0],[78788.5,32430.0],[78788.0,4340.0],[78787.5,3820.0],[78786.0,470.0],[78785.5,490.0],[78785.0,9680.0],[78784.0,5460.0],[78783.5,510.0]],"asks":[[78791.5,27520.0],[78794.0,160.0],[78795.0,1060.0],[78796.0,3.2e4],[78796.5,160.0],[78797.5,1170.0],[78799.0,190.0],[7.88e4,78850.0],[78801.5,200.0],[78802.0,16980.0]],"last_price":78767.0,"settlement_price":82998.58,"min_price":76420.0,"max_price":81147.5,"open_interest":10211371830,"mark_price":78783.71,"interest_value":-0.020843075990598987,"best_ask_price":78791.5,"best_bid_price":78791.0,"estimated_delivery_price":78800.32,"best_ask_amount":27520.0,"best_bid_amount":119630.0,"current_funding":0.0,"funding_8h":-1.25e-6},"usIn":1743993299497413,"usOut":1743993299497742,"usDiff":329,"testnet":true}
[2025-04-07 08:09:59.408] [multi_sink] [error]  [Receive Loop] Error: Connection reset by peer
[2025-04-07 08:10:43.210] [multi_sink] [info]  Logger initialized successfully.
[2025-04-07 08:10:43.210] [multi_sink] [info]  DeribitClient created for test.deribit.com:443/ws/api/v2
[2025-04-07 08:10:43.836] [multi_sink] [info] Starting receive_thread...
[2025-04-07 08:10:43.836] [multi_sink] [info]  Starting process_thread...
[2025-04-07 08:10:43.836] [multi_sink] [info]  Starting send_thread...
[2025-04-07 08:10:43.836] [multi_sink] [info] Starting WebSocket server on port 8080
[2025-04-07 08:10:43.836] [multi_sink] [info] Local WebSocket server running on port 8080
[2025-04-07 08:15:49.293] [multi_sink] [error]  [Receive Loop] Error: Connection reset by peer
[2025-04-07 08:23:05.215] [multi_sink] [info]  Logger initialized successfully.
[2025-04-07 08:23:05.216] [multi_sink] [info]  DeribitClient created for test.deribit.com:443/ws/api/v2
[2025-04-07 08:23:06.034] [multi_sink] [info] Starting receive_thread...
[2025-04-07 08:23:06.034] [multi_sink] [info]  Starting process_thread...
[2025-04-07 08:23:06.035] [multi_sink] [info]  Starting send_thread...
[2025-04-07 08:23:06.035] [multi_sink] [info] Starting WebSocket server on port 8080
[2025-04-07 08:23:06.035] [multi_sink] [info] Local WebSocket server running on port 8080
[2025-04-07 08:23:43.627] [multi_sink] [info] ➡️ Added to send queue: {"id":"auth#2","jsonrpc":"2.0","method":"public/auth","params":{"client_id":"KrYGD58Z","client_secret":"gI4vZ-kp10WPIwcRjdbNexOPOfppHpQWqHp6_fzEc3k","grant_type":"client_credentials"}}
[2025-04-07 08:23:43.627] [multi_sink] [info]  Sent authentication request
[2025-04-07 08:23:43.627] [multi_sink] [info] ➡️ Sent: {"id":"auth#2","jsonrpc":"2.0","method":"public/auth","params":{"client_id":"KrYGD58Z","client_secret":"gI4vZ-kp10WPIwcRjdbNexOPOfppHpQWqHp6_fzEc3k","grant_type":"client_credentials"}}
[2025-04-07 08:23:44.003] [multi_sink] [info] 📩 Received: {"jsonrpc":"2.0","id":"auth#2","result":{"enabled_features":["block_trade_approval","restricted_block_trades"],"access_token":"1775530425452.1YUK01wp.tVaEZcags53xo3awR-0ageeFa9ByT732qUSTys54QECUriUwrpf18RhJeqfaY9n-XEOK0VdU0WmeLSyumj9fHj_4mATJA5IEyTA5AiQpMWnjdjE53Ofl0aFTB8JYNO_eJpLSJnlLzg7iMvdG3VdQ70kX_Po5qEV-uLoieuQaG_k6OKLg7z5HbTFXgHzKpbom7tPrbjsvk0zMFwoaxIAAhsdpC49QabbL8qyqW_wW0NsEfaPrsFtNs3PfEJbDBXT1i_-56QS3nRO8ZmmZyGjzAhkleOydURMIS5N7CtXc0Eb6AaVLFr5EtTwAenuis7SeXjHplOP_tlB_gy9KksuR5kIegPWO5okydd5_fcchSIqmqbSWqD6NKn3lQGTw","expires_in":31535999,"refresh_token":"1775530425452.1QP_xhov.SdJ5PMXqDke3kGqcqEHa2sOl0ARdmmEuIogS7HB8Nf5OkWupYvKAQGiu3ULe8Ix9dGffjm8Ch1fkhvcCttjThk0cmCQkLbJDGn4ZelLsKVPhrotw8OQNFZ4HH2bz-7CG6Pqwkill-DnDhjInY90I8nTkoj7pl95xr_9Qf26OI_65AMv08d4j3Y3xrQsdyvvpBSc0RTPBtDGo0TQte0qe1tUfjIospCSWoiKmZL9qVqnyw0Zi3kwhgvBvdDxnydQeP5D5lX-itMcOCNuUdJGKgt6rYFvc4rHb5IGcONrzhPO8tHNMcc9glbHpeS0zGdvTQtVsiuAKZ9F0vGWXQlCsoW_GD9fBPptE4E4KxWmTasKsNz3BI1lGlnEzPxg","scope":"name:test block_rfq:read_write block_trade:read_write connection trade:read_write custody:read_write account:read_write wallet:read_write mainaccount","token_type":"bearer"},"usIn":1743994425452842,"usOut":1743994425453029,"usDiff":187,"testnet":true}
[2025-04-07 08:23:44.005] [multi_sink] [info] Processing received message: {"jsonrpc":"2.0","id":"auth#2","result":{"enabled_features":["block_trade_approval","restricted_block_trades"],"access_token":"1775530425452.1YUK01wp.tVaEZcags53xo3awR-0ageeFa9ByT732qUSTys54QECUriUwrpf18RhJeqfaY9n-XEOK0VdU0WmeLSyumj9fHj_4mATJA5IEyTA5AiQpMWnjdjE53Ofl0aFTB8JYNO_eJpLSJnlLzg7iMvdG3VdQ70kX_Po5qEV-uLoieuQaG_k6OKLg7z5HbTFXgHzKpbom7tPrbjsvk0zMFwoaxIAAhsdpC49QabbL8qyqW_wW0NsEfaPrsFtNs3PfEJbDBXT1i_-56QS3nRO8ZmmZyGjzAhkleOydURMIS5N7CtXc0Eb6AaVLFr5EtTwAenuis7SeXjHplOP_tlB_gy9KksuR5kIegPWO5okydd5_fcchSIqmqbSWqD6NKn3lQGTw","expires_in":31535999,"refresh_token":"1775530425452.1QP_xhov.SdJ5PMXqDke3kGqcqEHa2sOl0ARdmmEuIogS7HB8Nf5OkWupYvKAQGiu3ULe8Ix9dGffjm8Ch1fkhvcCttjThk0cmCQkLbJDGn4ZelLsKVPhrotw8OQNFZ4HH2bz-7CG6Pqwkill-DnDhjInY90I8nTkoj7pl95xr_9Qf26OI_65AMv08d4j3Y3xrQsdyvvpBSc0RTPBtDGo0TQte0qe1tUfjIospCSWoiKmZL9qVqnyw0Zi3kwhgvBvdDxnydQeP5D5lX-itMcOCNuUdJGKgt6rYFvc4rHb5IGcONrzhPO8tHNMcc9glbHpeS0zGdvTQtVsiuAKZ9F0vGWXQlCsoW_GD9fBPptE4E4KxWmTasKsNz3BI1lGlnEzPxg","scope":"name:test block_rfq:read_write block_trade:read_write connection trade:read_write custody:read_write account:read_write wallet:read_write mainaccount","token_type":"bearer"},"usIn":1743994425452842,"usOut":1743994425453029,"usDiff":187,"testnet":true}
[2025-04-07 08:25:13.124] [multi_sink] [info] ➡️ Added to send queue: {"id":"order#3","jsonrpc":"2.0","method":"private/buy","params":{"amount":1200.0,"instrument_name":"ETH-PERPETUAL","post_only":false,"price":12300.0,"reduce_only":false,"type":"limit"}}
[2025-04-07 08:25:13.124] [multi_sink] [info] Sent  order request for ETH-PERPETUAL
[2025-04-07 08:25:13.124] [multi_sink] [info] ➡️ Sent: {"id":"order#3","jsonrpc":"2.0","method":"private/buy","params":{"amount":1200.0,"instrument_name":"ETH-PERPETUAL","post_only":false,"price":12300.0,"reduce_only":false,"type":"limit"}}
[2025-04-07 08:25:13.294] [multi_sink] [info] 📩 Received: {"jsonrpc":"2.0","id":"order#3","error":{"code":10007,"message":"price_too_high 1736.4"},"usIn":1743994514919983,"usOut":1743994514922759,"usDiff":2776,"testnet":true}
[2025-04-07 08:25:13.298] [multi_sink] [info] Processing received message: {"jsonrpc":"2.0","id":"order#3","error":{"code":10007,"message":"price_too_high 1736.4"},"usIn":1743994514919983,"usOut":1743994514922759,"usDiff":2776,"testnet":true}
[2025-04-07 08:25:45.883] [multi_sink] [info] ➡️ Added to send queue: {"id":"order#4","jsonrpc":"2.0","method":"private/buy","params":{"amount":100.0,"instrument_name":"ETH-PERPETUAL","post_only":false,"price":2000.0,"reduce_only":false,"type":"limit"}}
[2025-04-07 08:25:45.883] [multi_sink] [info] Sent  order request for ETH-PERPETUAL
[2025-04-07 08:25:45.883] [multi_sink] [info] ➡️ Sent: {"id":"order#4","jsonrpc":"2.0","method":"private/buy","params":{"amount":100.0,"instrument_name":"ETH-PERPETUAL","post_only":false,"price":2000.0,"reduce_only":false,"type":"limit"}}
[2025-04-07 08:25:46.051] [multi_sink] [info] 📩 Received: {"jsonrpc":"2.0","id":"order#4","error":{"code":10007,"message":"price_too_high 1735.3"},"usIn":1743994547679181,"usOut":1743994547681278,"usDiff":2097,"testnet":true}
[2025-04-07 08:25:46.054] [multi_sink] [info] Processing received message: {"jsonrpc":"2.0","id":"order#4","error":{"code":10007,"message":"price_too_high 1735.3"},"usIn":1743994547679181,"usOut":1743994547681278,"usDiff":2097,"testnet":true}
[2025-04-07 08:26:16.258] [multi_sink] [info] ➡️ Added to send queue: {"id":"order#5","jsonrpc":"2.0","method":"private/buy","params":{"amount":10.0,"instrument_name":"BTC-PERPETUAL","post_only":false,"price":100.0,"reduce_only":false,"type":"limit"}}
[2025-04-07 08:26:16.259] [multi_sink] [info] Sent  order request for BTC-PERPETUAL
[2025-04-07 08:26:16.259] [multi_sink] [info] ➡️ Sent: {"id":"order#5","jsonrpc":"2.0","method":"private/buy","params":{"amount":10.0,"instrument_name":"BTC-PERPETUAL","post_only":false,"price":100.0,"reduce_only":false,"type":"limit"}}
[2025-04-07 08:26:16.428] [multi_sink] [info] 📩 Received: {"jsonrpc":"2.0","id":"order#5","result":{"order":{"label":"","price":100.0,"amount":10.0,"direction":"buy","time_in_force":"good_til_cancelled","instrument_name":"BTC-PERPETUAL","api":true,"web":false,"order_id":"41151537902","creation_timestamp":1743994578057,"mmp":false,"replaced":false,"filled_amount":0.0,"post_only":false,"last_update_timestamp":1743994578057,"reduce_only":false,"average_price":0.0,"contracts":1.0,"order_state":"open","order_type":"limit","is_liquidation":false,"risk_reducing":false},"trades":[]},"usIn":1743994578055331,"usOut":1743994578058782,"usDiff":3451,"testnet":true}
[2025-04-07 08:26:16.431] [multi_sink] [info] Processing received message: {"jsonrpc":"2.0","id":"order#5","result":{"order":{"label":"","price":100.0,"amount":10.0,"direction":"buy","time_in_force":"good_til_cancelled","instrument_name":"BTC-PERPETUAL","api":true,"web":false,"order_id":"41151537902","creation_timestamp":1743994578057,"mmp":false,"replaced":false,"filled_amount":0.0,"post_only":false,"last_update_timestamp":1743994578057,"reduce_only":false,"average_price":0.0,"contracts":1.0,"order_state":"open","order_type":"limit","is_liquidation":false,"risk_reducing":false},"trades":[]},"usIn":1743994578055331,"usOut":1743994578058782,"usDiff":3451,"testnet":true}
[2025-04-07 08:27:02.563] [multi_sink] [info] ➡️ Added to send queue: {"id":"modify#6","jsonrpc":"2.0","method":"private/edit","params":{"amount":2000.0,"order_id":"41151537902","price":2500.0}}
[2025-04-07 08:27:02.563] [multi_sink] [info] Sent modify request for Order ID: 41151537902
[2025-04-07 08:27:02.563] [multi_sink] [info] ➡️ Sent: {"id":"modify#6","jsonrpc":"2.0","method":"private/edit","params":{"amount":2000.0,"order_id":"41151537902","price":2500.0}}
[2025-04-07 08:27:02.733] [multi_sink] [info] 📩 Received: {"jsonrpc":"2.0","id":"modify#6","result":{"order":{"label":"","price":2.5e3,"amount":2.0e3,"direction":"buy","time_in_force":"good_til_cancelled","instrument_name":"BTC-PERPETUAL","api":true,"web":false,"order_id":"41151537902","creation_timestamp":1743994578057,"mmp":false,"replaced":true,"filled_amount":0.0,"post_only":false,"last_update_timestamp":1743994624361,"reduce_only":false,"average_price":0.0,"contracts":200.0,"order_state":"open","order_type":"limit","is_liquidation":false,"risk_reducing":false},"trades":[]},"usIn":1743994624360534,"usOut":1743994624362415,"usDiff":1881,"testnet":true}
[2025-04-07 08:27:02.735] [multi_sink] [info] Processing received message: {"jsonrpc":"2.0","id":"modify#6","result":{"order":{"label":"","price":2.5e3,"amount":2.0e3,"direction":"buy","time_in_force":"good_til_cancelled","instrument_name":"BTC-PERPETUAL","api":true,"web":false,"order_id":"41151537902","creation_timestamp":1743994578057,"mmp":false,"replaced":true,"filled_amount":0.0,"post_only":false,"last_update_timestamp":1743994624361,"reduce_only":false,"average_price":0.0,"contracts":200.0,"order_state":"open","order_type":"limit","is_liquidation":false,"risk_reducing":false},"trades":[]},"usIn":1743994624360534,"usOut":1743994624362415,"usDiff":1881,"testnet":true}
[2025-04-07 08:27:37.731] [multi_sink] [info] ➡️ Added to send queue: {"id":"get_positions#7","jsonrpc":"2.0","method":"private/get_positions","params":{"currency":"BTC","kind":"any"}}
[2025-04-07 08:27:37.731] [multi_sink] [info] 📦 Requested positions for currency: BTC, kind: any
[2025-04-07 08:27:37.731] [multi_sink] [info] ➡️ Sent: {"id":"get_positions#7","jsonrpc":"2.0","method":"private/get_positions","params":{"currency":"BTC","kind":"any"}}
[2025-04-07 08:27:37.900] [multi_sink] [info] 📩 Received: {"jsonrpc":"2.0","id":"get_positions#7","result":[{"size":0.0,"kind":"future","direction":"zero","index_price":78375.69,"maintenance_margin":0.0,"initial_margin":0.0,"open_orders_margin":0.016032,"instrument_name":"BTC-PERPETUAL","settlement_price":82998.58,"mark_price":78370.5,"interest_value":-0.020843075990598987,"delta":0.0,"average_price":0.0,"leverage":50,"floating_profit_loss":0.0,"realized_profit_loss":0.0,"total_profit_loss":0.0,"realized_funding":0.0,"size_currency":0.0,"estimated_liquidation_price":null}],"usIn":1743994659528729,"usOut":1743994659531292,"usDiff":2563,"testnet":true}
[2025-04-07 08:27:37.902] [multi_sink] [info] Processing received message: {"jsonrpc":"2.0","id":"get_positions#7","result":[{"size":0.0,"kind":"future","direction":"zero","index_price":78375.69,"maintenance_margin":0.0,"initial_margin":0.0,"open_orders_margin":0.016032,"instrument_name":"BTC-PERPETUAL","settlement_price":82998.58,"mark_price":78370.5,"interest_value":-0.020843075990598987,"delta":0.0,"average_price":0.0,"leverage":50,"floating_profit_loss":0.0,"realized_profit_loss":0.0,"total_profit_loss":0.0,"realized_funding":0.0,"size_currency":0.0,"estimated_liquidation_price":null}],"usIn":1743994659528729,"usOut":1743994659531292,"usDiff":2563,"testnet":true}
[2025-04-07 08:28:14.628] [multi_sink] [info] ➡️ Added to send queue: {"id":"get_orderbook#8","jsonrpc":"2.0","method":"public/get_order_book","params":{"depth":10,"instrument_name":"BTC-PERPETUAL"}}
[2025-04-07 08:28:14.628] [multi_sink] [info] ➡️ Sent: {"id":"get_orderbook#8","jsonrpc":"2.0","method":"public/get_order_book","params":{"depth":10,"instrument_name":"BTC-PERPETUAL"}}
[2025-04-07 08:28:14.794] [multi_sink] [info] 📩 Received: {"jsonrpc":"2.0","id":"get_orderbook#8","result":{"timestamp":1743994696152,"state":"open","stats":{"high":83490.0,"low":75871.5,"price_change":-5.8984,"volume":37258.66421812,"volume_usd":2959626060.0,"volume_notional":2959626060.0},"change_id":41151707842,"index_price":78358.88,"instrument_name":"BTC-PERPETUAL","bids":[[78348.5,83060.0],[78346.5,340.0],[78346.0,490.0],[78345.5,6.9e3],[78344.5,10.0],[78344.0,41440.0],[78342.5,16490.0],[78342.0,1.0e3],[78340.5,34140.0],[78340.0,20.0]],"asks":[[78349.0,36580.0],[78355.5,9630.0],[78356.0,3.34e4],[78358.0,1.6e4],[78358.5,33230.0],[78359.0,80960.0],[78360.0,1.73e4],[78360.5,34330.0],[78363.0,15980.0],[78363.5,5470.0]],"last_price":78349.0,"settlement_price":82998.58,"min_price":76000.5,"max_price":80702.5,"open_interest":10210266120,"mark_price":78351.51,"interest_value":-0.020843075990598987,"best_ask_price":78349.0,"best_bid_price":78348.5,"estimated_delivery_price":78358.88,"best_ask_amount":36580.0,"best_bid_amount":83060.0,"current_funding":0.0,"funding_8h":-5.6e-6},"usIn":1743994696426208,"usOut":1743994696426513,"usDiff":305,"testnet":true}
[2025-04-07 08:28:14.795] [multi_sink] [info] Processing received message: {"jsonrpc":"2.0","id":"get_orderbook#8","result":{"timestamp":1743994696152,"state":"open","stats":{"high":83490.0,"low":75871.5,"price_change":-5.8984,"volume":37258.66421812,"volume_usd":2959626060.0,"volume_notional":2959626060.0},"change_id":41151707842,"index_price":78358.88,"instrument_name":"BTC-PERPETUAL","bids":[[78348.5,83060.0],[78346.5,340.0],[78346.0,490.0],[78345.5,6.9e3],[78344.5,10.0],[78344.0,41440.0],[78342.5,16490.0],[78342.0,1.0e3],[78340.5,34140.0],[78340.0,20.0]],"asks":[[78349.0,36580.0],[78355.5,9630.0],[78356.0,3.34e4],[78358.0,1.6e4],[78358.5,33230.0],[78359.0,80960.0],[78360.0,1.73e4],[78360.5,34330.0],[78363.0,15980.0],[78363.5,5470.0]],"last_price":78349.0,"settlement_price":82998.58,"min_price":76000.5,"max_price":80702.5,"open_interest":10210266120,"mark_price":78351.51,"interest_value":-0.020843075990598987,"best_ask_price":78349.0,"best_bid_price":78348.5,"estimated_delivery_price":78358.88,"best_ask_amount":36580.0,"best_bid_amount":83060.0,"current_funding":0.0,"funding_8h":-5.6e-6},"usIn":1743994696426208,"usOut":1743994696426513,"usDiff":305,"testnet":true}
[2025-04-07 08:28:33.835] [multi_sink] [info] ➡️ Added to send queue: {"id":"cancel_all#9","jsonrpc":"2.0","method":"private/cancel_all","params":{}}
[2025-04-07 08:28:33.835] [multi_sink] [info] ➡️ Sent: {"id":"cancel_all#9","jsonrpc":"2.0","method":"private/cancel_all","params":{}}
[2025-04-07 08:28:34.007] [multi_sink] [info] 📩 Received: {"jsonrpc":"2.0","id":"cancel_all#9","result":1,"usIn":1743994715633294,"usOut":1743994715640094,"usDiff":6800,"testnet":true}
[2025-04-07 08:28:34.010] [multi_sink] [info] Processing received message: {"jsonrpc":"2.0","id":"cancel_all#9","result":1,"usIn":1743994715633294,"usOut":1743994715640094,"usDiff":6800,"testnet":true}
[2025-04-07 08:28:59.586] [multi_sink] [info] ➡️ Added to send queue: {"id":"subscribe#10","jsonrpc":"2.0","method":"private/subscribe","params":{"channels":["book.BTC-PERPETUAL.100ms"]}}
[2025-04-07 08:28:59.586] [multi_sink] [info]  Subscribed to BTC-PERPETUAL.100ms order book
[2025-04-07 08:28:59.586] [multi_sink] [info] ➡️ Sent: {"id":"subscribe#10","jsonrpc":"2.0","method":"private/subscribe","params":{"channels":["book.BTC-PERPETUAL.100ms"]}}
[2025-04-07 08:28:59.755] [multi_sink] [info] 📩 Received: {"jsonrpc":"2.0","id":"subscribe#10","result":["book.BTC-PERPETUAL.100ms"],"usIn":1743994741385156,"usOut":1743994741385484,"usDiff":328,"testnet":true}
[2025-04-07 08:28:59.757] [multi_sink] [info] Processing received message: {"jsonrpc":"2.0","id":"subscribe#10","result":["book.BTC-PERPETUAL.100ms"],"usIn":1743994741385156,"usOut":1743994741385484,"usDiff":328,"testnet":true}
